Workbook

Sheet Januari 2026 PMG 1
C1: PRODUCTION REPORT PMG 1
C2: No | D2: ITEM | E2: Budget / Norma | F2: UoM | G2: Januari 2026 | AM2: TOTAL MONTHLY (Kg)
G3: 1 | H3: 2 | I3: 3 | J3: 4 | K3: 5 | L3: 6 | M3: 7 | N3: 8 | O3: 9 | P3: 10 | Q3: 11 | R3: 12 | S3: 13 | T3: 14 | U3: 15 | V3: 16 | W3: 17 | X3: 18 | Y3: 19 | Z3: 20 | AA3: 21 | AB3: 22 | AC3: 23 | AD3: 24 | AE3: 25 | AF3: 26 | AG3: 27 | AH3: 28 | AI3: 29 | AJ3: 30 | AK3: 31
C4: 1 | D4: PRODUCTION | AM4: Production | AO4: aktual refinery | AR4: opening stok rpo | AS4: =AS6+AS7+AS9 -> 80236
D5: Refinery | AM5: Refinery | AO5: cpo feed | AP5: =AM9 -> 16794736 | AR5: sisa rbpo tank
D6: Running Days | F6: Day | L6: 1 | M6: 1 | N6: 1 | O6: 1 | P6: 1 | Q6: 1 | R6: 1 | S6: 1 | T6: 1 | U6: 1 | V6: 1 | AM6: =SUM(G6:AK6) -> 11 | AO6: rpo prod | AP6: =AM20+AM19+AM18 -> 15901359 | AR6: tk 108 | AS6: 80236
D7: Incoming CPO | F7: Kg | L7: 2047361 | M7: 2895861 | N7: 2094222 | O7: 1599295 | P7: 2822387 | Q7: 1400949 | R7: 2135308 | S7: 2069937 | T7: 2270473 | U7: 2856728 | AM7: =SUM(G7:AK7) -> 22192521
D8: Ratio Run CPO ( utilisasi kapasitas ) | F8: % | L8: =L9/2500000 -> 0.0690872 | M8: =M9/2500000 -> 0.5847548 | N8: =N9/2500000 -> 0.8215036 | O8: =O9/2500000 -> 0.836346 | P8: =P9/2500000 -> 0.8000988 | Q8: =Q9/2500000 -> 0.8173816 | R8: =R9/2500000 -> 0.6617068 | S8: =S9/2500000 -> 0.734196 | ... V8: =V9/2500000 -> 0 | W8: 0.8090604 | X8: 0 | Y8: =Y9/2500000 -> 0 | Z8: =Z9/2500000 -> 0 | AA8: =AA9/2500000 -> 0 | AB8: =AB9/2500000 -> 0 | AC8: =AC9/2500000 -> 0 | AD8: =AD9/2500000 -> 0 | AE8: =AE9/2500000 -> 0 | AF8: =AF9/2500000 -> 0 | ... AK8: =AK9/2500000 -> 0 | AM8: =AM9/2500000/AM6 -> 0.61071767
D9: CPO Consume Total | E9: 58900000 | F9: Kg | L9: 172718 | M9: 1461887 | N9: 2053759 | O9: =2100865-10000 -> 2090865 | P9: 2000247 | Q9: 2043454 | R9: 1654267 | S9: 1835490 | T9: 1830941 | U9: 1651108 | AM9: =SUM(G9:U9) -> 16794736
D10: Avg Daily Consump CPO ( MTD ) | AM10: =AM9/AM6 -> 1526794.2
D11: CPO Consume Poram | F11: Kg | L11: =L9-L12 -> 172718 | M11: =M9-M12 -> 1461887 | N11: =N9-N12 -> 2053759 | O11: =O9-O12 -> 2090865 | P11: =P9-P12 -> 2000247 | Q11: =Q9-Q12 -> 2043454 | R11: =R9-R12 -> 1654267 | S11: =S9-S12 -> 1835490 | ... AK11: =AK9-AK12 -> 0 | AM11: =SUM(G11:AK11) -> 16794736
D12: CPO Consume Brand | F12: Kg | L12: =L40+L49+L54 -> 0 | M12: =M40+M49+M54 -> 0 | N12: =N40+N49+N54 -> 0 | O12: =O40+O49+O54 -> 0 | P12: =P40+P49+P54 -> 0 | Q12: =Q40+Q49+Q54 -> 0 | R12: =R40+R49+R54 -> 0 | S12: 0 | T12: =T40+T49+T54 -> 0 | U12: =U40+U49+U54 -> 0 | V12: =V40+V49+V54 -> 0 | W12: 0 | X12: 0 | Y12: =Y40+Y49+Y54 -> 0 | Z12: =Z40+Z49+Z54 -> 0 | AA12: =AA40+AA49+AA54 -> 0 | AB12: =AB40+AB49+AB54 -> 0 | AC12: 0 | AD12: 0 | AE12: =AE40+AE49+AE54 -> 0 | AF12: =AF40+AF49+AF54 -> 0 | AG12: =AG40+AG49+AG54 -> 0 | AH12: =AH40+AH49+AH54 -> 0 | AM12: =SUM(G12:AK12) -> 0
D13: - FFA | E13: 5 | F13: % | L13: 3.6 | M13: =(4.4+3.74)/2 -> 4.07 | N13: =(3.93+3.79)/2 -> 3.86 | O13: 3.97 | P13: 4.03 | Q13: =(4.1+3.79)/2 -> 3.945 | R13: =(4.01+3.79)/2 -> 3.9 | S13: =(4.21+4.01)/2 -> 4.11 | T13: =(4.12+3.89)/2 -> 4.005 | U13: 4.1 | V13: 4.07 | AM13: =SUM(G13:AK13)/AM6 -> 3.9690909 | AO13: rpo feed | AP13: =AP14+AP15 -> 221307 | AR13: tk131 | AS13: ='OIP Fract PMG 2'!T13 -> 133300
D14: - Moist & Impurities | E14: 0.5 | F14: % | L14: 0.38 | M14: =(0.43+0.38)/2 -> 0.405 | N14: =(0.36+0.4)/2 -> 0.38 | O14: 0.39 | P14: 0.41 | Q14: =(0.42+0.39)/2 -> 0.405 | R14: =(0.38+0.39)/2 -> 0.385 | S14: =(0.39+0.4)/2 -> 0.395 | T14: =(0.39+0.47)/2 -> 0.43 | U14: 0.4 | V14: 0.39 | AM14: =SUM(G14:AK14)/AM6 -> 0.39727273 | AO14: olein 56 | AP14: =AM33 -> 182200 | AR14: tk132 | AS14: ='OIP Fract PMG 2'!U13 -> 0
D15: - DOBI | E15: 2,20 Min | F15: % | AM15: =SUM(G15:AK15)/AM6 -> 0 | AO15: stearin 56 | AP15: =AM34 -> 39107 | AR15: after
D16: TANK | L16: 106 | M16: 104106 | N16: 104106 | O16: 104 | P16: 104 | Q16: 104107 | R16: 106107 | S16: 104106 | T16: 104107 | U16: 104 | V16: 106 | AO16: yield olein | AP16: =AP14/(AP14+AP15)*100 -> 82.329072 | AR16: tk131 | AS16: =AS13 -> 133300
D17: Product | AM17: Product | AO17: yield stearin | AP17: =AP15/(AP14+AP15)*100 -> 17.670928 | AR17: tk132 | AS17: =AS14-AP13 -> -221307
D18: OIP RBDPO | F18: Kg | M18: ='OIP Ref PMG 1'!K7 -> 0 | AM18: =SUM(G18:AK18) -> 0
D19: DIRECT RBDPO FRACT | F19: Kg | L19: 169993 | M19: 1372080 | N19: 1888301 | O19: 1997308 | P19: 1895612 | Q19: 1942581 | R19: 1563435 | S19: 1750349 | T19: 1747544 | U19: 1574156 | AM19: =SUM(G19:U19) -> 15901359
D20: RBDPO | E20: 55661000 | F20: Kg | L20: 0 | AM20: =SUM(G20:AK20) -> 0
D21: PFAD | E21: 2827000 | F21: Kg | L21: 0 | M21: 52979 | N21: 80109 | O21: 91693 | P21: 80627 | Q21: 70559 | R21: 67084 | S21: 76310 | T21: 74082 | U21: 62874 | AM21: =SUM(G21:U21) -> 656317
D22: Fractionation
D23: Running Days | F23: Day | P23: 1 | Q23: 1 | AC23: 1 | AF23: 1 | AG23: 1 | AH23: 1 | AM23: =SUM(G23:AK23) -> 6
D24: Avg Daily Consump RBDPO ( MTD ) | F24: Kg | L24: 0 | M24: 0 | N24: 0 | O24: 0 | P24: 0 | Q24: 0 | R24: 0 | S24: 0 | T24: 0 | U24: 0 | V24: 0 | W24: 0 | X24: 0 | Y24: 0 | Z24: 0 | AA24: 0 | AB24: 0 | AC24: 0 | AD24: 0 | AE24: 0 | AF24: 0 | AG24: 0 | AH24: 0 | AI24: 0 | AJ24: 0 | AK24: 0 | AM24: =AM29/AM23 -> 396151.67
D25: Total RBDPO transfer to plant | F25: Kg | AJ25: 0 | AK25: 0 | AM25: =SUM(G25:AK25) -> 0
D26: Stok TK 131 | E26: 559 | F26: ton
D27: Stok TK 132 | E27: 559 | F27: ton
D28: Ratio Run RBDPO | F28: % | L28: =L29/2500000 -> 0 | M28: =M29/2500000 -> 0 | N28: =N29/2500000 -> 0 | O28: =O29/2500000 -> 0 | P28: =P29/2500000 -> 0 | Q28: =Q29/2500000 -> 0 | R28: =R29/2500000 -> 0 | S28: =S29/2500000 -> 0 | ... V28: =V29/2500000 -> 0 | W28: 0.7274628 | X28: 0 | Y28: =Y29/2500000 -> 0 | Z28: =Z29/2500000 -> 0 | AA28: =AA29/2500000 -> 0 | AB28: =AB29/2500000 -> 0 | AC28: 0.52886 | AD28: =AD29/2500000 -> 0 | AE28: =AE29/2500000 -> 0 | AF28: =AF29/2500000 -> 0.21776 | AG28: =AG29/2500000 -> 0.40436 | AH28: =AH29/2500000 -> 0.328644 | AI28: =AI29/2500000 -> 0 | AJ28: =AJ29/2500000 -> 0 | AK28: =AK29/2500000 -> 0 | AM28: =AM29/2500000/AM23 -> 0.15846067
D29: Total Proses RBDPO | E29: 35501000 | F29: Kg | L29: =SUM(L32,L36,L41,L45,L55) -> 0 | M29: =SUM(M32,M36,M41,M45,M55) -> 0 | N29: =SUM(N32,N36,N41,N45,N55) -> 0 | O29: =SUM(O32,O36,O41,O45,O55) -> 0 | P29: =SUM(P32,P36,P41,P45,P55) -> 0 | Q29: =SUM(Q32,Q36,Q41,Q45,Q55) -> 0 | R29: =SUM(R32,R36,R41,R45,R55) -> 0 | S29: =SUM(S32,S36,S41,S45,S55) -> 0 | ... AK29: =SUM(AK32,AK36,AK41,AK45,AK55) -> 0 | AM29: =SUM(G29:AK29) -> 2376910
D30: Sisa Filling Crystalizer | F30: Kg | L30: =L25-L29 -> 0 | M30: =M25-M29 -> 0 | N30: =N25-N29 -> 0 | O30: =O25-O29 -> 0 | P30: =P25-P29 -> 0 | Q30: =Q25-Q29 -> 0 | R30: =R25-R29 -> 0 | S30: =S25-S29 -> 0 | ... AK30: =AK25-AK29 -> 0 | AM30: =SUM(G30:AK30) -> -2376910
D31: Fractionation OLEIN IV 56 | AM31: Olein IV 56
D32: RBDPO Consume | F32: Kg | L32: =L33+L34 -> 0 | M32: =M33+M34 -> 0 | N32: =N33+N34 -> 0 | O32: =O33+O34 -> 0 | P32: =P33+P34 -> 0 | Q32: =Q33+Q34 -> 0 | R32: =R33+R34 -> 0 | S32: =S33+S34 -> 0 | ... AK32: =AK33+AK34 -> 0 | AM32: =SUM(G32:AK32) -> 221307
D33: OLEIN IV 56 | E33: 25000000 | F33: Kg | AF33: 135000 | AH33: 47200 | AM33: =SUM(G33:AK33) -> 182200
D34: STEARIN | E34: 639000 | F34: Kg | AF34: 29064 | AH34: 10043 | AM34: =SUM(G34:AK34) -> 39107
D35: Fractionation OLEIN IV 57 ( Bulk ) | Z35: 0 | AM35: Olein IV 57 ( Bulk )
D36: RBDPO Consume | F36: Kg | L36: =L37+L38 -> 0 | M36: 0 | R36: =R37+R38 -> 0 | S36: 0 | T36: =T37+T38 -> 0 | U36: =U37+U38 -> 0 | V36: =V37+V38 -> 0 | W36: 0 | X36: 0 | AA36: =AA37+AA38 -> 0 | AB36: =AB37+AB38 -> 0 | AC36: 0 | AD36: =AD37+AD38 -> 0 | AE36: =AE37+AE38 -> 0 | AF36: =AF37+AF38 -> 0 | AG36: =AG37+AG38 -> 0 | AH36: =AH37+AH38 -> 0 | AM36: =SUM(G36:AK36) -> 0
D37: OLEIN IV 57 | F37: Kg | L37: 0 | M37: 0 | R37: 0 | S37: 0 | T37: 0 | U37: 0 | V37: 0 | W37: 0 | X37: 0 | AA37: 0 | AB37: 0 | AC37: 0 | AD37: 0 | AE37: 0 | AF37: 0 | AG37: 0 | AM37: =SUM(G37:AK37) -> 0
D38: STEARIN | F38: Kg | L38: 0 | M38: 0 | R38: 0 | S38: 0 | T38: 0 | U38: 0 | V38: 0 | W38: 0 | X38: 0 | AA38: 0 | AB38: 0 | AC38: 0 | AD38: 0 | AE38: 0 | AF38: 0 | AG38: 0 | AM38: =SUM(G38:AK38) -> 0
D39: Fractionation OLEIN IV 57 ( Retail ) | AM39: Olein IV 57 ( Retail )
D40: CPO Consume | F40: Kg | AM40: =SUM(G40:AK40) -> 0
...

Sheet OIP Ref PMG 1
B4: Oil In Plant (OIP) Refinery pmg | I4: Oktober | J4: OIP | M4: TK131 RPO | P4: TK132 RPO | S4: TOTAL STOK RPO DI PLANT
B5: Vessel | C5: Operating Volume (m3) | D5: Oil Density (kg/m3) | E5: MT | F5: Level yg diisi | G5: Actual OIP (Kg) | I5: Tanggal | J5: Opening Stock | K5: Closing Stock | L5: balance stok | M5: Opening Stock | N5: Closing Stock | O5: CONSUMP stok | P5: Opening Stock | Q5: Closing Stock | R5: CONSUMP stok
B6: 2MX312 | C6: 5.67 | D6: 850 | E6: =C6*D6/1000 -> 4.8195 | G6: =(F6*E6/100)*1000 -> 0 | I6: 46023 | L6: =J6-K6 -> 0
B7: 2VE611A | C7: 47.22 | D7: 850 | E7: =C7*D7/1000 -> 40.137 | G7: =(F7*E7/100)*1000 -> 0 | I7: 46024 | L7: =J7-K7 -> 0
B8: 2VE611B | C8: 47.22 | D8: 850 | E8: =C8*D8/1000 -> 40.137 | G8: =(F8*E8/100)*1000 -> 0 | I8: 46025 | L8: =J8-K8 -> 0
B9: 2VE612 | C9: 35.68 | D9: 850 | E9: =C9*D9/1000 -> 30.328 | G9: =(F9*E9/100)*1000 -> 0 | I9: 46026 | L9: =J9-K9 -> 0
B10: 2VE661 | C10: 10.8 | D10: 850 | E10: =C10*D10/1000 -> 9.18 | G10: =(F10*E10/100)*1000 -> 0 | I10: 46027 | L10: =J10-K10 -> 0
B11: FL621 | C11: 10.1 | D11: 850 | E11: =C11*D11/1000 -> 8.585 | G11: =(F11*E11/100)*1000 -> 0 | I11: 46028 | J11: 0 | K11: 169993 | L11: =J11-K11 -> -169993
B12: FL622 | C12: 10.1 | D12: 850 | E12: =C12*D12/1000 -> 8.585 | G12: =(F12*E12/100)*1000 -> 0 | I12: 46029 | J12: =K11 -> 169993 | K12: 298276 | L12: =J12-K12 -> -128283
B13: FL623 | C13: 10.1 | D13: 850 | E13: =C13*D13/1000 -> 8.585 | G13: =(F13*E13/100)*1000 -> 0 | I13: 46030 | J13: =K12 -> 298276 | K13: 300521 | L13: =J13-K13 -> -2245 | N13: 0 | Q13: 174609
B14: FL624 | C14: 10.1 | D14: 850 | E14: =C14*D14/1000 -> 8.585 | G14: =(F14*E14/100)*1000 -> 0 | I14: 46031 | J14: =K13 -> 300521 | K14: 291536 | L14: =J14-K14 -> 8985 | N14: 44191 | P14: 174609 | Q14: 38852 | R14: =P14-Q14 -> 135757 | S14: =R14+O14+L14 -> 144742
B15: FL625 | C15: 10.1 | D15: 850 | E15: =C15*D15/1000 -> 8.585 | G15: =(F15*E15/100)*1000 -> 0 | I15: 46032 | J15: =K14 -> 291536 | K15: 266295 | L15: =J15-K15 -> 25241 | M15: 44191 | N15: 405272 | O15: =M15-N15 -> -361081 | P15: 38852 | Q15: 38852 | R15: =P15-Q15 -> 0 | S15: =R15+O15+L15 -> -335840
B16: 2VE701 | C16: 72.13 | D16: 850 | E16: =C16*D16/1000 -> 61.3105 | G16: =(F16*E16/100)*1000 -> 0 | I16: 46033 | J16: =K15 -> 266295 | K16: 280865 | L16: =J16-K16 -> -14570
B17: 2VE751 | C17: 4.28 | D17: 860 | E17: =C17*D17/1000 -> 3.6808 | G17: =(F17*E17/100)*1000 -> 0 | I17: 46034 | J17: =K16 -> 280865 | K17: 263772 | L17: =J17-K17 -> 17093
B18: 2HE721A (tube) | C18: 10 | D18: 810 | E18: =C18*D18/1000 -> 8.1 | G18: =(F18*E18/100)*1000 -> 0 | I18: 46035 | J18: =K17 -> 263772 | K18: 292150 | L18: =J18-K18 -> -28378
B19: 2HE721A (shell) | C19: 21.8 | D19: 800 | E19: =C19*D19/1000 -> 17.44 | G19: =(F19*E19/100)*1000 -> 0 | I19: 46036 | J19: =K18 -> 292150 | K19: 270324 | L19: =J19-K19 -> 21826
B20: HE721B (tube) | C20: 10 | D20: 810 | E20: =C20*D20/1000 -> 8.1 | G20: =(F20*E20/100)*1000 -> 0 | I20: 46037 | J20: =K19 -> 270324 | K20: 264646 | L20: =J20-K20 -> 5678
B21: 2HE722 | C21: 11.4 | D21: 790 | E21: =C21*D21/1000 -> 9.006 | G21: =(F21*E21/100)*1000 -> 0 | I21: 46038 | J21: =K20 -> 264646 | K21: 135284 | L21: =J21-K21 -> 129362
B22: 2PR731 | C22: 14 | D22: 790 | E22: =C22*D22/1000 -> 11.06 | G22: =(F22*E22/100)*1000 -> 0 | I22: 46039 | L22: =J22-K22 -> 0
B23: 2DE732 | C23: 149.76 | D23: 790 | E23: =C23*D23/1000 -> 118.3104 | G23: =(F23*E23/100)*1000 -> 0 | I23: 46040 | L23: =J23-K23 -> 0
C24: =SUM(C6:C23) -> 490.46 | E24: =SUM(E6:E23) -> 404.5342 | I24: 46041 | L24: =J24-K24 -> 0
F25: Total OIP = | G25: =SUM(G6:G24) -> 0 | I25: 46042 | L25: =J25-K25 -> 0
I26: 46043 | L26: =J26-K26 -> 0
I27: 46044 | L27: =J27-K27 -> 0
I28: 46045 | L28: =J28-K28 -> 0
I29: 46046 | L29: =J29-K29 -> 0
I30: 46047 | L30: =J30-K30 -> 0
H31: 0 | I31: 46048 | L31: =J31-K31 -> 0
I32: 46049 | L32: =J32-K32 -> 0
I33: 46050 | L33: =J33-K33 -> 0
I34: 46051 | L34: =J34-K34 -> 0
I35: 46052 | L35: =J35-K35 -> 0
I36: 46053 | L36: =J36-K36 -> 0
B38: Solar Daily Tank HPB
B39: 2TK726 | C39: =5.3+0.78 -> 6.08 | D39: 840 | E39: =C39*D39/1000 -> 5.1072 | F39: 0 | G39: =F39*E39/100*1000 -> 0
B41: Stock Chemicals In Plant
C42: Sisa Stok Di Lap | D42: Order | E42: Consumption
B43: BE
B44: 630A | D44: 298
B45: 630B
...

Sheet Peformance test Fract 1
C1: PT.INDUSTRI NABATI LESTARI
C2: Pabrik Minyak Goreng ( PMG 2 )
C3: Kantor Pusat: Komp. KEK Sei Mangkei, Kav.2-3, Kec. Bosar Maligas, Kab. Simalungun, Sumatera Utara, 21184
C4: ACTUAL PEFORMANCE / CONSUMPT REPORT FRAKSINASI PLANT | H4: Trial | I4: 1
H5: Start / Date / Time | I5: 17/12/24 ( 07.00 Wib )
H6: Finish / Date / Time | I6: 17/12/24 ( 07.00 Wib )
A8: No | B8: ITEM | C8: Kontrak LIPICO | D8: UOM | E8: TOTALIZER
A10: 1 | B10: PRODUCTION | C10: IV 56 | D10: 24 jam | E10: BEFORE | F10: AFTER | G10: TOTAL | H10: YIELD % | I10: STATUS/REMAKS
B11: Fraksinasi
B12: Running Days
B13: Incoming CPO
B14: Ratio Run CPO
B15: RBDPO Consume Total | C15: 2500 | D15: TPD | E15: 8982.8 | F15: 11717.8 | G15: =F15-E15 -> 2735 | H15: =G15/25000*10 -> 1.094 | I15: OK
B16: Avg Daily Consump CPO ( MTD )
B17: CPO Consume Poram | C17: 29045000
B18: CPO Consume Brand | C18: 7314000 | E18: =E49+E58+E63 -> 0
B19: QUALITY
B20: - FFA | C20: 0.1 | D20: % Max | H20: 0.063
B21: - Moist & Impurities | C21: 0.1 | D21: % Max | H21: 0.05
B22: - IV | C22: 52 - 52,5 | H22: 51.8
B23: - LC | H23: 2,6/20
B24: - Temp | C24: 68 | D24: ˚C Min | H24: 65
B25: TANK | H25: 108/109
B26: Product
B27: OLEIN IV 56 | C27: =C15*84% -> 2100 | D27: TPD | E27: 6537.1 | F27: 8213 | G27: =F27-E27 -> 1675.9 | H27: =G27/(G27+G32) -> 0.82838219 | I27: OK
B28: QUALITY
B29: - IV | C29: 56 | D29: Min
B30: - LC
B31: - Cloud Point ( metter ) | C31: 10 | D31: ˚C Max
B32: STEARIN | C32: =C15*16% -> 400 | E32: 2268.1 | F32: 2615.3 | G32: =F32-E32 -> 347.2 | H32: =G32/(G32+G27) -> 0.17161781 | I32: OK
B33: Fractionation
B34: Running Days
B35: Filling Langsung CR Fr Refinery | E35: 0
B36: Total Filling Crystalizer ( Feed ) | E36: 392100
B37: Avg Daily Consump RPO ( MTD )
B38: Total Proses RBDPO | E38: =SUM(E41,E45,E50,E54,E64) -> 0
B39: Sisa Filling Crystalizer | E39: =E36-E38 -> 392100
B40: Fractionation OLEIN IV 56
B41: RBDPO Consume | E41: =E42+E43 -> 0
B42: OLEIN IV 56 | E42: 0
...

Sheet Peformance Test REFINERY 1
C1: PT.INDUSTRI NABATI LESTARI
C2: Pabrik Minyak Goreng ( PMG 2 )
C3: Kantor Pusat: Komp. KEK Sei Mangkei, Kav.2-3, Kec. Bosar Maligas, Kab. Simalungun, Sumatera Utara, 21184
C4: ACTUAL PEFORMANCE / CONSUMPT REPORT REFINERY PLANT | H4: Peformance | I4: 1
H5: Start / Date / Time | I5: 17/12/24 ( 21.00 Wib )
H6: Finish / Date / Time | I6: 18/12/24 ( 21.00 Wib )
A7: No | B7: ITEM | C7: Kontrak LIPICO | D7: UOM | E7: TOTALIZER
A9: 1 | B9: PRODUCTION | E9: BEFORE | F9: AFTER | G9: TOTAL | H9: Yield ( % ) | I9: STATUS/REMAKS
B10: Refinery
B11: Running Days
B12: Incoming CPO
B13: Ratio Run CPO
B14: CPO Consume Total | C14: 2500 | D14: TPD | E14: 13533.82 | F14: 16053.42 | G14: =F14-E14 -> 2519.6 | I14: OK
B15: Avg Daily Consump CPO ( MTD )
B16: CPO Consume Poram | C16: 29045000
B17: CPO Consume Brand | C17: 7314000 | E17: =E53+E62+E67 -> 0
B18: - FFA | C18: 5 | D18: % | G18: 4
B19: - Moist & Impurities | C19: 0.5 | D19: % | G19: 0.41
B20: - DOBI | C20: 2.2 | D20: Min | G20: 2.42
B21: - TOTOX 2PV + AV | C21: 12 | D21: Max | G21: N/A
B22: - FE Content | C22: < 5 | D22: ppm | G22: N/A
B23: - PV | C23: < 4 | D23: Meg/kg | G23: N/A
B24: - Phosporus Max | C24: 25 | D24: ppm | G24: N/A
B25: TANK / TEMP | C25: 50 | D25: ˚C | G25: 50
B26: Product
B27: RBDPO | C27: =C14*94.2% -> 2355 | D27: TPD | E27: 12357.54 | F27: 14705.95 | G27: =F27-E27 -> 2348.41 | H27: =G27/G14 -> 0.93205668
B28: - FFA | C28: 0.05 | D28: % | G28: 0.06
B29: - Moist & Impurities | C29: 0.03 | D29: % | G29: 0.05
B30: - Peroxide value | D30: Nil | G30: -
B31: - Phosporous max | C31: 2 | D31: ppm | G31: N/A
B32: - LC | C32: 2.5 | D32: % | G32: 2.5
B33: - Aom stability min ( hr ) | C33: 60 | D33: min ( hr ) | G33: N/A
B34: - teste & Odor | C34: bland/Odorless | G34: N/A
B35: - temp max ( C ) | C35: 50 | D35: max˚C | G35: 50
B36: PFAD | C36: =C14*5% -> 125 | D36: TPD | E36: 572.71 | F36: 675.39 | G36: =F36-E36 -> 102.68 | H36: =G36/G14 -> 0.0407525
B37: Fractionation
B38: Running Days
B39: Filling Langsung CR Fr Refinery | E39: 0
B40: Total Filling Crystalizer ( Feed ) | E40: 392100
B41: Avg Daily Consump RPO ( MTD )
...

Sheet peformance  test REFINERY 2
A1: REFINERY PMG 2
A2: No | B2: ITEM | C2: Norma LIPICO | D2: UOM | E2: Day 2 tanggal 12/12/2024
A4: 1 | B4: PRODUCTION | E4: BEFORE | F4: AFTER | G4: TOTAL | H4: Yield ( % )
B5: Refinery
B6: Running Days
B7: Incoming CPO
B8: Ratio Run CPO
B9: CPO Consume Total | C9: 2500 | D9: TPD | E9: 5880.74 | F9: 8383.74 | G9: =F9-E9 -> 2503 | H9: =G9/2500000*100000 -> 100.12
B10: Avg Daily Consump CPO ( MTD )
B11: CPO Consume Poram | C11: 29045000
B12: CPO Consume Brand | C12: 7314000 | E12: =E43+E52+E57 -> 0
B13: - FFA | C13: 5 | D13: % | G13: 3.97
B14: - Moist & Impurities | C14: 0.5 | D14: % | G14: 0.4
B15: - DOBI | C15: 2.2 | D15: Min | G15: 2.42
B16: TANK | G16: 105
B17: Product
B18: OIP RBDPO
B19: RBDPO | C19: =C9*94.2% -> 2355 | D19: TPD | E19: 5143.38 | F19: 7493.18 | G19: =F19-E19 -> 2349.8 | H19: =G19/G9*100 -> 93.879345
B20: - FFA | C20: 0.05 | D20: % | G20: 0.043
B21: - Moist & Impurities | C21: 0.03 | D21: % | G21: 0.04
B22: - LC | C22: 2.5 | D22: % | G22: 2.5
B23: - Aom stability min ( hr ) | C23: 60 | D23: min ( hr )
B24: - teste & Odor | C24: bland/Odorless
B25: - temp max ( C ) | C25: 50 | D25: max˚C
B26: PFAD | C26: =C9*5% -> 125 | D26: TPD | E26: 243.04 | F26: 347.1 | G26: =F26-E26 -> 104.06 | H26: =G26/G9*100 -> 4.1574111
B27: Fractionation
B28: Running Days
B29: Filling Langsung CR Fr Refinery | E29: 0
B30: Total Filling Crystalizer ( Feed ) | E30: 392100
B31: Avg Daily Consump RPO ( MTD )
B32: Total Proses RBDPO | E32: =SUM(E35,E39,E44,E48,E58) -> 0
B33: Sisa Filling Crystalizer | E33: =E30-E32 -> 392100
B34: Fractionation OLEIN IV 56
B35: RBDPO Consume | E35: =E36+E37 -> 0
B36: OLEIN IV 56 | E36: 0
B37: STEARIN | E37: 0
B38: Fractionation OLEIN IV 57 ( Bulk )
B39: RBDPO Consume | E39: =E40+E41 -> 0
B40: OLEIN IV 57 | E40: 0
B41: STEARIN | E41: 0
...

Sheet HPP REF 
B2: Refinery Cost
B3: Through Put CPO Proses | N3: =('Januari 2026 PMG 2'!AM10)/1000 -> 2006.269 | O3: TPD
B4: Working Day | N4: ='Januari 2026 PMG 2'!AM6 -> 20 | O4: Days
B5: Total CPO Process | N5: =N4*N3 -> 40125.38 | O5: MTD
B6: KURS | N6: 16000 | O6: Rp/USD
B7: No | C7: Item Cost | D7: Norma | F7: Pemakaian / Hari | H7: HK | J7: Total Pemakaian | K7: Harga / stn | M7: Total Biaya | N7: Rp / kg | O7: USD/MT
B8: 1 | C8: Bleaching Earth | D8: ='Januari 2026 PMG 2'!$AM$76 -> 0.67460296 | F8: =($D$8*$N$3*10) -> 13534.35 | G8: Kg/day | H8: =$N$4 -> 20 | J8: =$H$8*$F$8 -> 270687 | K8: 4550 | M8: =$J$8*$K$8 -> 1.2316259e+09 | N8: =$M$8/($N$5*1000) -> 30.694435 | O8: =($M$8/$N$6)/$N$5 -> 1.9184022
B9: 2 | C9: Phosporic acid | D9: ='Januari 2026 PMG 2'!$AM$87 -> 0.60967796 | F9: =($D$9*$N$3*10) -> 12231.78 | G9: Kg/day | H9: =$H$8 -> 20 | J9: =$H$9*$F$9 -> 244635.6 | K9: 17420 | M9: =$J$9*$K$9 -> 4261552152 | N9: =$M$9/($N$5*1000) -> 106.2059 | O9: =($M$9/$N$6)/$N$5 -> 6.6378688
B10: 3 | C10: Caustic Soda | D10: 29.166667 | E10: kg/day | F10: =D10 -> 29.166667 | G10: kg/day | H10: =$H$8 -> 20 | J10: =$H$10*$F$10 -> 583.33333 | K10: 15700 | M10: =$J$10*$K$10 -> 9158333.3 | N10: =$M$10/($N$5*1000) -> 0.22824291 | O10: =($M$10/$N$6)/$N$5 -> 0.014265182
B11: 4 | C11: Pemakaian Natural Gas HPB Geka
C12: Normal Consumption | D12: ='Januari 2026 PMG 2'!$AM$249 -> 0.10825282 | E12: MMBTU/MT CPO | F12: =$D$12*$N$3 -> 217.18428 | G12: MMBTU/day | H12: =$H$8 -> 20 | J12: =$H$12*$F$12 -> 4343.6855 | K12: =11.5*$N$6 -> 184000 | M12: =$J$12*$K$12 -> 7.9923814e+08 | N12: =$M$12/($N$5*1000) -> 19.918519 | O12: =($M$12/$N$6)/$N$5 -> 1.2449074
C13: Penalty Below Consumption | D13: 0 | E13: MMBTU/MT CPO | F13: =$D$13*$N$3 -> 0 | G13: MMBTU/day | H13: =$H$8 -> 20 | J13: =$H$13*$F$13 -> 0 | K13: =11.5*$N$6 -> 184000 | M13: =$J$13*$K$13 -> 0 | N13: =$M$13/($N$5*1000) -> 0 | O13: =($M$13/$N$6)/$N$5 -> 0
C14: Penalty Above Consumption | D14: 0 | E14: MMBTU/MT CPO | F14: =$D$14*$N$3 -> 0 | G14: MMBTU/day | H14: =$H$8 -> 20 | J14: =$H$14*$F$14 -> 0 | K14: =11.5*$N$6 -> 184000 | M14: =$J$14*$K$14 -> 0 | N14: =$M$14/($N$5*1000) -> 0 | O14: =($M$14/$N$6)/$N$5 -> 0
B15: 5 | C15: Pemakaian Steam
C16: For Process | D16: ='Januari 2026 PMG 2'!AM256 -> 43131.305 | E16: Kg/MT CPO | F16: =$D$16*$N$3/1000 -> 86533 | G16: Ton/day | H16: =$H$8 -> 20 | J16: =$H$16*$F$16 -> 1730660 | K16: =Steam!H15 -> 45.029294 | M16: =$J$16*$K$16 -> 77930398 | N16: =$M$16/($N$5*1000) -> 1.9421722 | O16: =($M$16/$N$6)/$N$5 -> 0.12138576
C17: Storage Tank for Heating | D17: ='Januari 2026 PMG 2'!$AM$260 -> 69146.398 | E17: Kg/MT CPO | F17: =$D$17*$N$3/1000 -> 138726.27 | G17: Ton/day | H17: =$H$8 -> 20 | J17: =$H$17*$F$17 -> 2774525.5 | K17: =Steam!H15 -> 45.029294 | M17: =$J$17*$K$17 -> 1.2493492e+08 | N17: =$M$17/($N$5*1000) -> 3.1136135 | O17: =($M$17/$N$6)/$N$5 -> 0.19460084
B18: 6 | C18: Pemakaian Electrical
C19: For Process | D19: ='Januari 2026 PMG 2'!$AM$297 -> 6.4437271 | E19: kW/MT CPO | F19: =$D$19*$N$3 -> 12927.85 | G19: kW/day | H19: =$H$8 -> 20 | I19: 0 | J19: =$H$19*$F$19 -> 258557 | K19: 1550 | L19: =[1]Electric!H21 -> 3666.6667 | M19: =($F$19*$H$19*$K$19)+($F$19*$I$19*$L$19) -> 400763350 | N19: =$M$19/($N$5*1000) -> 9.9877771 | O19: =($M$19/$N$6)/$N$5 -> 0.62423607
C20: Cooling Tower | D20: ='Januari 2026 PMG 2'!$AM$299 -> 4.8851126 | E20: kW/MT CPO | F20: =$D$20*$N$3 -> 9800.85 | G20: kW/day | H20: =$H$8 -> 20 | I20: 0 | J20: =$H$20*$F$20 -> 196017 | K20: 1550 | L20: =L19 -> 3666.6667 | M20: =(F20*H20*K20)+(F20*I20*L20) -> 303826350 | N20: =$M$20/($N$5*1000) -> 7.5719246 | O20: =($M$20/$N$6)/$N$5 -> 0.47324528
C21: Storage Tank | D21: 0.3377877 | E21: kW/MT CPO | F21: =$D$21*$N$3 -> 677.69299 | G21: kW/day | H21: =$H$8 -> 20 | I21: 0 | J21: =$H$21*$F$21 -> 13553.86 | K21: 1550 | L21: =L20 -> 3666.6667 | M21: =($F$21*$H$21*$K$21)+($F$21*$I$21*$L$21) -> 21008483 | N21: =$M$21/($N$5*1000) -> 0.52357093 | O21: =($M$21/$N$6)/$N$5 -> 0.032723183
B22: 7 | C22: Pemakaian Water
C23: Make Up CT | D23: ='Januari 2026 PMG 2'!$AM$274 -> 0.10634167 | E23: M3/day | F23: =$D$23 -> 0.10634167 | G23: M3/day | H23: =$H$8 -> 20 | J23: =$H$23*$F$23 -> 2.1268334 | K23: =WTP!H13 -> 25239.326 | M23: =$J$23*$K$23 -> 53679.843 | N23: =$M$23/($N$5*1000) -> 0.0013378027 | O23: =($M$23/$N$6)/$N$5 -> 8.3612671e-05
B24: 8 | C24: Chemical Water | N24: =$M$24/($N$5*1000) -> 0 | O24: =($M$24/$N$6)/$N$5 -> 0
C25: EONBAC BC 3108 | D25: 0.4 | E25: Kg/day | F25: =D25 -> 0.4 | G25: Kg/day | H25: =$H$8 -> 20 | J25: =$H$25*$F$25 -> 8 | K25: 27240 | M25: =$J$25*$K$25 -> 217920 | N25: =$M$25/($N$5*1000) -> 0.0054309766 | O25: =($M$25/$N$6)/$N$5 -> 0.00033943604
C26: EONLINE T722 | D26: 0.66 | E26: Kg/day | F26: =D26 -> 0.66 | G26: Kg/day | H26: =$H$8 -> 20 | J26: =$H$26*$F$26 -> 13.2 | K26: 29120 | M26: =$J$26*$K$26 -> 384384 | N26: =$M$26/($N$5*1000) -> 0.0095795728 | O26: =($M$26/$N$6)/$N$5 -> 0.0005987233
C27: EONLINE AG5770 | D27: 0.41 | E27: Kg/day | F27: =D27 -> 0.41 | G27: Kg/day | H27: =$H$8 -> 20 | J27: =$H$27*$F$27 -> 8.2 | K27: 117212 | M27: =$J$27*$K$27 -> 961138.4 | N27: =$M$27/($N$5*1000) -> 0.023953378 | O27: =($M$27/$N$6)/$N$5 -> 0.0014970861
C28: EONScale T2511 | D28: 0.1 | E28: Kg/day | F28: =D28 -> 0.1 | G28: Kg/day | H28: =$H$8 -> 20 | J28: =$H$28*$F$28 -> 2 | K28: 45940 | M28: =$J$28*$K$28 -> 91880 | N28: =$M$28/($N$5*1000) -> 0.0022898226 | O28: =($M$28/$N$6)/$N$5 -> 0.00014311391
B29: 9 | C29: Others
C30: Filter Bag 10 Microne | D30: 0.90361446 | E30: Pcs/day | F30: =D30 -> 0.90361446 | G30: Pcs/day | H30: =$H$8 -> 20 | J30: =$H$30*$F$30 -> 18.072289 | K30: 40000 | M30: =$J$30*$K$30 -> 722891.57 | N30: =$M$30/($N$5*1000) -> 0.018015819 | O30: =($M$30/$N$6)/$N$5 -> 0.0011259887
C31: Filter Bag 100 Microne | D31: 0.63253012 | E31: Pcs/day | F31: =D31 -> 0.63253012 | G31: Pcs/day | H31: =$H$8 -> 20 | J31: =$H$31*$F$31 -> 12.650602 | K31: 125000 | M31: =$J$31*$K$31 -> 1581325.3 | N31: =$M$31/($N$5*1000) -> 0.039409603 | O31: =($M$31/$N$6)/$N$5 -> 0.0024631002
C32: Filter Cartridge 10 Microne | D32: 1.5666667 | E32: Pcs/day | F32: =D32 -> 1.5666667 | G32: Pcs/day | H32: =$H$8 -> 20 | J32: =$H$32*$F$32 -> 31.333333 | K32: 145000 | M32: =$J$32*$K$32 -> 4543333.3 | N32: =$M$32/($N$5*1000) -> 0.11322842 | O32: =($M$32/$N$6)/$N$5 -> 0.0070767762
C33: Filter Dustbag | D33: 0.12048193 | E33: Pcs/day | F33: =D33 -> 0.12048193 | G33: Pcs/day | H33: =$H$8 -> 20 | J33: =$H$33*$F$33 -> 2.4096386 | K33: 682500 | M33: =$J$33*$K$33 -> 1644578.3 | N33: =$M$33/($N$5*1000) -> 0.040985987 | O33: =($M$33/$N$6)/$N$5 -> 0.0025616242
C34: O Ring Filter Leaves | D34: 3.6144578 | E34: Pcs/day | F34: =D34 -> 3.6144578 | G34: Pcs/day | H34: =$H$8 -> 20 | J34: =$H$34*$F$34 -> 72.289157 | K34: 14500 | M34: =$J$34*$K$34 -> 1048192.8 | N34: =$M$34/($N$5*1000) -> 0.026122937 | O34: =($M$34/$N$6)/$N$5 -> 0.0016326836
B35: 10 | C35: Waste Water Treatment Plant ( WWTP ) | D35: ='Januari 2026 PMG 2'!E279 -> 330 | E35: M3/day | F35: =D35 -> 330 | G35: M3/day | H35: =$H$8 -> 20 | J35: =$H$35*$F$35 -> 6600 | K35: =WWTP!H17 -> 971.17576 | M35: =$J$35*$K$35 -> 6409760 | N35: =$M$35/($N$5*1000) -> 0.15974329 | O35: =($M$35/$N$6)/$N$5 -> 0.0099839553
B36: 11 | C36: SHE
C37: SBE | D37: ='Januari 2026 PMG 2'!$AM$91 -> 273050.1 | E37: Kg/day | F37: =D37 -> 273050.1 | G37: Kg/day | H37: =$H$8 -> 20 | J37: =$F$37 -> 273050.1 | K37: 0 | M37: =$J$37*$K$37 -> 0 | N37: =$M$37/($N$5*1000) -> 0 | O37: =($M$37/$N$6)/$N$5 -> 0
C38: Domestic | D38: 0.1 | E38: Trip/day | F38: =D38 -> 0.1 | G38: Trip/day | H38: =$H$8 -> 20 | J38: =$H$38*$F$38 -> 2 | K38: 303030.3 | M38: =$J$38*$K$38 -> 606060.61 | N38: =$M$38/($N$5*1000) -> 0.015104171 | O38: =($M$38/$N$6)/$N$5 -> 0.0009440107
B39: 12 | C39: Chemical Consumption | N39: =$M$39/($N$5*1000) -> 0 | O39: =($M$39/$N$6)/$N$5 -> 0
C40: LAB Chemical | D40: =lab!H33 -> 745255.21 | E40: Rp/day | F40: =D40 -> 745255.21 | G40: Rp/day | H40: =$H$8 -> 20 | M40: =$H$40*$F$40 -> 14905104 | N40: =$M$40/($N$5*1000) -> 0.37146325 | O40: =($M$40/$N$6)/$N$5 -> 0.023216453
C41: Chemical Boiler dan WTP | D41: =lab!H54 -> 259161.44 | E41: Rp/day | F41: =D41 -> 259161.44 | G41: Rp/day | H41: =$H$8 -> 20 | M41: =$H$41*$F$41 -> 5183228.9 | N41: =$M$41/($N$5*1000) -> 0.12917582 | O41: =($M$41/$N$6)/$N$5 -> 0.0080734888
...

Sheet HPP FRACT
B2: Fractionation Cost
B3: RPO Proses / Day | N3: TPD | O3: ='Januari 2026 PMG 2'!AM24/1000 -> 1775.536
B4: Working Day | N4: Days | O4: ='Januari 2026 PMG 2'!AM23 -> 29
B5: Total CPO Process | N5: MTD | O5: =O3*O4 -> 51490.545
B6: KURS | N6: Rp/USD | O6: 16000
B7: No | C7: Item Cost | D7: Norma | F7: Pemakaian / Hari | H7: HK | J7: Total Pemakaian | K7: Harga / stn | M7: Total Biaya | N7: Rp / kg | O7: USD/MT
B8: 1 | C8: Steam | D8: ='Januari 2026 PMG 2'!AM258 -> 21310.98 | E8: Kg/MT CPO | F8: =$D$8*$O$3/1000 -> 37838.414 | G8: Ton/day | H8: =$O$4 -> 29 | J8: =$H$8*$F$8 -> 1097314 | K8: =Steam!H15 -> 45.029294 | M8: =$K$8*$J$8 -> 49411275 | N8: =$M$8/($O$5*1000) -> 0.9596184 | O8: =($M$8/$O$6)/$O$5 -> 0.05997615
B9: 2 | C9: Electrical
C10: For Process | D10: ='Januari 2026 PMG 2'!$AM$304 -> 4.3139057 | E10: kW/MT CPO | F10: =$D$10*$O$3 -> 7659.495 | G10: kW/day | H10: =$O$4 -> 29 | I10: 0 | J10: =$H$10*$F$10 -> 222125.35 | K10: =[1]Electric!$L$5 -> 1550 | L10: 3666.6667 | M10: =($F$10*$H$10*$K$10)+($F$10*$I$10*$L$10) -> 3.442943e+08 | N10: =$M$10/($O$5*1000) -> 6.6865538 | O10: =($M$10/$O$6)/$O$5 -> 0.41790961
C11: Cooling Tower | D11: ='Januari 2026 PMG 2'!$AM$302 -> 5.7170954 | E11: kW/MT CPO | F11: =$D$11*$O$3 -> 10150.909 | G11: kW/day | H11: =$H$10 -> 29 | I11: 0 | J11: =$H$11*$F$11 -> 294376.36 | K11: =$K$10 -> 1550 | L11: 3666.6667 | M11: =($F$11*$H$11*$K$11)+($F$11*$I$11*$L$11) -> 4.5628336e+08 | N11: =$M$11/($O$5*1000) -> 8.8614979 | O11: =($M$11/$O$6)/$O$5 -> 0.55384362
B12: 3 | C12: Water
C13: Make Up CT | D13: ='Januari 2026 PMG 2'!$AM$276 -> 0.047309657 | E13: M3/day | F13: =$D$13 -> 0.047309657 | G13: M3/day | H13: =$H$11 -> 29 | J13: =$H$13*$F$13 -> 1.37198 | K13: =WTP!H13 -> 25239.326 | M13: =$K$13*$J$13 -> 34627.852 | N13: =$M$13/($O$5*1000) -> 0.00067250894 | O13: =($M$13/$O$6)/$O$5 -> 4.2031809e-05
B14: 4 | C14: Chemical Water
C15: EONBAC BC 3108 | D15: 0.4 | E15: Kg/day | F15: =$D$15 -> 0.4 | G15: Kg/day | H15: =$H$13 -> 29 | J15: =$H$15*$F$15 -> 11.6 | K15: 27240 | M15: =$K$15*$J$15 -> 315984 | N15: =$M$15/($O$5*1000) -> 0.0061367383 | O15: =($M$15/$O$6)/$O$5 -> 0.00038354614
C16: EONLINE T722 | D16: 0.66 | E16: Kg/day | F16: =$D$16 -> 0.66 | G16: Kg/day | H16: =$H$15 -> 29 | J16: =$H$16*$F$16 -> 19.14 | K16: 29120 | M16: =$K$16*$J$16 -> 557356.8 | N16: =$M$16/($O$5*1000) -> 0.010824449 | O16: =($M$16/$O$6)/$O$5 -> 0.00067652809
C17: EONLINE AG5770 | D17: 0.41 | E17: Kg/day | F17: =$D$17 -> 0.41 | G17: Kg/day | H17: =$H$15 -> 29 | J17: =$H$17*$F$17 -> 11.89 | K17: 117212 | M17: =$K$17*$J$17 -> 1393650.7 | N17: =$M$17/($O$5*1000) -> 0.027066147 | O17: =($M$17/$O$6)/$O$5 -> 0.0016916342
C18: EONScale T2511 | D18: 0.1 | E18: Kg/day | F18: =$D$18 -> 0.1 | G18: Kg/day | H18: =$H$16 -> 29 | J18: =$H$18*$F$18 -> 2.9 | K18: 45940 | M18: =$K$18*$J$18 -> 133226 | N18: =$M$18/($O$5*1000) -> 0.0025873876 | O18: =($M$18/$O$6)/$O$5 -> 0.00016171173
B19: 5 | C19: Others
C20: Filter Cloth | D20: 0.33333333 | E20: Pcs/day | F20: =$D$20 -> 0.33333333 | G20: Pcs/day | H20: =$H$18 -> 29 | J20: =$H$20*$F$20 -> 9.6666667 | K20: 895000 | M20: =$K$20*$J$20 -> 8651666.7 | N20: =$M$20/($O$5*1000) -> 0.16802438 | O20: =($M$20/$O$6)/$O$5 -> 0.010501523
C21: Filter Bag 100 Microne | D21: 0.63253012 | E21: Pcs/day | F21: =$D$21 -> 0.63253012 | G21: Pcs/day | H21: =$H$20 -> 29 | J21: =$H$21*$F$21 -> 18.343373 | K21: 125000 | M21: =$K$21*$J$21 -> 2292921.7 | N21: =$M$21/($O$5*1000) -> 0.044530927 | O21: =($M$21/$O$6)/$O$5 -> 0.0027831829
M22: =SUM(M8:M21) -> 8.6336836e+08 | N22: =SUM(N8:N21) -> 16.767513 | O22: =SUM($O$8:$O$21) -> 1.0479695

Sheet SUMMARY HPP 
B2: Production Cost OKTOBER 2025
B3: Through Put CPO Proses (Ton/Day) | H3: TPD | I3: ='HPP REF '!$N$3 -> 2006.269
B4: Working Day | F4: 1 | H4: Days | I4: ='HPP REF '!$N$4 -> 20
B5: Refined CPO ( Ton/month ) | H5: MTD | I5: =$I$4*$I$3 -> 40125.38
B6: Through Put RPO Proses (Ton/Day) | H6: TPD | I6: ='HPP FRACT'!$O$3 -> 1775.536
B7: Working Day | H7: Days | I7: ='HPP FRACT'!$O$4 -> 29
B8: Fract RPO ( ton/month ) | H8: MTD | I8: =$I$7*$I$6 -> 51490.545
B9: KURS | H9: Rp/USD | I9: 16000
B10: No | C10: Items | D10: Description | G10: Rupiah | H10: Rp/Kg | I10: USD/MT
B11: I | C11: Production Cost | D11: ● | E11: Refining Cost | G11: ='HPP REF '!$M$48 -> 7.2719271e+09 | H11: =$G$11/($I$5*1000) -> 181.23011 | I11: =(G11/$I$9)/$I$5 -> 11.326882
D12: ● | E12: Fractionation Cost | G12: ='HPP FRACT'!$M$22 -> 8.6336836e+08 | H12: =$G$12/($I$8*1000) -> 16.767513 | I12: =(G12/$I$9)/$I$8 -> 1.0479695
D13: ● | E13: Preventive Maintenance Cost | F13: 0 | G13: =MTC!$F$18*F13 -> 0 | H13: =$G$13/($I$5*1000) -> 0 | I13: =(G13/$I$9)/$I$5 -> 0
G14: =SUM(G11:$G$13) -> 8.1352955e+09 | H14: =SUM($H$11:$H$13) -> 197.99762 | I14: =SUM(I11:I13) -> 12.374852
B16: II | C16: Port Cost | D16: ● | E16: Trucking Komoditi ke Kuala Tanjung | G16: =LOG!I8+LOG!I9+LOG!$I$10 -> 4.1659775e+09 | H16: =$G$16/($I$5*1000) -> 103.824 | I16: =($G$16/$I$9)/$I$5 -> 6.489
D17: ● | E17: Sewa Tank PTI Total Volume : 24.000 MT ( 5 Unit ) | F17: =F4 -> 1 | G17: =LOG!I11+LOG!I12+LOG!I13+LOG!$I$14*F17 -> 1886000000 | H17: =$G$17/($I$5*1000) -> 47.00267 | I17: =($G$17/$I$9)/$I$5 -> 2.9376669
D18: ● | E18: Instalasi & Pemanasan, Pompa, Surveyor dan Documen | G18: =LOG!I18+LOG!I19+LOG!I20+LOG!$I$21 -> 2.1494364e+09 | H18: =$G$18/($I$5*1000) -> 53.568 | I18: =($G$18/$I$9)/$I$5 -> 3.348
D19: ● | E19: Finalty Over Capacity Tank | G19: =LOG!I15+LOG!I16+LOG!$I$17 -> 1.7115882e+09 | H19: =$G$19/($I$5*1000) -> 42.656 | I19: =($G$19/$I$9)/$I$5 -> 2.666
G20: =SUM($G$16:$G$19) -> 9.913002e+09 | H20: =SUM($H$16:$H$19) -> 247.05067 | I20: =SUM($I$16:$I$19) -> 15.440667
B22: II | C22: Fix Cost | D22: ● | E22: Manpower Cost | F22: =F4 -> 1 | G22: =[1]MPC!$H$29*$F$22 -> 2.1846655e+09 | H22: =$G$22/($I$5*1000) -> 54.445977 | I22: =($G$22/$I$9)/$I$5 -> 3.4028736
D23: ● | E23: Admin OH Cost | F23: =F4 -> 1 | G23: =OH!G51*$F$23 -> 1.4360564e+09 | H23: =$G$23/($I$5*1000) -> 35.789228 | I23: =($G$23/$I$9)/$I$5 -> 2.2368268
D24: ● | E24: Depresiasi Cost | F24: =F4 -> 1 | G24: =DEP!I9*$F$24 -> 4.1811848e+09 | H24: =$G$24/($I$5*1000) -> 104.203 | I24: =($G$24/$I$9)/$I$5 -> 6.5126872
D25: ● | E25: Amortisation of leasehold land Cost | F25: =F4 -> 1 | G25: =AMOR!$G$20*$F$25 -> 1.0484098e+09 | H25: =$G$25/($I$5*1000) -> 26.128346 | I25: =($G$25/$I$9)/$I$5 -> 1.6330216
G26: =SUM($G$22:$G$25) -> 8.8503165e+09 | H26: =SUM($H$22:$H$25) -> 220.56655 | I26: =SUM($I$22:$I$25) -> 13.785409
B28: Total Production Cost | G28: =$G$26+$G$20+$G$14 -> 2.6898614e+10 | H28: =$H$26+$H$20+$H$14 -> 665.61484 | I28: =$I$26+$I$20+$I$14 -> 41.600928

Sheet Lembar1

Sheet OIP Fract PMG 1
A4: Oil In Plant (OIP) Fraksinasi | I4: OIP | S4: BUFFER TANK | W4: DIRECT
A5: RBDPO OIP | I5: RPO CR | M5: OLEIN | P5: STEARIN | S5: TK131 RPO | U5: TK132 RPO
A6: Vessel | B6: Operating Volume (m3) | C6: Oil Density (kg/m3) | D6: MT | E6: Level Transmitter (1%/MT) | F6: Level (%) | G6: Kg | I6: Tanggal | J6: Opening Stock | K6: Closing Stock | L6: balance stok | M6: Opening Stock | N6: Closing Stock | O6: balance stok | P6: Opening Stock | Q6: Closing Stock | R6: balance stok | S6: Opening Stock | T6: Closing Stock | U6: Opening Stock | V6: Closing Stock
A7: 2CR1201 | B7: 70.51 | C7: 890 | D7: 60 | E7: =D7/100 -> 0.6 | F7: 0 | G7: =E7*F7*1000 -> 0 | I7: 46023
A8: 2CR1202 | B8: 70.51 | C8: 890 | D8: 60 | E8: =D8/100 -> 0.6 | F8: 0 | G8: =E8*F8*1000 -> 0 | I8: 46024
A9: 2CR1203 | B9: 70.51 | C9: 890 | D9: 60 | E9: =D9/100 -> 0.6 | F9: 0 | G9: =E9*F9*1000 -> 0 | I9: 46025
A10: 2CR1204 | B10: 70.51 | C10: 890 | D10: 60 | E10: =D10/100 -> 0.6 | F10: 0 | G10: =E10*F10*1000 -> 0 | I10: 46026
A11: 2CR1205 | B11: 70.51 | C11: 890 | D11: 60 | E11: =D11/100 -> 0.6 | F11: 0 | G11: =E11*F11*1000 -> 0 | I11: 46027
A12: 2CR1206 | B12: 70.51 | C12: 890 | D12: 60 | E12: =D12/100 -> 0.6 | F12: 0 | G12: =E12*F12*1000 -> 0 | I12: 46028
A13: 2CR1207 | B13: 70.51 | C13: 890 | D13: 60 | E13: =D13/100 -> 0.6 | F13: 0 | G13: =E13*F13*1000 -> 0 | I13: 46029
A14: 2CR1208 | B14: 70.51 | C14: 890 | D14: 60 | E14: =D14/100 -> 0.6 | F14: 0 | G14: =E14*F14*1000 -> 0 | I14: 46030
A15: 2CR1209 | B15: 70.51 | C15: 890 | D15: 60 | E15: =D15/100 -> 0.6 | F15: 0 | G15: =E15*F15*1000 -> 0 | I15: 46031
A16: 2CR1210 | B16: 70.51 | C16: 890 | D16: 60 | E16: =D16/100 -> 0.6 | F16: 0 | G16: =E16*F16*1000 -> 0 | I16: 46032 | K16: 168670
A17: 2CR1211 | B17: 70.51 | C17: 890 | D17: 60 | E17: =D17/100 -> 0.6 | F17: 0 | G17: =E17*F17*1000 -> 0 | I17: 46033 | J17: =K16 -> 168670 | K17: 0
A18: 2CR1212 | B18: 70.51 | C18: 890 | D18: 60 | E18: =D18/100 -> 0.6 | F18: 0 | G18: =E18*F18*1000 -> 0 | I18: 46034 | J18: =K17 -> 0
A19: 2CR1213 | B19: 70.51 | C19: 890 | D19: 60 | E19: =D19/100 -> 0.6 | F19: 0 | G19: =E19*F19*1000 -> 0 | I19: 46035 | J19: =K18 -> 0
A20: 2CR1214 | B20: 70.51 | C20: 890 | D20: 60 | E20: =D20/100 -> 0.6 | F20: 0 | G20: =E20*F20*1000 -> 0 | I20: 46036 | J20: =K19 -> 0
A21: 2CR1215 | B21: 70.51 | C21: 890 | D21: 60 | E21: =D21/100 -> 0.6 | F21: 0 | G21: =E21*F21*1000 -> 0 | I21: 46037 | J21: =K20 -> 0
I22: 46038 | J22: =K21 -> 0 | K22: 287700
F23: Total RBDPO | G23: =SUM(G7:G21) -> 0 | I23: 46039 | J23: =K22 -> 287700 | K23: 446900
I24: 46040 | J24: =K23 -> 446900 | K24: 446900
A25: Olein OIP | I25: 46041 | J25: 416900 | K25: 416900
A26: Vessel | B26: Operating Volume (m3) | C26: Oil Density (kg/m3) | D26: MT | E26: Level Transmitter (1%/MT) | F26: Level (%) | G26: Kg | I26: 46042
A27: 2TK261 | B27: 15.95 | C27: 885 | D27: =B27*C27/1000 -> 14.11575 | E27: =D27/100 -> 0.1411575 | G27: =E27*F27*1000 -> 0 | I27: 46043
A28: 2CL251 | B28: 3.02 | C28: 885 | D28: =B28*C28/1000 -> 2.6727 | E28: =D28/100 -> 0.026727 | G28: =E28*F28*1000 -> 0 | I28: 46044
A29: 2TK221 | B29: 82.48 | C29: 885 | D29: =B29*C29/1000 -> 72.9948 | E29: =D29/100 -> 0.729948 | G29: =E29*F29*1000 -> 0 | I29: 46045
A30: 2TK241 | B30: 16.95 | C30: 885 | D30: =B30*C30/1000 -> 15.00075 | E30: =D30/100 -> 0.1500075 | G30: =E30*F30*1000 -> 0 | I30: 46046
F31: Total Olein | G31: =SUM(G27:G30) -> 0 | I31: 46047
I32: 46048 | K32: 402210 | N32: 37360
I33: 46049 | J33: =K32 -> 402210 | K33: 309830 | M33: =N32 -> 37360 | N33: =280+1278+1358 -> 2916
I34: 46050 | J34: =K33 -> 309830 | M34: =N33 -> 2916
I35: 46051
I36: 46052
I37: 46053
A39: Stearin OIP
A40: Melting Tank | B40: Panjang (m) | C40: Lebar (m) | D40: tinggi (m) | E40: Density | F40: Tinggi Sounding (Cm) Maks 4,4 m | G40: Kg
A41: TK231 A | B41: 12.2 | C41: 1.75 | D41: 1.52 | E41: 0.88 | F41: 0 | G41: =B41*C41*D41*E41*F41/100 -> 0
A42: TK231 B | B42: 12.2 | C42: 1.75 | D42: 1.52 | E42: 0.88 | F42: 0 | G42: =B42*C42*D42*E42*F42/100 -> 0
F43: Total STEARIN | G43: =SUM(G41:G42) -> 0

Sheet Convert Gas
B3: CONVERT PEMAKAIAN GAS HP BOILER & MP BOILER
B4: Januari 2026
B5: Tanggal | C5: HP BOILER | F5: TOTAL CORRECTED VOLUME (Sm3) | K5: ENERGY MP BOILER (MMBTU) | L5: TOTAL GAS CONSUMPTION (MMBTU) | M5: PERCENTAGE
C6: UNCORRECTED VOLUME (UV) (Nm3) | D6: PRESS. Bar | E6: CORRECTED VOLUME (CV) (Sm3) | G6: Convert Sm3 to SCF | H6: VOLUME (MSCF) | I6: HEATING VALUE (BTU / SCF) | J6: ENERGY HP BOILER (MMBTU) | M6: HP Boiler | N6: MP Boiler
C7: 1 | D7: 2 | E7: 3 = 1 x 2 | F7: 4 = 3 | G7: 5 | H7: 6 = (4 x 5) / 1000 | I7: 7 | J7: 8 = (6 x 7) / 1000 | K7: 9 = 10 - 8 | L7: 10 | M7: 11 = 8 / 10 | N7: 12 = 9 / 10
B8: 1 | C8: 5430 | D8: 5 | E8: =C8*D8 -> 27150 | F8: =E8 -> 27150 | G8: 35.314667 | H8: =(F8*G8)/1000 -> 958.79321 | I8: 1039.3855 | J8: =(H8*I8)/1000 -> 996.55575 | K8: =L8-J8 -> -181.40615 | L8: ='Januari 2026 PMG 2'!G242 -> 815.1496 | M8: =(J8/L8) -> 1.2225434 | N8: =K8/L8 -> -0.22254338
B9: =B8+1 -> 2 | C9: 5479 | D9: 5 | E9: =C9*D9 -> 27395 | F9: =E9 -> 27395 | G9: 35.314667 | H9: =(F9*G9)/1000 -> 967.4453 | I9: 1051.3796 | J9: =(H9*I9)/1000 -> 1017.1523 | K9: =L9-J9 -> -134.18438 | L9: ='Januari 2026 PMG 2'!H242 -> 882.9679 | M9: =(J9/L9) -> 1.1519697 | N9: =K9/L9 -> -0.15196972
B10: =B9+1 -> 3 | C10: 5420 | D10: 5 | E10: =C10*D10 -> 27100 | F10: =E10 -> 27100 | G10: 35.314667 | H10: =(F10*G10)/1000 -> 957.02748 | I10: 1051.0228 | J10: =(H10*I10)/1000 -> 1005.8577 | K10: =L10-J10 -> -100.18902 | L10: ='Januari 2026 PMG 2'!I242 -> 905.6687 | M10: =(J10/L10) -> 1.1106244 | N10: =K10/L10 -> -0.11062436
B11: =B10+1 -> 4 | C11: 199 | D11: 5 | E11: =C11*D11 -> 995 | F11: =E11 -> 995 | G11: 35.314667 | H11: =(F11*G11)/1000 -> 35.138094 | I11: 1054.8217 | J11: =(H11*I11)/1000 -> 37.064422 | K11: =L11-J11 -> 533.54988 | L11: ='Januari 2026 PMG 2'!J242 -> 570.6143 | M11: =(J11/L11) -> 0.064955298 | N11: =K11/L11 -> 0.9350447
B12: =B11+1 -> 5 | C12: 0 | D12: 5 | E12: =C12*D12 -> 0 | F12: =E12 -> 0 | G12: 35.314667 | H12: =(F12*G12)/1000 -> 0 | I12: 1057.0889 | J12: =(H12*I12)/1000 -> 0 | K12: =L12-J12 -> 330.2773 | L12: ='Januari 2026 PMG 2'!K242 -> 330.2773 | M12: =(J12/L12) -> 0 | N12: =K12/L12 -> 1
B13: =B12+1 -> 6 | C13: 100 | D13: 5 | E13: =C13*D13 -> 500 | F13: =E13 -> 500 | G13: 35.314667 | H13: =(F13*G13)/1000 -> 17.657334 | I13: 1059.7585 | J13: =(H13*I13)/1000 -> 18.71251 | K13: =L13-J13 -> 403.37109 | L13: 422.0836 | M13: =(J13/L13) -> 0.044333658 | N13: =K13/L13 -> 0.95566634
B14: =B13+1 -> 7 | C14: 785.4 | D14: 5 | E14: =C14*D14 -> 3927 | F14: =E14 -> 3927 | G14: 35.314667 | H14: =(F14*G14)/1000 -> 138.6807 | I14: 1061.899 | J14: =(H14*I14)/1000 -> 147.2649 | K14: =L14-J14 -> 1118.9188 | L14: 1266.1837 | M14: =(J14/L14) -> 0.11630611 | N14: =K14/L14 -> 0.88369389
B15: =B14+1 -> 8 | C15: 769.5 | D15: 5 | E15: =C15*D15 -> 3847.5 | F15: =E15 -> 3847.5 | G15: 35.314667 | H15: =(F15*G15)/1000 -> 135.87318 | I15: 1061.7688 | J15: =(H15*I15)/1000 -> 144.2659 | K15: =L15-J15 -> 1204.7675 | L15: 1349.0334 | M15: =(J15/L15) -> 0.1069402 | N15: =K15/L15 -> 0.8930598
B16: =B15+1 -> 9 | D16: 5 | E16: =C16*D16 -> 0 | F16: =E16 -> 0 | G16: 35.314667 | H16: =(F16*G16)/1000 -> 0 | I16: 1061.1997 | J16: =(H16*I16)/1000 -> 0 | K16: =L16-J16 -> 0 | M16: =(J16/L16) -> #DIV/0! | N16: =K16/L16 -> #DIV/0!
B17: =B16+1 -> 10 | D17: 5 | E17: =C17*D17 -> 0 | F17: =E17 -> 0 | G17: 35.314667 | H17: =(F17*G17)/1000 -> 0 | I17: 1062.1747 | J17: =(H17*I17)/1000 -> 0 | K17: =L17-J17 -> 0 | M17: =(J17/L17) -> #DIV/0! | N17: =K17/L17 -> #DIV/0!
B18: =B17+1 -> 11 | D18: 5 | E18: =C18*D18 -> 0 | F18: =E18 -> 0 | G18: 35.314667 | H18: =(F18*G18)/1000 -> 0 | I18: 1061.2948 | J18: =(H18*I18)/1000 -> 0 | K18: =L18-J18 -> 0 | M18: =(J18/L18) -> #DIV/0! | N18: =K18/L18 -> #DIV/0!
B19: =B18+1 -> 12 | D19: 5 | E19: =C19*D19 -> 0 | F19: =E19 -> 0 | G19: 35.314667 | H19: =(F19*G19)/1000 -> 0 | I19: 1060.6908 | J19: =(H19*I19)/1000 -> 0 | K19: =L19-J19 -> 0 | M19: =(J19/L19) -> #DIV/0! | N19: =K19/L19 -> #DIV/0!
B20: =B19+1 -> 13 | D20: 5 | E20: =C20*D20 -> 0 | F20: =E20 -> 0 | G20: 35.314667 | H20: =(F20*G20)/1000 -> 0 | I20: 1054.3016 | J20: =(H20*I20)/1000 -> 0 | K20: =L20-J20 -> 0 | M20: =(J20/L20) -> #DIV/0! | N20: =K20/L20 -> #DIV/0!
B21: =B20+1 -> 14 | D21: 5 | E21: =C21*D21 -> 0 | F21: =E21 -> 0 | G21: 35.314667 | H21: =(F21*G21)/1000 -> 0 | I21: 1059.7623 | J21: =(H21*I21)/1000 -> 0 | K21: =L21-J21 -> 0 | M21: =(J21/L21) -> #DIV/0! | N21: =K21/L21 -> #DIV/0!
B22: =B21+1 -> 15 | D22: 5 | E22: =C22*D22 -> 0 | F22: =E22 -> 0 | G22: 36.314667 | H22: =(F22*G22)/1000 -> 0 | I22: 1063.1437 | J22: =(H22*I22)/1000 -> 0 | K22: =L22-J22 -> 0 | M22: =(J22/L22) -> #DIV/0! | N22: =K22/L22 -> #DIV/0!
B23: =B22+1 -> 16 | D23: 5 | E23: =C23*D23 -> 0 | F23: =E23 -> 0 | G23: 37.314667 | H23: =(F23*G23)/1000 -> 0 | I23: 1062.3756 | J23: =(H23*I23)/1000 -> 0 | K23: =L23-J23 -> 0 | M23: =(J23/L23) -> #DIV/0! | N23: =K23/L23 -> #DIV/0!
B24: =B23+1 -> 17 | D24: 5 | E24: =C24*D24 -> 0 | F24: =E24 -> 0 | G24: 38.314667 | H24: =(F24*G24)/1000 -> 0 | I24: 1056.7511 | J24: =(H24*I24)/1000 -> 0 | K24: =L24-J24 -> 0 | M24: =(J24/L24) -> #DIV/0! | N24: =K24/L24 -> #DIV/0!
B25: =B24+1 -> 18 | D25: 5 | E25: =C25*D25 -> 0 | F25: =E25 -> 0 | G25: 39.314667 | H25: =(F25*G25)/1000 -> 0 | I25: 1055.0821 | J25: =(H25*I25)/1000 -> 0 | K25: =L25-J25 -> 0 | M25: =(J25/L25) -> #DIV/0! | N25: =K25/L25 -> #DIV/0!
B26: =B25+1 -> 19 | D26: 5 | E26: =C26*D26 -> 0 | F26: =E26 -> 0 | G26: 40.314667 | H26: =(F26*G26)/1000 -> 0 | I26: 1057.166 | J26: =(H26*I26)/1000 -> 0 | K26: =L26-J26 -> 0 | M26: =(J26/L26) -> #DIV/0! | N26: =K26/L26 -> #DIV/0!
B27: =B26+1 -> 20 | D27: 5 | E27: =C27*D27 -> 0 | F27: =E27 -> 0 | G27: 41.314667 | H27: =(F27*G27)/1000 -> 0 | I27: 1061.4358 | J27: =(H27*I27)/1000 -> 0 | K27: =L27-J27 -> 0 | M27: =(J27/L27) -> #DIV/0! | N27: =K27/L27 -> #DIV/0!
... B38: =B37+1 -> 31 | D38: 5 | E38: =C38*D38 -> 0 | F38: =E38 -> 0 | G38: 51.314667 | H38: =(F38*G38)/1000 -> 0 | I38: 1083.7642 | J38: =(H38*I38)/1000 -> 0 | K38: =L38-J38 -> 0 | M38: =(J38/L38) -> #DIV/0! | N38: =K38/L38 -> #DIV/0!
B39: Average | F39: =E39 -> 0 | H39: =AVERAGE(H8:H38) -> 103.56824 | I39: =AVERAGE(I8:I38) -> 1062.8347 | J39: =AVERAGE(J8:J38) -> 108.60882 | K39: =AVERAGE(K8:K38) -> 102.42274 | L39: =AVERAGE(L8:L38) -> 817.74731 | M39: =AVERAGE(M8:M37) -> #DIV/0! | N39: =AVERAGE(N8:N37) -> #DIV/0!
B40: TOTAL | C40: =SUM(C8:C38) -> 18182.9 | E40: =SUM(E8:E38) -> 90914.5 | F40: =E40 -> 90914.5 | H40: =SUM(H8:H38) -> 3210.6153 | J40: =SUM(J8:J38) -> 3366.8735
B41: Koreksi
B42: Total Setelah Koreksi | H42: =H40+H41 -> 3210.6153 | J42: =J40+J41 -> 3366.8735
C44: CONVERT HP Boiler from Utility
C45: =C40 -> 18182.9 | D45: m3 | F45: =C40*5 -> 90914.5 | G45: 9983.7
C46: 5 | D46: bar | F46: 21286.9 | G46: =G45-C40 -> -8199.2
C47: =C45*C46 -> 90914.5 | D47: Sm3 | F47: =F45/F46 -> 4.2709131
C48: =#REF! -> #REF! | D48: Scf
C49: =(C47*C48)/1000 -> #REF! | D49: Volume (MSCF)
C50: =I39 -> 1062.8347 | D50: Heating Value
C51: =(C49*C50)/1000 -> #REF! | D51: Energy (mmbtu)

Sheet Januari 2026 PMG 2
C1: PRODUCTION REPORT PMG 2
C2: No | D2: ITEM | E2: Budget / Norma | F2: UoM | G2: Januari 2026 | AM2: TOTAL MONTHLY (Kg)
G3: 1 | H3: 2 | I3: 3 | J3: 4 | K3: 5 | L3: 6 | M3: 7 | N3: 8 | O3: 9 | P3: 10 | Q3: 11 | R3: 12 | S3: 13 | T3: 14 | U3: 15 | V3: 16 | W3: 17 | X3: 18 | Y3: 19 | Z3: 20 | AA3: 21 | AB3: 22 | AC3: 23 | AD3: 24 | AE3: 25 | AF3: 26 | AG3: 27 | AH3: 28 | AI3: 29 | AJ3: 30 | AK3: 31
C4: 1 | D4: PRODUCTION | AM4: Production | AO4: aktual refinery | AR4: opening stok rpo | AS4: =AS6+AS7+AS9 -> 80236
D5: Refinery | AM5: Refinery | AO5: cpo feed | AP5: =AM9 -> 40125380 | AR5: sisa rbpo tank
D6: Running Days | F6: Day | G6: 1 | H6: 1 | I6: 1 | J6: 1 | V6: 1 | W6: 1 | X6: 1 | Y6: 1 | Z6: 1 | AA6: 1 | AB6: 1 | AC6: 1 | AD6: 1 | AE6: 1 | AF6: 1 | AG6: 1 | AH6: 1 | AI6: 1 | AJ6: 1 | AK6: 1 | AM6: =SUM(G6:AK6) -> 20 | AO6: rpo prod | AP6: =AM20+AM19+AM18 -> 38270376 | AR6: tk 108 | AS6: 80236
D7: Incoming CPO | F7: Kg | G7: 0 | J7: 105280 | K7: 522460 | V7: 2298459 | W7: 1760050 | X7: 1100253 | Y7: 1170450 | Z7: 2354398 | AA7: 2685019 | AB7: 2794189 | AC7: 2277190 | AD7: 3746325 | AE7: 1563383 | AF7: 1263930 | AG7: 1485561 | AH7: 2164949 | AI7: 3173686 | AJ7: 1588046 | AK7: 3641207 | AM7: =SUM(G7:AK7) -> 35694835 | AU7: =AM7+'Januari 2026 PMG 1'!AM7 -> 57887356
D8: Ratio Run CPO ( utilisasi kapasitas ) | F8: % | G8: =G9/2500000 -> 0.7517528 | H8: =H9/2500000 -> 0.78712 | I8: =I9/2500000 -> 0.7869976 | J8: =J9/2500000 -> 0 | K8: =K9/2500000 -> 0 | L8: =L9/2500000 -> 0 | M8: =M9/2500000 -> 0 | N8: =N9/2500000 -> 0 | ... V8: =V9/2500000 -> 0.5465676 | W8: 0.8090604 | X8: 0 | Y8: =Y9/2500000 -> 0.8180376 | Z8: =Z9/2500000 -> 0.8255544 | AA8: =AA9/2500000 -> 0.8262308 | AB8: =AB9/2500000 -> 0.9176256 | AC8: =AC9/2500000 -> 0.9530264 | AD8: =AD9/2500000 -> 0.9034832 | AE8: =AE9/2500000 -> 0.9438852 | AF8: =AF9/2500000 -> 0.8196664 | ... AK8: =AK9/2500000 -> 0.8586632 | AM8: =AM9/2500000/AM6 -> 0.8025076
D9: CPO Consume Total | E9: 58900000 | F9: Kg | G9: 1879382 | H9: 1967800 | I9: 1967494 | J9: 0 | K9: 0 | V9: 1366419 | W9: 2328853 | X9: 2350380 | Y9: 2045094 | Z9: 2063886 | AA9: 2065577 | AB9: 2294064 | AC9: 2382566 | AD9: 2258708 | AE9: 2359713 | AF9: 2049166 | AG9: 2193352 | AH9: 2154090 | AI9: 2127237 | AJ9: 2124941 | AK9: 2146658 | AM9: =SUM(G9:AK9) -> 40125380
D10: Avg Daily Consump CPO ( MTD ) | AM10: =AM9/AM6 -> 2006269
D11: CPO Consume Poram | F11: Kg | G11: =G9-G12 -> 1879382 | H11: =H9-H12 -> 1967800 | I11: =I9-I12 -> 1967494 | J11: =J9-J12 -> 0 | K11: =K9-K12 -> 0 | L11: =L9-L12 -> 0 | M11: =M9-M12 -> 0 | N11: =N9-N12 -> 0 | ... AK11: =AK9-AK12 -> 2146658 | AM11: =SUM(G11:AK11) -> 40125380
D12: CPO Consume Brand | F12: Kg | G12: =G40+G49+G54 -> 0 | H12: =H40+H49+H54 -> 0 | I12: =I40+I49+I54 -> 0 | J12: =J40+J49+J54 -> 0 | K12: =K40+K49+K54 -> 0 | L12: =L40+L49+L54 -> 0 | M12: =M40+M49+M54 -> 0 | N12: =N40+N49+N54 -> 0 | ... R12: =R40+R49+R54 -> 0 | S12: 0 | T12: =T40+T49+T54 -> 0 | U12: =U40+U49+U54 -> 0 | V12: =V40+V49+V54 -> 0 | W12: 0 | X12: 0 | Y12: =Y40+Y49+Y54 -> 0 | Z12: =Z40+Z49+Z54 -> 0 | AA12: =AA40+AA49+AA54 -> 0 | AB12: =AB40+AB49+AB54 -> 0 | AC12: 0 | AD12: 0 | AE12: =AE40+AE49+AE54 -> 0 | AF12: =AF40+AF49+AF54 -> 0 | AG12: =AG40+AG49+AG54 -> 0 | AH12: =AH40+AH49+AH54 -> 0 | AM12: =SUM(G12:AK12) -> 0
D13: - FFA | E13: 5 | F13: % | G13: 4.1 | H13: =(4.15+3.97)/2 -> 4.06 | I13: 4.03 | J13: 0 | V13: 0 | W13: 4.24 | X13: 3.97 | Y13: =(4.09+3.48)/2 -> 3.785 | Z13: 4.13 | AA13: =(4.28+4.21)/2 -> 4.245 | AB13: 4.23 | AC13: 4.26 | AD13: =(4.5+3.89)/2 -> 4.195 | AE13: =(3.89+4.22)/2 -> 4.055 | AF13: 4.24 | AG13: =(5.67+4.42)/2 -> 5.045 | AH13: 4.12 | AI13: =(4.41+3.93)/2 -> 4.17 | AJ13: =(3.83+4.17)/2 -> 4 | AK13: =(4.16+4.44+3.71)/3 -> 4.1033333 | AM13: =SUM(G13:AK13)/AM6 -> 3.7489167 | AO13: rpo feed | AP13: =AP14+AP15 -> 39418618 | AR13: tk131 | AS13: ='OIP Fract PMG 2'!T13 -> 133300
D14: - Moist & Impurities | E14: 0.5 | F14: % | G14: 0.44 | H14: =(0.45+0.41)/2 -> 0.43 | I14: 0.43 | J14: 0 | V14: 0 | W14: 0.4 | X14: 0.4 | Y14: =(3.48+0.41)/2 -> 1.945 | Z14: 0.4 | AA14: =(0.41+0.44)/2 -> 0.425 | AB14: 0.45 | AC14: 0.46 | AD14: =(0.49+0.38)/2 -> 0.435 | AE14: =(0.4+0.39)/2 -> 0.395 | AF14: 0.4 | AG14: =(0.43+0.41)/2 -> 0.42 | AH14: 0.44 | AI14: =(0.4+0.36)/2 -> 0.38 | AJ14: =(0.41+0.46)/2 -> 0.435 | AK14: =(0.45+0.46+0.4)/3 -> 0.43666667 | AM14: =SUM(G14:AK14)/AM6 -> 0.45608333 | AO14: olein 56 | AP14: =AM33 -> 32649843 | AR14: tk132 | AS14: ='OIP Fract PMG 2'!U13 -> 0
D15: - DOBI | E15: 2,20 Min | F15: % | AM15: =SUM(G15:AK15)/AM6 -> 0 | AO15: stearin 56 | AP15: =AM34 -> 6768775 | AR15: after
D16: TANK | G16: 107 | H16: 107104 | I16: 104 | J16: 0 | V16: 0 | W16: 106 | X16: 107 | Y16: 104107 | Z16: 104 | AA16: 104107 | AB16: 107 | AC16: 107 | AD16: 104107 | AE16: 106107 | AF16: 107 | AG16: 107104 | AH16: 107 | AI16: 104106 | AJ16: 106107 | AK16: 106107 | AO16: yield olein | AP16: =AP14/(AP14+AP15)*100 -> 82.828482 | AR16: tk131 | AS16: =AS13 -> 133300
D17: Product | AM17: Product | AO17: yield stearin | AP17: =AP15/(AP14+AP15)*100 -> 17.171518 | AR17: tk132 | AS17: =AS14-AP13 -> -39418618
D18: OIP RBDPO | F18: Kg | AM18: =SUM(G18:AK18) -> 0
D19: DIRECT RBDPO FRACT | F19: Kg | G19: 1789520 | H19: 1871999 | I19: 1865431 | J19: 83475 | V19: 1288722 | W19: 2199287 | X19: 2244332 | Y19: 1945574 | Z19: 1960365 | AA19: 1964892 | AB19: 2186862 | AC19: 2278056 | AD19: 2159702 | AE19: 2258073 | AF19: 1949216 | AG19: 2082705 | AH19: 2049455 | AI19: 2008090 | AJ19: 2023267 | AK19: 2061353 | AM19: =SUM(G19:AK19) -> 38270376
D20: RBDPO | E20: 55661000 | F20: Kg | AM20: =SUM(G20:AK20) -> 0
D21: PFAD | E21: 2827000 | F21: Kg | G21: 79332 | H21: 86463 | I21: 83606 | J21: 4613 | V21: 67467 | W21: 109927 | X21: 94071 | Y21: 88505 | Z21: 90992 | AA21: 91336 | AB21: 104079 | AC21: 97755 | AD21: 104153 | AE21: 89862 | AF21: 91305 | AG21: 98055 | AH21: 89257 | AI21: 100135 | AJ21: 87907 | AK21: 93668 | AM21: =SUM(G21:AK21) -> 1752488
D22: Fractionation
D23: Running Days | F23: Day | G23: 1 | H23: 1 | I23: 1 | J23: 1 | M23: 1 | N23: 1 | O23: 1 | P23: 1 | Q23: 1 | R23: 1 | S23: 1 | T23: 1 | U23: 1 | V23: 1 | W23: 1 | X23: 1 | Y23: 1 | Z23: 1 | AA23: 1 | AB23: 1 | AC23: 1 | AD23: 1 | AE23: 1 | AF23: 1 | AG23: 1 | AH23: 1 | AI23: 1 | AJ23: 1 | AK23: 1 | AM23: =SUM(G23:AK23) -> 29
D24: Avg Daily Consump RBDPO ( MTD ) | F24: Kg | G24: 0 | H24: 0 | I24: 0 | J24: 0 | K24: 0 | L24: 0 | M24: 0 | N24: 0 | O24: 0 | P24: 0 | Q24: 0 | R24: 0 | S24: 0 | T24: 0 | U24: 0 | V24: 0 | W24: 0 | X24: 0 | Y24: 0 | Z24: 0 | AA24: 0 | AB24: 0 | AC24: 0 | AD24: 0 | AE24: 0 | AF24: 0 | AG24: 0 | AH24: 0 | AI24: 0 | AJ24: 0 | AK24: 0 | AM24: =AM29/AM23 -> 1775536
D25: Total RBDPO transfer to plant | F25: Kg | AJ25: 0 | AK25: 0 | AM25: =SUM(G25:AK25) -> 0
D26: Stok TK 131 | E26: 559 | F26: ton
D27: Stok TK 132 | E27: 559 | F27: ton
D28: Ratio Run RBDPO | F28: % | G28: =G29/2500000 -> 0.7676072 | H28: =H29/2500000 -> 0.6317164 | I28: =I29/2500000 -> 0.6484316 | J28: =J29/2500000 -> 0.4699164 | K28: =K29/2500000 -> 0 | L28: =L29/2500000 -> 0 | M28: =M29/2500000 -> 0.2025492 | N28: =N29/2500000 -> 0.6516948 | ... V28: =V29/2500000 -> 0.4461308 | W28: 0.7274628 | X28: 0 | Y28: =Y29/2500000 -> 0.7295156 | Z28: =Z29/2500000 -> 0.8939452 | AA28: =AA29/2500000 -> 0.8844584 | AB28: =AB29/2500000 -> 0.9157468 | AC28: 0.52886 | AD28: =AD29/2500000 -> 0.8784892 | AE28: =AE29/2500000 -> 0.6777416 | AF28: =AF29/2500000 -> 0.638504 | AG28: =AG29/2500000 -> 0.6582624 | AH28: =AH29/2500000 -> 0.6811392 | AI28: =AI29/2500000 -> 0.7545008 | AJ28: =AJ29/2500000 -> 0.7655932 | AK28: =AK29/2500000 -> 0.8334324 | AM28: =AM29/2500000/AM23 -> 0.71021441
D29: Total Proses RBDPO | E29: 35501000 | F29: Kg | G29: =SUM(G32,G36,G41,G45,G55) -> 1919018 | H29: =SUM(H32,H36,H41,H45,H55) -> 1579291 | I29: =SUM(I32,I36,I41,I45,I55) -> 1621079 | J29: =SUM(J32,J36,J41,J45,J55) -> 1174791 | K29: =SUM(K32,K36,K41,K45,K55) -> 0 | L29: =SUM(L32,L36,L41,L45,L55) -> 0 | M29: =SUM(M32,M36,M41,M45,M55) -> 506373 | N29: =SUM(N32,N36,N41,N45,N55) -> 1629237 | ... AK29: =SUM(AK32,AK36,AK41,AK45,AK55) -> 2083581 | AM29: =SUM(G29:AK29) -> 51490545
D30: Sisa Filling Crystalizer | F30: Kg | G30: =G25-G29 -> -1919018 | H30: =H25-H29 -> -1579291 | I30: =I25-I29 -> -1621079 | J30: =J25-J29 -> -1174791 | K30: =K25-K29 -> 0 | L30: =L25-L29 -> 0 | M30: =M25-M29 -> -506373 | N30: =N25-N29 -> -1629237 | ... AK30: =AK25-AK29 -> -2083581 | AM30: =SUM(G30:AK30) -> -51490545
D31: Fractionation OLEIN IV 56 | AM31: Olein IV 56
D32: RBDPO Consume | F32: Kg | G32: =G33+G34 -> 1919018 | H32: =H33+H34 -> 60632 | I32: =I33+I34 -> 0 | J32: =J33+J34 -> 0 | K32: =K33+K34 -> 0 | L32: =L33+L34 -> 0 | M32: =M33+M34 -> 0 | N32: =N33+N34 -> 0 | ... AK32: =AK33+AK34 -> 2083581 | AM32: =SUM(G32:AK32) -> 39418618
D33: OLEIN IV 56 | E33: 25000000 | F33: Kg | G33: 1638220 | H33: 45173 | O33: 1070613 | P33: 1779634 | Q33: 1641727 | R33: 1472069 | S33: 1577279 | T33: 1483953 | U33: 1470575 | V33: 931609 | W33: 1268920 | X33: 1089983 | Y33: 1344811 | Z33: 1856465 | AA33: 1830392 | AB33: 1907299 | AC33: 1809986 | AD33: 1817464 | AE33: 947513 | AF33: 419201 | AH33: 386576 | AI33: 1551630 | AJ33: 1576974 | AK33: 1731777 | AM33: =SUM(G33:AK33) -> 32649843 | AN33: ok cek konsum rpo pas
D34: STEARIN | E34: 639000 | F34: Kg | G34: 280798 | H34: 15459 | O34: 209542 | P34: 338068 | Q34: 378795 | R34: 320029 | S34: 330863 | T34: 307196 | U34: 293951 | V34: 183718 | W34: 294260 | X34: 239771 | Y34: 278732 | Z34: =135333+243065 -> 378398 | AA34: 380754 | AB34: 382068 | AC34: 397139 | AD34: 378759 | AE34: 193216 | AF34: 79368 | AH34: 84456 | AI34: 334622 | AJ34: 337009 | AK34: 351804 | AM34: =SUM(G34:AK34) -> 6768775 | AN34: ok cek konsum rpo pas
D35: Fractionation OLEIN IV 57 ( Bulk ) | Z35: 0 | AM35: Olein IV 57 ( Bulk )
D36: RBDPO Consume | F36: Kg | G36: =G37+G38 -> 0 | H36: =H37+H38 -> 0 | I36: =I37+I38 -> 0 | J36: =J37+J38 -> 0 | K36: 0 | M36: 0 | R36: =R37+R38 -> 0 | S36: 0 | T36: =T37+T38 -> 0 | U36: =U37+U38 -> 0 | V36: =V37+V38 -> 0 | W36: 0 | X36: 0 | AA36: =AA37+AA38 -> 0 | AB36: =AB37+AB38 -> 0 | AC36: 0 | AD36: =AD37+AD38 -> 0 | AE36: =AE37+AE38 -> 0 | AF36: =AF37+AF38 -> 0 | AG36: =AG37+AG38 -> 0 | AH36: =AH37+AH38 -> 0 | AM36: =SUM(G36:AK36) -> 0
D37: OLEIN IV 57 | F37: Kg | H37: 0 | I37: 0 | J37: 0 | K37: 0 | M37: 0 | R37: 0 | S37: 0 | T37: 0 | U37: 0 | V37: 0 | W37: 0 | X37: 0 | AA37: 0 | AB37: 0 | AC37: 0 | AD37: 0 | AE37: 0 | AF37: 0 | AG37: 0 | AM37: =SUM(G37:AK37) -> 0
D38: STEARIN | F38: Kg | H38: 0 | I38: 0 | J38: 0 | K38: 0 | M38: 0 | R38: 0 | S38: 0 | T38: 0 | U38: 0 | V38: 0 | W38: 0 | X38: 0 | AA38: 0 | AB38: 0 | AC38: 0 | AD38: 0 | AE38: 0 | AF38: 0 | AG38: 0 | AM38: =SUM(G38:AK38) -> 0
D39: Fractionation OLEIN IV 57 ( Retail ) | AM39: Olein IV 57 ( Retail )
D40: CPO Consume | F40: Kg | AM40: =SUM(G40:AK40) -> 0
...

Sheet OIP Ref PMG 2
B4: Oil In Plant (OIP) Refinery pmg 2 | I4: Oktober | J4: OIP | M4: TK131 RPO | P4: TK132 RPO | S4: TOTAL STOK RPO DI PLANT
B5: Vessel | C5: Operating Volume (m3) | D5: Oil Density (kg/m3) | E5: MT | F5: Level yg diisi | G5: Actual OIP (Kg) | I5: Tanggal | J5: Opening Stock | K5: Closing Stock | L5: balance stok | M5: Opening Stock | N5: Closing Stock | O5: CONSUMP stok | P5: Opening Stock | Q5: Closing Stock | R5: CONSUMP stok
B6: 2MX312 | C6: 5.67 | D6: 850 | E6: =C6*D6/1000 -> 4.8195 | F6: 100 | G6: =(F6*E6/100)*1000 -> 4819.5 | I6: 46023 | J6: 282664 | K6: 297894 | L6: =J6-K6 -> -15230
B7: 2VE611A | C7: 47.22 | D7: 850 | E7: =C7*D7/1000 -> 40.137 | F7: 80 | G7: =(F7*E7/100)*1000 -> 32109.6 | I7: 46024 | J7: =K6 -> 297894 | K7: 294828 | L7: =J7-K7 -> 3066
B8: 2VE611B | C8: 47.22 | D8: 850 | E8: =C8*D8/1000 -> 40.137 | F8: 80 | G8: =(F8*E8/100)*1000 -> 32109.6 | I8: 46025 | J8: =K7 -> 294828 | K8: 312285 | L8: =J8-K8 -> -17457
B9: 2VE612 | C9: 35.68 | D9: 850 | E9: =C9*D9/1000 -> 30.328 | F9: 71 | G9: =(F9*E9/100)*1000 -> 21532.88 | I9: 46026 | J9: =K8 -> 312285 | K9: 323561 | L9: =J9-K9 -> -11276
B10: 2VE661 | C10: 10.8 | D10: 850 | E10: =C10*D10/1000 -> 9.18 | F10: 15 | G10: =(F10*E10/100)*1000 -> 1377 | I10: 46027 | J10: =K9 -> 323561 | K10: 318233 | L10: =J10-K10 -> 5328
B11: FL621 | C11: 10.1 | D11: 850 | E11: =C11*D11/1000 -> 8.585 | F11: 100 | G11: =(F11*E11/100)*1000 -> 8585 | I11: 46028 | J11: =K10 -> 318233 | K11: 318233 | L11: =J11-K11 -> 0
B12: FL622 | C12: 10.1 | D12: 850 | E12: =C12*D12/1000 -> 8.585 | F12: 100 | G12: =(F12*E12/100)*1000 -> 8585 | I12: 46029 | J12: =K11 -> 318233 | K12: 318233 | L12: =J12-K12 -> 0
B13: FL623 | C13: 10.1 | D13: 850 | E13: =C13*D13/1000 -> 8.585 | F13: 100 | G13: =(F13*E13/100)*1000 -> 8585 | I13: 46030 | J13: =K12 -> 318233 | K13: 318233 | L13: =J13-K13 -> 0 | N13: 0 | Q13: 174609
B14: FL624 | C14: 10.1 | D14: 850 | E14: =C14*D14/1000 -> 8.585 | F14: 0 | G14: =(F14*E14/100)*1000 -> 0 | I14: 46031 | J14: =K13 -> 318233 | K14: 318233 | L14: =J14-K14 -> 0 | N14: 44191 | P14: 174609 | Q14: 38852 | R14: =P14-Q14 -> 135757 | S14: =R14+O14+L14 -> 135757
B15: FL625 | C15: 10.1 | D15: 850 | E15: =C15*D15/1000 -> 8.585 | F15: 100 | G15: =(F15*E15/100)*1000 -> 8585 | I15: 46032 | J15: =K14 -> 318233 | K15: 318233 | L15: =J15-K15 -> 0 | M15: 44191 | N15: 405272 | O15: =M15-N15 -> -361081 | P15: 38852 | Q15: 38852 | R15: =P15-Q15 -> 0 | S15: =R15+O15+L15 -> -361081
B16: 2VE701 | C16: 72.13 | D16: 850 | E16: =C16*D16/1000 -> 61.3105 | F16: 37 | G16: =(F16*E16/100)*1000 -> 22684.885 | I16: 46033 | J16: =K15 -> 318233 | K16: 318233 | L16: =J16-K16 -> 0
B17: 2VE751 | C17: 4.28 | D17: 860 | E17: =C17*D17/1000 -> 3.6808 | F17: 50 | G17: =(F17*E17/100)*1000 -> 1840.4 | I17: 46034 | J17: =K16 -> 318233 | K17: 318233 | L17: =J17-K17 -> 0
B18: 2HE721A (tube) | C18: 10 | D18: 810 | E18: =C18*D18/1000 -> 8.1 | F18: 100 | G18: =(F18*E18/100)*1000 -> 8100 | I18: 46035 | J18: =K17 -> 318233 | L18: =J18-K18 -> 318233
B19: 2HE721A (shell) | C19: 21.8 | D19: 800 | E19: =C19*D19/1000 -> 17.44 | F19: 30 | G19: =(F19*E19/100)*1000 -> 5232 | I19: 46036 | J19: =K18 -> 0 | L19: =J19-K19 -> 0
B20: HE721B (tube) | C20: 10 | D20: 810 | E20: =C20*D20/1000 -> 8.1 | F20: 100 | G20: =(F20*E20/100)*1000 -> 8100 | I20: 46037 | J20: =K19 -> 0 | L20: =J20-K20 -> 0
B21: 2HE722 | C21: 11.4 | D21: 790 | E21: =C21*D21/1000 -> 9.006 | F21: 80 | G21: =(F21*E21/100)*1000 -> 7204.8 | I21: 46038 | J21: =K20 -> 0 | L21: =J21-K21 -> 0
B22: 2PR731 | C22: 14 | D22: 790 | E22: =C22*D22/1000 -> 11.06 | F22: 30 | G22: =(F22*E22/100)*1000 -> 3318 | I22: 46039 | J22: =K21 -> 0 | K22: 300254 | L22: =J22-K22 -> -300254
B23: 2DE732 | C23: 149.76 | D23: 790 | E23: =C23*D23/1000 -> 118.3104 | F23: 100 | G23: =(F23*E23/100)*1000 -> 118310.4 | I23: 46040 | J23: =K22 -> 300254 | K23: 296976 | L23: =J23-K23 -> 3278
C24: =SUM(C6:C23) -> 490.46 | E24: =SUM(E6:E23) -> 404.5342 | G24: =(F24*E24/100)*1000 -> 0 | I24: 46041 | J24: =K23 -> 296976 | K24: 318272 | L24: =J24-K24 -> -21296
F25: Total OIP = | G25: =SUM(G6:G24) -> 301079.06 | I25: 46042 | J25: =K24 -> 318272 | K25: 300254 | L25: =J25-K25 -> 18018
I26: 46043 | J26: =K25 -> 300254 | K26: 316518 | L26: =J26-K26 -> -16264
I27: 46044 | J27: =K26 -> 316518 | K27: 308256 | L27: =J27-K27 -> 8262
I28: 46045 | J28: =K27 -> 308256 | K28: 310512 | L28: =J28-K28 -> -2256
I29: 46046 | J29: =K28 -> 310512 | K29: 305936 | L29: =J29-K29 -> 4576
I30: 46047 | J30: =K29 -> 305936 | K30: 306307 | L30: =J30-K30 -> -371
H31: 0 | I31: 46048 | J31: =K30 -> 306307 | K31: 311257 | L31: =J31-K31 -> -4950
