Workbook

Sheet Februari 2026 PMG 1
C1: PRODUCTION REPORT PMG 1
C2: No | D2: ITEM | E2: Budget / Norma | F2: UoM | G2: Februari 2026 | AJ2: TOTAL MONTHLY (Kg)
G3: 1 | H3: 2 | I3: 3 | J3: 4 | K3: 5 | L3: 6 | M3: 7 | N3: 8 | O3: 9 | P3: 10 | Q3: 11 | R3: 12 | S3: 13 | T3: 14 | U3: 15 | V3: 16 | W3: 17 | X3: 18 | Y3: 19 | Z3: 20 | AA3: 21 | AB3: 22 | AC3: 23 | AD3: 24 | AE3: 25 | AF3: 26 | AG3: 27 | AH3: 28
C4: 1 | D4: PRODUCTION | AJ4: Production | AL4: aktual refinery | AO4: opening stok rpo | AP4: =AP6+AP7+AP9 -> 80236
D5: Refinery | AJ5: Refinery | AL5: cpo feed | AM5: =AJ9 -> 857800 | AO5: sisa rbpo tank
D6: Running Days | F6: Day | J6: 1 | K6: 1 | L6: 1 | AJ6: =SUM(G6:AH6) -> 3 | AL6: rpo prod | AM6: =AJ20+AJ19+AJ18 -> 530000 | AO6: tk 108 | AP6: 80236
D7: Incoming CPO | F7: Kg | AJ7: =SUM(G7:AH7) -> 0
D8: Ratio Run CPO ( utilisasi kapasitas ) | F8: % | J8: =J9/2500000 -> 0.11632 | K8: =K9/2500000 -> 0.2268 | L8: =L9/2500000 -> 0 | M8: =M9/2500000 -> 0 | N8: =N9/2500000 -> 0 | O8: =O9/2500000 -> 0 | P8: =P9/2500000 -> 0 | Q8: =Q9/2500000 -> 0 | ... AH8: =AH9/2500000 -> 0 | AJ8: =AJ9/2500000/AJ6 -> 0.11437333
D9: CPO Consume Total | E9: 58900000 | F9: Kg | J9: 290800 | K9: 567000 | AJ9: =SUM(G9:U9) -> 857800
D10: Avg Daily Consump CPO ( MTD ) | AJ10: =AJ9/AJ6 -> 285933.33
D11: CPO Consume Poram | F11: Kg | J11: =J9-J12 -> 290800 | K11: =K9-K12 -> 567000 | AJ11: =SUM(G11:AH11) -> 857800
D12: CPO Consume Brand | F12: Kg | J12: =J40+J49+J54 -> 0 | AJ12: =SUM(G12:AH12) -> 0
D13: - FFA | E13: 5 | F13: % | K13: 4.36 | AJ13: =SUM(G13:AH13)/AJ6 -> 1.4533333 | AL13: rpo feed | AM13: =AM14+AM15 -> 3288600 | AO13: tk131 | AP13: ='OIP Fract PMG 2'!T13 -> 200835
D14: - Moist & Impurities | E14: 0.5 | F14: % | K14: 0.35 | AJ14: =SUM(G14:AH14)/AJ6 -> 0.11666667 | AL14: olein 56 | AM14: =AJ33 -> 2712800 | AO14: tk132 | AP14: ='OIP Fract PMG 2'!U13 -> 114939
D15: - DOBI | E15: 2,20 Min | F15: % | AJ15: =SUM(G15:AH15)/AJ6 -> 0 | AL15: stearin 56 | AM15: =AJ34 -> 575800 | AO15: after
D16: TANK | K16: 107 | AL16: yield olein | AM16: =AM14/(AM14+AM15)*100 -> 82.49103 | AO16: tk131 | AP16: =AP13 -> 200835
D17: Product | AJ17: Product | AL17: yield stearin | AM17: =AM15/(AM14+AM15)*100 -> 17.50897 | AO17: tk132 | AP17: =AP14-AM13 -> -3173661
D18: OIP RBDPO | F18: Kg | AJ18: =SUM(G18:AH18) -> 0
D19: DIRECT RBDPO FRACT | F19: Kg | K19: 530000 | AJ19: =SUM(G19:U19) -> 530000
D20: RBDPO | E20: 55661000 | F20: Kg | AJ20: =SUM(G20:AH20) -> 0
D21: PFAD | E21: 2827000 | F21: Kg | J21: 13600 | K21: 32400 | AJ21: =SUM(G21:U21) -> 46000
D22: Fractionation
D23: Running Days | F23: Day | L23: 1 | M23: 1 | N23: 1 | O23: 1 | P23: 1 | X23: 1 | Y23: 1 | Z23: 1 | AA23: 1 | AB23: 1 | AC23: 1 | AD23: 1 | AE23: 1 | AF23: 1 | AG23: 1 | AH23: 1 | AJ23: =SUM(G23:AH23) -> 16
D24: Avg Daily Consump RBDPO ( MTD ) | F24: Kg | J24: 0 | K24: 0 | L24: 0 | M24: 0 | N24: 0 | O24: 0 | P24: 0 | Q24: 0 | R24: 0 | S24: 0 | T24: 0 | U24: 0 | V24: 0 | W24: 0 | X24: 0 | Y24: 0 | AJ24: =AJ29/AJ23 -> 584525
D25: Total RBDPO transfer to plant | F25: Kg | AJ25: =SUM(G25:AH25) -> 0
D26: Stok TK 131 | E26: 559 | F26: ton
D27: Stok TK 132 | E27: 559 | F27: ton
D28: Ratio Run RBDPO | F28: % | J28: =J29/2500000 -> 0 | K28: =K29/2500000 -> 0 | L28: =L29/2500000 -> 0 | M28: =M29/2500000 -> 0.20636 | N28: =N29/2500000 -> 0.363 | O28: =O29/2500000 -> 0.30008 | P28: =P29/2500000 -> 0.29308 | Q28: =Q29/2500000 -> 0 | ... AH28: =AH29/2500000 -> 0.12728 | AJ28: =AJ29/2500000/AJ23 -> 0.23381
D29: Total Proses RBDPO | E29: 35501000 | F29: Kg | J29: =SUM(J32,J36,J41,J45,J55) -> 0 | K29: =SUM(K32,K36,K41,K45,K55) -> 0 | L29: =SUM(L32,L36,L41,L45,L55) -> 0 | M29: =SUM(M32,M36,M41,M45,M55) -> 515900 | N29: =SUM(N32,N36,N41,N45,N55) -> 907500 | O29: =SUM(O32,O36,O41,O45,O55) -> 750200 | P29: =SUM(P32,P36,P41,P45,P55) -> 732700 | Q29: =SUM(Q32,Q36,Q41,Q45,Q55) -> 0 | ... AH29: =SUM(AH32,AH36,AH41,AH45,AH55) -> 318200 | AJ29: =SUM(G29:AH29) -> 9352400
D30: Sisa Filling Crystalizer | F30: Kg | J30: =J25-J29 -> 0 | AJ30: =SUM(G30:AH30) -> 0
D31: Fractionation OLEIN IV 56 | AJ31: Olein IV 56
D32: RBDPO Consume | F32: Kg | J32: =J33+J34 -> 0 | K32: =K33+K34 -> 0 | L32: =L33+L34 -> 0 | M32: =M33+M34 -> 335100 | N32: =N33+N34 -> 0 | O32: =O33+O34 -> 0 | P32: =P33+P34 -> 0 | Q32: =Q33+Q34 -> 0 | ... AH32: =AH33+AH34 -> 318200 | AJ32: =SUM(G32:AH32) -> 3288600
D33: OLEIN IV 56 | E33: 25000000 | F33: Kg | M33: 276100 | AC33: 50200 | AE33: 437200 | AF33: =362600+394400+216400 -> 973400 | AG33: 723500 | AH33: 252400 | AJ33: =SUM(G33:AH33) -> 2712800
D34: STEARIN | E34: 639000 | F34: Kg | M34: 59000 | AC34: 11000 | AE34: 90500 | AF34: 192300 | AG34: 157200 | AH34: 65800 | AJ34: =SUM(G34:AH34) -> 575800
D35: Fractionation OLEIN IV 57 ( Bulk ) | AJ35: Olein IV 57 ( Bulk )
D36: RBDPO Consume | F36: Kg | J36: =J37+J38 -> 0 | AJ36: =SUM(G36:AH36) -> 0
D37: OLEIN IV 57 | F37: Kg | J37: 0 | AJ37: =SUM(G37:AH37) -> 0
D38: STEARIN | F38: Kg | J38: 0 | AJ38: =SUM(G38:AH38) -> 0
D39: Fractionation OLEIN IV 57 ( Retail ) | AJ39: Olein IV 57 ( Retail )
D40: CPO Consume | F40: Kg | AJ40: =SUM(G40:AH40) -> 0
...

Sheet OIP Ref PMG 1
B4: Oil In Plant (OIP) Refinery pmg | I4: February | J4: OIP | M4: TK131 RPO | P4: TK132 RPO | S4: TOTAL STOK RPO DI PLANT
B5: Vessel | C5: Operating Volume (m3) | D5: Oil Density (kg/m3) | E5: MT | F5: Level yg diisi | G5: Actual OIP (Kg) | I5: Tanggal | J5: Opening Stock | K5: Closing Stock | L5: balance stok | M5: Opening Stock | N5: Closing Stock | O5: CONSUMP stok | P5: Opening Stock | Q5: Closing Stock | R5: CONSUMP stok
B6: 2MX312 | C6: 5.67 | D6: 850 | E6: =C6*D6/1000 -> 4.8195 | G6: =(F6*E6/100)*1000 -> 0 | I6: 46054 | L6: =J6-K6 -> 0
B7: 2VE611A | C7: 47.22 | D7: 850 | E7: =C7*D7/1000 -> 40.137 | G7: =(F7*E7/100)*1000 -> 0 | I7: 46055 | L7: =J7-K7 -> 0
B8: 2VE611B | C8: 47.22 | D8: 850 | E8: =C8*D8/1000 -> 40.137 | G8: =(F8*E8/100)*1000 -> 0 | I8: 46056 | L8: =J8-K8 -> 0
B9: 2VE612 | C9: 35.68 | D9: 850 | E9: =C9*D9/1000 -> 30.328 | G9: =(F9*E9/100)*1000 -> 0 | I9: 46057 | J9: 0 | K9: 269071 | L9: =J9-K9 -> -269071
B10: 2VE661 | C10: 10.8 | D10: 850 | E10: =C10*D10/1000 -> 9.18 | G10: =(F10*E10/100)*1000 -> 0 | I10: 46058 | J10: =K9 -> 269071 | K10: 180800 | L10: =J10-K10 -> 88271
B11: FL621 | C11: 10.1 | D11: 850 | E11: =C11*D11/1000 -> 8.585 | G11: =(F11*E11/100)*1000 -> 0 | I11: 46059 | J11: =K10 -> 180800 | K11: 0 | L11: =J11-K11 -> 180800
B12: FL622 | C12: 10.1 | D12: 850 | E12: =C12*D12/1000 -> 8.585 | G12: =(F12*E12/100)*1000 -> 0 | I12: 46060 | J12: =K11 -> 0 | L12: =J12-K12 -> 0
B13: FL623 | C13: 10.1 | D13: 850 | E13: =C13*D13/1000 -> 8.585 | G13: =(F13*E13/100)*1000 -> 0 | I13: 46061 | J13: =K12 -> 0 | L13: =J13-K13 -> 0 | N13: 0 | Q13: 174609
B14: FL624 | C14: 10.1 | D14: 850 | E14: =C14*D14/1000 -> 8.585 | G14: =(F14*E14/100)*1000 -> 0 | I14: 46062 | J14: =K13 -> 0 | L14: =J14-K14 -> 0 | N14: 44191 | P14: 174609 | Q14: 38852 | R14: =P14-Q14 -> 135757 | S14: =R14+O14+L14 -> 135757
B15: FL625 | C15: 10.1 | D15: 850 | E15: =C15*D15/1000 -> 8.585 | G15: =(F15*E15/100)*1000 -> 0 | I15: 46063 | J15: =K14 -> 0 | L15: =J15-K15 -> 0 | M15: 44191 | N15: 405272 | O15: =M15-N15 -> -361081 | P15: 38852 | Q15: 38852 | R15: =P15-Q15 -> 0 | S15: =R15+O15+L15 -> -361081
B16: 2VE701 | C16: 72.13 | D16: 850 | E16: =C16*D16/1000 -> 61.3105 | G16: =(F16*E16/100)*1000 -> 0 | I16: 46064 | J16: =K15 -> 0 | L16: =J16-K16 -> 0
B17: 2VE751 | C17: 4.28 | D17: 860 | E17: =C17*D17/1000 -> 3.6808 | G17: =(F17*E17/100)*1000 -> 0 | I17: 46065 | J17: =K16 -> 0 | L17: =J17-K17 -> 0
B18: 2HE721A (tube) | C18: 10 | D18: 810 | E18: =C18*D18/1000 -> 8.1 | G18: =(F18*E18/100)*1000 -> 0 | I18: 46066 | J18: =K17 -> 0 | L18: =J18-K18 -> 0
B19: 2HE721A (shell) | C19: 21.8 | D19: 800 | E19: =C19*D19/1000 -> 17.44 | G19: =(F19*E19/100)*1000 -> 0 | I19: 46067 | J19: =K18 -> 0 | L19: =J19-K19 -> 0
B20: HE721B (tube) | C20: 10 | D20: 810 | E20: =C20*D20/1000 -> 8.1 | G20: =(F20*E20/100)*1000 -> 0 | I20: 46068 | J20: =K19 -> 0 | L20: =J20-K20 -> 0
B21: 2HE722 | C21: 11.4 | D21: 790 | E21: =C21*D21/1000 -> 9.006 | G21: =(F21*E21/100)*1000 -> 0 | I21: 46069 | J21: =K20 -> 0 | L21: =J21-K21 -> 0
B22: 2PR731 | C22: 14 | D22: 790 | E22: =C22*D22/1000 -> 11.06 | G22: =(F22*E22/100)*1000 -> 0 | I22: 46070 | J22: =K21 -> 0 | L22: =J22-K22 -> 0
B23: 2DE732 | C23: 149.76 | D23: 790 | E23: =C23*D23/1000 -> 118.3104 | G23: =(F23*E23/100)*1000 -> 0 | I23: 46071 | J23: =K22 -> 0 | L23: =J23-K23 -> 0
C24: =SUM(C6:C23) -> 490.46 | E24: =SUM(E6:E23) -> 404.5342 | I24: 46072 | J24: =K23 -> 0 | L24: =J24-K24 -> 0
F25: Total OIP = | G25: =SUM(G6:G24) -> 0 | I25: 46073 | J25: =K24 -> 0 | L25: =J25-K25 -> 0
I26: 46074 | J26: =K25 -> 0 | L26: =J26-K26 -> 0
I27: 46075 | J27: =K26 -> 0 | L27: =J27-K27 -> 0
I28: 46076 | J28: =K27 -> 0 | L28: =J28-K28 -> 0
I29: 46077 | J29: =K28 -> 0 | L29: =J29-K29 -> 0
I30: 46078 | J30: =K29 -> 0 | L30: =J30-K30 -> 0
H31: 0 | I31: 46079 | J31: =K30 -> 0 | L31: =J31-K31 -> 0
I32: 46080 | J32: =K31 -> 0 | L32: =J32-K32 -> 0
I33: 46081 | J33: =K32 -> 0 | L33: =J33-K33 -> 0
B38: Solar Daily Tank HPB
B39: 2TK726 | C39: =5.3+0.78 -> 6.08 | D39: 840 | E39: =C39*D39/1000 -> 5.1072 | F39: 0 | G39: =F39*E39/100*1000 -> 0
B41: Stock Chemicals In Plant
C42: Sisa Stok Di Lap | D42: Order | E42: Consumption
B43: BE
B44: 630A | D44: 298
B45: 630B
B46: H3PO4
B47: NaOH
B48: Citrid Acid

Sheet Peformance test Fract 1
C1: PT.INDUSTRI NABATI LESTARI
C2: Pabrik Minyak Goreng ( PMG 2 )
C3: Kantor Pusat: Komp. KEK Sei Mangkei, Kav.2-3, Kec. Bosar Maligas, Kab. Simalungun, Sumatera Utara, 21184
C4: ACTUAL PEFORMANCE / CONSUMPT REPORT FRAKSINASI PLANT | H4: Trial | I4: 1
H5: Start / Date / Time | I5: 17/12/24 ( 07.00 Wib )
H6: Finish / Date / Time | I6: 17/12/24 ( 07.00 Wib )
A8: No | B8: ITEM | C8: Kontrak LIPICO | D8: UOM | E8: TOTALIZER
A10: 1 | B10: PRODUCTION | C10: IV 56 | D10: 24 jam | E10: BEFORE | F10: AFTER | G10: TOTAL | H10: YIELD % | I10: STATUS/REMAKS
B11: Fraksinasi
B12: Running Days
B13: Incoming CPO
B14: Ratio Run CPO
B15: RBDPO Consume Total | C15: 2500 | D15: TPD | E15: 8982.8 | F15: 11717.8 | G15: =F15-E15 -> 2735 | H15: =G15/25000*10 -> 1.094 | I15: OK
B16: Avg Daily Consump CPO ( MTD )
B17: CPO Consume Poram | C17: 29045000
B18: CPO Consume Brand | C18: 7314000 | E18: =E49+E58+E63 -> 0
B19: QUALITY
B20: - FFA | C20: 0.1 | D20: % Max | H20: 0.063
B21: - Moist & Impurities | C21: 0.1 | D21: % Max | H21: 0.05
B22: - IV | C22: 52 - 52,5 | H22: 51.8
B23: - LC | H23: 2,6/20
B24: - Temp | C24: 68 | D24: ˚C Min | H24: 65
B25: TANK | H25: 108/109
B26: Product
B27: OLEIN IV 56 | C27: =C15*84% -> 2100 | D27: TPD | E27: 6537.1 | F27: 8213 | G27: =F27-E27 -> 1675.9 | H27: =G27/(G27+G32) -> 0.82838219 | I27: OK
B28: QUALITY
B29: - IV | C29: 56 | D29: Min
B30: - LC
B31: - Cloud Point ( metter ) | C31: 10 | D31: ˚C Max
B32: STEARIN | C32: =C15*16% -> 400 | E32: 2268.1 | F32: 2615.3 | G32: =F32-E32 -> 347.2 | H32: =G32/(G32+G27) -> 0.17161781 | I32: OK
B33: Fractionation
B34: Running Days
B35: Filling Langsung CR Fr Refinery | E35: 0
B36: Total Filling Crystalizer ( Feed ) | E36: 392100
B37: Avg Daily Consump RPO ( MTD )
B38: Total Proses RBDPO | E38: =SUM(E41,E45,E50,E54,E64) -> 0
B39: Sisa Filling Crystalizer | E39: =E36-E38 -> 392100
B40: Fractionation OLEIN IV 56
B41: RBDPO Consume | E41: =E42+E43 -> 0
B42: OLEIN IV 56 | E42: 0
...

Sheet Peformance Test REFINERY 1
C1: PT.INDUSTRI NABATI LESTARI
C2: Pabrik Minyak Goreng ( PMG 2 )
C3: Kantor Pusat: Komp. KEK Sei Mangkei, Kav.2-3, Kec. Bosar Maligas, Kab. Simalungun, Sumatera Utara, 21184
C4: ACTUAL PEFORMANCE / CONSUMPT REPORT REFINERY PLANT | H4: Peformance | I4: 1
H5: Start / Date / Time | I5: 17/12/24 ( 21.00 Wib )
H6: Finish / Date / Time | I6: 18/12/24 ( 21.00 Wib )
A7: No | B7: ITEM | C7: Kontrak LIPICO | D7: UOM | E7: TOTALIZER
A9: 1 | B9: PRODUCTION | E9: BEFORE | F9: AFTER | G9: TOTAL | H9: Yield ( % ) | I9: STATUS/REMAKS
B10: Refinery
B11: Running Days
B12: Incoming CPO
B13: Ratio Run CPO
B14: CPO Consume Total | C14: 2500 | D14: TPD | E14: 13533.82 | F14: 16053.42 | G14: =F14-E14 -> 2519.6 | I14: OK
B15: Avg Daily Consump CPO ( MTD )
B16: CPO Consume Poram | C16: 29045000
B17: CPO Consume Brand | C17: 7314000 | E17: =E53+E62+E67 -> 0
B18: - FFA | C18: 5 | D18: % | G18: 4
B19: - Moist & Impurities | C19: 0.5 | D19: % | G19: 0.41
B20: - DOBI | C20: 2.2 | D20: Min | G20: 2.42
B21: - TOTOX 2PV + AV | C21: 12 | D21: Max | G21: N/A
B22: - FE Content | C22: < 5 | D22: ppm | G22: N/A
B23: - PV | C23: < 4 | D23: Meg/kg | G23: N/A
B24: - Phosporus Max | C24: 25 | D24: ppm | G24: N/A
B25: TANK / TEMP | C25: 50 | D25: ˚C | G25: 50
B26: Product
B27: RBDPO | C27: =C14*94.2% -> 2355 | D27: TPD | E27: 12357.54 | F27: 14705.95 | G27: =F27-E27 -> 2348.41 | H27: =G27/G14 -> 0.93205668
B28: - FFA | C28: 0.05 | D28: % | G28: 0.06
B29: - Moist & Impurities | C29: 0.03 | D29: % | G29: 0.05
B30: - Peroxide value | D30: Nil | G30: -
B31: - Phosporous max | C31: 2 | D31: ppm | G31: N/A
B32: - LC | C32: 2.5 | D32: % | G32: 2.5
B33: - Aom stability min ( hr ) | C33: 60 | D33: min ( hr ) | G33: N/A
B34: - teste & Odor | C34: bland/Odorless | G34: N/A
B35: - temp max ( C ) | C35: 50 | D35: max˚C | G35: 50
B36: PFAD | C36: =C14*5% -> 125 | D36: TPD | E36: 572.71 | F36: 675.39 | G36: =F36-E36 -> 102.68 | H36: =G36/G14 -> 0.0407525
B37: Fractionation
B38: Running Days
B39: Filling Langsung CR Fr Refinery | E39: 0
B40: Total Filling Crystalizer ( Feed ) | E40: 392100
B41: Avg Daily Consump RPO ( MTD )
...

Sheet peformance  test REFINERY 2
A1: REFINERY PMG 2
A2: No | B2: ITEM | C2: Norma LIPICO | D2: UOM | E2: Day 2 tanggal 12/12/2024
A4: 1 | B4: PRODUCTION | E4: BEFORE | F4: AFTER | G4: TOTAL | H4: Yield ( % )
B5: Refinery
B6: Running Days
B7: Incoming CPO
B8: Ratio Run CPO
B9: CPO Consume Total | C9: 2500 | D9: TPD | E9: 5880.74 | F9: 8383.74 | G9: =F9-E9 -> 2503 | H9: =G9/2500000*100000 -> 100.12
B10: Avg Daily Consump CPO ( MTD )
B11: CPO Consume Poram | C11: 29045000
B12: CPO Consume Brand | C12: 7314000 | E12: =E43+E52+E57 -> 0
B13: - FFA | C13: 5 | D13: % | G13: 3.97
B14: - Moist & Impurities | C14: 0.5 | D14: % | G14: 0.4
B15: - DOBI | C15: 2.2 | D15: Min | G15: 2.42
B16: TANK | G16: 105
B17: Product
B18: OIP RBDPO
B19: RBDPO | C19: =C9*94.2% -> 2355 | D19: TPD | E19: 5143.38 | F19: 7493.18 | G19: =F19-E19 -> 2349.8 | H19: =G19/G9*100 -> 93.879345
B20: - FFA | C20: 0.05 | D20: % | G20: 0.043
B21: - Moist & Impurities | C21: 0.03 | D21: % | G21: 0.04
B22: - LC | C22: 2.5 | D22: % | G22: 2.5
B23: - Aom stability min ( hr ) | C23: 60 | D23: min ( hr )
B24: - teste & Odor | C24: bland/Odorless
B25: - temp max ( C ) | C25: 50 | D25: max˚C
B26: PFAD | C26: =C9*5% -> 125 | D26: TPD | E26: 243.04 | F26: 347.1 | G26: =F26-E26 -> 104.06 | H26: =G26/G9*100 -> 4.1574111
B27: Fractionation
B28: Running Days
B29: Filling Langsung CR Fr Refinery | E29: 0
B30: Total Filling Crystalizer ( Feed ) | E30: 392100
B31: Avg Daily Consump RPO ( MTD )
B32: Total Proses RBDPO | E32: =SUM(E35,E39,E44,E48,E58) -> 0
B33: Sisa Filling Crystalizer | E33: =E30-E32 -> 392100
B34: Fractionation OLEIN IV 56
B35: RBDPO Consume | E35: =E36+E37 -> 0
B36: OLEIN IV 56 | E36: 0
B37: STEARIN | E37: 0
B38: Fractionation OLEIN IV 57 ( Bulk )
B39: RBDPO Consume | E39: =E40+E41 -> 0
B40: OLEIN IV 57 | E40: 0
B41: STEARIN | E41: 0
...

Sheet HPP REF 
B2: Refinery Cost
B3: Through Put CPO Proses | N3: =('Februari 2026 PMG 2'!AJ10)/1000 -> 2169.1977 | O3: TPD
B4: Working Day | N4: ='Februari 2026 PMG 2'!AJ6 -> 28 | O4: Days
B5: Total CPO Process | N5: =N4*N3 -> 60737.537 | O5: MTD
B6: KURS | N6: 16000 | O6: Rp/USD
B7: No | C7: Item Cost | D7: Norma | F7: Pemakaian / Hari | H7: HK | J7: Total Pemakaian | K7: Harga / stn | M7: Total Biaya | N7: Rp / kg | O7: USD/MT
B8: 1 | C8: Bleaching Earth | D8: ='Februari 2026 PMG 2'!$AJ$76 -> 0.53000832 | F8: =($D$8*$N$3*10) -> 11496.929 | G8: Kg/day | H8: =$N$4 -> 28 | J8: =$H$8*$F$8 -> 321914 | K8: 4550 | M8: =$J$8*$K$8 -> 1464708700 | N8: =$M$8/($N$5*1000) -> 24.115379 | O8: =($M$8/$N$6)/$N$5 -> 1.5072112
B9: 2 | C9: Phosporic acid | D9: ='Februari 2026 PMG 2'!$AJ$87 -> 0.53263842 | F9: =($D$9*$N$3*10) -> 11553.981 | G9: Kg/day | H9: =$H$8 -> 28 | J9: =$H$9*$F$9 -> 323511.46 | K9: 17420 | M9: =$J$9*$K$9 -> 5.6355696e+09 | N9: =$M$9/($N$5*1000) -> 92.785614 | O9: =($M$9/$N$6)/$N$5 -> 5.7991008
B10: 3 | C10: Caustic Soda | D10: 29.166667 | E10: kg/day | F10: =D10 -> 29.166667 | G10: kg/day | H10: =$H$8 -> 28 | J10: =$H$10*$F$10 -> 816.66667 | K10: 15700 | M10: =$J$10*$K$10 -> 12821667 | N10: =$M$10/($N$5*1000) -> 0.21109955 | O10: =($M$10/$N$6)/$N$5 -> 0.013193722
B11: 4 | C11: Pemakaian Natural Gas HPB Geka
C12: Normal Consumption | D12: ='Februari 2026 PMG 2'!$AJ$249 -> 0.10726318 | E12: MMBTU/MT CPO | F12: =$D$12*$N$3 -> 232.67504 | G12: MMBTU/day | H12: =$H$8 -> 28 | J12: =$H$12*$F$12 -> 6514.9012 | K12: =11.5*$N$6 -> 184000 | M12: =$J$12*$K$12 -> 1.1987418e+09 | N12: =$M$12/($N$5*1000) -> 19.736425 | O12: =($M$12/$N$6)/$N$5 -> 1.2335265
C13: Penalty Below Consumption | D13: 0 | E13: MMBTU/MT CPO | F13: =$D$13*$N$3 -> 0 | G13: MMBTU/day | H13: =$H$8 -> 28 | J13: =$H$13*$F$13 -> 0 | K13: =11.5*$N$6 -> 184000 | M13: =$J$13*$K$13 -> 0 | N13: =$M$13/($N$5*1000) -> 0 | O13: =($M$13/$N$6)/$N$5 -> 0
C14: Penalty Above Consumption | D14: 0 | E14: MMBTU/MT CPO | F14: =$D$14*$N$3 -> 0 | G14: MMBTU/day | H14: =$H$8 -> 28 | J14: =$H$14*$F$14 -> 0 | K14: =11.5*$N$6 -> 184000 | M14: =$J$14*$K$14 -> 0 | N14: =$M$14/($N$5*1000) -> 0 | O14: =($M$14/$N$6)/$N$5 -> 0
B15: 5 | C15: Pemakaian Steam
C16: For Process | D16: ='Februari 2026 PMG 2'!AJ256 -> 4382.6077 | E16: Kg/MT CPO | F16: =$D$16*$N$3/1000 -> 9506.7429 | G16: Ton/day | H16: =$H$8 -> 28 | J16: =$H$16*$F$16 -> 266188.8 | K16: =Steam!H15 -> 187.90511 | M16: =$J$16*$K$16 -> 50018236 | N16: =$M$16/($N$5*1000) -> 0.82351439 | O16: =($M$16/$N$6)/$N$5 -> 0.051469649
C17: Storage Tank for Heating | D17: ='Februari 2026 PMG 2'!$AJ$260 -> 9624.3039 | E17: Kg/MT CPO | F17: =$D$17*$N$3/1000 -> 20877.018 | G17: Ton/day | H17: =$H$8 -> 28 | J17: =$H$17*$F$17 -> 584556.52 | K17: =Steam!H15 -> 187.90511 | M17: =$J$17*$K$17 -> 1.0984116e+08 | N17: =$M$17/($N$5*1000) -> 1.8084559 | O17: =($M$17/$N$6)/$N$5 -> 0.11302849
B18: 6 | C18: Pemakaian Electrical
C19: For Process | D19: ='Februari 2026 PMG 2'!$AJ$297 -> 6.3594116 | E19: kW/MT CPO | F19: =$D$19*$N$3 -> 13794.821 | G19: kW/day | H19: =$H$8 -> 28 | I19: 0 | J19: =$H$19*$F$19 -> 386255 | K19: 1550 | L19: =[2]Electric!H21 -> 3666.6667 | M19: =($F$19*$H$19*$K$19)+($F$19*$I$19*$L$19) -> 598695250 | N19: =$M$19/($N$5*1000) -> 9.857088 | O19: =($M$19/$N$6)/$N$5 -> 0.616068
C20: Cooling Tower | D20: ='Februari 2026 PMG 2'!$AJ$299 -> 4.9299167 | E20: kW/MT CPO | F20: =$D$20*$N$3 -> 10693.964 | G20: kW/day | H20: =$H$8 -> 28 | I20: 0 | J20: =$H$20*$F$20 -> 299431 | K20: 1550 | L20: =L19 -> 3666.6667 | M20: =(F20*H20*K20)+(F20*I20*L20) -> 4.6411805e+08 | N20: =$M$20/($N$5*1000) -> 7.6413709 | O20: =($M$20/$N$6)/$N$5 -> 0.47758568
C21: Storage Tank | D21: 0.3377877 | E21: kW/MT CPO | F21: =$D$21*$N$3 -> 732.72832 | G21: kW/day | H21: =$H$8 -> 28 | I21: 0 | J21: =$H$21*$F$21 -> 20516.393 | K21: 1550 | L21: =L20 -> 3666.6667 | M21: =($F$21*$H$21*$K$21)+($F$21*$I$21*$L$21) -> 31800409 | N21: =$M$21/($N$5*1000) -> 0.52357093 | O21: =($M$21/$N$6)/$N$5 -> 0.032723183
B22: 7 | C22: Pemakaian Water
C23: Make Up CT | D23: ='Februari 2026 PMG 2'!$AJ$274 -> 0.11254984 | E23: M3/day | F23: =$D$23 -> 0.11254984 | G23: M3/day | H23: =$H$8 -> 28 | J23: =$H$23*$F$23 -> 3.1513955 | K23: =WTP!H13 -> 23503.384 | M23: =$J$23*$K$23 -> 74068.459 | N23: =$M$23/($N$5*1000) -> 0.0012194841 | O23: =($M$23/$N$6)/$N$5 -> 7.6217754e-05
B24: 8 | C24: Chemical Water | N24: =$M$24/($N$5*1000) -> 0 | O24: =($M$24/$N$6)/$N$5 -> 0
C25: EONBAC BC 3108 | D25: 0.4 | E25: Kg/day | F25: =D25 -> 0.4 | G25: Kg/day | H25: =$H$8 -> 28 | J25: =$H$25*$F$25 -> 11.2 | K25: 27240 | M25: =$J$25*$K$25 -> 305088 | N25: =$M$25/($N$5*1000) -> 0.0050230552 | O25: =($M$25/$N$6)/$N$5 -> 0.00031394095
C26: EONLINE T722 | D26: 0.66 | E26: Kg/day | F26: =D26 -> 0.66 | G26: Kg/day | H26: =$H$8 -> 28 | J26: =$H$26*$F$26 -> 18.48 | K26: 29120 | M26: =$J$26*$K$26 -> 538137.6 | N26: =$M$26/($N$5*1000) -> 0.0088600498 | O26: =($M$26/$N$6)/$N$5 -> 0.00055375311
C27: EONLINE AG5770 | D27: 0.41 | E27: Kg/day | F27: =D27 -> 0.41 | G27: Kg/day | H27: =$H$8 -> 28 | J27: =$H$27*$F$27 -> 11.48 | K27: 117212 | M27: =$J$27*$K$27 -> 1345593.8 | N27: =$M$27/($N$5*1000) -> 0.022154237 | O27: =($M$27/$N$6)/$N$5 -> 0.0013846398
C28: EONScale T2511 | D28: 0.1 | E28: Kg/day | F28: =D28 -> 0.1 | G28: Kg/day | H28: =$H$8 -> 28 | J28: =$H$28*$F$28 -> 2.8 | K28: 45940 | M28: =$J$28*$K$28 -> 128632 | N28: =$M$28/($N$5*1000) -> 0.0021178337 | O28: =($M$28/$N$6)/$N$5 -> 0.0001323646
B29: 9 | C29: Others
C30: Filter Bag 10 Microne | D30: 0.90361446 | E30: Pcs/day | F30: =D30 -> 0.90361446 | G30: Pcs/day | H30: =$H$8 -> 28 | J30: =$H$30*$F$30 -> 25.301205 | K30: 40000 | M30: =$J$30*$K$30 -> 1012048.2 | N30: =$M$30/($N$5*1000) -> 0.016662648 | O30: =($M$30/$N$6)/$N$5 -> 0.0010414155
C31: Filter Bag 100 Microne | D31: 0.63253012 | E31: Pcs/day | F31: =D31 -> 0.63253012 | G31: Pcs/day | H31: =$H$8 -> 28 | J31: =$H$31*$F$31 -> 17.710843 | K31: 125000 | M31: =$J$31*$K$31 -> 2213855.4 | N31: =$M$31/($N$5*1000) -> 0.036449542 | O31: =($M$31/$N$6)/$N$5 -> 0.0022780964
C32: Filter Cartridge 10 Microne | D32: 1.5666667 | E32: Pcs/day | F32: =D32 -> 1.5666667 | G32: Pcs/day | H32: =$H$8 -> 28 | J32: =$H$32*$F$32 -> 43.866667 | K32: 145000 | M32: =$J$32*$K$32 -> 6360666.7 | N32: =$M$32/($N$5*1000) -> 0.10472382 | O32: =($M$32/$N$6)/$N$5 -> 0.0065452385
C33: Filter Dustbag | D33: 0.12048193 | E33: Pcs/day | F33: =D33 -> 0.12048193 | G33: Pcs/day | H33: =$H$8 -> 28 | J33: =$H$33*$F$33 -> 3.373494 | K33: 682500 | M33: =$J$33*$K$33 -> 2302409.6 | N33: =$M$33/($N$5*1000) -> 0.037907524 | O33: =($M$33/$N$6)/$N$5 -> 0.0023692202
C34: O Ring Filter Leaves | D34: 3.6144578 | E34: Pcs/day | F34: =D34 -> 3.6144578 | G34: Pcs/day | H34: =$H$8 -> 28 | J34: =$H$34*$F$34 -> 101.20482 | K34: 14500 | M34: =$J$34*$K$34 -> 1467469.9 | N34: =$M$34/($N$5*1000) -> 0.024160839 | O34: =($M$34/$N$6)/$N$5 -> 0.0015100525
B35: 10 | C35: Waste Water Treatment Plant ( WWTP ) | D35: ='Februari 2026 PMG 2'!E279 -> 330 | E35: M3/day | F35: =D35 -> 330 | G35: M3/day | H35: =$H$8 -> 28 | J35: =$H$35*$F$35 -> 9240 | K35: =WWTP!H17 -> 473.92767 | M35: =$J$35*$K$35 -> 4379091.7 | N35: =$M$35/($N$5*1000) -> 0.072098605 | O35: =($M$35/$N$6)/$N$5 -> 0.0045061628
B36: 11 | C36: SHE
C37: SBE | D37: ='Februari 2026 PMG 2'!$AJ$91 -> 323920.17 | E37: Kg/day | F37: =D37 -> 323920.17 | G37: Kg/day | H37: =$H$8 -> 28 | J37: =$F$37 -> 323920.17 | K37: 0 | M37: =$J$37*$K$37 -> 0 | N37: =$M$37/($N$5*1000) -> 0 | O37: =($M$37/$N$6)/$N$5 -> 0
C38: Domestic | D38: 0.1 | E38: Trip/day | F38: =D38 -> 0.1 | G38: Trip/day | H38: =$H$8 -> 28 | J38: =$H$38*$F$38 -> 2.8 | K38: 303030.3 | M38: =$J$38*$K$38 -> 848484.85 | N38: =$M$38/($N$5*1000) -> 0.013969695 | O38: =($M$38/$N$6)/$N$5 -> 0.00087310592
B39: 12 | C39: Chemical Consumption | N39: =$M$39/($N$5*1000) -> 0 | O39: =($M$39/$N$6)/$N$5 -> 0
C40: LAB Chemical | D40: =lab!H33 -> 745255.21 | E40: Rp/day | F40: =D40 -> 745255.21 | G40: Rp/day | H40: =$H$8 -> 28 | M40: =$H$40*$F$40 -> 20867146 | N40: =$M$40/($N$5*1000) -> 0.3435626 | O40: =($M$40/$N$6)/$N$5 -> 0.021472662
C41: Chemical Boiler dan WTP | D41: =lab!H54 -> 259161.44 | E41: Rp/day | F41: =D41 -> 259161.44 | G41: Rp/day | H41: =$H$8 -> 28 | M41: =$H$41*$F$41 -> 7256520.4 | N41: =$M$41/($N$5*1000) -> 0.11947341 | O41: =($M$41/$N$6)/$N$5 -> 0.0074670879
...

Sheet HPP FRACT
B2: Fractionation Cost
B3: RPO Proses / Day | N3: TPD | O3: ='Februari 2026 PMG 2'!AJ24/1000 -> 1759.9365
B4: Working Day | N4: Days | O4: ='Februari 2026 PMG 2'!AJ23 -> 28
B5: Total CPO Process | N5: MTD | O5: =O3*O4 -> 49278.223
B6: KURS | N6: Rp/USD | O6: 16000
B7: No | C7: Item Cost | D7: Norma | F7: Pemakaian / Hari | H7: HK | J7: Total Pemakaian | K7: Harga / stn | M7: Total Biaya | N7: Rp / kg | O7: USD/MT
B8: 1 | C8: Steam | D8: ='Februari 2026 PMG 2'!AJ258 -> 2347.1092 | E8: Kg/MT CPO | F8: =$D$8*$O$3/1000 -> 4130.7632 | G8: Ton/day | H8: =$O$4 -> 28 | J8: =$H$8*$F$8 -> 115661.37 | K8: =Steam!H15 -> 187.90511 | M8: =$K$8*$J$8 -> 21733362 | N8: =$M$8/($O$5*1000) -> 0.44103381 | O8: =($M$8/$O$6)/$O$5 -> 0.027564613
B9: 2 | C9: Electrical
C10: For Process | D10: ='Februari 2026 PMG 2'!$AJ$304 -> 4.473126 | E10: kW/MT CPO | F10: =$D$10*$O$3 -> 7872.4179 | G10: kW/day | H10: =$O$4 -> 28 | I10: 0 | J10: =$H$10*$F$10 -> 220427.7 | K10: =[2]Electric!$L$5 -> 1550 | L10: 3666.6667 | M10: =($F$10*$H$10*$K$10)+($F$10*$I$10*$L$10) -> 3.4166294e+08 | N10: =$M$10/($O$5*1000) -> 6.9333454 | O10: =($M$10/$O$6)/$O$5 -> 0.43333409
C11: Cooling Tower | D11: ='Februari 2026 PMG 2'!$AJ$302 -> 5.2964689 | E11: kW/MT CPO | F11: =$D$11*$O$3 -> 9321.4491 | G11: kW/day | H11: =$H$10 -> 28 | I11: 0 | J11: =$H$11*$F$11 -> 261000.58 | K11: =$K$10 -> 1550 | L11: 3666.6667 | M11: =($F$11*$H$11*$K$11)+($F$11*$I$11*$L$11) -> 4.0455089e+08 | N11: =$M$11/($O$5*1000) -> 8.2095268 | O11: =($M$11/$O$6)/$O$5 -> 0.51309542
B12: 3 | C12: Water
C13: Make Up CT | D13: ='Februari 2026 PMG 2'!$AJ$276 -> 0.045537356 | E13: M3/day | F13: =$D$13 -> 0.045537356 | G13: M3/day | H13: =$H$11 -> 28 | J13: =$H$13*$F$13 -> 1.275046 | K13: =WTP!H13 -> 23503.384 | M13: =$K$13*$J$13 -> 29967.895 | N13: =$M$13/($O$5*1000) -> 0.00060813669 | O13: =($M$13/$O$6)/$O$5 -> 3.8008543e-05
B14: 4 | C14: Chemical Water
C15: EONBAC BC 3108 | D15: 0.4 | E15: Kg/day | F15: =$D$15 -> 0.4 | G15: Kg/day | H15: =$H$13 -> 28 | J15: =$H$15*$F$15 -> 11.2 | K15: 27240 | M15: =$K$15*$J$15 -> 305088 | N15: =$M$15/($O$5*1000) -> 0.0061911323 | O15: =($M$15/$O$6)/$O$5 -> 0.00038694577
C16: EONLINE T722 | D16: 0.66 | E16: Kg/day | F16: =$D$16 -> 0.66 | G16: Kg/day | H16: =$H$15 -> 28 | J16: =$H$16*$F$16 -> 18.48 | K16: 29120 | M16: =$K$16*$J$16 -> 538137.6 | N16: =$M$16/($O$5*1000) -> 0.010920394 | O16: =($M$16/$O$6)/$O$5 -> 0.00068252461
C17: EONLINE AG5770 | D17: 0.41 | E17: Kg/day | F17: =$D$17 -> 0.41 | G17: Kg/day | H17: =$H$15 -> 28 | J17: =$H$17*$F$17 -> 11.48 | K17: 117212 | M17: =$K$17*$J$17 -> 1345593.8 | N17: =$M$17/($O$5*1000) -> 0.027306053 | O17: =($M$17/$O$6)/$O$5 -> 0.0017066283
C18: EONScale T2511 | D18: 0.1 | E18: Kg/day | F18: =$D$18 -> 0.1 | G18: Kg/day | H18: =$H$16 -> 28 | J18: =$H$18*$F$18 -> 2.8 | K18: 45940 | M18: =$K$18*$J$18 -> 128632 | N18: =$M$18/($O$5*1000) -> 0.0026103214 | O18: =($M$18/$O$6)/$O$5 -> 0.00016314509
B19: 5 | C19: Others
C20: Filter Cloth | D20: 0.33333333 | E20: Pcs/day | F20: =$D$20 -> 0.33333333 | G20: Pcs/day | H20: =$H$18 -> 28 | J20: =$H$20*$F$20 -> 9.3333333 | K20: 895000 | M20: =$K$20*$J$20 -> 8353333.3 | N20: =$M$20/($O$5*1000) -> 0.16951369 | O20: =($M$20/$O$6)/$O$5 -> 0.010594606
C21: Filter Bag 100 Microne | D21: 0.63253012 | E21: Pcs/day | F21: =$D$21 -> 0.63253012 | G21: Pcs/day | H21: =$H$20 -> 28 | J21: =$H$21*$F$21 -> 17.710843 | K21: 125000 | M21: =$K$21*$J$21 -> 2213855.4 | N21: =$M$21/($O$5*1000) -> 0.044925634 | O21: =($M$21/$O$6)/$O$5 -> 0.0028078521
M22: =SUM(M8:M21) -> 7.808618e+08 | N22: =SUM(N8:N21) -> 15.845981 | O22: =SUM($O$8:$O$21) -> 0.99037383

Sheet SUMMARY HPP 
B2: Production Cost OKTOBER 2025
B3: Through Put CPO Proses (Ton/Day) | H3: TPD | I3: ='HPP REF '!$N$3 -> 2169.1977
B4: Working Day | F4: 1 | H4: Days | I4: ='HPP REF '!$N$4 -> 28
B5: Refined CPO ( Ton/month ) | H5: MTD | I5: =$I$4*$I$3 -> 60737.537
B6: Through Put RPO Proses (Ton/Day) | H6: TPD | I6: ='HPP FRACT'!$O$3 -> 1759.9365
B7: Working Day | H7: Days | I7: ='HPP FRACT'!$O$4 -> 28
B8: Fract RPO ( ton/month ) | H8: MTD | I8: =$I$7*$I$6 -> 49278.223
B9: KURS | H9: Rp/USD | I9: 16000
B10: No | C10: Items | D10: Description | G10: Rupiah | H10: Rp/Kg | I10: USD/MT
B11: I | C11: Production Cost | D11: ● | E11: Refining Cost | G11: ='HPP REF '!$M$48 -> 9.6203641e+09 | H11: =$G$11/($I$5*1000) -> 158.3924 | I11: =(G11/$I$9)/$I$5 -> 9.8995248
D12: ● | E12: Fractionation Cost | G12: ='HPP FRACT'!$M$22 -> 7.808618e+08 | H12: =$G$12/($I$8*1000) -> 15.845981 | I12: =(G12/$I$9)/$I$8 -> 0.99037383
D13: ● | E13: Preventive Maintenance Cost | F13: 0 | G13: =MTC!$F$18*F13 -> 0 | H13: =$G$13/($I$5*1000) -> 0 | I13: =(G13/$I$9)/$I$5 -> 0
G14: =SUM(G11:$G$13) -> 1.0401226e+10 | H14: =SUM($H$11:$H$13) -> 174.23838 | I14: =SUM(I11:I13) -> 10.889899
B16: II | C16: Port Cost | D16: ● | E16: Trucking Komoditi ke Kuala Tanjung | G16: =LOG!I8+LOG!I9+LOG!$I$10 -> 6.306014e+09 | H16: =$G$16/($I$5*1000) -> 103.824 | I16: =($G$16/$I$9)/$I$5 -> 6.489
D17: ● | E17: Sewa Tank PTI Total Volume : 24.000 MT ( 5 Unit ) | F17: =F4 -> 1 | G17: =LOG!I11+LOG!I12+LOG!I13+LOG!$I$14*F17 -> 1886000000 | H17: =$G$17/($I$5*1000) -> 31.051638 | I17: =($G$17/$I$9)/$I$5 -> 1.9407274
D18: ● | E18: Instalasi & Pemanasan, Pompa, Surveyor dan Documen | G18: =LOG!I18+LOG!I19+LOG!I20+LOG!$I$21 -> 3.2535884e+09 | H18: =$G$18/($I$5*1000) -> 53.568 | I18: =($G$18/$I$9)/$I$5 -> 3.348
D19: ● | E19: Finalty Over Capacity Tank | G19: =LOG!I15+LOG!I16+LOG!$I$17 -> 2.5908204e+09 | H19: =$G$19/($I$5*1000) -> 42.656 | I19: =($G$19/$I$9)/$I$5 -> 2.666
G20: =SUM($G$16:$G$19) -> 1.4036423e+10 | H20: =SUM($H$16:$H$19) -> 231.09964 | I20: =SUM($I$16:$I$19) -> 14.443727
B22: II | C22: Fix Cost | D22: ● | E22: Manpower Cost | F22: =F4 -> 1 | G22: =[2]MPC!$H$29*$F$22 -> 2.1846655e+09 | H22: =$G$22/($I$5*1000) -> 35.968952 | I22: =($G$22/$I$9)/$I$5 -> 2.2480595
D23: ● | E23: Admin OH Cost | F23: =F4 -> 1 | G23: =OH!G51*$F$23 -> 1.4360564e+09 | H23: =$G$23/($I$5*1000) -> 23.643639 | I23: =($G$23/$I$9)/$I$5 -> 1.4777274
D24: ● | E24: Depresiasi Cost | F24: =F4 -> 1 | G24: =DEP!I9*$F$24 -> 4.1811848e+09 | H24: =$G$24/($I$5*1000) -> 68.84021 | I24: =($G$24/$I$9)/$I$5 -> 4.3025131
D25: ● | E25: Amortisation of leasehold land Cost | F25: =F4 -> 1 | G25: =AMOR!$G$20*$F$25 -> 1.0484098e+09 | H25: =$G$25/($I$5*1000) -> 17.261316 | I25: =($G$25/$I$9)/$I$5 -> 1.0788322
G26: =SUM($G$22:$G$25) -> 8.8503165e+09 | H26: =SUM($H$22:$H$25) -> 145.71412 | I26: =SUM($I$22:$I$25) -> 9.1071323
B28: Total Production Cost | G28: =$G$26+$G$20+$G$14 -> 3.3287965e+10 | H28: =$H$26+$H$20+$H$14 -> 551.05213 | I28: =$I$26+$I$20+$I$14 -> 34.440758

Sheet Lembar1

Sheet OIP Fract PMG 1
A4: Oil In Plant (OIP) Fraksinasi | I4: OIP | S4: BUFFER TANK | W4: DIRECT
A5: RBDPO OIP | I5: RPO CR | M5: OLEIN | P5: STEARIN | S5: TK131 RPO | U5: TK132 RPO
A6: Vessel | B6: Operating Volume (m3) | C6: Oil Density (kg/m3) | D6: MT | E6: Level Transmitter (1%/MT) | F6: Level (%) | G6: Kg | I6: Tanggal | J6: Opening Stock | K6: Closing Stock | L6: balance stok | M6: Opening Stock | N6: Closing Stock | O6: balance stok | P6: Opening Stock | Q6: Closing Stock | R6: balance stok | S6: Opening Stock | T6: Closing Stock | U6: Opening Stock | V6: Closing Stock
A7: 2CR1201 | B7: 70.51 | C7: 890 | D7: 60 | E7: =D7/100 -> 0.6 | F7: 0 | G7: =E7*F7*1000 -> 0 | I7: 46054
A8: 2CR1202 | B8: 70.51 | C8: 890 | D8: 60 | E8: =D8/100 -> 0.6 | F8: 0 | G8: =E8*F8*1000 -> 0 | I8: 46055
A9: 2CR1203 | B9: 70.51 | C9: 890 | D9: 60 | E9: =D9/100 -> 0.6 | F9: 0 | G9: =E9*F9*1000 -> 0 | I9: 46056
A10: 2CR1204 | B10: 70.51 | C10: 890 | D10: 60 | E10: =D10/100 -> 0.6 | F10: 0 | G10: =E10*F10*1000 -> 0 | I10: 46057
A11: 2CR1205 | B11: 70.51 | C11: 890 | D11: 60 | E11: =D11/100 -> 0.6 | F11: 0 | G11: =E11*F11*1000 -> 0 | I11: 46058
A12: 2CR1206 | B12: 70.51 | C12: 890 | D12: 60 | E12: =D12/100 -> 0.6 | F12: 0 | G12: =E12*F12*1000 -> 0 | I12: 46059
A13: 2CR1207 | B13: 70.51 | C13: 890 | D13: 60 | E13: =D13/100 -> 0.6 | F13: 0 | G13: =E13*F13*1000 -> 0 | I13: 46060
A14: 2CR1208 | B14: 70.51 | C14: 890 | D14: 60 | E14: =D14/100 -> 0.6 | F14: 0 | G14: =E14*F14*1000 -> 0 | I14: 46061
A15: 2CR1209 | B15: 70.51 | C15: 890 | D15: 60 | E15: =D15/100 -> 0.6 | F15: 0 | G15: =E15*F15*1000 -> 0 | I15: 46062
A16: 2CR1210 | B16: 70.51 | C16: 890 | D16: 60 | E16: =D16/100 -> 0.6 | F16: 0 | G16: =E16*F16*1000 -> 0 | I16: 46063
A17: 2CR1211 | B17: 70.51 | C17: 890 | D17: 60 | E17: =D17/100 -> 0.6 | F17: 0 | G17: =E17*F17*1000 -> 0 | I17: 46064
A18: 2CR1212 | B18: 70.51 | C18: 890 | D18: 60 | E18: =D18/100 -> 0.6 | F18: 0 | G18: =E18*F18*1000 -> 0 | I18: 46065
... A21: 2CR1215 | B21: 70.51 | C21: 890 | D21: 60 | E21: =D21/100 -> 0.6 | F21: 0 | G21: =E21*F21*1000 -> 0 | I21: 46068
I22: 46069
F23: Total RBDPO | G23: =SUM(G7:G21) -> 0 | I23: 46070
I24: 46071
A25: Olein OIP | I25: 46072 | J25: =K24 -> 0 | K25: 394320 | M25: =N24 -> 0 | N25: 26250
A26: Vessel | B26: Operating Volume (m3) | C26: Oil Density (kg/m3) | D26: MT | E26: Level Transmitter (1%/MT) | F26: Level (%) | G26: Kg | I26: 46073 | J26: =K25 -> 394320 | K26: 449900 | M26: =N25 -> 26250 | N26: 21050
A27: 2TK261 | B27: 15.95 | C27: 885 | D27: =B27*C27/1000 -> 14.11575 | E27: =D27/100 -> 0.1411575 | G27: =E27*F27*1000 -> 0 | I27: 46074 | J27: =K26 -> 449900 | K27: 388000 | M27: =N26 -> 21050 | N27: 33600
A28: 2CL251 | B28: 3.02 | C28: 885 | D28: =B28*C28/1000 -> 2.6727 | E28: =D28/100 -> 0.026727 | G28: =E28*F28*1000 -> 0 | I28: 46075 | J28: =K27 -> 388000 | K28: 226400 | M28: =N27 -> 33600 | N28: 25980
A29: 2TK221 | B29: 82.48 | C29: 885 | D29: =B29*C29/1000 -> 72.9948 | E29: =D29/100 -> 0.729948 | G29: =E29*F29*1000 -> 0 | I29: 46076 | J29: =K28 -> 226400 | K29: 15960 | M29: =N28 -> 25980 | N29: 26050
A30: 2TK241 | B30: 16.95 | C30: 885 | D30: =B30*C30/1000 -> 15.00075 | E30: =D30/100 -> 0.1500075 | G30: =E30*F30*1000 -> 0 | I30: 46077 | J30: =K29 -> 15960 | K30: 506180 | M30: =N29 -> 26050 | N30: 26050
F31: Total Olein | G31: =SUM(G27:G30) -> 0 | I31: 46078 | J31: =K30 -> 506180 | K31: 398700 | M31: =N30 -> 26050 | N31: 26470
I32: 46079 | J32: =K31 -> 398700 | K32: 388950 | M32: =N31 -> 26470 | N32: 40850
I33: 46080 | J33: =K32 -> 388950 | M33: =N32 -> 40850
I34: 46081 | J34: =K33 -> 0 | M34: =N33 -> 0
A39: Stearin OIP
A40: Melting Tank | B40: Panjang (m) | C40: Lebar (m) | D40: tinggi (m) | E40: Density | F40: Tinggi Sounding (Cm) Maks 4,4 m | G40: Kg
A41: TK231 A | B41: 12.2 | C41: 1.75 | D41: 1.52 | E41: 0.88 | F41: 0 | G41: =B41*C41*D41*E41*F41/100 -> 0
A42: TK231 B | B42: 12.2 | C42: 1.75 | D42: 1.52 | E42: 0.88 | F42: 0 | G42: =B42*C42*D42*E42*F42/100 -> 0
F43: Total STEARIN | G43: =SUM(G41:G42) -> 0

Sheet Februari 2026 PMG 2
C1: PRODUCTION REPORT PMG 2
C2: No | D2: ITEM | E2: Budget / Norma | F2: UoM | G2: Februari 2026 | AJ2: TOTAL MONTHLY (Kg)
G3: 1 | H3: 2 | I3: 3 | J3: 4 | K3: 5 | L3: 6 | M3: 7 | N3: 8 | O3: 9 | P3: 10 | Q3: 11 | R3: 12 | S3: 13 | T3: 14 | U3: 15 | V3: 16 | W3: 17 | X3: 18 | Y3: 19 | Z3: 20 | AA3: 21 | AB3: 22 | AC3: 23 | AD3: 24 | AE3: 25 | AF3: 26 | AG3: 27 | AH3: 28
C4: 1 | D4: PRODUCTION | AJ4: Production | AL4: aktual refinery | AO4: opening stok rpo | AP4: =AP6+AP7+AP9 -> 80236
D5: Refinery | AJ5: Refinery | AL5: cpo feed | AM5: =AJ9 -> 60737537 | AO5: sisa rbpo tank
D6: Running Days | E6: 24 | F6: Day | G6: 1 | H6: 1 | I6: 1 | J6: 1 | K6: 1 | L6: 1 | M6: 1 | N6: 1 | O6: 1 | P6: 1 | Q6: 1 | R6: 1 | S6: 1 | T6: 1 | U6: 1 | V6: 1 | W6: 1 | X6: 1 | Y6: 1 | Z6: 1 | AA6: 1 | AB6: 1 | AC6: 1 | AD6: 1 | AE6: 1 | AF6: 1 | AG6: 1 | AH6: 1 | AJ6: =SUM(G6:AH6) -> 28 | AL6: rpo prod | AM6: =AJ20+AJ19+AJ18 -> 57977499 | AO6: tk 108 | AP6: 80236
D7: Incoming CPO | F7: Kg | G7: 1565196 | H7: 770270 | I7: 2113786 | J7: 1913843 | K7: 2352974 | L7: 3345000 | M7: 2952195 | N7: 1685073 | O7: 986350 | P7: 2312199 | Q7: 3163913 | R7: 2191531 | S7: 2065679 | T7: 2294814 | U7: 1930209 | V7: 2160626 | W7: 1214092 | X7: 1849690 | Y7: 2351337 | Z7: 2999000 | AA7: 2156902 | AB7: 1660100 | AC7: 1939870 | AD7: 2515085 | AE7: 2408043 | AF7: 2711413 | AG7: 2570464 | AH7: 1934846 | AJ7: =SUM(G7:AH7) -> 60114500 | AR7: =AJ7+'Februari 2026 PMG 1'!AJ7 -> 60114500
D8: Ratio Run CPO ( utilisasi kapasitas ) | F8: % | G8: =G9/2500000 -> 0.8040568 | H8: =H9/2500000 -> 0.8868388 | I8: =I9/2500000 -> 0.8052924 | J8: =J9/2500000 -> 0.8644532 | K8: =K9/2500000 -> 0.8582316 | L8: =L9/2500000 -> 0.730854 | M8: =M9/2500000 -> 0.8053832 | N8: =N9/2500000 -> 0.7657356 | ... AH8: =AH9/2500000 -> 0.8689092 | AJ8: =AJ9/2500000/AJ6 -> 0.8676791
D9: CPO Consume Total | E9: 48093.551 | F9: Kg | G9: 2010142 | H9: 2217097 | I9: 2013231 | J9: 2161133 | K9: 2145579 | L9: 1827135 | M9: 2013458 | N9: 1914339 | O9: 2036210 | P9: 2449732 | Q9: 2207000 | R9: 2040539 | S9: 2078053 | T9: 1585660 | U9: 1776733 | V9: 1933001 | W9: 2446881 | X9: 2548876 | Y9: 2469258 | Z9: 2408490 | AA9: 2376176 | AB9: 2608876 | AC9: 2393732 | AD9: 2274218 | AE9: 2443224 | AF9: 2070039 | AG9: 2116452 | AH9: 2172273 | AJ9: =SUM(G9:AH9) -> 60737537
D10: Avg Daily Consump CPO ( MTD ) | AJ10: =AJ9/AJ6 -> 2169197.8
D11: CPO Consume Poram | F11: Kg | G11: =G9-G12 -> 2010142 | H11: =H9-H12 -> 2217097 | I11: =I9-I12 -> 2013231 | J11: =J9-J12 -> 2161133 | K11: =K9-K12 -> 2145579 | L11: =L9-L12 -> 1827135 | M11: =M9-M12 -> 2013458 | N11: =N9-N12 -> 1914339 | ... AH11: =AH9-AH12 -> 2172273 | AJ11: =SUM(G11:AH11) -> 60737537
D12: CPO Consume Brand | F12: Kg | G12: =G40+G49+G54 -> 0 | H12: =H40+H49+H54 -> 0 | AJ12: =SUM(G12:AH12) -> 0
D13: - FFA | E13: 5 | F13: % | G13: 3.94 | H13: =(3.67+3.95)/2 -> 3.81 | I13: =(4.36+3.7)/2 -> 4.03 | J13: 3.71 | K13: =(4.15+4.21)/2 -> 4.18 | L13: =(4.1+4.22)/2 -> 4.16 | M13: 4.25 | N13: =(4.2+3.98)/2 -> 4.09 | O13: 4.11 | P13: =(4.12+4.01)/2 -> 4.065 | Q13: =(4.01+3.95)/2 -> 3.98 | R13: 3.96 | S13: =(3.95+4)/2 -> 3.975 | T13: 4.01 | U13: 4.01 | V13: 3.95 | W13: 3.99 | X13: =(3.98+3.99)/2 -> 3.985 | Y13: 3.98 | Z13: =(3.99+4.12)/2 -> 4.055 | AA13: 4.12 | AB13: =(4.16+3.93)/2 -> 4.045 | AC13: 4.05 | AD13: =(3.97+4.17)/2 -> 4.07 | AE13: 4.11 | AF13: 4.14 | AG13: 4.16 | AH13: 4.05 | AJ13: =SUM(G13:AH13)/AJ6 -> 4.0351786 | AL13: rpo feed | AM13: =AM14+AM15 -> 39712496 | AO13: tk131 | AP13: ='OIP Fract PMG 2'!T13 -> 200835
D14: - Moist & Impurities | E14: 0.5 | F14: % | G14: 0.42 | H14: =(0.42+0.44)/2 -> 0.43 | I14: =(0.45+0.35)/2 -> 0.4 | J14: 0.38 | K14: =(0.4+0.46)/2 -> 0.43 | L14: =(0.4+0.46)/2 -> 0.43 | M14: 0.46 | N14: =(0.46+0.36)/2 -> 0.41 | O14: 0.4 | P14: =(0.37+0.38)/2 -> 0.375 | Q14: =(0.4+0.42)/2 -> 0.41 | R14: 0.42 | S14: =(0.42+0.41)/2 -> 0.415 | T14: 0.4 | U14: 0.4 | V14: 0.39 | W14: 0.39 | X14: =(0.4+0.4)/2 -> 0.4 | Y14: 0.4 | Z14: =(0.41+0.37)/2 -> 0.39 | AA14: 0.38 | AB14: =(0.4+0.39)/2 -> 0.395 | AC14: 0.39 | AD14: =(0.37+0.38)/2 -> 0.375 | AE14: 0.38 | AF14: 0.41 | AG14: 0.4 | AH14: 0.4 | AJ14: =SUM(G14:AH14)/AJ6 -> 0.40285714 | AL14: olein 56 | AM14: =AJ33 -> 33000682 | AO14: tk132 | AP14: ='OIP Fract PMG 2'!U13 -> 114939
D15: - DOBI | E15: 2,20 Min | F15: % | AJ15: =SUM(G15:AH15)/AJ6 -> 0 | AL15: stearin 56 | AM15: =AJ34 -> 6711814 | AO15: after
D16: TANK | G16: 107 | H16: 106107 | I16: 104106 | J16: 106 | K16: 107104 | L16: 107104 | M16: 104 | N16: 104106 | O16: 107 | P16: 106107 | Q16: 107104 | R16: 104 | S16: 104107 | T16: 106 | U16: 106 | V16: 107 | W16: 107 | X16: 106107 | Y16: 106 | Z16: 106103 | AA16: 103 | AB16: 103107 | AC16: 107 | AD16: 106103 | AE16: 103 | AF16: 106 | AG16: 106 | AH16: 106 | AL16: yield olein | AM16: =AM14/(AM14+AM15)*100 -> 83.098987 | AO16: tk131 | AP16: =AP13 -> 200835
D17: Product | AJ17: Product | AL17: yield stearin | AM17: =AM15/(AM14+AM15)*100 -> 16.901013 | AO17: tk132 | AP17: =AP14-AM13 -> -39597557
D18: OIP RBDPO | F18: Kg | AJ18: =SUM(G18:AH18) -> 0
D19: DIRECT RBDPO FRACT | F19: Kg | G19: 1917000 | H19: 2113326 | I19: 1912963 | J19: 2332133 | K19: 2035181 | L19: 1731169 | M19: 1911945 | N19: 1820597 | O19: 1934293 | P19: 2327461 | Q19: 2099971 | R19: 1942907 | S19: 1971871 | T19: 1504162 | U19: 1686679 | V19: 1847188 | W19: 2330791 | X19: 2415706 | Y19: 2344049 | Z19: 2284965 | AA19: 2246848 | AB19: 2468887 | AC19: 2266883 | AD19: 2159846 | AE19: 2321868 | AF19: 1970076 | AG19: 2005719 | AH19: 2073015 | AJ19: =SUM(G19:AH19) -> 57977499
D20: RBDPO | E20: 45448.405 | F20: Kg | AJ20: =SUM(G20:AH20) -> 0
D21: PFAD | E21: 2308.4904 | F21: Kg | G21: 85768 | H21: 93136 | I21: 89158 | J21: 90000 | K21: 99100 | L21: 86927 | M21: 88760 | N21: 83135 | O21: 88886 | P21: 106308 | Q21: 94673 | R21: 85891 | S21: 87870 | T21: 70599 | U21: 81006 | V21: 77260 | W21: 104620 | X21: 113653 | Y21: 108660 | Z21: 102639 | AA21: 111540 | AB21: 124535 | AC21: 113122 | AD21: 97957 | AE21: 102747 | AF21: 89268 | AG21: 96599 | AH21: 87729 | AJ21: =SUM(G21:AH21) -> 2661546
D22: Fractionation
D23: Running Days | F23: Day | G23: 1 | H23: 1 | I23: 1 | J23: 1 | K23: 1 | L23: 1 | M23: 1 | N23: 1 | O23: 1 | P23: 1 | Q23: 1 | R23: 1 | S23: 1 | T23: 1 | U23: 1 | V23: 1 | W23: 1 | X23: 1 | Y23: 1 | Z23: 1 | AA23: 1 | AB23: 1 | AC23: 1 | AD23: 1 | AE23: 1 | AF23: 1 | AG23: 1 | AH23: 1 | AJ23: =SUM(G23:AH23) -> 28
D24: Avg Daily Consump RBDPO ( MTD ) | F24: Kg | G24: 0 | H24: 0 | AJ24: =AJ29/AJ23 -> 1759936.5
D25: Total RBDPO transfer to plant | F25: Kg | AJ25: =SUM(G25:AH25) -> 0
D26: Stok TK 131 | E26: 559 | F26: ton
D27: Stok TK 132 | E27: 559 | F27: ton
D28: Ratio Run RBDPO | F28: % | G28: =G29/2500000 -> 0.7386484 | H28: =H29/2500000 -> 0.7752728 | I28: =I29/2500000 -> 0.798872 | J28: =J29/2500000 -> 0.8185852 | K28: =K29/2500000 -> 0.8863812 | L28: =L29/2500000 -> 0.7349376 | M28: =M29/2500000 -> 0.6574152 | N28: =N29/2500000 -> 0.5946088 | ... AH28: =AH29/2500000 -> 0.7373288 | AJ28: =AJ29/2500000/AJ23 -> 0.70397461
D29: Total Proses RBDPO | E29: 49015.009 | F29: Kg | G29: =SUM(G32,G36,G41,G45,G55) -> 1846621 | H29: =SUM(H32,H36,H41,H45,H55) -> 1938182 | I29: =SUM(I32,I36,I41,I45,I55) -> 1997180 | J29: =SUM(J32,J36,J41,J45,J55) -> 2046463 | K29: =SUM(K32,K36,K41,K45,K55) -> 2215953 | L29: =SUM(L32,L36,L41,L45,L55) -> 1837344 | M29: =SUM(M32,M36,M41,M45,M55) -> 1643538 | N29: =SUM(N32,N36,N41,N45,N55) -> 1486522 | ... AH29: =SUM(AH32,AH36,AH41,AH45,AH55) -> 1843322 | AJ29: =SUM(G29:AH29) -> 49278223
D30: Sisa Filling Crystalizer | F30: Kg | G30: =G25-G29 -> -1846621 | H30: =H25-H29 -> -1938182 | AJ30: =SUM(G30:AH30) -> -3784803
D31: Fractionation OLEIN IV 56 | AJ31: Olein IV 56
D32: RBDPO Consume | F32: Kg | G32: =G33+G34 -> 1846621 | H32: =H33+H34 -> 1938182 | I32: =I33+I34 -> 1997180 | J32: =J33+J34 -> 2046463 | K32: =K33+K34 -> 2215953 | L32: =L33+L34 -> 1837344 | M32: =M33+M34 -> 1202723 | N32: =N33+N34 -> 0 | ... AH32: =AH33+AH34 -> 1843322 | AJ32: =SUM(G32:AH32) -> 39712496
D33: OLEIN IV 56 | E33: 40192.308 | F33: Kg | G33: 1513692 | H33: 1612199 | I33: 1657711 | J33: 1699816 | K33: 1850384 | L33: 1512176 | M33: 1014930 | P33: 89177 | Q33: 1506554 | R33: 1650659 | S33: 1605938 | T33: 1651695 | U33: 1689760 | V33: 1421100 | W33: 1726177 | X33: 1672975 | Y33: 696877 | AC33: 1343911 | AD33: 1684618 | AE33: 1686144 | AF33: 724525 | AG33: 1432240 | AH33: 1557424 | AJ33: =SUM(G33:AH33) -> 33000682 | AK33: ok cek konsum rpo pas
D34: STEARIN | E34: 639000 | F34: Kg | G34: 332929 | H34: 325983 | I34: 339469 | J34: 346647 | K34: 365569 | L34: 325168 | M34: 187793 | P34: 19500 | Q34: 364890 | R34: 293500 | S34: 313329 | T34: 322834 | U34: 360538 | V34: 318939 | W34: 352933 | X34: 350573 | Y34: 130039 | AC34: 263494 | AD34: 357261 | AE34: 317070 | AF34: 146420 | AG34: 291038 | AH34: 285898 | AJ34: =SUM(G34:AH34) -> 6711814 | AK34: ok cek konsum rpo pas
D35: Fractionation OLEIN IV 57 ( Bulk ) | AJ35: Olein IV 57 ( Bulk )
D36: RBDPO Consume | F36: Kg | G36: =G37+G38 -> 0 | H36: =H37+H38 -> 0 | AJ36: =SUM(G36:AH36) -> 0
D37: OLEIN IV 57 | F37: Kg | H37: 0 | AJ37: =SUM(G37:AH37) -> 0
D38: STEARIN | F38: Kg | H38: 0 | AJ38: =SUM(G38:AH38) -> 0
D39: Fractionation OLEIN IV 57 ( Retail ) | AJ39: Olein IV 57 ( Retail )
D40: CPO Consume | F40: Kg | AJ40: =SUM(G40:AH40) -> 0
...

Sheet Convert Gas
B3: CONVERT PEMAKAIAN GAS HP BOILER & MP BOILER
B4: Februari 2026
B5: Tanggal | C5: HP BOILER | F5: TOTAL CORRECTED VOLUME (Sm3) | K5: ENERGY MP BOILER (MMBTU) | L5: TOTAL GAS CONSUMPTION (MMBTU) | M5: PERCENTAGE
C6: UNCORRECTED VOLUME (UV) (Nm3) | D6: PRESS. Bar | E6: CORRECTED VOLUME (CV) (Sm3) | G6: Convert Sm3 to SCF | H6: VOLUME (MSCF) | I6: HEATING VALUE (BTU / SCF) | J6: ENERGY HP BOILER (MMBTU) | M6: HP Boiler | N6: MP Boiler
C7: 1 | D7: 2 | E7: 3 = 1 x 2 | F7: 4 = 3 | G7: 5 | H7: 6 = (4 x 5) / 1000 | I7: 7 | J7: 8 = (6 x 7) / 1000 | K7: 9 = 10 - 8 | L7: 10 | M7: 11 = 8 / 10 | N7: 12 = 9 / 10
B8: 1 | D8: 5 | E8: =C8*D8 -> 0 | F8: =E8 -> 0 | G8: 35.314667 | H8: =(F8*G8)/1000 -> 0 | I8: 1064.9573 | J8: =(H8*I8)/1000 -> 0 | K8: =L8-J8 -> 0 | M8: =(J8/L8) -> #DIV/0! | N8: =K8/L8 -> #DIV/0!
B9: =B8+1 -> 2 | D9: 5 | E9: =C9*D9 -> 0 | F9: =E9 -> 0 | G9: 35.314667 | H9: =(F9*G9)/1000 -> 0 | I9: 1068.3854 | J9: =(H9*I9)/1000 -> 0 | K9: =L9-J9 -> 0 | M9: =(J9/L9) -> #DIV/0! | N9: =K9/L9 -> #DIV/0!
B10: =B9+1 -> 3 | D10: 5 | E10: =C10*D10 -> 0 | F10: =E10 -> 0 | G10: 35.314667 | H10: =(F10*G10)/1000 -> 0 | I10: 1072.5902 | J10: =(H10*I10)/1000 -> 0 | K10: =L10-J10 -> 0 | M10: =(J10/L10) -> #DIV/0! | N10: =K10/L10 -> #DIV/0!
B11: =B10+1 -> 4 | D11: 5 | E11: =C11*D11 -> 0 | F11: =E11 -> 0 | G11: 35.314667 | H11: =(F11*G11)/1000 -> 0 | J11: =(H11*I11)/1000 -> 0 | K11: =L11-J11 -> 0 | M11: =(J11/L11) -> #DIV/0! | N11: =K11/L11 -> #DIV/0!
B12: =B11+1 -> 5 | D12: 5 | E12: =C12*D12 -> 0 | F12: =E12 -> 0 | G12: 35.314667 | H12: =(F12*G12)/1000 -> 0 | J12: =(H12*I12)/1000 -> 0 | K12: =L12-J12 -> 0 | M12: =(J12/L12) -> #DIV/0! | N12: =K12/L12 -> #DIV/0!
B13: =B12+1 -> 6 | D13: 5 | E13: =C13*D13 -> 0 | F13: =E13 -> 0 | G13: 35.314667 | H13: =(F13*G13)/1000 -> 0 | J13: =(H13*I13)/1000 -> 0 | K13: =L13-J13 -> 0 | M13: =(J13/L13) -> #DIV/0! | N13: =K13/L13 -> #DIV/0!
B14: =B13+1 -> 7 | D14: 5 | E14: =C14*D14 -> 0 | F14: =E14 -> 0 | G14: 35.314667 | H14: =(F14*G14)/1000 -> 0 | J14: =(H14*I14)/1000 -> 0 | K14: =L14-J14 -> 0 | M14: =(J14/L14) -> #DIV/0! | N14: =K14/L14 -> #DIV/0!
B15: =B14+1 -> 8 | D15: 5 | E15: =C15*D15 -> 0 | F15: =E15 -> 0 | G15: 35.314667 | H15: =(F15*G15)/1000 -> 0 | J15: =(H15*I15)/1000 -> 0 | K15: =L15-J15 -> 0 | M15: =(J15/L15) -> #DIV/0! | N15: =K15/L15 -> #DIV/0!
B16: =B15+1 -> 9 | D16: 5 | E16: =C16*D16 -> 0 | F16: =E16 -> 0 | G16: 35.314667 | H16: =(F16*G16)/1000 -> 0 | J16: =(H16*I16)/1000 -> 0 | K16: =L16-J16 -> 0 | M16: =(J16/L16) -> #DIV/0! | N16: =K16/L16 -> #DIV/0!
B17: =B16+1 -> 10 | D17: 5 | E17: =C17*D17 -> 0 | F17: =E17 -> 0 | G17: 35.314667 | H17: =(F17*G17)/1000 -> 0 | J17: =(H17*I17)/1000 -> 0 | K17: =L17-J17 -> 0 | M17: =(J17/L17) -> #DIV/0! | N17: =K17/L17 -> #DIV/0!
B18: =B17+1 -> 11 | D18: 5 | E18: =C18*D18 -> 0 | F18: =E18 -> 0 | G18: 35.314667 | H18: =(F18*G18)/1000 -> 0 | J18: =(H18*I18)/1000 -> 0 | K18: =L18-J18 -> 0 | M18: =(J18/L18) -> #DIV/0! | N18: =K18/L18 -> #DIV/0!
B19: =B18+1 -> 12 | D19: 5 | E19: =C19*D19 -> 0 | F19: =E19 -> 0 | G19: 35.314667 | H19: =(F19*G19)/1000 -> 0 | J19: =(H19*I19)/1000 -> 0 | K19: =L19-J19 -> 0 | M19: =(J19/L19) -> #DIV/0! | N19: =K19/L19 -> #DIV/0!
B20: =B19+1 -> 13 | D20: 5 | E20: =C20*D20 -> 0 | F20: =E20 -> 0 | G20: 35.314667 | H20: =(F20*G20)/1000 -> 0 | J20: =(H20*I20)/1000 -> 0 | K20: =L20-J20 -> 0 | M20: =(J20/L20) -> #DIV/0! | N20: =K20/L20 -> #DIV/0!
B21: =B20+1 -> 14 | D21: 5 | E21: =C21*D21 -> 0 | F21: =E21 -> 0 | G21: 35.314667 | H21: =(F21*G21)/1000 -> 0 | J21: =(H21*I21)/1000 -> 0 | K21: =L21-J21 -> 0 | M21: =(J21/L21) -> #DIV/0! | N21: =K21/L21 -> #DIV/0!
B22: =B21+1 -> 15 | D22: 5 | E22: =C22*D22 -> 0 | F22: =E22 -> 0 | G22: 36.314667 | H22: =(F22*G22)/1000 -> 0 | J22: =(H22*I22)/1000 -> 0 | K22: =L22-J22 -> 0 | M22: =(J22/L22) -> #DIV/0! | N22: =K22/L22 -> #DIV/0!
... B35: =B34+1 -> 28 | D35: 5 | E35: =C35*D35 -> 0 | F35: =E35 -> 0 | G35: 49.314667 | H35: =(F35*G35)/1000 -> 0 | J35: =(H35*I35)/1000 -> 0 | K35: =L35-J35 -> 0 | M35: =(J35/L35) -> #DIV/0! | N35: =K35/L35 -> #DIV/0!
B36: Average | F36: =E36 -> 0 | H36: =AVERAGE(H8:H35) -> 0 | I36: =AVERAGE(I8:I35) -> 1068.6443 | J36: =AVERAGE(J8:J35) -> 0 | K36: =AVERAGE(K8:K35) -> 0 | L36: =AVERAGE(L8:L35) -> #DIV/0! | M36: =AVERAGE(M8:M35) -> #DIV/0! | N36: =AVERAGE(N8:N35) -> #DIV/0!
B37: TOTAL | C37: =SUM(C8:C35) -> 0 | E37: =SUM(E8:E35) -> 0 | F37: =E37 -> 0 | H37: =SUM(H8:H35) -> 0 | J37: =SUM(J8:J35) -> 0
B38: Koreksi
B39: Total Setelah Koreksi | H39: =H37+H38 -> 0 | J39: =J37+J38 -> 0
C41: CONVERT HP Boiler from Utility
C42: =C37 -> 0 | D42: m3 | F42: =C37*5 -> 0 | G42: 9983.7
C43: 5 | D43: bar | F43: 21286.9 | G43: =G42-C37 -> 9983.7
C44: =C42*C43 -> 0 | D44: Sm3 | F44: =F42/F43 -> 0
C45: =#REF! -> #REF! | D45: Scf
C46: =(C44*C45)/1000 -> #REF! | D46: Volume (MSCF)
C47: =I36 -> 1068.6443 | D47: Heating Value
C48: =(C46*C47)/1000 -> #REF! | D48: Energy (mmbtu)

Sheet OIP Ref PMG 2
B4: Oil In Plant (OIP) Refinery pmg 2 | I4: Februari | J4: OIP | M4: TK131 RPO | P4: TK132 RPO | S4: TOTAL STOK RPO DI PLANT
B5: Vessel | C5: Operating Volume (m3) | D5: Oil Density (kg/m3) | E5: MT | F5: Level yg diisi | G5: Actual OIP (Kg) | I5: Tanggal | J5: Opening Stock | K5: Closing Stock | L5: balance stok | M5: Opening Stock | N5: Closing Stock | O5: CONSUMP stok | P5: Opening Stock | Q5: Closing Stock | R5: CONSUMP stok
B6: 2MX312 | C6: 5.67 | D6: 850 | E6: =C6*D6/1000 -> 4.8195 | F6: 100 | G6: =(F6*E6/100)*1000 -> 4819.5 | I6: 46054 | J6: 301079 | K6: 300189 | L6: =J6-K6 -> 890
B7: 2VE611A | C7: 47.22 | D7: 850 | E7: =C7*D7/1000 -> 40.137 | F7: 80 | G7: =(F7*E7/100)*1000 -> 32109.6 | I7: 46055 | J7: =K6 -> 300189 | K7: 300254 | L7: =J7-K7 -> -65
B8: 2VE611B | C8: 47.22 | D8: 850 | E8: =C8*D8/1000 -> 40.137 | F8: 80 | G8: =(F8*E8/100)*1000 -> 32109.6 | I8: 46056 | J8: =K7 -> 300254 | K8: 300189 | L8: =J8-K8 -> 65
B9: 2VE612 | C9: 35.68 | D9: 850 | E9: =C9*D9/1000 -> 30.328 | F9: 80 | G9: =(F9*E9/100)*1000 -> 24262.4 | I9: 46057 | J9: =K8 -> 300189 | K9: 301618 | L9: =J9-K9 -> -1429
B10: 2VE661 | C10: 10.8 | D10: 850 | E10: =C10*D10/1000 -> 9.18 | F10: 17 | G10: =(F10*E10/100)*1000 -> 1560.6 | I10: 46058 | J10: =K9 -> 301618 | K10: 300254 | L10: =J10-K10 -> 1364
B11: FL621 | C11: 10.1 | D11: 850 | E11: =C11*D11/1000 -> 8.585 | F11: 100 | G11: =(F11*E11/100)*1000 -> 8585 | I11: 46059 | J11: =K10 -> 300254 | K11: 299800 | L11: =J11-K11 -> 454
B12: FL622 | C12: 10.1 | D12: 850 | E12: =C12*D12/1000 -> 8.585 | F12: 100 | G12: =(F12*E12/100)*1000 -> 8585 | I12: 46060 | J12: =K11 -> 299800 | K12: 300254 | L12: =J12-K12 -> -454
B13: FL623 | C13: 10.1 | D13: 850 | E13: =C13*D13/1000 -> 8.585 | F13: 100 | G13: =(F13*E13/100)*1000 -> 8585 | I13: 46061 | J13: =K12 -> 300254 | K13: 308759 | L13: =J13-K13 -> -8505 | N13: 0 | Q13: 174609
B14: FL624 | C14: 10.1 | D14: 850 | E14: =C14*D14/1000 -> 8.585 | F14: 0 | G14: =(F14*E14/100)*1000 -> 0 | I14: 46062 | J14: =K13 -> 308759 | K14: 302600 | L14: =J14-K14 -> 6159 | N14: 44191 | P14: 174609 | Q14: 38852 | R14: =P14-Q14 -> 135757 | S14: =R14+O14+L14 -> 141916
B15: FL625 | C15: 10.1 | D15: 850 | E15: =C15*D15/1000 -> 8.585 | F15: 100 | G15: =(F15*E15/100)*1000 -> 8585 | I15: 46063 | J15: =K14 -> 302600 | K15: 313438 | L15: =J15-K15 -> -10838 | M15: 44191 | N15: 405272 | O15: =M15-N15 -> -361081 | P15: 38852 | Q15: 38852 | R15: =P15-Q15 -> 0 | S15: =R15+O15+L15 -> -371919
B16: 2VE701 | C16: 72.13 | D16: 850 | E16: =C16*D16/1000 -> 61.3105 | F16: 15 | G16: =(F16*E16/100)*1000 -> 9196.575 | I16: 46064 | J16: =K15 -> 313438 | K16: 293386 | L16: =J16-K16 -> 20052
B17: 2VE751 | C17: 4.28 | D17: 860 | E17: =C17*D17/1000 -> 3.6808 | F17: 50 | G17: =(F17*E17/100)*1000 -> 1840.4 | I17: 46065 | J17: =K16 -> 293386 | K17: 309940 | L17: =J17-K17 -> -16554
B18: 2HE721A (tube) | C18: 10 | D18: 810 | E18: =C18*D18/1000 -> 8.1 | F18: 100 | G18: =(F18*E18/100)*1000 -> 8100 | I18: 46066 | J18: =K17 -> 309940 | K18: 296910 | L18: =J18-K18 -> 13030
B19: 2HE721A (shell) | C19: 21.8 | D19: 800 | E19: =C19*D19/1000 -> 17.44 | F19: 30 | G19: =(F19*E19/100)*1000 -> 5232 | I19: 46067 | J19: =K18 -> 296910 | K19: 295027 | L19: =J19-K19 -> 1883
B20: HE721B (tube) | C20: 10 | D20: 810 | E20: =C20*D20/1000 -> 8.1 | F20: 100 | G20: =(F20*E20/100)*1000 -> 8100 | I20: 46068 | J20: =K19 -> 295027 | K20: 286594 | L20: =J20-K20 -> 8433
B21: 2HE722 | C21: 11.4 | D21: 790 | E21: =C21*D21/1000 -> 9.006 | F21: 80 | G21: =(F21*E21/100)*1000 -> 7204.8 | I21: 46069 | J21: =K20 -> 286594 | K21: 300102 | L21: =J21-K21 -> -13508
B22: 2PR731 | C22: 14 | D22: 790 | E22: =C22*D22/1000 -> 11.06 | F22: 30 | G22: =(F22*E22/100)*1000 -> 3318 | I22: 46070 | J22: =K21 -> 300102 | K22: 295092 | L22: =J22-K22 -> 5010
B23: 2DE732 | C23: 149.76 | D23: 790 | E23: =C23*D23/1000 -> 118.3104 | F23: 100 | G23: =(F23*E23/100)*1000 -> 118310.4 | I23: 46071 | J23: =K22 -> 295092 | K23: 294300 | L23: =J23-K23 -> 792
C24: =SUM(C6:C23) -> 490.46 | E24: =SUM(E6:E23) -> 404.5342 | G24: =(F24*E24/100)*1000 -> 0 | I24: 46072 | J24: =K23 -> 294300 | K24: 298309 | L24: =J24-K24 -> -4009
F25: Total OIP = | G25: =SUM(G6:G24) -> 290503.88 | I25: 46073 | J25: =K24 -> 298309 | K25: 294600 | L25: =J25-K25 -> 3709
I26: 46074 | J26: =K25 -> 294600 | K26: 298005 | L26: =J26-K26 -> -3405
I27: 46075 | J27: =K26 -> 298005 | K27: 297702 | L27: =J27-K27 -> 303
I28: 46076 | J28: =K27 -> 297702 | K28: 295092 | L28: =J28-K28 -> 2610
I29: 46077 | J29: =K28 -> 295092 | K29: 301618 | L29: =J29-K29 -> -6526
I30: 46078 | J30: =K29 -> 301618 | K30: 297702 | L30: =J30-K30 -> 3916
H31: 0 | I31: 46079 | J31: =K30 -> 297702 | K31: 290504 | L31: =J31-K31 -> 7198
I32: 46080 | J32: =K31 -> 290504 | K32: 305832 | L32: =J32-K32 -> -15328
I33: 46081 | J33: =K32 -> 305832 | K33: 307640 | L33: =J33-K33 -> -1808
B38: Solar Daily Tank HPB
B39: 2TK726 | C39: =5.3+0.78 -> 6.08 | D39: 840 | E39: =C39*D39/1000 -> 5.1072 | F39: 0 | G39: =F39*E39/100*1000 -> 0
B41: Stock Chemicals In Plant
C42: Sisa Stok Di Lap | D42: Order | E42: Consumption
B43: BE
B44: 630A | D44: 298
B45: 630B
B46: H3PO4
B47: NaOH
B48: Citrid Acid

Sheet OIP Fract PMG 2
A4: Oil In Plant (OIP) Fraksinasi | I4: OIP | S4: BUFFER TANK | W4: DIRECT
A5: RBDPO OIP | I5: RPO CR | M5: OLEIN | P5: STEARIN | S5: TK131 RPO | U5: TK132 RPO
A6: Vessel | B6: Operating Volume (m3) | C6: Oil Density (kg/m3) | D6: MT | E6: Level Transmitter (1%/MT) | F6: Level (%) | G6: Kg | I6: Tanggal | J6: Opening Stock | K6: Closing Stock | L6: balance stok | M6: Opening Stock | N6: Closing Stock | O6: balance stok | P6: Opening Stock | Q6: Closing Stock | R6: balance stok | S6: Opening Stock | T6: Closing Stock | U6: Opening Stock | V6: Closing Stock
A7: 2CR1201 | B7: 70.51 | C7: 890 | D7: 60 | E7: =D7/100 -> 0.6 | F7: 100 | G7: =E7*F7*1000 -> 60000 | I7: 46054 | J7: 865440 | K7: 900000 | M7: 21752 | N7: 21638 | S7: 75754 | T7: 87668 | U7: 62644 | V7: 87553
A8: 2CR1202 | B8: 70.51 | C8: 890 | D8: 60 | E8: =D8/100 -> 0.6 | F8: 99.9 | G8: =E8*F8*1000 -> 59940 | I8: 46055 | J8: =K7 -> 900000 | K8: 840000 | M8: =N7 -> 21638 | N8: 21448 | S8: =T7 -> 87668 | T8: 206458 | U8: =V7 -> 87553 | V8: 204032
A9: 2CR1203 | B9: 70.51 | C9: 890 | D9: 60 | E9: =D9/100 -> 0.6 | F9: 99.8 | G9: =E9*F9*1000 -> 59880 | I9: 46056 | J9: =K8 -> 840000 | K9: 840000 | M9: =N8 -> 21448 | N9: 45871 | S9: =T8 -> 206458 | T9: 150700 | U9: =V8 -> 204032 | V9: 151215
A10: 2CR1204 | B10: 70.51 | C10: 890 | D10: 60 | E10: =D10/100 -> 0.6 | F10: 98.5 | G10: =E10*F10*1000 -> 59100 | I10: 46057 | J10: =K9 -> 840000 | K10: 840000 | M10: =N9 -> 45871 | N10: 21160 | S10: =T9 -> 150700 | T10: 172935 | U10: =V9 -> 151215 | V10: 168861
A11: 2CR1205 | B11: 70.51 | C11: 890 | D11: 60 | E11: =D11/100 -> 0.6 | F11: 99.3 | G11: =E11*F11*1000 -> 59580 | I11: 46058 | J11: =K10 -> 840000 | K11: 840000 | M11: =N10 -> 21160 | N11: 35819 | S11: =T10 -> 172935 | T11: 387069 | U11: =V10 -> 168861 | V11: 378931
A12: 2CR1206 | B12: 70.51 | C12: 890 | D12: 60 | E12: =D12/100 -> 0.6 | F12: 100 | G12: =E12*F12*1000 -> 60000 | I12: 46059 | J12: =K11 -> 840000 | K12: 840000 | M12: =N11 -> 35819 | N12: 50658 | S12: =T11 -> 387069 | T12: 124359 | U12: =V11 -> 378931 | V12: 114939
A13: 2CR1207 | B13: 70.51 | C13: 890 | D13: 60 | E13: =D13/100 -> 0.6 | F13: 100 | G13: =E13*F13*1000 -> 60000 | I13: 46060 | J13: =K12 -> 840000 | K13: 720000 | M13: =N12 -> 50658 | N13: 25140 | S13: =T12 -> 124359 | T13: 200835 | U13: =V12 -> 114939 | V13: 190826
A14: 2CR1208 | B14: 70.51 | C14: 890 | D14: 60 | E14: =D14/100 -> 0.6 | F14: 100 | G14: =E14*F14*1000 -> 60000 | I14: 46061 | J14: =K13 -> 720000 | K14: 478620 | M14: =N13 -> 25140 | N14: 21421 | S14: =T13 -> 200835 | T14: 35000 | U14: =V13 -> 190826 | V14: 35000
A15: 2CR1209 | B15: 70.51 | C15: 890 | D15: 60 | E15: =D15/100 -> 0.6 | F15: 0 | G15: =E15*F15*1000 -> 0 | I15: 46062 | J15: =K14 -> 478620 | K15: 200680 | M15: =N14 -> 21421 | N15: 38896 | S15: =T14 -> 35000 | T15: 50000 | U15: =V14 -> 35000 | V15: 50000
A16: 2CR1210 | B16: 70.51 | C16: 890 | D16: 60 | E16: =D16/100 -> 0.6 | F16: 0 | G16: =E16*F16*1000 -> 0 | I16: 46063 | J16: =K15 -> 200680 | K16: 879600 | M16: =N15 -> 38896 | N16: 21214 | S16: =T15 -> 50000 | T16: 205239 | U16: =V15 -> 50000 | V16: 171858
A17: 2CR1211 | B17: 70.51 | C17: 890 | D17: 60 | E17: =D17/100 -> 0.6 | F17: 0 | G17: =E17*F17*1000 -> 0 | I17: 46064 | J17: =K16 -> 879600 | K17: 898860 | M17: =N16 -> 21214 | N17: 20603 | S17: =T16 -> 205239 | T17: 306034 | U17: =V16 -> 171858 | V17: 300993
A18: 2CR1212 | B18: 70.51 | C18: 890 | D18: 60 | E18: =D18/100 -> 0.6 | G18: =E18*F18*1000 -> 0 | I18: 46065 | J18: =K17 -> 898860 | K18: 898860 | M18: =N17 -> 20603 | N18: 21310 | S18: =T17 -> 306034 | T18: 293967 | U18: =V17 -> 300993 | V18: 294547
A19: 2CR1213 | B19: 70.51 | C19: 890 | D19: 60 | E19: =D19/100 -> 0.6 | F19: 67.2 | G19: =E19*F19*1000 -> 40320 | I19: 46066 | J19: =K18 -> 898860 | K19: 853260 | M19: =N18 -> 21310 | N19: 21008 | S19: =T18 -> 293967 | T19: 354542 | U19: =V18 -> 294547 | V19: 345508
A20: 2CR1214 | B20: 70.51 | C20: 890 | D20: 60 | E20: =D20/100 -> 0.6 | F20: 100 | G20: =E20*F20*1000 -> 60000 | I20: 46067 | J20: =K19 -> 853260 | K20: 845220 | M20: =N19 -> 21008 | N20: 37602 | S20: =T19 -> 354542 | T20: 116226 | U20: =V19 -> 345508 | V20: 106786
A21: 2CR1215 | B21: 70.51 | C21: 890 | D21: 60 | E21: =D21/100 -> 0.6 | F21: 100 | G21: =E21*F21*1000 -> 60000 | I21: 46068 | J21: =K20 -> 845220 | K21: 700020 | M21: =N20 -> 37602 | N21: 20628 | S21: =T20 -> 116226 | T21: 15000 | U21: =V20 -> 106786 | V21: 15000
I22: 46069 | J22: =K21 -> 700020 | K22: 720000 | M22: =N21 -> 20628 | N22: 20289 | S22: =T21 -> 15000 | T22: 54000 | U22: =V21 -> 15000 | V22: 50000
F23: Total RBDPO | G23: =SUM(G7:G21) -> 638820 | I23: 46070 | J23: =K22 -> 720000 | K23: 886260 | M23: =N22 -> 20289 | N23: 20656 | S23: =T22 -> 54000 | T23: 94451 | U23: =V22 -> 50000 | V23: 99613
I24: 46071 | J24: =K23 -> 886260 | K24: 844140 | M24: =N23 -> 20656 | N24: 20290 | S24: =T23 -> 94451 | T24: 50000 | U24: =V23 -> 99613 | V24: 50000
A25: Olein OIP | I25: 46072 | J25: =K24 -> 844140 | K25: 780000 | M25: =N24 -> 20290 | N25: 20067 | S25: =T24 -> 50000 | T25: 323798 | U25: =V24 -> 50000 | V25: 319831
A26: Vessel | B26: Operating Volume (m3) | C26: Oil Density (kg/m3) | D26: MT | E26: Level Transmitter (1%/MT) | F26: Level (%) | G26: Kg | I26: 46073 | J26: =K25 -> 780000 | K26: 660000 | M26: =N25 -> 20067 | N26: 19770 | S26: =T25 -> 323798 | T26: 277341 | U26: =V25 -> 319831 | V26: 264258
A27: 2TK261 | B27: 15.95 | C27: 885 | D27: =B27*C27/1000 -> 14.11575 | E27: =D27/100 -> 0.1411575 | F27: 49.3 | G27: =E27*F27*1000 -> 6959.0647 | I27: 46074 | J27: =K26 -> 660000 | K27: 833340 | M27: =N26 -> 19770 | N27: 19914 | S27: =T26 -> 277341 | T27: 133592 | U27: =V26 -> 264258 | V27: 120761
A28: 2CL251 | B28: 3.02 | C28: 885 | D28: =B28*C28/1000 -> 2.6727 | E28: =D28/100 -> 0.026727 | F28: 0 | G28: =E28*F28*1000 -> 0 | I28: 46075 | J28: =K27 -> 833340 | K28: 840000 | M28: =N27 -> 19914 | N28: 19461 | S28: =T27 -> 133592 | T28: 183924 | U28: =V27 -> 120761 | V28: 182268
A29: 2TK221 | B29: 82.48 | C29: 885 | D29: =B29*C29/1000 -> 72.9948 | E29: =D29/100 -> 0.729948 | F29: 0 | G29: =E29*F29*1000 -> 0 | I29: 46076 | J29: =K28 -> 840000 | K29: 841200 | M29: =N28 -> 19461 | N29: 19742 | S29: =T28 -> 183924 | T29: 424601 | U29: =V28 -> 182268 | V29: 425314
