Workbook

Sheet April 2025
C1: PRODUCTION REPORT PMG2
C2: No | D2: ITEM | E2: Budget / Norma | F2: UoM | G2: APRIL 2025 STOP PLANT | AM2: TOTAL MONTHLY (Kg)
G3: 1 | H3: 2 | I3: 3 | J3: 4 | K3: 5 | L3: 6 | M3: 7 | N3: 8 | O3: 9 | P3: 10 | Q3: 11 | R3: 12 | S3: 13 | T3: 14 | U3: 15 | V3: 16 | W3: 17 | X3: 18 | Y3: 19 | Z3: 20 | AA3: 21 | AB3: 22 | AC3: 23 | AD3: 24 | AE3: 25 | AF3: 26 | AG3: 27 | AH3: 28 | AI3: 29 | AJ3: 30 | AK3: 31
C4: 1 | D4: PRODUCTION | AM4: Production
D5: Refinery | AM5: Refinery
D6: Running Days | F6: Day | G6: 0 | H6: 0 | I6: 0 | J6: 0 | K6: 0 | L6: 0 | M6: 0 | N6: 0 | O6: 0 | P6: 0 | AM6: =SUM(G6:AK6) -> 0
D7: Incoming CPO | F7: Kg | AM7: =SUM(G7:AK7) -> 0 | AQ7: =AM7/28 -> 0
D8: Ratio Run CPO ( utilisasi kapasitas ) | F8: % | G8: =G9/2500000*100 -> 0 | H8: =H9/2500000*100 -> 0 | I8: =I9/2500000*100 -> 0 | J8: =J9/2500000*100 -> 0 | K8: =K9/2500000*100 -> 0 | L8: =L9/2500000*100 -> 0 | M8: =M9/2500000*100 -> 0 | N8: =N9/2500000*100 -> 0 | ... P8: =P9/2500000*100 -> 0 | AK8: =AK9/2500000*100 -> 0 | AM8: =AM9/2500000/AM6 -> #DIV/0!
D9: CPO Consume Total | E9: 58900 | F9: Kg | AM9: =SUM(G9:AK9) -> 0
D10: Avg Daily Consump CPO ( MTD ) | AM10: =AM9/AM6 -> #DIV/0! | AN10: =AM9/E9 -> 0
D11: CPO Consume Poram | F11: Kg | G11: =G9-G12 -> 0 | H11: =H9-H12 -> 0 | I11: =I9-I12 -> 0 | J11: =J9-J12 -> 0 | K11: =K9-K12 -> 0 | L11: =L9-L12 -> 0 | M11: =M9-M12 -> 0 | N11: =N9-N12 -> 0 | ... P11: =P9-P12 -> 0 | AK11: =AK9-AK12 -> 0 | AM11: =SUM(G11:AK11) -> 0
D12: CPO Consume Brand | F12: Kg | G12: =G39+G48+G53 -> 0 | H12: =H39+H48+H53 -> 0 | I12: =I39+I48+I53 -> 0 | J12: =J39+J48+J53 -> 0 | K12: 0 | L12: =L39+L48+L53 -> 0 | M12: =M39+M48+M53 -> 0 | N12: =N39+N48+N53 -> 0 | O12: =O39+O48+O53 -> 0 | P12: =P39+P48+P53 -> 0 | AK12: =AK39+AK48+AK53 -> 0 | AM12: =SUM(G12:AK12) -> 0
D13: - FFA | E13: 5 | F13: % | G13: 0 | H13: 0 | I13: 0 | J13: 0 | K13: 0 | L13: 0 | M13: 0 | N13: 0 | O13: 0 | P13: 0 | AM13: =SUM(G13:AK13)/AM6 -> #DIV/0!
D14: - Moist & Impurities | E14: 0.5 | F14: % | G14: 0 | H14: 0 | I14: 0 | J14: 0 | K14: 0 | L14: 0 | M14: 0 | N14: 0 | O14: 0 | P14: 0 | AM14: =SUM(G14:AK14)/AM6 -> #DIV/0!
D15: - DOBI | E15: 2,20 Min | F15: % | G15: 0 | H15: 0 | I15: 0 | J15: 0 | K15: 0 | L15: 0 | M15: 0 | N15: 0 | O15: 0 | P15: 0 | AM15: =SUM(G15:AK15)/AM6 -> #DIV/0!
D16: TANK | G16: 0 | H16: 0 | I16: 0 | J16: 0 | K16: 0 | L16: 0 | M16: 0 | N16: 0 | O16: 0 | P16: 0
D17: Product | AM17: Product
D18: OIP RBDPO
D19: RBDPO | E19: 55661 | F19: Kg | G19: 0 | H19: 0 | I19: 0 | J19: 0 | K19: 0 | L19: 0 | M19: 0 | N19: 0 | O19: 0 | P19: 0 | AM19: =SUM(G19:AK19) -> 0
D20: PFAD | E20: 2827 | F20: Kg | G20: 0 | H20: 0 | I20: 0 | J20: 0 | K20: 0 | L20: 0 | M20: 0 | N20: 0 | O20: 0 | P20: 0 | AM20: =SUM(G20:AK20) -> 0
D21: Fractionation
D22: Running Days | F22: Day | AM22: =SUM(G22:AK22) -> 0
D23: Avg Daily Consump RBDPO ( MTD ) | F23: Kg | G23: 0 | H23: 0 | I23: 0 | J23: 0 | K23: 0 | L23: 0 | M23: 0 | N23: 0 | O23: 0 | P23: 0 | AK23: 0 | AM23: =AM28/AM22 -> #DIV/0!
D24: Total RBDPO transfer to plant | F24: Kg | AM24: =SUM(G24:AK24) -> 0
D25: Stok TK 131 | E25: 559 | F25: ton | AM25: 0
D26: Stok TK 132 | E26: 559 | F26: ton | AM26: 0
D27: Ratio Run RBDPO | AM27: =AM28/2500000/10 -> 0
D28: Total Proses RBDPO | E28: 35501 | F28: Kg | G28: =SUM(G31,G35,G40,G44,G54) -> 0 | H28: =SUM(H31,H35,H40,H44,H54) -> 0 | I28: =SUM(I31,I35,I40,I44,I54) -> 0 | J28: =SUM(J31,J35,J40,J44,J54) -> 0 | L28: =SUM(L31,L35,L40,L44,L54) -> 0 | M28: =SUM(M31,M35,M40,M44,M54) -> 0 | N28: =SUM(N31,N35,N40,N44,N54) -> 0 | O28: =SUM(O31,O35,O40,O44,O54) -> 0 | P28: =SUM(P31,P35,P40,P44,P54) -> 0 | AK28: =SUM(AK31,AK35,AK40,AK44,AK54) -> 0 | AM28: =SUM(G28:AK28) -> 0 | AN28: =AM28/E19 -> 0
D29: Sisa Filling Crystalizer | F29: Kg | G29: =G24-G28 -> 0 | I29: =I24-I28 -> 0 | J29: =SUM(J32,J36,J41,J45,#REF!) -> #REF! | K29: 68473 | L29: =L24-L28 -> 0 | M29: =M24-M28 -> 0 | N29: =N24-N28 -> 0 | O29: =O24-O28 -> 0 | P29: =P24-P28 -> 0 | AK29: =AK24-AK28 -> 0 | AM29: =SUM(G29:AK29) -> #REF!
D30: Fractionation OLEIN IV 56 | AM30: Olein IV 56
D31: RBDPO Consume | F31: Kg | G31: =G32+G33 -> 0 | H31: =H32+H33 -> 0 | I31: =I32+I33 -> 0 | J31: =J32+J33 -> 0 | K31: 0 | L31: =L32+L33 -> 0 | M31: =M32+M33 -> 0 | N31: =N32+N33 -> 0 | O31: =O32+O33 -> 0 | P31: =P32+P33 -> 0 | Q31: =Q32+Q33 -> 0 | R31: =R32+R33 -> 0 | S31: 0 | T31: =T32+T33 -> 0 | U31: =U32+U33 -> 0 | V31: =V32+V33 -> 0 | W31: =W32+W33 -> 0 | AH31: =AH32+AH33 -> 0 | AK31: =AK32+AK33 -> 0 | AM31: =SUM(G31:AK31) -> 0
D32: OLEIN IV 56 | E32: 25000 | F32: Kg | G32: 0 | H32: 0 | I32: 0 | J32: 0 | K32: 0 | L32: 0 | M32: 0 | N32: 0 | O32: 0 | P32: 0 | Q32: 0 | R32: 0 | S32: 0 | T32: 0 | U32: 0 | V32: 0 | W32: 0 | X32: 0 | Y32: 0 | Z32: 0 | AA32: 0 | AB32: 0 | AC32: 0 | AD32: 0 | AF32: 0 | AG32: 0 | AH32: 0 | AK32: 0 | AM32: =SUM(G32:AK32) -> 0
D33: STEARIN | E33: 6390 | F33: Kg | G33: 0 | H33: 0 | I33: 0 | J33: 0 | K33: 0 | L33: 0 | M33: 0 | N33: 0 | O33: 0 | P33: 0 | Q33: 0 | R33: 0 | S33: 0 | T33: 0 | U33: 0 | V33: 0 | W33: 0 | X33: 0 | Y33: 0 | Z33: 0 | AA33: 0 | AB33: 0 | AC33: 0 | AD33: 0 | AF33: 0 | AG33: 0 | AK33: 0 | AM33: =SUM(G33:AK33) -> 0
D34: Fractionation OLEIN IV 57 ( Bulk ) | AM34: Olein IV 57 ( Bulk )
D35: RBDPO Consume | F35: Kg | G35: =G36+G37 -> 0 | H35: =H36+H37 -> 0 | I35: =I36+I37 -> 0 | J35: =J36+J37 -> 0 | K35: 0 | L35: =L36+L37 -> 0 | M35: =M36+M37 -> 0 | N35: =N36+N37 -> 0 | O35: =O36+O37 -> 0 | P35: =P36+P37 -> 0 | Q35: =Q36+Q37 -> 0 | R35: =R36+R37 -> 0 | S35: 0 | T35: =T36+T37 -> 0 | U35: =U36+U37 -> 0 | V35: =V36+V37 -> 0 | W35: =W36+W37 -> 0 | X35: =X36+X37 -> 0 | AA35: =AA36+AA37 -> 0 | AB35: =AB36+AB37 -> 0 | AC35: 0 | AD35: =AD36+AD37 -> 0 | AF35: =AF36+AF37 -> 0 | AG35: =AG36+AG37 -> 0 | AH35: =AH36+AH37 -> 0 | AK35: =AK36+AK37 -> 0 | AM35: =SUM(G35:AK35) -> 0
D36: OLEIN IV 57 | F36: Kg | G36: 0 | H36: 0 | I36: 0 | J36: 0 | K36: 0 | L36: 0 | M36: 0 | N36: 0 | O36: 0 | P36: 0 | Q36: 0 | R36: 0 | S36: 0 | T36: 0 | U36: 0 | V36: 0 | W36: 0 | X36: 0 | AA36: 0 | AB36: 0 | AC36: 0 | AD36: 0 | AF36: 0 | AG36: 0 | AM36: =SUM(G36:AK36) -> 0
D37: STEARIN | F37: Kg | G37: 0 | H37: 0 | I37: 0 | J37: 0 | K37: 0 | L37: 0 | M37: 0 | N37: 0 | O37: 0 | P37: 0 | Q37: 0 | R37: 0 | S37: 0 | T37: 0 | U37: 0 | V37: 0 | W37: 0 | X37: 0 | AA37: 0 | AB37: 0 | AC37: 0 | AD37: 0 | AE37: 0 | AF37: 0 | AG37: 0 | AM37: =SUM(G37:AK37) -> 0
D38: Fractionation OLEIN IV 57 ( Retail ) | AM38: Olein IV 57 ( Retail )
D39: CPO Consume | F39: Kg | AM39: =SUM(G39:AK39) -> 0
D40: RBDPO Brand Consume | F40: Kg | G40: =G41+G42 -> 0 | H40: =H41+H42 -> 0 | I40: =I41+I42 -> 0 | J40: =J41+J42 -> 0 | K40: 0 | L40: =L41+L42 -> 0 | M40: =M41+M42 -> 0 | N40: =N41+N42 -> 0 | O40: =O41+O42 -> 0 | P40: =P41+P42 -> 0 | Q40: =Q41+Q42 -> 0 | R40: =R41+R42 -> 0 | S40: 0 | T40: =T41+T42 -> 0 | U40: =U41+U42 -> 0 | V40: =V41+V42 -> 0 | W40: =W41+W42 -> 0 | X40: =X41+X42 -> 0 | AA40: =AA41+AA42 -> 0 | AB40: =AB41+AB42 -> 0 | AC40: 0 | AD40: =AD41+AD42 -> 0 | AE40: =AE41+AE42 -> 0 | AF40: =AF41+AF42 -> 0 | AG40: =AG41+AG42 -> 0 | AH40: =AH41+AH42 -> 0 | AK40: =AK41+AK42 -> 0 | AM40: =SUM(G40:AK40) -> 0
...

Sheet OIP Refinery 
B4: Oil In Plant (OIP) Refinery pmg 2 | I4: FEBUARI | J4: OIP | M4: TK131 RPO | P4: TK132 RPO | S4: TOTAL STOK RPO DI PLANT
B5: Vessel | C5: Operating Volume (m3) | D5: Oil Density (kg/m3) | E5: MT | F5: Level yg diisi | G5: Actual OIP (Kg) | I5: Tanggal | J5: Opening Stock | K5: Closing Stock | L5: balance stok | M5: Opening Stock | N5: Closing Stock | O5: CONSUMP stok | P5: Opening Stock | Q5: Closing Stock | R5: CONSUMP stok
B6: 2MX312 | C6: 5.67 | D6: 850 | E6: =C6*D6/1000 -> 4.8195 | F6: 0 | G6: =(F6*E6/100)*1000 -> 0 | I6: 45689
B7: 2VE611A | C7: 47.22 | D7: 850 | E7: =C7*D7/1000 -> 40.137 | F7: 0 | G7: =(F7*E7/100)*1000 -> 0 | I7: 45690
B8: 2VE611B | C8: 47.22 | D8: 850 | E8: =C8*D8/1000 -> 40.137 | F8: 0 | G8: =(F8*E8/100)*1000 -> 0 | I8: 45691
B9: 2VE612 | C9: 35.68 | D9: 850 | E9: =C9*D9/1000 -> 30.328 | F9: 0 | G9: =(F9*E9/100)*1000 -> 0 | I9: 45692
B10: 2VE661 | C10: 10.8 | D10: 850 | E10: =C10*D10/1000 -> 9.18 | F10: 0 | G10: =(F10*E10/100)*1000 -> 0 | I10: 45693
B11: FL621 | C11: 10.1 | D11: 850 | E11: =C11*D11/1000 -> 8.585 | F11: 0 | G11: =(F11*E11/100)*1000 -> 0 | I11: 45694 | L11: =J11-K11 -> 0
B12: FL622 | C12: 10.1 | D12: 850 | E12: =C12*D12/1000 -> 8.585 | F12: 0 | G12: =(F12*E12/100)*1000 -> 0 | I12: 45695 | L12: =J12-K12 -> 0
B13: FL623 | C13: 10.1 | D13: 850 | E13: =C13*D13/1000 -> 8.585 | F13: 0 | G13: =(F13*E13/100)*1000 -> 0 | I13: 45696 | L13: =J13-K13 -> 0 | N13: 0 | Q13: 174609
B14: FL624 | C14: 10.1 | D14: 850 | E14: =C14*D14/1000 -> 8.585 | F14: 0 | G14: =(F14*E14/100)*1000 -> 0 | I14: 45697 | L14: =J14-K14 -> 0 | N14: 44191 | P14: 174609 | Q14: 38852 | R14: =P14-Q14 -> 135757 | S14: =R14+O14+L14 -> 135757
B15: FL625 | C15: 10.1 | D15: 850 | E15: =C15*D15/1000 -> 8.585 | F15: 0 | G15: =(F15*E15/100)*1000 -> 0 | I15: 45698 | L15: =J15-K15 -> 0 | M15: 44191 | N15: 405272 | O15: =M15-N15 -> -361081 | P15: 38852 | Q15: 38852 | R15: =P15-Q15 -> 0 | S15: =R15+O15+L15 -> -361081
B16: 2VE701 | C16: 72.13 | D16: 850 | E16: =C16*D16/1000 -> 61.3105 | F16: 0 | G16: =(F16*E16/100)*1000 -> 0 | I16: 45699 | L16: 0
B17: 2VE751 | C17: 4.28 | D17: 860 | E17: =C17*D17/1000 -> 3.6808 | F17: 0 | G17: =(F17*E17/100)*1000 -> 0 | I17: 45700 | L17: =J17-K17 -> 0
B18: 2HE721A (tube) | C18: 10 | D18: 810 | E18: =C18*D18/1000 -> 8.1 | F18: 0 | G18: =(F18*E18/100)*1000 -> 0 | I18: 45701 | L18: =J18-K18 -> 0
B19: 2HE721A (shell) | C19: 21.8 | D19: 800 | E19: =C19*D19/1000 -> 17.44 | F19: 0 | G19: =(F19*E19/100)*1000 -> 0 | I19: 45702 | L19: =J19-K19 -> 0
B20: HE721B (tube) | C20: 10 | D20: 810 | E20: =C20*D20/1000 -> 8.1 | F20: 0 | G20: =(F20*E20/100)*1000 -> 0 | I20: 45703 | L20: =J20-K20 -> 0
B21: 2HE722 | C21: 11.4 | D21: 790 | E21: =C21*D21/1000 -> 9.006 | F21: 0 | G21: =(F21*E21/100)*1000 -> 0 | I21: 45704 | L21: =J21-K21 -> 0
B22: 2PR731 | C22: 14 | D22: 790 | E22: =C22*D22/1000 -> 11.06 | F22: 0 | G22: =(F22*E22/100)*1000 -> 0 | I22: 45705 | L22: =J22-K22 -> 0
B23: 2DE732 | C23: 149.76 | D23: 790 | E23: =C23*D23/1000 -> 118.3104 | F23: 0 | G23: =(F23*E23/100)*1000 -> 0 | I23: 45706 | L23: =J23-K23 -> 0
C24: =SUM(C6:C23) -> 490.46 | E24: =SUM(E6:E23) -> 404.5342 | I24: 45707 | L24: =J24-K24 -> 0
F25: Total OIP = | G25: =SUM(G6:G24) -> 0 | I25: 45708 | L25: =J25-K25 -> 0
I26: 45709 | L26: =J26-K26 -> 0
I27: 45710 | L27: =J27-K27 -> 0
I28: 45711 | L28: =J28-K28 -> 0
I29: 45712 | L29: =J29-K29 -> 0
B30: Solar Daily Tank HPB | I30: 45713 | L30: =J30-K30 -> 0
B31: 2TK726 | C31: =5.3+0.78 -> 6.08 | D31: 840 | E31: =C31*D31/1000 -> 5.1072 | F31: 0 | G31: =F31*E31/100*1000 -> 0 | H31: 0 | I31: 45714
I32: 45715
B33: Stock Chemicals In Plant | I33: 45716
C34: Read | D34: End Read | E34: Consumption
B35: BE
B36: 630A
B37: 630B
B38: H3PO4
B39: NaOH
B40: Citrid Acid

Sheet Oip Fract .
A4: Oil In Plant (OIP) Fraksinasi | I4: OIP | S4: BUFFER TANK
A5: RBDPO OIP pmg 2 | I5: RPO CR | M5: OLEIN | P5: STEARIN | S5: TK131 RPO | U5: TK132 RPO
A6: Vessel | B6: Operating Volume (m3) | C6: Oil Density (kg/m3) | D6: MT | E6: Level Transmitter (1%/MT) | F6: Level (%) | G6: Kg | I6: Tanggal | J6: Opening Stock | K6: Closing Stock | L6: balance stok | M6: Opening Stock | N6: Closing Stock | O6: balance stok | P6: Opening Stock | Q6: Closing Stock | R6: balance stok | S6: Opening Stock | T6: Closing Stock | U6: Opening Stock | V6: Closing Stock
A7: 2CR1201 | B7: 70.51 | C7: 890 | D7: 60 | E7: =D7/100 -> 0.6 | F7: 0 | G7: =E7*F7*1000 -> 0 | I7: 45658
A8: 2CR1202 | B8: 70.51 | C8: 890 | D8: 60 | E8: =D8/100 -> 0.6 | F8: 0 | G8: =E8*F8*1000 -> 0 | I8: 45659
A9: 2CR1203 | B9: 70.51 | C9: 890 | D9: 60 | E9: =D9/100 -> 0.6 | F9: 0 | G9: =E9*F9*1000 -> 0 | I9: 45660
A10: 2CR1204 | B10: 70.51 | C10: 890 | D10: 60 | E10: =D10/100 -> 0.6 | F10: 0 | G10: =E10*F10*1000 -> 0 | I10: 45661
A11: 2CR1205 | B11: 70.51 | C11: 890 | D11: 60 | E11: =D11/100 -> 0.6 | F11: 0 | G11: =E11*F11*1000 -> 0 | I11: 45662
A12: 2CR1206 | B12: 70.51 | C12: 890 | D12: 60 | E12: =D12/100 -> 0.6 | F12: 0 | G12: =E12*F12*1000 -> 0 | I12: 45663
A13: 2CR1207 | B13: 70.51 | C13: 890 | D13: 60 | E13: =D13/100 -> 0.6 | F13: 0 | G13: =E13*F13*1000 -> 0 | I13: 45664
A14: 2CR1208 | B14: 70.51 | C14: 890 | D14: 60 | E14: =D14/100 -> 0.6 | F14: 0 | G14: =E14*F14*1000 -> 0 | I14: 45665 | L14: =J14-K14 -> 0
A15: 2CR1209 | B15: 70.51 | C15: 890 | D15: 60 | E15: =D15/100 -> 0.6 | F15: 0 | G15: =E15*F15*1000 -> 0 | I15: 45666 | L15: =J15-K15 -> 0
A16: 2CR1210 | B16: 70.51 | C16: 890 | D16: 60 | E16: =D16/100 -> 0.6 | F16: 0 | G16: =E16*F16*1000 -> 0 | I16: 45667 | L16: =J16-K16 -> 0 | O16: =M16-N16 -> 0 | R16: =P16-Q16 -> 0
A17: 2CR1211 | B17: 70.51 | C17: 890 | D17: 60 | E17: =D17/100 -> 0.6 | F17: 0 | G17: =E17*F17*1000 -> 0 | I17: 45668 | W17: =S17+U17 -> 0
A18: 2CR1212 | B18: 70.51 | C18: 890 | D18: 60 | E18: =D18/100 -> 0.6 | F18: 0 | G18: =E18*F18*1000 -> 0 | I18: 45669
A19: 2CR1213 | B19: 70.51 | C19: 890 | D19: 60 | E19: =D19/100 -> 0.6 | F19: 0 | G19: =E19*F19*1000 -> 0 | I19: 45670
A20: 2CR1214 | B20: 70.51 | C20: 890 | D20: 60 | E20: =D20/100 -> 0.6 | F20: 0 | G20: =E20*F20*1000 -> 0 | I20: 45671
A21: 2CR1215 | B21: 70.51 | C21: 890 | D21: 60 | E21: =D21/100 -> 0.6 | F21: 0 | G21: =E21*F21*1000 -> 0 | I21: 45672
I22: 45673
F23: Total RBDPO | G23: =SUM(G7:G21) -> 0 | I23: 45674
I24: 45675
A25: Olein OIP | I25: 45676
A26: Vessel | B26: Operating Volume (m3) | C26: Oil Density (kg/m3) | D26: MT | E26: Level Transmitter (1%/MT) | F26: Level (%) | G26: Kg | I26: 45677
A27: 2TK261 | B27: 15.95 | C27: 885 | D27: =B27*C27/1000 -> 14.11575 | E27: =D27/100 -> 0.1411575 | G27: =E27*F27*1000 -> 0 | I27: 45678
A28: 2CL251 | B28: 3.02 | C28: 885 | D28: =B28*C28/1000 -> 2.6727 | E28: =D28/100 -> 0.026727 | G28: =E28*F28*1000 -> 0 | I28: 45679
A29: 2TK221 | B29: 82.48 | C29: 885 | D29: =B29*C29/1000 -> 72.9948 | E29: =D29/100 -> 0.729948 | G29: =E29*F29*1000 -> 0 | I29: 45680
A30: 2TK241 | B30: 16.95 | C30: 885 | D30: =B30*C30/1000 -> 15.00075 | E30: =D30/100 -> 0.1500075 | G30: =E30*F30*1000 -> 0 | I30: 45681
F31: Total OLEIN | G31: =SUM(G27:G30) -> 0 | I31: 45682
A32: Stearin OIP | I32: 45683
A33: Melting Tank | B33: Panjang (m) | C33: Lebar (m) | D33: tinggi (m) | E33: Density | F33: Tinggi Sounding (Cm) Maks 4,4 m | G33: Kg | I33: 45684
A34: TK231 A | B34: 12.2 | C34: 1.75 | D34: 1.52 | E34: 0.88 | F34: 0 | G34: =B34*C34*D34*E34*F34/100 -> 0 | I34: 45685
A35: TK231 B | B35: 12.2 | C35: 1.75 | D35: 1.52 | E35: 0.88 | F35: 0 | G35: =B35*C35*D35*E35*F35/100 -> 0 | I35: 45686
F36: Total STEARIN | G36: =SUM(G34:G35) -> 0 | I36: 45687
I37: 45688
T38: =S34+U34 -> 0

Sheet Downtime Ref Apr
D3: DOWN TIME SLOW FLOWRATE PRODUCTION REFINERY
D5: Periode 01 s.d 30 April 2025
D6: TANGGAL | E6: CAPACITY (Kg) | F6: REMARKS | G6: Down time | K6: Tph
G7: Stop | H7: Slow | I7: %
D8: 1 | E8: 0 | F8: SHUT DOWN | H8: =(2500-(E8/1000))/105 -> 23.809524 | I8: =E8/2500/1000 -> 0 | K8: =(E8/1000)/24 -> 0
D9: 2 | E9: 0 | F9: SHUT DOWN | H9: =(2500-(E9/1000))/105 -> 23.809524 | I9: =E9/2500/1000 -> 0 | K9: =(E9/1000)/24 -> 0
D10: 3 | E10: 0 | F10: SHUT DOWN | H10: =(2500-(E10/1000))/105 -> 23.809524 | I10: =E10/2500/1000 -> 0 | K10: =(E10/1000)/24 -> 0
D11: 4 | E11: 0 | F11: SHUT DOWN | H11: =(2500-(E11/1000))/105 -> 23.809524 | I11: =E11/2500/1000 -> 0 | K11: =(E11/1000)/24 -> 0
D12: 5 | E12: 0 | F12: SHUT DOWN | H12: =(2500-(E12/1000))/105 -> 23.809524 | I12: =E12/2500/1000 -> 0 | K12: =(E12/1000)/24 -> 0
D13: 6 | E13: 0 | F13: SHUT DOWN | H13: =(2500-(E13/1000))/105 -> 23.809524 | I13: =E13/2500/1000 -> 0 | K13: =(E13/1000)/24 -> 0
D14: 7 | E14: 0 | F14: SHUT DOWN | H14: =(2500-(E14/1000))/105 -> 23.809524 | I14: =E14/2500/1000 -> 0 | K14: =(E14/1000)/24 -> 0
D15: 8 | E15: 0 | F15: SHUT DOWN | H15: =(2500-(E15/1000))/105 -> 23.809524 | I15: =E15/2500/1000 -> 0 | K15: =(E15/1000)/24 -> 0
D16: 9 | E16: 0 | F16: SHUT DOWN | H16: =(2500-(E16/1000))/105 -> 23.809524 | I16: =E16/2500/1000 -> 0 | K16: =(E16/1000)/24 -> 0
D17: 10 | E17: 0 | F17: SHUT DOWN | H17: =(2500-(E17/1000))/105 -> 23.809524 | I17: =E17/2500/1000 -> 0 | K17: =(E17/1000)/24 -> 0
D18: 11 | E18: 0 | F18: SHUT DOWN | H18: =(2500-(E18/1000))/105 -> 23.809524 | I18: =E18/2500/1000 -> 0 | K18: =(E18/1000)/24 -> 0
D19: 12 | E19: 0 | F19: SHUT DOWN | H19: =(2500-(E19/1000))/105 -> 23.809524 | I19: =E19/2500/1000 -> 0 | K19: =(E19/1000)/24 -> 0
... D38: 31 | E38: 0 | F38: SHUT DOWN | H38: =(2500-(E38/1000))/105 -> 23.809524 | I38: =E38/2500/1000 -> 0 | K38: =(E38/1000)/24 -> 0
D39: TOTAL | E39: =SUM(E8:E37) -> 0 | G39: =SUM(G8:G37) -> 0 | H39: 0 | K39: =AVERAGE(K8:K37) -> 0
E41: Summary
E42: 1. Slow flow rate due to Space Tank High | G42: 0 | H42: hours
E43: 2. Slow flow rate due to Olein IV 60 process | G43: 0 | H43: hours
E44: 3. Hold plant due to trip MP boiler & maintenance | G44: 0 | H44: hours
E45: 4. Penyesuaian incoming CPO | G45: 0 | H45: hours
E46: 5. Downtime due to Start Up Plant | G46: 0 | H46: hours
E47: 6. Running Normal Plant | G47: 0 | H47: hours
E48: 7. Stop Plant due to Preventive Maintenance Plant | G48: 0 | H48: hours
E49: 8. Energizing PMG II | G49: 0 | H49: hours
E50: 9. Zero Suplay Gas (Problem Pertagas) | G50: 0 | H50: hours
E51: 10, Stop Plant | G51: 0 | H51: hours
E52: 11.HOLD CPO Shortage | G52: 0 | H52: hours
E53: Total | G53: 0 | H53: hours
E54: Note : Kapasitas 2500 TPD
C62: Prepared by, | F62: Checked by, | H62: Approved by,
C66: Bany Subana | F66: Reza P. Panjaitan | H66: Sudarianto
C67: Admin. Process | F67: Supervisor Produksi | H67: Jr. Manager Produksi

Sheet Downtime Fract Apr
C2: DOWN TIME SLOW FLOWRATE PRODUCTION FRACTIONATION
C4: Periode 01 s.d 30 April 2025
C5: TANGGAL | D5: CAPACITY (Kg) | E5: REMARKS | F5: Down time | J5: Tph
F6: Stop | G6: Slow | H6: %
C7: 1 | D7: 0 | E7: SHUT DOWN | G7: =(2500-(D7/1000))/105 -> 23.809524 | H7: =D7/2500/1000 -> 0 | J7: =(D7/1000)/24 -> 0
C8: 2 | D8: 0 | E8: SHUT DOWN | G8: =(2500-(D8/1000))/105 -> 23.809524 | H8: =D8/2500/1000 -> 0 | J8: =(D8/1000)/24 -> 0
C9: 3 | D9: 0 | E9: SHUT DOWN | G9: =(2500-(D9/1000))/105 -> 23.809524 | H9: =D9/2500/1000 -> 0 | J9: =(D9/1000)/24 -> 0
C10: 4 | D10: 0 | E10: SHUT DOWN | G10: =(2500-(D10/1000))/105 -> 23.809524 | H10: =D10/2500/1000 -> 0 | J10: =(D10/1000)/24 -> 0
C11: 5 | D11: 0 | E11: SHUT DOWN | G11: =(2500-(D11/1000))/105 -> 23.809524 | H11: =D11/2500/1000 -> 0 | J11: =(D11/1000)/24 -> 0
C12: 6 | D12: 0 | E12: SHUT DOWN | G12: =(2500-(D12/1000))/105 -> 23.809524 | H12: =D12/2500/1000 -> 0 | J12: =(D12/1000)/24 -> 0
C13: 7 | D13: 0 | E13: SHUT DOWN | G13: =(2500-(D13/1000))/105 -> 23.809524 | H13: =D13/2500/1000 -> 0 | J13: =(D13/1000)/24 -> 0
C14: 8 | D14: 0 | E14: SHUT DOWN | G14: =(2500-(D14/1000))/105 -> 23.809524 | H14: =D14/2500/1000 -> 0 | J14: =(D14/1000)/24 -> 0
C15: 9 | D15: 0 | E15: SHUT DOWN | G15: =(2500-(D15/1000))/105 -> 23.809524 | H15: =D15/2500/1000 -> 0 | J15: =(D15/1000)/24 -> 0
C16: 10 | D16: 0 | E16: SHUT DOWN | G16: =(2500-(D16/1000))/105 -> 23.809524 | H16: =D16/2500/1000 -> 0 | J16: =(D16/1000)/24 -> 0
C17: 11 | D17: 0 | E17: SHUT DOWN | G17: =(2500-(D17/1000))/105 -> 23.809524 | H17: =D17/2500/1000 -> 0 | J17: =(D17/1000)/24 -> 0
C18: 12 | D18: 0 | E18: SHUT DOWN | G18: =(2500-(D18/1000))/105 -> 23.809524 | H18: =D18/2500/1000 -> 0 | J18: =(D18/1000)/24 -> 0
... C34: 28 | D34: 0 | E34: SHUT DOWN | G34: =(2500-(D34/1000))/105 -> 23.809524 | H34: =D34/2500/1000 -> 0 | J34: =(D34/1000)/24 -> 0
C35: 29 | D35: 0 | E35: SHUT DOWN | G35: =(2500-(D35/1000))/105 -> 23.809524 | H35: =D35/2000/1000 -> 0 | J35: =(D35/1000)/24 -> 0
C36: 30 | D36: 0 | E36: SHUT DOWN | G36: =(2500-(D36/1000))/105 -> 23.809524 | H36: =D36/2000/1000 -> 0 | J36: =(D36/1000)/24 -> 0
C37: 31 | D37: 0 | E37: SHUT DOWN | G37: =(2500-(D37/1000))/105 -> 23.809524 | H37: =D37/2000/1000 -> 0 | J37: =(D37/1000)/24 -> 0
C38: TOTAL | D38: =SUM(D7:D37) -> 0 | F38: =SUM(F7:F36) -> 0 | G38: 0 | J38: =AVERAGE(J7:J37) -> 0
D40: Summary
D41: 1. Slow flow rate due to Space Tank High | F41: 0 | G41: hours
D42: 2. Slow flow rate due to Olein IV 60 process | F42: 0 | G42: hours
D43: 3. Slow flow rate due to Olein IV 57 process | F43: 0 | G43: hours
D44: 4. Slow Flow rate terkait material sortage & menyesuaikan | F44: 0 | G44: hours
D45: 5. Downtime due to Start/Stop Up Plant | F45: 0 | G45: hours
D46: 6. Running Normal Plant | F46: 0 | G46: hours
D47: 7. Stop Plant due to Preventive Maintenance Plant | F47: 0 | G47: hours
D48: 8. Energizing PMG II | F48: 0 | G48: hours
D49: 9. Zero Suplay Gas (Problem Pertagas) | F49: 0 | G49: hours
D50: 10. Slow flow rate due to Olein IV 58 process | F50: 0 | G50: hours | K50: =G38-F55 -> 0
D51: 11. STOP PLANT | F51: 0 | G51: hours
D52: 12.Slow flow rate due to Olein IV 56 process | F52: 0 | G52: hours
D53: 13. Slow flow rate due to Olein IV 56 process & IV 57 process | F53: 0 | G53: hours
D54: 14. Slow flow rate due to Olein IV 56 process & IV 58 process | F54: 0 | G54: hours
D55: Total | F55: 0 | G55: hours
D56: 8. Note : Kapasitas 2500 TPD
B64: Prepared by, | E64: Checked by, | G64: Approved by,
B68: Bany Subana | E68: Reza P. Panjaitan | G68: Sudarianto
...

Sheet Peformance test Fract 1
C1: PT.INDUSTRI NABATI LESTARI
C2: Pabrik Minyak Goreng ( PMG 2 )
C3: Kantor Pusat: Komp. KEK Sei Mangkei, Kav.2-3, Kec. Bosar Maligas, Kab. Simalungun, Sumatera Utara, 21184
C4: ACTUAL PEFORMANCE / CONSUMPT REPORT FRAKSINASI PLANT | H4: Trial | I4: 1
H5: Start / Date / Time | I5: 17/12/24 ( 07.00 Wib )
H6: Finish / Date / Time | I6: 17/12/24 ( 07.00 Wib )
A8: No | B8: ITEM | C8: Kontrak LIPICO | D8: UOM | E8: TOTALIZER
A10: 1 | B10: PRODUCTION | C10: IV 56 | D10: 24 jam | E10: BEFORE | F10: AFTER | G10: TOTAL | H10: YIELD % | I10: STATUS/REMAKS
B11: Fraksinasi
B12: Running Days
B13: Incoming CPO
B14: Ratio Run CPO
B15: RBDPO Consume Total | C15: 2500 | D15: TPD | E15: 8982.8 | F15: 11717.8 | G15: =F15-E15 -> 2735 | H15: =G15/25000*10 -> 1.094 | I15: OK
B16: Avg Daily Consump CPO ( MTD )
B17: CPO Consume Poram | C17: 29045000
B18: CPO Consume Brand | C18: 7314000 | E18: =E49+E58+E63 -> 0
B19: QUALITY
B20: - FFA | C20: 0.1 | D20: % Max | H20: 0.063
B21: - Moist & Impurities | C21: 0.1 | D21: % Max | H21: 0.05
B22: - IV | C22: 52 - 52,5 | H22: 51.8
B23: - LC | H23: 2,6/20
B24: - Temp | C24: 68 | D24: ˚C Min | H24: 65
B25: TANK | H25: 108/109
B26: Product
B27: OLEIN IV 56 | C27: =C15*84% -> 2100 | D27: TPD | E27: 6537.1 | F27: 8213 | G27: =F27-E27 -> 1675.9 | H27: =G27/(G27+G32) -> 0.82838219 | I27: OK
B28: QUALITY
B29: - IV | C29: 56 | D29: Min
B30: - LC
B31: - Cloud Point ( metter ) | C31: 10 | D31: ˚C Max
B32: STEARIN | C32: =C15*16% -> 400 | E32: 2268.1 | F32: 2615.3 | G32: =F32-E32 -> 347.2 | H32: =G32/(G32+G27) -> 0.17161781 | I32: OK
B33: Fractionation
B34: Running Days
B35: Filling Langsung CR Fr Refinery | E35: 0
B36: Total Filling Crystalizer ( Feed ) | E36: 392100
B37: Avg Daily Consump RPO ( MTD )
B38: Total Proses RBDPO | E38: =SUM(E41,E45,E50,E54,E64) -> 0
B39: Sisa Filling Crystalizer | E39: =E36-E38 -> 392100
B40: Fractionation OLEIN IV 56
B41: RBDPO Consume | E41: =E42+E43 -> 0
B42: OLEIN IV 56 | E42: 0
...

Sheet Peformance Test REFINERY 1
C1: PT.INDUSTRI NABATI LESTARI
C2: Pabrik Minyak Goreng ( PMG 2 )
C3: Kantor Pusat: Komp. KEK Sei Mangkei, Kav.2-3, Kec. Bosar Maligas, Kab. Simalungun, Sumatera Utara, 21184
C4: ACTUAL PEFORMANCE / CONSUMPT REPORT REFINERY PLANT | H4: Peformance | I4: 1
H5: Start / Date / Time | I5: 17/12/24 ( 21.00 Wib )
H6: Finish / Date / Time | I6: 18/12/24 ( 21.00 Wib )
A7: No | B7: ITEM | C7: Kontrak LIPICO | D7: UOM | E7: TOTALIZER
A9: 1 | B9: PRODUCTION | E9: BEFORE | F9: AFTER | G9: TOTAL | H9: Yield ( % ) | I9: STATUS/REMAKS
B10: Refinery
B11: Running Days
B12: Incoming CPO
B13: Ratio Run CPO
B14: CPO Consume Total | C14: 2500 | D14: TPD | E14: 13533.82 | F14: 16053.42 | G14: =F14-E14 -> 2519.6 | I14: OK
B15: Avg Daily Consump CPO ( MTD )
B16: CPO Consume Poram | C16: 29045000
B17: CPO Consume Brand | C17: 7314000 | E17: =E53+E62+E67 -> 0
B18: - FFA | C18: 5 | D18: % | G18: 4
B19: - Moist & Impurities | C19: 0.5 | D19: % | G19: 0.41
B20: - DOBI | C20: 2.2 | D20: Min | G20: 2.42
B21: - TOTOX 2PV + AV | C21: 12 | D21: Max | G21: N/A
B22: - FE Content | C22: < 5 | D22: ppm | G22: N/A
B23: - PV | C23: < 4 | D23: Meg/kg | G23: N/A
B24: - Phosporus Max | C24: 25 | D24: ppm | G24: N/A
B25: TANK / TEMP | C25: 50 | D25: ˚C | G25: 50
B26: Product
B27: RBDPO | C27: =C14*94.2% -> 2355 | D27: TPD | E27: 12357.54 | F27: 14705.95 | G27: =F27-E27 -> 2348.41 | H27: =G27/G14 -> 0.93205668
B28: - FFA | C28: 0.05 | D28: % | G28: 0.06
B29: - Moist & Impurities | C29: 0.03 | D29: % | G29: 0.05
B30: - Peroxide value | D30: Nil | G30: -
B31: - Phosporous max | C31: 2 | D31: ppm | G31: N/A
B32: - LC | C32: 2.5 | D32: % | G32: 2.5
B33: - Aom stability min ( hr ) | C33: 60 | D33: min ( hr ) | G33: N/A
B34: - teste & Odor | C34: bland/Odorless | G34: N/A
B35: - temp max ( C ) | C35: 50 | D35: max˚C | G35: 50
B36: PFAD | C36: =C14*5% -> 125 | D36: TPD | E36: 572.71 | F36: 675.39 | G36: =F36-E36 -> 102.68 | H36: =G36/G14 -> 0.0407525
B37: Fractionation
B38: Running Days
B39: Filling Langsung CR Fr Refinery | E39: 0
B40: Total Filling Crystalizer ( Feed ) | E40: 392100
B41: Avg Daily Consump RPO ( MTD )
...

Sheet peformance  test REFINERY 2
A1: REFINERY PMG 2
A2: No | B2: ITEM | C2: Norma LIPICO | D2: UOM | E2: Day 2 tanggal 12/12/2024
A4: 1 | B4: PRODUCTION | E4: BEFORE | F4: AFTER | G4: TOTAL | H4: Yield ( % )
B5: Refinery
B6: Running Days
B7: Incoming CPO
B8: Ratio Run CPO
B9: CPO Consume Total | C9: 2500 | D9: TPD | E9: 5880.74 | F9: 8383.74 | G9: =F9-E9 -> 2503 | H9: =G9/2500000*100000 -> 100.12
B10: Avg Daily Consump CPO ( MTD )
B11: CPO Consume Poram | C11: 29045000
B12: CPO Consume Brand | C12: 7314000 | E12: =E43+E52+E57 -> 0
B13: - FFA | C13: 5 | D13: % | G13: 3.97
B14: - Moist & Impurities | C14: 0.5 | D14: % | G14: 0.4
B15: - DOBI | C15: 2.2 | D15: Min | G15: 2.42
B16: TANK | G16: 105
B17: Product
B18: OIP RBDPO
B19: RBDPO | C19: =C9*94.2% -> 2355 | D19: TPD | E19: 5143.38 | F19: 7493.18 | G19: =F19-E19 -> 2349.8 | H19: =G19/G9*100 -> 93.879345
B20: - FFA | C20: 0.05 | D20: % | G20: 0.043
B21: - Moist & Impurities | C21: 0.03 | D21: % | G21: 0.04
B22: - LC | C22: 2.5 | D22: % | G22: 2.5
B23: - Aom stability min ( hr ) | C23: 60 | D23: min ( hr )
B24: - teste & Odor | C24: bland/Odorless
B25: - temp max ( C ) | C25: 50 | D25: max˚C
B26: PFAD | C26: =C9*5% -> 125 | D26: TPD | E26: 243.04 | F26: 347.1 | G26: =F26-E26 -> 104.06 | H26: =G26/G9*100 -> 4.1574111
B27: Fractionation
B28: Running Days
B29: Filling Langsung CR Fr Refinery | E29: 0
B30: Total Filling Crystalizer ( Feed ) | E30: 392100
B31: Avg Daily Consump RPO ( MTD )
B32: Total Proses RBDPO | E32: =SUM(E35,E39,E44,E48,E58) -> 0
B33: Sisa Filling Crystalizer | E33: =E30-E32 -> 392100
B34: Fractionation OLEIN IV 56
B35: RBDPO Consume | E35: =E36+E37 -> 0
B36: OLEIN IV 56 | E36: 0
B37: STEARIN | E37: 0
B38: Fractionation OLEIN IV 57 ( Bulk )
B39: RBDPO Consume | E39: =E40+E41 -> 0
B40: OLEIN IV 57 | E40: 0
B41: STEARIN | E41: 0
...

Sheet HPP REF 
B2: Refinery Cost
B3: Through Put CPO Proses | N3: =(#REF!)/1000 -> #REF! | O3: TPD
B4: Working Day | N4: =#REF! -> #REF! | O4: Days
B5: Total CPO Process | N5: =N4*N3 -> #REF! | O5: MTD
B6: KURS | N6: 16000 | O6: Rp/USD
B7: No | C7: Item Cost | D7: Norma | F7: Pemakaian / Hari | H7: HK | J7: Total Pemakaian | K7: Harga / stn | M7: Total Biaya | N7: Rp / kg | O7: USD/MT
B8: 1 | C8: Bleaching Earth | D8: =#REF! -> #REF! | F8: =($D$8*$N$3*10) -> #REF! | G8: Kg/day | H8: =$N$4 -> #REF! | J8: =$H$8*$F$8 -> #REF! | K8: 2400 | M8: =$J$8*$K$8 -> #REF! | N8: =$M$8/($N$5*1000) -> #REF! | O8: =($M$8/$N$6)/$N$5 -> #REF!
B9: 2 | C9: Phosporic acid | D9: =#REF! -> #REF! | F9: =($D$9*$N$3*10) -> #REF! | G9: Kg/day | H9: =$H$8 -> #REF! | J9: =$H$9*$F$9 -> #REF! | K9: 17420 | M9: =$J$9*$K$9 -> #REF! | N9: =$M$9/($N$5*1000) -> #REF! | O9: =($M$9/$N$6)/$N$5 -> #REF!
B10: 3 | C10: Caustic Soda | D10: 29.166667 | E10: kg/day | F10: =D10 -> 29.166667 | G10: kg/day | H10: =$H$8 -> #REF! | J10: =$H$10*$F$10 -> #REF! | K10: 15700 | M10: =$J$10*$K$10 -> #REF! | N10: =$M$10/($N$5*1000) -> #REF! | O10: =($M$10/$N$6)/$N$5 -> #REF!
B11: 4 | C11: Pemakaian Natural Gas HPB Geka
C12: Normal Consumption | D12: =#REF! -> #REF! | E12: MMBTU/MT CPO | F12: =$D$12*$N$3 -> #REF! | G12: MMBTU/day | H12: =$H$8 -> #REF! | J12: =$H$12*$F$12 -> #REF! | K12: =11.5*$N$6 -> 184000 | M12: =$J$12*$K$12 -> #REF! | N12: =$M$12/($N$5*1000) -> #REF! | O12: =($M$12/$N$6)/$N$5 -> #REF!
C13: Penalty Below Consumption | D13: 0 | E13: MMBTU/MT CPO | F13: =$D$13*$N$3 -> #REF! | G13: MMBTU/day | H13: =$H$8 -> #REF! | J13: =$H$13*$F$13 -> #REF! | K13: =11.5*$N$6 -> 184000 | M13: =$J$13*$K$13 -> #REF! | N13: =$M$13/($N$5*1000) -> #REF! | O13: =($M$13/$N$6)/$N$5 -> #REF!
C14: Penalty Above Consumption | D14: 0 | E14: MMBTU/MT CPO | F14: =$D$14*$N$3 -> #REF! | G14: MMBTU/day | H14: =$H$8 -> #REF! | J14: =$H$14*$F$14 -> #REF! | K14: =11.5*$N$6 -> 184000 | M14: =$J$14*$K$14 -> #REF! | N14: =$M$14/($N$5*1000) -> #REF! | O14: =($M$14/$N$6)/$N$5 -> #REF!
B15: 5 | C15: Pemakaian Steam
C16: For Process | D16: =#REF! -> #REF! | E16: Kg/MT CPO | F16: =$D$16*$N$3/1000 -> #REF! | G16: Ton/day | H16: =$H$8 -> #REF! | J16: =$H$16*$F$16 -> #REF! | K16: =Steam!H15 -> #REF! | M16: =$J$16*$K$16 -> #REF! | N16: =$M$16/($N$5*1000) -> #REF! | O16: =($M$16/$N$6)/$N$5 -> #REF!
C17: Storage Tank for Heating | D17: =#REF! -> #REF! | E17: Kg/MT CPO | F17: =$D$17*$N$3/1000 -> #REF! | G17: Ton/day | H17: =$H$8 -> #REF! | J17: =$H$17*$F$17 -> #REF! | K17: =Steam!H15 -> #REF! | M17: =$J$17*$K$17 -> #REF! | N17: =$M$17/($N$5*1000) -> #REF! | O17: =($M$17/$N$6)/$N$5 -> #REF!
B18: 6 | C18: Pemakaian Electrical
C19: For Process | D19: =#REF! -> #REF! | E19: kW/MT CPO | F19: =$D$19*$N$3 -> #REF! | G19: kW/day | H19: =$H$8 -> #REF! | I19: 0 | J19: =$H$19*$F$19 -> #REF! | K19: 1550 | L19: =[1]Electric!H21 -> 3666.6667 | M19: =($F$19*$H$19*$K$19)+($F$19*$I$19*$L$19) -> #REF! | N19: =$M$19/($N$5*1000) -> #REF! | O19: =($M$19/$N$6)/$N$5 -> #REF!
C20: Cooling Tower | D20: =#REF! -> #REF! | E20: kW/MT CPO | F20: =$D$20*$N$3 -> #REF! | G20: kW/day | H20: =$H$8 -> #REF! | I20: 0 | J20: =$H$20*$F$20 -> #REF! | K20: 1550 | L20: =L19 -> 3666.6667 | M20: =(F20*H20*K20)+(F20*I20*L20) -> #REF! | N20: =$M$20/($N$5*1000) -> #REF! | O20: =($M$20/$N$6)/$N$5 -> #REF!
C21: Storage Tank | D21: 0.3377877 | E21: kW/MT CPO | F21: =$D$21*$N$3 -> #REF! | G21: kW/day | H21: =$H$8 -> #REF! | I21: 0 | J21: =$H$21*$F$21 -> #REF! | K21: 1550 | L21: =L20 -> 3666.6667 | M21: =($F$21*$H$21*$K$21)+($F$21*$I$21*$L$21) -> #REF! | N21: =$M$21/($N$5*1000) -> #REF! | O21: =($M$21/$N$6)/$N$5 -> #REF!
B22: 7 | C22: Pemakaian Water
C23: Make Up CT | D23: =#REF! -> #REF! | E23: M3/day | F23: =$D$23 -> #REF! | G23: M3/day | H23: =$H$8 -> #REF! | J23: =$H$23*$F$23 -> #REF! | K23: =WTP!H13 -> #VALUE! | M23: =$J$23*$K$23 -> #REF! | N23: =$M$23/($N$5*1000) -> #REF! | O23: =($M$23/$N$6)/$N$5 -> #REF!
B24: 8 | C24: Chemical Water | N24: =$M$24/($N$5*1000) -> #REF! | O24: =($M$24/$N$6)/$N$5 -> #REF!
C25: EONBAC BC 3108 | D25: 0.4 | E25: Kg/day | F25: =D25 -> 0.4 | G25: Kg/day | H25: =$H$8 -> #REF! | J25: =$H$25*$F$25 -> #REF! | K25: 27240 | M25: =$J$25*$K$25 -> #REF! | N25: =$M$25/($N$5*1000) -> #REF! | O25: =($M$25/$N$6)/$N$5 -> #REF!
C26: EONLINE T722 | D26: 0.66 | E26: Kg/day | F26: =D26 -> 0.66 | G26: Kg/day | H26: =$H$8 -> #REF! | J26: =$H$26*$F$26 -> #REF! | K26: 29120 | M26: =$J$26*$K$26 -> #REF! | N26: =$M$26/($N$5*1000) -> #REF! | O26: =($M$26/$N$6)/$N$5 -> #REF!
C27: EONLINE AG5770 | D27: 0.41 | E27: Kg/day | F27: =D27 -> 0.41 | G27: Kg/day | H27: =$H$8 -> #REF! | J27: =$H$27*$F$27 -> #REF! | K27: 117212 | M27: =$J$27*$K$27 -> #REF! | N27: =$M$27/($N$5*1000) -> #REF! | O27: =($M$27/$N$6)/$N$5 -> #REF!
C28: EONScale T2511 | D28: 0.1 | E28: Kg/day | F28: =D28 -> 0.1 | G28: Kg/day | H28: =$H$8 -> #REF! | J28: =$H$28*$F$28 -> #REF! | K28: 45940 | M28: =$J$28*$K$28 -> #REF! | N28: =$M$28/($N$5*1000) -> #REF! | O28: =($M$28/$N$6)/$N$5 -> #REF!
B29: 9 | C29: Others
C30: Filter Bag 10 Microne | D30: 0.90361446 | E30: Pcs/day | F30: =D30 -> 0.90361446 | G30: Pcs/day | H30: =$H$8 -> #REF! | J30: =$H$30*$F$30 -> #REF! | K30: 40000 | M30: =$J$30*$K$30 -> #REF! | N30: =$M$30/($N$5*1000) -> #REF! | O30: =($M$30/$N$6)/$N$5 -> #REF!
C31: Filter Bag 100 Microne | D31: 0.63253012 | E31: Pcs/day | F31: =D31 -> 0.63253012 | G31: Pcs/day | H31: =$H$8 -> #REF! | J31: =$H$31*$F$31 -> #REF! | K31: 125000 | M31: =$J$31*$K$31 -> #REF! | N31: =$M$31/($N$5*1000) -> #REF! | O31: =($M$31/$N$6)/$N$5 -> #REF!
C32: Filter Cartridge 10 Microne | D32: 1.5666667 | E32: Pcs/day | F32: =D32 -> 1.5666667 | G32: Pcs/day | H32: =$H$8 -> #REF! | J32: =$H$32*$F$32 -> #REF! | K32: 145000 | M32: =$J$32*$K$32 -> #REF! | N32: =$M$32/($N$5*1000) -> #REF! | O32: =($M$32/$N$6)/$N$5 -> #REF!
C33: Filter Dustbag | D33: 0.12048193 | E33: Pcs/day | F33: =D33 -> 0.12048193 | G33: Pcs/day | H33: =$H$8 -> #REF! | J33: =$H$33*$F$33 -> #REF! | K33: 682500 | M33: =$J$33*$K$33 -> #REF! | N33: =$M$33/($N$5*1000) -> #REF! | O33: =($M$33/$N$6)/$N$5 -> #REF!
C34: O Ring Filter Leaves | D34: 3.6144578 | E34: Pcs/day | F34: =D34 -> 3.6144578 | G34: Pcs/day | H34: =$H$8 -> #REF! | J34: =$H$34*$F$34 -> #REF! | K34: 14500 | M34: =$J$34*$K$34 -> #REF! | N34: =$M$34/($N$5*1000) -> #REF! | O34: =($M$34/$N$6)/$N$5 -> #REF!
B35: 10 | C35: Waste Water Treatment Plant ( WWTP ) | D35: =#REF! -> #REF! | E35: M3/day | F35: =D35 -> #REF! | G35: M3/day | H35: =$H$8 -> #REF! | J35: =$H$35*$F$35 -> #REF! | K35: =WWTP!H17 -> #REF! | M35: =$J$35*$K$35 -> #REF! | N35: =$M$35/($N$5*1000) -> #REF! | O35: =($M$35/$N$6)/$N$5 -> #REF!
B36: 11 | C36: SHE
C37: SBE | D37: =#REF! -> #REF! | E37: Kg/day | F37: =D37 -> #REF! | G37: Kg/day | H37: =$H$8 -> #REF! | J37: =$F$37 -> #REF! | K37: 275 | M37: =$J$37*$K$37 -> #REF! | N37: =$M$37/($N$5*1000) -> #REF! | O37: =($M$37/$N$6)/$N$5 -> #REF!
C38: Domestic | D38: 0.1 | E38: Trip/day | F38: =D38 -> 0.1 | G38: Trip/day | H38: =$H$8 -> #REF! | J38: =$H$38*$F$38 -> #REF! | K38: 303030.3 | M38: =$J$38*$K$38 -> #REF! | N38: =$M$38/($N$5*1000) -> #REF! | O38: =($M$38/$N$6)/$N$5 -> #REF!
B39: 12 | C39: Chemical Consumption | N39: =$M$39/($N$5*1000) -> #REF! | O39: =($M$39/$N$6)/$N$5 -> #REF!
C40: LAB Chemical | D40: =lab!H33 -> 745255.21 | E40: Rp/day | F40: =D40 -> 745255.21 | G40: Rp/day | H40: =$H$8 -> #REF! | M40: =$H$40*$F$40 -> #REF! | N40: =$M$40/($N$5*1000) -> #REF! | O40: =($M$40/$N$6)/$N$5 -> #REF!
C41: Chemical Boiler dan WTP | D41: =lab!H54 -> 259161.44 | E41: Rp/day | F41: =D41 -> 259161.44 | G41: Rp/day | H41: =$H$8 -> #REF! | M41: =$H$41*$F$41 -> #REF! | N41: =$M$41/($N$5*1000) -> #REF! | O41: =($M$41/$N$6)/$N$5 -> #REF!
...

Sheet HPP FRACT
B2: Fractionation Cost
B3: RPO Proses / Day | N3: TPD | O3: =#REF!/1000 -> #REF!
B4: Working Day | N4: Days | O4: =#REF! -> #REF!
B5: Total CPO Process | N5: MTD | O5: =O3*O4 -> #REF!
B6: KURS | N6: Rp/USD | O6: 16000
B7: No | C7: Item Cost | D7: Norma | F7: Pemakaian / Hari | H7: HK | J7: Total Pemakaian | K7: Harga / stn | M7: Total Biaya | N7: Rp / kg | O7: USD/MT
B8: 1 | C8: Steam | D8: =#REF! -> #REF! | E8: Kg/MT CPO | F8: =$D$8*$O$3/1000 -> #REF! | G8: Ton/day | H8: =$O$4 -> #REF! | J8: =$H$8*$F$8 -> #REF! | K8: =Steam!H15 -> #REF! | M8: =$K$8*$J$8 -> #REF! | N8: =$M$8/($O$5*1000) -> #REF! | O8: =($M$8/$O$6)/$O$5 -> #REF!
B9: 2 | C9: Electrical
C10: For Process | D10: =#REF! -> #REF! | E10: kW/MT CPO | F10: =$D$10*$O$3 -> #REF! | G10: kW/day | H10: =$O$4 -> #REF! | I10: 0 | J10: =$H$10*$F$10 -> #REF! | K10: =[1]Electric!$L$5 -> 1550 | L10: 3666.6667 | M10: =($F$10*$H$10*$K$10)+($F$10*$I$10*$L$10) -> #REF! | N10: =$M$10/($O$5*1000) -> #REF! | O10: =($M$10/$O$6)/$O$5 -> #REF!
C11: Cooling Tower | D11: =#REF! -> #REF! | E11: kW/MT CPO | F11: =$D$11*$O$3 -> #REF! | G11: kW/day | H11: =$H$10 -> #REF! | I11: 0 | J11: =$H$11*$F$11 -> #REF! | K11: =$K$10 -> 1550 | L11: 3666.6667 | M11: =($F$11*$H$11*$K$11)+($F$11*$I$11*$L$11) -> #REF! | N11: =$M$11/($O$5*1000) -> #REF! | O11: =($M$11/$O$6)/$O$5 -> #REF!
B12: 3 | C12: Water
C13: Make Up CT | D13: =#REF! -> #REF! | E13: M3/day | F13: =$D$13 -> #REF! | G13: M3/day | H13: =$H$11 -> #REF! | J13: =$H$13*$F$13 -> #REF! | K13: =WTP!H13 -> #VALUE! | M13: =$K$13*$J$13 -> #VALUE! | N13: =$M$13/($O$5*1000) -> #VALUE! | O13: =($M$13/$O$6)/$O$5 -> #VALUE!
B14: 4 | C14: Chemical Water
C15: EONBAC BC 3108 | D15: 0.4 | E15: Kg/day | F15: =$D$15 -> 0.4 | G15: Kg/day | H15: =$H$13 -> #REF! | J15: =$H$15*$F$15 -> #REF! | K15: 27240 | M15: =$K$15*$J$15 -> #REF! | N15: =$M$15/($O$5*1000) -> #REF! | O15: =($M$15/$O$6)/$O$5 -> #REF!
C16: EONLINE T722 | D16: 0.66 | E16: Kg/day | F16: =$D$16 -> 0.66 | G16: Kg/day | H16: =$H$15 -> #REF! | J16: =$H$16*$F$16 -> #REF! | K16: 29120 | M16: =$K$16*$J$16 -> #REF! | N16: =$M$16/($O$5*1000) -> #REF! | O16: =($M$16/$O$6)/$O$5 -> #REF!
C17: EONLINE AG5770 | D17: 0.41 | E17: Kg/day | F17: =$D$17 -> 0.41 | G17: Kg/day | H17: =$H$15 -> #REF! | J17: =$H$17*$F$17 -> #REF! | K17: 117212 | M17: =$K$17*$J$17 -> #REF! | N17: =$M$17/($O$5*1000) -> #REF! | O17: =($M$17/$O$6)/$O$5 -> #REF!
C18: EONScale T2511 | D18: 0.1 | E18: Kg/day | F18: =$D$18 -> 0.1 | G18: Kg/day | H18: =$H$16 -> #REF! | J18: =$H$18*$F$18 -> #REF! | K18: 45940 | M18: =$K$18*$J$18 -> #REF! | N18: =$M$18/($O$5*1000) -> #REF! | O18: =($M$18/$O$6)/$O$5 -> #REF!
B19: 5 | C19: Others
C20: Filter Cloth | D20: 0.33333333 | E20: Pcs/day | F20: =$D$20 -> 0.33333333 | G20: Pcs/day | H20: =$H$18 -> #REF! | J20: =$H$20*$F$20 -> #REF! | K20: 895000 | M20: =$K$20*$J$20 -> #REF! | N20: =$M$20/($O$5*1000) -> #REF! | O20: =($M$20/$O$6)/$O$5 -> #REF!
C21: Filter Bag 100 Microne | D21: 0.63253012 | E21: Pcs/day | F21: =$D$21 -> 0.63253012 | G21: Pcs/day | H21: =$H$20 -> #REF! | J21: =$H$21*$F$21 -> #REF! | K21: 125000 | M21: =$K$21*$J$21 -> #REF! | N21: =$M$21/($O$5*1000) -> #REF! | O21: =($M$21/$O$6)/$O$5 -> #REF!
M22: =SUM(M8:M21) -> #REF! | N22: =SUM(N8:N21) -> #REF! | O22: =SUM($O$8:$O$21) -> #REF!

Sheet SUMMARY HPP 
B2: Production Cost September
B3: Through Put CPO Proses (Ton/Day) | H3: TPD | I3: ='HPP REF '!$N$3 -> #REF!
B4: Working Day | F4: 1 | H4: Days | I4: ='HPP REF '!$N$4 -> #REF!
B5: Refined CPO ( Ton/month ) | H5: MTD | I5: =$I$4*$I$3 -> #REF!
B6: Through Put RPO Proses (Ton/Day) | H6: TPD | I6: ='HPP FRACT'!$O$3 -> #REF!
B7: Working Day | H7: Days | I7: ='HPP FRACT'!$O$4 -> #REF!
B8: Fract RPO ( ton/month ) | H8: MTD | I8: =$I$7*$I$6 -> #REF!
B9: KURS | H9: Rp/USD | I9: 15546
B10: No | C10: Items | D10: Description | G10: Rupiah | H10: Rp/Kg | I10: USD/MT
B11: I | C11: Production Cost | D11: ● | E11: Refining Cost | G11: ='HPP REF '!$M$48 -> #REF! | H11: =$G$11/($I$5*1000) -> #REF! | I11: =(G11/$I$9)/$I$5 -> #REF!
D12: ● | E12: Fractionation Cost | G12: ='HPP FRACT'!$M$22 -> #REF! | H12: =$G$12/($I$8*1000) -> #REF! | I12: =(G12/$I$9)/$I$8 -> #REF!
D13: ● | E13: Preventive Maintenance Cost | F13: 0 | G13: =MTC!$F$18*F13 -> #REF! | H13: =$G$13/($I$5*1000) -> #REF! | I13: =(G13/$I$9)/$I$5 -> #REF!
G14: =SUM(G11:$G$13) -> #REF! | H14: =SUM($H$11:$H$13) -> #REF! | I14: =SUM(I11:I13) -> #REF! | K14: =I14+I26 -> #REF!
B16: II | C16: Port Cost | D16: ● | E16: Trucking Komoditi ke Kuala Tanjung | G16: =LOG!I8+LOG!I9+LOG!$I$10 -> #REF! | H16: =$G$16/($I$5*1000) -> #REF! | I16: =($G$16/$I$9)/$I$5 -> #REF!
D17: ● | E17: Sewa Tank PTI Total Volume : 24.000 MT ( 5 Unit ) | F17: =F4 -> 1 | G17: =LOG!I11+LOG!I12+LOG!I13+LOG!$I$14*F17 -> 1886000000 | H17: =$G$17/($I$5*1000) -> #REF! | I17: =($G$17/$I$9)/$I$5 -> #REF!
D18: ● | E18: Instalasi & Pemanasan, Pompa, Surveyor dan Documen | G18: =LOG!I18+LOG!I19+LOG!I20+LOG!$I$21 -> #REF! | H18: =$G$18/($I$5*1000) -> #REF! | I18: =($G$18/$I$9)/$I$5 -> #REF!
D19: ● | E19: Finalty Over Capacity Tank | G19: =LOG!I15+LOG!I16+LOG!$I$17 -> #REF! | H19: =$G$19/($I$5*1000) -> #REF! | I19: =($G$19/$I$9)/$I$5 -> #REF!
G20: =SUM($G$16:$G$19) -> #REF! | H20: =SUM($H$16:$H$19) -> #REF! | I20: =SUM($I$16:$I$19) -> #REF!
B22: II | C22: Fix Cost | D22: ● | E22: Manpower Cost | F22: =F4 -> 1 | G22: =[1]MPC!$H$29*$F$22 -> 2.1846655e+09 | H22: =$G$22/($I$5*1000) -> #REF! | I22: =($G$22/$I$9)/$I$5 -> #REF!
D23: ● | E23: Admin OH Cost | F23: =F4 -> 1 | G23: =OH!G51*$F$23 -> 1.4360564e+09 | H23: =$G$23/($I$5*1000) -> #REF! | I23: =($G$23/$I$9)/$I$5 -> #REF!
D24: ● | E24: Depresiasi Cost | F24: =F4 -> 1 | G24: =DEP!I9*$F$24 -> 4.1811848e+09 | H24: =$G$24/($I$5*1000) -> #REF! | I24: =($G$24/$I$9)/$I$5 -> #REF!
D25: ● | E25: Amortisation of leasehold land Cost | F25: =F4 -> 1 | G25: =AMOR!$G$20*$F$25 -> 1.0484098e+09 | H25: =$G$25/($I$5*1000) -> #REF! | I25: =($G$25/$I$9)/$I$5 -> #REF!
G26: =SUM($G$22:$G$25) -> 8.8503165e+09 | H26: =SUM($H$22:$H$25) -> #REF! | I26: =SUM($I$22:$I$25) -> #REF! | K26: =I26+I14 -> #REF!
B28: Total Production Cost | G28: =$G$26+$G$20+$G$14 -> #REF! | H28: =$H$26+$H$20+$H$14 -> #REF! | I28: =$I$26+$I$20+$I$14 -> #REF!

Sheet Convert Gas
B3: CONVERT PEMAKAIAN GAS HP BOILER & MP BOILER
D4: 2024
C5: HP BOILER | F5: TOTAL CORRECTED VOLUME (Sm3) | K5: ENERGY MP BOILER (MMBTU) | L5: TOTAL GAS CONSUMPTION (MMBTU) | M5: PERCENTAGE
C6: UNCORRECTED VOLUME (UV) (Nm3) | D6: PRESS. Bar | E6: CORRECTED VOLUME (CV) (Sm3) | G6: Convert Sm3 to SCF | H6: VOLUME (MSCF) | I6: HEATING VALUE (BTU / SCF) | J6: ENERGY HP BOILER (MMBTU) | M6: HP Boiler | N6: MP Boiler
C7: 1 | D7: 2 | E7: 3 = 1 x 2 | F7: 4 = 3 | G7: 5 | H7: 6 = (4 x 5) / 1000 | I7: 7 | J7: 8 = (6 x 7) / 1000 | K7: 9 = 10 - 8 | L7: 10 | M7: 11 = 8 / 10 | N7: 12 = 9 / 10
B8: 1 | D8: 5 | E8: =C8*D8 -> 0 | F8: =E8 -> 0 | G8: 35.314667 | H8: =(F8*G8)/1000 -> 0 | I8: 1047.7934 | J8: =(H8*I8)/1000 -> 0 | K8: =L8-J8 -> 0 | L8: 0 | M8: =(J8/L8) -> #DIV/0! | N8: =K8/L8 -> #DIV/0!
B9: =B8+1 -> 2 | D9: 5 | E9: =C9*D9 -> 0 | F9: =E9 -> 0 | G9: 35.314667 | H9: =(F9*G9)/1000 -> 0 | I9: 1042.7042 | J9: =(H9*I9)/1000 -> 0 | K9: =L9-J9 -> 0.7969 | L9: 0.7969 | M9: =(J9/L9) -> 0 | N9: =K9/L9 -> 1
B10: =B9+1 -> 3 | C10: 159.69 | D10: 5 | E10: =C10*D10 -> 798.45 | F10: =E10 -> 798.45 | G10: 35.314667 | H10: =(F10*G10)/1000 -> 28.196996 | I10: 1044.8302 | J10: =(H10*I10)/1000 -> 29.461073 | K10: =L10-J10 -> 656.37333 | L10: 685.8344 | M10: =(J10/L10) -> 0.04295654 | N10: =K10/L10 -> 0.95704346
B11: =B10+1 -> 4 | C11: 788.24 | D11: 5 | E11: =C11*D11 -> 3941.2 | F11: =E11 -> 3941.2 | G11: 35.314667 | H11: =(F11*G11)/1000 -> 139.18217 | I11: 1050.3635 | J11: =(H11*I11)/1000 -> 146.19187 | K11: =L11-J11 -> 696.04741 | L11: 842.23928 | M11: =(J11/L11) -> 0.17357522 | N11: =K11/L11 -> 0.82642478
B12: =B11+1 -> 5 | C12: 3.33 | D12: 5 | E12: =C12*D12 -> 16.65 | F12: =E12 -> 16.65 | G12: 35.314667 | H12: =(F12*G12)/1000 -> 0.58798921 | I12: 1050.6498 | J12: =(H12*I12)/1000 -> 0.61777073 | K12: =L12-J12 -> 767.54333 | L12: 768.1611 | M12: =(J12/L12) -> 0.00080422027 | N12: =K12/L12 -> 0.99919578
B13: =B12+1 -> 6 | C13: 1356.95 | D13: 5 | E13: =C13*D13 -> 6784.75 | F13: =E13 -> 6784.75 | G13: 35.314667 | H13: =(F13*G13)/1000 -> 239.60119 | I13: 1051.3912 | J13: =(H13*I13)/1000 -> 251.91459 | K13: =L13-J13 -> 389.14956 | L13: 641.06415 | M13: =(J13/L13) -> 0.39296315 | N13: =K13/L13 -> 0.60703685
B14: =B13+1 -> 7 | C14: 4051.52 | D14: 5 | E14: =C14*D14 -> 20257.6 | F14: =E14 -> 20257.6 | G14: 35.314667 | H14: =(F14*G14)/1000 -> 715.3904 | I14: 1053.7683 | J14: =(H14*I14)/1000 -> 753.85573 | K14: =L14-J14 -> 105.66983 | L14: 859.52556 | M14: =(J14/L14) -> 0.87706028 | N14: =K14/L14 -> 0.12293972
B15: =B14+1 -> 8 | C15: 5815.62 | D15: 5 | E15: =C15*D15 -> 29078.1 | F15: =E15 -> 29078.1 | G15: 35.314667 | H15: =(F15*G15)/1000 -> 1026.8834 | I15: 1055.9121 | J15: =(H15*I15)/1000 -> 1084.2986 | K15: =L15-J15 -> -55.066247 | L15: 1029.2324 | M15: =(J15/L15) -> 1.0535022 | N15: =K15/L15 -> -0.053502249
B16: =B15+1 -> 9 | C16: 5220.53 | D16: 5 | E16: =C16*D16 -> 26102.65 | F16: =E16 -> 26102.65 | G16: 35.314667 | H16: =(F16*G16)/1000 -> 921.80639 | I16: 1058.5967 | J16: =(H16*I16)/1000 -> 975.82117 | K16: =L16-J16 -> 139.90533 | L16: 1115.7265 | M16: =(J16/L16) -> 0.87460607 | N16: =K16/L16 -> 0.12539393
B17: =B16+1 -> 10 | C17: 2188 | D17: 5 | E17: =C17*D17 -> 10940 | F17: =E17 -> 10940 | G17: 35.314667 | H17: =(F17*G17)/1000 -> 386.34246 | I17: 1055.6055 | J17: =(H17*I17)/1000 -> 407.82521 | K17: =L17-J17 -> 551.84729 | L17: 959.6725 | M17: =(J17/L17) -> 0.4249629 | N17: =K17/L17 -> 0.5750371
B18: =B17+1 -> 11 | C18: 1796.49 | D18: 5 | E18: =C18*D18 -> 8982.45 | F18: =E18 -> 8982.45 | G18: 35.314667 | H18: =(F18*G18)/1000 -> 317.21223 | I18: 1056.3096 | J18: =(H18*I18)/1000 -> 335.07431 | K18: =L18-J18 -> 538.27709 | L18: 873.3514 | M18: =(J18/L18) -> 0.38366494 | N18: =K18/L18 -> 0.61633506
B19: =B18+1 -> 12 | C19: 4866.75 | D19: 5 | E19: =C19*D19 -> 24333.75 | F19: =E19 -> 24333.75 | G19: 35.314667 | H19: =(F19*G19)/1000 -> 859.33828 | I19: 1051.5483 | J19: =(H19*I19)/1000 -> 903.63574 | K19: =L19-J19 -> 6.6809602 | L19: 910.3167 | M19: =(J19/L19) -> 0.99266084 | N19: =K19/L19 -> 0.0073391603
B20: =B19+1 -> 13 | C20: 6932.28 | D20: 5 | E20: =C20*D20 -> 34661.4 | F20: =E20 -> 34661.4 | G20: 35.314667 | H20: =(F20*G20)/1000 -> 1224.0558 | I20: 1053.7374 | J20: =(H20*I20)/1000 -> 1289.8334 | K20: =L20-J20 -> -53.700699 | L20: 1236.1327 | M20: =(J20/L20) -> 1.0434425 | N20: =K20/L20 -> -0.043442504
B21: =B20+1 -> 14 | C21: 6338.15 | D21: 5 | E21: =C21*D21 -> 31690.75 | F21: =E21 -> 31690.75 | G21: 35.314667 | H21: =(F21*G21)/1000 -> 1119.1483 | I21: 1054.6459 | J21: =(H21*I21)/1000 -> 1180.3051 | K21: =L21-J21 -> -24.066515 | L21: 1156.2386 | M21: =(J21/L21) -> 1.0208145 | N21: =K21/L21 -> -0.020814488
... B24: =B23+1 -> 17 | C24: 6388.24 | D24: 5 | E24: =C24*D24 -> 31941.2 | F24: =E24 -> 31941.2 | G24: 38.314667 | H24: =(F24*G24)/1000 -> 1223.8164 | I24: 1041.3329 | J24: =(H24*I24)/1000 -> 1274.4003 | K24: =L24-J24 -> -125.496 | L24: 1148.9043 | M24: =(J24/L24) -> 1.109231 | N24: =K24/L24 -> -0.10923103
B25: =B24+1 -> 18 | C25: 7607.66 | D25: 5 | E25: =C25*D25 -> 38038.3 | F25: =E25 -> 38038.3 | G25: 39.314667 | H25: =(F25*G25)/1000 -> 1495.4631 | I25: 1042.2141 | J25: =(H25*I25)/1000 -> 1558.5927 | K25: =L25-J25 -> -1558.5927 | M25: =(J25/L25) -> #DIV/0! | N25: =K25/L25 -> #DIV/0!
B26: =B25+1 -> 19 | C26: 6514.97 | D26: 5 | E26: =C26*D26 -> 32574.85 | F26: =E26 -> 32574.85 | G26: 40.314667 | H26: =(F26*G26)/1000 -> 1313.2442 | I26: 1042.5071 | J26: =(H26*I26)/1000 -> 1369.0664 | K26: =L26-J26 -> -1369.0664 | M26: =(J26/L26) -> #DIV/0! | N26: =K26/L26 -> #DIV/0!
B27: =B26+1 -> 20 | C27: 4942.41 | D27: 5 | E27: =C27*D27 -> 24712.05 | F27: =E27 -> 24712.05 | G27: 41.314667 | H27: =(F27*G27)/1000 -> 1020.9701 | I27: 1042.9853 | J27: =(H27*I27)/1000 -> 1064.8569 | K27: =L27-J27 -> -1064.8569 | M27: =(J27/L27) -> #DIV/0! | N27: =K27/L27 -> #DIV/0!
B28: =B27+1 -> 21 | C28: 3073.52 | D28: 5 | E28: =C28*D28 -> 15367.6 | F28: =E28 -> 15367.6 | G28: 42.314667 | H28: =(F28*G28)/1000 -> 650.27488 | I28: 1043.1149 | J28: =(H28*I28)/1000 -> 678.31139 | K28: =L28-J28 -> -678.31139 | M28: =(J28/L28) -> #DIV/0! | N28: =K28/L28 -> #DIV/0!
B29: =B28+1 -> 22 | D29: 5 | E29: =C29*D29 -> 0 | F29: =E29 -> 0 | G29: 42.314667 | H29: =(F29*G29)/1000 -> 0 | I29: 1042.5884 | J29: =(H29*I29)/1000 -> 0 | K29: =L29-J29 -> 0 | M29: =(J29/L29) -> #DIV/0! | N29: =K29/L29 -> #DIV/0!
B30: =B29+1 -> 23 | D30: 5 | E30: =C30*D30 -> 0 | F30: =E30 -> 0 | G30: 44.314667 | H30: =(F30*G30)/1000 -> 0 | I30: 1042.7497 | J30: =(H30*I30)/1000 -> 0 | K30: =L30-J30 -> 0 | M30: =(J30/L30) -> #DIV/0! | N30: =K30/L30 -> #DIV/0!
B31: =B30+1 -> 24 | D31: 5 | E31: =C31*D31 -> 0 | F31: =E31 -> 0 | G31: 45.314667 | H31: =(F31*G31)/1000 -> 0 | I31: 1042.2931 | J31: =(H31*I31)/1000 -> 0 | K31: =L31-J31 -> 0 | M31: =(J31/L31) -> #DIV/0! | N31: =K31/L31 -> #DIV/0!
B32: =B31+1 -> 25 | D32: 5 | E32: =C32*D32 -> 0 | F32: =E32 -> 0 | G32: 46.314667 | H32: =(F32*G32)/1000 -> 0 | I32: 1039.4114 | J32: =(H32*I32)/1000 -> 0 | K32: =L32-J32 -> 0 | M32: =(J32/L32) -> #DIV/0! | N32: =K32/L32 -> #DIV/0!
B33: =B32+1 -> 26 | D33: 5 | E33: =C33*D33 -> 0 | F33: =E33 -> 0 | G33: 47.314667 | H33: =(F33*G33)/1000 -> 0 | I33: 1039.4407 | J33: =(H33*I33)/1000 -> 0 | K33: =L33-J33 -> 0 | M33: =(J33/L33) -> #DIV/0! | N33: =K33/L33 -> #DIV/0!
B34: =B33+1 -> 27 | D34: 5 | E34: =C34*D34 -> 0 | F34: =E34 -> 0 | G34: 48.314667 | H34: =(F34*G34)/1000 -> 0 | I34: 1040.2491 | J34: =(H34*I34)/1000 -> 0 | K34: =L34-J34 -> 0 | M34: =(J34/L34) -> #DIV/0! | N34: =K34/L34 -> #DIV/0!
B35: =B34+1 -> 28 | D35: 5 | E35: =C35*D35 -> 0 | F35: =E35 -> 0 | G35: 49.314667 | H35: =(F35*G35)/1000 -> 0 | J35: =(H35*I35)/1000 -> 0 | K35: =L35-J35 -> 0 | M35: =(J35/L35) -> #DIV/0! | N35: =K35/L35 -> #DIV/0!
B36: =B35+1 -> 29 | D36: 5 | E36: =C36*D36 -> 0 | F36: =E36 -> 0 | G36: 50.314667 | H36: =(F36*G36)/1000 -> 0 | J36: =(H36*I36)/1000 -> 0 | K36: =L36-J36 -> 0 | M36: =(J36/L36) -> #DIV/0! | N36: =K36/L36 -> #DIV/0!
B37: =B36+1 -> 30 | D37: 5 | E37: =C37*D37 -> 0 | F37: =E37 -> 0 | G37: 51.314667 | H37: =(F37*G37)/1000 -> 0 | J37: =(H37*I37)/1000 -> 0 | K37: =L37-J37 -> 0 | M37: =(J37/L37) -> #DIV/0! | N37: =K37/L37 -> #DIV/0!
B38: Average | F38: =AVERAGE(F8:F37) -> 12674.528 | H38: =AVERAGE(H8:H37) -> 471.76255 | I38: =AVERAGE(I8:I37) -> 1047.1339 | J38: =AVERAGE(J8:J37) -> 494.65048 | K38: =AVERAGE(K8:K37) -> -12.578486 | L38: =AVERAGE(L8:L37) -> 850.71528 | M38: =AVERAGE(M8:M37) -> #DIV/0! | N38: =AVERAGE(N8:N37) -> #DIV/0!
B39: TOTAL | C39: =SUM(C8:C37) -> 76047.17 | E39: =SUM(E8:E37) -> 380235.85 | F39: =SUM(F8:F37) -> 380235.85 | H39: =SUM(H8:H37) -> 14152.877 | J39: =SUM(J8:J37) -> 14839.514
B40: Koreksi
B41: Total Setelah Koreksi | H41: =H39+H40 -> 14152.877 | J41: =J39+J40 -> 14839.514
C43: CONVERT HP Boiler from Utility
C44: =C39 -> 76047.17 | D44: m3 | F44: =C39*5 -> 380235.85 | G44: 9983.7
C45: 5 | D45: bar | F45: 21286.9 | G45: =G44-C39 -> -66063.47
...

Sheet Prod
B2: MONTHLY PRODUCTION REPORT
B3: PT. INDUSTRI NABATI LESTARI
B4: Periode 01 s/d 30 April 2025
B5: NO | C5: Item | D5: Unit | E5: April | H5: Remaks
E6: Budget | F6: Actual | G6: Percentage Act.
B7: 1. | C7: PRODUCTION | H7: Stop Plant
C8: Refinery Plant
C9: Running Days | D9: Days | E9: 25 | F9: 0 | G9: =(F9/E9) -> 0
C10: CPO Incoming | D10: Kg
C11: Total CPO Consume | D11: Kg | E11: 58900000 | F11: 0 | G11: =(F11/E11) -> 0
C12: CPO Consume Poram | F12: 0
C13: CPO Consume Brand | F13: 0
C14: - Avg. FFA | D14: % | E14: 5 | F14: 0 | G14: =(F14/E14) -> 0
C15: - Avg. Moist & Impurities | D15: % | E15: 0.5 | F15: 0 | G15: =(F15/E15) -> 0
C16: - Avg. DOBI | D16: % | E16: 22.2 | F16: 0 | G16: =(F16/E16) -> 0
C17: Product
C18: RBDPO | D18: Kg | E18: 55661000 | F18: 0 | G18: =(F18/E18) -> 0
C19: PFAD | D19: Kg | E19: 2827000 | F19: 0 | G19: =(F19/E19) -> 0
C21: Fraksinasi Plant
C22: Total Proses RBDPO | D22: Kg | E22: =E25+E38+E43 -> 27109000 | F22: 0 | G22: =(F22/E22) -> 0
C23: Total Olah RBDPO ( Feed ) | D23: Kg | E23: =E25+E38+E43 -> 27109000 | F23: 0 | G23: =(F23/E23) -> 0
C24: Fractionation Olein IV 56
C25: RBDPO Consume | D25: Kg | E25: =E26+E27 -> 7883000 | F25: 0 | G25: =(F25/E25) -> 0
C26: Olein IV 56 | D26: Kg | E26: 6464000 | F26: 0 | G26: =(F26/E26) -> 0
C27: Stearin | D27: Kg | E27: 1419000 | F27: 0 | G27: =(F27/E27) -> 0
C28: Fractionation Olein IV 57 ( Bulk )
C29: RBDPO Consume | D29: Kg | E29: 0 | F29: 0 | G29: 0
C30: Olein IV 57 | D30: Kg | E30: 0 | F30: 0 | G30: 0
C31: Stearin | D31: Kg | E31: 0 | F31: 0 | G31: 0
C32: Fractionation Olein IV 57 ( Retail )
C33: CPO | D33: Kg | E33: 1812101.9 | G33: =(F33/E33)*100 -> 0
C34: RBDPO Consume | D34: Kg | E34: =E35+E36 -> 933000 | F34: =F35+F36 -> 0 | G34: =(F34/E34)*100 -> 0
C35: Olein IV 57 | D35: Kg | E35: 700000 | F35: 0 | G35: =(F35/E35)*100 -> 0
C36: Stearin | D36: Kg | E36: 233000 | F36: 0 | G36: =(F36/E36)*100 -> 0
C37: Fractionation Olein IV 58
C38: RBDPO Consume | D38: Kg | E38: =E39+E40 -> 17143000 | F38: 0 | G38: =(F38/E38)*100 -> 0
C39: Olein IV 58 | D39: Kg | E39: 12000000 | F39: 0 | G39: =(F39/E39)*100 -> 0
C40: Stearin | D40: Kg | E40: 5143000 | F40: 0 | G40: =(F40/E40)*100 -> 0
C41: Fractionation Olein IV 60
C42: CPO | E42: 2234607.2 | F42: 0 | G42: =(F42/E42)*100 -> 0
...

Sheet Utility
D2: UTILITY (GAS, STEAM, WATER & POWER) REPORT
D3: PT. INDUSTRI NABATI LESTARI
D5: Periode 01 s/d 30 April 2025
D6: No | E6: Item | F6: Norma | G6: UoM | H6: April | K6: Consume CPO ( MT ) | L6: Remaks
H7: Budget | I7: Actual | J7: Percentage Act.
E9: Total Feed Raw Material CPO
D10: 1. | E10: GAS CONSUMPTION
E11: Incoming *base on INL | G11: mmbtu | I11: 0
E12: Incoming *base on Pertagas | F12: 1460.001 | G12: mmbtu | H12: 26051.47 | I12: 0 | J12: =I12/H12 -> 0 | K12: =I12/K9 -> #DIV/0!
E13: Distribution to
E14: HP Boiler Refinery | F14: 0.2 | G14: mmbtu | H14: 3907.73 | I14: 0 | J14: =I14/H14 -> 0 | K14: =I14/K9 -> #DIV/0!
E15: MP Boiler | F15: 0.4 | G15: mmbtu | H15: 22143.74 | I15: =I12-$I$14 -> 0 | J15: =I15/H15 -> 0 | K15: =I15/K9 -> #DIV/0!
E16: Total | G16: mmbtu | H16: 26051.47 | I16: =$I$12 -> 0 | J16: =I16/H16 -> 0 | K16: =SUM(K14+K15) -> #DIV/0!
D17: 2. | E17: STEAM CONSUMPTION
E18: Incoming | F18: 408000 | G18: Kg | H18: 11424000 | I18: 0 | J18: =I18/H18 -> 0 | K18: =I18/$K$9 -> #DIV/0!
E19: Distribution to | K19: =I19/$K$9 -> #DIV/0!
E20: Refinery | F20: 28 | G20: Kg | H20: 3420000 | I20: 0 | J20: =I20/H20 -> 0 | K20: =I20/$K$9 -> #DIV/0!
E21: Fractionation | F21: 45 | G21: Kg | H21: 2318000 | I21: 0 | J21: =I21/H21 -> 0 | K21: =I21/$K$9 -> #DIV/0!
E22: Others | F22: 106000 | G22: Kg | H22: 5686000 | I22: 0 | J22: =I22/H22 -> 0 | K22: =I22/$K$9 -> #DIV/0!
E23: Total | G23: Kg | H23: 11424000 | I23: =SUM(I20:I22) -> 0 | J23: =I23/H23 -> 0 | K23: =I23/$K$9 -> #DIV/0!
D24: 3. | E24: WATER CONSUMPTION
E25: Incoming Raw Water | G25: m3 | H25: 19123.69 | I25: 0 | J25: =I25/H25 -> 0 | K25: =I25/$K$9 -> #DIV/0!
E26: - Suplay To RO Product | I26: 0 | K26: =I26/$K$9 -> #DIV/0!
E27: - Suplay To Proses dan Sanitary | I27: 0 | K27: =I27/$K$9 -> #DIV/0!
E28: Rincian Outgoing Proses | K28: =I28/$K$9 -> #DIV/0!
E29: Softener Product (to Refinery) | F29: 0.4 | G29: m3 | H29: 1521.33 | I29: 0 | J29: =I29/H29 -> 0 | K29: =I29/$K$9 -> #DIV/0!
E30: Softener Product (to Fractionation) | F30: 0.13 | G30: m3 | H30: 2622 | I30: 0 | J30: =I30/H30 -> 0 | K30: =I30/$K$9 -> #DIV/0!
E31: Others | G31: m3 | H31: 2730.3 | I31: 0 | J31: =I31/H31 -> 0 | K31: =I31/$K$9 -> #DIV/0!
E32: Total | G32: m3 | H32: 6873.63 | I32: =SUM(I26:I27) -> 0 | J32: =I32/H32 -> 0 | K32: =I32/$K$9 -> #DIV/0!
D33: 4 | E33: POWER CONSUMPTION
E34: Incoming
E35: PLN *base on BA Kinra | F35: 28770 | G35: Kwh | H35: 568099 | I35: 0 | J35: =I35/H35 -> 0 | K35: =I35/$K$9 -> #DIV/0!
E36: Outgoing | K36: =I36/$K$9 -> #DIV/0!
E37: - Physical Refinery Plant | F37: 4.4 | G37: Kwh | H37: 102679 | I37: 0 | J37: =I37/H37 -> 0 | K37: =I37/$K$9*1000 -> #DIV/0!
E38: - Utility System/chiller | F38: 7.3 | G38: Kwh | H38: 73158 | I38: 0 | J38: =I38/H38 -> 0 | K38: =I38/$K$9*1000 -> #DIV/0!
E39: - Refinery - Utilities | F39: 11.7 | G39: Kwh | H39: 212 | I39: 0 | J39: =I39/H39 -> 0 | K39: =I39/$K$9*1000 -> #DIV/0!
E40: - Dry Fractionation Plant | F40: 4.5 | G40: Kwh | H40: 109440 | I40: 0 | J40: =I40/H40 -> 0 | K40: =I40/$K$9*1000 -> #DIV/0!
E41: - Dry Fractionation CW System | F41: 4.1 | G41: Kwh | H41: 28747 | I41: 0 | J41: =I41/H41 -> 0 | K41: =I41/$K$9*1000 -> #DIV/0!
E42: - Lighting - Refinery & Dry Fractionation | G42: Kwh | H42: 4581 | I42: =#REF! -> #REF! | J42: =I42/H42 -> #REF! | K42: =I42/$K$9*1000 -> #REF!
D44: Note untuk Power Consumption
...

Sheet Qty cons analysis
D2: Quantity Utility Consumption Analysis (based on Guarantee Utility Consumption)
D3: Refinery & Fractionation Plant
D4: Periode 01 s/d 30 April 2025
D5: Periode 01 s/d 31 Januari 2025 | E5: UoM | F5: Budget | G5: Actual | H5: Under (Over) Budget | I5: Explanation Under / Over budget
D6: CPO Consume | E6: Kg | F6: 58900000 | G6: 0 | H6: =G6/F6 -> 0 | I6: STOP PLANT
D7: RbdPO Consume | E7: Kg | F7: 35501000 | G7: 0 | H7: =G7/F7 -> 0
D8: TOTAL ACTUAL CONSUMPTION
D9: Refinery
D10: Bleaching Earth to Poram Spec | E10: Kg | F10: 1300309 | G10: 0 | H10: 0
D11: Bleaching Earth to Branded Spec | E11: Kg | F11: 106326 | G11: 0 | H11: 0
D12: Phosporic Acid | E12: Kg | F12: 489915 | G12: 0 | H12: 0
D13: Gas Consumption (MP Boiler) | E13: mmbtu | F13: 22143.74 | G13: 0 | H13: 0
D14: Gas Consumption (HP Boiler) | E14: mmbtu | F14: 3907.73 | G14: 0 | H14: 0
D15: Cooling Water top up to Cooling Tower | E15: m3 | F15: 1521.33 | G15: 0 | H15: 0
D16: Steam | E16: Kg | F16: 11424000 | G16: 0 | H16: 0
D17: Power (Process Plant) | E17: Kwh | F17: 102679 | G17: 0 | H17: 0
D18: Power (Cooling Tower) | E18: Kwh | F18: 73158 | G18: 0 | H18: 0
D19: Fractionation
D20: Cooling Water top up to Cooling Tower | E20: m3 | F20: 2622 | G20: 0 | H20: 0
D21: Steam | E21: Kg | F21: 2318000 | G21: 0 | H21: 0
D22: Power (Process Plant) | E22: Kwh | F22: 109440 | G22: 0 | H22: 0
D23: Power (Cooling Tower) | E23: Kwh | F23: 28747 | G23: 0 | H23: 0
D24: ACTUAL CONSUMPTION PER MT RAW MATERIAL
D25: Refinery
D26: Bleaching Earth to Poram Spec | E26: Kg/MT | F26: 9 | G26: 0 | H26: 0
D27: Bleaching Earth to Branded Spec | E27: Kg/MT | F27: 16 | G27: 0 | H27: 0
D28: Phosporic Acid | E28: Kg/MT | F28: 0.55 | G28: 0 | H28: 0
D29: Gas Consumption (HP Boiler) | E29: Nm3/MT | F29: 4.2 | G29: 0 | H29: 0
D30: Gas Consumption (HP Boiler) **) | E30: mmbtu/MT | F30: 0.2 | G30: 0 | H30: 0
D31: Cooling Water top up to Cooling Tower | E31: m3/MT | F31: 0.4 | G31: 0 | H31: 0
D32: Steam | E32: Kg/MT | F32: 28 | G32: 0 | H32: 0
D33: Power (Process Plant) | E33: Kwh/MT | F33: 4.4 | G33: 0 | H33: 0
D34: Power (Cooling Tower) | E34: Kwh/MT | F34: 7.3 | G34: 0 | H34: 0
D35: Fractionation
D36: Cooling Water top up to Cooling Tower | E36: m3/MT | F36: 0.13 | G36: 0 | H36: 0
D37: Steam | E37: Kg/MT | F37: 45 | G37: 0 | H37: 0
D38: Power (Process Plant) | E38: Kwh/MT | F38: 4.5 | G38: 0 | H38: 0
D39: Power (Cooling Tower) | E39: Kwh/MT | F39: 4.1 | G39: 0 | H39: 0
D47: Prepared by, | G47: Checked by, | I47: Approved by,
D51: Bany Subana | F51: Reza P. Panjaitan | H51: Sudarianto | I51: Eben Jaya Ginting
...

Sheet 2025
C2: PRODUCTION REPORT 2025
F3: ok | G3: ok | H3: ok | I3: ok | J3: OK | K3: OK | L3: ok | M3: ok | N3: ok
B4: No | C4: ITEM | D4: Budget / Norma | E4: UoM | F4: MONTHLY REPORT | T4: Yearly Report | U4: Yearly Report RKAP (Budget) | V4: Yearly Report RKAP
F5: JANUARI | G5: FEBRUARI | H5: MARET | I5: APRIL | J5: MEI | K5: JUNI | L5: JULI | M5: AGUSTUS | N5: SEPTEMBER | O5: OKTOBER | P5: NOVEMBER | Q5: DESEMBER | R5: DESEMBER | T5: TOTAL (Kg) | U5: TOTAL (Kg) | V5: TOTAL (%)
B6: 1 | C6: PRODUCTION | T6: Production | U6: Production | V6: Production | DG6: 29 | DH6: 30 | DI6: 31
C7: Refinery | T7: Refinery | U7: Refinery | V7: Refinery | DE7: CPO Olah | DF7: Kg | DG7: 1971320 | DH7: 2015120 | DI7: 2015230 | AIU7: Sounding | AIV7: Production | AIW7: Diff
C8: Running Days | D8: 300 | E8: Day | F8: 0 | R8: ='[2]Desember 24'!AL9 -> 0 | T8: =SUM(F8:R8) -> 0 | U8: 231 | V8: =T8/U8*100 -> 0 | OR8: Poram | AEE8: 14 Juni | AEF8: 15 Juni | AIT8: CPO | AIU8: 11008948 | AIV8: =T11 -> 0 | AIW8: =AIU8-AIV8 -> 11008948
C9: Ratio Run CPO | R9: ='[2]Desember 24'!AL10 -> 0
C10: Utilitas CPO | R10: =R11/R14*100 -> #DIV/0! | T10: =AVERAGE(F10:Q10) -> #DIV/0!
C11: CPO Consume Total | D11: 707651 | E11: Kg | F11: 0 | R11: ='[2]Desember 24'!AL11 -> 0 | T11: =SUM(F11:Q11) -> 0 | U11: 421374000 | V11: =T11/U11 -> 0 | AX11: =T11/D11 -> 0 | DE11: HP Boiler | DF11: mmbtu | DG11: 251.19642 | DH11: 257.91391 | DI11: 251.51265 | OO11: 26946.108 | OP11: 17383.234 | OR11: RBDPO Olah | AEE11: =35.8500000000058*1000 -> 35850 | AIT11: PFAD | AIU11: 566885 | AIV11: =T20 -> 0 | AIW11: =AIU11-AIV11 -> 566885
C12: CPO Consume Poram | E12: Kg | F12: 0 | R12: ='[2]Desember 24'!AL12 -> #DIV/0! | T12: =SUM(F12:Q12) -> 0
