Workbook

Sheet JUNI 2025
C1: PRODUCTION REPORT PMG2
C2: No | D2: ITEM | E2: Budget / Norma | F2: UoM | G2: JUNI 2025 | AL2: TOTAL MONTHLY (Kg)
G3: 1 | H3: 2 | I3: 3 | J3: 4 | K3: 5 | L3: 6 | M3: 7 | N3: 8 | O3: 9 | P3: 10 | Q3: 11 | R3: 12 | S3: 13 | T3: 14 | U3: 15 | V3: 16 | W3: 17 | X3: 18 | Y3: 19 | Z3: 20 | AA3: 21 | AB3: 22 | AC3: 23 | AD3: 24 | AE3: 25 | AF3: 26 | AG3: 27 | AH3: 28 | AI3: 29 | AJ3: 30
C4: 1 | D4: PRODUCTION | AL4: Production | AN4: aktual refinery
D5: Refinery | AL5: Refinery | AN5: cpo feed | AO5: =AL9 -> 17813187 | AQ5: sisa rbpo tank
D6: Running Days | F6: Day | N6: 1 | O6: 1 | P6: 1 | Q6: 1 | R6: 1 | S6: 1 | T6: 1 | U6: 1 | V6: 1 | W6: 1 | AL6: =SUM(G6:AJ6) -> 10 | AN6: rpo prod | AO6: =AL20+AL19+AL18 -> 16884686 | AQ6: tk 108 | AR6: 80236
D7: Incoming CPO | F7: Kg | G7: ='[1]01 (stock opname)'!$Q$15 -> 0 | H7: ='[1]02'!$Q$15 -> 393366 | I7: ='[1]03'!$Q$15 -> 1185533 | J7: ='[2]04'!$Q$15 -> 0 | K7: ='[2]05'!$Q$15 -> 445557 | L7: ='[2]06'!$Q$15 -> 0 | M7: ='[2]07'!$Q$15 -> 0 | N7: ='[2]08'!$Q$15 -> 0 | O7: ='[2]09'!$Q$15 -> 0 | P7: ='[2]10'!$Q$15 -> 0 | Q7: ='[2]11'!$Q$15 -> 224431 | R7: ='[2]12'!$Q$15 -> 0 | S7: ='[2]13 (Rev)'!$Q$15 -> 0 | T7: ='[2]14'!$Q$15 -> 208963 | U7: ='[2]15'!$Q$15 -> 0 | V7: ='[2]16'!$Q$15 -> 0 | W7: ='[2]17'!$Q$15 -> 516088 | X7: ='[2]18'!$Q$15 -> 0 | Y7: ='[2]19'!$Q$15 -> 0 | Z7: ='[2]20'!$Q$15 -> 218854 | AA7: ='[2]21'!$Q$15 -> 671086 | AB7: ='[2]22'!$Q$15 -> 0 | AC7: ='[2]23'!$Q$15 -> 132192 | AD7: ='[2]24'!$Q$15 -> 210307 | AE7: ='[2]25'!$Q$15 -> 277054 | AF7: ='[2]26'!$Q$15 -> 161951 | AG7: ='[2]27'!$Q$15 -> 0 | AH7: ='[2]28'!$Q$15 -> 501448 | AI7: ='[2]29'!$Q$15 -> 0 | AJ7: ='[2]30'!$Q$15 -> 1020823 | AL7: =SUM(G7:AJ7) -> 6167653 | AN7: pfad prod | AO7: =AL21 -> 866309 | AQ7: tk 109 | AR7: 70298
D8: Ratio Run CPO ( utilisasi kapasitas ) | F8: % | G8: =G9/2500000 -> 0 | H8: =H9/2500000 -> 0 | I8: =I9/2500000 -> 0 | J8: =J9/2500000 -> 0 | K8: =K9/2500000 -> 0 | L8: =L9/2500000 -> 0 | M8: 0 | N8: =N9/2500000 -> 0.2955432 | O8: =O9/2500000 -> 0.8925324 | P8: =P9/2500000 -> 0.87464 | Q8: =Q9/2500000 -> 1.0053404 | R8: =R9/2500000 -> 0.919868 | S8: =S9/2500000 -> 0.7951732 | T8: =T9/2500000 -> 0.6404488 | U8: =U9/2500000 -> 0.8040796 | ... W8: =W9/2500000 -> 0.1286836 | X8: 0 | Y8: =Y9/2500000 -> 0 | Z8: =Z9/2500000 -> 0 | AA8: =AA9/2500000 -> 0 | AB8: =AB9/2500000 -> 0 | AC8: =AC9/2500000 -> 0 | AD8: =AD9/2500000 -> 0 | AE8: =AE9/2500000 -> 0 | AF8: =AF9/2500000 -> 0 | ... AJ8: =AJ9/2500000 -> 0 | AL8: =AL9/2500000/AL6 -> 0.71252748 | AN8: yield rpo | AO8: =AO6/AO5*100 -> 94.787564 | AQ8: total rpo tank | AR8: =AR6+AR7 -> 150534
D9: CPO Consume Total | E9: 58900000 | F9: Kg | G9: ='[1]01 (stock opname)'!$R$15 -> 0 | H9: ='[1]02'!$R$15 -> 0 | I9: 0 | J9: =[1]MTD!$R$15 -> 0 | K9: ='[1]04'!$R$15 -> 0 | L9: ='[1]05'!$R$15 -> 0 | M9: 0 | N9: 738858 | O9: 2231331 | P9: 2186600 | Q9: 2513351 | R9: 2299670 | S9: 1987933 | T9: 1601122 | U9: 2010199 | V9: 1922414 | W9: 321709 | X9: Stop plant, Refinery tgl 18 Pukul 17.00 WIB Fraksinasi tgl 17 Pukul 04.00 WIB | AL9: =SUM(G9:AJ9) -> 17813187 | AN9: yield pfad | AO9: =AO7/AO5*100 -> 4.8633016 | AQ9: oip | AR9: 307166
D10: Avg Daily Consump CPO ( MTD ) | AL10: =AL9/AL6 -> 1781318.7 | AN10: lossis | AO10: =(AO5-AO6-AO7)/AO5*100 -> 0.3491346 | AQ10: total keseluruhan rpo | AR10: =AR8+AR9 -> 457700
D11: CPO Consume Poram | F11: Kg | G11: =G9-G12 -> 0 | H11: =H9-H12 -> 0 | I11: =I9-I12 -> 0 | J11: =J9-J12 -> 0 | L11: =L9-L12 -> 0 | M11: =M9-M12 -> 0 | N11: =N9-N12 -> 738858 | O11: =O9-O12 -> 2231331 | P11: =P9-P12 -> 2186600 | Q11: =Q9-Q12 -> 2513351 | R11: =R9-R12 -> 2299670 | S11: =S9-S12 -> 1987933 | ... W11: =W9-W12 -> 321709 | Y11: =Y9-Y12 -> 0 | Z11: =Z9-Z12 -> 0 | AA11: =AA9-AA12 -> 0 | AB11: =AB9-AB12 -> 0 | AC11: 0 | AD11: =AD9-AD12 -> 0 | AE11: =AE9-AE12 -> 0 | AF11: =AF9-AF12 -> 0 | AG11: =AG9-AG12 -> 0 | AH11: =AH9-AH12 -> 0 | AJ11: =AJ9-AJ12 -> 0 | AL11: =SUM(G11:AJ11) -> 17813187
D12: CPO Consume Brand | F12: Kg | G12: =G40+G49+G54 -> 0 | H12: =H40+H49+H54 -> 0 | I12: =I40+I49+I54 -> 0 | J12: =J40+J49+J54 -> 0 | K12: 0 | L12: =L40+L49+L54 -> 0 | M12: =M40+M49+M54 -> 0 | N12: =N40+N49+N54 -> 0 | O12: =O40+O49+O54 -> 0 | P12: =P40+P49+P54 -> 0 | R12: =R40+R49+R54 -> 0 | S12: 0 | T12: =T40+T49+T54 -> 0 | U12: =U40+U49+U54 -> 0 | V12: =V40+V49+V54 -> 0 | W12: =W40+W49+W54 -> 0 | X12: 0 | Y12: =Y40+Y49+Y54 -> 0 | Z12: =Z40+Z49+Z54 -> 0 | AA12: =AA40+AA49+AA54 -> 0 | AB12: =AB40+AB49+AB54 -> 0 | AC12: 0 | AD12: =AD40+AD49+AD54 -> 0 | AE12: =AE40+AE49+AE54 -> 0 | AF12: =AF40+AF49+AF54 -> 0 | AG12: =AG40+AG49+AG54 -> 0 | AH12: =AH40+AH49+AH54 -> 0 | AJ12: =AJ40+AJ49+AJ54 -> 0 | AL12: =SUM(G12:AJ12) -> 0 | AN12: aktual fraksinasi
D13: - FFA | E13: 5 | F13: % | G13: 0 | H13: 0 | I13: 0 | J13: 0 | K13: 0 | L13: 0 | M13: 0 | N13: 3.95 | O13: 3.98 | P13: 4.425 | Q13: =(4.66+4.69)/2 -> 4.675 | R13: 4.405 | S13: 4.9833333 | T13: 4.8333333 | U13: 4.48 | V13: =(4.59+5.36)/2 -> 4.975 | W13: 4.995 | AE13: 0 | AF13: 0 | AL13: =SUM(G13:AJ13)/AL6 -> 4.5701667 | AN13: rpo feed | AO13: =AO14+AO15 -> 17792607
D14: - Moist & Impurities | E14: 0.5 | F14: % | G14: 0 | H14: 0 | I14: 0 | J14: 0 | K14: 0 | L14: 0 | M14: 0 | N14: 0.49 | O14: 0.47 | P14: 0.43 | Q14: =(0.44+0.45)/2 -> 0.445 | R14: 0.47 | S14: 0.42 | T14: 0.44666667 | U14: 0.44 | V14: =(0.46+0.45)/2 -> 0.455 | W14: 0.5 | AE14: 0 | AF14: 0 | AL14: =SUM(G14:AJ14)/AL6 -> 0.45666667 | AN14: olein 56 | AO14: =AL33 -> 14325558
D15: - DOBI | E15: 2,20 Min | F15: % | AL15: =SUM(G15:AJ15)/AL6 -> 0 | AN15: stearin 56 | AO15: =AL34 -> 3467049
D16: TANK | N16: 107 | O16: 107 | P16: 105&107 | Q16: 105&104 | R16: 107&104 | S16: 104,105&106 | T16: 104,103&106 | U16: 103 | V16: 103&106 | W16: 103&106 | AN16: yield olein | AO16: =AO14/(AO14+AO15)*100 -> 80.514103
D17: Product | AL17: Product | AN17: yield stearin | AO17: =AO15/(AO14+AO15)*100 -> 19.485897
D18: OIP RBDPO | F18: Kg | N18: ='[3]OIP Refinery '!L13 -> 311880 | O18: 4410 | P18: 0 | Q18: 6558 | R18: 9650 | S18: 0 | T18: 9873 | V18: 15966 | AL18: =SUM(N18:X18) -> 358337
D19: DIRECT RBDPO FRACT | F19: Kg | N19: 30000 | O19: 90000 | P19: 20000 | Q19: 60000 | R19: 0 | S19: 70000 | T19: 8000 | U19: 15000 | AL19: =SUM(N19:X19) -> 293000 | AN19: sap refinery | AQ19: sisa rbdo di gudang bulky 1014
D20: RBDPO | E20: 55661000 | F20: Kg | N20: =407840 -> 407840 | O20: =2031338 -> 2031338 | P20: 2046616 | Q20: 2312694 | R20: 2167692 | S20: 1801948 | T20: 1485187 | U20: 1883642 | V20: 1786212 | W20: 301271 | X20: 8909 | AL20: =SUM(G20:AJ20) -> 16233349 | AN20: cpo feed | AO20: 17813187 | AQ20: tk 108 | AR20: 195993 | AS20: =AR20-AR6 -> 115757
D21: PFAD | E21: 2827000 | F21: Kg | N21: 13234 | O21: 90330 | P21: 110892 | Q21: 119505 | R21: 104139 | S21: 97005 | T21: 84749 | U21: 96539 | V21: 106075 | W21: 32094 | X21: 11747 | AL21: =SUM(G21:AJ21) -> 866309 | AN21: rpo prod | AO21: 17065034 | AQ21: tk 109 | AR21: 390524 | AS21: =AR21-AR7 -> 320226 | AU21: =AS21/AS20*100 -> 276.6364
D22: Fractionation | AN22: pfad prod | AO22: 748153 | AQ22: total | AR22: =AR20+AR21 -> 586517 | AU22: =AS22/AS20*100 -> 0
D23: Running Days | F23: Day | N23: 1 | O23: 1 | P23: 1 | Q23: 1 | R23: 1 | S23: 1 | T23: 1 | U23: 1 | V23: 1 | W23: 1 | AL23: =SUM(G23:AJ23) -> 10 | AQ23: OIP actual | AR23: 435983 | AS23: adjust
D24: Avg Daily Consump RBDPO ( MTD ) | F24: Kg | G24: 0 | H24: 0 | I24: 0 | J24: 0 | K24: 0 | M24: 0 | N24: 0 | O24: 0 | P24: 0 | R24: 0 | S24: 0 | T24: 0 | U24: 0 | V24: 0 | W24: 0 | X24: 0 | Y24: 0 | Z24: 0 | AA24: 0 | AB24: 0 | AC24: 0 | AD24: 0 | AE24: 0 | AF24: 0 | AG24: 0 | AH24: 0 | AJ24: 0 | AL24: =AL29/AL23 -> 1779260.7 | AN24: yield rpo | AO24: =AO21/AO20*100 -> 95.800005 | AQ24: stok actual | AR24: =AR22-AR23 -> 150534
D25: Total RBDPO transfer to plant | F25: Kg | N25: 586396 | O25: 1842499 | P25: =1537236+1219751 -> 2756987 | Q25: =1183492+1051025 -> 2234517 | R25: =1166617+996624 -> 2163241 | S25: =907358+972093 -> 1879451 | T25: =944532+806441 -> 1750973 | U25: =750862+786319 -> 1537181 | V25: =1151822+657738 -> 1809560 | W25: 662642 | AF25: ='[4]26'!$R$18 -> 0 | AL25: =SUM(G25:AJ25) -> 17223447 | AN25: yield pfad | AO25: =AO22/AO20*100 -> 4.1999952 | AQ25: opening stok rpo sap | AR25: =AR23+AR24 -> 586517
D26: Stok TK 131 | E26: 559 | F26: ton | M26: ='[3]Oip Fract .'!T13 -> 0 | N26: ='[3]Oip Fract .'!T14 -> 34865 | O26: ='[3]Oip Fract .'!T15 -> 195375 | P26: 296343 | Q26: ='[3]Oip Fract .'!T17 -> 207866 | R26: ='[3]Oip Fract .'!T18 -> 175767 | S26: ='[3]Oip Fract .'!T19 -> 200007 | T26: ='[3]Oip Fract .'!T20 -> 158440 | U26: ='[3]Oip Fract .'!T21 -> 59863 | V26: ='[3]Oip Fract .'!T22 -> 34480 | W26: ='[3]Oip Fract .'!T23 -> 34859 | AN26: loss | AO26: =AO20-AO21-AO22 -> 0
D27: Stok TK 132 | E27: 559 | F27: ton | M27: ='[3]Oip Fract .'!V13 -> 0 | N27: ='[3]Oip Fract .'!V14 -> 52290 | O27: ='[3]Oip Fract .'!V15 -> 53075 | P27: 53075 | Q27: ='[3]Oip Fract .'!V17 -> 75063 | R27: ='[3]Oip Fract .'!V18 -> 97032 | S27: ='[3]Oip Fract .'!V19 -> 115080 | T27: ='[3]Oip Fract .'!V20 -> 130221 | U27: ='[3]Oip Fract .'!V21 -> 148827 | V27: ='[3]Oip Fract .'!V22 -> 165316 | W27: ='[3]Oip Fract .'!V23 -> 78396 | X27: ='[3]Oip Fract .'!V24 -> 272307
D28: Ratio Run RBDPO | G28: =G29/2500000 -> 0 | H28: =H29/2500000 -> 0 | I28: =I29/2500000 -> 0 | J28: =J29/2500000 -> 0 | K28: =K29/2500000 -> 0 | L28: =L29/2500000 -> 0 | M28: =M29/2500000 -> 0 | N28: =N29/2500000 -> 0.0762112 | ... W28: =W29/2500000 -> 0.577254 | X28: 0 | Y28: =Y29/2500000 -> 0 | Z28: =Z29/2500000 -> 0 | AA28: =AA29/2500000 -> 0 | AB28: =AB29/2500000 -> 0 | AC28: 0.52886 | AD28: =AD29/2500000 -> 0 | AE28: =AE29/2500000 -> 0 | AF28: =AF29/2500000 -> 0 | AG28: =AG29/2500000 -> 0 | AH28: =AH29/2500000 -> 0 | AI28: =AI29/2500000 -> 0 | AJ28: =AJ29/2500000 -> 0 | AL28: =AL29/2500000/10 -> 0.71170428 | AN28: sap fraksinasi
D29: Total Proses RBDPO | E29: 35501000 | F29: Kg | G29: =SUM(G32,G36,G41,G45,G55) -> 0 | H29: =SUM(H32,H36,H41,H45,H55) -> 0 | I29: =SUM(I32,I36,I41,I45,I55) -> 0 | J29: =SUM(J32,J36,J41,J45,J55) -> 0 | L29: =SUM(L32,L36,L41,L45,L55) -> 0 | M29: =SUM(M32,M36,M41,M45,M55) -> 0 | N29: =SUM(N32,N36,N41,N45,N55) -> 190528 | O29: =SUM(O32,O36,O41,O45,O55) -> 1817708 | P29: =SUM(P32,P36,P41,P45,P55) -> 2405788 | Q29: =SUM(Q32,Q36,Q41,Q45,Q55) -> 2393434 | R29: =SUM(R32,R36,R41,R45,R55) -> 2405045 | S29: =SUM(S32,S36,S41,S45,S55) -> 1825948 | ... AB29: =SUM(AB32,AB36,AB41,AB45,AB55) -> 0 | AC29: =AC46+AC47+AC56+AC57 -> 0 | AD29: =SUM(AD32,AD36,AD41,AD45,AD55) -> 0 | AE29: =SUM(AE32,AE36,AE41,AE45,AE55) -> 0 | AF29: =SUM(AF32,AF36,AF41,AF45,AF55) -> 0 | AG29: =SUM(AG32,AG36,AG41,AG45,AG55) -> 0 | AH29: =SUM(AH32,AH36,AH41,AH45,AH55) -> 0 | AJ29: =SUM(AJ32,AJ36,AJ41,AJ45,AJ55) -> 0 | AL29: =SUM(G29:AJ29) -> 17792607 | AN29: rpo feed | AO29: =AO31+AO32 -> 17792608
D30: Sisa Filling Crystalizer | F30: Kg | G30: =G25-G29 -> 0 | I30: =I25-I29 -> 0 | J30: =SUM(J33,J37,J42,J46,#REF!) -> #REF! | K30: 68473 | L30: =L25-L29 -> 0 | M30: =M25-M29 -> 0 | N30: =N25-N29 -> 395868 | O30: =O25-O29 -> 24791 | P30: =P25-P29 -> 351199 | Q30: =Q25-Q29 -> -158917 | R30: =R25-R29 -> -241804 | S30: 122463 | T30: =T25-T29 -> -485041 | U30: =U25-U29 -> 376836 | V30: =V25-V29 -> -80715 | W30: =W25-W29 -> -780493 | X30: -255281 | Y30: =Y25-Y29 -> 0 | Z30: =Z25-Z29 -> 0 | AA30: =AA25-AA29 -> 0 | AB30: =AB25-AB29 -> 0 | AC30: 390824 | AD30: =AD25-AD29 -> 0 | AE30: =AE25-AE29 -> 0 | AF30: =AF25-AF29 -> 0 | AG30: =AG25-AG29 -> 0 | AH30: =AH25-AH29 -> 0 | AJ30: =AJ25-AJ29 -> 0 | AL30: =SUM(G30:AJ30) -> #REF!
D31: Fractionation OLEIN IV 56 | AL31: Olein IV 56 | AN31: olein 56 | AO31: 14624233
D32: RBDPO Consume | F32: Kg | G32: =G33+G34 -> 0 | H32: =H33+H34 -> 0 | I32: =I33+I34 -> 0 | J32: =J33+J34 -> 0 | K32: 0 | L32: =L33+L34 -> 0 | M32: =M33+M34 -> 0 | N32: =N33+N34 -> 190528 | O32: =O33+O34 -> 1817708 | P32: =P33+P34 -> 2405788 | Q32: =Q33+Q34 -> 2393434 | R32: =R33+R34 -> 2405045 | S32: =S33+S34 -> 1825948 | ... AB32: =AB33+AB34 -> 0 | AC32: 0 | AD32: =AD33+AD34 -> 0 | AE32: =AE33+AE34 -> 0 | AF32: =AF33+AF34 -> 0 | AG32: =AG33+AG34 -> 0 | AH32: =AH33+AH34 -> 0 | AJ32: =AJ33+AJ34 -> 0 | AL32: =SUM(G32:AJ32) -> 17792607 | AN32: stearin 56 | AO32: 3168375
D33: OLEIN IV 56 | E33: 25000000 | F33: Kg | G33: 0 | H33: 0 | I33: 0 | J33: 0 | K33: 0 | L33: 0 | M33: 0 | N33: 190528 | O33: 1477571 | P33: 1922667 | Q33: 1924360 | R33: =1376983+564099 -> 1941082 | S33: 1474626 | T33: =1676048+133231 -> 1809279 | U33: =511790+424142 -> 935932 | V33: =591257+913865 -> 1505122 | W33: 1134304 | X33: 10087 | Z33: 0 | AA33: 0 | AB33: 0 | AC33: 0 | AD33: 0 | AF33: 0 | AG33: 0 | AH33: 0 | AJ33: 0 | AL33: =SUM(G33:AJ33) -> 14325558 | AN33: yield olein | AO33: =AO31/(AO31+AO32)*100 -> 82.192745
D34: STEARIN | E34: 639000 | F34: Kg | G34: 0 | H34: 0 | I34: 0 | J34: 0 | K34: 0 | L34: 0 | M34: 0 | N34: 0 | O34: 340137 | P34: 483121 | Q34: 469074 | R34: 463963 | S34: =242278+109044 -> 351322 | T34: 426735 | U34: 224413 | V34: 385153 | W34: 308831 | X34: 14300 | Z34: 0 | AA34: 0 | AB34: 0 | AC34: 0 | AD34: 0 | AF34: 0 | AG34: 0 | AJ34: 0 | AL34: =SUM(G34:AJ34) -> 3467049 | AN34: yiel stearin | AO34: =AO32/(AO31+AO32)*100 -> 17.807255
D35: Fractionation OLEIN IV 57 ( Bulk ) | AL35: Olein IV 57 ( Bulk )
D36: RBDPO Consume | F36: Kg | G36: =G37+G38 -> 0 | H36: =H37+H38 -> 0 | I36: =I37+I38 -> 0 | J36: =J37+J38 -> 0 | K36: 0 | L36: =L37+L38 -> 0 | M36: =M37+M38 -> 0 | N36: =N37+N38 -> 0 | O36: =O37+O38 -> 0 | P36: =P37+P38 -> 0 | Q36: =Q37+Q38 -> 0 | R36: =R37+R38 -> 0 | S36: 0 | T36: =T37+T38 -> 0 | U36: =U37+U38 -> 0 | V36: =V37+V38 -> 0 | W36: =W37+W38 -> 0 | X36: 0 | AA36: =AA37+AA38 -> 0 | AB36: =AB37+AB38 -> 0 | AC36: 0 | AD36: =AD37+AD38 -> 0 | AE36: =AE37+AE38 -> 0 | AF36: =AF37+AF38 -> 0 | AG36: =AG37+AG38 -> 0 | AH36: =AH37+AH38 -> 0 | AJ36: =AJ37+AJ38 -> 0 | AL36: =SUM(G36:AJ36) -> 0
D37: OLEIN IV 57 | F37: Kg | G37: 0 | H37: 0 | I37: 0 | J37: 0 | K37: 0 | L37: 0 | M37: 0 | N37: 0 | O37: 0 | P37: 0 | Q37: 0 | R37: 0 | S37: 0 | T37: 0 | U37: 0 | V37: 0 | W37: 0 | X37: 0 | AA37: 0 | AB37: 0 | AC37: 0 | AD37: 0 | AE37: 0 | AF37: 0 | AG37: 0 | AL37: =SUM(G37:AJ37) -> 0
D38: STEARIN | F38: Kg | G38: 0 | H38: 0 | I38: 0 | J38: 0 | K38: 0 | L38: 0 | M38: 0 | N38: 0 | O38: 0 | P38: 0 | Q38: 0 | R38: 0 | S38: 0 | T38: 0 | U38: 0 | V38: 0 | W38: 0 | X38: 0 | AA38: 0 | AB38: 0 | AC38: 0 | AD38: 0 | AE38: 0 | AF38: 0 | AG38: 0 | AL38: =SUM(G38:AJ38) -> 0
D39: Fractionation OLEIN IV 57 ( Retail ) | AL39: Olein IV 57 ( Retail )
D40: CPO Consume | F40: Kg | AL40: =SUM(G40:AJ40) -> 0
...

Sheet Peformance test Fract 1
C1: PT.INDUSTRI NABATI LESTARI
C2: Pabrik Minyak Goreng ( PMG 2 )
C3: Kantor Pusat: Komp. KEK Sei Mangkei, Kav.2-3, Kec. Bosar Maligas, Kab. Simalungun, Sumatera Utara, 21184
C4: ACTUAL PEFORMANCE / CONSUMPT REPORT FRAKSINASI PLANT | H4: Trial | I4: 1
H5: Start / Date / Time | I5: 17/12/24 ( 07.00 Wib )
H6: Finish / Date / Time | I6: 17/12/24 ( 07.00 Wib )
A8: No | B8: ITEM | C8: Kontrak LIPICO | D8: UOM | E8: TOTALIZER
A10: 1 | B10: PRODUCTION | C10: IV 56 | D10: 24 jam | E10: BEFORE | F10: AFTER | G10: TOTAL | H10: YIELD % | I10: STATUS/REMAKS
B11: Fraksinasi
B12: Running Days
B13: Incoming CPO
B14: Ratio Run CPO
B15: RBDPO Consume Total | C15: 2500 | D15: TPD | E15: 8982.8 | F15: 11717.8 | G15: =F15-E15 -> 2735 | H15: =G15/25000*10 -> 1.094 | I15: OK
B16: Avg Daily Consump CPO ( MTD )
B17: CPO Consume Poram | C17: 29045000
B18: CPO Consume Brand | C18: 7314000 | E18: =E49+E58+E63 -> 0
B19: QUALITY
B20: - FFA | C20: 0.1 | D20: % Max | H20: 0.063
B21: - Moist & Impurities | C21: 0.1 | D21: % Max | H21: 0.05
B22: - IV | C22: 52 - 52,5 | H22: 51.8
B23: - LC | H23: 2,6/20
B24: - Temp | C24: 68 | D24: ˚C Min | H24: 65
B25: TANK | H25: 108/109
B26: Product
B27: OLEIN IV 56 | C27: =C15*84% -> 2100 | D27: TPD | E27: 6537.1 | F27: 8213 | G27: =F27-E27 -> 1675.9 | H27: =G27/(G27+G32) -> 0.82838219 | I27: OK
B28: QUALITY
B29: - IV | C29: 56 | D29: Min
B30: - LC
B31: - Cloud Point ( metter ) | C31: 10 | D31: ˚C Max
B32: STEARIN | C32: =C15*16% -> 400 | E32: 2268.1 | F32: 2615.3 | G32: =F32-E32 -> 347.2 | H32: =G32/(G32+G27) -> 0.17161781 | I32: OK
B33: Fractionation
B34: Running Days
B35: Filling Langsung CR Fr Refinery | E35: 0
B36: Total Filling Crystalizer ( Feed ) | E36: 392100
B37: Avg Daily Consump RPO ( MTD )
B38: Total Proses RBDPO | E38: =SUM(E41,E45,E50,E54,E64) -> 0
B39: Sisa Filling Crystalizer | E39: =E36-E38 -> 392100
B40: Fractionation OLEIN IV 56
B41: RBDPO Consume | E41: =E42+E43 -> 0
B42: OLEIN IV 56 | E42: 0
...

Sheet Peformance Test REFINERY 1
C1: PT.INDUSTRI NABATI LESTARI
C2: Pabrik Minyak Goreng ( PMG 2 )
C3: Kantor Pusat: Komp. KEK Sei Mangkei, Kav.2-3, Kec. Bosar Maligas, Kab. Simalungun, Sumatera Utara, 21184
C4: ACTUAL PEFORMANCE / CONSUMPT REPORT REFINERY PLANT | H4: Peformance | I4: 1
H5: Start / Date / Time | I5: 17/12/24 ( 21.00 Wib )
H6: Finish / Date / Time | I6: 18/12/24 ( 21.00 Wib )
A7: No | B7: ITEM | C7: Kontrak LIPICO | D7: UOM | E7: TOTALIZER
A9: 1 | B9: PRODUCTION | E9: BEFORE | F9: AFTER | G9: TOTAL | H9: Yield ( % ) | I9: STATUS/REMAKS
B10: Refinery
B11: Running Days
B12: Incoming CPO
B13: Ratio Run CPO
B14: CPO Consume Total | C14: 2500 | D14: TPD | E14: 13533.82 | F14: 16053.42 | G14: =F14-E14 -> 2519.6 | I14: OK
B15: Avg Daily Consump CPO ( MTD )
B16: CPO Consume Poram | C16: 29045000
B17: CPO Consume Brand | C17: 7314000 | E17: =E53+E62+E67 -> 0
B18: - FFA | C18: 5 | D18: % | G18: 4
B19: - Moist & Impurities | C19: 0.5 | D19: % | G19: 0.41
B20: - DOBI | C20: 2.2 | D20: Min | G20: 2.42
B21: - TOTOX 2PV + AV | C21: 12 | D21: Max | G21: N/A
B22: - FE Content | C22: < 5 | D22: ppm | G22: N/A
B23: - PV | C23: < 4 | D23: Meg/kg | G23: N/A
B24: - Phosporus Max | C24: 25 | D24: ppm | G24: N/A
B25: TANK / TEMP | C25: 50 | D25: ˚C | G25: 50
B26: Product
B27: RBDPO | C27: =C14*94.2% -> 2355 | D27: TPD | E27: 12357.54 | F27: 14705.95 | G27: =F27-E27 -> 2348.41 | H27: =G27/G14 -> 0.93205668
B28: - FFA | C28: 0.05 | D28: % | G28: 0.06
B29: - Moist & Impurities | C29: 0.03 | D29: % | G29: 0.05
B30: - Peroxide value | D30: Nil | G30: -
B31: - Phosporous max | C31: 2 | D31: ppm | G31: N/A
B32: - LC | C32: 2.5 | D32: % | G32: 2.5
B33: - Aom stability min ( hr ) | C33: 60 | D33: min ( hr ) | G33: N/A
B34: - teste & Odor | C34: bland/Odorless | G34: N/A
B35: - temp max ( C ) | C35: 50 | D35: max˚C | G35: 50
B36: PFAD | C36: =C14*5% -> 125 | D36: TPD | E36: 572.71 | F36: 675.39 | G36: =F36-E36 -> 102.68 | H36: =G36/G14 -> 0.0407525
B37: Fractionation
B38: Running Days
B39: Filling Langsung CR Fr Refinery | E39: 0
B40: Total Filling Crystalizer ( Feed ) | E40: 392100
B41: Avg Daily Consump RPO ( MTD )
...

Sheet peformance  test REFINERY 2
A1: REFINERY PMG 2
A2: No | B2: ITEM | C2: Norma LIPICO | D2: UOM | E2: Day 2 tanggal 12/12/2024
A4: 1 | B4: PRODUCTION | E4: BEFORE | F4: AFTER | G4: TOTAL | H4: Yield ( % )
B5: Refinery
B6: Running Days
B7: Incoming CPO
B8: Ratio Run CPO
B9: CPO Consume Total | C9: 2500 | D9: TPD | E9: 5880.74 | F9: 8383.74 | G9: =F9-E9 -> 2503 | H9: =G9/2500000*100000 -> 100.12
B10: Avg Daily Consump CPO ( MTD )
B11: CPO Consume Poram | C11: 29045000
B12: CPO Consume Brand | C12: 7314000 | E12: =E43+E52+E57 -> 0
B13: - FFA | C13: 5 | D13: % | G13: 3.97
B14: - Moist & Impurities | C14: 0.5 | D14: % | G14: 0.4
B15: - DOBI | C15: 2.2 | D15: Min | G15: 2.42
B16: TANK | G16: 105
B17: Product
B18: OIP RBDPO
B19: RBDPO | C19: =C9*94.2% -> 2355 | D19: TPD | E19: 5143.38 | F19: 7493.18 | G19: =F19-E19 -> 2349.8 | H19: =G19/G9*100 -> 93.879345
B20: - FFA | C20: 0.05 | D20: % | G20: 0.043
B21: - Moist & Impurities | C21: 0.03 | D21: % | G21: 0.04
B22: - LC | C22: 2.5 | D22: % | G22: 2.5
B23: - Aom stability min ( hr ) | C23: 60 | D23: min ( hr )
B24: - teste & Odor | C24: bland/Odorless
B25: - temp max ( C ) | C25: 50 | D25: max˚C
B26: PFAD | C26: =C9*5% -> 125 | D26: TPD | E26: 243.04 | F26: 347.1 | G26: =F26-E26 -> 104.06 | H26: =G26/G9*100 -> 4.1574111
B27: Fractionation
B28: Running Days
B29: Filling Langsung CR Fr Refinery | E29: 0
B30: Total Filling Crystalizer ( Feed ) | E30: 392100
B31: Avg Daily Consump RPO ( MTD )
B32: Total Proses RBDPO | E32: =SUM(E35,E39,E44,E48,E58) -> 0
B33: Sisa Filling Crystalizer | E33: =E30-E32 -> 392100
B34: Fractionation OLEIN IV 56
B35: RBDPO Consume | E35: =E36+E37 -> 0
B36: OLEIN IV 56 | E36: 0
B37: STEARIN | E37: 0
B38: Fractionation OLEIN IV 57 ( Bulk )
B39: RBDPO Consume | E39: =E40+E41 -> 0
B40: OLEIN IV 57 | E40: 0
B41: STEARIN | E41: 0
...

Sheet HPP REF 
B2: Refinery Cost
B3: Through Put CPO Proses | N3: =('JUNI 2025'!AL10)/1000 -> 1781.3187 | O3: TPD
B4: Working Day | N4: ='JUNI 2025'!AL6 -> 10 | O4: Days
B5: Total CPO Process | N5: =N4*N3 -> 17813.187 | O5: MTD
B6: KURS | N6: 16000 | O6: Rp/USD
B7: No | C7: Item Cost | D7: Norma | F7: Pemakaian / Hari | H7: HK | J7: Total Pemakaian | K7: Harga / stn | M7: Total Biaya | N7: Rp / kg | O7: USD/MT
B8: 1 | C8: Bleaching Earth | D8: ='JUNI 2025'!$AL$76 -> 8.5932405 | F8: =($D$8*$N$3*10) -> 153073 | G8: Kg/day | H8: =$N$4 -> 10 | J8: =$H$8*$F$8 -> 1530730 | K8: 2400 | M8: =$J$8*$K$8 -> 3673752000 | N8: =$M$8/($N$5*1000) -> 206.23777 | O8: =($M$8/$N$6)/$N$5 -> 12.889861
B9: 2 | C9: Phosporic acid | D9: ='JUNI 2025'!$AL$84 -> 0.49363654 | F9: =($D$9*$N$3*10) -> 8793.24 | G9: Kg/day | H9: =$H$8 -> 10 | J9: =$H$9*$F$9 -> 87932.4 | K9: 17420 | M9: =$J$9*$K$9 -> 1531782408 | N9: =$M$9/($N$5*1000) -> 85.991485 | O9: =($M$9/$N$6)/$N$5 -> 5.3744678
B10: 3 | C10: Caustic Soda | D10: 29.166667 | E10: kg/day | F10: =D10 -> 29.166667 | G10: kg/day | H10: =$H$8 -> 10 | J10: =$H$10*$F$10 -> 291.66667 | K10: 15700 | M10: =$J$10*$K$10 -> 4579166.7 | N10: =$M$10/($N$5*1000) -> 0.25706611 | O10: =($M$10/$N$6)/$N$5 -> 0.016066632
B11: 4 | C11: Pemakaian Natural Gas HPB Geka
C12: Normal Consumption | D12: ='JUNI 2025'!$AL$244 -> 2032.2784 | E12: MMBTU/MT CPO | F12: =$D$12*$N$3 -> 3620135.4 | G12: MMBTU/day | H12: =$H$8 -> 10 | J12: =$H$12*$F$12 -> 36201354 | K12: =11.5*$N$6 -> 184000 | M12: =$J$12*$K$12 -> 6.6610492e+12 | N12: =$M$12/($N$5*1000) -> 373939.22 | O12: =($M$12/$N$6)/$N$5 -> 23371.201
C13: Penalty Below Consumption | D13: 0 | E13: MMBTU/MT CPO | F13: =$D$13*$N$3 -> 0 | G13: MMBTU/day | H13: =$H$8 -> 10 | J13: =$H$13*$F$13 -> 0 | K13: =11.5*$N$6 -> 184000 | M13: =$J$13*$K$13 -> 0 | N13: =$M$13/($N$5*1000) -> 0 | O13: =($M$13/$N$6)/$N$5 -> 0
C14: Penalty Above Consumption | D14: 0 | E14: MMBTU/MT CPO | F14: =$D$14*$N$3 -> 0 | G14: MMBTU/day | H14: =$H$8 -> 10 | J14: =$H$14*$F$14 -> 0 | K14: =11.5*$N$6 -> 184000 | M14: =$J$14*$K$14 -> 0 | N14: =$M$14/($N$5*1000) -> 0 | O14: =($M$14/$N$6)/$N$5 -> 0
B15: 5 | C15: Pemakaian Steam
C16: For Process | D16: ='JUNI 2025'!AL251 -> 790.67 | E16: Kg/MT CPO | F16: =$D$16*$N$3/1000 -> 1408.4353 | G16: Ton/day | H16: =$H$8 -> 10 | J16: =$H$16*$F$16 -> 14084.353 | K16: =Steam!H15 -> 529847.07 | M16: =$J$16*$K$16 -> 7.462553e+09 | N16: =$M$16/($N$5*1000) -> 418.93418 | O16: =($M$16/$N$6)/$N$5 -> 26.183387
C17: Storage Tank for Heating | D17: ='JUNI 2025'!$AL$255 -> 602.373 | E17: Kg/MT CPO | F17: =$D$17*$N$3/1000 -> 1073.0183 | G17: Ton/day | H17: =$H$8 -> 10 | J17: =$H$17*$F$17 -> 10730.183 | K17: =Steam!H15 -> 529847.07 | M17: =$J$17*$K$17 -> 5.685356e+09 | N17: =$M$17/($N$5*1000) -> 319.16557 | O17: =($M$17/$N$6)/$N$5 -> 19.947848
B18: 6 | C18: Pemakaian Electrical
C19: For Process | D19: ='JUNI 2025'!$AL$274 -> 135763 | E19: kW/MT CPO | F19: =$D$19*$N$3 -> 2.4183717e+08 | G19: kW/day | H19: =$H$8 -> 10 | I19: 0 | J19: =$H$19*$F$19 -> 2.4183717e+09 | K19: 1550 | L19: =[5]Electric!H21 -> 3666.6667 | M19: =($F$19*$H$19*$K$19)+($F$19*$I$19*$L$19) -> 3.7484761e+12 | N19: =$M$19/($N$5*1000) -> 210432.65 | O19: =($M$19/$N$6)/$N$5 -> 13152.041
C20: Cooling Tower | D20: ='JUNI 2025'!$AL$276 -> 99647.5 | E20: kW/MT CPO | F20: =$D$20*$N$3 -> 1.7750396e+08 | G20: kW/day | H20: =$H$8 -> 10 | I20: 0 | J20: =$H$20*$F$20 -> 1.7750396e+09 | K20: 1550 | L20: =L19 -> 3666.6667 | M20: =(F20*H20*K20)+(F20*I20*L20) -> 2.7513113e+12 | N20: =$M$20/($N$5*1000) -> 154453.62 | O20: =($M$20/$N$6)/$N$5 -> 9653.3516
C21: Storage Tank | D21: 0.3377877 | E21: kW/MT CPO | F21: =$D$21*$N$3 -> 601.70754 | G21: kW/day | H21: =$H$8 -> 10 | I21: 0 | J21: =$H$21*$F$21 -> 6017.0754 | K21: 1550 | L21: =L20 -> 3666.6667 | M21: =($F$21*$H$21*$K$21)+($F$21*$I$21*$L$21) -> 9326466.9 | N21: =$M$21/($N$5*1000) -> 0.52357093 | O21: =($M$21/$N$6)/$N$5 -> 0.032723183
B22: 7 | C22: Pemakaian Water
C23: Make Up CT | D23: ='JUNI 2025'!$AL$261 -> 1279 | E23: M3/day | F23: =$D$23 -> 1279 | G23: M3/day | H23: =$H$8 -> 10 | J23: =$H$23*$F$23 -> 12790 | K23: =WTP!H13 -> #VALUE! | M23: =$J$23*$K$23 -> #VALUE! | N23: =$M$23/($N$5*1000) -> #VALUE! | O23: =($M$23/$N$6)/$N$5 -> #VALUE!
B24: 8 | C24: Chemical Water | N24: =$M$24/($N$5*1000) -> 0 | O24: =($M$24/$N$6)/$N$5 -> 0
C25: EONBAC BC 3108 | D25: 0.4 | E25: Kg/day | F25: =D25 -> 0.4 | G25: Kg/day | H25: =$H$8 -> 10 | J25: =$H$25*$F$25 -> 4 | K25: 27240 | M25: =$J$25*$K$25 -> 108960 | N25: =$M$25/($N$5*1000) -> 0.0061168167 | O25: =($M$25/$N$6)/$N$5 -> 0.00038230104
C26: EONLINE T722 | D26: 0.66 | E26: Kg/day | F26: =D26 -> 0.66 | G26: Kg/day | H26: =$H$8 -> 10 | J26: =$H$26*$F$26 -> 6.6 | K26: 29120 | M26: =$J$26*$K$26 -> 192192 | N26: =$M$26/($N$5*1000) -> 0.01078931 | O26: =($M$26/$N$6)/$N$5 -> 0.00067433189
C27: EONLINE AG5770 | D27: 0.41 | E27: Kg/day | F27: =D27 -> 0.41 | G27: Kg/day | H27: =$H$8 -> 10 | J27: =$H$27*$F$27 -> 4.1 | K27: 117212 | M27: =$J$27*$K$27 -> 480569.2 | N27: =$M$27/($N$5*1000) -> 0.026978283 | O27: =($M$27/$N$6)/$N$5 -> 0.0016861427
C28: EONScale T2511 | D28: 0.1 | E28: Kg/day | F28: =D28 -> 0.1 | G28: Kg/day | H28: =$H$8 -> 10 | J28: =$H$28*$F$28 -> 1 | K28: 45940 | M28: =$J$28*$K$28 -> 45940 | N28: =$M$28/($N$5*1000) -> 0.0025789883 | O28: =($M$28/$N$6)/$N$5 -> 0.00016118677
B29: 9 | C29: Others
C30: Filter Bag 10 Microne | D30: 0.90361446 | E30: Pcs/day | F30: =D30 -> 0.90361446 | G30: Pcs/day | H30: =$H$8 -> 10 | J30: =$H$30*$F$30 -> 9.0361446 | K30: 40000 | M30: =$J$30*$K$30 -> 361445.78 | N30: =$M$30/($N$5*1000) -> 0.02029091 | O30: =($M$30/$N$6)/$N$5 -> 0.0012681819
C31: Filter Bag 100 Microne | D31: 0.63253012 | E31: Pcs/day | F31: =D31 -> 0.63253012 | G31: Pcs/day | H31: =$H$8 -> 10 | J31: =$H$31*$F$31 -> 6.3253012 | K31: 125000 | M31: =$J$31*$K$31 -> 790662.65 | N31: =$M$31/($N$5*1000) -> 0.044386367 | O31: =($M$31/$N$6)/$N$5 -> 0.0027741479
C32: Filter Cartridge 10 Microne | D32: 1.5666667 | E32: Pcs/day | F32: =D32 -> 1.5666667 | G32: Pcs/day | H32: =$H$8 -> 10 | J32: =$H$32*$F$32 -> 15.666667 | K32: 145000 | M32: =$J$32*$K$32 -> 2271666.7 | N32: =$M$32/($N$5*1000) -> 0.12752725 | O32: =($M$32/$N$6)/$N$5 -> 0.0079704528
C33: Filter Dustbag | D33: 0.12048193 | E33: Pcs/day | F33: =D33 -> 0.12048193 | G33: Pcs/day | H33: =$H$8 -> 10 | J33: =$H$33*$F$33 -> 1.2048193 | K33: 682500 | M33: =$J$33*$K$33 -> 822289.16 | N33: =$M$33/($N$5*1000) -> 0.046161821 | O33: =($M$33/$N$6)/$N$5 -> 0.0028851138
C34: O Ring Filter Leaves | D34: 3.6144578 | E34: Pcs/day | F34: =D34 -> 3.6144578 | G34: Pcs/day | H34: =$H$8 -> 10 | J34: =$H$34*$F$34 -> 36.144578 | K34: 14500 | M34: =$J$34*$K$34 -> 524096.39 | N34: =$M$34/($N$5*1000) -> 0.02942182 | O34: =($M$34/$N$6)/$N$5 -> 0.0018388638
B35: 10 | C35: Waste Water Treatment Plant ( WWTP ) | D35: ='JUNI 2025'!$AL$267 -> 1219 | E35: M3/day | F35: =D35 -> 1219 | G35: M3/day | H35: =$H$8 -> 10 | J35: =$H$35*$F$35 -> 12190 | K35: =WWTP!H17 -> 3464.8428 | M35: =$J$35*$K$35 -> 42236434 | N35: =$M$35/($N$5*1000) -> 2.3710768 | O35: =($M$35/$N$6)/$N$5 -> 0.1481923
B36: 11 | C36: SHE
C37: SBE | D37: ='JUNI 2025'!$AL$88 -> 156289.68 | E37: Kg/day | F37: =D37 -> 156289.68 | G37: Kg/day | H37: =$H$8 -> 10 | J37: =$F$37 -> 156289.68 | K37: 0 | M37: =$J$37*$K$37 -> 0 | N37: =$M$37/($N$5*1000) -> 0 | O37: =($M$37/$N$6)/$N$5 -> 0
C38: Domestic | D38: 0.1 | E38: Trip/day | F38: =D38 -> 0.1 | G38: Trip/day | H38: =$H$8 -> 10 | J38: =$H$38*$F$38 -> 1 | K38: 303030.3 | M38: =$J$38*$K$38 -> 303030.3 | N38: =$M$38/($N$5*1000) -> 0.017011571 | O38: =($M$38/$N$6)/$N$5 -> 0.0010632232
B39: 12 | C39: Chemical Consumption | N39: =$M$39/($N$5*1000) -> 0 | O39: =($M$39/$N$6)/$N$5 -> 0
C40: LAB Chemical | D40: =lab!H33 -> 745255.21 | E40: Rp/day | F40: =D40 -> 745255.21 | G40: Rp/day | H40: =$H$8 -> 10 | M40: =$H$40*$F$40 -> 7452552.1 | N40: =$M$40/($N$5*1000) -> 0.41837275 | O40: =($M$40/$N$6)/$N$5 -> 0.026148297
C41: Chemical Boiler dan WTP | D41: =lab!H54 -> 259161.44 | E41: Rp/day | F41: =D41 -> 259161.44 | G41: Rp/day | H41: =$H$8 -> 10 | M41: =$H$41*$F$41 -> 2591614.4 | N41: =$M$41/($N$5*1000) -> 0.14548853 | O41: =($M$41/$N$6)/$N$5 -> 0.0090930333
...

Sheet HPP FRACT
B2: Fractionation Cost
B3: RPO Proses / Day | N3: TPD | O3: ='JUNI 2025'!AL24/1000 -> 1779.2607
B4: Working Day | N4: Days | O4: ='JUNI 2025'!AL23 -> 10
B5: Total CPO Process | N5: MTD | O5: =O3*O4 -> 17792.607
B6: KURS | N6: Rp/USD | O6: 16000
B7: No | C7: Item Cost | D7: Norma | F7: Pemakaian / Hari | H7: HK | J7: Total Pemakaian | K7: Harga / stn | M7: Total Biaya | N7: Rp / kg | O7: USD/MT
B8: 1 | C8: Steam | D8: ='JUNI 2025'!AL253 -> 425.736 | E8: Kg/MT CPO | F8: =$D$8*$O$3/1000 -> 757.49533 | G8: Ton/day | H8: =$O$4 -> 10 | J8: =$H$8*$F$8 -> 7574.9533 | K8: =Steam!H15 -> 529847.07 | M8: =$K$8*$J$8 -> 4.0135668e+09 | N8: =$M$8/($O$5*1000) -> 225.57497 | O8: =($M$8/$O$6)/$O$5 -> 14.098436
B9: 2 | C9: Electrical
C10: For Process | D10: ='JUNI 2025'!$AL$281 -> 82129.1 | E10: kW/MT CPO | F10: =$D$10*$O$3 -> 1.4612908e+08 | G10: kW/day | H10: =$O$4 -> 10 | I10: 0 | J10: =$H$10*$F$10 -> 1.4612908e+09 | K10: =[5]Electric!$L$5 -> 1550 | L10: 3666.6667 | M10: =($F$10*$H$10*$K$10)+($F$10*$I$10*$L$10) -> 2.2650007e+12 | N10: =$M$10/($O$5*1000) -> 127300.11 | O10: =($M$10/$O$6)/$O$5 -> 7956.2566
C11: Cooling Tower | D11: ='JUNI 2025'!$AL$279 -> 150240 | E11: kW/MT CPO | F11: =$D$11*$O$3 -> 2.6731613e+08 | G11: kW/day | H11: =$H$10 -> 10 | I11: 0 | J11: =$H$11*$F$11 -> 2.6731613e+09 | K11: =$K$10 -> 1550 | L11: 3666.6667 | M11: =($F$11*$H$11*$K$11)+($F$11*$I$11*$L$11) -> 4.1434e+12 | N11: =$M$11/($O$5*1000) -> 232872 | O11: =($M$11/$O$6)/$O$5 -> 14554.5
B12: 3 | C12: Water
C13: Make Up CT | D13: ='JUNI 2025'!$AL$263 -> 950 | E13: M3/day | F13: =$D$13 -> 950 | G13: M3/day | H13: =$H$11 -> 10 | J13: =$H$13*$F$13 -> 9500 | K13: =WTP!H13 -> #VALUE! | M13: =$K$13*$J$13 -> #VALUE! | N13: =$M$13/($O$5*1000) -> #VALUE! | O13: =($M$13/$O$6)/$O$5 -> #VALUE!
B14: 4 | C14: Chemical Water
C15: EONBAC BC 3108 | D15: 0.4 | E15: Kg/day | F15: =$D$15 -> 0.4 | G15: Kg/day | H15: =$H$13 -> 10 | J15: =$H$15*$F$15 -> 4 | K15: 27240 | M15: =$K$15*$J$15 -> 108960 | N15: =$M$15/($O$5*1000) -> 0.0061238918 | O15: =($M$15/$O$6)/$O$5 -> 0.00038274324
C16: EONLINE T722 | D16: 0.66 | E16: Kg/day | F16: =$D$16 -> 0.66 | G16: Kg/day | H16: =$H$15 -> 10 | J16: =$H$16*$F$16 -> 6.6 | K16: 29120 | M16: =$K$16*$J$16 -> 192192 | N16: =$M$16/($O$5*1000) -> 0.01080179 | O16: =($M$16/$O$6)/$O$5 -> 0.00067511186
C17: EONLINE AG5770 | D17: 0.41 | E17: Kg/day | F17: =$D$17 -> 0.41 | G17: Kg/day | H17: =$H$15 -> 10 | J17: =$H$17*$F$17 -> 4.1 | K17: 117212 | M17: =$K$17*$J$17 -> 480569.2 | N17: =$M$17/($O$5*1000) -> 0.027009488 | O17: =($M$17/$O$6)/$O$5 -> 0.001688093
C18: EONScale T2511 | D18: 0.1 | E18: Kg/day | F18: =$D$18 -> 0.1 | G18: Kg/day | H18: =$H$16 -> 10 | J18: =$H$18*$F$18 -> 1 | K18: 45940 | M18: =$K$18*$J$18 -> 45940 | N18: =$M$18/($O$5*1000) -> 0.0025819713 | O18: =($M$18/$O$6)/$O$5 -> 0.0001613732
B19: 5 | C19: Others
C20: Filter Cloth | D20: 0.33333333 | E20: Pcs/day | F20: =$D$20 -> 0.33333333 | G20: Pcs/day | H20: =$H$18 -> 10 | J20: =$H$20*$F$20 -> 3.3333333 | K20: 895000 | M20: =$K$20*$J$20 -> 2983333.3 | N20: =$M$20/($O$5*1000) -> 0.16767264 | O20: =($M$20/$O$6)/$O$5 -> 0.01047954
C21: Filter Bag 100 Microne | D21: 0.63253012 | E21: Pcs/day | F21: =$D$21 -> 0.63253012 | G21: Pcs/day | H21: =$H$20 -> 10 | J21: =$H$21*$F$21 -> 6.3253012 | K21: 125000 | M21: =$K$21*$J$21 -> 790662.65 | N21: =$M$21/($O$5*1000) -> 0.044437707 | O21: =($M$21/$O$6)/$O$5 -> 0.0027773567
M22: =SUM(M8:M21) -> #VALUE! | N22: =SUM(N8:N21) -> #VALUE! | O22: =SUM($O$8:$O$21) -> #VALUE!

Sheet SUMMARY HPP 
B2: Production Cost MARET 2025
B3: Through Put CPO Proses (Ton/Day) | H3: TPD | I3: ='HPP REF '!$N$3 -> 1781.3187
B4: Working Day | F4: 1 | H4: Days | I4: ='HPP REF '!$N$4 -> 10
B5: Refined CPO ( Ton/month ) | H5: MTD | I5: =$I$4*$I$3 -> 17813.187
B6: Through Put RPO Proses (Ton/Day) | H6: TPD | I6: ='HPP FRACT'!$O$3 -> 1779.2607
B7: Working Day | H7: Days | I7: ='HPP FRACT'!$O$4 -> 10
B8: Fract RPO ( ton/month ) | H8: MTD | I8: =$I$7*$I$6 -> 17792.607
B9: KURS | H9: Rp/USD | I9: 16000
B10: No | C10: Items | D10: Description | G10: Rupiah | H10: Rp/Kg | I10: USD/MT
B11: I | C11: Production Cost | D11: ● | E11: Refining Cost | G11: ='HPP REF '!$M$48 -> #VALUE! | H11: =$G$11/($I$5*1000) -> #VALUE! | I11: =(G11/$I$9)/$I$5 -> #VALUE!
D12: ● | E12: Fractionation Cost | G12: ='HPP FRACT'!$M$22 -> #VALUE! | H12: =$G$12/($I$8*1000) -> #VALUE! | I12: =(G12/$I$9)/$I$8 -> #VALUE!
D13: ● | E13: Preventive Maintenance Cost | F13: 0 | G13: =MTC!$F$18*F13 -> 0 | H13: =$G$13/($I$5*1000) -> 0 | I13: =(G13/$I$9)/$I$5 -> 0
G14: =SUM(G11:$G$13) -> #VALUE! | H14: =SUM($H$11:$H$13) -> #VALUE! | I14: =SUM(I11:I13) -> #VALUE! | K14: =I14+I26 -> #VALUE!
B16: II | C16: Port Cost | D16: ● | E16: Trucking Komoditi ke Kuala Tanjung | G16: =LOG!I8+LOG!I9+LOG!$I$10 -> 1.8494363e+09 | H16: =$G$16/($I$5*1000) -> 103.824 | I16: =($G$16/$I$9)/$I$5 -> 6.489
D17: ● | E17: Sewa Tank PTI Total Volume : 24.000 MT ( 5 Unit ) | F17: =F4 -> 1 | G17: =LOG!I11+LOG!I12+LOG!I13+LOG!$I$14*F17 -> 1886000000 | H17: =$G$17/($I$5*1000) -> 105.87662 | I17: =($G$17/$I$9)/$I$5 -> 6.6172886
D18: ● | E18: Instalasi & Pemanasan, Pompa, Surveyor dan Documen | G18: =LOG!I18+LOG!I19+LOG!I20+LOG!$I$21 -> 9.542168e+08 | H18: =$G$18/($I$5*1000) -> 53.568 | I18: =($G$18/$I$9)/$I$5 -> 3.348
D19: ● | E19: Finalty Over Capacity Tank | G19: =LOG!I15+LOG!I16+LOG!$I$17 -> 7.598393e+08 | H19: =$G$19/($I$5*1000) -> 42.656 | I19: =($G$19/$I$9)/$I$5 -> 2.666
G20: =SUM($G$16:$G$19) -> 5.4494924e+09 | H20: =SUM($H$16:$H$19) -> 305.92462 | I20: =SUM($I$16:$I$19) -> 19.120289
B22: II | C22: Fix Cost | D22: ● | E22: Manpower Cost | F22: =F4 -> 1 | G22: =[5]MPC!$H$29*$F$22 -> 2.1846655e+09 | H22: =$G$22/($I$5*1000) -> 122.64316 | I22: =($G$22/$I$9)/$I$5 -> 7.6651975
D23: ● | E23: Admin OH Cost | F23: =F4 -> 1 | G23: =OH!G51*$F$23 -> 1.4360564e+09 | H23: =$G$23/($I$5*1000) -> 80.6176 | I23: =($G$23/$I$9)/$I$5 -> 5.0386
D24: ● | E24: Depresiasi Cost | F24: =F4 -> 1 | G24: =DEP!I9*$F$24 -> 4.1811848e+09 | H24: =$G$24/($I$5*1000) -> 234.72413 | I24: =($G$24/$I$9)/$I$5 -> 14.670258
D25: ● | E25: Amortisation of leasehold land Cost | F25: =F4 -> 1 | G25: =AMOR!$G$20*$F$25 -> 1.0484098e+09 | H25: =$G$25/($I$5*1000) -> 58.855824 | I25: =($G$25/$I$9)/$I$5 -> 3.678489
G26: =SUM($G$22:$G$25) -> 8.8503165e+09 | H26: =SUM($H$22:$H$25) -> 496.84071 | I26: =SUM($I$22:$I$25) -> 31.052545 | K26: =I26+I14 -> #VALUE!
B28: Total Production Cost | G28: =$G$26+$G$20+$G$14 -> #VALUE! | H28: =$H$26+$H$20+$H$14 -> #VALUE! | I28: =$I$26+$I$20+$I$14 -> #VALUE!

Sheet Convert Gas
B3: CONVERT PEMAKAIAN GAS HP BOILER & MP BOILER
D4: 2024
C5: HP BOILER | F5: TOTAL CORRECTED VOLUME (Sm3) | K5: ENERGY MP BOILER (MMBTU) | L5: TOTAL GAS CONSUMPTION (MMBTU) | M5: PERCENTAGE
C6: UNCORRECTED VOLUME (UV) (Nm3) | D6: PRESS. Bar | E6: CORRECTED VOLUME (CV) (Sm3) | G6: Convert Sm3 to SCF | H6: VOLUME (MSCF) | I6: HEATING VALUE (BTU / SCF) | J6: ENERGY HP BOILER (MMBTU) | M6: HP Boiler | N6: MP Boiler
C7: 1 | D7: 2 | E7: 3 = 1 x 2 | F7: 4 = 3 | G7: 5 | H7: 6 = (4 x 5) / 1000 | I7: 7 | J7: 8 = (6 x 7) / 1000 | K7: 9 = 10 - 8 | L7: 10 | M7: 11 = 8 / 10 | N7: 12 = 9 / 10
B8: 1 | D8: 5 | E8: =C8*D8 -> 0 | F8: =E8 -> 0 | G8: 35.314667 | H8: =(F8*G8)/1000 -> 0 | I8: 1047.7934 | J8: =(H8*I8)/1000 -> 0 | K8: =L8-J8 -> 0 | L8: 0 | M8: =(J8/L8) -> #DIV/0! | N8: =K8/L8 -> #DIV/0!
B9: =B8+1 -> 2 | D9: 5 | E9: =C9*D9 -> 0 | F9: =E9 -> 0 | G9: 35.314667 | H9: =(F9*G9)/1000 -> 0 | I9: 1042.7042 | J9: =(H9*I9)/1000 -> 0 | K9: =L9-J9 -> 0.7969 | L9: 0.7969 | M9: =(J9/L9) -> 0 | N9: =K9/L9 -> 1
B10: =B9+1 -> 3 | C10: 159.69 | D10: 5 | E10: =C10*D10 -> 798.45 | F10: =E10 -> 798.45 | G10: 35.314667 | H10: =(F10*G10)/1000 -> 28.196996 | I10: 1044.8302 | J10: =(H10*I10)/1000 -> 29.461073 | K10: =L10-J10 -> 656.37333 | L10: 685.8344 | M10: =(J10/L10) -> 0.04295654 | N10: =K10/L10 -> 0.95704346
B11: =B10+1 -> 4 | C11: 788.24 | D11: 5 | E11: =C11*D11 -> 3941.2 | F11: =E11 -> 3941.2 | G11: 35.314667 | H11: =(F11*G11)/1000 -> 139.18217 | I11: 1050.3635 | J11: =(H11*I11)/1000 -> 146.19187 | K11: =L11-J11 -> 696.04741 | L11: 842.23928 | M11: =(J11/L11) -> 0.17357522 | N11: =K11/L11 -> 0.82642478
B12: =B11+1 -> 5 | C12: 3.33 | D12: 5 | E12: =C12*D12 -> 16.65 | F12: =E12 -> 16.65 | G12: 35.314667 | H12: =(F12*G12)/1000 -> 0.58798921 | I12: 1050.6498 | J12: =(H12*I12)/1000 -> 0.61777073 | K12: =L12-J12 -> 767.54333 | L12: 768.1611 | M12: =(J12/L12) -> 0.00080422027 | N12: =K12/L12 -> 0.99919578
B13: =B12+1 -> 6 | C13: 1356.95 | D13: 5 | E13: =C13*D13 -> 6784.75 | F13: =E13 -> 6784.75 | G13: 35.314667 | H13: =(F13*G13)/1000 -> 239.60119 | I13: 1051.3912 | J13: =(H13*I13)/1000 -> 251.91459 | K13: =L13-J13 -> 389.14956 | L13: 641.06415 | M13: =(J13/L13) -> 0.39296315 | N13: =K13/L13 -> 0.60703685
B14: =B13+1 -> 7 | C14: 4051.52 | D14: 5 | E14: =C14*D14 -> 20257.6 | F14: =E14 -> 20257.6 | G14: 35.314667 | H14: =(F14*G14)/1000 -> 715.3904 | I14: 1053.7683 | J14: =(H14*I14)/1000 -> 753.85573 | K14: =L14-J14 -> 105.66983 | L14: 859.52556 | M14: =(J14/L14) -> 0.87706028 | N14: =K14/L14 -> 0.12293972
B15: =B14+1 -> 8 | C15: 5815.62 | D15: 5 | E15: =C15*D15 -> 29078.1 | F15: =E15 -> 29078.1 | G15: 35.314667 | H15: =(F15*G15)/1000 -> 1026.8834 | I15: 1055.9121 | J15: =(H15*I15)/1000 -> 1084.2986 | K15: =L15-J15 -> -55.066247 | L15: 1029.2324 | M15: =(J15/L15) -> 1.0535022 | N15: =K15/L15 -> -0.053502249
B16: =B15+1 -> 9 | C16: 5220.53 | D16: 5 | E16: =C16*D16 -> 26102.65 | F16: =E16 -> 26102.65 | G16: 35.314667 | H16: =(F16*G16)/1000 -> 921.80639 | I16: 1058.5967 | J16: =(H16*I16)/1000 -> 975.82117 | K16: =L16-J16 -> 139.90533 | L16: 1115.7265 | M16: =(J16/L16) -> 0.87460607 | N16: =K16/L16 -> 0.12539393
B17: =B16+1 -> 10 | C17: 2188 | D17: 5 | E17: =C17*D17 -> 10940 | F17: =E17 -> 10940 | G17: 35.314667 | H17: =(F17*G17)/1000 -> 386.34246 | I17: 1055.6055 | J17: =(H17*I17)/1000 -> 407.82521 | K17: =L17-J17 -> 551.84729 | L17: 959.6725 | M17: =(J17/L17) -> 0.4249629 | N17: =K17/L17 -> 0.5750371
B18: =B17+1 -> 11 | C18: 1796.49 | D18: 5 | E18: =C18*D18 -> 8982.45 | F18: =E18 -> 8982.45 | G18: 35.314667 | H18: =(F18*G18)/1000 -> 317.21223 | I18: 1056.3096 | J18: =(H18*I18)/1000 -> 335.07431 | K18: =L18-J18 -> 538.27709 | L18: 873.3514 | M18: =(J18/L18) -> 0.38366494 | N18: =K18/L18 -> 0.61633506
B19: =B18+1 -> 12 | C19: 4866.75 | D19: 5 | E19: =C19*D19 -> 24333.75 | F19: =E19 -> 24333.75 | G19: 35.314667 | H19: =(F19*G19)/1000 -> 859.33828 | I19: 1051.5483 | J19: =(H19*I19)/1000 -> 903.63574 | K19: =L19-J19 -> 6.6809602 | L19: 910.3167 | M19: =(J19/L19) -> 0.99266084 | N19: =K19/L19 -> 0.0073391603
B20: =B19+1 -> 13 | C20: 6932.28 | D20: 5 | E20: =C20*D20 -> 34661.4 | F20: =E20 -> 34661.4 | G20: 35.314667 | H20: =(F20*G20)/1000 -> 1224.0558 | I20: 1053.7374 | J20: =(H20*I20)/1000 -> 1289.8334 | K20: =L20-J20 -> -53.700699 | L20: 1236.1327 | M20: =(J20/L20) -> 1.0434425 | N20: =K20/L20 -> -0.043442504
B21: =B20+1 -> 14 | C21: 6338.15 | D21: 5 | E21: =C21*D21 -> 31690.75 | F21: =E21 -> 31690.75 | G21: 35.314667 | H21: =(F21*G21)/1000 -> 1119.1483 | I21: 1054.6459 | J21: =(H21*I21)/1000 -> 1180.3051 | K21: =L21-J21 -> -24.066515 | L21: 1156.2386 | M21: =(J21/L21) -> 1.0208145 | N21: =K21/L21 -> -0.020814488
... B24: =B23+1 -> 17 | C24: 6388.24 | D24: 5 | E24: =C24*D24 -> 31941.2 | F24: =E24 -> 31941.2 | G24: 38.314667 | H24: =(F24*G24)/1000 -> 1223.8164 | I24: 1041.3329 | J24: =(H24*I24)/1000 -> 1274.4003 | K24: =L24-J24 -> -125.496 | L24: 1148.9043 | M24: =(J24/L24) -> 1.109231 | N24: =K24/L24 -> -0.10923103
B25: =B24+1 -> 18 | C25: 7607.66 | D25: 5 | E25: =C25*D25 -> 38038.3 | F25: =E25 -> 38038.3 | G25: 39.314667 | H25: =(F25*G25)/1000 -> 1495.4631 | I25: 1042.2141 | J25: =(H25*I25)/1000 -> 1558.5927 | K25: =L25-J25 -> -1558.5927 | M25: =(J25/L25) -> #DIV/0! | N25: =K25/L25 -> #DIV/0!
B26: =B25+1 -> 19 | C26: 6514.97 | D26: 5 | E26: =C26*D26 -> 32574.85 | F26: =E26 -> 32574.85 | G26: 40.314667 | H26: =(F26*G26)/1000 -> 1313.2442 | I26: 1042.5071 | J26: =(H26*I26)/1000 -> 1369.0664 | K26: =L26-J26 -> -1369.0664 | M26: =(J26/L26) -> #DIV/0! | N26: =K26/L26 -> #DIV/0!
B27: =B26+1 -> 20 | C27: 4942.41 | D27: 5 | E27: =C27*D27 -> 24712.05 | F27: =E27 -> 24712.05 | G27: 41.314667 | H27: =(F27*G27)/1000 -> 1020.9701 | I27: 1042.9853 | J27: =(H27*I27)/1000 -> 1064.8569 | K27: =L27-J27 -> -1064.8569 | M27: =(J27/L27) -> #DIV/0! | N27: =K27/L27 -> #DIV/0!
B28: =B27+1 -> 21 | C28: 3073.52 | D28: 5 | E28: =C28*D28 -> 15367.6 | F28: =E28 -> 15367.6 | G28: 42.314667 | H28: =(F28*G28)/1000 -> 650.27488 | I28: 1043.1149 | J28: =(H28*I28)/1000 -> 678.31139 | K28: =L28-J28 -> -678.31139 | M28: =(J28/L28) -> #DIV/0! | N28: =K28/L28 -> #DIV/0!
B29: =B28+1 -> 22 | D29: 5 | E29: =C29*D29 -> 0 | F29: =E29 -> 0 | G29: 42.314667 | H29: =(F29*G29)/1000 -> 0 | I29: 1042.5884 | J29: =(H29*I29)/1000 -> 0 | K29: =L29-J29 -> 0 | M29: =(J29/L29) -> #DIV/0! | N29: =K29/L29 -> #DIV/0!
B30: =B29+1 -> 23 | D30: 5 | E30: =C30*D30 -> 0 | F30: =E30 -> 0 | G30: 44.314667 | H30: =(F30*G30)/1000 -> 0 | I30: 1042.7497 | J30: =(H30*I30)/1000 -> 0 | K30: =L30-J30 -> 0 | M30: =(J30/L30) -> #DIV/0! | N30: =K30/L30 -> #DIV/0!
B31: =B30+1 -> 24 | D31: 5 | E31: =C31*D31 -> 0 | F31: =E31 -> 0 | G31: 45.314667 | H31: =(F31*G31)/1000 -> 0 | I31: 1042.2931 | J31: =(H31*I31)/1000 -> 0 | K31: =L31-J31 -> 0 | M31: =(J31/L31) -> #DIV/0! | N31: =K31/L31 -> #DIV/0!
B32: =B31+1 -> 25 | D32: 5 | E32: =C32*D32 -> 0 | F32: =E32 -> 0 | G32: 46.314667 | H32: =(F32*G32)/1000 -> 0 | I32: 1039.4114 | J32: =(H32*I32)/1000 -> 0 | K32: =L32-J32 -> 0 | M32: =(J32/L32) -> #DIV/0! | N32: =K32/L32 -> #DIV/0!
B33: =B32+1 -> 26 | D33: 5 | E33: =C33*D33 -> 0 | F33: =E33 -> 0 | G33: 47.314667 | H33: =(F33*G33)/1000 -> 0 | I33: 1039.4407 | J33: =(H33*I33)/1000 -> 0 | K33: =L33-J33 -> 0 | M33: =(J33/L33) -> #DIV/0! | N33: =K33/L33 -> #DIV/0!
B34: =B33+1 -> 27 | D34: 5 | E34: =C34*D34 -> 0 | F34: =E34 -> 0 | G34: 48.314667 | H34: =(F34*G34)/1000 -> 0 | I34: 1040.2491 | J34: =(H34*I34)/1000 -> 0 | K34: =L34-J34 -> 0 | M34: =(J34/L34) -> #DIV/0! | N34: =K34/L34 -> #DIV/0!
B35: =B34+1 -> 28 | D35: 5 | E35: =C35*D35 -> 0 | F35: =E35 -> 0 | G35: 49.314667 | H35: =(F35*G35)/1000 -> 0 | J35: =(H35*I35)/1000 -> 0 | K35: =L35-J35 -> 0 | M35: =(J35/L35) -> #DIV/0! | N35: =K35/L35 -> #DIV/0!
B36: =B35+1 -> 29 | D36: 5 | E36: =C36*D36 -> 0 | F36: =E36 -> 0 | G36: 50.314667 | H36: =(F36*G36)/1000 -> 0 | J36: =(H36*I36)/1000 -> 0 | K36: =L36-J36 -> 0 | M36: =(J36/L36) -> #DIV/0! | N36: =K36/L36 -> #DIV/0!
B37: =B36+1 -> 30 | D37: 5 | E37: =C37*D37 -> 0 | F37: =E37 -> 0 | G37: 51.314667 | H37: =(F37*G37)/1000 -> 0 | J37: =(H37*I37)/1000 -> 0 | K37: =L37-J37 -> 0 | M37: =(J37/L37) -> #DIV/0! | N37: =K37/L37 -> #DIV/0!
B38: Average | F38: =AVERAGE(F8:F37) -> 12674.528 | H38: =AVERAGE(H8:H37) -> 471.76255 | I38: =AVERAGE(I8:I37) -> 1047.1339 | J38: =AVERAGE(J8:J37) -> 494.65048 | K38: =AVERAGE(K8:K37) -> -12.578486 | L38: =AVERAGE(L8:L37) -> 850.71528 | M38: =AVERAGE(M8:M37) -> #DIV/0! | N38: =AVERAGE(N8:N37) -> #DIV/0!
B39: TOTAL | C39: =SUM(C8:C37) -> 76047.17 | E39: =SUM(E8:E37) -> 380235.85 | F39: =SUM(F8:F37) -> 380235.85 | H39: =SUM(H8:H37) -> 14152.877 | J39: =SUM(J8:J37) -> 14839.514
B40: Koreksi
B41: Total Setelah Koreksi | H41: =H39+H40 -> 14152.877 | J41: =J39+J40 -> 14839.514
C43: CONVERT HP Boiler from Utility
C44: =C39 -> 76047.17 | D44: m3 | F44: =C39*5 -> 380235.85 | G44: 9983.7
C45: 5 | D45: bar | F45: 21286.9 | G45: =G44-C39 -> -66063.47
...

Sheet Qty cons analysis
D2: Quantity Utility Consumption Analysis (based on Guarantee Utility Consumption)
D3: Refinery & Fractionation Plant
D4: Periode 01 s/d 30 Juni 2025
D5: Consumption | E5: UoM | F5: Budget | G5: Actual | H5: Under (Over) Budget | I5: Explanation Under / Over budget
D6: CPO Consume | E6: Kg | F6: ='JUNI 2025'!E9 -> 58900000 | G6: ='JUNI 2025'!$AL$9 -> 17813187 | H6: =G6/F6 -> 0.30243102
D7: RbdPO Consume | E7: Kg | F7: ='JUNI 2025'!E20 -> 55661000 | G7: ='JUNI 2025'!AL29 -> 17792607 | H7: =G7/F7 -> 0.31966021
D8: TOTAL ACTUAL CONSUMPTION
D9: Refinery
D10: Bleaching Earth to Poram Spec | E10: Kg | F10: 232362 | G10: ='JUNI 2025'!$AL$75 -> 153073 | H10: =F10-G10 -> 79289 | I10: Under Budget
D11: Bleaching Earth to Branded Spec | E11: Kg | F11: 106326 | G11: ='JUNI 2025'!$AL$81 -> 0 | H11: 0
D12: Phosporic Acid | E12: Kg | F12: 20971 | G12: ='JUNI 2025'!$AL$83 -> 8793.24 | H12: =F12-G12 -> 12177.76 | I12: Under Budget
D13: Gas Consumption (MP Boiler) | E13: mmbtu | F13: 22143.74 | G13: 9451 | H13: =F13-G13 -> 12692.74 | I13: Under Budget
D14: Gas Consumption (HP Boiler) | E14: mmbtu | F14: 3907.73 | G14: 2032 | H14: =F14-G14 -> 1875.73 | I14: Under Budget
D15: Cooling Water top up to Cooling Tower | E15: m3 | F15: 1521.33 | G15: ='JUNI 2025'!$AL$260 -> 5429 | H15: =F15-G15 -> -3907.67 | I15: Under Budget
D16: Steam | E16: Kg | F16: 11424000 | G16: ='JUNI 2025'!$AL$250 -> 102.1306 | H16: =F16-G16 -> 11423898 | I16: Under Budget
D17: Power (Process Plant) | E17: Kwh | F17: 102679 | G17: 135 | H17: =F17-G17 -> 102544 | I17: Under Budget
D18: Power (Cooling Tower) | E18: Kwh | F18: 73158 | G18: 100 | H18: =F18-G18 -> 73058 | I18: Under Budget
D19: Fractionation
D20: Cooling Water top up to Cooling Tower | E20: m3 | F20: 2622 | G20: ='JUNI 2025'!$AL$262 -> 71.80074 | H20: =F20-G20 -> 2550.1993 | I20: Under Budget
D21: Steam | E21: Kg | F21: 2318000 | G21: ='JUNI 2025'!$AL$252 -> 44.386779 | H21: =F21-G21 -> 2317955.6 | I21: Under Budget
D22: Power (Process Plant) | E22: Kwh | F22: 109440 | G22: 150 | H22: =F22-G22 -> 109290 | I22: Over Budget
D23: Power (Cooling Tower) | E23: Kwh | F23: 28747 | G23: 82 | H23: =F23-G23 -> 28665 | I23: Over Budget
D24: ACTUAL CONSUMPTION PER MT RAW MATERIAL
D25: Refinery
D26: Bleaching Earth to Poram Spec | E26: Kg/MT | F26: 9 | G26: =(G10/$G$6)*1000 -> 8.5932405 | H26: =F26-G26 -> 0.4067595 | I26: Under Budget
D27: Bleaching Earth to Branded Spec | E27: Kg/MT | F27: 18 | G27: =(G11/$G$6)*1000 -> 0 | H27: =F27-G27 -> 18 | I27: Under Budget
D28: Phosporic Acid | E28: Kg/MT | F28: 0.6 | G28: =(G12/$G$6)*1000 -> 0.49363654 | H28: =F28-G28 -> 0.10636346 | I28: Under Budget
D29: Gas Consumption (HP Boiler) | E29: Nm3/MT | F29: 4.2 | G29: =(G13/$G$6)*1000 -> 0.53056199 | H29: =F29-G29 -> 3.669438 | I29: Under Budget
D30: Gas Consumption (HP Boiler) **) | E30: mmbtu/MT | F30: 0.2 | G30: =(G14/$G$6)*1000 -> 0.11407279 | H30: =F30-G30 -> 0.085927207 | I30: Under Budget
D31: Cooling Water top up to Cooling Tower | E31: m3/MT | F31: 0.04 | G31: =(G15/$G$6)*1000 -> 0.30477421 | H31: =F31-G31 -> -0.26477421 | I31: Over Budget
D32: Steam | E32: Kg/MT | F32: 28 | G32: =(G16/$G$6)*1000000 -> 5.7334265 | H32: =F32-G32 -> 22.266574 | I32: Over Budget
D33: Power (Process Plant) | E33: Kwh/MT | F33: 4.4 | G33: =(G17/$G$6)*1000000 -> 7.5786551 | H33: =F33-G33 -> -3.1786551 | I33: Over Budget
D34: utility section ( chiller ) | E34: Kwh/MT | F34: 7.3 | G34: =(G18/$G$6)*1000000 -> 5.6138186 | H34: =F34-G34 -> 1.6861814 | I34: Over Budget
D35: Fractionation
D36: Cooling Water top up to Cooling Tower | E36: m3/MT | F36: 0.13 | G36: =(G20/$G$7)*1000 -> 0.0040354255 | H36: =F36-G36 -> 0.12596457 | I36: Under Budget
D37: Steam | E37: Kg/MT | F37: 45 | G37: =(G21/$G$7)*1000000 -> 2.4946754 | H37: =F37-G37 -> 42.505325 | I37: Under Budget
D38: Power (Process Plant) | E38: Kwh/MT | F38: 4.1 | G38: =(G22/$G$7)*1000000 -> 8.4304678 | H38: =F38-G38 -> -4.3304678 | I38: Over Budget
D39: utility section ( chiller ) | E39: Kwh/MT | F39: 4.5 | G39: =(G23/$G$7)*1000000 -> 4.6086557 | H39: =F39-G39 -> -0.10865572 | I39: Over Budget
D42: - BE Achieve dengan pemakaian consume Bleaching Earth 8,59 Kg/MT
D43: * Pemakaian Listrik Over terkait penggunaan dua unit chiller
...

Sheet Utility
D2: UTILITY (GAS, STEAM, WATER & POWER) REPORT
D3: PT. INDUSTRI NABATI LESTARI
D5: Periode 01 s/d 30 Juni 2025
D6: No | E6: Item | F6: Norma | G6: UoM | H6: Juni | K6: Consume ( MT ) | L6: Remaks
H7: Budget | I7: Actual | J7: Percentage Act.
E9: Total Feed Raw Material CPO | K9: 17813187
E10: Total Proses RBDPO | K10: ='JUNI 2025'!AL29 -> 17792607
D11: 1. | E11: GAS CONSUMPTION
E12: Incoming *base on INL | G12: mmbtu | I12: ='JUNI 2025'!$AL$241 -> 11153.207
E13: Incoming *base on Pertagas | F13: 1460.001 | G13: mmbtu | H13: 26051.47 | I13: 11483.394 | J13: =I13/H13 -> 0.4407964 | K13: =I13/K9*1000 -> 0.64465692
E14: Distribution to
E15: HP Boiler Refinery | G15: mmbtu | H15: 5907.73 | I15: 2032.278 | J15: =I15/H15 -> 0.3440032 | K15: =I15/K9*1000 -> 0.1140884
E16: MP Boiler | G16: mmbtu | H16: 20143.74 | I16: =I13-I15 -> 9451.1163 | J16: =I16/H16 -> 0.46918379 | K16: =I16/K9*1000 -> 0.53056852
E17: Total | G17: mmbtu | H17: =H15+H16 -> 26051.47 | I17: =I15+I16 -> 11483.394 | J17: =I17/H17 -> 0.4407964 | K17: =SUM(K15+K16) -> 0.64465692
D18: 2. | E18: STEAM CONSUMPTION | M18: =M19/'JUNI 2025'!E9 -> 19.783647
E19: Incoming | G19: Kg | H19: 11424000 | I19: 1817779 | J19: =I19/H19 -> 0.15911931 | K19: =I19/$K$10*1000 -> 102.16485 | M19: 1.1652568e+09
E20: Distribution to | K20: =I20/$K$9 -> 0
E21: Refinery | F21: < 28 | G21: Kg | H21: 3420000 | I21: 790670 | J21: =I21/H21 -> 0.23119006 | K21: =I21/$K$9*1000 -> 44.386779
E22: Fractionation | F22: < 45 | G22: Kg | H22: 2318000 | I22: 425736 | J22: =I22/H22 -> 0.18366523 | K22: =I22/$K$10*1000 -> 23.927691 | M22: =24*5 -> 120 | N22: =M22*2 -> 240 | O22: oring filter leaf niagara 2 bulan
E23: Others | F23: 106000 | G23: Kg | H23: 5686000 | I23: 602373 | J23: =I23/H23 -> 0.10593968 | K23: =I23/$K$9*1000 -> 33.816127
E24: Total | G24: Kg | H24: =SUM(H21:H23) -> 11424000 | I24: =SUM(I21:I23) -> 1818779 | J24: =I24/H24 -> 0.15920685 | K24: =I24/$K$9*1000 -> 102.10295
D25: 3. | E25: WATER CONSUMPTION
E26: Incoming Raw Water | G26: m3 | H26: =SUM(H30:H32) -> 41253 | I26: =SUM(I27:$I$28) -> 8754.1937 | J26: =I26/H26 -> 0.21220744 | K26: =I26/$K$9*1000 -> 0.49144455
E27: - Suplay To RO Product | I27: ='JUNI 2025'!$AL$264 -> 53.392963 | K27: =I27/$K$9*1000 -> 0.0029973841
E28: - Suplay To Proses dan Sanitary | I28: =SUM(I30:$I$32) -> 8700.8007 | K28: =I28/$K$9*1000 -> 0.48844717
E29: Rincian Outgoing Proses | K29: =I29/$K$9 -> 0
E30: Softener Product (to Refinery) | F30: < 0,04 | G30: m3 | H30: 11745 | I30: ='JUNI 2025'!$AL$260 -> 5429 | J30: =I30/H30 -> 0.46223925 | K30: =I30/$K$9*1000 -> 0.30477421 | M30: =K27+K30+K31+K32 -> 0.49144921
E31: Softener Product (to Fractionation) | F31: < 0,13 | G31: m3 | H31: 20895 | I31: ='JUNI 2025'!$AL$262 -> 71.80074 | J31: =I31/H31 -> 0.0034362642 | K31: =I31/$K$10*1000 -> 0.0040354255
E32: Others | G32: m3 | H32: 8613 | I32: ='JUNI 2025'!$AL$265 -> 3200 | J32: =I32/H32 -> 0.37153141 | K32: =I32/$K$9*1000 -> 0.17964219
E33: Total | G33: m3 | H33: =H26 -> 41253 | I33: =SUM(I27:I28) -> 8754.1937 | J33: =I33/H33 -> 0.21220744 | K33: =I33/$K$9*1000 -> 0.49144455
D34: 4 | E34: POWER CONSUMPTION
E35: Incoming
E36: PLN *base on BA Kinra | G36: Kwh | H36: =H38+H39+H41+H42 -> 704938 | I36: ='JUNI 2025'!AL270 -> Incoming | J36: =I36/H36*1000 -> #VALUE! | K36: =I36/$K$9*100000 -> #VALUE!
E37: Outgoing | K37: =I37/$K$9 -> 0
E38: - Physical Refinery Plant | F38: 4.4 | G38: Kwh | H38: 162973 | I38: 135763 | J38: =I38/H38/10 -> 0.083303983 | K38: =I38/$K$9*1000 -> 7.6214885
E39: - Refinery - Cooling Water System | F39: 7.3 | G39: Kwh | H39: 100660 | I39: 99648 | J39: =I39/H39/10 -> 0.098994635 | K39: =I39/$K$9*1000 -> 5.5940579
E40: - Refinery - Utilities | F40: 11.81 | G40: Kwh | H40: 0 | I40: ='JUNI 2025'!$AL$283 -> Others | J40: =I40/H40/10 -> #VALUE! | K40: =I40/$K$9*1000 -> #VALUE!
E41: - Dry Fractionation Plant | F41: 4.5 | G41: Kwh | H41: 287808 | I41: 150240 | J41: =I41/H41/10 -> 0.052201468 | K41: =I41/$K$10*1000 -> 8.4439565
E42: - Dry Fractionation CW System | F42: 4.1 | G42: Kwh | H42: 153497 | I42: 82129 | J42: =I42/H42/10 -> 0.05350528 | K42: =I42/$K$10*1000 -> 4.6159059
E43: - Lighting - Refinery & Dry Fractionation | F43: 241.12 | G43: Kwh | H43: 4581 | I43: ='JUNI 2025'!$AL$284 -> 0 | J43: =I43/H43 -> 0 | K43: =I43/$K$9*1000 -> 0
...

Sheet Prod
B2: MONTHLY PRODUCTION REPORT
B3: PT. INDUSTRI NABATI LESTARI
B4: Periode 01 s/d 30 Juni 2025
B5: NO | C5: Item | D5: Unit | E5: Juni | H5: Remaks
E6: Budget | F6: Actual | G6: Percentage Act.
B7: 1. | C7: PRODUCTION
C8: Refinery Plant
C9: Running Days | D9: Days | E9: 15 | F9: ='JUNI 2025'!$AL$6 -> 10 | G9: =(F9/E9) -> 0.66666667 | H9: Tidak Tercapai
C10: CPO Incoming | D10: Kg
C11: Total CPO Consume | D11: Kg | E11: ='JUNI 2025'!E9 -> 58900000 | F11: =F12+F13 -> 17813187 | G11: =(F11/E11) -> 0.30243102 | H11: Tidak Tercapai
C12: CPO Consume Poram | F12: ='JUNI 2025'!$AL$11 -> 17813187
C13: CPO Consume Brand | F13: ='JUNI 2025'!$AL$12 -> 0
C14: - Avg. FFA | D14: % | E14: 5 | F14: ='JUNI 2025'!$AL$13 -> 4.5701667
C15: - Avg. Moist & Impurities | D15: % | E15: 0.5 | F15: ='JUNI 2025'!$AL$14 -> 0.45666667
C16: - Avg. DOBI | D16: % | E16: 22.2 | F16: ='JUNI 2025'!$O$15 -> 0
C17: Product
C18: RBDPO | D18: Kg | E18: ='JUNI 2025'!E20 -> 55661000 | F18: ='JUNI 2025'!$AL$20 -> 16233349 | G18: =(F18/E18) -> 0.29164674 | H18: Tidak Tercapai
C19: PFAD | D19: Kg | E19: ='JUNI 2025'!E21 -> 2827000 | F19: ='JUNI 2025'!$AL$21 -> 866309 | G19: =(F19/E19) -> 0.3064411 | H19: Tidak Tercapai
C21: Fraksinasi Plant
C22: Total Proses RBDPO | D22: Kg | E22: =E25 -> 25639000 | F22: ='JUNI 2025'!$AL$29 -> 17792607 | G22: =(F22/E22) -> 0.6939665 | H22: Tercapai
C23: Total Olah RBDPO ( Feed ) | D23: Kg | E23: =E25 -> 25639000 | F23: ='JUNI 2025'!$AL$25 -> 17223447 | G23: =(F23/E23) -> 0.6717675 | H23: Tercapai
C24: Fractionation Olein IV 56
C25: RBDPO Consume | D25: Kg | E25: =E26+E27 -> 25639000 | F25: =F26+F27 -> 17792607 | G25: =(F25/E25) -> 0.6939665 | H25: Tercapai
C26: Olein IV 56 | D26: Kg | E26: ='JUNI 2025'!E33 -> 25000000 | F26: ='JUNI 2025'!$AL$33 -> 14325558 | G26: =(F26/E26) -> 0.57302232 | H26: Tercapai
C27: Stearin | D27: Kg | E27: ='JUNI 2025'!E34 -> 639000 | F27: ='JUNI 2025'!$AL$34 -> 3467049 | G27: =(F27/E27) -> 5.4257418 | H27: Tercapai
C28: Fractionation Olein IV 57 ( Bulk )
C29: RBDPO Consume | D29: Kg | E29: 0
C30: Olein IV 57 | D30: Kg | E30: 0 | F30: 0 | G30: 0
C31: Stearin | D31: Kg | E31: 0
C32: Fractionation Olein IV 58 ( bulk )
C33: CPO | D33: Kg | E33: 1812101.9 | G33: =(F33/E33)*100 -> 0
C34: RBDPO Consume | D34: Kg | E34: =E35+E36 -> 22714 | F34: =F35+F36 -> 0 | G34: =(F34/E34)*100 -> 0
C35: Olein IV 58 | D35: Kg | E35: 15900 | G35: =(F35/E35)*100 -> 0
C36: Stearin | D36: Kg | E36: 6814 | G36: =(F36/E36)*100 -> 0
C37: Fractionation Olein IV 58
C38: RBDPO Consume | D38: Kg | E38: 21429000 | F38: =F39+F40 -> 0 | G38: =(F38/E38)*100 -> 0 | H38: Tidak Tercapai
C39: Olein IV 58 | D39: Kg | E39: 15000000 | F39: ='JUNI 2025'!$AL$46 -> 0 | G39: =(F39/E39)*100 -> 0 | H39: Tidak Tercapai
C40: Stearin | D40: Kg | E40: 6429000 | F40: ='JUNI 2025'!$AL$47 -> 0 | G40: =(F40/E40)*100 -> 0 | H40: Tidak Tercapai
C41: Fractionation Olein IV 60
C42: CPO | E42: 2234607.2 | F42: 0 | G42: =(F42/E42)*100 -> 0
...

Sheet OIP Refinery 
B4: Oil In Plant (OIP) Refinery pmg 2 | I4: FEBUARI | J4: OIP | M4: TK131 RPO | P4: TK132 RPO | S4: TOTAL STOK RPO DI PLANT
B5: Vessel | C5: Operating Volume (m3) | D5: Oil Density (kg/m3) | E5: MT | F5: Level yg diisi | G5: Actual OIP (Kg) | I5: Tanggal | J5: Opening Stock | K5: Closing Stock | L5: balance stok | M5: Opening Stock | N5: Closing Stock | O5: CONSUMP stok | P5: Opening Stock | Q5: Closing Stock | R5: CONSUMP stok
B6: 2MX312 | C6: 5.67 | D6: 850 | E6: =C6*D6/1000 -> 4.8195 | F6: 0 | G6: =(F6*E6/100)*1000 -> 0 | I6: 45809
B7: 2VE611A | C7: 47.22 | D7: 850 | E7: =C7*D7/1000 -> 40.137 | F7: 0 | G7: =(F7*E7/100)*1000 -> 0 | I7: 45810
B8: 2VE611B | C8: 47.22 | D8: 850 | E8: =C8*D8/1000 -> 40.137 | F8: 0 | G8: =(F8*E8/100)*1000 -> 0 | I8: 45811
B9: 2VE612 | C9: 35.68 | D9: 850 | E9: =C9*D9/1000 -> 30.328 | F9: 0 | G9: =(F9*E9/100)*1000 -> 0 | I9: 45812
B10: 2VE661 | C10: 10.8 | D10: 850 | E10: =C10*D10/1000 -> 9.18 | F10: 0 | G10: =(F10*E10/100)*1000 -> 0 | I10: 45813
B11: FL621 | C11: 10.1 | D11: 850 | E11: =C11*D11/1000 -> 8.585 | F11: 0 | G11: =(F11*E11/100)*1000 -> 0 | I11: 45814 | L11: =J11-K11 -> 0
B12: FL622 | C12: 10.1 | D12: 850 | E12: =C12*D12/1000 -> 8.585 | F12: 0 | G12: =(F12*E12/100)*1000 -> 0 | I12: 45815 | L12: =J12-K12 -> 0
B13: FL623 | C13: 10.1 | D13: 850 | E13: =C13*D13/1000 -> 8.585 | F13: 0 | G13: =(F13*E13/100)*1000 -> 0 | I13: 45816 | J13: 0 | K13: 311880 | L13: =K13 -> 311880 | N13: 0 | Q13: 174609
B14: FL624 | C14: 10.1 | D14: 850 | E14: =C14*D14/1000 -> 8.585 | F14: 0 | G14: =(F14*E14/100)*1000 -> 0 | I14: 45817 | J14: 311880 | K14: 316289 | L14: =J14-K14 -> -4409 | N14: 44191 | P14: 174609 | Q14: 38852 | R14: =P14-Q14 -> 135757 | S14: =R14+O14+L14 -> 131348
B15: FL625 | C15: 10.1 | D15: 850 | E15: =C15*D15/1000 -> 8.585 | F15: 0 | G15: =(F15*E15/100)*1000 -> 0 | I15: 45818 | J15: 316289 | K15: 310412 | L15: =J15-K15 -> 5877 | M15: 44191 | N15: 405272 | O15: =M15-N15 -> -361081 | P15: 38852 | Q15: 38852 | R15: =P15-Q15 -> 0 | S15: =R15+O15+L15 -> -355204
B16: 2VE701 | C16: 72.13 | D16: 850 | E16: =C16*D16/1000 -> 61.3105 | F16: 55 | G16: =(F16*E16/100)*1000 -> 33720.775 | I16: 45819 | J16: 310412 | K16: 316896 | L16: =J16-K16 -> -6484
B17: 2VE751 | C17: 4.28 | D17: 860 | E17: =C17*D17/1000 -> 3.6808 | F17: 50 | G17: =(F17*E17/100)*1000 -> 1840.4 | I17: 45820 | J17: 316896 | K17: 303575 | L17: =J17-K17 -> 13321
B18: 2HE721A (tube) | C18: 10 | D18: 810 | E18: =C18*D18/1000 -> 8.1 | F18: 100 | G18: =(F18*E18/100)*1000 -> 8100 | I18: 45821 | J18: 326546 | K18: 307265 | L18: =J18-K18 -> 19281
B19: 2HE721A (shell) | C19: 21.8 | D19: 800 | E19: =C19*D19/1000 -> 17.44 | F19: 45 | G19: =(F19*E19/100)*1000 -> 7848 | I19: 45822 | J19: 307265 | K19: 317800 | L19: =J19-K19 -> -10535
B20: HE721B (tube) | C20: 10 | D20: 810 | E20: =C20*D20/1000 -> 8.1 | F20: 100 | G20: =(F20*E20/100)*1000 -> 8100 | I20: 45823 | J20: 317800 | K20: 303575 | L20: =J20-K20 -> 14225
B21: 2HE722 | C21: 11.4 | D21: 790 | E21: =C21*D21/1000 -> 9.006 | F21: 100 | G21: =(F21*E21/100)*1000 -> 9006 | I21: 45824 | J21: 303575 | K21: 319541 | L21: =J21-K21 -> -15966
B22: 2PR731 | C22: 14 | D22: 790 | E22: =C22*D22/1000 -> 11.06 | F22: 35 | G22: =(F22*E22/100)*1000 -> 3871 | I22: 45825 | J22: 319541 | K22: 190797 | L22: =J22-K22 -> 128744
B23: 2DE732 | C23: 149.76 | D23: 790 | E23: =C23*D23/1000 -> 118.3104 | F23: 100 | G23: =(F23*E23/100)*1000 -> 118310.4 | I23: 45826 | L23: =J23-K23 -> 0
C24: =SUM(C6:C23) -> 490.46 | E24: =SUM(E6:E23) -> 404.5342 | I24: 45827 | L24: =J24-K24 -> 0
F25: Total OIP = | G25: =SUM(G6:G24) -> 190796.57 | I25: 45828 | L25: =J25-K25 -> 0
I26: 45829 | L26: =J26-K26 -> 0 | U26: =L26+L25 -> 0
I27: 45830 | L27: =J27-K27 -> 0
I28: 45831 | L28: =J28-K28 -> 0
I29: 45832 | L29: =J29-K29 -> 0
B30: Solar Daily Tank HPB | I30: 45833 | L30: =J30-K30 -> 0
B31: 2TK726 | C31: =5.3+0.78 -> 6.08 | D31: 840 | E31: =C31*D31/1000 -> 5.1072 | F31: 0 | G31: =F31*E31/100*1000 -> 0 | H31: 0 | I31: 45834
I32: 45835
B33: Stock Chemicals In Plant | I33: 45836
C34: Read | D34: End Read | E34: Consumption | I34: 45837
B35: BE | I35: 45838
B36: 630A
B37: 630B
B38: H3PO4
B39: NaOH
B40: Citrid Acid

Sheet Oip Fract .
A4: Oil In Plant (OIP) Fraksinasi | I4: OIP | S4: BUFFER TANK | W4: DIRECT
A5: RBDPO OIP pmg 2 | I5: RPO CR | M5: OLEIN | P5: STEARIN | S5: TK131 RPO | U5: TK132 RPO
