Workbook

Sheet Juli - 2024xx
B1: PRODUCTION REPORT
B2: No | C2: ITEM | D2: Budget / Norma | E2: UoM | F2: JulI | AL2: TOTAL (Kg)
F3: 1 | G3: 2 | H3: 3 | I3: 4 | J3: 5 | K3: 6 | L3: 7 | M3: 8 | N3: 9 | O3: 10 | P3: 11 | Q3: 12 | R3: 13 | S3: 14 | T3: 15 | U3: 16 | V3: 17 | W3: 18 | X3: 19 | Y3: 20 | Z3: 21 | AA3: 22 | AB3: 23 | AC3: 24 | AD3: 25 | AE3: 26 | AF3: 27 | AG3: 28 | AH3: 29 | AI3: 30 | AJ3: 31
B4: 1 | C4: PRODUCTION | AL4: Production
C5: Refinery | AL5: Refinery
C6: Running Days | E6: Day | F6: 1 | G6: 1 | H6: 1 | I6: 1 | J6: 1 | K6: 1 | L6: 1 | M6: 1 | N6: 1 | O6: 1 | P6: 1 | Q6: 1 | R6: 1 | S6: 1 | AL6: =SUM(F6:O6) -> 10
C7: Incoming CPO | E7: Kg | F7: ='[1]01 '!$P$14 -> 865877 | G7: ='[1]02'!$P$14 -> 1020502 | H7: ='[1]03'!$P$14 -> 623069 | I7: ='[1]04'!$P$14 -> 686156 | J7: ='[1]05'!$P$14 -> 500524 | K7: ='[1]06'!$P$14 -> 286477 | L7: ='[1]07'!$P$11 -> 40800 | M7: ='[1]08'!$P$13+168651 -> 335707 | N7: ='[1]09'!$P$13 -> 203264 | O7: ='[2]10'!$P$14-22440 -> 803740 | P7: ='[3]11'!$P$14 -> 474327 | Q7: ='[4]12'!$P$13+156887 -> 486876 | R7: =186434+'[4]13'!$P$13 -> 412792 | S7: 0 | AL7: =SUM(F7:AI7) -> 6740111 | AM7: =AVERAGE(G7:O7) -> 500026.56 | AO7: =AL7/14 -> 481436.5
C8: Ratio Run CPO | E8: % | F8: =F9/2200000*100 -> 33.860182 | G8: =G9/2200000*100 -> 33.816909 | H8: =H9/2200000*100 -> 47.656136 | I8: =I9/2200000*100 -> 50.673682 | J8: =J9/2200000*100 -> 11.278455 | K8: =K9/2200000*100 -> 17.6585 | L8: =L9/2200000*100 -> 2.6320909 | M8: =M9/2200000*100 -> 11.742864 | ... AJ8: =AJ9/2200000*100 -> 0 | AL8: =AVERAGE(F8:S8) -> 23.510006
C9: CPO Consume Total | D9: 36359000 | E9: Kg | F9: ='[1]01 '!$Q$14 -> 744924 | G9: ='[1]02'!$Q$14 -> 743972 | H9: ='[1]03'!$Q$14 -> 1048435 | I9: ='[1]04'!$Q$14 -> 1114821 | J9: ='[1]05'!$Q$14 -> 248126 | K9: ='[1]06'!$Q$14 -> 388487 | L9: ='[1]07'!$Q$14 -> 57906 | M9: ='[1]08'!$Q$13 -> 258343 | N9: ='[1]09'!$Q$11 -> 154743 | O9: 512647 | P9: ='OIP Refinery'!D15+'[3]11'!$Q$11-'OIP Refinery'!E15 -> 445789 | Q9: ='OIP Refinery'!D16+'[4]12'!$Q$13+'[4]12'!$Q$11-'OIP Refinery'!E16 -> 531293 | R9: ='[4]13'!$Q$13 -> 568358 | S9: ='OIP Refinery'!D18+'[4]14'!$Q$13+'[4]14'!$Q$11-'OIP Refinery'!E18 -> 423238 | T9: 0 | AL9: =SUM(F9:AI9) -> 7241082 | AM9: =AL9/D9*100 -> 19.915515 | AN9: =AL9/10 -> 724108.2
C10: CPO Consume Poram | D10: 29045000 | E10: Kg | F10: =F9-F27-F36 -> 744924 | G10: =G9-G27-G36 -> 743972 | H10: =H9-H27-H36 -> 1048435 | I10: =I9-I27-I36 -> 1114821 | J10: =J9-J27-J36 -> 248126 | K10: =K9-K27-K36 -> 388487 | L10: =L9-L27-L36 -> 57906 | M10: =M9-M27-M36 -> 258343 | ... AJ10: =AJ9-AJ27-AJ36 -> 0 | AL10: =SUM(F10:AI10) -> 7241082
C11: CPO Consume Brand | D11: 7314000 | E11: Kg | F11: =F27+F36 -> 0 | G11: =G27+G36 -> 0 | H11: =H27+H36 -> 0 | I11: =I27+I36 -> 0 | J11: =J27+J36 -> 0 | K11: =K27+K36 -> 0 | L11: =L27+L36 -> 0 | M11: =M27+M36 -> 0 | ... AJ11: =AJ27+AJ36 -> 0 | AL11: =SUM(F11:AI11) -> 0
C12: - FFA | D12: 5 | E12: % | F12: 4.03 | G12: 4.14 | H12: 4.06 | I12: =(4.12+4.17+3.97)/3 -> 4.0866667 | J12: 4.18 | K12: =4.14 -> 4.14 | L12: 4.2 | M12: 4.08 | N12: 4.16 | O12: 4.18 | P12: 4.2 | Q12: 4.22 | R12: 3.96 | S12: =(4.29+4.09)/2 -> 4.19 | AL12: =AVERAGE(F12:AI12) -> 4.1304762
C13: - Moist & Impurities | D13: 0.5 | E13: % | F13: 0.44 | G13: 0.46 | H13: 0.455 | I13: =(0.43+0.44+0.48)/3 -> 0.45 | J13: 0.49 | K13: =(0.44+0.49)/2 -> 0.465 | L13: 0.4 | M13: 0.48 | N13: 0.4 | O13: 0.41 | P13: 0.47 | Q13: 0.4 | R13: 0.49 | S13: =(0.4+0.49)/2 -> 0.445 | AL13: =AVERAGE(F13:AI13) -> 0.44678571
C14: - DOBI | D14: 2,20 Min | E14: % | F14: 2.21 | G14: 2.21 | H14: 2.22 | I14: 2.21 | J14: 2.21 | K14: 2.21 | L14: 2.21 | M14: 2.22 | N14: 2.21 | O14: 2.22 | P14: 2.21 | Q14: 2.21 | R14: 2.22 | S14: 2.22 | AL14: =AVERAGE(F14:AI14) -> 2.2135714
C15: Product | AL15: Product
C16: RbdPO | D16: 34458000 | E16: Kg | F16: ='[1]01 '!$P$15 -> 667300 | G16: ='[1]02'!$P$15 -> 695000 | H16: ='[1]03'!$P$15 -> 814100 | I16: ='[1]04'!$P$15 -> 760000 | J16: 0 | K16: ='[1]06'!$P$15 -> 587100 | L16: ='[1]07'!$P$15 -> 92106 | M16: ='[1]08'!$P$16+'[1]08'!$P$15 -> 105220 | N16: ='[1]09'!$P$15+'[1]09'!$P$16 -> 70837 | O16: ='[2]10'!$P$17 -> 488153 | P16: ='[3]11'!$P$17 -> 379337 | Q16: ='[4]12'!$P$17 -> 492952 | R16: ='[4]13'!$P$17 -> 532902 | S16: ='[4]14'!$P$16 -> 497845 | T16: 91674 | AL16: =SUM(F16:AI16) -> 6274526
C17: PFAD | D17: 1636000 | E17: Kg | F17: ='[1]01 '!$P$24 -> 25659 | G17: ='[1]02'!$P$24 -> 18786 | H17: ='[1]03'!$P$24 -> 46938 | I17: ='[1]04'!$P$24 -> 48667 | K17: ='[1]06'!$P$24 -> 32281 | L17: ='[1]07'!$P$24 -> 0 | M17: ='[1]08'!$P$24 -> 26283 | N17: ='[1]09'!$P$23+'[1]09'!$P$24 -> 6431 | O17: ='[2]10'!$P$23 -> 20426 | P17: ='[3]11'!$P$23 -> 23275 | Q17: ='[4]12'!$P$25 -> 27655 | R17: ='[4]13'!$P$25 -> 25803 | S17: ='[4]13'!$P$25 -> 25803 | T17: 6643 | AL17: =SUM(F17:AI17) -> 334650
C18: Fractionation OLEIN IV 56 | AL18: Olein IV 56
C19: RBDPO Consume | E19: Kg | F19: =F20+F21 -> 0 | G19: =G20+G21 -> 0 | H19: =H20+H21 -> 0 | I19: =I20+I21 -> 0 | J19: =J20+J21 -> 0 | K19: =K20+K21 -> 0 | L19: =L20+L21 -> 0 | M19: =M20+M21 -> 0 | ... AJ19: =AJ20+AJ21 -> 0 | AL19: =SUM(F19:AI19) -> 0
C20: OLEIN IV 56 | E20: Kg | F20: 0 | G20: 0 | H20: 0 | AL20: =SUM(F20:AI20) -> 0
C21: STEARIN | E21: Kg | F21: 0 | G21: 0 | H21: 0 | AL21: =SUM(F21:AI21) -> 0
C22: Fractionation OLEIN IV 57 ( Bulk ) | AL22: Olein IV 57 ( Bulk )
C23: RBDPO Consume | E23: Kg | F23: =F24+F25 -> 0 | G23: =G24+G25 -> 0 | H23: =H24+H25 -> 0 | I23: =I24+I25 -> 0 | J23: =J24+J25 -> 0 | K23: =K24+K25 -> 0 | L23: =L24+L25 -> 0 | M23: =M24+M25 -> 0 | ... AJ23: =AJ24+AJ25 -> 0 | AL23: =SUM(F23:O23) -> 0
C24: OLEIN IV 57 | E24: Kg | F24: 0 | G24: 0 | H24: 0 | AL24: =SUM(F24:O24) -> 0
C25: STEARIN | E25: Kg | F25: 0 | G25: 0 | H25: 0 | AL25: =SUM(F25:O25) -> 0
C26: Fractionation OLEIN IV 57 ( Retail ) | AL26: Olein IV 57 ( Retail )
C27: CPO Consume | E27: Kg | AL27: =SUM(F27:O27) -> 0
C28: RBDPO Brand Consume | E28: Kg | F28: =F29+F30 -> 0 | G28: =G29+G30 -> 0 | H28: =H29+H30 -> 0 | I28: =I29+I30 -> 0 | J28: =J29+J30 -> 0 | K28: =K29+K30 -> 0 | L28: =L29+L30 -> 0 | M28: =M29+M30 -> 0 | ... AJ28: =AJ29+AJ30 -> 0 | AL28: =SUM(F28:O28) -> 0
C29: OLEIN IV 57 Low Color | E29: Kg | F29: 0 | G29: 0 | H29: 0 | AL29: =SUM(F29:O29) -> 0
C30: STEARIN | E30: Kg | F30: 0 | G30: 0 | H30: 0 | AL30: =SUM(F30:O30) -> 0
C31: Fractionation OLEIN IV 58 ( Bulk ) | AL31: Olein IV 58 ( Bulk )
C32: RBDPO Consume | D32: =D33+D34 -> 21429000 | E32: Kg | F32: =F33+F34 -> 636794 | G32: =G33+G34 -> 705632 | H32: =H33+H34 -> 727663 | I32: =I33+I34 -> 1053776 | J32: =J33+J34 -> 585552 | K32: =K33+K34 -> 632355 | L32: =L33+L34 -> 315146 | M32: =M33+M34 -> 0 | ... AJ32: =AJ33+AJ34 -> 0 | AL32: =SUM(F32:AI32) -> 7315959
C33: OLEIN IV 58 | D33: 15000000 | E33: Kg | F33: ='[1]01 '!$P$21 -> 437978 | G33: ='[1]02'!$P$21 -> 502403 | H33: ='[1]03'!$P$21 -> 540182 | I33: ='[1]04'!$P$21 -> 762960 | J33: ='[1]05'!$P$21 -> 360256 | K33: ='[1]06'!$P$21 -> 449507 | L33: ='[1]07'!$P$21 -> 208841 | M33: 0 | N33: ='[1]09'!$P$21 -> 295995 | O33: 0 | P33: ='[3]11'!$P$21 -> 478550 | Q33: ='[4]12'!$P$21 -> 209348 | R33: ='[4]13'!$P$21 -> 245921 | S33: ='[4]14'!$P$21 -> 428023 | T33: ='[5]15'!$P$21 -> 212137 | AL33: =SUM(F33:AI33) -> 5132101
C34: STEARIN | D34: 6429000 | E34: Kg | F34: ='[1]01 '!$P$29 -> 198816 | G34: ='[1]02'!$P$29 -> 203229 | H34: ='[1]03'!$P$28 -> 187481 | I34: ='[1]04'!$P$30 -> 290816 | J34: ='[1]05'!$P$28 -> 225296 | K34: ='[1]06'!$P$28 -> 182848 | L34: ='[1]07'!$P$28 -> 106305 | M34: 0 | N34: ='[1]09'!$P$28 -> 96081 | O34: 0 | P34: ='[3]11'!$P$28 -> 169774 | Q34: ='[4]12'!$P$28 -> 111127 | R34: ='[4]13'!$P$30 -> 83059 | S34: ='[4]14'!$P$30 -> 191480 | T34: ='[5]15'!$P$29 -> 137546 | AL34: =SUM(F34:AI34) -> 2183858
C35: Fractionation OLEIN IV 60 | AL35: Olein IV 60
C36: CPO Consume | E36: Kg | AL36: =SUM(F36:O36) -> 0
C37: RBDPO Brand Consume | E37: Kg | F37: =F39+F40 -> 0 | G37: =G39+G40 -> 0 | H37: =H39+H40 -> 0 | I37: =I39+I40 -> 0 | J37: =J39+J40 -> 0 | K37: =K39+K40 -> 0 | L37: =L39+L40 -> 0 | M37: =M39+M40 -> 0 | ... AJ37: =AJ39+AJ40 -> 0 | AL37: =SUM(F37:O37) -> 0
C38: OLEIN IV 60 Bulk | E38: Kg | F38: 0 | G38: 0 | H38: 0 | AL38: =SUM(F38:O38) -> 0
C39: OLEIN IV 60 Salvaco | E39: Kg | F39: 0 | G39: 0 | H39: 0 | AL39: =SUM(F39:O39) -> 0
C40: SOFT STEARIN | E40: Kg | F40: 0 | G40: 0 | H40: 0 | AL40: =SUM(F40:O40) -> 0
...

Sheet Juli - 2024 ( Revisi )
B1: PRODUCTION REPORT
B2: No | C2: ITEM | D2: Budget / Norma | E2: UoM | F2: Juli | AL2: TOTAL (Kg)
F3: 1 | G3: 2 | H3: 3 | I3: 4 | J3: 5 | K3: 6 | L3: 7 | M3: 8 | N3: 9 | O3: 10 | P3: 11 | Q3: 12 | R3: 13 | S3: 14 | T3: 15 | U3: 16 | V3: 17 | W3: 18 | X3: 19 | Y3: 20 | Z3: 21 | AA3: 22 | AB3: 23 | AC3: 24 | AD3: 25 | AE3: 26 | AF3: 27 | AG3: 28 | AH3: 29 | AI3: 30 | AJ3: 31
B4: 1 | C4: PRODUCTION | AL4: Production
C5: Refinery | AL5: Refinery
C6: Running Days | E6: Day | F6: 1 | G6: 1 | H6: 1 | I6: 1 | J6: 1 | K6: 1 | L6: 1 | M6: 1 | N6: 1 | O6: 1 | P6: 1 | Q6: 1 | R6: 1 | S6: 1 | T6: 0 | U6: 0 | V6: 0 | W6: 0 | X6: 0 | Y6: 0 | Z6: 0 | AA6: 0 | AB6: 0 | AC6: 1 | AD6: 1 | AE6: 1 | AF6: 1 | AG6: 1 | AH6: 1 | AI6: 1 | AJ6: 1 | AL6: =SUM(F6:AJ6) -> 22
C7: Incoming CPO | E7: Kg | F7: ='[1]01 '!$P$14 -> 865877 | G7: ='[1]02'!$P$14 -> 1020502 | H7: ='[1]03'!$P$14 -> 623069 | I7: ='[1]04'!$P$14 -> 686156 | J7: ='[1]05'!$P$14 -> 500524 | K7: ='[1]06'!$P$14 -> 286477 | L7: ='[1]07'!$P$11 -> 40800 | M7: ='[1]08'!$P$13+168651 -> 335707 | N7: ='[1]09'!$P$13 -> 203264 | O7: ='[2]10'!$P$14-22440 -> 803740 | P7: ='[3]11'!$P$14 -> 474327 | Q7: ='[4]12'!$P$13+156887 -> 486876 | R7: =186434+'[4]13'!$P$13 -> 412792 | S7: 0 | T7: 309039 | U7: ='[6]16'!$P$13 -> 24674 | V7: =24919 -> 24919 | W7: 27425 | X7: 734033 | Y7: 1566855 | Z7: 606233 | AA7: 1510637 | AB7: 1230774 | AC7: ='[7]24'!$P$11 -> 1168304 | AD7: 720906 | AE7: ='[8]26'!$P$14+107603 -> 875445 | AF7: ='[8]27'!$P$13 -> 703530 | AG7: 0 | AH7: ='[9]29'!$P$14 -> 290049 | AI7: ='[10]30'!$P$14 -> 484162 | AJ7: ='[11]31 Stock Opname'!$P$14 -> 1179398 | AL7: =SUM(F7:AJ7) -> 18196494 | AM7: =AVERAGE(G7:O7) -> 500026.56
C8: Ratio Run CPO | E8: % | F8: =F9/2200000*100 -> 33.991182 | G8: =G9/2200000*100 -> 38.902364 | H8: =H9/2200000*100 -> 47.427591 | I8: =I9/2200000*100 -> 48.454364 | J8: =J9/2200000*100 -> 1.1002273 | K8: =K9/2200000*100 -> 27.8365 | L8: =L9/2200000*100 -> 5.7276818 | M8: =M9/2200000*100 -> 11.742864 | ... AJ8: =AJ9/2200000*100 -> 30.239909 | AL8: =AVERAGE(F8:AJ8) -> 23.454544
C9: CPO Consume Total | D9: 36359000 | E9: Kg | F9: 747806 | G9: 855852 | H9: 1043407 | I9: ='[7]04'!$Q$14 -> 1065996 | J9: 24205 | K9: 612403 | L9: 126009 | M9: 258343 | N9: ='[7]09'!$Q$11 -> 165639 | O9: 512647 | P9: 441064 | Q9: 526403 | R9: ='[4]13'!$Q$13 -> 568358 | S9: 430387 | T9: 0 | U9: 0 | V9: 0 | W9: 0 | X9: 0 | Y9: 0 | Z9: 0 | AA9: 0 | AB9: 0 | AC9: 273183 | AD9: 1638148 | AE9: 1804841 | AF9: 1260772 | AG9: 1188247 | AH9: 1067679 | AI9: 719332 | AJ9: 665278 | AL9: =SUM(F9:AJ9) -> 15995999 | AM9: =AL9/D9 -> 0.43994607 | AN9: =AL9/AL6 -> 727090.86
C10: CPO Consume Poram | D10: 29045000 | E10: Kg | F10: =F9-F27-F36 -> 747806 | G10: =G9-G27-G36 -> 855852 | H10: =H9-H27-H36 -> 1043407 | I10: =I9-I27-I36 -> 1065996 | J10: =J9-J27-J36 -> 24205 | K10: =K9-K27-K36 -> 612403 | L10: =L9-L27-L36 -> 126009 | M10: =M9-M27-M36 -> 258343 | ... AJ10: =AJ9-AJ27-AJ36 -> 665278 | AL10: =SUM(F10:AJ10) -> 15995999
C11: CPO Consume Brand | D11: 7314000 | E11: Kg | F11: =F27+F36 -> 0 | G11: =G27+G36 -> 0 | H11: =H27+H36 -> 0 | I11: =I27+I36 -> 0 | J11: =J27+J36 -> 0 | K11: =K27+K36 -> 0 | L11: =L27+L36 -> 0 | M11: =M27+M36 -> 0 | ... AJ11: =AJ27+AJ36 -> 0 | AL11: =SUM(F11:AJ11) -> 0
C12: - FFA | D12: 5 | E12: % | F12: 4.03 | G12: 4.14 | H12: 4.06 | I12: =(4.12+4.17+3.97)/3 -> 4.0866667 | J12: 4.18 | K12: =4.14 -> 4.14 | L12: 4.2 | M12: 4.08 | N12: 4.16 | O12: 4.18 | P12: 4.2 | Q12: 4.22 | R12: 3.96 | S12: =(4.29+4.09)/2 -> 4.19 | T12: 0 | U12: 0 | V12: 0 | W12: 0 | X12: 0 | Y12: 0 | Z12: 0 | AA12: 0 | AB12: 0 | AC12: 0 | AD12: 3.77 | AE12: 4.19 | AF12: 4.17 | AG12: 3.79 | AH12: 3.8 | AI12: 3.81 | AJ12: 4.11 | AL12: =SUM(F12:AJ12)/AL6 -> 3.8848485
C13: - Moist & Impurities | D13: 0.5 | E13: % | F13: 0.44 | G13: 0.46 | H13: 0.455 | I13: =(0.43+0.44+0.48)/3 -> 0.45 | J13: 0.49 | K13: =(0.44+0.49)/2 -> 0.465 | L13: 0.4 | M13: 0.48 | N13: 0.4 | O13: 0.41 | P13: 0.47 | Q13: 0.4 | R13: 0.49 | S13: =(0.4+0.49)/2 -> 0.445 | T13: 0 | U13: 0 | V13: 0 | W13: 0 | X13: 0 | Y13: 0 | Z13: 0 | AA13: 0 | AB13: 0 | AC13: 0 | AD13: 0.42 | AE13: 0.42 | AF13: 0.43 | AG13: 0.43 | AH13: 0.43 | AI13: 0.41 | AJ13: 0.4 | AL13: =SUM(F13:AJ13)/AL6 -> 0.41795455
C14: - DOBI | D14: 2,20 Min | E14: % | F14: 2.21 | G14: 2.21 | H14: 2.22 | I14: 2.21 | J14: 2.21 | K14: 2.21 | L14: 2.21 | M14: 2.22 | N14: 2.21 | O14: 2.22 | P14: 2.21 | Q14: 2.21 | R14: 2.22 | S14: 2.22 | T14: 0 | U14: 0 | V14: 0 | W14: 0 | X14: 0 | Y14: 0 | Z14: 0 | AA14: 0 | AB14: 0 | AC14: 0 | AD14: 2.21 | AE14: 2.21 | AF14: 2.22 | AG14: 2.21 | AH14: 2.22 | AI14: 2.21 | AJ14: 2.22 | AL14: =SUM(F14:AJ14)/AL6 -> 2.1131818
C15: Product | AL15: Product
C16: RbdPO | D16: 34458000 | E16: Kg | F16: 667300 | G16: 695000 | H16: 814100 | I16: 760000 | J16: 0 | K16: 587100 | M16: 198135 | N16: 70837 | O16: ='[2]10'!$P$17 -> 488153 | P16: 379337 | Q16: ='[4]12'!$P$17 -> 492952 | R16: 532900 | S16: 497845 | T16: ='[7]15'!$P$15 -> 91674 | U16: 168571 | V16: 0 | W16: 0 | X16: 0 | Y16: 0 | Z16: 0 | AA16: 0 | AB16: 0 | AC16: 0 | AD16: =1457222+97800 -> 1555022 | AE16: ='[8]26'!$P$17 -> 1732070 | AF16: ='[8]27'!$P$17 -> 1207599 | AG16: ='[8]28'!$P$17 -> 1126383 | AH16: ='[9]29'!$P$15 -> 1031434 | AI16: ='[10]30'!$P$17 -> 691482 | AJ16: ='[11]31 Stock Opname'!$P$17 -> 608815 | AL16: =SUM(F16:AJ16) -> 14396709
C17: PFAD | D17: 1636000 | E17: Kg | F17: ='[7]01 '!$P$24 -> 34831 | G17: ='[12]02'!$P$24 -> 37276 | H17: ='[1]03'!$P$24 -> 46938 | I17: ='[1]04'!$P$24 -> 48667 | J17: ='[7]05'!$P$24 -> 9507 | K17: ='[7]06'!$P$24 -> 32281 | L17: ='[7]07'!$P$24 -> 5827 | M17: ='[7]08'!$P$24 -> 25683 | N17: ='[7]09'!$P$23+'[7]09'!$P$24 -> 6431 | O17: ='[2]10'!$P$23 -> 20426 | P17: ='[3]11'!$P$23 -> 23275 | Q17: ='[4]12'!$P$25 -> 27655 | R17: ='[4]13'!$P$25 -> 25803 | S17: 20173 | T17: 6643 | U17: ='[6]16'!$P$25 -> 8852 | V17: 0 | W17: 0 | X17: 0 | Y17: 0 | Z17: 0 | AA17: 0 | AB17: 0 | AC17: ='[12]24'!$P$23 -> 4207 | AD17: ='[13]25'!$P$23 -> 61867 | AE17: ='[8]26'!$P$25 -> 66898 | AF17: ='[8]27'!$P$25 -> 56338 | AG17: ='[8]28'!$P$23 -> 49512 | AH17: ='[9]29'!$P$25 -> 39750 | AI17: ='[10]30'!$P$25 -> 25672 | AJ17: ='[11]31 Stock Opname'!$P$25 -> 29120 | AL17: =SUM(F17:AJ17) -> 713632
C18: Fractionation OLEIN IV 56 | AL18: Olein IV 56
C19: RBDPO Consume | E19: Kg | AD19: =AD20+AD21 -> 160400 | AL19: =SUM(F19:AJ19) -> 160400 | AM19: =AL19+AL32 -> 11846463 | AN19: =AM19/D16 -> 0.34379427
C20: OLEIN IV 56 | E20: Kg | F20: 0 | G20: 0 | H20: 0 | I20: 0 | J20: 0 | K20: 0 | L20: 0 | M20: 0 | N20: 0 | O20: 0 | P20: 0 | Q20: 0 | R20: 0 | S20: 0 | T20: 0 | U20: 0 | V20: 0 | W20: 0 | X20: 0 | Y20: 0 | Z20: 0 | AA20: 0 | AB20: 0 | AC20: 0 | AD20: =117900+17400 -> 135300 | AE20: 0 | AF20: 0 | AG20: 0 | AH20: 0 | AI20: 0 | AJ20: 0 | AL20: =SUM(F20:AJ20) -> 135300
C21: STEARIN | E21: Kg | F21: 0 | G21: 0 | H21: 0 | I21: 0 | J21: 0 | K21: 0 | L21: 0 | M21: 0 | N21: 0 | O21: 0 | P21: 0 | Q21: 0 | R21: 0 | S21: 0 | T21: 0 | U21: 0 | V21: 0 | W21: 0 | X21: 0 | Y21: 0 | Z21: 0 | AA21: 0 | AB21: 0 | AC21: 0 | AD21: 25100 | AE21: 0 | AF21: 0 | AG21: 0 | AH21: 0 | AI21: 0 | AJ21: 0 | AL21: =SUM(F21:AJ21) -> 25100 | AS21: =AL21+AL25+AL30+AL34+AL40 -> 3603924
C22: Fractionation OLEIN IV 57 ( Bulk ) | AL22: Olein IV 57 ( Bulk )
C23: RBDPO Consume | E23: Kg | G23: =G24+G25 -> 0 | H23: =H24+H25 -> 0 | I23: =I24+I25 -> 0 | J23: =J24+J25 -> 0 | K23: =K24+K25 -> 0 | L23: =L24+L25 -> 0 | M23: =M24+M25 -> 0 | N23: =N24+N25 -> 0 | ... AJ23: =AJ24+AJ25 -> 0 | AL23: =SUM(F23:O23) -> 0
C24: OLEIN IV 57 | E24: Kg | G24: 0 | H24: 0 | I24: 0 | J24: 0 | K24: 0 | L24: 0 | M24: 0 | N24: 0 | O24: 0 | P24: 0 | Q24: 0 | R24: 0 | S24: 0 | T24: 0 | U24: 0 | V24: 0 | W24: 0 | X24: 0 | Y24: 0 | Z24: 0 | AA24: 0 | AB24: 0 | AC24: 0 | AD24: 0 | AE24: 0 | AF24: 0 | AG24: 0 | AH24: 0 | AI24: 0 | AJ24: 0 | AL24: =SUM(F24:O24) -> 0
C25: STEARIN | E25: Kg | F25: 0 | G25: 0 | H25: 0 | I25: 0 | J25: 0 | K25: 0 | L25: 0 | M25: 0 | N25: 0 | O25: 0 | P25: 0 | Q25: 0 | R25: 0 | S25: 0 | T25: 0 | U25: 0 | V25: 0 | W25: 0 | X25: 0 | Y25: 0 | Z25: 0 | AA25: 0 | AB25: 0 | AC25: 0 | AD25: 0 | AE25: 0 | AF25: 0 | AG25: 0 | AH25: 0 | AI25: 0 | AJ25: 0 | AL25: =SUM(F25:O25) -> 0
C26: Fractionation OLEIN IV 57 ( Retail ) | AL26: Olein IV 57 ( Retail )
C27: CPO Consume | E27: Kg | AL27: =SUM(F27:O27) -> 0
C28: RBDPO Brand Consume | E28: Kg | F28: =F29+F30 -> 0 | G28: =G29+G30 -> 0 | H28: =H29+H30 -> 0 | I28: =I29+I30 -> 0 | J28: =J29+J30 -> 0 | K28: =K29+K30 -> 0 | L28: =L29+L30 -> 0 | M28: =M29+M30 -> 0 | ... AJ28: =AJ29+AJ30 -> 0 | AL28: =SUM(F28:O28) -> 0
C29: OLEIN IV 57 Low Color | E29: Kg | F29: 0 | G29: 0 | H29: 0 | I29: 0 | J29: 0 | K29: 0 | L29: 0 | M29: 0 | N29: 0 | O29: 0 | P29: 0 | Q29: 0 | R29: 0 | S29: 0 | T29: 0 | U29: 0 | V29: 0 | W29: 0 | X29: 0 | Y29: 0 | Z29: 0 | AA29: 0 | AB29: 0 | AC29: 0 | AD29: 0 | AE29: 0 | AF29: 0 | AG29: 0 | AL29: =SUM(F29:O29) -> 0
C30: STEARIN | E30: Kg | F30: 0 | G30: 0 | H30: 0 | I30: 0 | J30: 0 | K30: 0 | L30: 0 | M30: 0 | N30: 0 | O30: 0 | P30: 0 | Q30: 0 | R30: 0 | S30: 0 | T30: 0 | U30: 0 | V30: 0 | W30: 0 | X30: 0 | Y30: 0 | Z30: 0 | AA30: 0 | AB30: 0 | AC30: 0 | AD30: 0 | AE30: 0 | AF30: 0 | AG30: 0 | AL30: =SUM(F30:O30) -> 0
C31: Fractionation OLEIN IV 58 ( Bulk ) | AL31: Olein IV 58 ( Bulk )
C32: RBDPO Consume | D32: =D33+D34 -> 21429000 | E32: Kg | F32: ='[7]01 '!$Q$17 -> 591593 | G32: 564467 | H32: 641245 | I32: 536407 | J32: 596711 | K32: 602775 | M32: 28866 | N32: 240533 | O32: 233007 | P32: 458470 | Q32: 253649 | R32: 543620 | S32: 809346 | T32: 0 | U32: =U33+U34 -> 0 | V32: =V33+V34 -> 0 | W32: =W33+W34 -> 0 | X32: =X33+X34 -> 0 | Y32: =Y33+Y34 -> 0 | Z32: =Z33+Z34 -> 0 | AA32: =AA33+AA34 -> 0 | AB32: =AB33+AB34 -> 0 | AC32: 271225 | AD32: ='[7]25'!$Q$17 -> 451846 | AE32: 777047 | AF32: 786689 | AG32: 638913 | AH32: 638187 | AI32: 926379 | AJ32: 1095088 | AL32: =SUM(F32:AJ32) -> 11686063 | AR32: =SUM(AH32:AJ32) -> 2659654
C33: OLEIN IV 58 | D33: 15000000 | E33: Kg | F33: ='[1]01 '!$P$21 -> 437978 | G33: ='[1]02'!$P$21 -> 502403 | H33: ='[1]03'!$P$21 -> 540182 | I33: ='[1]04'!$P$21 -> 762960 | J33: ='[1]05'!$P$21 -> 360256 | K33: ='[7]06'!$P$21 -> 451075 | L33: 210086 | M33: 0 | N33: ='[1]09'!$P$21 -> 295995 | O33: 0 | P33: ='[3]11'!$P$21 -> 478550 | Q33: ='[4]12'!$P$21 -> 209348 | R33: ='[4]13'!$P$21 -> 245921 | S33: ='[4]14'!$P$21 -> 428023 | T33: ='[5]15'!$P$21 -> 212137 | U33: 0 | V33: 0 | W33: 0 | X33: 0 | Y33: 0 | Z33: 0 | AA33: 0 | AB33: 0 | AC33: 0 | AD33: ='[13]25'!$P$21 -> 202447 | AE33: ='[8]26'!$P$21 -> 500561 | AF33: ='[8]27'!$P$21 -> 492337 | AG33: ='[8]28'!$P$21 -> 482763 | AH33: ='[9]29'!$P$21 -> 458502 | AI33: ='[10]30'!$P$21 -> 687238 | AJ33: ='[11]31 Stock Opname'!$P$21 -> 668717 | AL33: =SUM(F33:AJ33) -> 8627479 | AR33: =SUM(AH33:AJ33) -> 1814457
C34: STEARIN | D34: 6429000 | E34: Kg | F34: ='[1]01 '!$P$29 -> 198816 | G34: ='[1]02'!$P$29 -> 203229 | H34: 214354 | I34: ='[7]04'!$P$30 -> 231602 | J34: ='[7]05'!$P$30 -> 316794 | K34: ='[1]06'!$P$28 -> 182848 | L34: ='[1]07'!$P$28 -> 106305 | M34: 0 | N34: ='[1]09'!$P$28 -> 96081 | O34: 1306 | P34: ='[3]11'!$P$28 -> 169774 | Q34: ='[4]12'!$P$28 -> 111127 | R34: ='[4]13'!$P$30 -> 83059 | S34: ='[4]14'!$P$30 -> 191480 | T34: ='[5]15'!$P$29 -> 137546 | U34: 0 | V34: 0 | W34: 0 | X34: 0 | Y34: 0 | Z34: 0 | AA34: 0 | AB34: 0 | AC34: 0 | AD34: 106690 | AE34: ='[8]26'!$P$27 -> 196065 | AF34: ='[8]27'!$P$27 -> 198863 | AG34: ='[8]28'!$P$27 -> 180437 | AH34: ='[9]29'!$P$27 -> 179685 | AI34: ='[10]30'!$P$30 -> 227514 | AJ34: ='[11]31 Stock Opname'!$P$27 -> 245249 | AL34: =SUM(F34:AJ34) -> 3578824 | AR34: =SUM(AH34:AJ34) -> 652448
C35: Fractionation OLEIN IV 60 | AL35: Olein IV 60
C36: CPO Consume | E36: Kg | AL36: =SUM(F36:AJ36) -> 0
C37: RBDPO Brand Consume | E37: Kg | F37: =F39+F40 -> 0 | G37: =G39+G40 -> 0 | H37: =H39+H40 -> 0 | I37: =I39+I40 -> 0 | J37: =J39+J40 -> 0 | K37: =K39+K40 -> 0 | L37: =L39+L40 -> 0 | M37: =M39+M40 -> 0 | ... AJ37: =AJ39+AJ40 -> 0 | AL37: =SUM(F37:AJ37) -> 0
C38: OLEIN IV 60 Bulk | E38: Kg | F38: 0 | G38: 0 | H38: 0 | I38: 0 | J38: 0 | K38: 0 | L38: 0 | M38: 0 | N38: 0 | O38: 0 | P38: 0 | Q38: 0 | R38: 0 | S38: 0 | T38: 0 | U38: 0 | V38: 0 | W38: 0 | X38: 0 | Y38: 0 | Z38: 0 | AA38: 0 | AB38: 0 | AC38: 0 | AD38: 0 | AE38: 0 | AF38: 0 | AG38: 0 | AH38: 0 | AI38: 0 | AJ38: 0 | AL38: =SUM(F38:AJ38) -> 0
C39: OLEIN IV 60 Salvaco | E39: Kg | F39: 0 | G39: 0 | H39: 0 | I39: 0 | J39: 0 | K39: 0 | L39: 0 | M39: 0 | N39: 0 | O39: 0 | P39: 0 | Q39: 0 | R39: 0 | S39: 0 | T39: 0 | U39: 0 | V39: 0 | W39: 0 | X39: 0 | Y39: 0 | Z39: 0 | AA39: 0 | AB39: 0 | AC39: 0 | AD39: 0 | AE39: 0 | AF39: 0 | AG39: 0 | AH39: 0 | AI39: 0 | AJ39: 0 | AL39: =SUM(F39:AJ39) -> 0
C40: SOFT STEARIN | E40: Kg | F40: 0 | G40: 0 | H40: 0 | I40: 0 | J40: 0 | K40: 0 | L40: 0 | M40: 0 | N40: 0 | O40: 0 | P40: 0 | Q40: 0 | R40: 0 | S40: 0 | T40: 0 | U40: 0 | V40: 0 | W40: 0 | X40: 0 | Y40: 0 | Z40: 0 | AA40: 0 | AB40: 0 | AC40: 0 | AD40: 0 | AE40: 0 | AF40: 0 | AG40: 0 | AH40: 0 | AI40: 0 | AJ40: 0 | AL40: =SUM(F40:AJ40) -> 0
...

Sheet Juli - 2024( Asli )
B1: PRODUCTION REPORT
B2: No | C2: ITEM | D2: Budget / Norma | E2: UoM | F2: Juli | AL2: TOTAL (Kg)
F3: 1 | G3: 2 | H3: 3 | I3: 4 | J3: 5 | K3: 6 | L3: 7 | M3: 8 | N3: 9 | O3: 10 | P3: 11 | Q3: 12 | R3: 13 | S3: 14 | T3: 15 | U3: 16 | V3: 17 | W3: 18 | X3: 19 | Y3: 20 | Z3: 21 | AA3: 22 | AB3: 23 | AC3: 24 | AD3: 25 | AE3: 26 | AF3: 27 | AG3: 28 | AH3: 29 | AI3: 30 | AJ3: 31
B4: 1 | C4: PRODUCTION | AL4: Production
C5: Refinery | AL5: Refinery
C6: Running Days | E6: Day | F6: 1 | G6: 1 | H6: 1 | I6: 1 | J6: 1 | K6: 1 | L6: 1 | M6: 1 | N6: 1 | O6: 1 | P6: 1 | Q6: 1 | R6: 1 | S6: 1 | T6: 0 | U6: 0 | V6: 0 | W6: 0 | X6: 0 | Y6: 0 | Z6: 0 | AA6: 0 | AB6: 0 | AC6: 1 | AD6: 1 | AE6: 1 | AF6: 1 | AG6: 1 | AH6: 1 | AI6: 1 | AJ6: 1 | AL6: =SUM(F6:AJ6) -> 22
C7: Incoming CPO | E7: Kg | F7: ='[1]01 '!$P$14 -> 865877 | G7: ='[1]02'!$P$14 -> 1020502 | H7: ='[1]03'!$P$14 -> 623069 | I7: ='[1]04'!$P$14 -> 686156 | J7: ='[1]05'!$P$14 -> 500524 | K7: ='[1]06'!$P$14 -> 286477 | L7: ='[1]07'!$P$11 -> 40800 | M7: ='[1]08'!$P$13+168651 -> 335707 | N7: ='[1]09'!$P$13 -> 203264 | O7: ='[2]10'!$P$14-22440 -> 803740 | P7: ='[3]11'!$P$14 -> 474327 | Q7: ='[4]12'!$P$13+156887 -> 486876 | R7: =186434+'[4]13'!$P$13 -> 412792 | S7: 0 | T7: 309039 | U7: ='[6]16'!$P$13 -> 24674 | V7: =24919 -> 24919 | W7: 27425 | X7: 734033 | Y7: 1566855 | Z7: 606233 | AA7: 1510637 | AB7: 1230774 | AC7: ='[14]30 Jun stock Opname'!$P$14 -> 339007 | AD7: 720906 | AE7: ='[8]26'!$P$14+107603 -> 875445 | AF7: ='[8]27'!$P$13 -> 703530 | AG7: 0 | AH7: ='[9]29'!$P$14 -> 290049 | AI7: ='[10]30'!$P$14 -> 484162 | AJ7: ='[11]31 Stock Opname'!$P$14 -> 1179398 | AL7: =SUM(F7:AJ7) -> 17367197 | AM7: =AVERAGE(G7:O7) -> 500026.56 | AT7: =AL7/AL6 -> 789418.05
C8: Ratio Run CPO | E8: % | F8: =F9/2200000*100 -> 33.860182 | G8: =G9/2200000*100 -> 33.816909 | H8: =H9/2200000*100 -> 47.656136 | I8: =I9/2200000*100 -> 50.673682 | J8: =J9/2200000*100 -> 11.278455 | K8: =K9/2200000*100 -> 22.779409 | L8: =L9/2200000*100 -> 4.7349091 | M8: =M9/2200000*100 -> 14.586682 | ... AJ8: =AJ9/2200000*100 -> 30.229409 | AL8: =AVERAGE(F8:AJ8) -> 23.09772
C9: CPO Consume Total | D9: 36359000 | E9: Kg | F9: ='[1]01 '!$Q$14 -> 744924 | G9: ='[1]02'!$Q$14 -> 743972 | H9: ='[1]03'!$Q$14 -> 1048435 | I9: ='[1]04'!$Q$14 -> 1114821 | J9: ='[1]05'!$Q$14 -> 248126 | K9: ='[12]06'!$Q$14 -> 501147 | L9: 104168 | M9: 320907 | N9: 100743 | O9: 512647 | P9: 441064 | Q9: 524002 | R9: ='[4]13'!$Q$13 -> 568358 | S9: 430387 | T9: 0 | U9: 0 | V9: 0 | W9: 0 | X9: 0 | Y9: 0 | Z9: 0 | AA9: 0 | AB9: 0 | AC9: ='OIP Refinery'!D28+'[13]24'!$Q$13-'OIP Refinery'!E28 -> 29055 | AD9: ='OIP Refinery'!D29+'[13]25'!$Q$13-'OIP Refinery'!E29 -> 1610698 | AE9: ='[8]26'!$Q$13+'[8]26'!$Q$11+'OIP Refinery'!D30-'OIP Refinery'!E30 -> 1794490 | AF9: ='[8]27'!$Q$11+'OIP Refinery'!D31-'OIP Refinery'!E31 -> 1269615 | AG9: ='OIP Refinery'!D32+'[8]28'!$Q$13-'OIP Refinery'!E32 -> 1184803 | AH9: ='OIP Refinery'!D33+'[9]29'!$Q$13-'OIP Refinery'!E33 -> 1080189 | AI9: ='OIP Refinery'!D34+'[10]30'!$Q$14-'OIP Refinery'!E34 -> 715047 | AJ9: ='OIP Refinery'!D35+'[11]31 Stock Opname'!$Q$14-'OIP Refinery'!E35 -> 665047 | AL9: =SUM(F9:AJ9) -> 15752645 | AM9: =AL9/D9 -> 0.43325298 | AN9: =AL9/AL6 -> 716029.32
C10: CPO Consume Poram | D10: 29045000 | E10: Kg | F10: =F9-F27-F36 -> 744924 | G10: =G9-G27-G36 -> 743972 | H10: =H9-H27-H36 -> 1048435 | I10: =I9-I27-I36 -> 1114821 | J10: =J9-J27-J36 -> 248126 | K10: =K9-K27-K36 -> 501147 | L10: =L9-L27-L36 -> 104168 | M10: =M9-M27-M36 -> 320907 | ... AJ10: =AJ9-AJ27-AJ36 -> 665047 | AL10: =SUM(F10:AJ10) -> 15752645
C11: CPO Consume Brand | D11: 7314000 | E11: Kg | F11: =F27+F36 -> 0 | G11: =G27+G36 -> 0 | H11: =H27+H36 -> 0 | I11: =I27+I36 -> 0 | J11: =J27+J36 -> 0 | K11: =K27+K36 -> 0 | L11: =L27+L36 -> 0 | M11: =M27+M36 -> 0 | ... AJ11: =AJ27+AJ36 -> 0 | AL11: =SUM(F11:AJ11) -> 0
C12: - FFA | D12: 5 | E12: % | F12: 4.03 | G12: 4.14 | H12: 4.06 | I12: =(4.12+4.17+3.97)/3 -> 4.0866667 | J12: 4.18 | K12: =4.14 -> 4.14 | L12: 4.2 | M12: 4.08 | N12: 4.16 | O12: 4.18 | P12: 4.2 | Q12: 4.22 | R12: 3.96 | S12: =(4.29+4.09)/2 -> 4.19 | T12: 0 | U12: 0 | V12: 0 | W12: 0 | X12: 0 | Y12: 0 | Z12: 0 | AA12: 0 | AB12: 0 | AC12: 0 | AD12: 3.77 | AE12: 4.19 | AF12: 4.17 | AG12: 3.79 | AH12: 3.8 | AI12: 3.81 | AJ12: 4.11 | AL12: =SUM(F12:AJ12)/AL6 -> 3.8848485
C13: - Moist & Impurities | D13: 0.5 | E13: % | F13: 0.44 | G13: 0.46 | H13: 0.455 | I13: =(0.43+0.44+0.48)/3 -> 0.45 | J13: 0.49 | K13: =(0.44+0.49)/2 -> 0.465 | L13: 0.4 | M13: 0.48 | N13: 0.4 | O13: 0.41 | P13: 0.47 | Q13: 0.4 | R13: 0.49 | S13: =(0.4+0.49)/2 -> 0.445 | T13: 0 | U13: 0 | V13: 0 | W13: 0 | X13: 0 | Y13: 0 | Z13: 0 | AA13: 0 | AB13: 0 | AC13: 0 | AD13: 0.42 | AE13: 0.42 | AF13: 0.43 | AG13: 0.43 | AH13: 0.43 | AI13: 0.41 | AJ13: 0.4 | AL13: =SUM(F13:AJ13)/AL6 -> 0.41795455
C14: - DOBI | D14: 2,20 Min | E14: % | F14: 2.21 | G14: 2.21 | H14: 2.22 | I14: 2.21 | J14: 2.21 | K14: 2.21 | L14: 2.21 | M14: 2.22 | N14: 2.21 | O14: 2.22 | P14: 2.21 | Q14: 2.21 | R14: 2.22 | S14: 2.22 | T14: 0 | U14: 0 | V14: 0 | W14: 0 | X14: 0 | Y14: 0 | Z14: 0 | AA14: 0 | AB14: 0 | AC14: 0 | AD14: 2.21 | AE14: 2.21 | AF14: 2.22 | AG14: 2.21 | AH14: 2.22 | AI14: 2.21 | AJ14: 2.22 | AL14: =SUM(F14:AJ14)/AL6 -> 2.1131818
C15: Product | AL15: Product
C16: RbdPO | D16: 34458000 | E16: Kg | F16: 713300 | G16: 708000 | H16: 993100 | I16: 1056000 | J16: 237021 | K16: ='[12]06'!$P$15 -> 480100 | L16: 99001 | M16: 305010 | N16: 97507 | O16: ='[2]10'!$P$17 -> 488153 | P16: 417337 | Q16: ='[4]12'!$P$17 -> 492952 | R16: ='[4]13'!$P$17+3000 -> 535902 | S16: 405010 | T16: 0 | U16: 0 | V16: 0 | W16: 0 | X16: 0 | Y16: 0 | Z16: 0 | AA16: 0 | AB16: 0 | AC16: 0 | AD16: ='[13]25'!$P$17+97800 -> 1555022 | AE16: ='[8]26'!$P$17 -> 1732070 | AF16: ='[8]27'!$P$17 -> 1207599 | AG16: ='[8]28'!$P$17 -> 1126383 | AH16: ='[9]29'!$P$15 -> 1031434 | AI16: ='[10]30'!$P$17 -> 691482 | AJ16: ='[11]31 Stock Opname'!$P$17 -> 608815 | AL16: =SUM(F16:AJ16) -> 14981198
C17: PFAD | D17: 1636000 | E17: Kg | F17: ='[1]01 '!$P$24 -> 25659 | G17: ='[12]02'!$P$24 -> 37276 | H17: ='[1]03'!$P$24 -> 46938 | I17: ='[1]04'!$P$24 -> 48667 | J17: 8070 | K17: 19280 | L17: 3234 | M17: 18283 | N17: 5131 | O17: ='[2]10'!$P$23 -> 20426 | P17: ='[3]11'!$P$23 -> 23275 | Q17: ='[4]12'!$P$25 -> 27655 | R17: ='[4]13'!$P$25 -> 25803 | S17: ='[12]14'!$P$25 -> 26239 | T17: 6643 | U17: ='[6]16'!$P$25 -> 8852 | V17: 0 | W17: 0 | X17: 0 | Y17: 0 | Z17: 0 | AA17: 0 | AB17: 0 | AC17: ='[12]24'!$P$23 -> 4207 | AD17: ='[13]25'!$P$23 -> 61867 | AE17: ='[8]26'!$P$25 -> 66898 | AF17: ='[8]27'!$P$25 -> 56338 | AG17: ='[8]28'!$P$23 -> 49512 | AH17: ='[9]29'!$P$25 -> 39750 | AI17: ='[10]30'!$P$25 -> 25672 | AJ17: ='[11]31 Stock Opname'!$P$25 -> 29120 | AL17: =SUM(F17:AJ17) -> 684795
C18: Fractionation OLEIN IV 56 | AL18: Olein IV 56
C19: RBDPO Consume | E19: Kg | F19: =F20+F21 -> 0 | G19: =G20+G21 -> 0 | H19: =H20+H21 -> 0 | I19: =I20+I21 -> 0 | J19: =J20+J21 -> 0 | K19: =K20+K21 -> 0 | L19: =L20+L21 -> 0 | M19: =M20+M21 -> 0 | ... AJ19: =AJ20+AJ21 -> 0 | AL19: =SUM(F19:AJ19) -> 160400 | AM19: =AL19+AL32 -> 12278327 | AN19: =AM19/D16 -> 0.35632733 | AT19: =AL19+AL32 -> 12278327
C20: OLEIN IV 56 | E20: Kg | F20: 0 | G20: 0 | H20: 0 | I20: 0 | J20: 0 | K20: 0 | L20: 0 | M20: 0 | N20: 0 | O20: 0 | P20: 0 | Q20: 0 | R20: 0 | S20: 0 | T20: 0 | U20: 0 | V20: 0 | W20: 0 | X20: 0 | Y20: 0 | Z20: 0 | AA20: 0 | AB20: 0 | AC20: 0 | AD20: =117900+17400 -> 135300 | AE20: 0 | AF20: 0 | AG20: 0 | AH20: 0 | AI20: 0 | AJ20: 0 | AL20: =SUM(F20:AJ20) -> 135300
C21: STEARIN | E21: Kg | F21: 0 | G21: 0 | H21: 0 | I21: 0 | J21: 0 | K21: 0 | L21: 0 | M21: 0 | N21: 0 | O21: 0 | P21: 0 | Q21: 0 | R21: 0 | S21: 0 | T21: 0 | U21: 0 | V21: 0 | W21: 0 | X21: 0 | Y21: 0 | Z21: 0 | AA21: 0 | AB21: 0 | AC21: 0 | AD21: 25100 | AE21: 0 | AF21: 0 | AG21: 0 | AH21: 0 | AI21: 0 | AJ21: 0 | AL21: =SUM(F21:AJ21) -> 25100
C22: Fractionation OLEIN IV 57 ( Bulk ) | AL22: Olein IV 57 ( Bulk )
C23: RBDPO Consume | E23: Kg | F23: =F24+F25 -> 0 | G23: =G24+G25 -> 0 | H23: =H24+H25 -> 0 | I23: =I24+I25 -> 0 | J23: =J24+J25 -> 0 | K23: =K24+K25 -> 0 | L23: =L24+L25 -> 0 | M23: =M24+M25 -> 0 | ... AJ23: =AJ24+AJ25 -> 0 | AL23: =SUM(F23:O23) -> 0
C24: OLEIN IV 57 | E24: Kg | F24: 0 | G24: 0 | H24: 0 | I24: 0 | J24: 0 | K24: 0 | L24: 0 | M24: 0 | N24: 0 | O24: 0 | P24: 0 | Q24: 0 | R24: 0 | S24: 0 | T24: 0 | U24: 0 | V24: 0 | W24: 0 | X24: 0 | Y24: 0 | Z24: 0 | AA24: 0 | AB24: 0 | AC24: 0 | AD24: 0 | AE24: 0 | AF24: 0 | AG24: 0 | AH24: 0 | AI24: 0 | AJ24: 0 | AL24: =SUM(F24:O24) -> 0
C25: STEARIN | E25: Kg | F25: 0 | G25: 0 | H25: 0 | I25: 0 | J25: 0 | K25: 0 | L25: 0 | M25: 0 | N25: 0 | O25: 0 | P25: 0 | Q25: 0 | R25: 0 | S25: 0 | T25: 0 | U25: 0 | V25: 0 | W25: 0 | X25: 0 | Y25: 0 | Z25: 0 | AA25: 0 | AB25: 0 | AC25: 0 | AD25: 0 | AE25: 0 | AF25: 0 | AG25: 0 | AH25: 0 | AI25: 0 | AJ25: 0 | AL25: =SUM(F25:O25) -> 0
C26: Fractionation OLEIN IV 57 ( Retail ) | AL26: Olein IV 57 ( Retail )
C27: CPO Consume | E27: Kg | AL27: =SUM(F27:O27) -> 0
C28: RBDPO Brand Consume | E28: Kg | F28: =F29+F30 -> 0 | G28: =G29+G30 -> 0 | H28: =H29+H30 -> 0 | I28: =I29+I30 -> 0 | J28: =J29+J30 -> 0 | K28: =K29+K30 -> 0 | L28: =L29+L30 -> 0 | M28: =M29+M30 -> 0 | ... AJ28: =AJ29+AJ30 -> 0 | AL28: =SUM(F28:O28) -> 0
C29: OLEIN IV 57 Low Color | E29: Kg | F29: 0 | G29: 0 | H29: 0 | I29: 0 | J29: 0 | K29: 0 | L29: 0 | M29: 0 | N29: 0 | O29: 0 | P29: 0 | Q29: 0 | R29: 0 | S29: 0 | T29: 0 | U29: 0 | V29: 0 | W29: 0 | X29: 0 | Y29: 0 | Z29: 0 | AA29: 0 | AB29: 0 | AC29: 0 | AD29: 0 | AE29: 0 | AF29: 0 | AG29: 0 | AL29: =SUM(F29:O29) -> 0
C30: STEARIN | E30: Kg | F30: 0 | G30: 0 | H30: 0 | I30: 0 | J30: 0 | K30: 0 | L30: 0 | M30: 0 | N30: 0 | O30: 0 | P30: 0 | Q30: 0 | R30: 0 | S30: 0 | T30: 0 | U30: 0 | V30: 0 | W30: 0 | X30: 0 | Y30: 0 | Z30: 0 | AA30: 0 | AB30: 0 | AC30: 0 | AD30: 0 | AE30: 0 | AF30: 0 | AG30: 0 | AL30: =SUM(F30:O30) -> 0
C31: Fractionation OLEIN IV 58 ( Bulk ) | AL31: Olein IV 58 ( Bulk )
C32: RBDPO Consume | D32: =D33+D34 -> 21429000 | E32: Kg | F32: =F33+F34 -> 636794 | G32: =G33+G34 -> 705632 | H32: =H33+H34 -> 727663 | I32: =I33+I34 -> 1053776 | J32: =J33+J34 -> 585552 | K32: =K33+K34 -> 632355 | L32: =L33+L34 -> 315146 | M32: =M33+M34 -> 0 | ... AJ32: =AJ33+AJ34 -> 913966 | AL32: =SUM(F32:AJ32) -> 12117927
C33: OLEIN IV 58 | D33: 15000000 | E33: Kg | F33: ='[1]01 '!$P$21 -> 437978 | G33: ='[1]02'!$P$21 -> 502403 | H33: ='[1]03'!$P$21 -> 540182 | I33: ='[1]04'!$P$21 -> 762960 | J33: ='[1]05'!$P$21 -> 360256 | K33: ='[1]06'!$P$21 -> 449507 | L33: ='[1]07'!$P$21 -> 208841 | M33: 0 | N33: ='[1]09'!$P$21 -> 295995 | O33: 0 | P33: ='[3]11'!$P$21 -> 478550 | Q33: ='[4]12'!$P$21 -> 209348 | R33: ='[4]13'!$P$21 -> 245921 | S33: ='[4]14'!$P$21 -> 428023 | T33: ='[5]15'!$P$21 -> 212137 | U33: 0 | V33: 0 | W33: 0 | X33: 0 | Y33: 0 | Z33: 0 | AA33: 0 | AB33: 0 | AC33: 0 | AD33: ='[13]25'!$P$21 -> 202447 | AE33: ='[8]26'!$P$21 -> 500561 | AF33: ='[8]27'!$P$21 -> 492337 | AG33: ='[8]28'!$P$21 -> 482763 | AH33: ='[9]29'!$P$21 -> 458502 | AI33: ='[10]30'!$P$21 -> 687238 | AJ33: ='[11]31 Stock Opname'!$P$21 -> 668717 | AL33: =SUM(F33:AJ33) -> 8624666
C34: STEARIN | D34: 6429000 | E34: Kg | F34: ='[1]01 '!$P$29 -> 198816 | G34: ='[1]02'!$P$29 -> 203229 | H34: ='[1]03'!$P$28 -> 187481 | I34: ='[1]04'!$P$30 -> 290816 | J34: ='[1]05'!$P$28 -> 225296 | K34: ='[1]06'!$P$28 -> 182848 | L34: ='[1]07'!$P$28 -> 106305 | M34: 0 | N34: ='[1]09'!$P$28 -> 96081 | O34: 0 | P34: ='[3]11'!$P$28 -> 169774 | Q34: ='[4]12'!$P$28 -> 111127 | R34: ='[4]13'!$P$30 -> 83059 | S34: ='[4]14'!$P$30 -> 191480 | T34: ='[5]15'!$P$29 -> 137546 | U34: 0 | V34: 0 | W34: 0 | X34: 0 | Y34: 0 | Z34: 0 | AA34: 0 | AB34: 0 | AC34: 0 | AD34: ='[13]25'!$P$27-AD21 -> 81590 | AE34: ='[8]26'!$P$27 -> 196065 | AF34: ='[8]27'!$P$27 -> 198863 | AG34: ='[8]28'!$P$27 -> 180437 | AH34: ='[9]29'!$P$27 -> 179685 | AI34: ='[10]30'!$P$30 -> 227514 | AJ34: ='[11]31 Stock Opname'!$P$27 -> 245249 | AL34: =SUM(F34:AJ34) -> 3493261
C35: Fractionation OLEIN IV 60 | AL35: Olein IV 60
C36: CPO Consume | E36: Kg | AL36: =SUM(F36:AJ36) -> 0
C37: RBDPO Brand Consume | E37: Kg | F37: =F39+F40 -> 0 | G37: =G39+G40 -> 0 | H37: =H39+H40 -> 0 | I37: =I39+I40 -> 0 | J37: =J39+J40 -> 0 | K37: =K39+K40 -> 0 | L37: =L39+L40 -> 0 | M37: =M39+M40 -> 0 | ... AJ37: =AJ39+AJ40 -> 0 | AL37: =SUM(F37:AJ37) -> 0
C38: OLEIN IV 60 Bulk | E38: Kg | F38: 0 | G38: 0 | H38: 0 | I38: 0 | J38: 0 | K38: 0 | L38: 0 | M38: 0 | N38: 0 | O38: 0 | P38: 0 | Q38: 0 | R38: 0 | S38: 0 | T38: 0 | U38: 0 | V38: 0 | W38: 0 | X38: 0 | Y38: 0 | Z38: 0 | AA38: 0 | AB38: 0 | AC38: 0 | AD38: 0 | AE38: 0 | AF38: 0 | AG38: 0 | AH38: 0 | AI38: 0 | AJ38: 0 | AL38: =SUM(F38:AJ38) -> 0
C39: OLEIN IV 60 Salvaco | E39: Kg | F39: 0 | G39: 0 | H39: 0 | I39: 0 | J39: 0 | K39: 0 | L39: 0 | M39: 0 | N39: 0 | O39: 0 | P39: 0 | Q39: 0 | R39: 0 | S39: 0 | T39: 0 | U39: 0 | V39: 0 | W39: 0 | X39: 0 | Y39: 0 | Z39: 0 | AA39: 0 | AB39: 0 | AC39: 0 | AD39: 0 | AE39: 0 | AF39: 0 | AG39: 0 | AH39: 0 | AI39: 0 | AJ39: 0 | AL39: =SUM(F39:AJ39) -> 0
C40: SOFT STEARIN | E40: Kg | F40: 0 | G40: 0 | H40: 0 | I40: 0 | J40: 0 | K40: 0 | L40: 0 | M40: 0 | N40: 0 | O40: 0 | P40: 0 | Q40: 0 | R40: 0 | S40: 0 | T40: 0 | U40: 0 | V40: 0 | W40: 0 | X40: 0 | Y40: 0 | Z40: 0 | AA40: 0 | AB40: 0 | AC40: 0 | AD40: 0 | AE40: 0 | AF40: 0 | AG40: 0 | AH40: 0 | AI40: 0 | AJ40: 0 | AL40: =SUM(F40:AJ40) -> 0
...

Sheet Prod
B2: MONTHLY PRODUCTION REPORT
B3: PT. INDUSTRI NABATI LESTARI
B4: Periode 01 s/d 31 Juli 2024
B5: NO | C5: Item | D5: Unit | E5: Juli | H5: Remaks
E6: Budget | F6: Actual | G6: Percentage Act.
B7: 1. | C7: PRODUCTION
C8: Refinery Plant
C9: Running Days | D9: Days | E9: ='[15]Planning Production Plant 1 (22'!$M$7 -> 19 | F9: ='Juli - 2024( Asli )'!AL6 -> 22 | G9: =(F9/E9) -> 1.1578947 | H9: Tercapai
C10: CPO Incoming | D10: Kg | F10: ='Juli - 2024( Asli )'!AL7 -> 17367197
C11: CPO Consume | D11: Kg | E11: ='[15]Planning Production Plant 1 (22'!$M$10*1000 -> 36359123 | F11: ='Juli - 2024( Asli )'!AL9 -> 15752645 | G11: =(F11/E11) -> 0.43325151 | H11: Tidak Tercapai
C12: - Avg. FFA | D12: % | E12: 5 | F12: ='Juli - 2024( Asli )'!AL12 -> 3.8848485 | G12: =(F12/E12) -> 0.7769697
C13: - Avg. Moist & Impurities | D13: % | E13: 0.5 | F13: ='Juli - 2024( Asli )'!AL13 -> 0.41795455 | G13: =(F13/E13) -> 0.83590909
C14: - Avg. DOBI | D14: % | E14: 22.2 | F14: ='Juli - 2024( Asli )'!AL14 -> 2.1131818 | G14: =(F14/E14) -> 0.09518837 | K14: Done
C15: Product
C16: RBDPO | D16: Kg | E16: ='[15]Planning Production Plant 1 (22'!$M$13 -> 34457.541 | F16: ='Juli - 2024( Asli )'!AL16 -> 14981198 | G16: =(F16/E16) -> 434.77269
C17: PFAD | D17: Kg | E17: ='[15]Planning Production Plant 1 (22'!$M$39 -> 1636.1606 | F17: ='Juli - 2024( Asli )'!AL17 -> 684795 | G17: =(F17/E17) -> 418.53778
C19: Fraksinasi Plant
C20: Total Proses RBDPO | D20: Kg | E20: =E23+E36+E41 -> 21442029 | F20: ='[16]Juni - 24'!AL35 -> 7764784 | G20: =(F20/E20) -> 0.36212917 | H20: Tidak Tercapai
C21: Total Olah RBDPO ( Feed ) | D21: Kg | E21: =E23+E36+E41 -> 21442029 | F21: ='[17]September - 2024'!AM23 -> 22592969 | G21: =(F21/E21) -> 1.0536768 | H21: Tidak Tercapai
C22: Fractionation Olein IV 56
C23: RBDPO Consume | D23: Kg | E23: 13028.54 | F23: 160.4 | G23: =(F23/E23) -> 0.012311433 | H23: Tidak Tercapai
C24: Olein IV 56 | D24: Kg | E24: =E23*82% -> 10683.403 | F24: 135.3 | G24: =(F24/E24) -> 0.012664504 | H24: Tidak Tercapai
C25: Stearin | D25: Kg | E25: =E23*18% -> 2345.1372 | F25: 25.1 | G25: =(F25/E25) -> 0.010702999 | H25: Tidak Tercapai
C26: Fractionation Olein IV 57 ( Bulk )
C27: RBDPO Consume | D27: Kg | E27: 0 | F27: ='[16]Juni - 24'!AL26 -> 0 | G27: =(F27/E27) -> #DIV/0!
C28: Olein IV 57 | D28: Kg | E28: 0 | F28: ='[16]Juni - 24'!AL27 -> 0 | G28: =(F28/E28) -> #DIV/0!
C29: Stearin | D29: Kg | E29: 0 | F29: ='[16]Juni - 24'!AL28 -> 0 | G29: =(F29/E29) -> #DIV/0!
C30: Fractionation Olein IV 57 ( Retail )
C31: CPO | D31: Kg | E31: 1812101.9 | G31: =(F31/E31)*100 -> 0
C32: RBDPO Consume | D32: Kg | E32: 0 | F32: ='[16]Juni - 24'!AL31 -> 0 | G32: =(F32/E32)*100 -> #DIV/0!
C33: Olein IV 57 | D33: Kg | E33: 0 | F33: ='[16]Juni - 24'!AL32 -> 0 | G33: =(F33/E33)*100 -> #DIV/0!
C34: Stearin | D34: Kg | E34: 0 | F34: ='[16]Juni - 24'!AL33 -> 0 | G34: =(F34/E34)*100 -> #DIV/0!
C35: Fractionation Olein IV 58
C36: RBDPO Consume | D36: Kg | E36: 21429000 | F36: ='Juli - 2024( Asli )'!AL32 -> 12117927 | G36: =(F36/E36)*100 -> 56.549195 | H36: Tidak Tercapai
C37: Olein IV 58 | D37: Kg | E37: 15000000 | F37: ='Juli - 2024( Asli )'!AL33 -> 8624666 | G37: =(F37/E37)*100 -> 57.497773 | H37: Tidak Tercapai
C38: Stearin | D38: Kg | E38: 6429000 | F38: ='Juli - 2024( Asli )'!AL34 -> 3493261 | G38: =(F38/E38)*100 -> 54.335993 | H38: Tidak Tercapai
C39: Fractionation Olein IV 60
C40: CPO | E40: 2234607.2 | F40: 0 | G40: =(F40/E40)*100 -> 0
C41: RBDPO Consume | D41: Kg | E41: 0 | F41: 0 | G41: =(F41/E41)*100 -> #DIV/0!
C42: Olein IV 60 Salvaco | D42: Kg | E42: 0 | F42: 0 | G42: =(F42/E42)*100 -> #DIV/0!
...

Sheet Utility
D2: UTILITY (GAS, STEAM, WATER & POWER) REPORT
D3: PT. INDUSTRI NABATI LESTARI
D5: Periode 01 s/d 31 Juli 2024
D6: No | E6: Item | F6: Norma | G6: UoM | H6: Juli | K6: Consume CPO ( MT ) | L6: Remaks
H7: Budget | I7: Actual | J7: Percentage Act.
E9: Total Feed Raw Material CPO | K9: 15752
D10: 1. | E10: GAS CONSUMPTION
E11: Incoming *base on INL | G11: mmbtu | I11: ='Juli - 2024( Asli )'!AL216 -> 27875.59
E12: Incoming *base on Pertagas | F12: 1460.001 | G12: mmbtu | H12: ='[15]Planning Production Plant 1 (22'!$M$92 -> 28793.73 | I12: ='Juli - 2024( Asli )'!AL217 -> 26610.053 | J12: =I12/H12 -> 0.92416137 | K12: =I12/K9 -> 1.6893127 | O12: done
E13: Distribution to
E14: HP Boiler Refinery | G14: mmbtu | H14: ='[15]Planning Production Plant 1 (22'!$M$93 -> 4319.07 | I14: ='Juli - 2024( Asli )'!AL219 -> 4776.329 | J14: =I14/H14 -> 1.1058698 | K14: =I14/K9 -> 0.30322048
E15: MP Boiler | G15: mmbtu | H15: ='[15]Planning Production Plant 1 (22'!$M$94 -> 24474.66 | I15: ='Juli - 2024( Asli )'!AL220 -> 21833.724 | J15: =I15/H15 -> 0.89209509 | K15: =I15/K9 -> 1.3860922
E16: Total | G16: mmbtu | H16: =SUM(H14:H15) -> 28793.73 | I16: =I14+I15 -> 26610.053 | J16: =I16/H16 -> 0.92416137 | K16: =SUM(K14+K15) -> 1.6893127
D17: 2. | E17: STEAM CONSUMPTION
E18: Incoming | G18: Kg | H18: ='[15]Planning Production Plant 1 (22'!$M$97 -> 10080000 | I18: ='Juli - 2024( Asli )'!AL223 -> 4916977 | J18: =I18/H18 -> 0.48779534 | K18: =I18/$K$9 -> 312.14938
E19: Distribution to | K19: =I19/$K$9 -> 0
E20: Refinery | F20: < 90 | G20: Kg | H20: ='[15]Planning Production Plant 1 (22'!$M$98 -> 3780000 | I20: ='Juli - 2024( Asli )'!AL225 -> 3311110 | J20: =I20/H20 -> 0.87595503 | K20: =I20/$K$9 -> 210.20251
E21: Fractionation | F21: < 61 | G21: Kg | H21: ='[15]Planning Production Plant 1 (22'!$M$99 -> 2562000 | I21: ='Juli - 2024( Asli )'!AL226 -> 1238750 | J21: =I21/H21 -> 0.48350898 | K21: =I21/$K$9 -> 78.640808
E22: Others | F22: 106000 | G22: Kg | H22: ='[15]Planning Production Plant 1 (22'!$M$100 -> 3738000 | I22: ='Juli - 2024( Asli )'!AL227 -> 367117 | J22: =I22/H22 -> 0.098212146 | K22: =I22/$K$9 -> 23.306056
E23: Total | G23: Kg | H23: =SUM(H20:H22) -> 10080000 | I23: =SUM(I20:I22) -> 4916977 | J23: =I23/H23 -> 0.48779534 | K23: =I23/$K$9 -> 312.14938
D24: 3. | E24: WATER CONSUMPTION
E25: Incoming Raw Water | G25: m3 | H25: ='[15]Planning Production Plant 1 (22'!$M$102 -> 21136.71 | I25: ='Juli - 2024( Asli )'!AL230 -> 18760 | J25: =I25/H25 -> 0.88755535 | K25: =I25/$K$9 -> 1.1909599
E26: - Suplay To RO Product | H26: ='[15]Planning Production Plant 1 (22'!$M$105 -> 12259.8 | I26: ='Juli - 2024( Asli )'!AL234 -> 8167.3 | K26: =I26/$K$9 -> 0.51849289
E27: - Suplay To Proses dan Sanitary | H27: =SUM(H29:H31) -> 8876.91 | I27: =SUM(I29:I31) -> 10938.7 | K27: =I27/$K$9 -> 0.69443245
E28: Rincian Outgoing Proses | K28: =I28/$K$9 -> 0
E29: Softener Product (to Refinery) | F29: < 0,5 | G29: m3 | H29: ='[15]Planning Production Plant 1 (22'!$M$103 -> 1681.47 | I29: ='Juli - 2024( Asli )'!AL232 -> 3095 | J29: =I29/H29 -> 1.8406513 | K29: =I29/$K$9 -> 0.19648299
E30: Softener Product (to Fractionation) | F30: < 0,4 | G30: m3 | H30: ='[15]Planning Production Plant 1 (22'!$M$104 -> 2904.51 | I30: ='Juli - 2024( Asli )'!AL233 -> 1579 | J30: =I30/H30 -> 0.54363731 | K30: =I30/$K$9 -> 0.10024124
E31: Others | G31: m3 | H31: 4290.93 | I31: ='Juli - 2024( Asli )'!AL235 -> 6264.7 | J31: =I31/H31 -> 1.4599865 | K31: =I31/$K$9 -> 0.39770823
E32: Total | G32: m3 | H32: =SUM(H26:H27) -> 21136.71 | I32: =SUM(I26:I27) -> 19106 | J32: =I32/H32 -> 0.90392497 | K32: =I32/$K$9 -> 1.2129253
D33: 4 | E33: POWER CONSUMPTION
E34: Incoming
E35: PLN *base on BA Kinra | G35: Kwh | H35: 568099 | I35: ='Juli - 2024( Asli )'!AL239 -> 538900 | J35: =I35/H35 -> 0.94860227 | K35: =I35/$K$9 -> 34.211529
E36: Outgoing | K36: =I36/$K$9 -> 0
E37: - Physical Refinery Plant | F37: 5404.17 | G37: Kwh | H37: 102679 | I37: ='Juli - 2024( Asli )'!AL242 -> 69700 | J37: =I37/H37 -> 0.67881456 | K37: =I37/$K$9*1000 -> 4424.8349
E38: - Refinery - Cooling Water System | F38: 3850.42 | G38: Kwh | H38: 73158 | I38: ='Juli - 2024( Asli )'!AL243 -> 65890 | J38: =I38/H38 -> 0.90065338 | K38: =I38/$K$9*1000 -> 4182.9609
E39: - Refinery - Utilities | F39: 11.81 | G39: Kwh | H39: 212 | I39: ='Juli - 2024( Asli )'!AL248 -> 748.31 | J39: =I39/H39 -> 3.5297642 | K39: =I39/$K$9*1000 -> 47.505714
E40: - Dry Fractionation Plant | F40: 5759.67 | G40: Kwh | H40: 109440 | I40: ='Juli - 2024( Asli )'!AL245 -> 71800 | J40: =I40/H40 -> 0.65606725 | K40: =I40/$K$9*1000 -> 4558.1513
E41: - Dry Fractionation CW System | F41: 1308.96 | G41: Kwh | H41: 28747 | I41: ='Juli - 2024( Asli )'!AL246 -> 19517 | J41: =I41/H41 -> 0.67892302 | K41: =I41/$K$9*1000 -> 1239.0173
E42: - Lighting - Refinery & Dry Fractionation | F42: 241.12 | G42: Kwh | H42: 4581 | I42: ='Juli - 2024( Asli )'!AL249 -> 7628.8 | J42: =I42/H42 -> 1.6653133 | K42: =I42/$K$9*1000 -> 484.30675
D44: Note untuk Power Consumption
...

Sheet Qty cons analysis
D2: Quantity Utility Consumption Analysis (based on Guarantee Utility Consumption)
D3: Refinery & Fractionation Plant
D4: Periode 01 s/d 31 Juli 2024
D5: Consumption | E5: UoM | F5: Budget | G5: Actual | H5: Under (Over) Budget | I5: Explanation Under / Over budget
D6: CPO Consume | E6: Kg | F6: 36359000 | G6: ='Juli - 2024( Asli )'!AL9 -> 15752645 | H6: =G6/F6 -> 0.43325298
D7: RbdPO Consume | E7: Kg | F7: 34458000 | G7: ='Juli - 2024( Asli )'!AT19 -> 12278327 | H7: =G7/F7 -> 0.35632733
D8: TOTAL ACTUAL CONSUMPTION
D9: Refinery
D10: Bleaching Earth to Poram Spec | E10: Kg | F10: ='[15]Planning Production Plant 1 (22'!$M$78 -> 232361.57 | G10: ='Juli - 2024( Asli )'!AL56 -> 162476 | H10: =F10-G10 -> 69885.569 | L10: done
D11: Bleaching Earth to Branded Spec | E11: Kg | F11: ='[15]Planning Production Plant 1 (22'!$M$79 -> 131650.69 | G11: ='Juli - 2024( Asli )'!AL58 -> 0 | H11: =F11-G11 -> 131650.69
D12: Phosporic Acid | E12: Kg | F12: ='[15]Planning Production Plant 1 (22'!$M$83 -> 21815.474 | G12: ='Juli - 2024( Asli )'!AL60 -> 7823.782 | H12: =F12-G12 -> 13991.692
D13: Gas Consumption (MP Boiler) | E13: mmbtu | F13: ='[15]Planning Production Plant 1 (22'!$M$94 -> 24474.66 | G13: ='Juli - 2024( Asli )'!AL220+0.3 -> 21834.024 | H13: =F13-G13 -> 2640.636
D14: Gas Consumption (HP Boiler) | E14: mmbtu | F14: ='[15]Planning Production Plant 1 (22'!$M$93 -> 4319.07 | G14: ='Juli - 2024( Asli )'!AL219 -> 4776.329 | H14: =F14-G14 -> -457.25903
D15: Cooling Water top up to Cooling Tower | E15: m3 | F15: ='[15]Planning Production Plant 1 (22'!$M$103 -> 1681.47 | G15: ='Juli - 2024( Asli )'!AL232 -> 3095 | H15: =F15-G15 -> -1413.53
D16: Steam | E16: Kg | F16: ='[15]Planning Production Plant 1 (22'!$M$98 -> 3780000 | G16: ='Juli - 2024( Asli )'!AL225 -> 3311110 | H16: =F16-G16 -> 468890
D17: Power (Process Plant) | E17: Kwh | F17: ='[15]Planning Production Plant 1 (22'!$M$112 -> 113487.5 | G17: ='Juli - 2024( Asli )'!AL242 -> 69700 | H17: =F17-G17 -> 43787.5
D18: Power (Cooling Tower) | E18: Kwh | F18: ='[15]Planning Production Plant 1 (22'!$M$113 -> 80858.75 | G18: ='Juli - 2024( Asli )'!AL243 -> 65890 | H18: =F18-G18 -> 14968.75
D19: Fractionation
D20: Cooling Water top up to Cooling Tower | E20: m3 | F20: ='[15]Planning Production Plant 1 (22'!$M$104 -> 2904.51 | G20: ='Juli - 2024( Asli )'!AL233 -> 1579 | H20: =F20-G20 -> 1325.51
D21: Steam | E21: Kg | F21: ='[15]Planning Production Plant 1 (22'!$M$99 -> 2562000 | G21: ='Juli - 2024( Asli )'!AL226 -> 1238750 | H21: =F21-G21 -> 1323250
D22: Power (Process Plant) | E22: Kwh | F22: ='[15]Planning Production Plant 1 (22'!$M$115 -> 120960 | G22: ='Juli - 2024( Asli )'!AL245 -> 71800 | H22: =F22-G22 -> 49160
D23: Power (Cooling Tower) | E23: Kwh | F23: ='[15]Planning Production Plant 1 (22'!$M$116 -> 31773 | G23: ='Juli - 2024( Asli )'!AL246 -> 19517 | H23: =F23-G23 -> 12256
D24: ACTUAL CONSUMPTION PER MT RAW MATERIAL
D25: Refinery
D26: Bleaching Earth to Poram Spec | E26: Kg/MT | F26: 8 | G26: =(G10/$G$6)*1000 -> 10.314204 | H26: =F26-G26 -> -2.3142044
D27: Bleaching Earth to Branded Spec | E27: Kg/MT | F27: 16 | G27: =(G11/$G$6)*1000 -> 0 | H27: =F27-G27 -> 16
D28: Phosporic Acid | E28: Kg/MT | F28: 0.55 | G28: =(G12/$G$6)*1000 -> 0.49666466 | H28: =F28-G28 -> 0.053335345
D29: Gas Consumption (HP Boiler) | E29: Nm3/MT | F29: 4.2 | G29: =(G13/$G$6)*1000 -> 1.3860545 | H29: =F29-G29 -> 2.8139455
D30: Gas Consumption (HP Boiler) **) | E30: mmbtu/MT | F30: 0.147294 | G30: =(G14/$G$6)*1000 -> 0.30320807 | H30: =F30-G30 -> -0.15591407
D31: Cooling Water top up to Cooling Tower | E31: m3/MT | F31: 0.55 | G31: =(G15/$G$6)*1000 -> 0.19647494 | H31: =F31-G31 -> 0.35352506
D32: Steam | E32: Kg/MT | F32: 90 | G32: =(G16/$G$6)*1000 -> 210.19391 | H32: =F32-G32 -> -120.19391 | I32: Steam Refinery Over dikarenakan kapasitas tidak tercapai
D33: Power (Process Plant) | E33: Kwh/MT | F33: 3.6133333 | G33: =(G17/$G$6)*1000 -> 4.4246538 | H33: =F33-G33 -> -0.81132043 | I33: Power Over dikarenakan kapasitas tidak tercapai
D34: Power (Cooling Tower) | E34: Kwh/MT | F34: 2.1290444 | G34: =(G18/$G$6)*1000 -> 4.1827896 | H34: =F34-G34 -> -2.0537452
D35: Fractionation
D36: Cooling Water top up to Cooling Tower | E36: m3/MT | F36: 0.4 | G36: =(G20/$G$6)*1000 -> 0.10023713 | H36: =F36-G36 -> 0.29976287
D37: Steam | E37: Kg/MT | F37: 61 | G37: =(G21/$G$6)*1000 -> 78.637588 | H37: =F37-G37 -> -17.637588 | I37: Steam Over dikarenakan menggunakan 2 unit chiller
D38: Power (Process Plant) | E38: Kwh/MT | F38: 3.6996983 | G38: =(G22/$G$6)*1000 -> 4.5579647 | H38: =F38-G38 -> -0.8582664 | I38: Power Over dikarenakan kapasitas tidak tercapai
D39: Power (Cooling Tower) | E39: Kwh/MT | F39: 0.98466667 | G39: =(G23/$G$6)*1000 -> 1.2389665 | H39: =F39-G39 -> -0.25429987
D42: - BE Over dengan pemakaian consume Bleaching Earth 10,3 Kg/MT
D43: * Steam Refinery Over dikarenakan kapasitas tidak tercapai
...

Sheet Downtime Ref Juli
F2: DOWN TIME SLOW FLOWRATE PRODUCTION REFINERY
F4: Periode 01/31 Juli 2024
F5: TANGGAL | G5: CAPACITY (Kg) | H5: REMARKS | I5: Down time | M5: Tph
I6: Stop | J6: Slow | K6: % | AE6: 17 | AF6: 18 | AG6: 19 | AH6: 20 | AI6: 21 | AJ6: 22 | AK6: 23 | AL6: 24 | AM6: 25 | AN6: 26 | AO6: 27 | AP6: 28 | AQ6: 29 | AR6: 30 | AS6: 31
F7: 1 | G7: ='[1]01 '!$Q$14 -> 744924 | H7: Penyesuaian incoming CPO | J7: =(2200-(G7/1000))/91.7 -> 15.867786 | K7: =G7/2200/1000 -> 0.33860182 | M7: =(G7/1000)/24 -> 31.0385 | O7: =249.262+270.9 -> 520.162 | P7: =1356.367+39.742 -> 1396.109 | Q7: =1086.521+50.6 -> 1137.121 | R7: =1353.558+373.309 -> 1726.867 | S7: 1942.746 | T7: 1868.212 | U7: 2057.011 | V7: 1781.844 | W7: 1250.764 | X7: 1613.486 | Y7: 1325.077 | Z7: =66.442+571.568 -> 638.01 | AA7: =815.429 -> 815.429 | AB7: =352.234+731.627 -> 1083.861 | AC7: =1626.002+13.213 -> 1639.215 | AD7: 2094.791 | AE7: 2075.375 | AF7: 2008.804 | AG7: 1946.712 | AH7: 1998.939 | AI7: =1623.839+281.468 -> 1905.307 | AJ7: 1610.024 | AK7: =1135.181+98.368 -> 1233.549 | AL7: =958.893+543.852 -> 1502.745 | AM7: 2043.15 | AN7: 1762.642 | AO7: 2170.336 | AP7: =1181.38+463.711 -> 1645.091 | AQ7: 219.474 | AR7: =48.153+1225.968+107.3 -> 1381.421
F8: 2 | G8: ='[1]02'!$Q$14 -> 743972 | H8: Penyesuaian incoming CPO | J8: =(2200-(G8/1000))/91.7 -> 15.878168 | K8: =G8/2200/1000 -> 0.33816909 | M8: =(G8/1000)/24 -> 30.998833
F9: 3 | G9: ='[1]03'!$Q$14 -> 1048435 | H9: Penyesuaian incoming CPO | J9: =(2200-(G9/1000))/91.7 -> 12.557961 | K9: =G9/2200/1000 -> 0.47656136 | M9: =(G9/1000)/24 -> 43.684792
F10: 4 | G10: ='[1]04'!$Q$14 -> 1114821 | H10: Penyesuaian incoming CPO | J10: =(2200-(G10/1000))/91.7 -> 11.834013 | K10: =G10/2200/1000 -> 0.50673682 | M10: =(G10/1000)/24 -> 46.450875
F11: 5 | G11: ='[1]05'!$Q$14 -> 248126 | H11: Penyesuaian incoming CPO | J11: =(2200-(G11/1000))/91.7 -> 21.285431 | K11: =G11/2000/1000 -> 0.124063 | M11: =(G11/1000)/24 -> 10.338583
F12: 6 | G12: 501147 | H12: Penyesuaian incoming CPO | J12: =(2200-(G12/1000))/91.7 -> 18.526205 | K12: =G12/2200/1000 -> 0.22779409 | M12: =(G12/1000)/24 -> 20.881125
F13: 7 | G13: 104168 | H13: Penyesuaian incoming CPO | J13: =(2200-(G13/1000))/91.7 -> 22.855311 | K13: =G13/2200/1000 -> 0.047349091 | M13: =(G13/1000)/24 -> 4.3403333
F14: 8 | G14: 320907 | H14: Penyesuaian incoming CPO | J14: =(2200-(G14/1000))/91.7 -> 20.491745 | K14: =G14/2200/1000 -> 0.14586682 | M14: =(G14/1000)/24 -> 13.371125
F15: 9 | G15: 100743 | H15: Penyesuaian incoming CPO | J15: =(2200-(G15/1000))/91.7 -> 22.892661 | K15: =G15/2200/1000 -> 0.045792273 | M15: =(G15/1000)/24 -> 4.197625
F16: 10 | G16: 512647 | H16: Penyesuaian incoming CPO | J16: =(2200-(G16/1000))/91.7 -> 18.400796 | K16: =G16/2200/1000 -> 0.23302136 | M16: =(G16/1000)/24 -> 21.360292
F17: 11 | G17: 441064 | H17: Penyesuaian incoming CPO | J17: =(2200-(G17/1000))/91.7 -> 19.181418 | K17: =G17/2200/1000 -> 0.20048364 | M17: =(G17/1000)/24 -> 18.377667
F18: 12 | G18: 524002 | H18: Penyesuaian incoming CPO | J18: =(2200-(G18/1000))/91.7 -> 18.276968 | K18: =G18/2200/1000 -> 0.23818273 | M18: =(G18/1000)/24 -> 21.833417
F19: 13 | G19: ='[4]13'!$Q$13 -> 568358 | H19: Penyesuaian incoming CPO | J19: =(2200-(G19/1000))/91.7 -> 17.793261 | K19: =G19/2200/1000 -> 0.25834455 | M19: =(G19/1000)/24 -> 23.681583
F20: 14 | G20: 430750 | H20: Penyesuaian incoming CPO | J20: =(2200-(G20/1000))/91.7 -> 19.293893 | K20: =G20/2200/1000 -> 0.19579545 | M20: =(G20/1000)/24 -> 17.947917
F21: 15 | H21: STOP PLANT | J21: =(2200-(G21/1000))/91.7 -> 23.991276 | K21: =G21/2200/1000 -> 0 | M21: =(G21/1000)/24 -> 0
F22: 16 | H22: STOP PLANT | J22: =(2200-(G22/1000))/91.7 -> 23.991276 | K22: =G22/2200/1000 -> 0 | M22: =(G22/1000)/24 -> 0
F23: 17 | H23: STOP PLANT | J23: =(2200-(G23/1000))/91.7 -> 23.991276 | K23: =G23/2200/1000 -> 0 | M23: =(G23/1000)/24 -> 0
F24: 18 | H24: STOP PLANT | J24: =(2200-(G24/1000))/91.7 -> 23.991276 | K24: =G24/2200/1000 -> 0 | M24: =(G24/1000)/24 -> 0
F25: 19 | H25: STOP PLANT | J25: =(2200-(G25/1000))/91.7 -> 23.991276 | K25: =G25/2200/1000 -> 0 | M25: =(G25/1000)/24 -> 0
F26: 20 | H26: STOP PLANT | J26: =(2200-(G26/1000))/91.7 -> 23.991276 | K26: =G26/2200/1000 -> 0 | M26: =(G26/1000)/24 -> 0
F27: 21 | H27: STOP PLANT | J27: =(2200-(G27/1000))/91.7 -> 23.991276 | K27: =G27/2200/1000 -> 0 | M27: =(G27/1000)/24 -> 0
F28: 22 | H28: STOP PLANT | J28: =(2200-(G28/1000))/91.7 -> 23.991276 | K28: =G28/2200/1000 -> 0 | M28: =(G28/1000)/24 -> 0
F29: 23 | H29: STOP PLANT | J29: =(2200-(G29/1000))/91.7 -> 23.991276 | K29: =G29/2200/1000 -> 0 | M29: =(G29/1000)/24 -> 0
F30: 24 | G30: 29055 | H30: START UP | J30: =(2200-(G30/1000))/91.7 -> 23.674427 | K30: =G30/2200/1000 -> 0.013206818 | M30: =(G30/1000)/24 -> 1.210625
F31: 25 | G31: 1610698 | H31: Penyesuaian incoming CPO | J31: =(2200-(G31/1000))/91.7 -> 6.4264122 | K31: =G31/2200/1000 -> 0.73213545 | M31: =(G31/1000)/24 -> 67.112417
F32: 26 | G32: 1794490 | H32: Penyesuaian incoming CPO | J32: =(2200-(G32/1000))/91.7 -> 4.4221374 | K32: =G32/2200/1000 -> 0.81567727 | M32: =(G32/1000)/24 -> 74.770417
F33: 27 | G33: 1269615 | H33: Penyesuaian incoming CPO | J33: =(2200-(G33/1000))/91.7 -> 10.145965 | K33: =G33/2200/1000 -> 0.57709773 | M33: =(G33/1000)/24 -> 52.900625
F34: 28 | G34: 1184803 | H34: Penyesuaian incoming CPO | J34: =(2200-(G34/1000))/91.7 -> 11.070851 | K34: =G34/2200/1000 -> 0.53854682 | M34: =(G34/1000)/24 -> 49.366792
F35: 29 | G35: 1080189 | H35: Penyesuaian incoming CPO | J35: =(2200-(G35/1000))/91.7 -> 12.211679 | K35: =G35/2200/1000 -> 0.490995 | M35: =(G35/1000)/24 -> 45.007875
F36: 30 | G36: 715047 | H36: Penyesuaian incoming CPO | J36: =(2200-(G36/1000))/91.7 -> 16.193599 | K36: =G36/2200/1000 -> 0.32502136 | M36: =(G36/1000)/24 -> 29.793625
F37: 31 | G37: 665047 | H37: Penyesuaian incoming CPO | J37: =(2200-(G37/1000))/91.7 -> 16.738855 | K37: =G37/2200/1000 -> 0.30229409 | M37: =(G37/1000)/24 -> 27.710292
F38: TOTAL | G38: =SUM(G7:G37) -> 15753008 | I38: =SUM(I7:I37) -> 0 | J38: =SUM(J7:J37) -> 571.94103 | M38: =AVERAGE(M7:M37) -> 21.173398
G40: Summary
G41: 1. Slow flow rate due to Space Tank High | I41: 0 | J41: hours
G42: 2. Slow flow rate due to Olein IV 60 process | I42: 0 | J42: hours
G43: 3. Hold plant due to trip MP boiler & maintenance | I43: 0 | J43: hours
...

Sheet Downtime Fract Juli
F2: DOWN TIME SLOW FLOWRATE PRODUCTION FRACTIONATION
F4: Periode 01/31 Juli 2024
F5: TANGGAL | G5: CAPACITY (Kg) | H5: REMARKS | I5: Down time | M5: Tph
I6: Stop | J6: Slow | K6: % | AE6: 17 | AF6: 18 | AG6: 19 | AH6: 20 | AI6: 21 | AJ6: 22 | AK6: 23 | AL6: 24 | AM6: 25 | AN6: 26 | AO6: 27 | AP6: 28 | AQ6: 29 | AR6: 30 | AS6: 31
F7: 1 | G7: 636794 | H7: Slow flow rate due to Olein IV 58 process | J7: =(2000-(G7/1000))/83.33 -> 16.359126 | K7: =G7/2000/1000 -> 0.318397 | M7: =(G7/1000)/24 -> 26.533083 | O7: =249.262+270.9 -> 520.162 | P7: =1356.367+39.742 -> 1396.109 | Q7: =1086.521+50.6 -> 1137.121 | R7: =1353.558+373.309 -> 1726.867 | S7: 1942.746 | T7: 1868.212 | U7: 2057.011 | V7: 1781.844 | W7: 1250.764 | X7: 1613.486 | Y7: 1325.077 | Z7: =66.442+571.568 -> 638.01 | AA7: =815.429 -> 815.429 | AB7: =352.234+731.627 -> 1083.861 | AC7: =1626.002+13.213 -> 1639.215 | AD7: 2094.791 | AE7: 2075.375 | AF7: 2008.804 | AG7: 1946.712 | AH7: 1998.939 | AI7: =1623.839+281.468 -> 1905.307 | AJ7: 1610.024 | AK7: =1135.181+98.368 -> 1233.549 | AL7: =958.893+543.852 -> 1502.745 | AM7: 2043.15 | AN7: 1762.642 | AO7: 2170.336 | AP7: =1181.38+463.711 -> 1645.091 | AQ7: 219.474 | AR7: =48.153+1225.968+107.3 -> 1381.421
F8: 2 | G8: 705632 | H8: Slow flow rate due to Olein IV 58 process | J8: =(2000-(G8/1000))/83.33 -> 15.533037 | K8: =G8/2000/1000 -> 0.352816 | M8: =(G8/1000)/24 -> 29.401333
F9: 3 | G9: 727663 | H9: Slow flow rate due to Olein IV 58 process | J9: =(2000-(G9/1000))/83.33 -> 15.268655 | K9: =G9/2000/1000 -> 0.3638315 | M9: =(G9/1000)/24 -> 30.319292
F10: 4 | G10: 1053776 | H10: Slow flow rate due to Olein IV 58 process | J10: =(2000-(G10/1000))/83.33 -> 11.355142 | K10: =G10/2000/1000 -> 0.526888 | M10: =(G10/1000)/24 -> 43.907333
F11: 5 | G11: 585552 | H11: Slow flow rate due to Olein IV 58 process | J11: =(2000-(G11/1000))/83.33 -> 16.974055 | K11: =G11/2000/1000 -> 0.292776 | M11: =(G11/1000)/24 -> 24.398
F12: 6 | G12: 632355 | H12: Slow flow rate due to Olein IV 58 process | J12: =(2000-(G12/1000))/83.33 -> 16.412396 | K12: =G12/2000/1000 -> 0.3161775 | M12: =(G12/1000)/24 -> 26.348125
F13: 7 | G13: 315146 | H13: Slow flow rate due to Olein IV 58 process | J13: =(2000-(G13/1000))/83.33 -> 20.219057 | K13: =G13/2000/1000 -> 0.157573 | M13: =(G13/1000)/24 -> 13.131083
F14: 8 | H14: STOP PLANT | J14: =(2000-(G14/1000))/83.33 -> 24.00096 | K14: =G14/2000/1000 -> 0 | M14: =(G14/1000)/24 -> 0
F15: 9 | G15: 392076 | H15: Slow flow rate due to Olein IV 58 process | J15: =(2000-(G15/1000))/83.33 -> 19.29586 | K15: =G15/2000/1000 -> 0.196038 | M15: =(G15/1000)/24 -> 16.3365
F16: 10 | H16: STOP PLANT | J16: =(2000-(G16/1000))/83.33 -> 24.00096 | K16: =G16/2000/1000 -> 0 | M16: =(G16/1000)/24 -> 0
F17: 11 | G17: 648324 | H17: Slow flow rate due to Olein IV 58 process | J17: =(2000-(G17/1000))/83.33 -> 16.220761 | K17: =G17/2000/1000 -> 0.324162 | M17: =(G17/1000)/24 -> 27.0135
F18: 12 | G18: 320475 | H18: Slow flow rate due to Olein IV 58 process | J18: =(2000-(G18/1000))/83.33 -> 20.155106 | K18: =G18/2000/1000 -> 0.1602375 | M18: =(G18/1000)/24 -> 13.353125
F19: 13 | G19: 328980 | H19: Slow flow rate due to Olein IV 58 process | J19: =(2000-(G19/1000))/83.33 -> 20.053042 | K19: =G19/2000/1000 -> 0.16449 | M19: =(G19/1000)/24 -> 13.7075
F20: 14 | G20: 619503 | H20: Slow flow rate due to Olein IV 58 process | J20: =(2000-(G20/1000))/83.33 -> 16.566627 | K20: =G20/2000/1000 -> 0.3097515 | M20: =(G20/1000)/24 -> 25.812625
F21: 15 | G21: 349683 | H21: Slow flow rate due to Olein IV 58 process | J21: =(2000-(G21/1000))/83.33 -> 19.804596 | K21: =G21/2000/1000 -> 0.1748415 | M21: =(G21/1000)/24 -> 14.570125
F22: 16 | H22: STOP PLANT | J22: =(2000-(G22/1000))/83.33 -> 24.00096 | K22: =G22/2000/1000 -> 0 | M22: =(G22/1000)/24 -> 0
F23: 17 | H23: STOP PLANT | J23: =(2000-(G23/1000))/83.33 -> 24.00096 | K23: =G23/2000/1000 -> 0 | M23: =(G23/1000)/24 -> 0
F24: 18 | H24: STOP PLANT | J24: =(2000-(G24/1000))/83.33 -> 24.00096 | K24: =G24/2000/1000 -> 0 | M24: =(G24/1000)/24 -> 0
F25: 19 | H25: STOP PLANT | J25: =(2000-(G25/1000))/83.33 -> 24.00096 | K25: =G25/2000/1000 -> 0 | M25: =(G25/1000)/24 -> 0
F26: 20 | H26: STOP PLANT | J26: =(2000-(G26/1000))/83.33 -> 24.00096 | K26: =G26/2000/1000 -> 0 | M26: =(G26/1000)/24 -> 0
F27: 21 | H27: STOP PLANT | J27: =(2000-(G27/1000))/83.33 -> 24.00096 | K27: =G27/2000/1000 -> 0 | M27: =(G27/1000)/24 -> 0
F28: 22 | H28: STOP PLANT | J28: =(2000-(G28/1000))/83.33 -> 24.00096 | K28: =G28/2000/1000 -> 0 | M28: =(G28/1000)/24 -> 0
F29: 23 | H29: STOP PLANT | J29: =(2000-(G29/1000))/83.33 -> 24.00096 | K29: =G29/2000/1000 -> 0 | M29: =(G29/1000)/24 -> 0
F30: 24 | H30: STOP PLANT | J30: =(2000-(G30/1000))/83.33 -> 24.00096 | K30: =G30/2000/1000 -> 0 | M30: =(G30/1000)/24 -> 0
F31: 25 | G31: 284037 | H31: Slow flow rate due to Olein IV 58 process | J31: =(2000-(G31/1000))/83.33 -> 20.59238 | K31: =G31/2000/1000 -> 0.1420185 | M31: =(G31/1000)/24 -> 11.834875
F32: 26 | G32: 696626 | H32: Slow flow rate due to Olein IV 58 process | J32: =(2000-(G32/1000))/83.33 -> 15.641114 | K32: =G32/2000/1000 -> 0.348313 | M32: =(G32/1000)/24 -> 29.026083
