Workbook

Sheet JULI 2025
C1: PRODUCTION REPORT PMG2
C2: No | D2: ITEM | E2: Budget / Norma | F2: UoM | G2: JULI 2025 | AM2: TOTAL MONTHLY (Kg)
G3: 1 | H3: 2 | I3: 3 | J3: 4 | K3: 5 | L3: 6 | M3: 7 | N3: 8 | O3: 9 | P3: 10 | Q3: 11 | R3: 12 | S3: 13 | T3: 14 | U3: 15 | V3: 16 | W3: 17 | X3: 18 | Y3: 19 | Z3: 20 | AA3: 21 | AB3: 22 | AC3: 23 | AD3: 24 | AE3: 25 | AF3: 26 | AG3: 27 | AH3: 28 | AI3: 29 | AJ3: 30 | AK3: 31
C4: 1 | D4: PRODUCTION | AM4: Production | AO4: aktual refinery | AR4: opening stok rpo | AS4: =AS6+AS7+AS9 -> 451103 | AU4: =AM7/AM6 -> 1160465.1
D5: Refinery | AM5: Refinery | AO5: cpo feed | AP5: =AM9 -> 34566291 | AR5: sisa rbpo tank
D6: Running Days | F6: Day | M6: 1 | N6: 1 | O6: 1 | P6: 1 | Q6: 1 | R6: 1 | S6: 1 | T6: 1 | U6: 1 | V6: 1 | W6: 1 | X6: 1 | Y6: 1 | Z6: 1 | AA6: 1 | AB6: 1 | AC6: 1 | AD6: 1 | AE6: 1 | AF6: 1 | AG6: 1 | AH6: 1 | AI6: 1 | AJ6: 1 | AK6: 1 | AM6: =SUM(G6:AK6) -> 25 | AO6: rpo prod | AP6: =AM20+AM19+AM18 -> 33163713 | AR6: tk 108 | AS6: 80236
D7: Incoming CPO | F7: Kg | G7: 466886 | H7: 1042428 | I7: 598062 | J7: 1098366 | K7: 1154208 | L7: 0 | M7: 569874 | N7: 827244 | O7: 366660 | P7: 813396 | Q7: 1037784 | R7: 892776 | S7: 0 | T7: 1139271 | U7: 905494 | V7: 1258927 | W7: 1153068 | X7: 841278 | Y7: 1641495 | Z7: 490591 | AA7: 932649 | AB7: 1011790 | AC7: 1168715 | AD7: 1203986 | AE7: 1641206 | AF7: 1531753 | AG7: 214444 | AH7: 1312455 | AI7: 1108453 | AJ7: 875847 | AK7: 1712522 | AM7: =SUM(G7:AK7) -> 29011628 | AO7: pfad prod | AP7: =AM21 -> 1487076 | AR7: tk 109 | AS7: 70298
D8: Ratio Run CPO ( utilisasi kapasitas ) | F8: % | G8: =G9/2500000 -> 0 | H8: =H9/2500000 -> 0 | I8: =I9/2500000 -> 0 | J8: =J9/2500000 -> 0 | K8: =K9/2500000 -> 0 | L8: =L9/2500000 -> 0 | M8: 0 | N8: =N9/2500000 -> 0.6070164 | O8: =O9/2500000 -> 0.5988804 | P8: =P9/2500000 -> 0.740244 | Q8: =Q9/2500000 -> 0.6717804 | R8: =R9/2500000 -> 0.5541288 | S8: =S9/2500000 -> 0.6478244 | T8: =T9/2500000 -> 0.7902612 | U8: =U9/2500000 -> 0.7655548 | ... W8: =W9/2500000 -> 0.5332788 | X8: 0 | Y8: =Y9/2500000 -> 0.7316068 | Z8: =Z9/2500000 -> 0.7564572 | AA8: =AA9/2500000 -> 0.6752512 | AB8: =AB9/2500000 -> 0.740792 | AC8: =AC9/2500000 -> 0.526138 | AD8: =AD9/2500000 -> 0.5256036 | AE8: =AE9/2500000 -> 0.4035696 | AF8: =AF9/2500000 -> 0.7623712 | ... AK8: =AK9/2500000 -> 0.43194 | AM8: =AM9/2500000/AM6 -> 0.55306066 | AO8: yield rpo | AP8: =AP6/AP5*100 -> 95.942354 | AR8: total rpo tank | AS8: =AS6+AS7 -> 150534
D9: CPO Consume Total | E9: 58900000 | F9: Kg | G9: ='[1]01 (stock opname)'!$R$15 -> 0 | H9: ='[1]02'!$R$15 -> 0 | I9: 0 | J9: =[1]MTD!$R$15 -> 0 | K9: ='[1]04'!$R$15 -> 0 | L9: ='[1]05'!$R$15 -> 0 | M9: 297079 | N9: 1517541 | O9: 1497201 | P9: 1850610 | Q9: 1679451 | R9: 1385322 | S9: 1619561 | T9: 1975653 | U9: 1913887 | V9: 1413326 | W9: 1333197 | X9: 893602 | Y9: 1829017 | Z9: 1891143 | AA9: 1688128 | AB9: 1851980 | AC9: 1315345 | AD9: 1314009 | AE9: 1008924 | AF9: 1905928 | AG9: 853654 | AH9: 707016 | AI9: 709605 | AJ9: 1035262 | AK9: 1079850 | AM9: =SUM(G9:AK9) -> 34566291 | AO9: yield pfad | AP9: =AP7/AP5*100 -> 4.3020988 | AR9: oip | AS9: 300569 | AZ9: =AM9/AM6 -> 1382651.6
D10: Avg Daily Consump CPO ( MTD ) | AM10: =AM9/AM6 -> 1382651.6 | AO10: lossis | AP10: =(AP5-AP6-AP7)/AP5*100 -> -0.24445307 | AR10: total keseluruhan rpo | AS10: =AS8+AS9 -> 451103 | AZ10: =AM9/E9 -> 0.58686402
D11: CPO Consume Poram | F11: Kg | G11: =G9-G12 -> 0 | H11: =H9-H12 -> 0 | I11: =I9-I12 -> 0 | J11: =J9-J12 -> 0 | L11: =L9-L12 -> 0 | M11: =M9-M12 -> 297079 | N11: =N9-N12 -> 1517541 | O11: =O9-O12 -> 1497201 | P11: =P9-P12 -> 1850610 | Q11: =Q9-Q12 -> 1679451 | R11: =R9-R12 -> 1385322 | S11: =S9-S12 -> 1619561 | ... AC11: =AC9-AC12 -> 1315345 | AD11: 1314009 | AE11: =AE9-AE12 -> 1008924 | AF11: =AF9-AF12 -> 1905928 | AG11: =AG9-AG12 -> 853654 | AH11: =AH9-AH12 -> 707016 | AI11: =AI9-AI12 -> 709605 | AJ11: =AJ9-AJ12 -> 1035262 | AK11: =AK9-AK12 -> 1079850 | AM11: =SUM(G11:AK11) -> 34566291
D12: CPO Consume Brand | F12: Kg | G12: =G40+G49+G54 -> 0 | H12: =H40+H49+H54 -> 0 | I12: =I40+I49+I54 -> 0 | J12: =J40+J49+J54 -> 0 | K12: 0 | L12: =L40+L49+L54 -> 0 | M12: =M40+M49+M54 -> 0 | N12: =N40+N49+N54 -> 0 | O12: =O40+O49+O54 -> 0 | P12: =P40+P49+P54 -> 0 | R12: =R40+R49+R54 -> 0 | S12: 0 | T12: =T40+T49+T54 -> 0 | U12: =U40+U49+U54 -> 0 | V12: =V40+V49+V54 -> 0 | W12: =W40+W49+W54 -> 0 | X12: 0 | Y12: =Y40+Y49+Y54 -> 0 | Z12: =Z40+Z49+Z54 -> 0 | AA12: =AA40+AA49+AA54 -> 0 | AB12: =AB40+AB49+AB54 -> 0 | AC12: 0 | AD12: 0 | AE12: =AE40+AE49+AE54 -> 0 | AF12: =AF40+AF49+AF54 -> 0 | AG12: =AG40+AG49+AG54 -> 0 | AH12: =AH40+AH49+AH54 -> 0 | AJ12: =AJ40+AJ49+AJ54 -> 0 | AK12: =AK40+AK49+AK54 -> 0 | AM12: =SUM(G12:AK12) -> 0 | AO12: aktual fraksinasi | AR12: before
D13: - FFA | E13: 5 | F13: % | G13: 0 | H13: 0 | I13: 0 | J13: 0 | K13: 0 | L13: 0 | M13: 4.15 | N13: 4.18 | O13: 4.4 | P13: 4.06 | Q13: 3.845 | R13: 3.885 | S13: 3.94 | T13: 4.205 | U13: 4.315 | V13: 4.01 | W13: 3.77 | X13: 3.99 | Y13: 3.94 | Z13: 3.905 | AA13: 4.04 | AB13: =(4.07+3.82+3.75)/3 -> 3.88 | AC13: =(3.8+4.04)/2 -> 3.92 | AD13: 3.97 | AE13: 3.945 | AF13: 3.89 | AG13: 3.93 | AH13: =(3.62+3.93)/2 -> 3.775 | AI13: 3.61 | AJ13: =(3.61+3.62)/2 -> 3.615 | AK13: =(3.65+3.61)/2 -> 3.63 | AM13: =SUM(G13:AK13)/AM6 -> 3.952 | AO13: rpo feed | AP13: =AP14+AP15 -> 12309228 | AR13: tk131 | AS13: ='Oip Fract .'!T13 -> 34831
D14: - Moist & Impurities | E14: 0.5 | F14: % | G14: 0 | H14: 0 | I14: 0 | J14: 0 | K14: 0 | L14: 0 | M14: 0.39 | N14: 0.4 | O14: 0.42 | P14: 0.41 | Q14: 0.46 | R14: 0.46 | S14: 0.48 | T14: 0.45 | U14: 0.43 | V14: 0.435 | W14: 0.435 | X14: 0.45 | Y14: 0.465 | Z14: 0.475 | AA14: 0.46 | AB14: =(0.46+0.42+0.44)/3 -> 0.44 | AC14: =(0.43+0.46)/2 -> 0.445 | AD14: 0.43666667 | AE14: 0.455 | AF14: 0.465 | AG14: 0.43 | AH14: =(0.44+0.43)/2 -> 0.435 | AI14: 0.39 | AJ14: =(0.4+0.46)/2 -> 0.43 | AK14: =(0.43+0.44)/2 -> 0.435 | AM14: =SUM(G14:AK14)/AM6 -> 0.43926667 | AO14: olein 56 | AP14: =AM33 -> 9895094 | AR14: tk132 | AS14: ='Oip Fract .'!U13 -> 272307
D15: - DOBI | E15: 2,20 Min | F15: % | AM15: =SUM(G15:AK15)/AM6 -> 0 | AO15: stearin 56 | AP15: =AM34 -> 2414134 | AR15: after
D16: TANK | M16: 102 | N16: 102 | O16: 102107 | P16: 103107 | Q16: 103107 | R16: 103107 | S16: 103 | T16: 103102 | U16: 102106 | V16: 106107 | W16: 107105 | X16: 105 | Y16: 105107 | Z16: 104107 | AA16: 104 | AB16: 104106107 | AC16: 107103 | AD16: 103106105 | AE16: 105104 | AF16: 104107 | AG16: 105 | AH16: 104105 | AI16: 104 | AJ16: 104107 | AK16: 107105 | AO16: yield olein | AP16: =AP14/(AP14+AP15)*100 -> 80.387608 | AR16: tk131 | AS16: =AS13 -> 34831
D17: Product | AM17: Product | AO17: yield stearin | AP17: =AP15/(AP14+AP15)*100 -> 19.612392 | AR17: tk132 | AS17: =AS14-AP13 -> -12036921
D18: OIP RBDPO | F18: Kg | M18: 300569.36 | N18: 0 | O18: 0 | P18: 0 | Q18: 0 | R18: 0 | S18: 0 | T18: 0 | U18: 0 | V18: 0 | AM18: =SUM(M18:AK18) -> 300569.36
D19: DIRECT RBDPO FRACT | F19: Kg | N19: 53843 | O19: 0 | P19: 0 | Q19: 0 | R19: 0 | S19: 0 | T19: 0 | U19: 0 | AM19: =SUM(N19:AK19) -> 53843 | AO19: sap refinery | AR19: sisa rbdo di gudang bulky 1014 | AU19: sap.rpo.t | AV19: 2145555 | AW19: =AM20-AW20 -> 0
D20: RBDPO | E20: 55661000 | F20: Kg | N20: 1365197 | O20: 1564998 | P20: 1678118 | Q20: 1587178 | R20: 1366312 | S20: 1490762 | T20: 1838515 | U20: 1770735 | V20: 1421546 | W20: 1321961 | X20: 860939 | Y20: 1700000 | Z20: 1854033 | AA20: 1551384 | AB20: 1831540 | AC20: 1459334 | AD20: 1311592 | AE20: 1043325 | AF20: 1690449 | AG20: 841876 | AH20: 675289 | AI20: 654500 | AJ20: 938117 | AK20: 991601 | AM20: =SUM(G20:AK20) -> 32809301 | AO20: cpo feed | AP20: 17813187 | AR20: tk 108 | AS20: 195993 | AT20: =AS20-AS6 -> 115757 | AU20: sap.rpo.non.t | AV20: 30663746 | AW20: =AV19+AV20 -> 32809301 | AY20: =AM20-2145555 -> 30663746
D21: PFAD | E21: 2827000 | F21: Kg | M21: 14278 | N21: 68137 | O21: 74862 | P21: 74613 | Q21: 73664 | R21: 59574 | S21: 62387 | T21: 90023 | U21: 91173 | V21: 66426 | W21: 60361 | X21: 41550 | Y21: 73389 | Z21: 84906 | AA21: 69478 | AB21: 65976 | AC21: 59560 | AD21: 53922 | AE21: 45176 | AF21: 80746 | AG21: 41530 | AH21: 23224 | AI21: 33682 | AJ21: 38824 | AK21: 39615 | AM21: =SUM(G21:AK21) -> 1487076 | AO21: rpo prod | AP21: =17065034 -> 17065034 | AR21: tk 109 | AS21: 390524 | AT21: =AS21-AS7 -> 320226 | AU21: sap.rpo.t
D22: Fractionation | AO22: pfad prod | AP22: 748153 | AR22: total | AS22: =AS20+AS21 -> 586517 | AU22: sap.rpo.non.t
D23: Running Days | F23: Day | M23: 1 | N23: 1 | O23: 1 | P23: 1 | Q23: 1 | R23: 1 | S23: 1 | T23: 1 | U23: 1 | V23: 1 | W23: 1 | X23: 1 | Y23: 1 | Z23: 1 | AA23: 1 | AB23: 1 | AC23: 1 | AD23: 1 | AE23: 1 | AF23: 1 | AG23: 1 | AH23: 1 | AI23: 1 | AJ23: 1 | AK23: 1 | AM23: =SUM(G23:AK23) -> 25 | AR23: OIP actual | AS23: 435983 | AT23: adjust
D24: Avg Daily Consump RBDPO ( MTD ) | F24: Kg | G24: 0 | H24: 0 | I24: 0 | J24: 0 | K24: 0 | M24: 0 | N24: 0 | O24: 0 | P24: 0 | R24: 0 | S24: 0 | T24: 0 | U24: 0 | V24: 0 | W24: 0 | X24: 0 | Y24: 0 | Z24: 0 | AA24: 0 | AB24: 0 | AC24: 0 | AD24: 0 | AE24: 0 | AF24: 0 | AG24: 0 | AH24: 0 | AJ24: 0 | AK24: 0 | AM24: =AM29/AM23 -> 1270534.2 | AO24: yield rpo | AP24: =AP21/AP20*100 -> 95.800005 | AR24: stok actual | AS24: =AS22-AS23 -> 150534
D25: Total RBDPO transfer to plant | F25: Kg | N25: =511511+416468 -> 927979 | O25: 1330366 | P25: 1947000 | Q25: 1579000 | R25: 1391000 | S25: 1488800 | T25: 1812000 | U25: 1512300 | V25: 1574000 | W25: 1396153 | X25: 887000 | Y25: 1845120 | Z25: 1563000 | AA25: 1629100 | AB25: 1807900 | AC25: 1855000 | AD25: 1385000 | AE25: 940400 | AF25: 1771400 | AG25: 856700 | AH25: 702841 | AI25: 644515 | AJ25: 957300 | AK25: 971600 | AM25: =SUM(G25:AK25) -> 32775474 | AO25: yield pfad | AP25: =AP22/AP20*100 -> 4.1999952 | AR25: opening stok rpo sap | AS25: =AS23+AS24 -> 586517
D26: Stok TK 131 | E26: 559 | F26: ton | M26: ='Oip Fract .'!T13 -> 34831 | N26: ='Oip Fract .'!T14 -> 106130 | O26: ='Oip Fract .'!T15 -> 34893 | P26: ='Oip Fract .'!T16 -> 68629 | Q26: 34876 | AO26: loss | AP26: =AP20-AP21-AP22 -> 0
D27: Stok TK 132 | E27: 559 | F27: ton | M27: ='Oip Fract .'!V13 -> 33986 | N27: ='Oip Fract .'!V14 -> 33991 | O27: ='Oip Fract .'!V15 -> 34003 | P27: ='Oip Fract .'!V16 -> 40538 | Q27: 59415
D28: Ratio Run RBDPO | G28: =G29/2500000 -> 0 | H28: =H29/2500000 -> 0 | I28: =I29/2500000 -> 0 | J28: =J29/2500000 -> 0 | K28: =K29/2500000 -> 0 | L28: =L29/2500000 -> 0 | M28: =M29/2500000 -> 0.0830172 | N28: =N29/2500000 -> 0.14748 | ... W28: =W29/2500000 -> 0.6014596 | X28: 0 | Y28: =Y29/2500000 -> 0.5871016 | Z28: =Z29/2500000 -> 0.4891536 | AA28: =AA29/2500000 -> 0.6958416 | AB28: =AB29/2500000 -> 0.7353908 | AC28: 0.52886 | AD28: =AD29/2500000 -> 0.6797268 | AE28: =AE29/2500000 -> 0.422808 | AF28: =AF29/2500000 -> 0.5165264 | AG28: =AG29/2500000 -> 0.4069248 | AH28: =AH29/2500000 -> 0.4996276 | AI28: =AI29/2500000 -> 0.17587 | AJ28: =AJ29/2500000 -> 0.257858 | AK28: =AK29/2500000 -> 0.3378208 | AM28: =AM29/2500000/AM23 -> 0.5082137 | AO28: sap fraksinasi
D29: Total Proses RBDPO | E29: 35501000 | F29: Kg | G29: =SUM(G32,G36,G41,G45,G55) -> 0 | H29: =SUM(H32,H36,H41,H45,H55) -> 0 | I29: =SUM(I32,I36,I41,I45,I55) -> 0 | J29: =SUM(J32,J36,J41,J45,J55) -> 0 | L29: =SUM(L32,L36,L41,L45,L55) -> 0 | M29: =SUM(M32,M36,M41,M45,M55) -> 207543 | N29: =SUM(N32,N36,N41,N45,N55) -> 368700 | O29: =SUM(O32,O36,O41,O45,O55) -> 1392984 | P29: =SUM(P32,P36,P41,P45,P55) -> 1575153 | Q29: =SUM(Q32,Q36,Q41,Q45,Q55) -> 1878169 | R29: =SUM(R32,R36,R41,R45,R55) -> 1342545 | S29: =SUM(S32,S36,S41,S45,S55) -> 1510756 | ... AB29: =SUM(AB32,AB36,AB41,AB45,AB55) -> 1838477 | AC29: =AC46+AC47+AC56+AC57 -> 1823688 | AD29: =SUM(AD32,AD36,AD41,AD45,AD55) -> 1699317 | AE29: =SUM(AE32,AE36,AE41,AE45,AE55) -> 1057020 | AF29: =SUM(AF32,AF36,AF41,AF45,AF55) -> 1291316 | AG29: =SUM(AG32,AG36,AG41,AG45,AG55) -> 1017312 | AH29: =SUM(AH32,AH36,AH41,AH45,AH55) -> 1249069 | AI29: =SUM(AI32,AI36,AI41,AI45,AI55) -> 439675 | AJ29: =SUM(AJ32,AJ36,AJ41,AJ45,AJ55) -> 644645 | AK29: =SUM(AK32,AK36,AK41,AK45,AK55) -> 844552 | AM29: =SUM(G29:AK29) -> 31763356 | AO29: rpo feed | AP29: =AP31+AP32 -> 17792608
D30: Sisa Filling Crystalizer | F30: Kg | G30: =G25-G29 -> 0 | I30: =I25-I29 -> 0 | J30: =SUM(J33,J37,J42,J46,#REF!) -> #REF! | K30: 68473 | L30: =L25-L29 -> 0 | M30: =M25-M29 -> -207543 | N30: =N25-N29 -> 559279 | O30: =O25-O29 -> -62618 | P30: =P25-P29 -> 371847 | Q30: =Q25-Q29 -> -299169 | R30: =R25-R29 -> 48455 | S30: 122463 | T30: =T25-T29 -> 125292 | U30: =U25-U29 -> 216410 | V30: =V25-V29 -> -28726 | W30: =W25-W29 -> -107496 | X30: -255281 | Y30: =Y25-Y29 -> 377366 | Z30: =Z25-Z29 -> 340116 | AA30: =AA25-AA29 -> -110504 | AB30: =AB25-AB29 -> -30577 | AC30: 390824 | AD30: =AD25-AD29 -> -314317 | AE30: =AE25-AE29 -> -116620 | AF30: =AF25-AF29 -> 480084 | AG30: =AG25-AG29 -> -160612 | AH30: =AH25-AH29 -> -546228 | AJ30: =AJ25-AJ29 -> 312655 | AK30: =AK25-AK29 -> 127048 | AM30: =SUM(G30:AJ30) -> #REF!
D31: Fractionation OLEIN IV 56 | AM31: Olein IV 56 | AO31: olein 56 | AP31: 14624233
D32: RBDPO Consume | F32: Kg | G32: =G33+G34 -> 0 | H32: =H33+H34 -> 0 | I32: =I33+I34 -> 0 | J32: =J33+J34 -> 0 | K32: 0 | L32: =L33+L34 -> 0 | M32: =M33+M34 -> 207543 | N32: =N33+N34 -> 368700 | O32: =O33+O34 -> 1392984 | P32: =P33+P34 -> 1575153 | Q32: =Q33+Q34 -> 1878169 | R32: =R33+R34 -> 1342545 | S32: =S33+S34 -> 1510756 | ... AB32: =AB33+AB34 -> 0 | AC32: 0 | AD32: =AD33+AD34 -> 0 | AE32: =AE33+AE34 -> 0 | AF32: =AF33+AF34 -> 1148549 | AG32: =AG33+AG34 -> 0 | AH32: =AH33+AH34 -> 0 | AJ32: =AJ33+AJ34 -> 0 | AK32: =AK33+AK34 -> 0 | AM32: =SUM(G32:AK32) -> 12309228 | AO32: stearin 56 | AP32: 3168375
D33: OLEIN IV 56 | E33: 25000000 | F33: Kg | G33: 0 | H33: 0 | I33: 0 | J33: 0 | K33: 0 | L33: 0 | M33: 173519 | N33: 272300 | O33: 1154926 | P33: 1255804 | Q33: 1491769 | R33: 1088291 | S33: 1240812 | T33: 1368328 | U33: 700175 | V33: 0 | W33: 0 | X33: 291544 | Z33: 0 | AA33: 0 | AB33: 0 | AC33: 0 | AD33: 0 | AE33: 0 | AF33: 857626 | AG33: 0 | AH33: 0 | AI33: 0 | AJ33: 0 | AK33: 0 | AM33: =SUM(G33:AK33) -> 9895094 | AO33: yield olein | AP33: =AP31/(AP31+AP32)*100 -> 82.192745
D34: STEARIN | E34: 639000 | F34: Kg | G34: 0 | H34: 0 | I34: 0 | J34: 0 | K34: 0 | L34: 0 | M34: 34024 | N34: 96400 | O34: 238058 | P34: 319349 | Q34: 386400 | R34: 254254 | S34: 269944 | T34: 318380 | U34: 139018 | V34: 0 | W34: 0 | X34: 67384 | Z34: 0 | AA34: 0 | AB34: 0 | AC34: 0 | AD34: 0 | AE34: 0 | AF34: 290923 | AG34: 0 | AH34: 0 | AI34: 0 | AJ34: 0 | AK34: 0 | AM34: =SUM(G34:AK34) -> 2414134 | AO34: yiel stearin | AP34: =AP32/(AP31+AP32)*100 -> 17.807255 | AU34: =AM34+AM47 -> 8169423
D35: Fractionation OLEIN IV 57 ( Bulk ) | AM35: Olein IV 57 ( Bulk )
D36: RBDPO Consume | F36: Kg | G36: =G37+G38 -> 0 | H36: =H37+H38 -> 0 | I36: =I37+I38 -> 0 | J36: =J37+J38 -> 0 | K36: 0 | L36: =L37+L38 -> 0 | M36: =M37+M38 -> 0 | N36: =N37+N38 -> 0 | O36: =O37+O38 -> 0 | P36: =P37+P38 -> 0 | Q36: =Q37+Q38 -> 0 | R36: =R37+R38 -> 0 | S36: 0 | T36: =T37+T38 -> 0 | U36: =U37+U38 -> 0 | V36: =V37+V38 -> 0 | W36: =W37+W38 -> 0 | X36: 0 | AA36: =AA37+AA38 -> 0 | AB36: =AB37+AB38 -> 0 | AC36: 0 | AD36: =AD37+AD38 -> 0 | AE36: =AE37+AE38 -> 0 | AF36: =AF37+AF38 -> 0 | AG36: =AG37+AG38 -> 0 | AH36: =AH37+AH38 -> 0 | AJ36: =AJ37+AJ38 -> 0 | AK36: =AK37+AK38 -> 0 | AM36: =SUM(G36:AJ36) -> 0
D37: OLEIN IV 57 | F37: Kg | G37: 0 | H37: 0 | I37: 0 | J37: 0 | K37: 0 | L37: 0 | M37: 0 | N37: 0 | O37: 0 | P37: 0 | Q37: 0 | R37: 0 | S37: 0 | T37: 0 | U37: 0 | V37: 0 | W37: 0 | X37: 0 | AA37: 0 | AB37: 0 | AC37: 0 | AD37: 0 | AE37: 0 | AF37: 0 | AG37: 0 | AM37: =SUM(G37:AJ37) -> 0
D38: STEARIN | F38: Kg | G38: 0 | H38: 0 | I38: 0 | J38: 0 | K38: 0 | L38: 0 | M38: 0 | N38: 0 | O38: 0 | P38: 0 | Q38: 0 | R38: 0 | S38: 0 | T38: 0 | U38: 0 | V38: 0 | W38: 0 | X38: 0 | AA38: 0 | AB38: 0 | AC38: 0 | AD38: 0 | AE38: 0 | AF38: 0 | AG38: 0 | AM38: =SUM(G38:AJ38) -> 0
D39: Fractionation OLEIN IV 57 ( Retail ) | AM39: Olein IV 57 ( Retail )
D40: CPO Consume | F40: Kg | AM40: =SUM(G40:AJ40) -> 0
...

Sheet Peformance test Fract 1
C1: PT.INDUSTRI NABATI LESTARI
C2: Pabrik Minyak Goreng ( PMG 2 )
C3: Kantor Pusat: Komp. KEK Sei Mangkei, Kav.2-3, Kec. Bosar Maligas, Kab. Simalungun, Sumatera Utara, 21184
C4: ACTUAL PEFORMANCE / CONSUMPT REPORT FRAKSINASI PLANT | H4: Trial | I4: 1
H5: Start / Date / Time | I5: 17/12/24 ( 07.00 Wib )
H6: Finish / Date / Time | I6: 17/12/24 ( 07.00 Wib )
A8: No | B8: ITEM | C8: Kontrak LIPICO | D8: UOM | E8: TOTALIZER
A10: 1 | B10: PRODUCTION | C10: IV 56 | D10: 24 jam | E10: BEFORE | F10: AFTER | G10: TOTAL | H10: YIELD % | I10: STATUS/REMAKS
B11: Fraksinasi
B12: Running Days
B13: Incoming CPO
B14: Ratio Run CPO
B15: RBDPO Consume Total | C15: 2500 | D15: TPD | E15: 8982.8 | F15: 11717.8 | G15: =F15-E15 -> 2735 | H15: =G15/25000*10 -> 1.094 | I15: OK
B16: Avg Daily Consump CPO ( MTD )
B17: CPO Consume Poram | C17: 29045000
B18: CPO Consume Brand | C18: 7314000 | E18: =E49+E58+E63 -> 0
B19: QUALITY
B20: - FFA | C20: 0.1 | D20: % Max | H20: 0.063
B21: - Moist & Impurities | C21: 0.1 | D21: % Max | H21: 0.05
B22: - IV | C22: 52 - 52,5 | H22: 51.8
B23: - LC | H23: 2,6/20
B24: - Temp | C24: 68 | D24: ˚C Min | H24: 65
B25: TANK | H25: 108/109
B26: Product
B27: OLEIN IV 56 | C27: =C15*84% -> 2100 | D27: TPD | E27: 6537.1 | F27: 8213 | G27: =F27-E27 -> 1675.9 | H27: =G27/(G27+G32) -> 0.82838219 | I27: OK
B28: QUALITY
B29: - IV | C29: 56 | D29: Min
B30: - LC
B31: - Cloud Point ( metter ) | C31: 10 | D31: ˚C Max
B32: STEARIN | C32: =C15*16% -> 400 | E32: 2268.1 | F32: 2615.3 | G32: =F32-E32 -> 347.2 | H32: =G32/(G32+G27) -> 0.17161781 | I32: OK
B33: Fractionation
B34: Running Days
B35: Filling Langsung CR Fr Refinery | E35: 0
B36: Total Filling Crystalizer ( Feed ) | E36: 392100
B37: Avg Daily Consump RPO ( MTD )
B38: Total Proses RBDPO | E38: =SUM(E41,E45,E50,E54,E64) -> 0
B39: Sisa Filling Crystalizer | E39: =E36-E38 -> 392100
B40: Fractionation OLEIN IV 56
B41: RBDPO Consume | E41: =E42+E43 -> 0
B42: OLEIN IV 56 | E42: 0
...

Sheet Peformance Test REFINERY 1
C1: PT.INDUSTRI NABATI LESTARI
C2: Pabrik Minyak Goreng ( PMG 2 )
C3: Kantor Pusat: Komp. KEK Sei Mangkei, Kav.2-3, Kec. Bosar Maligas, Kab. Simalungun, Sumatera Utara, 21184
C4: ACTUAL PEFORMANCE / CONSUMPT REPORT REFINERY PLANT | H4: Peformance | I4: 1
H5: Start / Date / Time | I5: 17/12/24 ( 21.00 Wib )
H6: Finish / Date / Time | I6: 18/12/24 ( 21.00 Wib )
A7: No | B7: ITEM | C7: Kontrak LIPICO | D7: UOM | E7: TOTALIZER
A9: 1 | B9: PRODUCTION | E9: BEFORE | F9: AFTER | G9: TOTAL | H9: Yield ( % ) | I9: STATUS/REMAKS
B10: Refinery
B11: Running Days
B12: Incoming CPO
B13: Ratio Run CPO
B14: CPO Consume Total | C14: 2500 | D14: TPD | E14: 13533.82 | F14: 16053.42 | G14: =F14-E14 -> 2519.6 | I14: OK
B15: Avg Daily Consump CPO ( MTD )
B16: CPO Consume Poram | C16: 29045000
B17: CPO Consume Brand | C17: 7314000 | E17: =E53+E62+E67 -> 0
B18: - FFA | C18: 5 | D18: % | G18: 4
B19: - Moist & Impurities | C19: 0.5 | D19: % | G19: 0.41
B20: - DOBI | C20: 2.2 | D20: Min | G20: 2.42
B21: - TOTOX 2PV + AV | C21: 12 | D21: Max | G21: N/A
B22: - FE Content | C22: < 5 | D22: ppm | G22: N/A
B23: - PV | C23: < 4 | D23: Meg/kg | G23: N/A
B24: - Phosporus Max | C24: 25 | D24: ppm | G24: N/A
B25: TANK / TEMP | C25: 50 | D25: ˚C | G25: 50
B26: Product
B27: RBDPO | C27: =C14*94.2% -> 2355 | D27: TPD | E27: 12357.54 | F27: 14705.95 | G27: =F27-E27 -> 2348.41 | H27: =G27/G14 -> 0.93205668
B28: - FFA | C28: 0.05 | D28: % | G28: 0.06
B29: - Moist & Impurities | C29: 0.03 | D29: % | G29: 0.05
B30: - Peroxide value | D30: Nil | G30: -
B31: - Phosporous max | C31: 2 | D31: ppm | G31: N/A
B32: - LC | C32: 2.5 | D32: % | G32: 2.5
B33: - Aom stability min ( hr ) | C33: 60 | D33: min ( hr ) | G33: N/A
B34: - teste & Odor | C34: bland/Odorless | G34: N/A
B35: - temp max ( C ) | C35: 50 | D35: max˚C | G35: 50
B36: PFAD | C36: =C14*5% -> 125 | D36: TPD | E36: 572.71 | F36: 675.39 | G36: =F36-E36 -> 102.68 | H36: =G36/G14 -> 0.0407525
B37: Fractionation
B38: Running Days
B39: Filling Langsung CR Fr Refinery | E39: 0
B40: Total Filling Crystalizer ( Feed ) | E40: 392100
B41: Avg Daily Consump RPO ( MTD )
...

Sheet peformance  test REFINERY 2
A1: REFINERY PMG 2
A2: No | B2: ITEM | C2: Norma LIPICO | D2: UOM | E2: Day 2 tanggal 12/12/2024
A4: 1 | B4: PRODUCTION | E4: BEFORE | F4: AFTER | G4: TOTAL | H4: Yield ( % )
B5: Refinery
B6: Running Days
B7: Incoming CPO
B8: Ratio Run CPO
B9: CPO Consume Total | C9: 2500 | D9: TPD | E9: 5880.74 | F9: 8383.74 | G9: =F9-E9 -> 2503 | H9: =G9/2500000*100000 -> 100.12
B10: Avg Daily Consump CPO ( MTD )
B11: CPO Consume Poram | C11: 29045000
B12: CPO Consume Brand | C12: 7314000 | E12: =E43+E52+E57 -> 0
B13: - FFA | C13: 5 | D13: % | G13: 3.97
B14: - Moist & Impurities | C14: 0.5 | D14: % | G14: 0.4
B15: - DOBI | C15: 2.2 | D15: Min | G15: 2.42
B16: TANK | G16: 105
B17: Product
B18: OIP RBDPO
B19: RBDPO | C19: =C9*94.2% -> 2355 | D19: TPD | E19: 5143.38 | F19: 7493.18 | G19: =F19-E19 -> 2349.8 | H19: =G19/G9*100 -> 93.879345
B20: - FFA | C20: 0.05 | D20: % | G20: 0.043
B21: - Moist & Impurities | C21: 0.03 | D21: % | G21: 0.04
B22: - LC | C22: 2.5 | D22: % | G22: 2.5
B23: - Aom stability min ( hr ) | C23: 60 | D23: min ( hr )
B24: - teste & Odor | C24: bland/Odorless
B25: - temp max ( C ) | C25: 50 | D25: max˚C
B26: PFAD | C26: =C9*5% -> 125 | D26: TPD | E26: 243.04 | F26: 347.1 | G26: =F26-E26 -> 104.06 | H26: =G26/G9*100 -> 4.1574111
B27: Fractionation
B28: Running Days
B29: Filling Langsung CR Fr Refinery | E29: 0
B30: Total Filling Crystalizer ( Feed ) | E30: 392100
B31: Avg Daily Consump RPO ( MTD )
B32: Total Proses RBDPO | E32: =SUM(E35,E39,E44,E48,E58) -> 0
B33: Sisa Filling Crystalizer | E33: =E30-E32 -> 392100
B34: Fractionation OLEIN IV 56
B35: RBDPO Consume | E35: =E36+E37 -> 0
B36: OLEIN IV 56 | E36: 0
B37: STEARIN | E37: 0
B38: Fractionation OLEIN IV 57 ( Bulk )
B39: RBDPO Consume | E39: =E40+E41 -> 0
B40: OLEIN IV 57 | E40: 0
B41: STEARIN | E41: 0
...

Sheet HPP REF 
B2: Refinery Cost
B3: Through Put CPO Proses | N3: =('JULI 2025'!AM10)/1000 -> 1382.6516 | O3: TPD
B4: Working Day | N4: ='JULI 2025'!AM6 -> 25 | O4: Days
B5: Total CPO Process | N5: =N4*N3 -> 34566.291 | O5: MTD
B6: KURS | N6: 16000 | O6: Rp/USD
B7: No | C7: Item Cost | D7: Norma | F7: Pemakaian / Hari | H7: HK | J7: Total Pemakaian | K7: Harga / stn | M7: Total Biaya | N7: Rp / kg | O7: USD/MT
B8: 1 | C8: Bleaching Earth | D8: ='JULI 2025'!$AM$76 -> 7.8514122 | F8: =($D$8*$N$3*10) -> 108557.68 | G8: Kg/day | H8: =$N$4 -> 25 | J8: =$H$8*$F$8 -> 2713942 | K8: 2400 | M8: =$J$8*$K$8 -> 6.5134608e+09 | N8: =$M$8/($N$5*1000) -> 188.43389 | O8: =($M$8/$N$6)/$N$5 -> 11.777118
B9: 2 | C9: Phosporic acid | D9: ='JULI 2025'!$AM$84 -> 0.47753836 | F9: =($D$9*$N$3*10) -> 6602.692 | G9: Kg/day | H9: =$H$8 -> 25 | J9: =$H$9*$F$9 -> 165067.3 | K9: 17420 | M9: =$J$9*$K$9 -> 2.8754724e+09 | N9: =$M$9/($N$5*1000) -> 83.187183 | O9: =($M$9/$N$6)/$N$5 -> 5.1991989
B10: 3 | C10: Caustic Soda | D10: 29.166667 | E10: kg/day | F10: =D10 -> 29.166667 | G10: kg/day | H10: =$H$8 -> 25 | J10: =$H$10*$F$10 -> 729.16667 | K10: 15700 | M10: =$J$10*$K$10 -> 11447917 | N10: =$M$10/($N$5*1000) -> 0.3311873 | O10: =($M$10/$N$6)/$N$5 -> 0.020699206
B11: 4 | C11: Pemakaian Natural Gas HPB Geka
C12: Normal Consumption | D12: ='JULI 2025'!$AM$245 -> 0.13987313 | E12: MMBTU/MT CPO | F12: =$D$12*$N$3 -> 193.39581 | G12: MMBTU/day | H12: =$H$8 -> 25 | J12: =$H$12*$F$12 -> 4834.8953 | K12: =11.5*$N$6 -> 184000 | M12: =$J$12*$K$12 -> 8.8962074e+08 | N12: =$M$12/($N$5*1000) -> 25.736656 | O12: =($M$12/$N$6)/$N$5 -> 1.608541
C13: Penalty Below Consumption | D13: 0 | E13: MMBTU/MT CPO | F13: =$D$13*$N$3 -> 0 | G13: MMBTU/day | H13: =$H$8 -> 25 | J13: =$H$13*$F$13 -> 0 | K13: =11.5*$N$6 -> 184000 | M13: =$J$13*$K$13 -> 0 | N13: =$M$13/($N$5*1000) -> 0 | O13: =($M$13/$N$6)/$N$5 -> 0
C14: Penalty Above Consumption | D14: 0 | E14: MMBTU/MT CPO | F14: =$D$14*$N$3 -> 0 | G14: MMBTU/day | H14: =$H$8 -> 25 | J14: =$H$14*$F$14 -> 0 | K14: =11.5*$N$6 -> 184000 | M14: =$J$14*$K$14 -> 0 | N14: =$M$14/($N$5*1000) -> 0 | O14: =($M$14/$N$6)/$N$5 -> 0
B15: 5 | C15: Pemakaian Steam
C16: For Process | D16: ='JULI 2025'!AM252 -> 46.623168 | E16: Kg/MT CPO | F16: =$D$16*$N$3/1000 -> 64.4636 | G16: Ton/day | H16: =$H$8 -> 25 | J16: =$H$16*$F$16 -> 1611.59 | K16: =Steam!H15 -> 58707.905 | M16: =$J$16*$K$16 -> 94613072 | N16: =$M$16/($N$5*1000) -> 2.7371485 | O16: =($M$16/$N$6)/$N$5 -> 0.17107178
C17: Storage Tank for Heating | D17: ='JULI 2025'!$AM$256 -> 1.4679041 | E17: Kg/MT CPO | F17: =$D$17*$N$3/1000 -> 2.0296 | G17: Ton/day | H17: =$H$8 -> 25 | J17: =$H$17*$F$17 -> 50.74 | K17: =Steam!H15 -> 58707.905 | M17: =$J$17*$K$17 -> 2978839.1 | N17: =$M$17/($N$5*1000) -> 0.086177574 | O17: =($M$17/$N$6)/$N$5 -> 0.0053860984
B18: 6 | C18: Pemakaian Electrical
C19: For Process | D19: ='JULI 2025'!$AM$275 -> 9.2559748 | E19: kW/MT CPO | F19: =$D$19*$N$3 -> 12797.789 | G19: kW/day | H19: =$H$8 -> 25 | I19: 0 | J19: =$H$19*$F$19 -> 319944.72 | K19: 1550 | L19: =[2]Electric!H21 -> 3666.6667 | M19: =($F$19*$H$19*$K$19)+($F$19*$I$19*$L$19) -> 4.9591432e+08 | N19: =$M$19/($N$5*1000) -> 14.346761 | O19: =($M$19/$N$6)/$N$5 -> 0.89667256
C20: Cooling Tower | D20: ='JULI 2025'!$AM$277 -> 6.5333304 | E20: kW/MT CPO | F20: =$D$20*$N$3 -> 9033.32 | G20: kW/day | H20: =$H$8 -> 25 | I20: 0 | J20: =$H$20*$F$20 -> 225833 | K20: 1550 | L20: =L19 -> 3666.6667 | M20: =(F20*H20*K20)+(F20*I20*L20) -> 3.5004115e+08 | N20: =$M$20/($N$5*1000) -> 10.126662 | O20: =($M$20/$N$6)/$N$5 -> 0.63291638
C21: Storage Tank | D21: 0.3377877 | E21: kW/MT CPO | F21: =$D$21*$N$3 -> 467.04272 | G21: kW/day | H21: =$H$8 -> 25 | I21: 0 | J21: =$H$21*$F$21 -> 11676.068 | K21: 1550 | L21: =L20 -> 3666.6667 | M21: =($F$21*$H$21*$K$21)+($F$21*$I$21*$L$21) -> 18097905 | N21: =$M$21/($N$5*1000) -> 0.52357093 | O21: =($M$21/$N$6)/$N$5 -> 0.032723183
B22: 7 | C22: Pemakaian Water
C23: Make Up CT | D23: ='JULI 2025'!$AM$262 -> 12.931674 | E23: M3/day | F23: =$D$23 -> 12.931674 | G23: M3/day | H23: =$H$8 -> 25 | J23: =$H$23*$F$23 -> 323.29185 | K23: =WTP!H13 -> 9401.4761 | M23: =$J$23*$K$23 -> 3039420.6 | N23: =$M$23/($N$5*1000) -> 0.087930191 | O23: =($M$23/$N$6)/$N$5 -> 0.0054956369
B24: 8 | C24: Chemical Water | N24: =$M$24/($N$5*1000) -> 0 | O24: =($M$24/$N$6)/$N$5 -> 0
C25: EONBAC BC 3108 | D25: 0.4 | E25: Kg/day | F25: =D25 -> 0.4 | G25: Kg/day | H25: =$H$8 -> 25 | J25: =$H$25*$F$25 -> 10 | K25: 27240 | M25: =$J$25*$K$25 -> 272400 | N25: =$M$25/($N$5*1000) -> 0.0078805099 | O25: =($M$25/$N$6)/$N$5 -> 0.00049253187
C26: EONLINE T722 | D26: 0.66 | E26: Kg/day | F26: =D26 -> 0.66 | G26: Kg/day | H26: =$H$8 -> 25 | J26: =$H$26*$F$26 -> 16.5 | K26: 29120 | M26: =$J$26*$K$26 -> 480480 | N26: =$M$26/($N$5*1000) -> 0.013900247 | O26: =($M$26/$N$6)/$N$5 -> 0.00086876547
C27: EONLINE AG5770 | D27: 0.41 | E27: Kg/day | F27: =D27 -> 0.41 | G27: Kg/day | H27: =$H$8 -> 25 | J27: =$H$27*$F$27 -> 10.25 | K27: 117212 | M27: =$J$27*$K$27 -> 1201423 | N27: =$M$27/($N$5*1000) -> 0.03475707 | O27: =($M$27/$N$6)/$N$5 -> 0.0021723169
C28: EONScale T2511 | D28: 0.1 | E28: Kg/day | F28: =D28 -> 0.1 | G28: Kg/day | H28: =$H$8 -> 25 | J28: =$H$28*$F$28 -> 2.5 | K28: 45940 | M28: =$J$28*$K$28 -> 114850 | N28: =$M$28/($N$5*1000) -> 0.0033226012 | O28: =($M$28/$N$6)/$N$5 -> 0.00020766258
B29: 9 | C29: Others
C30: Filter Bag 10 Microne | D30: 0.90361446 | E30: Pcs/day | F30: =D30 -> 0.90361446 | G30: Pcs/day | H30: =$H$8 -> 25 | J30: =$H$30*$F$30 -> 22.590361 | K30: 40000 | M30: =$J$30*$K$30 -> 903614.46 | N30: =$M$30/($N$5*1000) -> 0.026141493 | O30: =($M$30/$N$6)/$N$5 -> 0.0016338433
C31: Filter Bag 100 Microne | D31: 0.63253012 | E31: Pcs/day | F31: =D31 -> 0.63253012 | G31: Pcs/day | H31: =$H$8 -> 25 | J31: =$H$31*$F$31 -> 15.813253 | K31: 125000 | M31: =$J$31*$K$31 -> 1976656.6 | N31: =$M$31/($N$5*1000) -> 0.057184516 | O31: =($M$31/$N$6)/$N$5 -> 0.0035740323
C32: Filter Cartridge 10 Microne | D32: 1.5666667 | E32: Pcs/day | F32: =D32 -> 1.5666667 | G32: Pcs/day | H32: =$H$8 -> 25 | J32: =$H$32*$F$32 -> 39.166667 | K32: 145000 | M32: =$J$32*$K$32 -> 5679166.7 | N32: =$M$32/($N$5*1000) -> 0.16429783 | O32: =($M$32/$N$6)/$N$5 -> 0.010268614
C33: Filter Dustbag | D33: 0.12048193 | E33: Pcs/day | F33: =D33 -> 0.12048193 | G33: Pcs/day | H33: =$H$8 -> 25 | J33: =$H$33*$F$33 -> 3.0120482 | K33: 682500 | M33: =$J$33*$K$33 -> 2055722.9 | N33: =$M$33/($N$5*1000) -> 0.059471897 | O33: =($M$33/$N$6)/$N$5 -> 0.0037169936
C34: O Ring Filter Leaves | D34: 3.6144578 | E34: Pcs/day | F34: =D34 -> 3.6144578 | G34: Pcs/day | H34: =$H$8 -> 25 | J34: =$H$34*$F$34 -> 90.361446 | K34: 14500 | M34: =$J$34*$K$34 -> 1310241 | N34: =$M$34/($N$5*1000) -> 0.037905165 | O34: =($M$34/$N$6)/$N$5 -> 0.0023690728
B35: 10 | C35: Waste Water Treatment Plant ( WWTP ) | D35: ='JULI 2025'!$AM$268 -> 213.48 | E35: M3/day | F35: =D35 -> 213.48 | G35: M3/day | H35: =$H$8 -> 25 | J35: =$H$35*$F$35 -> 5337 | K35: =WWTP!H17 -> 19784.726 | M35: =$J$35*$K$35 -> 1.0559108e+08 | N35: =$M$35/($N$5*1000) -> 3.0547415 | O35: =($M$35/$N$6)/$N$5 -> 0.19092135
B36: 11 | C36: SHE
C37: SBE | D37: ='JULI 2025'!$AM$88 -> 273743.48 | E37: Kg/day | F37: =D37 -> 273743.48 | G37: Kg/day | H37: =$H$8 -> 25 | J37: =$F$37 -> 273743.48 | K37: 0 | M37: =$J$37*$K$37 -> 0 | N37: =$M$37/($N$5*1000) -> 0 | O37: =($M$37/$N$6)/$N$5 -> 0
C38: Domestic | D38: 0.1 | E38: Trip/day | F38: =D38 -> 0.1 | G38: Trip/day | H38: =$H$8 -> 25 | J38: =$H$38*$F$38 -> 2.5 | K38: 303030.3 | M38: =$J$38*$K$38 -> 757575.76 | N38: =$M$38/($N$5*1000) -> 0.021916605 | O38: =($M$38/$N$6)/$N$5 -> 0.0013697878
B39: 12 | C39: Chemical Consumption | N39: =$M$39/($N$5*1000) -> 0 | O39: =($M$39/$N$6)/$N$5 -> 0
C40: LAB Chemical | D40: =lab!H33 -> 745255.21 | E40: Rp/day | F40: =D40 -> 745255.21 | G40: Rp/day | H40: =$H$8 -> 25 | M40: =$H$40*$F$40 -> 18631380 | N40: =$M$40/($N$5*1000) -> 0.53900432 | O40: =($M$40/$N$6)/$N$5 -> 0.03368777
C41: Chemical Boiler dan WTP | D41: =lab!H54 -> 259161.44 | E41: Rp/day | F41: =D41 -> 259161.44 | G41: Rp/day | H41: =$H$8 -> 25 | M41: =$H$41*$F$41 -> 6479036.1 | N41: =$M$41/($N$5*1000) -> 0.18743799 | O41: =($M$41/$N$6)/$N$5 -> 0.011714874
...

Sheet HPP FRACT
B2: Fractionation Cost
B3: RPO Proses / Day | N3: TPD | O3: ='JULI 2025'!AM24/1000 -> 1270.5342
B4: Working Day | N4: Days | O4: ='JULI 2025'!AM23 -> 25
B5: Total CPO Process | N5: MTD | O5: =O3*O4 -> 31763.356
B6: KURS | N6: Rp/USD | O6: 16000
B7: No | C7: Item Cost | D7: Norma | F7: Pemakaian / Hari | H7: HK | J7: Total Pemakaian | K7: Harga / stn | M7: Total Biaya | N7: Rp / kg | O7: USD/MT
B8: 1 | C8: Steam | D8: ='JULI 2025'!AM254 -> 32.953602 | E8: Kg/MT CPO | F8: =$D$8*$O$3/1000 -> 41.86868 | G8: Ton/day | H8: =$O$4 -> 25 | J8: =$H$8*$F$8 -> 1046.717 | K8: =Steam!H15 -> 58707.905 | M8: =$K$8*$J$8 -> 61450562 | N8: =$M$8/($O$5*1000) -> 1.9346369 | O8: =($M$8/$O$6)/$O$5 -> 0.12091481
B9: 2 | C9: Electrical
C10: For Process | D10: ='JULI 2025'!$AM$282 -> 14.325009 | E10: kW/MT CPO | F10: =$D$10*$O$3 -> 18200.414 | G10: kW/day | H10: =$O$4 -> 25 | I10: 0 | J10: =$H$10*$F$10 -> 455010.36 | K10: =[2]Electric!$L$5 -> 1550 | L10: 3666.6667 | M10: =($F$10*$H$10*$K$10)+($F$10*$I$10*$L$10) -> 7.0526605e+08 | N10: =$M$10/($O$5*1000) -> 22.203764 | O10: =($M$10/$O$6)/$O$5 -> 1.3877352
C11: Cooling Tower | D11: ='JULI 2025'!$AM$280 -> 25.631502 | E11: kW/MT CPO | F11: =$D$11*$O$3 -> 32565.701 | G11: kW/day | H11: =$H$10 -> 25 | I11: 0 | J11: =$H$11*$F$11 -> 814142.52 | K11: =$K$10 -> 1550 | L11: 3666.6667 | M11: =($F$11*$H$11*$K$11)+($F$11*$I$11*$L$11) -> 1.2619209e+09 | N11: =$M$11/($O$5*1000) -> 39.728828 | O11: =($M$11/$O$6)/$O$5 -> 2.4830517
B12: 3 | C12: Water
C13: Make Up CT | D13: ='JULI 2025'!$AM$264 -> 6.4413848 | E13: M3/day | F13: =$D$13 -> 6.4413848 | G13: M3/day | H13: =$H$11 -> 25 | J13: =$H$13*$F$13 -> 161.03462 | K13: =WTP!H13 -> 9401.4761 | M13: =$K$13*$J$13 -> 1513963.1 | N13: =$M$13/($O$5*1000) -> 0.047663828 | O13: =($M$13/$O$6)/$O$5 -> 0.0029789893
B14: 4 | C14: Chemical Water
C15: EONBAC BC 3108 | D15: 0.4 | E15: Kg/day | F15: =$D$15 -> 0.4 | G15: Kg/day | H15: =$H$13 -> 25 | J15: =$H$15*$F$15 -> 10 | K15: 27240 | M15: =$K$15*$J$15 -> 272400 | N15: =$M$15/($O$5*1000) -> 0.00857592 | O15: =($M$15/$O$6)/$O$5 -> 0.000535995
C16: EONLINE T722 | D16: 0.66 | E16: Kg/day | F16: =$D$16 -> 0.66 | G16: Kg/day | H16: =$H$15 -> 25 | J16: =$H$16*$F$16 -> 16.5 | K16: 29120 | M16: =$K$16*$J$16 -> 480480 | N16: =$M$16/($O$5*1000) -> 0.015126865 | O16: =($M$16/$O$6)/$O$5 -> 0.00094542907
C17: EONLINE AG5770 | D17: 0.41 | E17: Kg/day | F17: =$D$17 -> 0.41 | G17: Kg/day | H17: =$H$15 -> 25 | J17: =$H$17*$F$17 -> 10.25 | K17: 117212 | M17: =$K$17*$J$17 -> 1201423 | N17: =$M$17/($O$5*1000) -> 0.037824183 | O17: =($M$17/$O$6)/$O$5 -> 0.0023640115
C18: EONScale T2511 | D18: 0.1 | E18: Kg/day | F18: =$D$18 -> 0.1 | G18: Kg/day | H18: =$H$16 -> 25 | J18: =$H$18*$F$18 -> 2.5 | K18: 45940 | M18: =$K$18*$J$18 -> 114850 | N18: =$M$18/($O$5*1000) -> 0.0036158018 | O18: =($M$18/$O$6)/$O$5 -> 0.00022598761
B19: 5 | C19: Others
C20: Filter Cloth | D20: 0.33333333 | E20: Pcs/day | F20: =$D$20 -> 0.33333333 | G20: Pcs/day | H20: =$H$18 -> 25 | J20: =$H$20*$F$20 -> 8.3333333 | K20: 895000 | M20: =$K$20*$J$20 -> 7458333.3 | N20: =$M$20/($O$5*1000) -> 0.23480936 | O20: =($M$20/$O$6)/$O$5 -> 0.014675585
C21: Filter Bag 100 Microne | D21: 0.63253012 | E21: Pcs/day | F21: =$D$21 -> 0.63253012 | G21: Pcs/day | H21: =$H$20 -> 25 | J21: =$H$21*$F$21 -> 15.813253 | K21: 125000 | M21: =$K$21*$J$21 -> 1976656.6 | N21: =$M$21/($O$5*1000) -> 0.062230724 | O21: =($M$21/$O$6)/$O$5 -> 0.0038894202
M22: =SUM(M8:M21) -> 2.0416556e+09 | N22: =SUM(N8:N21) -> 64.277075 | O22: =SUM($O$8:$O$21) -> 4.0173172

Sheet SUMMARY HPP 
B2: Production Cost MARET 2025
B3: Through Put CPO Proses (Ton/Day) | H3: TPD | I3: ='HPP REF '!$N$3 -> 1382.6516
B4: Working Day | F4: 1 | H4: Days | I4: ='HPP REF '!$N$4 -> 25
B5: Refined CPO ( Ton/month ) | H5: MTD | I5: =$I$4*$I$3 -> 34566.291
B6: Through Put RPO Proses (Ton/Day) | H6: TPD | I6: ='HPP FRACT'!$O$3 -> 1270.5342
B7: Working Day | H7: Days | I7: ='HPP FRACT'!$O$4 -> 25
B8: Fract RPO ( ton/month ) | H8: MTD | I8: =$I$7*$I$6 -> 31763.356
B9: KURS | H9: Rp/USD | I9: 16000
B10: No | C10: Items | D10: Description | G10: Rupiah | H10: Rp/Kg | I10: USD/MT
B11: I | C11: Production Cost | D11: ● | E11: Refining Cost | G11: ='HPP REF '!$M$48 -> 1.1410142e+10 | H11: =$G$11/($I$5*1000) -> 330.09449 | I11: =(G11/$I$9)/$I$5 -> 20.630906
D12: ● | E12: Fractionation Cost | G12: ='HPP FRACT'!$M$22 -> 2.0416556e+09 | H12: =$G$12/($I$8*1000) -> 64.277075 | I12: =(G12/$I$9)/$I$8 -> 4.0173172
D13: ● | E13: Preventive Maintenance Cost | F13: 0 | G13: =MTC!$F$18*F13 -> 0 | H13: =$G$13/($I$5*1000) -> 0 | I13: =(G13/$I$9)/$I$5 -> 0
G14: =SUM(G11:$G$13) -> 1.3451798e+10 | H14: =SUM($H$11:$H$13) -> 394.37157 | I14: =SUM(I11:I13) -> 24.648223
B16: II | C16: Port Cost | D16: ● | E16: Trucking Komoditi ke Kuala Tanjung | G16: =LOG!I8+LOG!I9+LOG!$I$10 -> 3.5888106e+09 | H16: =$G$16/($I$5*1000) -> 103.824 | I16: =($G$16/$I$9)/$I$5 -> 6.489
D17: ● | E17: Sewa Tank PTI Total Volume : 24.000 MT ( 5 Unit ) | F17: =F4 -> 1 | G17: =LOG!I11+LOG!I12+LOG!I13+LOG!$I$14*F17 -> 1886000000 | H17: =$G$17/($I$5*1000) -> 54.561827 | I17: =($G$17/$I$9)/$I$5 -> 3.4101142
D18: ● | E18: Instalasi & Pemanasan, Pompa, Surveyor dan Documen | G18: =LOG!I18+LOG!I19+LOG!I20+LOG!$I$21 -> 1.8516471e+09 | H18: =$G$18/($I$5*1000) -> 53.568 | I18: =($G$18/$I$9)/$I$5 -> 3.348
D19: ● | E19: Finalty Over Capacity Tank | G19: =LOG!I15+LOG!I16+LOG!$I$17 -> 1.4744597e+09 | H19: =$G$19/($I$5*1000) -> 42.656 | I19: =($G$19/$I$9)/$I$5 -> 2.666
G20: =SUM($G$16:$G$19) -> 8.8009174e+09 | H20: =SUM($H$16:$H$19) -> 254.60983 | I20: =SUM($I$16:$I$19) -> 15.913114
B22: II | C22: Fix Cost | D22: ● | E22: Manpower Cost | F22: =F4 -> 1 | G22: =[2]MPC!$H$29*$F$22 -> 2.1846655e+09 | H22: =$G$22/($I$5*1000) -> 63.202197 | I22: =($G$22/$I$9)/$I$5 -> 3.9501373
D23: ● | E23: Admin OH Cost | F23: =F4 -> 1 | G23: =OH!G51*$F$23 -> 1.4360564e+09 | H23: =$G$23/($I$5*1000) -> 41.544995 | I23: =($G$23/$I$9)/$I$5 -> 2.5965622
D24: ● | E24: Depresiasi Cost | F24: =F4 -> 1 | G24: =DEP!I9*$F$24 -> 4.1811848e+09 | H24: =$G$24/($I$5*1000) -> 120.96134 | I24: =($G$24/$I$9)/$I$5 -> 7.5600836
D25: ● | E25: Amortisation of leasehold land Cost | F25: =F4 -> 1 | G25: =AMOR!$G$20*$F$25 -> 1.0484098e+09 | H25: =$G$25/($I$5*1000) -> 30.330411 | I25: =($G$25/$I$9)/$I$5 -> 1.8956507
G26: =SUM($G$22:$G$25) -> 8.8503165e+09 | H26: =SUM($H$22:$H$25) -> 256.03894 | I26: =SUM($I$22:$I$25) -> 16.002434
B28: Total Production Cost | G28: =$G$26+$G$20+$G$14 -> 3.1103032e+10 | H28: =$H$26+$H$20+$H$14 -> 905.02033 | I28: =$I$26+$I$20+$I$14 -> 56.563771

Sheet Convert Gas
B3: CONVERT PEMAKAIAN GAS HP BOILER & MP BOILER
D4: 2024
C5: HP BOILER | F5: TOTAL CORRECTED VOLUME (Sm3) | K5: ENERGY MP BOILER (MMBTU) | L5: TOTAL GAS CONSUMPTION (MMBTU) | M5: PERCENTAGE
C6: UNCORRECTED VOLUME (UV) (Nm3) | D6: PRESS. Bar | E6: CORRECTED VOLUME (CV) (Sm3) | G6: Convert Sm3 to SCF | H6: VOLUME (MSCF) | I6: HEATING VALUE (BTU / SCF) | J6: ENERGY HP BOILER (MMBTU) | M6: HP Boiler | N6: MP Boiler
C7: 1 | D7: 2 | E7: 3 = 1 x 2 | F7: 4 = 3 | G7: 5 | H7: 6 = (4 x 5) / 1000 | I7: 7 | J7: 8 = (6 x 7) / 1000 | K7: 9 = 10 - 8 | L7: 10 | M7: 11 = 8 / 10 | N7: 12 = 9 / 10
B8: 1 | D8: 5 | E8: =C8*D8 -> 0 | F8: =E8 -> 0 | G8: 35.314667 | H8: =(F8*G8)/1000 -> 0 | I8: 0 | J8: =(H8*I8)/1000 -> 0 | K8: =L8-J8 -> 0 | L8: 0 | M8: =(J8/L8) -> #DIV/0! | N8: =K8/L8 -> #DIV/0!
B9: =B8+1 -> 2 | D9: 5 | E9: =C9*D9 -> 0 | F9: =E9 -> 0 | G9: 35.314667 | H9: =(F9*G9)/1000 -> 0 | I9: 0 | J9: =(H9*I9)/1000 -> 0 | K9: =L9-J9 -> 0 | L9: 0 | M9: =(J9/L9) -> #DIV/0! | N9: =K9/L9 -> #DIV/0!
B10: =B9+1 -> 3 | C10: 0 | D10: 5 | E10: =C10*D10 -> 0 | F10: =E10 -> 0 | G10: 35.314667 | H10: =(F10*G10)/1000 -> 0 | I10: 0 | J10: =(H10*I10)/1000 -> 0 | K10: =L10-J10 -> 0 | L10: 0 | M10: =(J10/L10) -> #DIV/0! | N10: =K10/L10 -> #DIV/0!
B11: =B10+1 -> 4 | C11: 0 | D11: 5 | E11: =C11*D11 -> 0 | F11: =E11 -> 0 | G11: 35.314667 | H11: =(F11*G11)/1000 -> 0 | I11: 0 | J11: =(H11*I11)/1000 -> 0 | K11: =L11-J11 -> 0 | L11: 0 | M11: =(J11/L11) -> #DIV/0! | N11: =K11/L11 -> #DIV/0!
B12: =B11+1 -> 5 | C12: 0 | D12: 5 | E12: =C12*D12 -> 0 | F12: =E12 -> 0 | G12: 35.314667 | H12: =(F12*G12)/1000 -> 0 | I12: 0 | J12: =(H12*I12)/1000 -> 0 | K12: =L12-J12 -> 0 | L12: 0 | M12: =(J12/L12) -> #DIV/0! | N12: =K12/L12 -> #DIV/0!
B13: =B12+1 -> 6 | C13: 0 | D13: 5 | E13: =C13*D13 -> 0 | F13: =E13 -> 0 | G13: 35.314667 | H13: =(F13*G13)/1000 -> 0 | I13: 0 | J13: =(H13*I13)/1000 -> 0 | K13: =L13-J13 -> 0 | L13: 0 | M13: =(J13/L13) -> #DIV/0! | N13: =K13/L13 -> #DIV/0!
B14: =B13+1 -> 7 | C14: 5445.8 | D14: 5 | E14: =C14*D14 -> 27229 | F14: =E14 -> 27229 | G14: 35.314667 | H14: =(F14*G14)/1000 -> 961.58307 | I14: 1070.1539 | J14: =(H14*I14)/1000 -> 1029.0419 | K14: =L14-J14 -> -104.99096 | L14: 924.05094 | M14: =(J14/L14) -> 1.1136203 | N14: =K14/L14 -> -0.11362031
B15: =B14+1 -> 8 | C15: 5810.5 | D15: 5 | E15: =C15*D15 -> 29052.5 | F15: =E15 -> 29052.5 | G15: 35.314667 | H15: =(F15*G15)/1000 -> 1025.9794 | I15: 1073.6387 | J15: =(H15*I15)/1000 -> 1101.5311 | K15: =L15-J15 -> -21.234858 | L15: 1080.2963 | M15: =(J15/L15) -> 1.0196565 | N15: =K15/L15 -> -0.019656514
B16: =B15+1 -> 9 | C16: 5849.8 | D16: 5 | E16: =C16*D16 -> 29249 | F16: =E16 -> 29249 | G16: 35.314667 | H16: =(F16*G16)/1000 -> 1032.9187 | I16: 1077.4325 | J16: =(H16*I16)/1000 -> 1112.9002 | K16: =L16-J16 -> 68.943764 | L16: 1181.8439 | M16: =(J16/L16) -> 0.94166424 | N16: =K16/L16 -> 0.05833576
B17: =B16+1 -> 10 | C17: 6108.5 | D17: 5 | E17: =C17*D17 -> 30542.5 | F17: =E17 -> 30542.5 | G17: 35.314667 | H17: =(F17*G17)/1000 -> 1078.5982 | I17: 1057.6573 | J17: =(H17*I17)/1000 -> 1140.7873 | K17: =L17-J17 -> 27.883244 | L17: 1168.6706 | M17: =(J17/L17) -> 0.97614106 | N17: =K17/L17 -> 0.023858942
B18: =B17+1 -> 11 | C18: 5078.5 | D18: 5 | E18: =C18*D18 -> 25392.5 | F18: =E18 -> 25392.5 | G18: 35.314667 | H18: =(F18*G18)/1000 -> 896.72768 | I18: 1042.4353 | J18: =(H18*I18)/1000 -> 934.78059 | K18: =L18-J18 -> 9.2041238 | L18: 943.98471 | M18: =(J18/L18) -> 0.99024971 | N18: =K18/L18 -> 0.009750289
B19: =B18+1 -> 12 | C19: 5266.9 | D19: 5 | E19: =C19*D19 -> 26334.5 | F19: =E19 -> 26334.5 | G19: 35.314667 | H19: =(F19*G19)/1000 -> 929.9941 | I19: 1049.662 | J19: =(H19*I19)/1000 -> 976.17945 | K19: =L19-J19 -> -87.64916 | L19: 888.53029 | M19: =(J19/L19) -> 1.0986451 | N19: =K19/L19 -> -0.098645101
B20: =B19+1 -> 13 | C20: 5177.5 | D20: 5 | E20: =C20*D20 -> 25887.5 | F20: =E20 -> 25887.5 | G20: 35.314667 | H20: =(F20*G20)/1000 -> 914.20844 | I20: 1058.6798 | J20: =(H20*I20)/1000 -> 967.85402 | K20: =L20-J20 -> -86.894691 | L20: 880.95933 | M20: =(J20/L20) -> 1.0986364 | N20: =K20/L20 -> -0.098636439
B21: =B20+1 -> 14 | C21: 6466.2 | D21: 5 | E21: =C21*D21 -> 32331 | F21: =E21 -> 32331 | G21: 35.314667 | H21: =(F21*G21)/1000 -> 1141.7585 | I21: 1062.4056 | J21: 981.9593 | K21: =L21-J21 -> 14.775555 | L21: 996.73485 | M21: =(J21/L21) -> 0.98517604 | N21: =K21/L21 -> 0.014823957
B22: =B21+1 -> 15 | C22: 6087.8 | D22: 5 | E22: =C22*D22 -> 30439 | F22: =E22 -> 30439 | G22: 36.314667 | H22: =(F22*G22)/1000 -> 1105.3821 | I22: 1052.2938 | J22: =(H22*I22)/1000 -> 1163.1868 | K22: =L22-J22 -> -128.11069 | L22: 1035.0761 | M22: =(J22/L22) -> 1.1237693 | N22: =K22/L22 -> -0.12376935
B23: =B22+1 -> 16 | C23: 4873.1 | D23: 5 | E23: =C23*D23 -> 24365.5 | F23: =E23 -> 24365.5 | G23: 37.314667 | H23: =(F23*G23)/1000 -> 909.19052 | I23: 1053.3732 | J23: =(H23*I23)/1000 -> 957.71689 | K23: =L23-J23 -> 56.552119 | L23: 1014.269 | M23: =(J23/L23) -> 0.94424347 | N23: =K23/L23 -> 0.055756528
B24: =B23+1 -> 17 | C24: 5075.4 | D24: 5 | E24: =C24*D24 -> 25377 | F24: =E24 -> 25377 | G24: 38.314667 | H24: =(F24*G24)/1000 -> 972.3113 | I24: 1053.6904 | J24: =(H24*I24)/1000 -> 1024.5151 | K24: =L24-J24 -> -103.99445 | L24: 920.52067 | M24: =(J24/L24) -> 1.1129735 | N24: =K24/L24 -> -0.11297351
B25: =B24+1 -> 18 | C25: 4606.6 | D25: 5 | E25: =C25*D25 -> 23033 | F25: =E25 -> 23033 | G25: 39.314667 | H25: =(F25*G25)/1000 -> 905.53473 | I25: 1062.8414 | J25: =(H25*I25)/1000 -> 962.43982 | K25: =L25-J25 -> 26.636388 | L25: 989.07621 | M25: =(J25/L25) -> 0.97306943 | N25: =K25/L25 -> 0.026930572
B26: =B25+1 -> 19 | C26: 5261.1 | D26: 5 | E26: =C26*D26 -> 26305.5 | F26: =E26 -> 26305.5 | G26: 40.314667 | H26: =(F26*G26)/1000 -> 1060.4975 | I26: 1082.6918 | J26: =(H26*I26)/1000 -> 1148.1919 | K26: =L26-J26 -> -209.58953 | L26: 938.60235 | M26: =(J26/L26) -> 1.2232996 | N26: =K26/L26 -> -0.2232996
B27: =B26+1 -> 20 | C27: 5977.4 | D27: 5 | E27: =C27*D27 -> 29887 | F27: =E27 -> 29887 | G27: 41.314667 | H27: =(F27*G27)/1000 -> 1234.7715 | I27: 1069.7089 | J27: =(H27*I27)/1000 -> 1320.846 | K27: =L27-J27 -> -338.8867 | L27: 981.95926 | M27: =(J27/L27) -> 1.3451128 | N27: =K27/L27 -> -0.34511279
B28: =B27+1 -> 21 | C28: 6186.5 | D28: 5 | E28: =C28*D28 -> 30932.5 | F28: =E28 -> 30932.5 | G28: 42.314667 | H28: =(F28*G28)/1000 -> 1308.8984 | I28: 1062.3425 | J28: =(H28*I28)/1000 -> 1390.4985 | K28: =L28-J28 -> -363.93485 | L28: 1026.5636 | M28: =(J28/L28) -> 1.3545176 | N28: =K28/L28 -> -0.35451758
B29: =B28+1 -> 22 | C29: 6815.5 | D29: 5 | E29: =C29*D29 -> 34077.5 | F29: =E29 -> 34077.5 | G29: 42.314667 | H29: =(F29*G29)/1000 -> 1441.9781 | I29: 1069.4774 | J29: =(H29*I29)/1000 -> 1542.163 | K29: =L29-J29 -> -403.20768 | L29: 1138.9553 | M29: =(J29/L29) -> 1.3540154 | N29: =K29/L29 -> -0.35401538
B30: =B29+1 -> 23 | C30: 6251.8 | D30: 5 | E30: =C30*D30 -> 31259 | F30: =E30 -> 31259 | G30: 44.314667 | H30: =(F30*G30)/1000 -> 1385.2322 | I30: 1073.8507 | J30: =(H30*I30)/1000 -> 1487.5325 | K30: =L30-J30 -> -410.8689 | L30: 1076.6636 | M30: =(J30/L30) -> 1.3816131 | N30: =K30/L30 -> -0.38161306
B31: =B30+1 -> 24 | C31: 5082.1 | D31: 5 | E31: =C31*D31 -> 25410.5 | F31: =E31 -> 25410.5 | G31: 45.314667 | H31: =(F31*G31)/1000 -> 1151.4683 | I31: 1076.3122 | J31: =(H31*I31)/1000 -> 1239.3395 | K31: =L31-J31 -> -290.50519 | L31: 948.8343 | M31: =(J31/L31) -> 1.3061706 | N31: =K31/L31 -> -0.30617062
B32: =B31+1 -> 25 | C32: 5137.6 | D32: 5 | E32: =C32*D32 -> 25688 | F32: =E32 -> 25688 | G32: 46.314667 | H32: =(F32*G32)/1000 -> 1189.7312 | I32: 1078.7582 | J32: =(H32*I32)/1000 -> 1283.4322 | K32: =L32-J32 -> -341.59792 | L32: 941.8343 | M32: =(J32/L32) -> 1.3626943 | N32: =K32/L32 -> -0.36269428
B33: =B32+1 -> 26 | C33: 5733.3 | D33: 5 | E33: =C33*D33 -> 28666.5 | F33: =E33 -> 28666.5 | G33: 47.314667 | H33: =(F33*G33)/1000 -> 1356.3459 | I33: 1089.0374 | J33: =(H33*I33)/1000 -> 1477.1113 | K33: =L33-J33 -> -550.52535 | L33: 926.586 | M33: =(J33/L33) -> 1.5941438 | N33: =K33/L33 -> -0.59414382
... B38: =B37+1 -> 31 | C38: 4295 | D38: 5 | E38: =C38*D38 -> 21475 | F38: =E38 -> 21475 | G38: 51.314667 | H38: =(F38*G38)/1000 -> 1101.9825 | I38: 1093.9934 | J38: =(H38*I38)/1000 -> 1205.5616 | K38: =L38-J38 -> -241.15245 | L38: 964.4091 | M38: =(J38/L38) -> 1.250052 | N38: =K38/L38 -> -0.25005203
B39: Average | F39: =AVERAGE(F8:F38) -> 21369.403 | H39: =AVERAGE(H8:H38) -> 873.11189 | I39: =AVERAGE(I8:I38) -> 863.84979 | J39: =AVERAGE(J8:J38) -> 928.22604 | K39: =AVERAGE(K8:K38) -> -135.19303 | L39: =AVERAGE(L8:L38) -> 793.03301 | M39: =AVERAGE(M8:M38) -> #DIV/0! | N39: =AVERAGE(N8:N38) -> #DIV/0!
B40: TOTAL | C40: =SUM(C8:C37) -> 128195.3 | E40: =SUM(E8:E38) -> 662451.5 | F40: =SUM(F8:F38) -> 662451.5 | H40: =SUM(H8:H38) -> 27066.469 | J40: =SUM(J8:J38) -> 28775.007
B41: Koreksi
B42: Total Setelah Koreksi | H42: =H40+H41 -> 27066.469 | J42: =J40+J41 -> 28775.007
C44: CONVERT HP Boiler from Utility
C45: =C40 -> 128195.3 | D45: m3 | F45: =C40*5 -> 640976.5 | G45: 9983.7
C46: 5 | D46: bar | F46: 21286.9 | G46: =G45-C40 -> -118211.6
C47: =C45*C46 -> 640976.5 | D47: Sm3 | F47: =F45/F46 -> 30.111313
...

Sheet OIP Refinery 
B4: Oil In Plant (OIP) Refinery pmg 2 | I4: FEBUARI | J4: OIP | M4: TK131 RPO | P4: TK132 RPO | S4: TOTAL STOK RPO DI PLANT
B5: Vessel | C5: Operating Volume (m3) | D5: Oil Density (kg/m3) | E5: MT | F5: Level yg diisi | G5: Actual OIP (Kg) | I5: Tanggal | J5: Opening Stock | K5: Closing Stock | L5: balance stok | M5: Opening Stock | N5: Closing Stock | O5: CONSUMP stok | P5: Opening Stock | Q5: Closing Stock | R5: CONSUMP stok
B6: 2MX312 | C6: 5.67 | D6: 850 | E6: =C6*D6/1000 -> 4.8195 | F6: 100 | G6: =(F6*E6/100)*1000 -> 4819.5 | I6: 45839
B7: 2VE611A | C7: 47.22 | D7: 850 | E7: =C7*D7/1000 -> 40.137 | F7: 80 | G7: =(F7*E7/100)*1000 -> 32109.6 | I7: 45840
B8: 2VE611B | C8: 47.22 | D8: 850 | E8: =C8*D8/1000 -> 40.137 | F8: 80 | G8: =(F8*E8/100)*1000 -> 32109.6 | I8: 45841
B9: 2VE612 | C9: 35.68 | D9: 850 | E9: =C9*D9/1000 -> 30.328 | F9: 0 | G9: =(F9*E9/100)*1000 -> 0 | I9: 45842
B10: 2VE661 | C10: 10.8 | D10: 850 | E10: =C10*D10/1000 -> 9.18 | F10: 17 | G10: =(F10*E10/100)*1000 -> 1560.6 | I10: 45843
B11: FL621 | C11: 10.1 | D11: 850 | E11: =C11*D11/1000 -> 8.585 | F11: 0 | G11: =(F11*E11/100)*1000 -> 0 | I11: 45844 | L11: =J11-K11 -> 0
B12: FL622 | C12: 10.1 | D12: 850 | E12: =C12*D12/1000 -> 8.585 | F12: 0 | G12: =(F12*E12/100)*1000 -> 0 | I12: 45845 | K12: 300569.36 | L12: =J12-K12 -> -300569.36
B13: FL623 | C13: 10.1 | D13: 850 | E13: =C13*D13/1000 -> 8.585 | F13: 0 | G13: =(F13*E13/100)*1000 -> 0 | I13: 45846 | J13: 300569.36 | K13: 310412 | L13: =J13-K13 -> -9842.64 | N13: 0 | Q13: 174609
B14: FL624 | C14: 10.1 | D14: 850 | E14: =C14*D14/1000 -> 8.585 | F14: 0 | G14: =(F14*E14/100)*1000 -> 0 | I14: 45847 | J14: 310412 | K14: 301214 | L14: =J14-K14 -> 9198 | N14: 44191 | P14: 174609 | Q14: 38852 | R14: =P14-Q14 -> 135757 | S14: =R14+O14+L14 -> 144955
B15: FL625 | C15: 10.1 | D15: 850 | E15: =C15*D15/1000 -> 8.585 | F15: 0 | G15: =(F15*E15/100)*1000 -> 0 | I15: 45848 | J15: 301214 | K15: 294983 | L15: =J15-K15 -> 6231 | M15: 44191 | N15: 405272 | O15: =M15-N15 -> -361081 | P15: 38852 | Q15: 38852 | R15: =P15-Q15 -> 0 | S15: =R15+O15+L15 -> -354850
B16: 2VE701 | C16: 72.13 | D16: 850 | E16: =C16*D16/1000 -> 61.3105 | F16: 0 | G16: =(F16*E16/100)*1000 -> 0 | I16: 45849 | J16: 294983 | K16: 298492 | L16: =J16-K16 -> -3509
B17: 2VE751 | C17: 4.28 | D17: 860 | E17: =C17*D17/1000 -> 3.6808 | F17: 50 | G17: =(F17*E17/100)*1000 -> 1840.4 | I17: 45850 | J17: 298492 | K17: 279848 | L17: =J17-K17 -> 18644
B18: 2HE721A (tube) | C18: 10 | D18: 810 | E18: =C18*D18/1000 -> 8.1 | F18: 100 | G18: =(F18*E18/100)*1000 -> 8100 | I18: 45851 | J18: 279848 | K18: 307500 | L18: =J18-K18 -> -27652
B19: 2HE721A (shell) | C19: 21.8 | D19: 800 | E19: =C19*D19/1000 -> 17.44 | F19: 40 | G19: =(F19*E19/100)*1000 -> 6976 | I19: 45852 | J19: 307500 | K19: 298308 | L19: =J19-K19 -> 9192
B20: HE721B (tube) | C20: 10 | D20: 810 | E20: =C20*D20/1000 -> 8.1 | F20: 100 | G20: =(F20*E20/100)*1000 -> 8100 | I20: 45853 | J20: 298308 | K20: 301410 | L20: =J20-K20 -> -3102
B21: 2HE722 | C21: 11.4 | D21: 790 | E21: =C21*D21/1000 -> 9.006 | F21: 80 | G21: =(F21*E21/100)*1000 -> 7204.8 | I21: 45854 | J21: 301410 | K21: 304623 | L21: =J21-K21 -> -3213
B22: 2PR731 | C22: 14 | D22: 790 | E22: =C22*D22/1000 -> 11.06 | F22: 40 | G22: =(F22*E22/100)*1000 -> 4424 | I22: 45855 | J22: 304623 | K22: 293070 | L22: =J22-K22 -> 11553
B23: 2DE732 | C23: 149.76 | D23: 790 | E23: =C23*D23/1000 -> 118.3104 | F23: 100 | G23: =(F23*E23/100)*1000 -> 118310.4 | I23: 45856 | J23: 293070 | K23: 302448 | L23: =J23-K23 -> -9378
C24: =SUM(C6:C23) -> 490.46 | E24: =SUM(E6:E23) -> 404.5342 | I24: 45857 | J24: 302448 | K24: 294782 | L24: =J24-K24 -> 7666
F25: Total OIP = | G25: =SUM(G6:G24) -> 225554.9 | I25: 45858 | J25: 294782 | K25: 302448 | L25: =J25-K25 -> -7666
I26: 45859 | J26: 302448 | K26: 307090 | L26: =J26-K26 -> -4642 | U26: =L26+L25 -> -12308
I27: 45860 | J27: 307090 | K27: 301876 | L27: =J27-K27 -> 5214
I28: 45861 | J28: 301876 | K28: 312139 | L28: =J28-K28 -> -10263
I29: 45862 | J29: 312139 | K29: 283528 | L29: =J29-K29 -> 28611
B30: Solar Daily Tank HPB | I30: 45863 | J30: 283528 | K30: 313730 | L30: =J30-K30 -> -30202
B31: 2TK726 | C31: =5.3+0.78 -> 6.08 | D31: 840 | E31: =C31*D31/1000 -> 5.1072 | F31: 0 | G31: =F31*E31/100*1000 -> 0 | H31: 0 | I31: 45864 | J31: 313730 | K31: 313427 | L31: =J31-K31 -> 303
I32: 45865 | J32: 313427 | K32: 298308 | L32: =J32-K32 -> 15119
B33: Stock Chemicals In Plant | I33: 45866 | J33: 298308 | K33: 208557 | L33: =J33-K33 -> 89751
C34: Read | D34: End Read | E34: Consumption | I34: 45867 | J34: 208557 | K34: 295949 | L34: =J34-K34 -> -87392
B35: BE | I35: 45868 | J35: 295949 | K35: 199965 | L35: =J35-K35 -> 95984
B36: 630A | I36: 45869 | J36: 199965 | K36: 225555 | L36: =J36-K36 -> -25590
B37: 630B
B38: H3PO4
B39: NaOH
B40: Citrid Acid

Sheet Oip Fract .
A4: Oil In Plant (OIP) Fraksinasi | I4: OIP | S4: BUFFER TANK | W4: DIRECT
A5: RBDPO OIP pmg 2 | I5: RPO CR | M5: OLEIN | P5: STEARIN | S5: TK131 RPO | U5: TK132 RPO
A6: Vessel | B6: Operating Volume (m3) | C6: Oil Density (kg/m3) | D6: MT | E6: Level Transmitter (1%/MT) | F6: Level (%) | G6: Kg | I6: Tanggal | J6: Opening Stock | K6: Closing Stock | L6: balance stok | M6: Opening Stock | N6: Closing Stock | O6: balance stok | P6: Opening Stock | Q6: Closing Stock | R6: balance stok | S6: Opening Stock | T6: Closing Stock | U6: Opening Stock | V6: Closing Stock
A7: 2CR1201 | B7: 70.51 | C7: 890 | D7: 60 | E7: =D7/100 -> 0.6 | F7: 0 | G7: =E7*F7*1000 -> 0 | I7: 45839
A8: 2CR1202 | B8: 70.51 | C8: 890 | D8: 60 | E8: =D8/100 -> 0.6 | F8: 0 | G8: =E8*F8*1000 -> 0 | I8: 45840
A9: 2CR1203 | B9: 70.51 | C9: 890 | D9: 60 | E9: =D9/100 -> 0.6 | F9: 100 | G9: =E9*F9*1000 -> 60000 | I9: 45841
A10: 2CR1204 | B10: 70.51 | C10: 890 | D10: 60 | E10: =D10/100 -> 0.6 | F10: 98.9 | G10: =E10*F10*1000 -> 59340 | I10: 45842
A11: 2CR1205 | B11: 70.51 | C11: 890 | D11: 60 | E11: =D11/100 -> 0.6 | F11: 100 | G11: =E11*F11*1000 -> 60000 | I11: 45843
A12: 2CR1206 | B12: 70.51 | C12: 890 | D12: 60 | E12: =D12/100 -> 0.6 | F12: 99.9 | G12: =E12*F12*1000 -> 59940 | I12: 45844
A13: 2CR1207 | B13: 70.51 | C13: 890 | D13: 60 | E13: =D13/100 -> 0.6 | F13: 100 | G13: =E13*F13*1000 -> 60000 | I13: 45845 | S13: 34859 | T13: 34831 | U13: 272307 | V13: 33986
A14: 2CR1208 | B14: 70.51 | C14: 890 | D14: 60 | E14: =D14/100 -> 0.6 | F14: 100 | G14: =E14*F14*1000 -> 60000 | I14: 45846 | J14: 0 | K14: 420000 | L14: =J14-K14 -> -420000 | M14: 0 | N14: 21696 | P14: 0 | Q14: 0 | S14: 34831 | T14: 106130 | U14: 33986 | V14: 33991
A15: 2CR1209 | B15: 70.51 | C15: 890 | D15: 60 | E15: =D15/100 -> 0.6 | F15: 100 | G15: =E15*F15*1000 -> 60000 | I15: 45847 | J15: 420000 | K15: 360000 | L15: =J15-K15 -> 60000 | M15: 216969 | N15: 22253 | Q15: 0 | R15: 0 | S15: 106130 | T15: 34893 | U15: 33991 | V15: 34003 | W15: 53843
A16: 2CR1210 | B16: 70.51 | C16: 890 | D16: 60 | E16: =D16/100 -> 0.6 | F16: 99.9 | G16: =E16*F16*1000 -> 59940 | I16: 45848 | J16: 360000 | K16: 600000 | L16: =J16-J17 -> -240000 | M16: 22253 | N16: 12490 | O16: =M16-N16 -> 9763 | P16: 0 | Q16: 0 | R16: =P16-Q16 -> 0 | S16: 34893 | T16: 68629 | U16: 34003 | V16: 40538
A17: 2CR1211 | B17: 70.51 | C17: 890 | D17: 60 | E17: =D17/100 -> 0.6 | F17: 100 | G17: =E17*F17*1000 -> 60000 | I17: 45849 | J17: 600000 | K17: 419580 | L17: =#REF!-K17 -> #REF! | M17: 12490 | N17: 17315 | O17: =M17-N17 -> -4825 | P17: 0 | Q17: 0 | R17: =P17-Q17 -> 0 | S17: 68629 | T17: 34876 | U17: 40538 | V17: 59415
A18: 2CR1212 | B18: 70.51 | C18: 890 | D18: 60 | E18: =D18/100 -> 0.6 | F18: 99.9 | G18: =E18*F18*1000 -> 59940 | I18: 45850 | J18: 419580 | K18: 479100 | L18: =J18-K18 -> -59520 | M18: 17315 | N18: 21738 | O18: =M18-N18 -> -4423 | P18: 0 | Q18: 0 | R18: =P18-Q18 -> 0 | S18: 34876 | T18: 34876 | U18: 59415 | V18: 71991
A19: 2CR1213 | B19: 70.51 | C19: 890 | D19: 60 | E19: =D19/100 -> 0.6 | F19: 99.8 | G19: =E19*F19*1000 -> 59880 | I19: 45851 | J19: 479100 | K19: 418500 | L19: =J19-K19 -> 60600 | M19: 21738 | N19: 22623 | O19: =M19-N19 -> -885 | P19: 0 | Q19: 0 | R19: =P19-Q19 -> 0 | S19: 34876 | T19: 85045 | U19: 71991 | V19: 86131
A20: 2CR1214 | B20: 70.51 | C20: 890 | D20: 60 | E20: =D20/100 -> 0.6 | F20: 99.6 | G20: =E20*F20*1000 -> 59760 | I20: 45852 | J20: 418500 | K20: 540000 | L20: =J20-K20 -> -121500 | M20: 22623 | N20: 39470 | O20: =M20-N20 -> -16847 | P20: 0 | Q20: 0 | R20: =P20-Q20 -> 0 | S20: 85045 | T20: 81918 | U20: 86131 | V20: 102628
A21: 2CR1215 | B21: 70.51 | C21: 890 | D21: 60 | E21: =D21/100 -> 0.6 | F21: 99.5 | G21: =E21*F21*1000 -> 59700 | I21: 45853 | J21: 540000 | K21: 780000 | L21: =J21-K21 -> -240000 | M21: 39470 | N21: 25248 | O21: =M21-N21 -> 14222 | P21: 0 | Q21: 0 | R21: =P21-Q21 -> 0 | S21: 85045 | T21: 81918 | U21: 86131 | V21: 102628
I22: 45854 | J22: 780000 | K22: 701880 | L22: =J22-K22 -> 78120 | M22: 25248 | N22: 40262 | O22: =M22-N22 -> -15014 | P22: 0 | R22: =P22-Q22 -> 0 | S22: 81918 | T22: 84269 | U22: 102628 | V22: 115980
F23: Total RBDPO | G23: =SUM(G7:G21) -> 778500 | I23: 45855 | J23: 701880 | K23: 540000 | M23: 40262 | N23: 56197 | O23: =M23-N23 -> -15935 | R23: =P23-Q23 -> 0 | S23: 34870 | T23: 34856 | U23: 136404 | V23: 157615
I24: 45856 | J24: 540000 | K24: 300000 | M24: 56197 | N24: 23201 | R24: =P24-Q24 -> 0 | S24: 34856 | T24: 58883 | U24: 157615 | V24: 170967
A25: Olein OIP | I25: 45857 | J25: 300000 | K25: 780000 | M25: 23201 | N25: 24721 | R25: =P25-Q25 -> 0 | S25: 58883 | T25: 98338 | U25: 170967 | V25: 195337
A26: Vessel | B26: Operating Volume (m3) | C26: Oil Density (kg/m3) | D26: MT | E26: Level Transmitter (1%/MT) | F26: Level (%) | G26: Kg | I26: 45858 | J26: 780000 | K26: 720000 | M26: 24721 | N26: 24721 | S26: 98338 | T26: 113968 | U26: 195337 | V26: 209474
A27: 2TK261 | B27: 15.95 | C27: 885 | D27: =B27*C27/1000 -> 14.11575 | E27: =D27/100 -> 0.1411575 | F27: 72.3 | G27: =E27*F27*1000 -> 10205.687 | I27: 45859 | J27: 720000 | K27: 658920 | M27: 24721 | N27: 19504 | S27: 113968 | T27: 67849 | U27: 209474 | V27: 232257
A28: 2CL251 | B28: 3.02 | C28: 885 | D28: =B28*C28/1000 -> 2.6727 | E28: =D28/100 -> 0.026727 | F28: 0 | G28: =E28*F28*1000 -> 0 | I28: 45860 | J28: 658920 | K28: 658860 | M28: 19504 | N28: 20809 | S28: 67849 | T28: 163972 | U28: 232257 | V28: 152224
A29: 2TK221 | B29: 82.48 | C29: 885 | D29: =B29*C29/1000 -> 72.9948 | E29: =D29/100 -> 0.729948 | F29: 0 | G29: =E29*F29*1000 -> 0 | I29: 45861 | J29: 658860 | K29: 635580 | M29: 20809 | N29: 19215 | S29: 163972 | T29: 47434 | U29: 152224 | V29: 160023
A30: 2TK241 | B30: 16.95 | C30: 885 | D30: =B30*C30/1000 -> 15.00075 | E30: =D30/100 -> 0.1500075 | F30: 93 | G30: =E30*F30*1000 -> 13950.697 | I30: 45862 | J30: 635580 | K30: 360000 | M30: 19215 | N30: 31795 | S30: 43586 | T30: 51413 | U30: 160023 | V30: 181229
G31: =SUM(G27:G30) -> 24156.385 | I31: 45863 | J31: 360000 | K31: 168240 | M31: 31795 | N31: 32417 | S31: 51413 | T31: 34860 | U31: 181229 | V31: 197739
A32: Stearin OIP | I32: 45864 | J32: 168240 | K32: 598680 | M32: 32417 | N32: 23135 | S32: 34860 | T32: 34975 | U32: 197739 | V32: 213446
A33: Melting Tank | B33: Panjang (m) | C33: Lebar (m) | D33: tinggi (m) | E33: Density | F33: Tinggi Sounding (Cm) Maks 4,4 m | G33: Kg | I33: 45865 | J33: 598680 | K33: 480000 | M33: 23135 | N33: 23032 | S33: 34975 | T33: 67850 | U33: 213446 | V33: 226007
A34: TK231 A | B34: 12.2 | C34: 1.75 | D34: 1.52 | E34: 0.88 | F34: 0 | G34: =B34*C34*D34*E34*F34/100 -> 0 | I34: 45866 | J34: 480000 | K34: 120000 | M34: 23032 | N34: 22191 | S34: 67850 | T34: 34881 | U34: 226007 | V34: 93213
A35: TK231 B | B35: 12.2 | C35: 1.75 | D35: 1.52 | E35: 0.88 | F35: 0 | G35: =B35*C35*D35*E35*F35/100 -> 0 | I35: 45867 | J35: 120000 | K35: 359820 | M35: 22191 | N35: 19700 | S35: 34881 | T35: 34891 | U35: 93213 | V35: 97917
F36: Total STEARIN | G36: =SUM(G34:G35) -> 0 | I36: 45868 | J36: 359820 | K36: 658200 | M36: 19700 | N36: 20597 | S36: 34891 | T36: 44368 | U36: 97917 | V36: 106549
I37: 45869 | J37: 658200 | K37: 778500 | M37: 20597 | N37: 24156 | S37: 44368 | T37: 34894 | U37: 106549 | V37: 118327

Sheet 2025
B2: PRODUCTION REPORT 2025
F3: ok | M3: ok | N3: ok
B4: No | C4: ITEM | D4: Budget / Norma | E4: UoM | F4: YEARLY REPORT | T4: Yearly Report | U4: Yearly Report RKAP (Budget) | V4: Yearly Report RKAP
F5: JANUARI | G5: FEBRUARI | H5: MARET | I5: APRIL | J5: MEI | K5: JUNI | L5: JULI | M5: AGUSTUS | N5: SEPTEMBER | O5: OKTOBER | P5: NOVEMBER | Q5: DESEMBER | R5: DESEMBER | T5: TOTAL (Kg) | U5: TOTAL (Kg) | V5: TOTAL (%)
B6: 1 | C6: PRODUCTION | T6: Production | U6: Production | V6: Production | DG6: 29 | DH6: 30 | DI6: 31
C7: Refinery | T7: Refinery | U7: Refinery | V7: Refinery | DE7: CPO Olah | DF7: Kg | DG7: 1971320 | DH7: 2015120 | DI7: 2015230 | AIU7: Sounding | AIV7: Production | AIW7: Diff
C8: Running Days | D8: 300 | E8: Day | F8: 0 | G8: 13 | H8: 6 | K8: 10 | L8: ='JULI 2025'!AM6 -> 25 | R8: ='[3]Desember 24'!AL9 -> 0 | T8: =SUM(F8:R8) -> 54 | U8: 231 | V8: =T8/U8*100 -> 23.376623 | OR8: Poram | AEE8: 14 Juni | AEF8: 15 Juni | AIT8: CPO | AIU8: 11008948 | AIV8: =T11 -> 74559975 | AIW8: =AIU8-AIV8 -> -63551027
C9: Ratio Run CPO | G9: 0 | H9: 0 | K9: 0 | R9: ='[3]Desember 24'!AL10 -> 0
C10: Utilitas CPO | G10: 0 | H10: 0 | K10: 0 | R10: =R11/R14*100 -> #DIV/0! | T10: =AVERAGE(F10:Q10) -> 0
C11: CPO Consume Total | D11: 707651000 | E11: Kg | F11: 0 | G11: 16619582 | H11: 5560915 | I11: 0 | K11: 17813187 | L11: ='JULI 2025'!AM9 -> 34566291 | R11: ='[3]Desember 24'!AL11 -> 0 | T11: =SUM(F11:Q11) -> 74559975 | U11: 421374000 | V11: =T11/U11 -> 0.17694489 | AX11: =T11/D11 -> 0.10536264 | DE11: HP Boiler | DF11: mmbtu | DG11: 251.19642 | DH11: 257.91391 | DI11: 251.51265 | OO11: 26946.108 | OP11: 17383.234 | OR11: RBDPO Olah | AEE11: =35.8500000000058*1000 -> 35850 | AIT11: PFAD | AIU11: 566885 | AIV11: =T20 -> 3372812 | AIW11: =AIU11-AIV11 -> -2805927
C12: CPO Consume Poram | E12: Kg | F12: 0 | G12: 16619582 | H12: 5560915 | I12: =I11 -> 0 | J12: =J11 -> 0 | K12: 17813187 | L12: =L11 -> 34566291 | R12: ='[3]Desember 24'!AL12 -> #DIV/0! | T12: =SUM(F12:Q12) -> 74559975
