Workbook

Sheet Agustus - 2024
C1: PRODUCTION REPORT
C2: No | D2: ITEM | E2: Budget / Norma | F2: UoM | G2: Agustus | AN2: TOTAL MONTHLY (Kg)
G3: 1 | H3: 2 | I3: 3 | J3: 4 | K3: 5 | L3: 6 | M3: 7 | N3: 8 | O3: 9 | P3: 10 | Q3: 11 | R3: 12 | S3: 13 | T3: 14 | U3: 15 | V3: 16 | W3: 17 | X3: 18 | Y3: 19 | Z3: 20 | AA3: 21 | AB3: 22 | AC3: 23 | AD3: 24 | AE3: 25 | AF3: 26 | AG3: 27 | AH3: 28 | AI3: 29 | AJ3: 30 | AK3: 31 | AL3: 31
C4: 1 | D4: PRODUCTION | AN4: Production
D5: Refinery | AN5: Refinery
D6: Running Days | F6: Day | G6: 1 | H6: 1 | I6: 1 | J6: 1 | K6: 1 | L6: 1 | M6: 1 | N6: 1 | O6: 1 | P6: 1 | Q6: 1 | R6: 1 | S6: 1 | T6: 1 | U6: 1 | V6: 1 | W6: 0 | X6: 0 | Y6: 0 | Z6: 1 | AA6: 1 | AB6: 1 | AC6: 1 | AD6: 1 | AE6: 1 | AF6: 1 | AG6: 1 | AH6: 1 | AI6: 1 | AJ6: 1 | AK6: 1 | AN6: =SUM(G6:AL6) -> 28
D7: Incoming CPO | F7: Kg | G7: ='[1]01'!$P$13 -> 489345 | H7: ='[2]02'!$P$14 -> 1012278 | I7: ='[2]03'!$P$14 -> 802407 | J7: =0 -> 0 | K7: =453628+'[3]05'!$P$13 -> 714345 | L7: 449365 | M7: ='[3]07'!$P$14 -> 211955 | N7: 417327 | O7: 682500 | P7: 472840 | R7: 1150409 | S7: ='[4]13'!$P$14 -> 518236 | T7: ='[4]14'!$P$14 -> 327333 | U7: 607907 | V7: ='[5]16'!$P$14 -> 281390 | W7: ='[5]17'!$P$14 -> 161291 | X7: ='[5]18'!$P$14 -> 64256 | Y7: 1642352 | Z7: ='[6]20'!$P$15 -> 990208 | AA7: ='[7]21'!$P$15 -> 1561101 | AB7: ='[8]22'!$P$15 -> 1408409 | AC7: ='[9]23'!$P$15 -> 395196 | AD7: ='[9]24'!$P$15 -> 851110 | AE7: ='[9]25'!$P$15 -> 0 | AF7: 804622 | AG7: ='[10]27'!$P$15 -> 583740 | AH7: ='[11]28'!$P$15 -> 937351 | AI7: ='[12]29'!$P$15 -> 254530 | AJ7: ='[13]30'!$P$15 -> 596514 | AK7: ='[5]31 Stok Opname'!$P$15 -> 801007 | AN7: =SUM(G7:AL7) -> 19189324 | AO7: =AVERAGE(H7:AA7) -> 635131.58
D8: Ratio Run CPO | F8: % | G8: =G9/2200000*100 -> 64.436273 | H8: =H9/2200000*100 -> 50.225045 | I8: =I9/2200000*100 -> 47.389545 | J8: =J9/2200000*100 -> 48.294682 | K8: =K9/2200000*100 -> 18.650409 | L8: =L9/2200000*100 -> 34.512318 | M8: =M9/2200000*100 -> 9.8673182 | N8: =N9/2200000*100 -> 15.987364 | ... AL8: =AL9/2200000*100 -> 0 | AN8: =AVERAGE(G8:AK8) -> 33.834848
D9: CPO Consume Total | E9: 36359000 | F9: Kg | G9: ='[3]01'!$Q$13+'[3]01'!$Q$11 -> 1417598 | H9: ='[3]02'!$Q$14 -> 1104951 | I9: 1042570 | J9: ='[3]04'!$Q$14 -> 1062483 | K9: ='[3]05'!$Q$11 -> 410309 | L9: ='[3]06'!$Q$9+'[3]06'!$Q$13 -> 759271 | M9: ='[3]07'!$Q$14 -> 217081 | N9: =348722+3000 -> 351722 | O9: 743456 | P9: 1152731 | Q9: 521179 | R9: 337454 | S9: =1333353 -> 1333353 | T9: ='[14]14 Rev'!$Q$14 -> 723542 | U9: 261913 | V9: ='[5]16'!$Q$14 -> 843222 | W9: 0 | X9: 0 | Y9: 0 | Z9: ='[6]20'!$Q$15 -> 997925 | AA9: ='[7]21'!$Q$15 -> 1452148 | AB9: ='[8]22'!$Q$15 -> 720213 | AC9: ='[9]23'!$Q$15 -> 976465 | AD9: ='[9]24'!$Q$15 -> 1563156 | AE9: ='[9]25'!$Q$15 -> 1396380 | AF9: 225122 | AG9: ='[10]27'!$Q$15 -> 672238 | AH9: ='[11]28'!$Q$15 -> 1017095 | AI9: ='[12]29'!$Q$15 -> 596307 | AJ9: ='[13]30'!$Q$15 -> 347783 | AK9: ='[5]31 Stok Opname'!$Q$10+'[5]31 Stok Opname'!$Q$14 -> 827699 | AN9: =SUM(G9:AL9) -> 23075366 | AO9: =AN9/E9 -> 0.63465348 | AP9: =AN9/AN6 -> 824120.21
D10: CPO Consume Poram | E10: 29045000 | F10: Kg | G10: =G9-G33-G42 -> 1417598 | H10: =H9-H33-H42 -> 1104951 | I10: =I9-I33-I42 -> 1042570 | J10: =J9-J33-J42 -> 1062483 | K10: =K9-K33-K42 -> 410309 | L10: =L9-L33-L42 -> 759271 | M10: =M9-M33-M42 -> 217081 | N10: =N9-N33-N42 -> 351722 | ... AG10: =AG9-AG33-AG42 -> 672238 | AH10: =AH9-AH33-AH42-AH11 -> 832400 | AI10: =AI9-AI33-AI42 -> 596307 | AJ10: =AJ9-AJ33-AJ42 -> 347783 | AK10: =AK9-AK33-AK42 -> 827699 | AL10: =AL9-AL33-AL42 -> 0 | AN10: =SUM(G10:AL10) -> 22890671
D11: CPO Consume Brand | E11: 7314000 | F11: Kg | G11: =G33+G42 -> 0 | H11: =H33+H42 -> 0 | I11: =I33+I42 -> 0 | J11: =J33+J42 -> 0 | K11: =K33+K42 -> 0 | L11: =L33+L42 -> 0 | M11: =M33+M42 -> 0 | N11: =N33+N42 -> 0 | ... AG11: =AG33+AG42 -> 0 | AH11: 184695 | AI11: =AI33+AI42 -> 0 | AJ11: =AJ33+AJ42 -> 0 | AK11: =AK33+AK42 -> 0 | AL11: =AL33+AL42 -> 0 | AN11: =SUM(G11:AL11) -> 184695
D12: - FFA | E12: 5 | F12: % | G12: 4.15 | H12: 4.34 | I12: 4.14 | J12: =(3.85+3.7)/2 -> 3.775 | K12: 4.16 | L12: =(4.09+3.46)/2 -> 3.775 | M12: 4.3 | N12: 4.32 | O12: 4.32 | P12: 4.475 | Q12: 3.79 | R12: 4.09 | S12: =(4.1+3.57)/2 -> 3.835 | T12: =(4.1+3.5)/2 -> 3.8 | U12: 4.3 | V12: =(4.1+4.35)/2 -> 4.225 | W12: 0 | X12: 0 | Y12: 0 | Z12: =(3.8+3.65)/2 -> 3.725 | AA12: =(3.71+3.62)/2 -> 3.665 | AB12: 3.59 | AC12: =(2.84+3.78+3.59)/3 -> 3.4033333 | AD12: =(3.92+3.85)/2 -> 3.885 | AE12: =(3.85+3.52)/2 -> 3.685 | AF12: 4.09 | AG12: 3.92 | AH12: =(4.04+3.51)/2 -> 3.775 | AI12: =(4.01+4.12+3.58)/3 -> 3.9033333 | AJ12: 3.7 | AK12: =(3.91+3.66)/2 -> 3.785 | AN12: =SUM(G12:AK12)/AN6 -> 3.9614881
D13: - Moist & Impurities | E13: 0.5 | F13: % | G13: 0.42 | H13: 0.41 | I13: 0.41 | J13: =(0.4+0.42)/2 -> 0.41 | K13: 0.43 | L13: 0.47 | M13: 0.42 | N13: 0.42 | O13: 0.42 | P13: 0.42 | Q13: 0.49 | R13: 0.44 | S13: =(0.4+0.48)/2 -> 0.44 | T13: 0.49 | U13: 0.4 | V13: =(0.4+0.42)/2 -> 0.41 | W13: 0 | X13: 0 | Y13: 0 | Z13: =(0.42+0.46)/2 -> 0.44 | AA13: =(0.44+0.47)/2 -> 0.455 | AB13: 0.42 | AC13: =(0.34+0.4+0.48)/3 -> 0.40666667 | AD13: =(0.42+0.41)/2 -> 0.415 | AE13: =(0.41+0.46)/2 -> 0.435 | AF13: 0.42 | AG13: 0.46 | AH13: =(0.39+0.44)/2 -> 0.415 | AI13: =(0.44+0.38+0.46)/3 -> 0.42666667 | AJ13: 0.43 | AK13: =(0.4+0.48)/2 -> 0.44 | AN13: =SUM(G13:AK13)/AN6 -> 0.43083333
D14: - DOBI | E14: 2,20 Min | F14: % | G14: 2.21 | H14: 2.21 | I14: 2.22 | J14: 2.21 | K14: 2.22 | L14: 2.21 | M14: 2.21 | N14: 2.21 | O14: 2.21 | P14: 2.21 | Q14: 2.21 | R14: 2.22 | S14: 2.21 | T14: 2.22 | U14: 2.21 | V14: 2.21 | W14: 0 | X14: 0 | Y14: 0 | Z14: 2.222 | AA14: 2.21 | AB14: 2.21 | AC14: 2.22 | AD14: 2.21 | AE14: 2.22 | AF14: 2.21 | AG14: 2.2 | AH14: 2.21 | AI14: 2.22 | AJ14: 2.21 | AK14: 2.22 | AN14: =SUM(G14:AL14)/AN6 -> 2.2129286
D15: Product | AN15: Product
D16: RBDPO | E16: 34458000 | F16: Kg | G16: ='[1]01'!$P$17 -> 1337671 | H16: ='[2]02'!$P$17 -> 1062915 | I16: ='[2]03'!$P$17 -> 1004399 | J16: ='[2]04'!$P$17 -> 1014004 | K16: ='[3]05'!$P$17 -> 375835 | L16: 751036 | M16: ='[3]07'!$P$17 -> 205973 | N16: 300695 | O16: 723509 | P16: 1082408 | Q16: 522678 | R16: 291425 | S16: =1251548+12500 -> 1264048 | T16: =688994-25961 -> 663033 | U16: =286771-30559 -> 256212 | V16: ='[5]16'!$P$17-23295 -> 764988 | W16: 0 | X16: 0 | Y16: 0 | Z16: ='[6]20'!$P$18+Z20+'OIP Refinery'!G24 -> 974136 | AA16: ='[7]21'!$P$17+AA20+'OIP Refinery'!G25 -> 1374725 | AB16: ='[8]22'!$P$18+AB20 -> 684147 | AC16: ='[9]23'!$P$18+AC20-24268 -> 886585 | AD16: ='[9]24'!$P$18+'OIP Refinery'!G28 -> 1543843 | AE16: ='[9]25'!$P$18-10084 -> 1313723 | AF16: =187550+33039 -> 220589 | AG16: ='[10]27'!$P$18-4779 -> 640699 | AH16: ='[11]28'!$P$18+AH20+'OIP Refinery'!G32 -> 983679.2 | AI16: ='[12]29'!$P$18-26834 -> 796939 | AJ16: ='[13]30'!$P$18+7092 -> 318511 | AK16: ='[5]31 Stok Opname'!$P$18+'OIP Refinery'!G35 -> 793401 | AN16: =SUM(G16:AL16) -> 22151806
D17: PFAD | E17: 1636000 | F17: Kg | G17: ='[1]01'!$P$23 -> 54840 | H17: ='[2]02'!$P$25 -> 43942 | I17: ='[2]03'!$P$25 -> 37168 | J17: ='[2]04'!$P$25 -> 43898 | K17: ='[3]05'!$P$25 -> 17690 | L17: 28851 | M17: ='[3]07'!$P$25 -> 8686 | N17: 20527 | O17: 25468 | P17: 50238 | Q17: 20927 | R17: 15400 | S17: 57789 | T17: 27742 | U17: 15397 | V17: ='[5]16'!$P$25 -> 41535 | W17: 0 | X17: 0 | Y17: 0 | Z17: ='[6]20'!$P$26 -> 45493 | AA17: ='[7]21'!$P$26 -> 54837 | AB17: ='[8]22'!$P$26 -> 28814 | AC17: ='[9]23'!$P$26 -> 42594 | AD17: ='[9]24'!$P$26 -> 58048 | AE17: ='[9]25'!$P$26 -> 53833 | AF17: 13940 | AG17: ='[10]27'!$P$26 -> 30763 | AH17: ='[11]28'!$P$26 -> 35257 | AI17: ='[12]29'!$P$26 -> 25789 | AJ17: ='[13]30'!$P$26 -> 13679 | AK17: ='[5]31 Stok Opname'!$P$26 -> 34315 | AN17: =SUM(G17:AL17) -> 947460
D18: Fractionation
D19: Running Days | F19: Day | G19: 1 | H19: 1 | I19: 1 | J19: 1 | K19: 1 | L19: 1 | M19: 1 | N19: 1 | O19: 1 | P19: 1 | Q19: 1 | R19: 1 | S19: 1 | T19: 1 | U19: 1 | V19: 1 | W19: 1 | X19: 0 | Y19: 0 | Z19: 1 | AA19: 1 | AB19: 1 | AC19: 1 | AD19: 1 | AE19: 1 | AF19: 1 | AG19: 1 | AH19: 1 | AI19: 1 | AJ19: 1 | AK19: 1 | AN19: =SUM(G19:AL19) -> 29
D20: Filling Langsung CR Fr Refinery | F20: Kg | K20: 0 | L20: 0 | M20: 0 | N20: 0 | O20: 0 | P20: 0 | Q20: 0 | R20: 0 | S20: 0 | T20: 0 | U20: 0 | V20: 0 | W20: 0 | X20: 0 | Y20: 0 | Z20: 118100 | AA20: 935500 | AB20: 219100 | AC20: 230700 | AD20: 0 | AE20: 0 | AF20: 0 | AG20: 0 | AH20: 175900 | AI20: 0 | AJ20: 0 | AK20: 0 | AN20: =SUM(G20:AK20) -> 1679300
D21: Total Filling Crystalizer ( Feed ) | F21: Kg | G21: ='[13]01'!$Q$17 -> 858578 | H21: ='[13]02'!$Q$17 -> 1054796 | I21: ='[13]03'!$Q$17 -> 860932 | J21: ='[13]04'!$Q$17 -> 922447 | K21: ='[13]05'!$Q$17 -> 1038779 | L21: ='[13]06'!$Q$17 -> 1410359 | M21: ='[13]07'!$Q$17 -> 1171827 | N21: ='[13]08'!$Q$17 -> 1048480 | O21: ='[13]09'!$Q$17 -> 518065 | P21: ='[13]10'!$Q$17 -> 1272374 | Q21: ='[13]11'!$Q$17 -> 702972 | R21: ='[13]12'!$Q$17 -> 50573 | S21: ='[13]13'!$Q$17 -> 931812 | T21: ='[13]14'!$Q$17 -> 1278793 | U21: ='[13]15'!$Q$17 -> 0 | V21: ='[5]16'!$Q$17 -> 895292 | W21: ='[5]17'!$Q$17 -> 266317 | X21: ='[13]15'!$Q$17 -> 0 | Y21: ='[13]15'!$Q$17 -> 0 | Z21: ='[6]20'!$Q$18+Z20 -> 574027 | AA21: ='[7]21'!$Q$18+AA20 -> 1109871 | AB21: =AB20+'[8]22'!$Q$18 -> 1144787 | AC21: ='[9]23'!$Q$18+AC20 -> 358903 | AD21: ='[9]24'!$Q$18 -> 1073186 | AE21: ='[9]25'!$Q$18 -> 806379 | AF21: 813937 | AG21: ='[10]27'!$Q$18 -> 809229 | AH21: ='[11]28'!$Q$18+AH20 -> 654036 | AI21: ='[12]29'!$Q$18 -> 926106 | AJ21: ='[13]30'!$Q$18 -> 862504 | AK21: ='[5]31 Stok Opname'!$Q$18 -> 1036869 | AN21: =SUM(G21:AK21) -> 24452230 | AO21: =AN21/E16 -> 0.70962418
D22: Total Proses RBDPO | F22: Kg | G22: =SUM(G25,G29,G34,G38,G43) -> 930616 | H22: =SUM(H25,H29,H34,H38,H43) -> 971961 | I22: =SUM(I25,I29,I34,I38,I43) -> 860808 | J22: =SUM(J25,J29,J34,J38,J43) -> 963967 | K22: =SUM(K25,K29,K34,K38,K43) -> 1052818 | L22: =SUM(L25,L29,L34,L38,L43) -> 1321319 | M22: =SUM(M25,M29,M34,M38,M43) -> 1212660 | N22: =SUM(N25,N29,N34,N38,N43) -> 1250229 | ... AK22: =SUM(AK25,AK29,AK34,AK38,AK43) -> 983160 | AN22: =SUM(G22:AK22) -> 24206356
D23: Sisa Filling Crystalizer | F23: Kg | G23: =G21-G22 -> -72038 | H23: =H21-H22 -> 82835 | I23: =I21-I22 -> 124 | J23: =J21-J22 -> -41520 | K23: =K21-K22 -> -14039 | L23: =L21-L22 -> 89040 | M23: =M21-M22 -> -40833 | N23: =N21-N22 -> -201749 | ... AK23: =AK21-AK22 -> 53709 | AN23: =SUM(G23:AK23) -> 245874
D24: Fractionation OLEIN IV 56 | AN24: Olein IV 56
D25: RBDPO Consume | F25: Kg | G25: =G26+G27 -> 351441 | H25: =H26+H27 -> 578725 | I25: =I26+I27 -> 0 | J25: =J26+J27 -> 0 | K25: =K26+K27 -> 432307 | L25: =L26+L27 -> 1321319 | M25: =M26+M27 -> 1212660 | N25: =N26+N27 -> 1250229 | ... AK25: =AK26+AK27 -> 0 | AN25: =SUM(G25:AL25) -> 14223412
D26: OLEIN IV 56 | F26: Kg | G26: ='[1]01'!$P$20 -> 310941 | H26: ='[2]02'!$P$20 -> 518225 | I26: 0 | J26: 0 | K26: ='[3]05'!$P$20 -> 384558 | L26: 1080575 | M26: ='[3]07'!$P$22 -> 1006716 | N26: 1023788 | O26: 665308 | P26: 722385 | Q26: 913100 | R26: 165357 | S26: 478290 | T26: 1006655 | U26: 329308 | V26: ='[5]16'!$P$20 -> 558630 | W26: ='[5]17'!$P$20 -> 355043 | X26: 0 | Y26: 0 | Z26: ='[6]20'!$P$21 -> 237525 | AA26: ='[14]21'!$P$23 -> 673349 | AB26: ='[8]22'!$P$21 -> 872454 | AC26: ='[9]23'!$P$21 -> 368020 | AD26: 0 | AE26: 0 | AF26: 0 | AG26: 0 | AH26: 0 | AI26: 0 | AJ26: 0 | AK26: 0 | AL26: 0 | AN26: =SUM(G26:AL26) -> 11670227
D27: STEARIN | F27: Kg | G27: 40500 | H27: 60500 | I27: 0 | J27: 0 | K27: 47749 | L27: 240744 | M27: ='[3]07'!$P$30 -> 205944 | N27: 226441 | O27: 145526 | P27: 152583 | Q27: 215093 | R27: 43380 | S27: 85165 | T27: 194412 | U27: 131652 | V27: ='[5]16'!$P$29 -> 86388 | W27: ='[5]17'!$P$30 -> 137403 | X27: 0 | Y27: 0 | Z27: ='[6]20'!$P$29 -> 47314 | AA27: ='[14]21'!$P$30 -> 185623 | AB27: ='[8]22'!$P$27 -> 246668 | AC27: 60100 | AD27: 0 | AE27: 0 | AF27: 0 | AG27: 0 | AH27: 0 | AI27: 0 | AJ27: 0 | AK27: 0 | AL27: 0 | AN27: =SUM(G27:AL27) -> 2553185 | AS27: =AN27+AN31+AN36+AN40+AN46 -> 5456593
D28: Fractionation OLEIN IV 57 ( Bulk ) | AN28: Olein IV 57 ( Bulk )
D29: RBDPO Consume | F29: Kg | G29: =G30+G31 -> 0 | H29: =H30+H31 -> 0 | I29: =I30+I31 -> 0 | J29: =J30+J31 -> 0 | L29: =L30+L31 -> 0 | M29: =M30+M31 -> 0 | N29: =N30+N31 -> 0 | O29: =O30+O31 -> 0 | P29: =P30+P31 -> 0 | Q29: =Q30+Q31 -> 0 | R29: =R30+R31 -> 0 | S29: =S30+S31 -> 0 | ... AL29: =AL30+AL31 -> 0 | AN29: =SUM(G29:AK29) -> 0
D30: OLEIN IV 57 | F30: Kg | G30: 0 | H30: 0 | I30: 0 | J30: 0 | K30: 0 | L30: 0 | M30: 0 | N30: 0 | O30: 0 | P30: 0 | Q30: 0 | R30: 0 | S30: 0 | T30: 0 | U30: 0 | V30: 0 | W30: 0 | X30: 0 | Y30: 0 | Z30: 0 | AA30: 0 | AB30: 0 | AC30: 0 | AD30: 0 | AE30: 0 | AF30: 0 | AG30: 0 | AH30: 0 | AI30: 0 | AJ30: 0 | AK30: 0 | AL30: 0 | AN30: =SUM(G30:AK30) -> 0
D31: STEARIN | F31: Kg | G31: 0 | H31: 0 | I31: 0 | J31: 0 | K31: 0 | L31: 0 | M31: 0 | N31: 0 | O31: 0 | P31: 0 | Q31: 0 | R31: 0 | S31: 0 | T31: 0 | U31: 0 | V31: 0 | W31: 0 | X31: 0 | Y31: 0 | Z31: 0 | AA31: 0 | AB31: 0 | AC31: 0 | AD31: 0 | AE31: 0 | AF31: 0 | AG31: 0 | AH31: 0 | AI31: 0 | AJ31: 0 | AK31: 0 | AL31: 0 | AN31: =SUM(G31:AK31) -> 0
D32: Fractionation OLEIN IV 57 ( Retail ) | AN32: Olein IV 57 ( Retail )
D33: CPO Consume | F33: Kg | P33: 0 | Q33: 0 | R33: 0 | S33: 0 | T33: 0 | U33: 0 | V33: 0 | W33: 0 | X33: 0 | Y33: 0 | Z33: 0 | AA33: 0 | AB33: 0 | AC33: 0 | AD33: 0 | AE33: 0 | AF33: 0 | AG33: 0 | AH33: 0 | AI33: 0 | AJ33: 0 | AK33: 0 | AL33: 0 | AN33: =SUM(G33:AK33) -> 0
D34: RBDPO Brand Consume | F34: Kg | G34: =G35+G36 -> 0 | H34: =H35+H36 -> 0 | I34: =I35+I36 -> 0 | J34: =J35+J36 -> 0 | K34: =K35+K36 -> 0 | L34: =L35+L36 -> 0 | M34: =M35+M36 -> 0 | N34: =N35+N36 -> 0 | ... AL34: =AL35+AL36 -> 0 | AN34: =SUM(G34:AK34) -> 0
D35: OLEIN IV 57 Low Color | F35: Kg | G35: 0 | H35: 0 | I35: 0 | J35: 0 | K35: 0 | L35: 0 | M35: 0 | N35: 0 | O35: 0 | P35: 0 | Q35: 0 | R35: 0 | S35: 0 | T35: 0 | U35: 0 | V35: 0 | W35: 0 | X35: 0 | Y35: 0 | Z35: 0 | AA35: 0 | AB35: 0 | AC35: 0 | AD35: 0 | AE35: 0 | AF35: 0 | AG35: 0 | AH35: 0 | AI35: 0 | AJ35: 0 | AN35: =SUM(G35:AK35) -> 0
D36: STEARIN | F36: Kg | G36: 0 | H36: 0 | I36: 0 | J36: 0 | K36: 0 | L36: 0 | M36: 0 | N36: 0 | O36: 0 | P36: 0 | Q36: 0 | R36: 0 | S36: 0 | T36: 0 | U36: 0 | V36: 0 | W36: 0 | X36: 0 | Y36: 0 | Z36: 0 | AA36: 0 | AB36: 0 | AC36: 0 | AD36: 0 | AE36: 0 | AF36: 0 | AG36: 0 | AH36: 0 | AI36: 0 | AJ36: 0 | AN36: =SUM(G36:AK36) -> 0
D37: Fractionation OLEIN IV 58 ( Bulk ) | AN37: Olein IV 58 ( Bulk )
D38: RBDPO Consume | E38: =E39+E40 -> 21429000 | F38: Kg | G38: =G39+G40 -> 579175 | H38: =H39+H40 -> 393236 | I38: =I39+I40 -> 860808 | J38: =J39+J40 -> 963967 | K38: =K39+K40 -> 620511 | L38: =L39+L40 -> 0 | M38: =M39+M40 -> 0 | N38: =N39+N40 -> 0 | ... AL38: =AL39+AL40 -> 0 | AN38: =SUM(G38:AL38) -> 9837344
D39: OLEIN IV 58 | E39: 15000000 | F39: Kg | G39: ='[1]01'!$P$21 -> 396390 | H39: ='[2]02'!$P$21 -> 273297 | I39: ='[2]03'!$P$21 -> 637018 | J39: ='[2]04'!$P$21 -> 714860 | K39: ='[3]05'!$P$21 -> 443511 | L39: 0 | M39: 0 | N39: 0 | O39: 0 | P39: 0 | Q39: 0 | R39: 0 | S39: 0 | T39: 0 | U39: 0 | V39: 0 | W39: 0 | X39: 0 | Y39: 0 | Z39: 0 | AA39: 0 | AB39: 0 | AC39: ='[9]23'!$P$22 -> 158029 | AD39: ='[9]24'!$P$22 -> 449001 | AE39: ='[9]25'!$P$22 -> 547847 | AF39: 598477 | AG39: ='[10]27'!$P$22 -> 558944 | AH39: ='[11]28'!$P$22 -> 644632 | AI39: ='[12]29'!$P$22 -> 193043 | AJ39: ='[13]30'!$P$22 -> 670371 | AK39: ='[5]31 Stok Opname'!$P$22 -> 706516 | AN39: =SUM(G39:AL39) -> 6991936
D40: STEARIN | E40: 6429000 | F40: Kg | G40: ='[1]01'!$P$30-G27 -> 182785 | H40: ='[2]02'!$P$30-H27 -> 119939 | I40: ='[2]03'!$P$30 -> 223790 | J40: ='[2]04'!$P$30 -> 249107 | K40: ='[9]05'!$P$30-K27 -> 177000 | L40: 0 | M40: 0 | N40: 0 | O40: 0 | P40: 0 | Q40: 0 | R40: 0 | S40: 0 | T40: 0 | U40: 0 | V40: 0 | W40: 0 | X40: 0 | Y40: 0 | Z40: 0 | AA40: 0 | AB40: 0 | AC40: ='[9]23'!$P$30-AC27 -> 88370 | AD40: ='[9]24'!$P$30 -> 205696 | AE40: ='[9]25'!$P$30 -> 240847 | AF40: 233031 | AG40: ='[10]27'!$P$28 -> 222549 | AH40: ='[11]28'!$P$30 -> 286390 | AI40: ='[12]29'!$P$30-AI46 -> 92356 | AJ40: ='[13]30'!$P$28 -> 246904 | AK40: ='[5]31 Stok Opname'!$P$30 -> 276644 | AN40: =SUM(G40:AL40) -> 2845408
...

Sheet HPP REF 
B2: Refinery Cost
B3: No | C3: Item Cost | D3: Norma | F3: Pemakaian / Hari | H3: HK | J3: Total Pemakaian | K3: Harga / stn | M3: Total Biaya | N3: Rp / kg | O3: Kurs | P3: USD/MT
B4: Through Put CPO Proses (Ton/Day) | O4: ='Agustus - 2024'!AQ7 -> 0 | P4: Days
B5: Working Day | O5: 18 | P5: Days
B6: Operation By PLN | O6: 300 | P6: Days
B7: Operation By Genset | O7: =[15]Formula!G6 -> 0 | P7: Days
B8: Total CPO Process | O8: 600000 | P8: MTPY
B9: KURS | O9: 16200 | P9: Rp/USD
B10: 1 | C10: Bleaching Earth | D10: ='Agustus - 2024'!AN63 -> 1.1201463 | E10: kg/ton | F10: =D10*$O$4*1000 -> 0 | G10: Kg/day | H10: =O5 -> 18 | J10: =H10*F10 -> 0 | K10: 2750 | M10: =K10*J10 -> 0 | N10: =M10/($O$5*$O$4*1000) -> #DIV/0! | O10: =O9 -> 16200 | P10: =(M10/O10)/($O$4*$O$5) -> #DIV/0! | Q10: 44.1 | R10: 3.0413793
B11: 2 | C11: Phosporic acid | D11: ='Agustus - 2024'!AN67 -> 0.050873473 | E11: kg/ton | F11: =D11*$O$4*1000 -> 0 | G11: Kg/day | H11: =O5 -> 18 | J11: =H11*F11 -> 0 | K11: 18100 | M11: =K11*J11 -> 0 | N11: =M11/($O$5*$O$4*1000) -> #DIV/0! | O11: =O10 -> 16200 | P11: =(M11/O11)/($O$4*$O$5) -> #DIV/0! | Q11: 9.35 | R11: 0.64482759
B12: 3 | C12: Caustic Soda | D12: =(35*25)/30 -> 29.166667 | E12: kg/day | F12: =D12 -> 29.166667 | G12: kg/day | H12: =O5 -> 18 | J12: =H12*F12 -> 525 | K12: 15700 | M12: =K12*J12 -> 8242500 | N12: =M12/($O$5*$O$4*1000) -> #DIV/0! | O12: =O11 -> 16200 | P12: =(M12/O12)/($O$4*$O$5) -> #DIV/0!
B13: 4 | C13: Pemakaian Natural Gas HPB Geka | Q13: 32 | R13: 2.2068966
C14: Normal Consumption | D14: 0.18 | E14: MMBTU/MT CPO | F14: =D14*O4 -> 0 | G14: MMBTU/day | H14: =O5 -> 18 | J14: =H14*F14 -> 0 | K14: =L14*O9 -> 205740 | L14: 12.7 | M14: =K14*J14 -> 0 | N14: =M14/($O$5*$O$4*1000) -> #DIV/0! | O14: =O11 -> 16200 | P14: =(M14/O14)/($O$4*$O$5) -> #DIV/0!
C15: Penalty Below Consumption | D15: 0 | E15: MMBTU/MT CPO | F15: =D15*O4 -> 0 | G15: MMBTU/day | H15: =O5 -> 18 | J15: =H15*F15 -> 0 | K15: =12.7*O9 -> 205740 | M15: =K15*J15 -> 0 | N15: =M15/($O$5*$O$4*1000) -> #DIV/0! | O15: =O14 -> 16200 | P15: =(M15/O15)/($O$4*$O$5) -> #DIV/0!
C16: Penalty Above Consumption | D16: 0 | E16: MMBTU/MT CPO | F16: =D16*O4 -> 0 | G16: MMBTU/day | H16: =O5 -> 18 | J16: =H16*F16 -> 0 | K16: =12.7*O9 -> 205740 | M16: =K16*J16 -> 0 | N16: =M16/($O$5*$O$4*1000) -> #DIV/0! | O16: =O15 -> 16200 | P16: =(M16/O16)/($O$4*$O$5) -> #DIV/0!
B17: 5 | C17: Steam
C18: For Process | D18: 45.12 | E18: Kg/MT CPO | F18: =(D18*$O$4)/1000 -> 0 | G18: Ton/day | H18: =O5 -> 18 | J18: =(H18*F18) -> 0 | K18: ='[16]MP BOILER'!H15 -> 516233.21 | M18: =(F18*H18*K18)+(F18*I18*L18) -> 0 | N18: =M18/($O$5*$O$4*1000) -> #DIV/0! | O18: =O16 -> 16200 | P18: =(M18/O18)/($O$4*$O$5) -> #DIV/0! | Q18: 32.16 | R18: 2.217931
C19: Storage Tank for Heating | D19: 30 | E19: Kg/MT CPO | F19: =(D19*$O$4)/1000 -> 0 | G19: Ton/day | H19: =O5 -> 18 | J19: =H19*F19 -> 0 | K19: ='[16]MP BOILER'!H15 -> 516233.21 | M19: =(F19*H19*K19)+(F19*I19*L19) -> 0 | N19: =M19/($O$5*$O$4*1000) -> #DIV/0! | O19: =O18 -> 16200 | P19: =(M19/O19)/($O$4*$O$5) -> #DIV/0!
B20: 6 | C20: Electrical
C21: For Process | D21: =1.5 -> 1.5 | E21: kW/MT CPO | F21: =D21*$O$4 -> 0 | G21: kW/day | H21: =O6 -> 300 | I21: =O7 -> 0 | J21: =(H21*F21)+(F21*I21) -> 0 | K21: 1550 | M21: =(F21*H21*K21)+(F21*I21*L21) -> 0 | N21: =M21/($O$5*$O$4*1000) -> #DIV/0! | O21: =O19 -> 16200 | P21: =(M21/O21)/($O$4*$O$5) -> #DIV/0!
C22: Cooling Tower | D22: =1.18 -> 1.18 | E22: kW/MT CPO | F22: =D22*$O$4 -> 0 | G22: kW/day | H22: =H21 -> 300 | I22: =$O$7 -> 0 | J22: =(H22*F22)+(F22*I22) -> 0 | K22: 1550 | M22: =(F22*H22*K22)+(F22*I22*L22) -> 0 | N22: =M22/($O$5*$O$4*1000) -> #DIV/0! | O22: =O21 -> 16200 | P22: =(M22/O22)/($O$4*$O$5) -> #DIV/0!
C23: Storage Tank | D23: =(680.98/24)/84 -> 0.3377877 | E23: kW/MT CPO | F23: =D23*$O$4 -> 0 | G23: kW/day | H23: =H22 -> 300 | I23: =$O$7 -> 0 | J23: =(H23*F23)+(F23*I23) -> 0 | K23: 1550 | M23: =(F23*H23*K23)+(F23*I23*L23) -> 0 | N23: =M23/($O$5*$O$4*1000) -> #DIV/0! | O23: =O22 -> 16200 | P23: =(M23/O23)/($O$4*$O$5) -> #DIV/0!
B24: 7 | C24: Water | Q24: 0.29484 | R24: 0.020333793
C25: Make Up CT | D25: 60 | E25: M3/day | F25: =D25 -> 60 | G25: =E25 -> M3/day | H25: =O5 -> 18 | J25: =H25*F25 -> 1080 | K25: =[15]L.Water!F6 -> 8700 | M25: =K25*J25 -> 9396000 | N25: =M25/($O$5*$O$4*1000) -> #DIV/0! | O25: =O23 -> 16200 | P25: =(M25/O25)/($O$4*$O$5) -> #DIV/0!
B26: 8 | C26: Chemical Water | Q26: 32.592264 | R26: 2.2477424
C27: EONBAC BC 3108 | D27: 0.4 | E27: Kg/day | F27: =D27 -> 0.4 | G27: =E27 -> Kg/day | H27: =O5 -> 18 | J27: =H27*F27 -> 7.2 | K27: 27240 | M27: =K27*J27 -> 196128 | N27: =M27/($O$5*$O$4*1000) -> #DIV/0! | O27: =O25 -> 16200 | P27: =(M27/O27)/($O$4*$O$5) -> #DIV/0!
C28: EONLINE T722 | D28: 0.66 | E28: Kg/day | F28: =D28 -> 0.66 | G28: =E28 -> Kg/day | H28: =O5 -> 18 | J28: =H28*F28 -> 11.88 | K28: 29120 | M28: =K28*J28 -> 345945.6 | N28: =M28/($O$5*$O$4*1000) -> #DIV/0! | O28: =O27 -> 16200 | P28: =(M28/O28)/($O$4*$O$5) -> #DIV/0!
C29: EONLINE AG5770 | D29: 0.41 | E29: Kg/day | F29: =D29 -> 0.41 | G29: =E29 -> Kg/day | H29: =O5 -> 18 | J29: =H29*F29 -> 7.38 | K29: 117212 | M29: =K29*J29 -> 865024.56 | N29: =M29/($O$5*$O$4*1000) -> #DIV/0! | O29: =O27 -> 16200 | P29: =(M29/O29)/($O$4*$O$5) -> #DIV/0!
C30: EONScale T2511 | D30: 0.1 | E30: Kg/day | F30: =D30 -> 0.1 | G30: =E30 -> Kg/day | H30: =O5 -> 18 | J30: =H30*F30 -> 1.8 | K30: 45940 | M30: =K30*J30 -> 82692 | N30: =M30/($O$5*$O$4*1000) -> #DIV/0! | O30: =O28 -> 16200 | P30: =(M30/O30)/($O$4*$O$5) -> #DIV/0!
B31: 9 | C31: Others | Q31: 2.7410526 | R31: 0.18903811
C32: Filter Bag 10 Microne | D32: =300/332 -> 0.90361446 | E32: Pcs/day | F32: =D32 -> 0.90361446 | G32: =E32 -> Pcs/day | H32: =O5 -> 18 | J32: =H32*F32 -> 16.26506 | K32: 40000 | M32: =J32*K32 -> 650602.41 | N32: =M32/($O$5*$O$4*1000) -> #DIV/0! | O32: =O30 -> 16200 | P32: =(M32/O32)/($O$4*$O$5) -> #DIV/0!
C33: Filter Bag 100 Microne | D33: =210/332 -> 0.63253012 | E33: Pcs/day | F33: =D33 -> 0.63253012 | G33: =E33 -> Pcs/day | H33: =O5 -> 18 | J33: =H33*F33 -> 11.385542 | K33: 125000 | M33: =J33*K33 -> 1423192.8 | N33: =M33/($O$5*$O$4*1000) -> #DIV/0! | O33: =O32 -> 16200 | P33: =(M33/O33)/($O$4*$O$5) -> #DIV/0!
C34: Filter Cartridge 10 Microne | D34: =47/30 -> 1.5666667 | E34: Pcs/day | F34: =D34 -> 1.5666667 | G34: =E34 -> Pcs/day | H34: =O5 -> 18 | J34: =H34*F34 -> 28.2 | K34: 145000 | M34: =J34*K34 -> 4089000 | N34: =M34/($O$5*$O$4*1000) -> #DIV/0! | O34: =O33 -> 16200 | P34: =(M34/O34)/($O$4*$O$5) -> #DIV/0!
C35: Filter Dustbag | D35: =40/332 -> 0.12048193 | E35: Pcs/day | F35: =D35 -> 0.12048193 | G35: =E35 -> Pcs/day | H35: =O5 -> 18 | J35: =H35*F35 -> 2.1686747 | K35: 682500 | M35: =J35*K35 -> 1480120.5 | N35: =M35/($O$5*$O$4*1000) -> #DIV/0! | O35: =O34 -> 16200 | P35: =(M35/O35)/($O$4*$O$5) -> #DIV/0!
C36: O Ring Filter Leaves | D36: =1200/332 -> 3.6144578 | E36: Pcs/day | F36: =D36 -> 3.6144578 | G36: =E36 -> Pcs/day | H36: =O5 -> 18 | J36: =H36*F36 -> 65.060241 | K36: 14500 | M36: =J36*K36 -> 943373.49 | N36: =M36/($O$5*$O$4*1000) -> #DIV/0! | O36: =O35 -> 16200 | P36: =(M36/O36)/($O$4*$O$5) -> #DIV/0!
B37: 10 | C37: Waste Water | D37: =200 -> 200 | E37: M3/day | F37: =D37 -> 200 | G37: =E37 -> M3/day | H37: =O5 -> 18 | J37: =H37*F37 -> 3600 | K37: =[16]L.WWTP!H17 -> 27499.717 | M37: =J37*K37 -> 98998981 | N37: =M37/($O$5*$O$4*1000) -> #DIV/0! | O37: =O36 -> 16200 | P37: =(M37/O37)/($O$4*$O$5) -> #DIV/0! | Q37: 1.0462652 | R37: 0.072156222
B38: 11 | C38: SHE
C39: SBE | D39: =(D10*O4*1000)*120% -> 0 | E39: Kg/day | F39: =D39 -> 0 | G39: Kg/day | H39: =O5 -> 18 | J39: =H39*F39 -> 0 | K39: 300 | M39: =J39*K39 -> 0 | N39: =M39/($O$5*$O$4*1000) -> #DIV/0! | O39: =O37 -> 16200 | P39: =(M39/O39)/($O$4*$O$5) -> #DIV/0!
C40: Domestic | D40: 0.1 | E40: Trip/day | F40: =D40 -> 0.1 | G40: Trip/day | H40: =O5 -> 18 | J40: =H40*F40 -> 1.8 | K40: 303030.3 | M40: =J40*K40 -> 545454.55 | N40: =M40/($O$5*$O$4*1000) -> #DIV/0! | O40: =O39 -> 16200 | P40: =(M40/O40)/($O$4*$O$5) -> #DIV/0!
B41: 12 | C41: Lab
...

Sheet HPP FRACT 
B2: Fractionation Cost
B3: No | C3: Item Cost | D3: Norma | F3: Pemakaian / Hari | H3: HK | J3: Total Pemakaian | K3: Harga / stn | M3: Total Biaya | N3: Rp / kg | O3: Kurs | P3: USD/MT
B4: RPO Proses / Day | O4: 2000 | P4: MTD
B5: Working Day | O5: 300 | P5: Days
B6: Operation By PLN | O6: 300 | P6: Days
B7: Operation By Genset | O7: =[15]Formula!G6 -> 0 | P7: Days
B8: Total RBDPO Process | O8: 600000 | P8: MTPY
B9: KURS | O9: 16200 | P9: Rp/USD
B10: 1 | C10: Steam | D10: 60 | E10: Kg/MT CPO | F10: =(D10*$O$4)/1000 -> 120 | G10: Kg/day | H10: =O5 -> 300 | J10: =(H10*F10)+(I10*F10) -> 36000 | K10: ='[18]MP BOILER'!H15 -> 516233.21 | L10: 0 | M10: =(K10*H10*F10)+(L10*I10*F10) -> 1.8584396e+10 | N10: =M10/($O$5*$O$4*1000) -> 30.973993 | O10: =O9 -> 16200 | P10: =(M10/O10)/($O$4*$O$5) -> 1.9119749 | Q10: 32.16 | R10: 2.217931
B11: 2 | C11: Electrical
C12: For Process | D12: 3 | E12: kW/MT CPO | F12: =D12*$O$4 -> 6000 | G12: kW/day | H12: =O6 -> 300 | I12: =O7 -> 0 | J12: =H12*F12 -> 1800000 | K12: 1550 | M12: =(K12*H12*F12)+(L12*I12*F12) -> 2790000000 | N12: =M12/($O$5*$O$4*1000) -> 4.65 | O12: =O10 -> 16200 | P12: =(M12/O12)/($O$4*$O$5) -> 0.28703704
C13: Cooling Tower | D13: 1.97 | E13: kW/MT CPO | F13: =D13*$O$4 -> 3940 | G13: kW/day | H13: =O6 -> 300 | I13: =O7 -> 0 | J13: =H13*F13 -> 1182000 | K13: 1550 | M13: =(K13*H13*F13)+(L13*I13*F13) -> 1832100000 | N13: =M13/($O$5*$O$4*1000) -> 3.0535 | O13: =O12 -> 16200 | P13: =(M13/O13)/($O$4*$O$5) -> 0.18848765
B14: 3 | C14: Water | Q14: 0.29484 | R14: 0.020333793
C15: Make Up CT | D15: =110-60 -> 50 | E15: M3/day | F15: =D15 -> 50 | G15: =E15 -> M3/day | H15: =O5 -> 300 | J15: =H15*F15 -> 15000 | K15: =[18]LWTP!H13 -> 22504.09 | M15: =K15*J15 -> 3.3756135e+08 | N15: =M15/($O$5*$O$4*1000) -> 0.56260226 | O15: =O13 -> 16200 | P15: =(M15/O15)/($O$4*$O$5) -> 0.034728534
B16: 4 | C16: Chemical Water | Q16: 32.592264 | R16: 2.2477424
C17: EONBAC BC 3108 | D17: 0.4 | E17: Kg/day | F17: =D17 -> 0.4 | G17: =E17 -> Kg/day | H17: =O5 -> 300 | J17: =H17*F17 -> 120 | K17: 27240 | M17: =K17*J17 -> 3268800 | N17: =M17/($O$5*$O$4*1000) -> 0.005448 | O17: =O15 -> 16200 | P17: =(M17/O17)/($O$4*$O$5) -> 0.0003362963
C18: EONLINE T722 | D18: 0.66 | E18: Kg/day | F18: =D18 -> 0.66 | G18: =E18 -> Kg/day | H18: =O5 -> 300 | J18: =H18*F18 -> 198 | K18: 29120 | M18: =K18*J18 -> 5765760 | N18: =M18/($O$5*$O$4*1000) -> 0.0096096 | O18: =O17 -> 16200 | P18: =(M18/O18)/($O$4*$O$5) -> 0.00059318519
C19: EONLINE AG5770 | D19: 0.41 | E19: Kg/day | F19: =D19 -> 0.41 | G19: =E19 -> Kg/day | H19: =O5 -> 300 | J19: =H19*F19 -> 123 | K19: 117212 | M19: =K19*J19 -> 14417076 | N19: =M19/($O$5*$O$4*1000) -> 0.02402846 | O19: =O17 -> 16200 | P19: =(M19/O19)/($O$4*$O$5) -> 0.0014832383
C20: EONScale T2511 | D20: 0.1 | E20: Kg/day | F20: =D20 -> 0.1 | G20: =E20 -> Kg/day | H20: =O5 -> 300 | J20: =H20*F20 -> 30 | K20: 45940 | M20: =K20*J20 -> 1378200 | N20: =M20/($O$5*$O$4*1000) -> 0.002297 | O20: =O18 -> 16200 | P20: =(M20/O20)/($O$4*$O$5) -> 0.00014179012
B21: 5 | C21: Others | Q21: 2.7410526 | R21: 0.18903811
C22: Filter Cloth | D22: =110/330 -> 0.33333333 | E22: Pcs/day | F22: =D22*1 -> 0.33333333 | G22: =E22 -> Pcs/day | H22: =O5 -> 300 | J22: =F22*H22 -> 100 | K22: 895000 | M22: =J22*K22 -> 89500000 | N22: =M22/($O$5*$O$4*1000) -> 0.14916667 | O22: =O20 -> 16200 | P22: =(M22/O22)/($O$4*$O$5) -> 0.0092078189 | Q22: 0.27527033 | R22: 0.01898416
C23: Filter Bag 80 Microne monofilament | D23: =150/332 -> 0.45180723 | E23: Pcs/day | F23: =D23 -> 0.45180723 | G23: =E23 -> Pcs/day | H23: =O5 -> 300 | J23: =F23*H23 -> 135.54217 | K23: 130000 | M23: =J23*K23 -> 17620482 | N23: =M23/($O$5*$O$4*1000) -> 0.02936747 | O23: 16200 | P23: =(M23/O23)/($O$4*$O$5) -> 0.0018128068
C24: Filter Bag 100 Microne monofilament | D24: =150/332 -> 0.45180723 | E24: Pcs/day | F24: =D24 -> 0.45180723 | G24: =E24 -> Pcs/day | H24: =O5 -> 300 | J24: =F24*H24 -> 135.54217 | K24: 125000 | M24: =J24*K24 -> 16942771 | N24: =M24/($O$5*$O$4*1000) -> 0.028237952 | O24: =O22 -> 16200 | P24: =(M24/O24)/($O$4*$O$5) -> 0.0017430834
J25: Cost Fractionation/ CPO | M25: =SUM(M10:M24) -> 2.369295e+10 | N25: =SUM(N10:N24) -> 39.48825 | P25: =SUM(P10:P24) -> 2.4375463

Sheet SUMARY HPP
B2: actual cost juni 2024 based on chemical & utility
B3: Through Put CPO Proses (Ton/Day) | G3: =[16]REF!O4 -> 2200 | H3: MTD
B4: Through Put RBDPO Proses (Ton/Day) | G4: =[16]FRACT!O4 -> 4314 | H4: MTD
B5: Working Day | G5: 18 | H5: Days
B6: Operation By PLN | G6: 300 | H6: Days
B7: Operation By Genset | G7: 0 | H7: Days
B8: Total CPO Process | G8: =G3*G5 -> 39600 | H8: MTPY
B9: KURS | G9: 16200 | H9: Rp/USD
B10: No | C10: Items | D10: Description | F10: Rp/Tahun | G10: Rp/Kg | H10: USD/MT
B11: I | C11: Processing Cost | D11: 1 | E11: Refining Cost | F11: =[16]REF!M48 -> 1.6422668e+10 | G11: =F11/($G$8*1000) -> 414.71384 | H11: =(F11/$G$8)/$G$9 -> 25.59962
D12: 2 | E12: Fractionation Cost | F12: =[16]FRACT!M25 -> 1.7406851e+10 | G12: =F12/($G$8*1000) -> 439.56694 | H12: =(F12/$G$8)/$G$9 -> 27.133762
D13: 3 | E13: Preventive Maintenance Cost | F13: =[16]MTC!C15+[16]ELECTRICAL!C19 -> 9.4717847e+09 | G13: =F13/($G$8*1000) -> 239.18648 | H13: =(F13/$G$8)/$G$9 -> 14.764598
G14: =SUM(G11:G13) -> 1093.4673 | H14: =SUM(H11:H13) -> 67.497979
B15: II | C15: Fix Cost | D15: 1 | E15: Manpower Cost | F15: =SUM('[15]FC-1 New'!I17,'[15]FC-1 New'!I38) -> 5.7497185e+10 | G15: =F15/($G$8*1000) -> 1451.9491 | H15: =(F15/$G$8)/$G$9 -> 89.626489
D16: 2 | E16: Admin OH Cost | F16: ='[15]FC-2'!J69 -> 1.1780863e+10 | G16: =F16/($G$8*1000) -> 297.49655 | H16: =(F16/$G$8)/$G$9 -> 18.363984
D17: 3 | E17: Depresiasi Cost | F17: ='[15]FC-4'!E5 -> 4.1807174e+10 | G17: =F17/($G$8*1000) -> 1055.7367 | H17: =(F17/$G$8)/$G$9 -> 65.168933
D18: 4 | E18: Amortisation of leasehold land Cost | F18: ='[15]FC-5'!D5 -> 2.4145564e+10 | G18: =F18/($G$8*1000) -> 609.73647 | H18: =(F18/$G$8)/$G$9 -> 37.638053
G19: =SUM(G15:G18) -> 3414.9189 | H19: =SUM(H15:H18) -> 210.79746
B20: III | C20: Finance Cost | D20: 1 | E20: Beban Keuangan | F20: =[15]Finance!H8 -> 5.7976217e+10 | G20: =F20/($G$8*1000) -> 1464.0459 | H20: =(F20/$G$8)/$G$9 -> 90.373203
D21: 2 | E21: Beban Operasional Lainnya | F21: =[15]Finance!H22 -> 0 | G21: =F21/($G$8*1000) -> 0 | H21: =(F21/$G$8)/$G$9 -> 0
D22: 3 | E22: Beban Lain-Lain | F22: =[15]Finance!H26 -> 0 | G22: =F22/($G$8*1000) -> 0 | H22: =(F22/$G$8)/$G$9 -> 0
G23: =SUM(G20:G22) -> 1464.0459 | H23: =SUM(H20:H22) -> 90.373203
B24: IV | C24: Sales Cost | D24: 1 | E24: Sales Cost Bulk | F24: ='[15]Sales-1'!M26 -> 1.192173e+11 | G24: =F24/($G$8*1000) -> 3010.5378 | H24: =(F24/$G$8)/$G$9 -> 185.83566
D25: 2 | E25: Sales Cost Retail | F25: ='[15]Sales-2'!G13 -> 7.9024016e+10 | G25: =F25/($G$8*1000) -> 1995.5559 | H25: =(F25/$G$8)/$G$9 -> 123.18247
G26: =SUM(G24:G25) -> 5006.0937 | H26: =SUM(H24:H25) -> 309.01813
F27: =(SUM(F11:F26)/G9)/G8 -> 677.68677 | H27: =SUM(H14,H19,H23,H24) -> 554.50431

Sheet Convert Gas
B3: CONVERT PEMAKAIAN GAS HP BOILER & MP BOILER
D4: 2024
C5: HP BOILER | F5: TOTAL CORRECTED VOLUME (Sm3) | K5: ENERGY MP BOILER (MMBTU) | L5: TOTAL GAS CONSUMPTION (MMBTU) | M5: PERCENTAGE
C6: UNCORRECTED VOLUME (UV) (m3) | D6: PRESS. Bar | E6: CORRECTED VOLUME (CV) (Sm3) | G6: Convert Sm3 to SCF | H6: VOLUME (MSCF) | I6: HEATING VALUE (BTU / SCF) | J6: ENERGY HP BOILER (MMBTU) | M6: HP Boiler | N6: MP Boiler
C7: 1 | D7: 2 | E7: 3 = 1 x 2 | F7: 4 = 3 | G7: 5 | H7: 6 = (4 x 5) / 1000 | I7: 7 | J7: 8 = (6 x 7) / 1000 | K7: 9 = 10 - 8 | L7: 10 | M7: 11 = 8 / 10 | N7: 12 = 9 / 10
B8: 1 | C8: 1266.7 | D8: 5 | E8: =C8*D8 -> 6333.5 | F8: =E8 -> 6333.5 | G8: 35.314667 | H8: =(F8*G8)/1000 -> 223.66544 | I8: 1062.2961 | J8: =(H8*I8)/1000 -> 237.59894 | K8: =L8-J8 -> -237.59894 | M8: =(J8/L8) -> #DIV/0! | N8: =K8/L8 -> #DIV/0!
B9: =B8+1 -> 2 | C9: 1335.7 | D9: 5 | E9: =C9*D9 -> 6678.5 | F9: =E9 -> 6678.5 | G9: 35.314667 | H9: =(F9*G9)/1000 -> 235.849 | I9: 1061.8892 | J9: =(H9*I9)/1000 -> 250.4455 | K9: =L9-J9 -> -250.4455 | M9: =(J9/L9) -> #DIV/0! | N9: =K9/L9 -> #DIV/0!
B10: =B9+1 -> 3 | C10: 1352.6 | D10: 5 | E10: =C10*D10 -> 6763 | F10: =E10 -> 6763 | G10: 35.314667 | H10: =(F10*G10)/1000 -> 238.83309 | I10: 1061.3033 | J10: =(H10*I10)/1000 -> 253.47436 | K10: =L10-J10 -> -253.47436 | M10: =(J10/L10) -> #DIV/0! | N10: =K10/L10 -> #DIV/0!
B11: =B10+1 -> 4 | C11: 1378.9 | D11: 5 | E11: =C11*D11 -> 6894.5 | F11: =E11 -> 6894.5 | G11: 35.314667 | H11: =(F11*G11)/1000 -> 243.47697 | I11: 1060.7416 | J11: =(H11*I11)/1000 -> 258.26615 | K11: =L11-J11 -> -258.26615 | M11: =(J11/L11) -> #DIV/0! | N11: =K11/L11 -> #DIV/0!
B12: =B11+1 -> 5 | C12: 654.3 | D12: 5 | E12: =C12*D12 -> 3271.5 | F12: =E12 -> 3271.5 | G12: 35.314667 | H12: =(F12*G12)/1000 -> 115.53193 | I12: 1057.9053 | J12: =(H12*I12)/1000 -> 122.22184 | K12: =L12-J12 -> -122.22184 | M12: =(J12/L12) -> #DIV/0! | N12: =K12/L12 -> #DIV/0!
B13: =B12+1 -> 6 | C13: 1129.3 | D13: 5 | E13: =C13*D13 -> 5646.5 | F13: =E13 -> 5646.5 | G13: 35.314667 | H13: =(F13*G13)/1000 -> 199.40427 | I13: 1059.3735 | J13: =(H13*I13)/1000 -> 211.2436 | K13: =L13-J13 -> -211.2436 | M13: =(J13/L13) -> #DIV/0! | N13: =K13/L13 -> #DIV/0!
B14: =B13+1 -> 7 | C14: 503.2 | D14: 5 | E14: =C14*D14 -> 2516 | F14: =E14 -> 2516 | G14: 35.314667 | H14: =(F14*G14)/1000 -> 88.851702 | I14: 1056.9999 | J14: =(H14*I14)/1000 -> 93.916238 | K14: =L14-J14 -> -93.916238 | M14: =(J14/L14) -> #DIV/0! | N14: =K14/L14 -> #DIV/0!
B15: =B14+1 -> 8 | C15: 610.8 | D15: 5 | E15: =C15*D15 -> 3054 | F15: =E15 -> 3054 | G15: 35.314667 | H15: =(F15*G15)/1000 -> 107.85099 | I15: 1037.3219 | J15: =(H15*I15)/1000 -> 111.87619 | K15: =L15-J15 -> -111.87619 | M15: =(J15/L15) -> #DIV/0! | N15: =K15/L15 -> #DIV/0!
B16: =B15+1 -> 9 | C16: 1327.2 | D16: 5 | E16: =C16*D16 -> 6636 | F16: =E16 -> 6636 | G16: 35.314667 | H16: =(F16*G16)/1000 -> 234.34813 | I16: 1045.3993 | J16: =(H16*I16)/1000 -> 244.98737 | K16: =L16-J16 -> -244.98737 | M16: =(J16/L16) -> #DIV/0! | N16: =K16/L16 -> #DIV/0!
B17: =B16+1 -> 10 | C17: 1237.5 | D17: 5 | E17: =C17*D17 -> 6187.5 | F17: =E17 -> 6187.5 | G17: 35.314667 | H17: =(F17*G17)/1000 -> 218.5095 | I17: 1047.8158 | J17: =(H17*I17)/1000 -> 228.95771 | K17: =L17-J17 -> -228.95771 | M17: =(J17/L17) -> #DIV/0! | N17: =K17/L17 -> #DIV/0!
B18: =B17+1 -> 11 | C18: 541.5 | D18: 5 | E18: =C18*D18 -> 2707.5 | F18: =E18 -> 2707.5 | G18: 35.314667 | H18: =(F18*G18)/1000 -> 95.614461 | I18: 1048.465 | J18: =(H18*I18)/1000 -> 100.24841 | K18: =L18-J18 -> -100.24841 | M18: =(J18/L18) -> #DIV/0! | N18: =K18/L18 -> #DIV/0!
B19: =B18+1 -> 12 | C19: 514.4 | D19: 5 | E19: =C19*D19 -> 2572 | F19: =E19 -> 2572 | G19: 35.314667 | H19: =(F19*G19)/1000 -> 90.829324 | I19: 1044.9255 | J19: =(H19*I19)/1000 -> 94.909879 | K19: =L19-J19 -> -94.909879 | M19: =(J19/L19) -> #DIV/0! | N19: =K19/L19 -> #DIV/0!
B20: =B19+1 -> 13 | C20: 1349.3 | D20: 5 | E20: =C20*D20 -> 6746.5 | F20: =E20 -> 6746.5 | G20: 35.314667 | H20: =(F20*G20)/1000 -> 238.2504 | I20: 1048.4922 | J20: =(H20*I20)/1000 -> 249.80368 | K20: =L20-J20 -> -249.80368 | M20: =(J20/L20) -> #DIV/0! | N20: =K20/L20 -> #DIV/0!
... B38: =B37+1 -> 31 | C38: 1028.9 | D38: 5 | E38: =C38*D38 -> 5144.5 | F38: =E38 -> 5144.5 | G38: 52.314667 | H38: =(F38*G38)/1000 -> 269.1328 | I38: 1063.1716 | J38: =(H38*I38)/1000 -> 286.13436 | K38: =L38-J38 -> -286.13436 | M38: =(J38/L38) -> #DIV/0! | N38: =K38/L38 -> #DIV/0!
B39: Average | F39: =AVERAGE(F8:F38) -> 5031.6129 | H39: =AVERAGE(H8:H38) -> 202.03544 | I39: =AVERAGE(I8:I38) -> 1056.8169 | J39: =AVERAGE(J8:J38) -> 213.80604 | K39: =AVERAGE(K8:K38) -> -213.80604 | L39: =AVERAGE(L8:L38) -> #DIV/0! | M39: =AVERAGE(M8:M38) -> #DIV/0! | N39: =AVERAGE(N8:N38) -> #DIV/0!
B40: TOTAL | C40: =SUM(C8:C38) -> 31196 | E40: =SUM(E8:E38) -> 155980 | F40: =SUM(F8:F38) -> 155980 | H40: =SUM(H8:H38) -> 6263.0988 | J40: =SUM(J8:J38) -> 6627.9873
B41: Koreksi
B42: Total Setelah Koreksi | H42: =H40+H41 -> 6263.0988 | J42: =J40+J41 -> 6627.9873
C44: CONVERT HP Boiler from Utility
C45: =C40 -> 31196 | D45: m3 | F45: =C40*5 -> 155980 | G45: 9983.7
C46: 5 | D46: bar | F46: 21286.9 | G46: =G45-C40 -> -21212.3
C47: =C45*C46 -> 155980 | D47: Sm3 | F47: =F45/F46 -> 7.3275113
C48: =G38 -> 52.314667 | D48: Scf
C49: =(C47*C48)/1000 -> 8160.0418 | D49: Volume (MSCF)
C50: =I39 -> 1056.8169 | D50: Heating Value
C51: =(C49*C50)/1000 -> 8623.6697 | D51: Energy (mmbtu)

Sheet OIP Refinery
B2: Oil In Plant Refinery
B4: No | C4: Tanggal | D4: Opening Stock | E4: Closing Stock | F4: Closing Stock | G4: Selisih OIP Consume
B5: 1 | C5: 01 Agustus 2024 | D5: 268536 | E5: 278115 | F5: 278115 | G5: =E5-D5 -> 9579
B6: 2 | C6: 02 Agustus 2024 | D6: =E5 -> 278115 | E6: 218067 | F6: 218067 | G6: =E6-D6 -> -60048
B7: 3 | C7: 03 Agustus 2024 | D7: =E6 -> 218067 | E7: 257614 | F7: 257614 | G7: =E7-D7 -> 39547
B8: 4 | C8: 04 Agustus 2024 | D8: =E7 -> 257614 | E8: 246851 | F8: 246851 | G8: =E8-D8 -> -10763
B9: 5 | C9: 05 Agustus 2024 | D9: =E8 -> 246851 | E9: 255653 | F9: 255653 | G9: =E9-D9 -> 8802
B10: 6 | C10: 06 Agustus 2024 | D10: =E9 -> 255653 | E10: 258450 | F10: 258450 | G10: =E10-D10 -> 2797
B11: 7 | C11: 07 Agustus 2024 | D11: =E10 -> 258450 | E11: 238552 | F11: 238552 | G11: =E11-D11 -> -19898
B12: 8 | C12: 08 Agustus 2024 | D12: =E11 -> 238552 | E12: 283505 | F12: 283505 | G12: =E12-D12 -> 44953
B13: 9 | C13: 09 Agustus 2024 | D13: =E12 -> 283505 | E13: 269320 | F13: 269320 | G13: =E13-D13 -> -14185
B14: 10 | C14: 10 Agustus 2024 | D14: =E13 -> 269320 | E14: 281809 | F14: 281809 | G14: =E14-D14 -> 12489
B15: 11 | C15: 11 Agustus 2024 | D15: =E14 -> 281809 | E15: 267958 | F15: 267958 | G15: =E15-D15 -> -13851
B16: 12 | C16: 12 Agustus 2024 | D16: =E15 -> 267958 | E16: 267268 | F16: 267268 | G16: =E16-D16 -> -690
B17: 13 | C17: 13 Agustus 2024 | D17: =E16 -> 267268 | E17: 285895 | F17: 285895 | G17: =E17-D17 -> 18627
B18: 14 | C18: 14 Agustus 2024 | D18: =E17 -> 285895 | E18: 259934 | F18: =286934-27000 -> 259934 | G18: =E18-D18 -> -25961
B19: 15 | C19: 15 Agustus 2024 | D19: =E18 -> 259934 | E19: 229375 | F19: =259375-30000 -> 229375 | G19: =E19-D19 -> -30559
B20: 16 | C20: 16 Agustus 2024 | D20: =E19 -> 229375 | E20: 206080 | F20: 206080 | G20: =E20-D20 -> -23295
B21: 17 | C21: 17 Agustus 2024 | D21: =E20 -> 206080 | E21: 205580 | F21: 205580 | G21: =E21-D21 -> -500
B22: 18 | C22: 18 Agustus 2024 | D22: =E21 -> 205580 | E22: 204650 | F22: 204650 | G22: =E22-D22 -> -930
B23: 19 | C23: 19 Agustus 2024 | D23: =E22 -> 204650 | E23: 204650 | F23: 204650 | G23: =E23-D23 -> 0
B24: 20 | C24: 20 Agustus 2024 | D24: =E23 -> 204650 | E24: 239103 | F24: =259103-20000 -> 239103 | G24: =E24-D24 -> 34453
B25: 21 | C25: 21 Agustus 2024 | D25: =E24 -> 239103 | E25: 242878 | F25: =222878+20000 -> 242878 | G25: =E25-D25 -> 3775
B26: 22 | C26: 22 Agustus 2024 | D26: =E25 -> 242878 | E26: 243484 | F26: =222984+20500 -> 243484 | G26: =E26-D26 -> 606
B27: 23 | C27: 23 Agustus 2024 | D27: =E26 -> 243484 | E27: 219216 | F27: 219216 | G27: =E27-D27 -> -24268
B28: 24 | C28: 24 Agustus 2024 | D28: =E27 -> 219216 | E28: 244970 | F28: 244970 | G28: =E28-D28 -> 25754
B29: 25 | C29: 25 Agustus 2024 | D29: =E28 -> 244970 | E29: 234886 | F29: =209886+25000 -> 234886 | G29: =E29-D29 -> -10084
B30: 26 | C30: 26 Agustus 2024 | D30: =E29 -> 234886 | E30: 267925 | F30: 0 | G30: =E30-D30 -> 33039
B31: 27 | C31: 27 Agustus 2024 | D31: =E30 -> 267925 | E31: 263146 | F31: 0 | G31: =E31-D31 -> -4779
B32: 28 | C32: 28 Agustus 2024 | D32: =E31 -> 263146 | E32: 290180.2 | F32: 0 | G32: =E32-D32 -> 27034.2
B33: 29 | C33: 29 Agustus 2024 | D33: =E32 -> 290180.2 | E33: 263346 | F33: 0 | G33: =E33-D33 -> -26834.2
B34: 30 | C34: 30 Agustus 2024 | D34: =E33 -> 263346 | E34: 270438 | F34: 0 | G34: =E34-D34 -> 7092
B35: 31 | C35: 31 Agustus 2024 | D35: =E34 -> 270438 | E35: 283428 | F35: 0 | G35: =E35-D35 -> 12990

Sheet OIP Fract
B2: Oil In Plant Fract
B4: No | C4: Tanggal | D4: Opening Stock | E4: Closing Stock | F4: Stock Minyak
B5: 1 | C5: 01 Agustus 2024 | F5: =E5-D5 -> 0
B6: 2 | C6: 02 Agustus 2024 | D6: =E5 -> 0 | E6: 0 | F6: =E6-D6 -> 0
B7: 3 | C7: 03 Agustus 2024 | D7: =E6 -> 0 | E7: 0 | F7: =E7-D7 -> 0
B8: 4 | C8: 04 Agustus 2024 | D8: =E7 -> 0 | E8: 0 | F8: =E8-D8 -> 0
B9: 5 | C9: 05 Agustus 2024 | D9: =E8 -> 0 | E9: 0 | F9: =E9-D9 -> 0
B10: 6 | C10: 06 Agustus 2024 | D10: =E9 -> 0 | E10: 0 | F10: =E10-D10 -> 0
B11: 7 | C11: 07 Agustus 2024 | D11: =E10 -> 0 | E11: 630010 | F11: =E11-D11 -> 630010
B12: 8 | C12: 08 Agustus 2024 | D12: =E11 -> 630010 | E12: 452800 | F12: =E12-D12 -> -177210
B13: 9 | C13: 09 Agustus 2024 | D13: =E12 -> 452800 | E13: 0 | F13: =E13-D13 -> -452800
B14: 10 | C14: 10 Agustus 2024 | D14: =E13 -> 0 | E14: 0 | F14: =E14-D14 -> 0
B15: 11 | C15: 11 Agustus 2024 | D15: =E14 -> 0 | E15: 0 | F15: =E15-D15 -> 0
B16: 12 | C16: 12 Agustus 2024 | D16: =E15 -> 0 | E16: 32710 | F16: =E16-D16 -> 32710
B17: 13 | C17: 13 Agustus 2024 | D17: =E16 -> 32710 | E17: 386480 | F17: =E17-D17 -> 353770
... B35: 31 | C35: 31 Agustus 2024 | D35: =E34 -> 582820 | E35: 637920 | F35: =E35-D35 -> 55100

Sheet Detail Agustus OIP Akhir Plant
D2: PT. INDUSTRI NABATI LESTARI | L2: Nomor Dokumen | N2: Tanggal Berlaku
D3: PABRIK MINYAK GORENG | L3: INLHO/BOPP-PRD/F-021 | N3: 44866
D4: Kantor Pusat : Komp.KEK Sei Mangkei, Kav.2-3, Kec. Bosar Maligas, Kab. Simalungun, Sumatera Utara, 21184 | L4: Nomor Revisi | N4: Halaman
D5: BERITA ACARA DEPARTEMEN REFINERY & FRACTIONATION | L5: 00 | N5: 2
C6: Hal : Stock Opname Oil In Plant ( Refinery & Fractionation )
C7: Berikut kami lampirkan laporan Stok Opname Oil In Plant Per-tanggal 01 September 2024.
D8: 1. Refinery | J8: 2. Fractination
D9: No. | E9: Tag. | F9: Volume (Ton) | G9: % | H9: Quantity (Ton) | J9: No. | K9: Tag. | L9: Volume (Ton) | M9: % | N9: Quantity (Ton)
F10: By Lipico | L10: By Lipico
D11: 1 | E11: MX312 | F11: 0.81 | G11: 100 | H11: =G11*F11/100 -> 0.81 | J11: 1 | K11: CR 1201 | L11: 56 | M11: 98.1 | N11: =M11*L11/100 -> 54.936
D12: 2 | E12: VE611 | F12: 72.587 | G12: 80 | H12: =G12*F12/100 -> 58.0696 | J12: 2 | K12: CR 1202 | L12: 56 | M12: 97.6 | N12: =M12*L12/100 -> 54.656
D13: 3 | E13: VE612 | F13: 23.884 | G13: 59 | H13: =G13*F13/100 -> 14.09156 | J13: 3 | K13: CR 1203 | L13: 56 | M13: 98.4 | N13: =M13*L13/100 -> 55.104
D14: 4 | E14: FL621 | F14: 7.38 | G14: 100 | H14: =G14*F14/100 -> 7.38 | J14: 4 | K14: CR 1204 | L14: 56 | M14: 98.4 | N14: =M14*L14/100 -> 55.104
D15: 5 | E15: FL622 | F15: 7.38 | G15: 100 | H15: =G15*F15/100 -> 7.38 | J15: 5 | K15: CR 1205 | L15: 56 | M15: 98.4 | N15: =M15*L15/100 -> 55.104
D16: 6 | E16: FL623 | F16: 7.38 | G16: 100 | H16: =G16*F16/100 -> 7.38 | J16: 6 | K16: CR 1206 | L16: 56 | M16: 98.4 | N16: =M16*L16/100 -> 55.104
D17: 7 | E17: FL624 | F17: 7.38 | G17: 0 | H17: =G17*F17/100 -> 0 | J17: 7 | K17: CR 1207 | L17: 56 | M17: 15.5 | N17: =M17*L17/100 -> 8.68
D18: 8 | E18: FL625 | F18: 7.38 | G18: 0 | H18: =G18*F18/100 -> 0 | J18: 8 | K18: CR 1208 | L18: 56 | M18: 98.3 | N18: =M18*L18/100 -> 55.048 | AB18: 55.888
D19: 9 | E19: FL625A/B | F19: 0.369 | G19: 100 | H19: =G19*F19/100 -> 0.369 | J19: 9 | K19: CR 1209 | L19: 56 | M19: 98.3 | N19: =M19*L19/100 -> 55.048 | AB19: 55.888
D20: 10 | E20: FL626A/B | F20: 0.243 | G20: 100 | H20: =G20*F20/100 -> 0.243 | J20: 10 | K20: CR 1210 | L20: 56 | M20: 98.3 | N20: =M20*L20/100 -> 55.048 | AB20: 55.776
D21: 11 | E21: FL741A/B | F21: 0.306 | G21: 100 | H21: =G21*F21/100 -> 0.306 | J21: 11 | K21: CR 1211 | L21: 56 | M21: 98.3 | N21: =M21*L21/100 -> 55.048 | AB21: 55.776
D22: 12 | E22: VE661 | F22: 5.383 | G22: 30 | H22: =G22*F22/100 -> 1.6149 | J22: 12 | K22: CR 1212 | L22: 56 | M22: 98.3 | N22: =M22*L22/100 -> 55.048 | AB22: 55.776
D23: 13 | E23: TK641 | F23: 7.798 | G23: 0 | H23: =G23*F23/100 -> 0 | J23: 13 | K23: T-261 | L23: 14.59 | M23: 80 | N23: =M23*L23/100 -> 11.672 | AB23: 55.664
D24: 14 | E24: VE701 | F24: 51.513 | G24: 70 | H24: =G24*F24/100 -> 36.0591 | J24: 14 | K24: T-241 | L24: 14.39 | M24: 85.6 | N24: =M24*L24/100 -> 12.31784 | AB24: 55.664
D25: 15 | E25: HE721A | F25: 18.45 | G25: 35 | H25: =G25*F25/100 -> 6.4575 | J25: 15 | K25: T-221 | L25: 56 | M25: 0 | N25: =M25*L25/100 -> 0 | AB25: 0
D26: 16 | E26: HE721B | F26: 18.45 | G26: 100 | H26: =G26*F26/100 -> 18.45 | J26: 16 | K26: T-231 A | L26: 23.4 | M26: 0 | N26: =M26*L26/100 -> 0 | AB26: 0
D27: 17 | E27: HE722 | F27: 12.33 | G27: 80 | H27: =G27*F27/100 -> 9.864 | J27: 17 | K27: T-231 B | L27: 23.4 | M27: 0 | N27: =M27*L27/100 -> 0 | AB27: 55.38
D28: 18 | E28: PR731 | F28: 8.171 | G28: 35 | H28: =G28*F28/100 -> 2.85985 | J28: 18 | K28: T-251 A | L28: 2.25 | M28: 0 | N28: =M28*L28/100 -> 0 | AB28: 55.88
D29: 19 | E29: DE732 | F29: 110.7 | G29: 100 | H29: =G29*F29/100 -> 110.7 | J29: 19 | K29: T-251 B | L29: 2.25 | M29: 0 | N29: =M29*L29/100 -> 0 | AB29: 56
D30: 20 | E30: VE 771 | F30: 0.433 | G30: 50 | H30: =G30*F30/100 -> 0.2165 | J30: Total | N30: =SUM(N11:N29) -> 637.91784 | AB30: 7.36
D31: 21 | E31: VE751 | F31: 4.149 | G31: 30 | H31: =G31*F31/100 -> 1.2447 | J31: Dengan Rincian OIP Fract Sebagai berikut : | AB31: 11.44
D32: 22 | E32: VE753 | F32: 0.814 | G32: 0 | H32: =G32*F32/100 -> 0 | K32: RBDPO : | L32: =SUM(N11:N25)+N28+N29 -> 637.91784 | M32: Mt | AB32: 47.88
D33: Total | H33: =SUM(H11:H32) -> 283.49571 | J33: RBDPS : | L33: =N26+N27 -> 0 | M33: Mt | AB33: =SUM(AB18:AB32) -> 624.372
D34: Dengan Rincian OIP Refinery Sebagai berikut :
D35: CPO : | E35: =H12+H13 -> 72.16116 | F35: Mt
D36: RBDPO : | E36: =H33-E35 -> 211.33455 | F36: Mt
C38: Demikian saya sampaikan, Terimakasih.
D39: Dibuat Oleh : | G39: Diperiksa Oleh : | L39: Diketahui Oleh :
C43: Triana Bayu Pramoedito | G43: Sudarianto | L43: Gunawan E. Putra
D44: SPV IBL | G44: Manager Produksi | L44: Head Controller and Tax

Sheet Juli - 2024xx
B1: PRODUCTION REPORT
B2: No | C2: ITEM | D2: Budget / Norma | E2: UoM | F2: JulI | AL2: TOTAL (Kg)
F3: 1 | G3: 2 | H3: 3 | I3: 4 | J3: 5 | K3: 6 | L3: 7 | M3: 8 | N3: 9 | O3: 10 | P3: 11 | Q3: 12 | R3: 13 | S3: 14 | T3: 15 | U3: 16 | V3: 17 | W3: 18 | X3: 19 | Y3: 20 | Z3: 21 | AA3: 22 | AB3: 23 | AC3: 24 | AD3: 25 | AE3: 26 | AF3: 27 | AG3: 28 | AH3: 29 | AI3: 30 | AJ3: 31
B4: 1 | C4: PRODUCTION | AL4: Production
C5: Refinery | AL5: Refinery
C6: Running Days | E6: Day | F6: 1 | G6: 1 | H6: 1 | I6: 1 | J6: 1 | K6: 1 | L6: 1 | M6: 1 | N6: 1 | O6: 1 | P6: 1 | Q6: 1 | R6: 1 | S6: 1 | AL6: =SUM(F6:O6) -> 10
C7: Incoming CPO | E7: Kg | F7: ='[19]01 '!$P$14 -> 865877 | G7: ='[19]02'!$P$14 -> 1020502 | H7: ='[19]03'!$P$14 -> 623069 | I7: ='[19]04'!$P$14 -> 686156 | J7: ='[19]05'!$P$14 -> 500524 | K7: ='[19]06'!$P$14 -> 286477 | L7: ='[19]07'!$P$11 -> 40800 | M7: ='[19]08'!$P$13+168651 -> 335707 | N7: ='[19]09'!$P$13 -> 203264 | O7: ='[20]10'!$P$14-22440 -> 803740 | P7: ='[21]11'!$P$14 -> 474327 | Q7: ='[22]12'!$P$13+156887 -> 486876 | R7: =186434+'[22]13'!$P$13 -> 412792 | S7: 0 | AL7: =SUM(F7:AI7) -> 6740111 | AM7: =AVERAGE(G7:O7) -> 500026.56 | AO7: =AL7/14 -> 481436.5
C8: Ratio Run CPO | E8: % | F8: =F9/2200000*100 -> 33.860182 | G8: =G9/2200000*100 -> 33.816909 | H8: =H9/2200000*100 -> 47.656136 | I8: =I9/2200000*100 -> 50.673682 | J8: =J9/2200000*100 -> 11.278455 | K8: =K9/2200000*100 -> 17.6585 | L8: =L9/2200000*100 -> 2.6320909 | M8: =M9/2200000*100 -> 11.742864 | ... AJ8: =AJ9/2200000*100 -> 0 | AL8: =AVERAGE(F8:S8) -> 23.675701
C9: CPO Consume Total | D9: 36359000 | E9: Kg | F9: ='[19]01 '!$Q$14 -> 744924 | G9: ='[19]02'!$Q$14 -> 743972 | H9: ='[19]03'!$Q$14 -> 1048435 | I9: ='[19]04'!$Q$14 -> 1114821 | J9: ='[19]05'!$Q$14 -> 248126 | K9: ='[19]06'!$Q$14 -> 388487 | L9: ='[19]07'!$Q$14 -> 57906 | M9: ='[19]08'!$Q$13 -> 258343 | N9: ='[19]09'!$Q$11 -> 154743 | O9: 512647 | P9: ='OIP Fract'!D15+'[21]11'!$Q$11-'OIP Fract'!E15 -> 441064 | Q9: ='OIP Fract'!D16+'[22]12'!$Q$13+'[22]12'!$Q$11-'OIP Fract'!E16 -> 493693 | R9: ='[22]13'!$Q$13 -> 568358 | S9: ='OIP Fract'!D18+'[22]14'!$Q$13+'[22]14'!$Q$11-'OIP Fract'!E18 -> 516597 | T9: 0 | AL9: =SUM(F9:AI9) -> 7292116 | AM9: =AL9/D9*100 -> 20.055876 | AN9: =AL9/10 -> 729211.6
C10: CPO Consume Poram | D10: 29045000 | E10: Kg | F10: =F9-F27-F36 -> 744924 | G10: =G9-G27-G36 -> 743972 | H10: =H9-H27-H36 -> 1048435 | I10: =I9-I27-I36 -> 1114821 | J10: =J9-J27-J36 -> 248126 | K10: =K9-K27-K36 -> 388487 | L10: =L9-L27-L36 -> 57906 | M10: =M9-M27-M36 -> 258343 | ... AJ10: =AJ9-AJ27-AJ36 -> 0 | AL10: =SUM(F10:AI10) -> 7292116
C11: CPO Consume Brand | D11: 7314000 | E11: Kg | F11: =F27+F36 -> 0 | G11: =G27+G36 -> 0 | H11: =H27+H36 -> 0 | I11: =I27+I36 -> 0 | J11: =J27+J36 -> 0 | K11: =K27+K36 -> 0 | L11: =L27+L36 -> 0 | M11: =M27+M36 -> 0 | ... AJ11: =AJ27+AJ36 -> 0 | AL11: =SUM(F11:AI11) -> 0
C12: - FFA | D12: 5 | E12: % | F12: 4.03 | G12: 4.14 | H12: 4.06 | I12: =(4.12+4.17+3.97)/3 -> 4.0866667 | J12: 4.18 | K12: =4.14 -> 4.14 | L12: 4.2 | M12: 4.08 | N12: 4.16 | O12: 4.18 | P12: 4.2 | Q12: 4.22 | R12: 3.96 | S12: =(4.29+4.09)/2 -> 4.19 | AL12: =AVERAGE(F12:AI12) -> 4.1304762
C13: - Moist & Impurities | D13: 0.5 | E13: % | F13: 0.44 | G13: 0.46 | H13: 0.455 | I13: =(0.43+0.44+0.48)/3 -> 0.45 | J13: 0.49 | K13: =(0.44+0.49)/2 -> 0.465 | L13: 0.4 | M13: 0.48 | N13: 0.4 | O13: 0.41 | P13: 0.47 | Q13: 0.4 | R13: 0.49 | S13: =(0.4+0.49)/2 -> 0.445 | AL13: =AVERAGE(F13:AI13) -> 0.44678571
C14: - DOBI | D14: 2,20 Min | E14: % | F14: 2.21 | G14: 2.21 | H14: 2.22 | I14: 2.21 | J14: 2.21 | K14: 2.21 | L14: 2.21 | M14: 2.22 | N14: 2.21 | O14: 2.22 | P14: 2.21 | Q14: 2.21 | R14: 2.22 | S14: 2.22 | AL14: =AVERAGE(F14:AI14) -> 2.2135714
C15: Product | AL15: Product
C16: RbdPO | D16: 34458000 | E16: Kg | F16: ='[19]01 '!$P$15 -> 667300 | G16: ='[19]02'!$P$15 -> 695000 | H16: ='[19]03'!$P$15 -> 814100 | I16: ='[19]04'!$P$15 -> 760000 | J16: 0 | K16: ='[19]06'!$P$15 -> 587100 | L16: ='[19]07'!$P$15 -> 92106 | M16: ='[19]08'!$P$16+'[19]08'!$P$15 -> 105220 | N16: ='[19]09'!$P$15+'[19]09'!$P$16 -> 70837 | O16: ='[20]10'!$P$17 -> 488153 | P16: ='[21]11'!$P$17 -> 379337 | Q16: ='[22]12'!$P$17 -> 492952 | R16: ='[22]13'!$P$17 -> 532902 | S16: ='[22]14'!$P$16 -> 497845 | T16: 91674 | AL16: =SUM(F16:AI16) -> 6274526
C17: PFAD | D17: 1636000 | E17: Kg | F17: ='[19]01 '!$P$24 -> 25659 | G17: ='[19]02'!$P$24 -> 18786 | H17: ='[19]03'!$P$24 -> 46938 | I17: ='[19]04'!$P$24 -> 48667 | K17: ='[19]06'!$P$24 -> 32281 | L17: ='[19]07'!$P$24 -> 0 | M17: ='[19]08'!$P$24 -> 26283 | N17: ='[19]09'!$P$23+'[19]09'!$P$24 -> 6431 | O17: ='[20]10'!$P$23 -> 20426 | P17: ='[21]11'!$P$23 -> 23275 | Q17: ='[22]12'!$P$25 -> 27655 | R17: ='[22]13'!$P$25 -> 25803 | S17: ='[22]13'!$P$25 -> 25803 | T17: 6643 | AL17: =SUM(F17:AI17) -> 334650
C18: Fractionation OLEIN IV 56 | AL18: Olein IV 56
C19: RBDPO Consume | E19: Kg | F19: =F20+F21 -> 0 | G19: =G20+G21 -> 0 | H19: =H20+H21 -> 0 | I19: =I20+I21 -> 0 | J19: =J20+J21 -> 0 | K19: =K20+K21 -> 0 | L19: =L20+L21 -> 0 | M19: =M20+M21 -> 0 | ... AJ19: =AJ20+AJ21 -> 0 | AL19: =SUM(F19:AI19) -> 0
C20: OLEIN IV 56 | E20: Kg | F20: 0 | G20: 0 | H20: 0 | AL20: =SUM(F20:AI20) -> 0
C21: STEARIN | E21: Kg | F21: 0 | G21: 0 | H21: 0 | AL21: =SUM(F21:AI21) -> 0
C22: Fractionation OLEIN IV 57 ( Bulk ) | AL22: Olein IV 57 ( Bulk )
C23: RBDPO Consume | E23: Kg | F23: =F24+F25 -> 0 | G23: =G24+G25 -> 0 | H23: =H24+H25 -> 0 | I23: =I24+I25 -> 0 | J23: =J24+J25 -> 0 | K23: =K24+K25 -> 0 | L23: =L24+L25 -> 0 | M23: =M24+M25 -> 0 | ... AJ23: =AJ24+AJ25 -> 0 | AL23: =SUM(F23:O23) -> 0
C24: OLEIN IV 57 | E24: Kg | F24: 0 | G24: 0 | H24: 0 | AL24: =SUM(F24:O24) -> 0
C25: STEARIN | E25: Kg | F25: 0 | G25: 0 | H25: 0 | AL25: =SUM(F25:O25) -> 0
C26: Fractionation OLEIN IV 57 ( Retail ) | AL26: Olein IV 57 ( Retail )
C27: CPO Consume | E27: Kg | AL27: =SUM(F27:O27) -> 0
C28: RBDPO Brand Consume | E28: Kg | F28: =F29+F30 -> 0 | G28: =G29+G30 -> 0 | H28: =H29+H30 -> 0 | I28: =I29+I30 -> 0 | J28: =J29+J30 -> 0 | K28: =K29+K30 -> 0 | L28: =L29+L30 -> 0 | M28: =M29+M30 -> 0 | ... AJ28: =AJ29+AJ30 -> 0 | AL28: =SUM(F28:O28) -> 0
C29: OLEIN IV 57 Low Color | E29: Kg | F29: 0 | G29: 0 | H29: 0 | AL29: =SUM(F29:O29) -> 0
C30: STEARIN | E30: Kg | F30: 0 | G30: 0 | H30: 0 | AL30: =SUM(F30:O30) -> 0
C31: Fractionation OLEIN IV 58 ( Bulk ) | AL31: Olein IV 58 ( Bulk )
C32: RBDPO Consume | D32: =D33+D34 -> 21429000 | E32: Kg | F32: =F33+F34 -> 636794 | G32: =G33+G34 -> 705632 | H32: =H33+H34 -> 727663 | I32: =I33+I34 -> 1053776 | J32: =J33+J34 -> 585552 | K32: =K33+K34 -> 632355 | L32: =L33+L34 -> 315146 | M32: =M33+M34 -> 0 | ... AJ32: =AJ33+AJ34 -> 0 | AL32: =SUM(F32:AI32) -> 7315959
C33: OLEIN IV 58 | D33: 15000000 | E33: Kg | F33: ='[19]01 '!$P$21 -> 437978 | G33: ='[19]02'!$P$21 -> 502403 | H33: ='[19]03'!$P$21 -> 540182 | I33: ='[19]04'!$P$21 -> 762960 | J33: ='[19]05'!$P$21 -> 360256 | K33: ='[19]06'!$P$21 -> 449507 | L33: ='[19]07'!$P$21 -> 208841 | M33: 0 | N33: ='[19]09'!$P$21 -> 295995 | O33: 0 | P33: ='[21]11'!$P$21 -> 478550 | Q33: ='[22]12'!$P$21 -> 209348 | R33: ='[22]13'!$P$21 -> 245921 | S33: ='[22]14'!$P$21 -> 428023 | T33: ='[23]15'!$P$21 -> 212137 | AL33: =SUM(F33:AI33) -> 5132101
C34: STEARIN | D34: 6429000 | E34: Kg | F34: ='[19]01 '!$P$29 -> 198816 | G34: ='[19]02'!$P$29 -> 203229 | H34: ='[19]03'!$P$28 -> 187481 | I34: ='[19]04'!$P$30 -> 290816 | J34: ='[19]05'!$P$28 -> 225296 | K34: ='[19]06'!$P$28 -> 182848 | L34: ='[19]07'!$P$28 -> 106305 | M34: 0 | N34: ='[19]09'!$P$28 -> 96081 | O34: 0 | P34: ='[21]11'!$P$28 -> 169774 | Q34: ='[22]12'!$P$28 -> 111127 | R34: ='[22]13'!$P$30 -> 83059 | S34: ='[22]14'!$P$30 -> 191480 | T34: ='[23]15'!$P$29 -> 137546 | AL34: =SUM(F34:AI34) -> 2183858
C35: Fractionation OLEIN IV 60 | AL35: Olein IV 60
C36: CPO Consume | E36: Kg | AL36: =SUM(F36:O36) -> 0
C37: RBDPO Brand Consume | E37: Kg | F37: =F39+F40 -> 0 | G37: =G39+G40 -> 0 | H37: =H39+H40 -> 0 | I37: =I39+I40 -> 0 | J37: =J39+J40 -> 0 | K37: =K39+K40 -> 0 | L37: =L39+L40 -> 0 | M37: =M39+M40 -> 0 | ... AJ37: =AJ39+AJ40 -> 0 | AL37: =SUM(F37:O37) -> 0
C38: OLEIN IV 60 Bulk | E38: Kg | F38: 0 | G38: 0 | H38: 0 | AL38: =SUM(F38:O38) -> 0
C39: OLEIN IV 60 Salvaco | E39: Kg | F39: 0 | G39: 0 | H39: 0 | AL39: =SUM(F39:O39) -> 0
C40: SOFT STEARIN | E40: Kg | F40: 0 | G40: 0 | H40: 0 | AL40: =SUM(F40:O40) -> 0
...

Sheet 2024
C2: PRODUCTION REPORT 2024
B4: No | C4: ITEM | D4: Budget / Norma | E4: UoM | F4: MONTHLY REPORT | S4: Yearly Report | T4: Yearly Report RKAP (Budget) | U4: Yearly Report RKAP
F5: JANUARI | G5: FEBRUARI | H5: MARET | I5: APRIL | J5: MEI | K5: JUNI | L5: JULI | M5: AGUSTUS | N5: SEPTEMBER | O5: OKTOBER | P5: NOVEMBER | Q5: DESEMBER | S5: TOTAL (Kg) | T5: TOTAL (Kg) | U5: TOTAL (%)
B6: 1 | C6: PRODUCTION | S6: Production | T6: Production | U6: Production | DG6: 29 | DH6: 30 | DI6: 31
C7: Refinery | S7: Refinery | T7: Refinery | U7: Refinery | DE7: CPO Olah | DF7: Kg | DG7: 1971320 | DH7: 2015120 | DI7: 2015230 | AIU7: Sounding | AIV7: Production | AIW7: Diff
C8: Running Days | E8: Day | F8: ='[24]Januari 24'!AL9 -> 18 | G8: ='[24]Februari 24'!AL9 -> 11 | H8: ='[24]Maret 24'!AL9 -> 5 | I8: ='[25]April - 24'!$AK$9 -> 0 | J8: ='[26]Mei - 24'!$AL$9 -> 0 | K8: ='[27]Juni - 24'!$AL$9 -> 18 | L8: ='[28]Juli - 2024 ( Revisi )'!$AL$6 -> 22 | M8: ='Agustus - 2024'!AN6 -> 28 | N8: ='[24]September 24'!AL9 -> 0 | O8: ='[24]Oktober 24'!AL9 -> 0 | P8: ='[24]November 24'!AL9 -> 0 | Q8: ='[24]Desember 24'!AL9 -> 0 | S8: =SUM(F8:Q8) -> 102 | T8: 231 | U8: =S8/T8*100 -> 44.155844 | OR8: Poram | AEE8: 14 Juni | AEF8: 15 Juni | AIT8: CPO | AIU8: 11008948 | AIV8: =S11 -> 74746909 | AIW8: =AIU8-AIV8 -> -63737961
C9: Ratio Run CPO | F9: ='[24]Januari 24'!AL10 -> 17.457609 | G9: ='[24]Februari 24'!AL10 -> 17.224767 | H9: ='[24]Maret 24'!AL10 -> 4.5497713 | I9: ='[25]April - 24'!$AK$11 -> 0 | J9: ='[26]Mei - 24'!$AL$11 -> 0 | K9: ='[27]Juni - 24'!$AL$11 -> 13.078035 | L9: ='[28]Juli - 2024 ( Revisi )'!$AL$8 -> 23.454544 | M9: ='Agustus - 2024'!AN8 -> 33.834848 | N9: ='[24]September 24'!AL10 -> 0 | O9: ='[24]Oktober 24'!AL10 -> 0 | P9: ='[24]November 24'!AL10 -> 0 | Q9: ='[24]Desember 24'!AL10 -> 0
C10: Utilitas CPO | F10: =F11/F14*100 -> 18.288923 | G10: =G11/G14*100 -> 25.986707 | H10: =H11/H14*100 -> 7.9383545 | I10: =I11/I14*100 -> #VALUE! | J10: =J11/J14*100 -> 0 | K10: =K11/K14*100 -> 24.530983 | L10: =L11/L14*100 -> 43.994607 | M10: =M11/M14*100 -> 63.465348 | ... Q10: =Q11/Q14*100 -> 0 | S10: =AVERAGE(F10:O10) -> #VALUE!
C11: CPO Consume Total | D11: 701400000 | E11: Kg | F11: ='[24]Januari 24'!AL11 -> 11906089 | G11: ='[24]Februari 24'!AL11 -> 11747291 | H11: ='[24]Maret 24'!AL11 -> 3102944 | I11: ='[25]April - 24'!$AK$12 -> 0 | J11: ='[26]Mei - 24'!$AL$12 -> 0 | K11: ='[27]Juni - 24'!$AL$12 -> 8919220 | L11: ='[28]Juli - 2024 ( Revisi )'!$AL$9 -> 15995999 | M11: ='Agustus - 2024'!AN9 -> 23075366 | N11: ='[24]September 24'!AL11 -> 0 | O11: ='[24]Oktober 24'!AL11 -> 0 | P11: ='[24]November 24'!AL11 -> 0 | Q11: ='[24]Desember 24'!AL11 -> 0 | S11: =SUM(F11:Q11) -> 74746909 | T11: 421374000 | U11: =S11/T11 -> 0.17738852 | AX11: =S11/D11 -> 0.10656816 | DE11: HP Boiler | DF11: mmbtu | DG11: 251.19642 | DH11: 257.91391 | DI11: 251.51265 | OO11: 26946.108 | OP11: 17383.234 | OR11: RBDPO Olah | AEE11: =35.8500000000058*1000 -> 35850 | AIT11: PFAD | AIU11: 566885 | AIV11: =S20 -> 3394842 | AIW11: =AIU11-AIV11 -> -2827957
C12: CPO Consume Poram | E12: Kg | F12: ='[24]Januari 24'!AL12 -> 10284033 | G12: ='[24]Februari 24'!AL12 -> 10885811 | H12: ='[24]Maret 24'!AL12 -> 2891954.7 | I12: ='[25]April - 24'!$AK$13 -> 0 | J12: ='[26]Mei - 24'!$AL$13 -> 0 | K12: ='[27]Juni - 24'!$AL$13 -> 8919220 | L12: ='[28]Juli - 2024 ( Revisi )'!$AL$10 -> 15995999 | M12: ='Agustus - 2024'!AN10 -> 22890671 | N12: 0 | O12: 0 | P12: ='[24]November 24'!AL12 -> #DIV/0! | Q12: ='[24]Desember 24'!AL12 -> #DIV/0! | S12: =SUM(F12:O12) -> 71867688
C13: CPO Consume Brand | E13: Kg | F13: ='[24]Januari 24'!AL13 -> 1622056.5 | G13: ='[24]Februari 24'!AL13 -> 861480.39 | H13: ='[24]Maret 24'!AL13 -> 210989.34 | I13: 0 | J13: 0 | K13: 0 | L13: ='[28]Juli - 2024 ( Revisi )'!$AL$11 -> 0 | M13: ='Agustus - 2024'!AN11 -> 184695 | N13: 0 | O13: 0 | P13: ='[24]November 24'!AL13 -> #DIV/0! | Q13: ='[24]Desember 24'!AL13 -> #DIV/0! | S13: =SUM(F13:O13) -> 2879221.2 | AX13: =AW13/P13 -> #DIV/0!
C14: Budget CPO Olah | E14: Kg | F14: 65100000 | G14: 45205000 | H14: 39088000 | I14: ='[25]April - 24'!$C$12 -> CPO Consume Total | J14: ='[26]Mei - 24'!$D$12 -> 36359000 | K14: ='[27]Juni - 24'!$D$12 -> 36359000 | L14: ='[29]Juli - 2024'!$D$9 -> 36359000 | M14: ='[29]Juli - 2024'!$D$9 -> 36359000 | N14: ='[29]Juli - 2024'!$D$9 -> 36359000 | O14: ='[29]Juli - 2024'!$D$9 -> 36359000 | P14: ='[29]Juli - 2024'!$D$9 -> 36359000 | Q14: ='[29]Juli - 2024'!$D$9 -> 36359000 | S14: =SUM(F14:Q14) -> 440265000
C15: - FFA | D15: 5 | E15: % | F15: 4.38 | G15: 4.56 | H15: 4.19 | I15: 4.11 | J15: 3.86 | K15: 4.25 | L15: ='[28]Juli - 2024 ( Revisi )'!$AL$12 -> 3.8848485 | M15: ='Agustus - 2024'!AN12 -> 3.9614881 | N15: 0 | O15: 0 | P15: ='[24]November 24'!AL14 -> #DIV/0! | Q15: ='[24]Desember 24'!AL14 -> #DIV/0! | S15: =AVERAGE(F15:O15) -> 3.3196337 | T15: =AVERAGE(G15:R15) -> #DIV/0! | U15: =AVERAGE(H15:S15) -> #DIV/0! | DE15: Steam Ref | DF15: Kg | DG15: 182230 | DH15: 190070 | DI15: 197800 | OO15: =S11/1000 -> 74746.909 | OP15: =(S25+S43+S34)/1000 -> 18951.156 | OR15: =SUM(OR16:OR17) -> #REF! | AGV15: 2000
