Workbook

Sheet September - 2024
P1: PRODUCTION REPORT
C2: No | D2: ITEM | E2: Budget / Norma | F2: UoM | G2: September | AM2: TOTAL MONTHLY (Kg)
G3: 1 | H3: 2 | I3: 3 | J3: 4 | K3: 5 | L3: 6 | M3: 7 | N3: 8 | O3: 9 | P3: 10 | Q3: 11 | R3: 12 | S3: 13 | T3: 14 | U3: 15 | V3: 16 | W3: 17 | X3: 18 | Y3: 19 | Z3: 20 | AA3: 21 | AB3: 22 | AC3: 23 | AD3: 24 | AE3: 25 | AF3: 26 | AG3: 27 | AH3: 28 | AI3: 29 | AJ3: 30 | AK3: 31
C4: 1 | D4: PRODUCTION | AM4: Production
D5: Refinery | AM5: Refinery
D6: Running Days | F6: Day | G6: 1 | H6: 1 | I6: 1 | J6: 1 | K6: 1 | L6: 1 | M6: 1 | N6: 1 | O6: 1 | P6: 1 | Q6: 1 | R6: 1 | S6: 1 | T6: 1 | U6: 1 | V6: 0 | W6: 1 | X6: 1 | Y6: 1 | Z6: 1 | AA6: 1 | AB6: 1 | AC6: 0 | AD6: 0 | AE6: 1 | AF6: 1 | AG6: 1 | AH6: 1 | AI6: 1 | AJ6: 1 | AM6: =SUM(G6:AK6) -> 27
D7: Incoming CPO | F7: Kg | G7: ='[1]01'!$P$15 -> 0 | H7: ='[2]02'!$P$15 -> 1091462 | I7: ='[3]03'!$P$15 -> 775948 | J7: ='[4]04'!$P$15 -> 411548 | K7: ='[5]05'!$P$15 -> 662586 | L7: ='[6]06'!$P$15 -> 581111 | M7: ='[7]07'!$P$15 -> 1040334 | N7: ='[7]08'!$P$15 -> 0 | O7: ='[6]09'!$P$15 -> 1393093 | P7: ='[3]10'!$P$15 -> 1072925 | Q7: ='[5]11'!$P$15 -> 820575 | R7: ='[6]12'!$P$15 -> 544250 | S7: ='[8]13'!$P$15 -> 646901 | T7: ='[9]14'!$P$15 -> 1738216 | U7: ='[9]15'!$P$15 -> 511082 | V7: 0 | W7: ='[10]17'!$P$15 -> 885719 | X7: ='[7]18'!$P$15 -> 1402234 | Y7: ='[11]19'!$P$15-3000 -> 901325 | Z7: ='[12]20'!$P$15 -> 870362 | AA7: ='[13]21'!$P$15 -> 1413850 | AB7: ='[13]22'!$P$15 -> 577458 | AC7: ='[13]23'!$P$15-9880 -> 727575 | AD7: ='[14]24'!$P$15 -> 733336 | AE7: ='[15]25'!$P$15 -> 786729 | AF7: ='[16]26'!$P$15 -> 792985 | AG7: =956721+110099+463387 -> 1530207 | AH7: ='[17]28'!$P$15 -> 1209719 | AI7: ='[18]29'!$P$15 -> 914652 | AJ7: ='[14]30 (Stock Opname)'!$P$15 -> 950954 | AM7: =SUM(G7:AK7) -> 24987136 | AN7: =AVERAGE(H7:AA7) -> 838176.05
D8: Ratio Run CPO | F8: % | G8: =G9/2200000*100 -> 14.784727 | H8: =H9/2200000*100 -> 11.107818 | I8: =I9/2200000*100 -> 51.390636 | J8: =J9/2200000*100 -> 31.202818 | K8: =K9/2200000*100 -> 27.664455 | L8: =L9/2200000*100 -> 30.109727 | M8: =M9/2200000*100 -> 27.837318 | N8: =N9/2200000*100 -> 17.565727 | ... AK8: =AK9/2200000*100 -> 0 | AM8: =SUM(G8:AJ8)/AM6 -> 40.48197 | AW8: =AM9/30 -> 801543
D9: CPO Consume Total | E9: 36359000 | F9: Kg | G9: ='[1]01'!$Q$15 -> 325264 | H9: ='[2]02'!$Q$15 -> 244372 | I9: ='[3]03'!$Q$15 -> 1130594 | J9: ='[4]04'!$Q$15 -> 686462 | K9: ='[5]05'!$Q$15 -> 608618 | L9: ='[6]06'!$Q$15 -> 662414 | M9: ='[7]07'!$Q$15 -> 612421 | N9: ='[7]08'!$Q$15 -> 386446 | O9: ='[6]09'!$Q$15 -> 1041561 | P9: ='[3]10'!$Q$12+'[3]10'!$Q$14 -> 1056809 | Q9: ='[5]11'!$Q$15 -> 1067764 | R9: ='[6]12'!$Q$15 -> 701797 | S9: ='[8]13'!$Q$15 -> 563620 | T9: 605861 | U9: 1587899 | W9: ='[10]17'!$Q$15 -> 430122 | X9: ='[7]18'!$Q$15 -> 1154162 | Y9: ='[11]19'!$Q$15 -> 1380669 | Z9: ='[12]20'!$Q$15 -> 938737 | AA9: ='[13]21'!$Q$15 -> 875019 | AB9: ='[13]22 Rev'!$Q$15 -> 41122 | AC9: 0 | AD9: 0 | AE9: ='[15]25'!$Q$15 -> 879838 | AF9: 1623131 | AG9: 1648997 | AH9: 1718627 | AI9: 1528732 | AJ9: ='[14]30 (Stock Opname)'!$Q$10 -> 545232 | AM9: =SUM(G9:AK9) -> 24046290 | AN9: =AM9/E9 -> 0.6613573 | AO9: =AM9/AM6 -> 890603.33 | AP9: =AO9/E9 -> 0.024494715 | AR9: =AM9/E9 -> 0.6613573 | AS9: =AM9/E9 -> 0.6613573
D10: Avg Daily Consump CPO ( MTD ) | AM10: =AM9/AM6 -> 890603.33 | AW10: =AM7/30 -> 832904.53
D11: CPO Consume Poram | E11: 29045000 | F11: Kg | G11: =G9-G36-G45 -> 325264 | H11: =H9-H36-H45 -> 244372 | I11: =I9-I36-I45 -> 1130594 | J11: =J9-J36-J45 -> 686462 | K11: =K9-K36-K45 -> 608618 | L11: =L9-L36-L45 -> 662414 | M11: =M9-M36-M45 -> 612421 | N11: =N9-N36-N45 -> 386446 | ... AK11: =AK9-AK36-AK45 -> 0 | AM11: =SUM(G11:AK11) -> 24046290
D12: CPO Consume Brand | E12: 7314000 | F12: Kg | G12: =G36+G45 -> 0 | H12: =H36+H45 -> 0 | I12: =I36+I45 -> 0 | J12: =J36+J45 -> 0 | K12: =K36+K45 -> 0 | L12: =L36+L45 -> 0 | M12: =M36+M45 -> 0 | N12: =N36+N45 -> 0 | ... AK12: =AK36+AK45 -> 0 | AM12: =SUM(G12:AK12) -> 0
D13: - FFA | E13: 5 | F13: % | G13: 4.16 | H13: =3.99 -> 3.99 | I13: 3.58 | J13: =(3.6+3.65+3.95)/3 -> 3.7333333 | K13: =(4.17+3.99)/2 -> 4.08 | L13: =(3.55+3.59)/2 -> 3.57 | M13: =(3.99) -> 3.99 | N13: 3.6 | O13: =(3.83+3.78)/2 -> 3.805 | P13: =(3.61+3.43)/2 -> 3.52 | Q13: =(3.62+3.69)/2 -> 3.655 | R13: 3.77 | S13: =(3.83+3.55)/2 -> 3.69 | T13: 3.85 | U13: 3.74 | V13: 0 | W13: 3.64 | X13: =(3.56+3.58)/2 -> 3.57 | Y13: 3.71 | Z13: =(3.98+3.78)/2 -> 3.88 | AA13: 3.85 | AB13: 0 | AC13: 0 | AD13: 0 | AE13: 3.95 | AF13: =(4.15+3.76)/2 -> 3.955 | AG13: =(3.41+3.74)/2 -> 3.575 | AH13: =(3.74+3.77)/2 -> 3.755 | AI13: =(4.02+3.77)/2 -> 3.895 | AJ13: 3.88 | AM13: =SUM(G13:AJ13)/AM6 -> 3.6441975
D14: - Moist & Impurities | E14: 0.5 | F14: % | G14: 0.48 | H14: 0.48 | I14: 0.4 | J14: =(0.38+0.35+0.48)/3 -> 0.40333333 | K14: =(0.4+0.49)/2 -> 0.445 | L14: =(0.44+0.47)/2 -> 0.455 | M14: 0.41 | N14: 0.47 | O14: =(0.42+0.49)/2 -> 0.455 | P14: =(0.4+0.42)/2 -> 0.41 | Q14: =(0.42+0.38)/2 -> 0.4 | R14: 0.4 | S14: 0.44 | T14: 0.46 | U14: 0.44 | V14: 0 | W14: 0.4 | X14: =(0.38+0.46)/2 -> 0.42 | Y14: 0.38 | Z14: 0.39 | AA14: =(0.42+0.45)/2 -> 0.435 | AB14: 0 | AC14: 0 | AD14: 0 | AE14: 0.41 | AF14: 0.42 | AG14: 0.46 | AH14: =(0.41+0.47)/2 -> 0.44 | AI14: =(0.43+0.48)/2 -> 0.455 | AJ14: 0.42 | AM14: =SUM(G14:AJ14)/AM6 -> 0.41401235
D15: - DOBI | E15: 2,20 Min | F15: % | G15: 22.18 | H15: 22.18 | I15: 22.18 | J15: 22.15 | K15: 22.17 | L15: 22.16 | M15: 22.18 | N15: 22.18 | O15: 22.1 | P15: 22.1 | Q15: 22.18 | R15: 22.1 | S15: 22 | T15: 22.02 | U15: 22.02 | V15: 0 | W15: 22.08 | X15: 22.02 | Y15: 22.02 | Z15: 22.01 | AA15: 22.02 | AB15: 0 | AC15: 0 | AD15: 0 | AE15: 22.02 | AF15: 22.02 | AG15: 22.02 | AH15: 22.02 | AI15: 22.01 | AJ15: 22.02 | AM15: =SUM(G15:AK15)/AM6 -> 21.265185
D16: Product | AM16: Product
D17: OIP RBDPO | G17: -25058 | H17: 5184 | I17: 12794 | J17: -15208 | K17: -2710 | L17: 4240 | M17: 3950 | N17: 8077 | O17: -16405 | P17: 2258 | Q17: 3187 | R17: 2456 | S17: ='OIP Refinery'!G17 -> 20802 | T17: -9534 | U17: -592 | V17: 0 | W17: 13769 | X17: -2231 | Y17: -24516 | Z17: -2682 | AA17: -8332 | AB17: -5229 | AC17: -4192 | AD17: 4232 | AE17: 21733 | AF17: -6956 | AG17: -12010 | AH17: 12177 | AI17: -7816 | AJ17: 3740
D18: RBDPO | E18: 34458000 | F18: Kg | G18: ='[1]01'!$P$18+G17 -> 288137 | H18: ='[2]02'!$P$18+H17 -> 229820 | I18: ='[6]03'!$P$18+I17 -> 1094261 | J18: ='[4]04'!$P$18+J17 -> 651579 | K18: ='[5]05'!$P$18+K22+K17 -> 582876 | L18: ='[6]06'!$P$18+L17 -> 619308 | M18: ='[7]07'!$P$18+M22+M17 -> 583790 | N18: ='[7]08'!$P$18+N17 -> 364733 | O18: ='[2]09'!$P$18+O17 -> 962440 | P18: ='[3]10'!$P$18+P17 -> 1024438 | Q18: ='[5]11'!$P$18+Q17 -> 1038100 | R18: ='[6]12'!$P$18+R17 -> 657990 | S18: ='[8]13'!$P$18+S17 -> 532167 | T18: =580282+T17 -> 570748 | U18: =1519300+U17 -> 1518708 | V18: 0 | W18: ='[10]17'!$P$18+W17 -> 416007 | X18: ='[7]18'!$P$18+X17 -> 1100547 | Y18: ='[11]19'!$P$18+Y17 -> 1309668 | Z18: ='[12]20'!$P$18+Z17 -> 896963 | AA18: ='[13]21'!$P$18+AA17 -> 818274 | AB18: ='[13]22'!$P$18+AB17 -> 29377 | AC18: 0 | AD18: 0 | AE18: ='[15]25'!$P$18+AE22+AE17 -> 818213 | AF18: =1548139+AF17 -> 1541183 | AG18: =1587278+AG17 -> 1575268 | AH18: =1612436+AH17 -> 1624613 | AI18: =1301424+AI22+AI17 -> 1411508 | AJ18: ='[14]30 (Stock Opname)'!$P$18+AJ17 -> 522775 | AM18: =SUM(G18:AK18) -> 22783491 | AR18: =AM18/E18 -> 0.66119598 | AS18: =SUM(Q18:Z18) -> 8040898
D19: PFAD | E19: 1636000 | F19: Kg | G19: ='[1]01'!$P$26 -> 17895 | H19: ='[2]02'!$P$26 -> 9543 | I19: 47327 | J19: ='[4]04'!$P$26 -> 27444 | K19: ='[5]05'!$P$26 -> 24771 | L19: ='[6]06'!$P$26 -> 25126 | M19: ='[7]07'!$P$26 -> 25986 | N19: ='[7]08'!$P$26 -> 16762 | O19: ='[2]09'!$P$26 -> 39994 | P19: ='[3]10'!$P$26 -> 42272 | Q19: ='[5]11'!$P$26 -> 45133 | R19: ='[6]12'!$P$26 -> 37189 | S19: ='[8]13'!$P$26 -> 16219 | T19: 26322 | U19: 71848 | V19: =3083 -> 3083 | W19: ='[10]17'!$P$26 -> 11052 | X19: ='[7]18'!$P$26 -> 45065 | Y19: ='[11]19'!$P$26 -> 58214 | Z19: ='[12]20'!$P$26 -> 40299 | AA19: ='[13]21'!$P$26 -> 38288 | AB19: ='[13]22'!$P$26 -> 1071 | AC19: 0 | AD19: 0 | AE19: ='[15]25'!$P$26 -> 56619 | AF19: 70755 | AG19: 49063 | AH19: 69396 | AI19: 56417 | AJ19: ='[14]30 (Stock Opname)'!$P$26 -> 25365 | AM19: =SUM(G19:AK19) -> 998518
D20: Fractionation
D21: Running Days | F21: Day | G21: 1 | H21: 1 | I21: 1 | J21: 1 | K21: 1 | L21: 1 | M21: 1 | N21: 1 | O21: 1 | P21: 1 | Q21: 1 | R21: 1 | S21: 1 | T21: 1 | U21: 1 | V21: 1 | W21: 0 | X21: 1 | Y21: 1 | Z21: 1 | AA21: 1 | AB21: 1 | AC21: 0 | AD21: 0 | AE21: 1 | AF21: 1 | AG21: 1 | AH21: 1 | AI21: 1 | AJ21: 1 | AM21: =SUM(G21:AK21) -> 27
D22: Filling Langsung CR Fr Refinery | F22: Kg | G22: 0 | H22: 0 | I22: 0 | J22: 0 | K22: 119600 | L22: 0 | M22: 126600 | N22: 0 | O22: 0 | P22: 0 | Q22: 0 | R22: 0 | S22: 0 | T22: 0 | U22: 0 | V22: 0 | W22: 0 | X22: 0 | Y22: 0 | Z22: 0 | AA22: 0 | AB22: 0 | AC22: 0 | AD22: 0 | AE22: =60800 -> 60800 | AF22: 0 | AG22: 0 | AH22: 0 | AI22: 117900 | AJ22: 0 | AK22: 0 | AM22: =SUM(G22:AJ22) -> 424900
D23: Total Filling Crystalizer ( Feed ) | F23: Kg | G23: ='[1]01'!$Q$18 -> 526736 | H23: ='[2]02'!$Q$18 -> 224510 | I23: =509400+165400 -> 674800 | J23: ='[4]04'!$Q$18 -> 695363 | K23: ='[5]05'!$Q$18+K22 -> 747977 | L23: ='[6]06'!$Q$18 -> 524444 | M23: ='[7]07'!$Q$18 -> 501574 | N23: ='[7]08'!$Q$18 -> 680764 | O23: ='[6]09'!$Q$18 -> 589345 | P23: ='[3]10'!$Q$18 -> 817090 | Q23: ='[5]11'!$Q$18 -> 1110923 | R23: ='[6]12'!$Q$18 -> 411103 | S23: ='[8]13'!$Q$18 -> 634120 | T23: =578566+290444 -> 869010 | U23: =584944+567152 -> 1152096 | V23: ='[9]16'!$Q$18 -> 688986 | W23: 0 | X23: ='[7]18'!$Q$18 -> 1221935 | Y23: ='[11]19'!$Q$18 -> 867293 | Z23: ='[13]20'!$Q$18 -> 1218693 | AA23: ='[13]21'!$Q$18 -> 998551 | AB23: ='[13]22'!$Q$18 -> 284335 | AC23: 0 | AD23: 0 | AE23: ='[15]25'!$Q$18+AE22 -> 296046 | AF23: ='[16]26'!$Q$18 -> 1562863 | AG23: =931340+642286 -> 1573626 | AH23: ='[17]28'!$Q$18 -> 1569616 | AI23: =340263+818995 -> 1159258 | AJ23: ='[14]30 (Stock Opname)'!$Q$18 -> 991912 | AM23: =SUM(G23:AJ23) -> 22592969 | AN23: =AM23/E18 -> 0.65566687
D24: Avg Daily Consump RPO ( MTD ) | AM24: =AM23/AM21 -> 836776.63
D25: Total Proses RBDPO | F25: Kg | G25: =SUM(G28,G32,G37,G41,G46) -> 921143 | H25: =SUM(H28,H32,H37,H41,H46) -> 250811 | I25: =SUM(I28,I32,I37,I41,I46) -> 519670 | J25: =SUM(J28,J32,J37,J41,J46) -> 738041 | K25: =SUM(K28,K32,K37,K41,K46) -> 756126 | L25: =SUM(L28,L32,L37,L41,L46) -> 570133 | M25: =SUM(M28,M32,M37,M41,M46) -> 638607 | N25: =SUM(N28,N32,N37,N41,N46) -> 813834 | ... AJ25: =SUM(AJ28,AJ32,AJ37,AJ41,AJ46) -> 1153492 | AM25: =SUM(G25:AJ25) -> 23189025
D26: Sisa Filling Crystalizer | F26: Kg | G26: =G23-G25 -> -394407 | H26: =H23-H25 -> -26301 | I26: =I23-I25 -> 155130 | J26: =J23-J25 -> -42678 | K26: =K23-K25 -> -8149 | L26: =L23-L25 -> -45689 | M26: =M23-M25 -> -137033 | N26: =N23-N25 -> -133070 | ... AJ26: =AJ23-AJ25 -> -161580 | AM26: =SUM(G26:AJ26) -> -596056
D27: Fractionation OLEIN IV 56 | AM27: Olein IV 56
D28: RBDPO Consume | F28: Kg | G28: =G29+G30 -> 0 | H28: =H29+H30 -> 0 | I28: =I29+I30 -> 0 | J28: =J29+J30 -> 0 | K28: =K29+K30 -> 222848 | L28: =L29+L30 -> 0 | M28: =M29+M30 -> 0 | N28: =N29+N30 -> 0 | ... AJ28: =AJ29+AJ30 -> 0 | AM28: =SUM(G28:AK28) -> 16566545
D29: OLEIN IV 56 | F29: Kg | K29: 190348 | O29: ='[6]09'!$P$21 -> 95794 | P29: ='[3]10'!$P$21 -> 772516 | Q29: ='[5]11'!$P$21+237105 -> 967571 | R29: ='[6]12'!$P$21 -> 538270 | S29: ='[8]13'!$P$21 -> 572873 | T29: 469337 | U29: 822558 | V29: ='[9]16'!$P$23 -> 964480 | W29: 0 | X29: ='[7]18'!$P$21 -> 526646 | Y29: ='[11]19'!$P$23 -> 822471 | Z29: ='[12]20'!$P$21 -> 977688 | AA29: ='[13]21'!$P$21 -> 908032 | AB29: ='[13]22'!$P$21 -> 343197 | AC29: 0 | AD29: 0 | AE29: ='[15]25'!$P$21 -> 217590 | AF29: ='[16]26'!$P$23 -> 1097545 | AG29: 1298759 | AH29: 1426210 | AI29: ='[19]29'!$P$21 -> 777910 | AJ29: 0 | AK29: 0 | AM29: =SUM(G29:AK29) -> 13789795
D30: STEARIN | F30: Kg | K30: 32500 | O30: 18345 | P30: ='[3]10'!$P$30 -> 173336 | Q30: ='[5]11'!$P$28 -> 186831 | R30: ='[6]12'!$P$28 -> 118662 | S30: ='[8]13'!$P$30 -> 124438 | T30: 96521 | U30: 147543 | V30: ='[9]16'!$P$30 -> 208479 | W30: 0 | X30: ='[7]18'!$P$27 -> 99947 | Y30: ='[11]19'!$P$30-Y39 -> 186549 | Z30: ='[12]20'!$P$30 -> 185126 | AA30: ='[13]21'!$P$30 -> 193691 | AB30: ='[13]22'!$P$30 -> 88321 | AC30: 0 | AD30: 0 | AE30: ='[15]25'!$P$30 -> 27470 | AF30: ='[16]26'!$P$30 -> 234400 | AG30: 226378 | AH30: 278163 | AI30: 150050 | AJ30: 0 | AK30: 0 | AM30: =SUM(G30:AK30) -> 2776750 | AU30: =AM30+AM34+AM39+AM43+AM49 -> 4579832
D31: Fractionation OLEIN IV 57 ( Bulk ) | AM31: Olein IV 57 ( Bulk )
D32: RBDPO Consume | F32: Kg | G32: =G33+G34 -> 0 | H32: =H33+H34 -> 0 | I32: =I33+I34 -> 0 | J32: =J33+J34 -> 0 | K32: =K33+K34 -> 0 | L32: =L33+L34 -> 0 | M32: =M33+M34 -> 0 | N32: =N33+N34 -> 0 | ... AK32: =AK33+AK34 -> 0 | AM32: =SUM(G32:AJ32) -> 0
D33: OLEIN IV 57 | F33: Kg | G33: 0 | H33: 0 | I33: 0 | J33: 0 | K33: 0 | L33: 0 | M33: 0 | N33: 0 | O33: 0 | P33: 0 | Q33: 0 | R33: 0 | S33: 0 | T33: 0 | U33: 0 | V33: 0 | W33: 0 | X33: 0 | Y33: 0 | Z33: 0 | AA33: 0 | AB33: 0 | AC33: 0 | AD33: 0 | AE33: 0 | AF33: 0 | AG33: 0 | AH33: 0 | AI33: 0 | AJ33: 0 | AK33: 0 | AM33: =SUM(G33:AJ33) -> 0
D34: STEARIN | F34: Kg | G34: 0 | H34: 0 | I34: 0 | J34: 0 | K34: 0 | L34: 0 | M34: 0 | N34: 0 | O34: 0 | P34: 0 | Q34: 0 | R34: 0 | S34: 0 | T34: 0 | U34: 0 | V34: 0 | W34: 0 | X34: 0 | Y34: 0 | Z34: 0 | AA34: 0 | AB34: 0 | AC34: 0 | AD34: 0 | AE34: 0 | AF34: 0 | AG34: 0 | AH34: 0 | AI34: 0 | AJ34: 0 | AK34: 0 | AM34: =SUM(G34:AJ34) -> 0
D35: Fractionation OLEIN IV 57 ( Retail ) | AM35: Olein IV 57 ( Retail )
D36: CPO Consume | F36: Kg | G36: 0 | H36: 0 | I36: 0 | J36: 0 | K36: 0 | L36: 0 | M36: 0 | N36: 0 | O36: 0 | P36: 0 | Q36: 0 | R36: 0 | T36: 0 | U36: 0 | V36: 0 | W36: 0 | X36: 0 | AK36: 0 | AM36: =SUM(G36:AJ36) -> 0
D37: RBDPO Brand Consume | F37: Kg | G37: =G38+G39 -> 0 | H37: =H38+H39 -> 0 | I37: =I38+I39 -> 0 | J37: =J38+J39 -> 0 | K37: =K38+K39 -> 0 | L37: =L38+L39 -> 0 | M37: =M38+M39 -> 0 | N37: =N38+N39 -> 0 | ... AK37: =AK38+AK39 -> 0 | AM37: =SUM(G37:AJ37) -> 40950
D38: OLEIN IV 57 Low Color | F38: Kg | G38: 0 | H38: 0 | I38: 0 | J38: 0 | K38: 0 | L38: 0 | M38: 0 | N38: 0 | O38: 0 | P38: 0 | Q38: 0 | R38: 0 | S38: 0 | T38: 0 | U38: 0 | V38: 0 | W38: 0 | X38: 0 | Y38: 30800 | Z38: 0 | AA38: 0 | AB38: 0 | AC38: 0 | AD38: 0 | AE38: 0 | AF38: 0 | AG38: 0 | AH38: 0 | AI38: 0 | AJ38: 0 | AM38: =SUM(G38:AJ38) -> 30800
D39: STEARIN | F39: Kg | G39: 0 | H39: 0 | I39: 0 | J39: 0 | K39: 0 | L39: 0 | M39: 0 | N39: 0 | O39: 0 | P39: 0 | Q39: 0 | R39: 0 | S39: 0 | T39: 0 | U39: 0 | V39: 0 | W39: 0 | X39: 0 | Y39: 10150 | Z39: 0 | AA39: 0 | AB39: 0 | AC39: 0 | AD39: 0 | AE39: 0 | AF39: 0 | AG39: 0 | AH39: 0 | AI39: 0 | AJ39: 0 | AM39: =SUM(G39:AJ39) -> 10150
D40: Fractionation OLEIN IV 58 | AM40: Olein IV 58 ( Bulk )
...

Sheet SUMMARY HPP 
B2: Production Cost September
B3: Through Put CPO Proses (Ton/Day) | H3: TPD | I3: ='HPP REF '!$N$3 -> 890.60333
B4: Working Day | F4: 1 | H4: Days | I4: ='HPP REF '!$N$4 -> 27
B5: Refined CPO ( Ton/month ) | H5: MTD | I5: =$I$4*$I$3 -> 24046.29
B6: Through Put RPO Proses (Ton/Day) | H6: TPD | I6: ='HPP FRACT'!$O$3 -> 836.77663
B7: Working Day | H7: Days | I7: ='HPP FRACT'!$O$4 -> 27
B8: Fract RPO ( ton/month ) | H8: MTD | I8: =$I$7*$I$6 -> 22592.969
B9: KURS | H9: Rp/USD | I9: 16000
B10: No | C10: Items | D10: Description | G10: Rupiah | H10: Rp/Kg | I10: USD/MT
B11: I | C11: Production Cost | D11: ● | E11: Refining Cost | G11: ='HPP REF '!$M$48 -> 4.7511346e+09 | H11: =$G$11/($I$5*1000) -> 197.58285 | I11: =(G11/$I$9)/$I$5 -> 12.348928
D12: ● | E12: Fractionation Cost | G12: ='HPP FRACT'!$M$22 -> 1.0424867e+09 | H12: =$G$12/($I$8*1000) -> 46.142086 | I12: =(G12/$I$9)/$I$8 -> 2.8838804
D13: ● | E13: Preventive Maintenance Cost | F13: 1 | G13: =MTC!$F$18 -> 7.1038385e+08 | H13: =$G$13/($I$5*1000) -> 29.542347 | I13: =(G13/$I$9)/$I$5 -> 1.8463967
G14: =SUM(G11:$G$13) -> 6.5040051e+09 | H14: =SUM($H$11:$H$13) -> 273.26729 | I14: =SUM(I11:I13) -> 17.079205
B16: II | C16: Port Cost | D16: ● | E16: Trucking Komoditi ke Kuala Tanjung | G16: =LOG!I8+LOG!I9+LOG!$I$10 -> 2.496582e+09 | H16: =$G$16/($I$5*1000) -> 103.824 | I16: =($G$16/$I$9)/$I$5 -> 6.489
D17: ● | E17: Sewa Tank PTI Total Volume : 24.000 MT ( 5 Unit ) | F17: 1 | G17: =LOG!I11+LOG!I12+LOG!I13+LOG!$I$14 -> 1886000000 | H17: =$G$17/($I$5*1000) -> 78.432058 | I17: =($G$17/$I$9)/$I$5 -> 4.9020036
D18: ● | E18: Instalasi & Pemanasan, Pompa, Surveyor dan Documen | G18: =LOG!I18+LOG!I19+LOG!I20+LOG!$I$21 -> 1.2881117e+09 | H18: =$G$18/($I$5*1000) -> 53.568 | I18: =($G$18/$I$9)/$I$5 -> 3.348
D19: ● | E19: Finalty Over Capacity Tank | G19: =LOG!I15+LOG!I16+LOG!$I$17 -> 6.8171855e+08 | H19: =$G$19/($I$5*1000) -> 28.350259 | I19: =($G$19/$I$9)/$I$5 -> 1.7718912
G20: =SUM($G$16:$G$19) -> 6.3524122e+09 | H20: =SUM($H$16:$H$19) -> 264.17432 | I20: =SUM($I$16:$I$19) -> 16.510895
B22: II | C22: Fix Cost | D22: ● | E22: Manpower Cost | F22: =F4 -> 1 | G22: =[20]MPC!$H$29*$F$22 -> 2.1846655e+09 | H22: =$G$22/($I$5*1000) -> 90.852499 | I22: =($G$22/$I$9)/$I$5 -> 5.6782812
D23: ● | E23: Admin OH Cost | F23: =F4 -> 1 | G23: =OH!G51*$F$23 -> 1.4360564e+09 | H23: =$G$23/($I$5*1000) -> 59.720497 | I23: =($G$23/$I$9)/$I$5 -> 3.7325311
D24: ● | E24: Depresiasi Cost | F24: =F4 -> 1 | G24: =DEP!I9*$F$24 -> 4.1811848e+09 | H24: =$G$24/($I$5*1000) -> 173.88066 | I24: =($G$24/$I$9)/$I$5 -> 10.867541
D25: ● | E25: Amortisation of leasehold land Cost | F25: =F4 -> 1 | G25: =AMOR!$G$20*$F$25 -> 1.0484098e+09 | H25: =$G$25/($I$5*1000) -> 43.599649 | I25: =($G$25/$I$9)/$I$5 -> 2.7249781
G26: =SUM($G$22:$G$25) -> 8.8503165e+09 | H26: =SUM($H$22:$H$25) -> 368.05331 | I26: =SUM($I$22:$I$25) -> 23.003332 | K26: =I26+I14 -> 40.082537
B28: Total Production Cost | G28: =$G$26+$G$20+$G$14 -> 2.1706734e+10 | H28: =$H$26+$H$20+$H$14 -> 905.49491 | I28: =$I$26+$I$20+$I$14 -> 56.593432

Sheet HPP REF 
B2: Refinery Cost
B3: Through Put CPO Proses | N3: =('September - 2024'!AM10)/1000 -> 890.60333 | O3: TPD
B4: Working Day | N4: ='September - 2024'!AM6 -> 27 | O4: Days
B5: Total CPO Process | N5: =N4*N3 -> 24046.29 | O5: MTD
B6: KURS | N6: 16000 | O6: Rp/USD
B7: No | C7: Item Cost | D7: Norma | F7: Pemakaian / Hari | H7: HK | J7: Total Pemakaian | K7: Harga / stn | M7: Total Biaya | N7: Rp / kg | O7: USD/MT
B8: 1 | C8: Bleaching Earth | D8: ='September - 2024'!$AM$66 -> 0.77980013 | F8: =($D$8*$N$3*10) -> 6944.9259 | G8: Kg/day | H8: =$N$4 -> 27 | J8: =$H$8*$F$8 -> 187513 | K8: 2400 | M8: =$J$8*$K$8 -> 450031200 | N8: =$M$8/($N$5*1000) -> 18.715203 | O8: =($M$8/$N$6)/$N$5 -> 1.1697002
B9: 2 | C9: Phosporic acid | D9: ='September - 2024'!$AM$70 -> 0.051981067 | F9: =($D$9*$N$3*10) -> 462.94511 | G9: Kg/day | H9: =$H$8 -> 27 | J9: =$H$9*$F$9 -> 12499.518 | K9: 17420 | M9: =$J$9*$K$9 -> 2.177416e+08 | N9: =$M$9/($N$5*1000) -> 9.0551018 | O9: =($M$9/$N$6)/$N$5 -> 0.56594386
B10: 3 | C10: Caustic Soda | D10: 29.166667 | E10: kg/day | F10: =D10 -> 29.166667 | G10: kg/day | H10: =$H$8 -> 27 | J10: =$H$10*$F$10 -> 787.5 | K10: 15700 | M10: =$J$10*$K$10 -> 12363750 | N10: =$M$10/($N$5*1000) -> 0.51416456 | O10: =($M$10/$N$6)/$N$5 -> 0.032135285
B11: 4 | C11: Pemakaian Natural Gas HPB Geka
C12: Normal Consumption | D12: ='September - 2024'!$AM$229 -> 0.24405569 | E12: MMBTU/MT CPO | F12: =$D$12*$N$3 -> 217.35681 | G12: MMBTU/day | H12: =$H$8 -> 27 | J12: =$H$12*$F$12 -> 5868.6339 | K12: =12.7*$N$6 -> 203200 | M12: =$J$12*$K$12 -> 1.1925064e+09 | N12: =$M$12/($N$5*1000) -> 49.592116 | O12: =($M$12/$N$6)/$N$5 -> 3.0995073
C13: Penalty Below Consumption | D13: 0 | E13: MMBTU/MT CPO | F13: =$D$13*$N$3 -> 0 | G13: MMBTU/day | H13: =$H$8 -> 27 | J13: =$H$13*$F$13 -> 0 | K13: =12.7*$N$6 -> 203200 | M13: =$J$13*$K$13 -> 0 | N13: =$M$13/($N$5*1000) -> 0 | O13: =($M$13/$N$6)/$N$5 -> 0
C14: Penalty Above Consumption | D14: 0 | E14: MMBTU/MT CPO | F14: =$D$14*$N$3 -> 0 | G14: MMBTU/day | H14: =$H$8 -> 27 | J14: =$H$14*$F$14 -> 0 | K14: =12.7*$N$6 -> 203200 | M14: =$J$14*$K$14 -> 0 | N14: =$M$14/($N$5*1000) -> 0 | O14: =($M$14/$N$6)/$N$5 -> 0
B15: 5 | C15: Pemakaian Steam
C16: For Process | D16: ='September - 2024'!$AM$236 -> 163.35135 | E16: Kg/MT CPO | F16: =$D$16*$N$3/1000 -> 145.48126 | G16: Ton/day | H16: =$H$8 -> 27 | J16: =$H$16*$F$16 -> 3927.994 | K16: 507006 | M16: =$J$16*$K$16 -> 1.9915165e+09 | N16: =$M$16/($N$5*1000) -> 82.820116 | O16: =($M$16/$N$6)/$N$5 -> 5.1762572
C17: Storage Tank for Heating | D17: 30 | E17: Kg/MT CPO | F17: =$D$17*$N$3/1000 -> 26.7181 | G17: Ton/day | H17: =$H$8 -> 27 | J17: =$H$17*$F$17 -> 721.3887 | K17: 507006 | M17: =$J$17*$K$17 -> 3.657484e+08 | N17: =$M$17/($N$5*1000) -> 15.21018 | O17: =($M$17/$N$6)/$N$5 -> 0.95063625
B18: 6 | C18: Pemakaian Electrical
C19: For Process | D19: ='September - 2024'!$AM$258 -> 3.4001087 | E19: kW/MT CPO | F19: =$D$19*$N$3 -> 3028.1481 | G19: kW/day | H19: =$H$8 -> 27 | I19: 0 | J19: =$H$19*$F$19 -> 81760 | K19: 1550 | L19: =[20]Electric!H21 -> 3666.6667 | M19: =($F$19*$H$19*$K$19)+($F$19*$I$19*$L$19) -> 126728000 | N19: =$M$19/($N$5*1000) -> 5.2701685 | O19: =($M$19/$N$6)/$N$5 -> 0.32938553
C20: Cooling Tower | D20: ='September - 2024'!$AM$260 -> 4.0837901 | E20: kW/MT CPO | F20: =$D$20*$N$3 -> 3637.037 | G20: kW/day | H20: =$H$8 -> 27 | I20: 0 | J20: =$H$20*$F$20 -> 98200 | K20: 1550 | L20: =L19 -> 3666.6667 | M20: =(F20*H20*K20)+(F20*I20*L20) -> 1.5221e+08 | N20: =$M$20/($N$5*1000) -> 6.3298746 | O20: =($M$20/$N$6)/$N$5 -> 0.39561716
C21: Storage Tank | D21: 0.3377877 | E21: kW/MT CPO | F21: =$D$21*$N$3 -> 300.83485 | G21: kW/day | H21: =$H$8 -> 27 | I21: 0 | J21: =$H$21*$F$21 -> 8122.541 | K21: 1550 | L21: =L20 -> 3666.6667 | M21: =($F$21*$H$21*$K$21)+($F$21*$I$21*$L$21) -> 12589938 | N21: =$M$21/($N$5*1000) -> 0.52357093 | O21: =($M$21/$N$6)/$N$5 -> 0.032723183
B22: 7 | C22: Pemakaian Water
C23: Make Up CT | D23: ='September - 2024'!$AM$245 -> 112.24185 | E23: M3/day | F23: =$D$23 -> 112.24185 | G23: M3/day | H23: =$H$8 -> 27 | J23: =$H$23*$F$23 -> 3030.5299 | K23: 8700 | M23: =$J$23*$K$23 -> 26365610 | N23: =$M$23/($N$5*1000) -> 1.0964523 | O23: =($M$23/$N$6)/$N$5 -> 0.068528268
B24: 8 | C24: Chemical Water | N24: =$M$24/($N$5*1000) -> 0 | O24: =($M$24/$N$6)/$N$5 -> 0
C25: EONBAC BC 3108 | D25: 0.4 | E25: Kg/day | F25: =D25 -> 0.4 | G25: Kg/day | H25: =$H$8 -> 27 | J25: =$H$25*$F$25 -> 10.8 | K25: 27240 | M25: =$J$25*$K$25 -> 294192 | N25: =$M$25/($N$5*1000) -> 0.012234403 | O25: =($M$25/$N$6)/$N$5 -> 0.00076465018
C26: EONLINE T722 | D26: 0.66 | E26: Kg/day | F26: =D26 -> 0.66 | G26: Kg/day | H26: =$H$8 -> 27 | J26: =$H$26*$F$26 -> 17.82 | K26: 29120 | M26: =$J$26*$K$26 -> 518918.4 | N26: =$M$26/($N$5*1000) -> 0.021579978 | O26: =($M$26/$N$6)/$N$5 -> 0.0013487486
C27: EONLINE AG5770 | D27: 0.41 | E27: Kg/day | F27: =D27 -> 0.41 | G27: Kg/day | H27: =$H$8 -> 27 | J27: =$H$27*$F$27 -> 11.07 | K27: 117212 | M27: =$J$27*$K$27 -> 1297536.8 | N27: =$M$27/($N$5*1000) -> 0.05395996 | O27: =($M$27/$N$6)/$N$5 -> 0.0033724975
C28: EONScale T2511 | D28: 0.1 | E28: Kg/day | F28: =D28 -> 0.1 | G28: Kg/day | H28: =$H$8 -> 27 | J28: =$H$28*$F$28 -> 2.7 | K28: 45940 | M28: =$J$28*$K$28 -> 124038 | N28: =$M$28/($N$5*1000) -> 0.0051583009 | O28: =($M$28/$N$6)/$N$5 -> 0.00032239381
B29: 9 | C29: Others
C30: Filter Bag 10 Microne | D30: 0.90361446 | E30: Pcs/day | F30: =D30 -> 0.90361446 | G30: Pcs/day | H30: =$H$8 -> 27 | J30: =$H$30*$F$30 -> 24.39759 | K30: 40000 | M30: =$J$30*$K$30 -> 975903.61 | N30: =$M$30/($N$5*1000) -> 0.040584373 | O30: =($M$30/$N$6)/$N$5 -> 0.0025365233
C31: Filter Bag 100 Microne | D31: 0.63253012 | E31: Pcs/day | F31: =D31 -> 0.63253012 | G31: Pcs/day | H31: =$H$8 -> 27 | J31: =$H$31*$F$31 -> 17.078313 | K31: 125000 | M31: =$J$31*$K$31 -> 2134789.2 | N31: =$M$31/($N$5*1000) -> 0.088778317 | O31: =($M$31/$N$6)/$N$5 -> 0.0055486448
C32: Filter Cartridge 10 Microne | D32: 1.5666667 | E32: Pcs/day | F32: =D32 -> 1.5666667 | G32: Pcs/day | H32: =$H$8 -> 27 | J32: =$H$32*$F$32 -> 42.3 | K32: 145000 | M32: =$J$32*$K$32 -> 6133500 | N32: =$M$32/($N$5*1000) -> 0.25507053 | O32: =($M$32/$N$6)/$N$5 -> 0.015941908
C33: Filter Dustbag | D33: 0.12048193 | E33: Pcs/day | F33: =D33 -> 0.12048193 | G33: Pcs/day | H33: =$H$8 -> 27 | J33: =$H$33*$F$33 -> 3.253012 | K33: 682500 | M33: =$J$33*$K$33 -> 2220180.7 | N33: =$M$33/($N$5*1000) -> 0.09232945 | O33: =($M$33/$N$6)/$N$5 -> 0.0057705906
C34: O Ring Filter Leaves | D34: 3.6144578 | E34: Pcs/day | F34: =D34 -> 3.6144578 | G34: Pcs/day | H34: =$H$8 -> 27 | J34: =$H$34*$F$34 -> 97.590361 | K34: 14500 | M34: =$J$34*$K$34 -> 1415060.2 | N34: =$M$34/($N$5*1000) -> 0.058847342 | O34: =($M$34/$N$6)/$N$5 -> 0.0036779588
B35: 10 | C35: Waste Water Treatment Plant ( WWTP ) | D35: ='September - 2024'!$AM$251 -> 193.96296 | E35: M3/day | F35: =D35 -> 193.96296 | G35: M3/day | H35: =$H$8 -> 27 | J35: =$H$35*$F$35 -> 5237 | K35: 18616 | M35: =$J$35*$K$35 -> 97491992 | N35: =$M$35/($N$5*1000) -> 4.0543465 | O35: =($M$35/$N$6)/$N$5 -> 0.25339666
B36: 11 | C36: SHE
C37: SBE | D37: ='September - 2024'!$AM$74 -> 189044.92 | E37: Kg/day | F37: =D37 -> 189044.92 | G37: Kg/day | H37: =$H$8 -> 27 | J37: =$F$37 -> 189044.92 | K37: 275 | M37: =$J$37*$K$37 -> 51987354 | N37: =$M$37/($N$5*1000) -> 2.1619698 | O37: =($M$37/$N$6)/$N$5 -> 0.13512311
C38: Domestic | D38: 0.1 | E38: Trip/day | F38: =D38 -> 0.1 | G38: Trip/day | H38: =$H$8 -> 27 | J38: =$H$38*$F$38 -> 2.7 | K38: 303030.3 | M38: =$J$38*$K$38 -> 818181.82 | N38: =$M$38/($N$5*1000) -> 0.034025283 | O38: =($M$38/$N$6)/$N$5 -> 0.0021265802
B39: 12 | C39: Chemical Consumption | N39: =$M$39/($N$5*1000) -> 0 | O39: =($M$39/$N$6)/$N$5 -> 0
C40: LAB Chemical | D40: =[20]Chemical!$H$33 -> 745255.21 | E40: Rp/day | F40: =D40 -> 745255.21 | G40: Rp/day | H40: =$H$8 -> 27 | M40: =$H$40*$F$40 -> 20121891 | N40: =$M$40/($N$5*1000) -> 0.83679814 | O40: =($M$40/$N$6)/$N$5 -> 0.052299884
C41: Chemical Boiler dan WTP | D41: =[20]Chemical!$H$54 -> 259161.44 | E41: Rp/day | F41: =D41 -> 259161.44 | G41: Rp/day | H41: =$H$8 -> 27 | M41: =$H$41*$F$41 -> 6997359 | N41: =$M$41/($N$5*1000) -> 0.29099537 | O41: =($M$41/$N$6)/$N$5 -> 0.01818721
...

Sheet HPP FRACT
B2: Fractionation Cost
B3: RPO Proses / Day | N3: TPD | O3: =('September - 2024'!AM24)/1000 -> 836.77663
B4: Working Day | N4: Days | O4: ='September - 2024'!AM21 -> 27
B5: Total CPO Process | N5: MTD | O5: =O3*O4 -> 22592.969
B6: KURS | N6: Rp/USD | O6: =[20]Formula!I6 -> 16000
B7: No | C7: Item Cost | D7: Norma | F7: Pemakaian / Hari | H7: HK | J7: Total Pemakaian | K7: Harga / stn | M7: Total Biaya | N7: Rp / kg | O7: USD/MT
B8: 1 | C8: Steam | D8: ='September - 2024'!$AM$238 -> 72.243714 | E8: Kg/MT CPO | F8: =$D$8*$O$3/1000 -> 60.451852 | G8: Ton/day | H8: =$O$4 -> 27 | J8: =$H$8*$F$8 -> 1632.2 | K8: =[20]Steam!$H$15 -> 507005.63 | M8: =$K$8*$J$8 -> 8.2753459e+08 | N8: =$M$8/($O$5*1000) -> 36.62797 | O8: =($M$8/$O$6)/$O$5 -> 2.2892481
B9: 2 | C9: Electrical
C10: For Process | D10: ='September - 2024'!$AM$265 -> 4.1694387 | E10: kW/MT CPO | F10: =$D$10*$O$3 -> 3488.8889 | G10: kW/day | H10: =$O$4 -> 27 | I10: 0 | J10: =$H$10*$F$10 -> 94200 | K10: =[20]Electric!$L$5 -> 1550 | L10: 3666.6667 | M10: =($F$10*$H$10*$K$10)+($F$10*$I$10*$L$10) -> 146010000 | N10: =$M$10/($O$5*1000) -> 6.46263 | O10: =($M$10/$O$6)/$O$5 -> 0.40391438
C11: Cooling Tower | D11: ='September - 2024'!$AM$263 -> 1.002303 | E11: kW/MT CPO | F11: =$D$11*$O$3 -> 838.7037 | G11: kW/day | H11: =$H$10 -> 27 | I11: 0 | J11: =$H$11*$F$11 -> 22645 | K11: =$K$10 -> 1550 | L11: 3666.6667 | M11: =($F$11*$H$11*$K$11)+($F$11*$I$11*$L$11) -> 35099750 | N11: =$M$11/($O$5*1000) -> 1.5535696 | O11: =($M$11/$O$6)/$O$5 -> 0.097098101
B12: 3 | C12: Water
C13: Make Up CT | D13: ='September - 2024'!$AM$247 -> 91.178809 | E13: M3/day | F13: =$D$13 -> 91.178809 | G13: M3/day | H13: =$H$11 -> 27 | J13: =$H$13*$F$13 -> 2461.8278 | K13: =[20]Water!$F$10 -> 8700 | M13: =$K$13*$J$13 -> 21417902 | N13: =$M$13/($O$5*1000) -> 0.94798971 | O13: =($M$13/$O$6)/$O$5 -> 0.059249357
B14: 4 | C14: Chemical Water
C15: EONBAC BC 3108 | D15: 0.4 | E15: Kg/day | F15: =$D$15 -> 0.4 | G15: Kg/day | H15: =$H$13 -> 27 | J15: =$H$15*$F$15 -> 10.8 | K15: 27240 | M15: =$K$15*$J$15 -> 294192 | N15: =$M$15/($O$5*1000) -> 0.013021396 | O15: =($M$15/$O$6)/$O$5 -> 0.00081383726
C16: EONLINE T722 | D16: 0.66 | E16: Kg/day | F16: =$D$16 -> 0.66 | G16: Kg/day | H16: =$H$15 -> 27 | J16: =$H$16*$F$16 -> 17.82 | K16: 29120 | M16: =$K$16*$J$16 -> 518918.4 | N16: =$M$16/($O$5*1000) -> 0.022968137 | O16: =($M$16/$O$6)/$O$5 -> 0.0014355085
C17: EONLINE AG5770 | D17: 0.41 | E17: Kg/day | F17: =$D$17 -> 0.41 | G17: Kg/day | H17: =$H$15 -> 27 | J17: =$H$17*$F$17 -> 11.07 | K17: 117212 | M17: =$K$17*$J$17 -> 1297536.8 | N17: =$M$17/($O$5*1000) -> 0.057431002 | O17: =($M$17/$O$6)/$O$5 -> 0.0035894376
C18: EONScale T2511 | D18: 0.1 | E18: Kg/day | F18: =$D$18 -> 0.1 | G18: Kg/day | H18: =$H$16 -> 27 | J18: =$H$18*$F$18 -> 2.7 | K18: 45940 | M18: =$K$18*$J$18 -> 124038 | N18: =$M$18/($O$5*1000) -> 0.0054901151 | O18: =($M$18/$O$6)/$O$5 -> 0.00034313219
B19: 5 | C19: Others
C20: Filter Cloth | D20: 0.33333333 | E20: Pcs/day | F20: =$D$20 -> 0.33333333 | G20: Pcs/day | H20: =$H$18 -> 27 | J20: =$H$20*$F$20 -> 9 | K20: 895000 | M20: =$K$20*$J$20 -> 8055000 | N20: =$M$20/($O$5*1000) -> 0.35652685 | O20: =($M$20/$O$6)/$O$5 -> 0.022282928
C21: Filter Bag 100 Microne | D21: 0.63253012 | E21: Pcs/day | F21: =$D$21 -> 0.63253012 | G21: Pcs/day | H21: =$H$20 -> 27 | J21: =$H$21*$F$21 -> 17.078313 | K21: 125000 | M21: =$K$21*$J$21 -> 2134789.2 | N21: =$M$21/($O$5*1000) -> 0.094489093 | O21: =($M$21/$O$6)/$O$5 -> 0.0059055683
M22: =SUM(M8:M21) -> 1.0424867e+09 | N22: =SUM(N8:N21) -> 46.142086 | O22: =SUM($O$8:$O$21) -> 2.8838804

Sheet AMOR
B2: Amortization
B3: Through Put CPO Proses | H3: TPD | I3: ='HPP REF '!N3 -> 890.60333
B4: Working Day | H4: Day | I4: ='HPP REF '!N4 -> 27
B5: Total CPO Refined | H5: TPM | I5: =I4*I3 -> 24046.29
B6: Kurs Rupiah | I6: =[21]Formula!I6 -> 16000
B7: No | C7: Description | D7: Actual 2023 | F7: Budget 2024
D8: Years | E8: Month | F8: Years | G8: Month | H8: RP/KG | I8: USD/MT
B9: 1 | C9: Perangkat Lunak/Software | D9: 9.6270931e+08 | E9: =D9/12 -> 80225776 | F9: =G9*12 -> 5.3192735e+08 | G9: 44327279 | H9: =$G$9/($I$5*1000) -> 1.8434145 | I9: =($G$9/$I$6)/$I$5 -> 0.1152134 | J9: =D9/12 -> 80225776
B10: =B9+1 -> 2 | C10: Sertifikat/Surat Izin | D10: 2.6961444e+08 | E10: =D10/12 -> 22467870 | F10: 0 | G10: 0 | H10: =$G$10/($I$5*1000) -> 0 | I10: =($G$10/$I$6)/$I$5 -> 0
B11: =B10+1 -> 3 | C11: Inventaris Kecil (Aset Sewa) | D11: 0 | E11: =D11/12 -> 0 | F11: 0 | G11: 0 | H11: =$G$11/($I$5*1000) -> 0 | I11: =($G$11/$I$6)/$I$5 -> 0
B12: =B11+1 -> 4 | C12: Aset Hak Guna (ROU) - Kendaraan | D12: 0 | E12: =D12/12 -> 0 | F12: 0 | G12: 0 | H12: =$G$12/($I$5*1000) -> 0 | I12: =($G$12/$I$6)/$I$5 -> 0
B13: =B12+1 -> 5 | C13: Aset Hak Guna (ROU) - Tangki Timbun | D13: 0 | E13: =D13/12 -> 0 | F13: 0 | G13: 0 | H13: =$G$13/($I$5*1000) -> 0 | I13: =($G$13/$I$6)/$I$5 -> 0
B14: =B13+1 -> 6 | C14: Aset Atas Biaya Penyambungan | D14: 0 | E14: =D14/12 -> 0 | F14: 0 | G14: 0 | H14: =$G$14/($I$5*1000) -> 0 | I14: =($G$14/$I$6)/$I$5 -> 0
B15: =B14+1 -> 7 | C15: Aset Hak Guna (ROU) - Pemanfaatan Lahan Sei Mangkei + Surabaya | D15: 1.2576903e+10 | E15: =D15/12 -> 1.0480752e+09 | F15: =G15*12 -> 12048990312 | G15: 1004082526 | H15: =$G$15/($I$5*1000) -> 41.756235 | I15: =($G$15/$I$6)/$I$5 -> 2.6097647
B20: Total Cost Depreciation | D20: =SUM(D9:D19) -> 1.3809227e+10 | E20: =SUM(E9:E19) -> 1.1507689e+09 | F20: =SUM(F9:F19) -> 1.2580918e+10 | G20: =SUM(G9:G19) -> 1.0484098e+09 | H20: =SUM(H9:H19) -> 43.599649 | I20: =SUM(I9:I19) -> 2.7249781

Sheet DEP
B2: Depreciation
B3: Through Put CPO Proses | J3: TPD | K3: ='HPP REF '!N3 -> 890.60333
B4: Working Day | J4: Day | K4: ='HPP REF '!N4 -> 27
B5: Total CPO Refined | J5: TPM | K5: =K4*K3 -> 24046.29
B6: Kurs Rupiah | K6: =[21]Formula!I6 -> 16000
B7: No | C7: Description | D7: Actual 2023 (Audited) | G7: Budget 2024
D8: Asset | E8: Years | F8: Month | G8: Asset | H8: Years | I8: Month | J8: RP/KG | K8: USD/MT
B9: Total Cost Depreciation | D9: =SUM(D10:D75) -> 6.7971213e+11 | E9: =SUM(E10:E75) -> 4.1807174e+10 | F9: =SUM(F10:F75) -> 3.4839312e+09 | G9: =SUM(G10:G75) -> 7.7503139e+11 | H9: =SUM(H10:H75) -> 5.0174217e+10 | I9: =SUM(I10:I75) -> 4.1811848e+09 | J9: =SUM(J10:J75) -> 173.88066 | K9: =SUM(K10:K75) -> 10.867541
B10: 1 | C10: Front Office + Canteen | D10: 3844320790 | E10: 1.9221604e+08 | F10: 16018003 | G10: 3.8443208e+09 | H10: =I10*12 -> 1.9221604e+08 | I10: 16018003 | J10: =$I$10/($K$5*1000) -> 0.666132 | K10: =($I$10/$K$6)/$K$5 -> 0.04163325
B11: =B10+1 -> 2 | C11: Bea Cukai Building | D11: 247144032 | E11: 12357202 | F11: 1029766.8 | G11: 2.4714403e+08 | H11: =I11*12 -> 12357202 | I11: 1029766.8 | J11: =$I$11/($K$5*1000) -> 0.042824352 | K11: =($I$11/$K$6)/$K$5 -> 0.002676522
B12: =B11+1 -> 3 | C12: Security Building | D12: 199088248 | E12: 12429395 | F12: 1035782.9 | G12: 3.9708686e+08 | H12: =I12*12 -> 19854343 | I12: 1654528.6 | J12: =$I$12/($K$5*1000) -> 0.068805982 | K12: =($I$12/$K$6)/$K$5 -> 0.0043003739
B13: =B12+1 -> 4 | C13: Bangunan Shelter / Pelataran | D13: 53111657402 | E13: 2.6555829e+09 | F13: 2.2129857e+08 | G13: 5.3111657e+10 | H13: =I13*12 -> 2.6555829e+09 | I13: 2.2129857e+08 | J13: =$I$13/($K$5*1000) -> 9.2030235 | K13: =($I$13/$K$6)/$K$5 -> 0.57518897
B14: =B13+1 -> 5 | C14: Laboratorium Building | D14: 1.3920764e+09 | E14: 70956822 | F14: 5913068.5 | G14: 1.5003164e+09 | H14: =I14*12 -> 75015820 | I14: 6251318.3 | J14: =$I$14/($K$5*1000) -> 0.25997018 | K14: =($I$14/$K$6)/$K$5 -> 0.016248136
B15: =B14+1 -> 6 | C15: Refinery Room | D15: 22378266872 | E15: 1.1189133e+09 | F15: 93242779 | G15: 2.2378267e+10 | H15: =I15*12 -> 1.1189133e+09 | I15: 93242779 | J15: =$I$15/($K$5*1000) -> 3.8776368 | K15: =($I$15/$K$6)/$K$5 -> 0.2423523
B16: =B15+1 -> 7 | C16: Fractionation Room | D16: 22378266872 | E16: 1.1189133e+09 | F16: 93242779 | G16: 2.2378267e+10 | H16: =I16*12 -> 1.1189133e+09 | I16: 93242779 | J16: =$I$16/($K$5*1000) -> 3.8776368 | K16: =($I$16/$K$6)/$K$5 -> 0.2423523
B17: =B16+1 -> 8 | C17: Utility Building | D17: 22548996820 | E17: 1.1274498e+09 | F17: 93954153 | G17: 2.2548997e+10 | H17: =I17*12 -> 1.1274498e+09 | I17: 93954153 | J17: =$I$17/($K$5*1000) -> 3.9072203 | K17: =($I$17/$K$6)/$K$5 -> 0.24420127
B18: =B17+1 -> 9 | C18: Power House & Electrical Building | D18: 3242778116 | E18: 1.6663346e+08 | F18: 13886122 | G18: 3.6023423e+09 | H18: =I18*12 -> 1.8011712e+08 | I18: 15009760 | J18: =$I$18/($K$5*1000) -> 0.62420272 | K18: =($I$18/$K$6)/$K$5 -> 0.03901267
B19: =B18+1 -> 10 | C19: Weight Bridge Building (Timbangan) | D19: 3.0883582e+09 | E19: 1.6798762e+08 | F19: 13998968 | G19: 4.173935e+09 | H19: =I19*12 -> 2.0869675e+08 | I19: 17391396 | J19: =$I$19/($K$5*1000) -> 0.72324653 | K19: =($I$19/$K$6)/$K$5 -> 0.045202908
B20: =B19+1 -> 11 | C20: Warehouse TPS Spent Earth | D20: 1.3067146e+09 | E20: 65335728 | F20: 5444644 | G20: 1.3067146e+09 | H20: =I20*12 -> 65335728 | I20: 5444644 | J20: =$I$20/($K$5*1000) -> 0.22642345 | K20: =($I$20/$K$6)/$K$5 -> 0.014151466
B21: =B20+1 -> 12 | C21: Bangunan Shelter / Pelataran | D21: 0 | E21: 0 | F21: 0 | G21: 0 | H21: =I21*12 -> 0 | I21: 0 | J21: =$I$21/($K$5*1000) -> 0 | K21: =($I$21/$K$6)/$K$5 -> 0
B22: =B21+1 -> 13 | C22: Packaging Building | D22: 26865966199 | E22: 1.3432983e+09 | F22: 1.1194153e+08 | G22: 2.6865966e+10 | H22: =I22*12 -> 1.895783e+09 | I22: 1.5798192e+08 | J22: =$I$22/($K$5*1000) -> 6.5699083 | K22: =($I$22/$K$6)/$K$5 -> 0.41061927
B23: =B22+1 -> 14 | C23: Warehouse TPS Limbah B3 | D23: 808088751 | E23: 52164853 | F23: 4347071.1 | G23: 1.748922e+09 | H23: =I23*12 -> 87446098 | I23: 7287174.8 | J23: =$I$23/($K$5*1000) -> 0.30304778 | K23: =($I$23/$K$6)/$K$5 -> 0.018940486
B24: =B23+1 -> 15 | C24: Panel Room Loading - Unloading | D24: 669445527 | E24: 33472276 | F24: 2789356.4 | G24: 6.6944553e+08 | H24: =I24*12 -> 33472276 | I24: 2789356.4 | J24: =$I$24/($K$5*1000) -> 0.11599945 | K24: =($I$24/$K$6)/$K$5 -> 0.0072499655
B25: =B24+1 -> 16 | C25: Bangunan Shelter / Pelataran | D25: 0 | E25: 0 | F25: 0 | G25: 0 | H25: =I25*12 -> 0 | I25: 0 | J25: =$I$25/($K$5*1000) -> 0 | K25: =($I$25/$K$6)/$K$5 -> 0
B26: =B25+1 -> 17 | C26: Kantor RO Medan | D26: 35739000 | E26: 3573900 | F26: 297825 | G26: 35739000 | H26: =I26*12 -> 3573900 | I26: 297825 | J26: =$I$26/($K$5*1000) -> 0.012385486 | K26: =($I$26/$K$6)/$K$5 -> 0.00077409291
B27: =B26+1 -> 18 | C27: Gedung Logistic | D27: 537402145 | E27: 26870107 | F27: 2239175.6 | G27: 537402145 | H27: =I27*12 -> 26870107 | I27: 2239175.6 | J27: =$I$27/($K$5*1000) -> 0.09311938 | K27: =($I$27/$K$6)/$K$5 -> 0.0058199612
B28: =B27+1 -> 19 | C28: Ruang Expansi Filling Packaging | D28: 1071796228 | E28: 26794906 | F28: 2232908.8 | G28: 1071796228 | H28: =I28*12 -> 53589811 | I28: 4465817.6 | J28: =$I$28/($K$5*1000) -> 0.18571753 | K28: =($I$28/$K$6)/$K$5 -> 0.011607346
B29: =B28+1 -> 20 | C29: Bangunan Lainnya | D29: 236594750 | E29: 67601093 | F29: 5633424.5 | G29: 3.7519242e+09 | H29: =I29*12 -> 1.9942595e+08 | I29: 16618829 | J29: =$I$29/($K$5*1000) -> 0.69111822 | K29: =($I$29/$K$6)/$K$5 -> 0.043194889
B30: =B29+1 -> 21 | C30: Power House System | D30: 30414179484 | E30: 1.6120305e+09 | F30: 1.3433587e+08 | G30: 3.0414179e+10 | H30: =I30*12 -> 1.7106159e+09 | I30: 1.4255132e+08 | J30: =$I$30/($K$5*1000) -> 5.9282045 | K30: =($I$30/$K$6)/$K$5 -> 0.37051278
B31: =B30+1 -> 22 | C31: Reception from Road Tanker System | D31: 15714477178 | E31: 1.5906981e+09 | F31: 1.3255817e+08 | G31: 1.5714477e+10 | H31: =I31*12 -> 1.6892835e+09 | I31: 1.4077362e+08 | J31: =$I$31/($K$5*1000) -> 5.8542763 | K31: =($I$31/$K$6)/$K$5 -> 0.36589227
B32: =B31+1 -> 23 | C32: Reception & CPO Storage Tank System | D32: 3.9160256e+10 | E32: 1.8156968e+09 | F32: 1.5130807e+08 | G32: 3.9160256e+10 | H32: =I32*12 -> 1.9142822e+09 | I32: 1.5952352e+08 | J32: =$I$32/($K$5*1000) -> 6.634018 | K32: =($I$32/$K$6)/$K$5 -> 0.41462612
B33: =B32+1 -> 24 | C33: Refinery Product System | D33: 26158484525 | E33: 1.546139e+09 | F33: 1.2884492e+08 | G33: 2.6158485e+10 | H33: =I33*12 -> 2.1043359e+09 | I33: 1.7536132e+08 | J33: =$I$33/($K$5*1000) -> 7.2926561 | K33: =($I$33/$K$6)/$K$5 -> 0.45579101
B34: =B33+1 -> 25 | C34: Fractionation Product System | D34: 44700543389 | E34: 2.5257813e+09 | F34: 2.1048177e+08 | G34: 4.4700543e+10 | H34: =I34*12 -> 2.6243667e+09 | I34: 2.1869722e+08 | J34: =$I$34/($K$5*1000) -> 9.0948426 | K34: =($I$34/$K$6)/$K$5 -> 0.56842766
B35: =B34+1 -> 26 | C35: Compressed Air System | D35: 12406716786 | E35: 6.9726354e+08 | F35: 58105295 | G35: 1.2406717e+10 | H35: =I35*12 -> 6.9726354e+08 | I35: 58105295 | J35: =$I$35/($K$5*1000) -> 2.4163933 | K35: =($I$35/$K$6)/$K$5 -> 0.15102458
B36: =B35+1 -> 27 | C36: Fuel Distribution System | D36: 2279256408 | E36: 1.6844371e+08 | F36: 14036976 | G36: 2.2792564e+09 | H36: =I36*12 -> 2.0366838e+08 | I36: 16972365 | J36: =$I$36/($K$5*1000) -> 0.70582054 | K36: =($I$36/$K$6)/$K$5 -> 0.044113784
B37: =B36+1 -> 28 | C37: Waste Water Treatment System | D37: 8173671310 | E37: 5.0165483e+08 | F37: 41804569 | G37: 8.1736713e+09 | H37: =I37*12 -> 5.1840723e+08 | I37: 43200602 | J37: =$I$37/($K$5*1000) -> 1.79656 | K37: =($I$37/$K$6)/$K$5 -> 0.112285
B38: =B37+1 -> 29 | C38: Clean Water System | D38: 8.1369458e+09 | E38: 4.697884e+08 | F38: 39149033 | G38: 8.1369458e+09 | H38: =I38*12 -> 4.697884e+08 | I38: 39149033 | J38: =$I$38/($K$5*1000) -> 1.6280696 | K38: =($I$38/$K$6)/$K$5 -> 0.10175435
B39: =B38+1 -> 30 | C39: Demin Water Distribution System | D39: 5554219736 | E39: 3.7021373e+08 | F39: 30851144 | G39: 5.5542197e+09 | H39: =I39*12 -> 3.7021373e+08 | I39: 30851144 | J39: =$I$39/($K$5*1000) -> 1.2829898 | K39: =($I$39/$K$6)/$K$5 -> 0.080186861
B40: =B39+1 -> 31 | C40: Steam Generation System | D40: 28411905935 | E40: 1.6009903e+09 | F40: 1.3341586e+08 | G40: 2.8411906e+10 | H40: =I40*12 -> 1.6009903e+09 | I40: 1.3341586e+08 | J40: =$I$40/($K$5*1000) -> 5.5482928 | K40: =($I$40/$K$6)/$K$5 -> 0.3467683 | L40: =H40/12 -> 1.3341586e+08
B41: =B40+1 -> 32 | C41: Cooling Water Distribution System | D41: 8813632097 | E41: 5.5719688e+08 | F41: 46433074 | G41: 8.8136321e+09 | H41: =I41*12 -> 5.5719688e+08 | I41: 46433074 | J41: =$I$41/($K$5*1000) -> 1.930987 | K41: =($I$41/$K$6)/$K$5 -> 0.12068669
...

Sheet MTC
C1: working days | F1: working days
B2: Summary - PM Electrical | C2: ='September - 2024'!AM6 -> 27 | E2: Summary - PM Mechanical | F2: ='September - 2024'!AM6 -> 27
B3: Consumable Item | C3: Total Price | E3: Consumable Item | F3: Total Price
C4: Per Day | F4: Per Day
B5: Biaya Pemeliharaan Unit Refinery(Listrik) | C5: 1648879.6 | E5: Biaya Pemeliharaan Unit Refinery | F5: 4911824.3
B6: HP Boiler | C6: 2678431.4 | E6: Biaya Pemeliharaan Unit Fraksinasi | F6: 1230672.3
B7: Dry Fractination - Crystalizer & Filter Press | C7: 288459.38 | E7: Biaya Pemeliharaan Unit Cooling Tower | F7: 1084733.9
B8: Physical Refinery-Bleaching and Deodorization | C8: 404271.71 | E8: Biaya Pemeliharaan Unit Packaging | F8: 833815.52
B9: BOILER | C9: 150891.4 | E9: Biaya Pemeliharaan Unit Material Handling | F9: 949299.72
B10: Water Plant, Effluent & Hydrant | C10: 58543.417 | E10: Biaya Pemeliharaan Unit Utility | F10: 1106022.4
B11: Pump House | C11: 87425.77 | E11: Barang Consumable Maintenance | F11: 5634698.9
B12: DCS-CCR ISBL | C12: 254341.74
B13: Lighting All Area | C13: 114733.89 | E13: Total | F13: =SUM(F5:F12) -> 15751067
B14: Consumable | C14: 203159.66 | E14: Total/Month | F14: =F13*F2 -> 4.2527881e+08
B15: Kalibrasi Instrument Pabrik | C15: 580672.27 | E15: Total/Yearly | F15: =F14*12 -> 5.1033457e+09
B16: Service Special Equipment | C16: 4089635.9
B17: Total/Day | C17: =SUM(C5:C16) -> 10559446 | E17: TOTAL COST
B18: Total/Month | C18: =C17*C2 -> 2.8510504e+08 | E18: PM E + PM M | F18: =F14+C18 -> 7.1038385e+08
B19: Total/Yearly | C19: =C18*12 -> 3.4212605e+09 | E19: TOTAL | F19: =F18*12 -> 8.5246062e+09

Sheet LOG
B2: Port Cost Kuala Tanjung
B3: Through Put CPO Proses | J3: TPD | K3: ='HPP REF '!N3 -> 890.60333
B4: Working Day | J4: Day | K4: ='HPP REF '!N4 -> 27
B5: Total CPO Refined | J5: TPM | K5: =K4*K3 -> 24046.29
B6: Kurs Rupiah | K6: =[21]Formula!I6 -> 16000
B7: No | C7: Description | G7: Norma | I7: Total Biaya ( Rp ) | J7: RP/KG | K7: USD/MT
B8: 1 | C8: Trucking Komoditi ke Kuala Tanjung | E8: Olein ( Ton ) | F8: =(100%-0.8%-1.1*5%)*80%*K5 -> 18025.099 | G8: Rp/Kg | H8: 90 | I8: =H8*F8*1000 -> 1.6222589e+09 | J8: =I8/($K$5*1000) -> 67.464 | K8: =(I8/$K$6)/$K$5 -> 4.2165
E9: Stearin ( Ton ) Iso Tank | F9: =(100%-0.8%-1.1*5%)*20%*K5 -> 4506.2747 | G9: Rp/Kg | H9: 150 | I9: =H9*F9*1000 -> 6.7594121e+08 | J9: =I9/($K$5*1000) -> 28.11 | K9: =(I9/$K$6)/$K$5 -> 1.756875
E10: PFAD ( Ton ) Iso Tank | F10: =1.1*5%*K5 -> 1322.546 | G10: Rp/Kg | H10: 150 | I10: =H10*F10*1000 -> 1.9838189e+08 | J10: =I10/($K$5*1000) -> 8.25 | K10: =(I10/$K$6)/$K$5 -> 0.515625
B11: 2 | C11: Sewa Tank PTI Total Volume : 24.000 MT ( 5 Unit ) | E11: Tank 8.000 MT >> Olein | F11: 1 | G11: Rp/Kg | H11: 77 | I11: =H11*8000*F11*1000 -> 616000000 | J11: =I11/($K$5*1000) -> 25.617257 | K11: =(I11/$K$6)/$K$5 -> 1.6010786
E12: Tank 5.000 MT >> Stearin | F12: 2 | G12: Rp/Kg | H12: 79 | I12: =H12*5000*F12*1000 -> 790000000 | J12: =I12/($K$5*1000) -> 32.853301 | K12: =(I12/$K$6)/$K$5 -> 2.0533313
E13: Tank 3.000 MT >> RBDPO | F13: 1 | G13: Rp/Kg | H13: 77 | I13: =H13*3000*F13*1000 -> 231000000 | J13: =I13/($K$5*1000) -> 9.6064715 | K13: =(I13/$K$6)/$K$5 -> 0.60040447
E14: Tank 3.000 MT S/S >> PFAD | F14: 1 | G14: Rp/Kg | H14: 83 | I14: =H14*3000*F14*1000 -> 249000000 | J14: =I14/($K$5*1000) -> 10.355028 | K14: =(I14/$K$6)/$K$5 -> 0.64718923
B15: 3 | C15: Finalty Over Capacity dari tank | D15: =[21]Formula!F14 -> 1 | E15: Over Volume Olein | F15: =F8-(8000*D15) -> 10025.099 | G15: Rp/Kg | H15: 43 | I15: =H15*F15*1000 -> 4.3107926e+08 | J15: =I15/($K$5*1000) -> 17.927059 | K15: =(I15/$K$6)/$K$5 -> 1.1204412
D16: 0 | E16: Over Volume Stearin | F16: =F9-(10000*D16) -> 4506.2747 | G16: Rp/Kg | H16: 43 | I16: =H16*F16*1000 -> 1.9376981e+08 | J16: =I16/($K$5*1000) -> 8.0582 | K16: =(I16/$K$6)/$K$5 -> 0.5036375
D17: 0 | E17: Over Volume PFAD | F17: =F10-(3000*D17) -> 1322.546 | G17: Rp/Kg | H17: 43 | I17: =H17*F17*1000 -> 56869476 | J17: =I17/($K$5*1000) -> 2.365 | K17: =(I17/$K$6)/$K$5 -> 0.1478125
B18: 3 | C18: Beban Instalasi Pemompaan dan Pemanasan | E18: Total Volume | F18: =SUM(F8:F10) -> 23853.92 | G18: Rp/Kg | H18: 22 | I18: =H18*F18*1000 -> 5.2478623e+08 | J18: =I18/($K$5*1000) -> 21.824 | K18: =(I18/$K$6)/$K$5 -> 1.364
B19: =B18+1 -> 4 | C19: Pompa | E19: Total Volume | F19: =F18 -> 23853.92 | G19: Rp/Kg | H19: 26 | I19: =H19*F18*1000 -> 6.2020191e+08 | J19: =I19/($K$5*1000) -> 25.792 | K19: =(I19/$K$6)/$K$5 -> 1.612
B20: =B19+1 -> 5 | C20: Beban Analisa ( Surveyor ) | E20: Total Volume | F20: =F18 -> 23853.92 | G20: Rp/Kg | H20: 3 | I20: =H20*F20*1000 -> 71561759 | J20: =I20/($K$5*1000) -> 2.976 | K20: =(I20/$K$6)/$K$5 -> 0.186
B21: =B20+1 -> 6 | C21: Beban Pelabuhan ( Documen-Documen Pelabuhan ) | E21: Total Volume | F21: =F20 -> 23853.92 | G21: Rp/Kg | H21: 3 | I21: =H21*F21*1000 -> 71561759 | J21: =I21/($K$5*1000) -> 2.976 | K21: =(I21/$K$6)/$K$5 -> 0.186
B22: =B21+1 -> 7 | C22: Beban Asuransi (Cost Insurance Freight)
B23: =B22+1 -> 8 | C23: Beban Sewa Kapal
B24: =B23+1 -> 9 | C24: Beban Pengangkutan Di Pelabuhan
B25: Total Biaya Transfer Product ke Kuala Tanjung Port | I25: =SUM(I8:I24) -> 6.3524122e+09 | J25: =SUM(J8:J24) -> 264.17432 | K25: =SUM(K8:K24) -> 16.510895

Sheet OH
B2: Overhead ( OH )
B3: Through Put CPO Proses | H3: TPD | I3: ='HPP REF '!N3 -> 890.60333
B4: Working Day | H4: Day | I4: ='SUMMARY HPP '!I4 -> 27
B5: Total CPO Refined | H5: TPM | I5: =I4*I3 -> 24046.29
B6: Kurs Rupiah | I6: =[21]Formula!I6 -> 16000
B7: No | C7: Description | D7: Actual 2023 (Audited) | F7: Budget 2024
D8: Years | E8: Month | F8: Years | G8: Month | H8: RP/KG | I8: USD/MT
B9: 1 | C9: Biaya Perjalanan Dinas (Dalam Provinsi) | D9: 305458258 | E9: =IFERROR(D9/12,0) -> 25454855 | F9: =G9*12 -> 3.6654991e+08 | G9: 30545826 | H9: =G9/($I$5*1000) -> 1.2702927 | I9: =(G9/$I$6)/$I$5 -> 0.079393292
B10: =B9+1 -> 2 | C10: Biaya Perjalanan Dinas (Luar Provinsi) | D10: 2.6287295e+09 | E10: =IFERROR(D10/12,0) -> 2.1906079e+08 | F10: =G10*12 -> 3.5487849e+09 | G10: 2.9573207e+08 | H10: =G10/($I$5*1000) -> 12.298449 | I10: =(G10/$I$6)/$I$5 -> 0.76865306
B11: =B10+1 -> 3 | C11: Beban BBM Kendaraan | D11: 720175678 | E11: =IFERROR(D11/12,0) -> 60014640 | F11: =G11*12 -> 7.5618446e+08 | G11: 63015372 | H11: =G11/($I$5*1000) -> 2.620586 | I11: =(G11/$I$6)/$I$5 -> 0.16378663
B12: =B11+1 -> 4 | C12: Beban Sewa Kendaraan | D12: 2428347903 | E12: =IFERROR(D12/12,0) -> 2.0236233e+08 | F12: =G12*12 -> 2220000000 | G12: 185000000 | H12: =G12/($I$5*1000) -> 7.6934945 | I12: =(G12/$I$6)/$I$5 -> 0.48084341
B13: =B12+1 -> 5 | C13: Beban Kendaraan Lainnya | D13: 110862850 | E13: =IFERROR(D13/12,0) -> 9238570.8 | F13: =G13*12 -> 110862850 | G13: 9238570.8 | H13: =G13/($I$5*1000) -> 0.38419943 | I13: =(G13/$I$6)/$I$5 -> 0.024012464
B14: =B13+1 -> 6 | C14: Beban Sewa Bangunan / Inventaris / Aset | D14: 126990400 | E14: =IFERROR(D14/12,0) -> 10582533 | F14: =G14*12 -> 110000400 | G14: 9166700 | H14: =G14/($I$5*1000) -> 0.38121057 | I14: =(G14/$I$6)/$I$5 -> 0.023825661
B15: =B14+1 -> 7 | C15: Beban Penelitian, Percobaan & Pengembangan | D15: 108868060 | E15: =IFERROR(D15/12,0) -> 9072338.3 | F15: =G15*12 -> 100000000 | G15: 8333333.3 | H15: =G15/($I$5*1000) -> 0.34655381 | I15: =(G15/$I$6)/$I$5 -> 0.021659613
B16: =B15+1 -> 8 | C16: Beban Pemeliharaan Bangunan Rumah | D16: 203000 | E16: =IFERROR(D16/12,0) -> 16916.667 | F16: =G16*12 -> 0 | G16: 0 | H16: =G16/($I$5*1000) -> 0 | I16: =(G16/$I$6)/$I$5 -> 0
B17: =B16+1 -> 9 | C17: Beban Pemeliharaan Bangunan Perusahaan | D17: 108952486 | E17: =IFERROR(D17/12,0) -> 9079373.8 | F17: =G17*12 -> 1.1440011e+08 | G17: 9533342.5 | H17: =G17/($I$5*1000) -> 0.39645794 | I17: =(G17/$I$6)/$I$5 -> 0.024778621
B18: =B17+1 -> 10 | C18: Beban Pemeliharaan Mesin & Instalansi | D18: 32369030 | E18: =IFERROR(D18/12,0) -> 2697419.2 | F18: =G18*12 -> 33987482 | G18: 2832290.1 | H18: =G18/($I$5*1000) -> 0.11778491 | I18: =(G18/$I$6)/$I$5 -> 0.0073615569
B19: =B18+1 -> 11 | C19: Beban Pemeliharaan Jalan, Jembatan & Saluran Air | D19: 179265600 | E19: =IFERROR(D19/12,0) -> 14938800 | F19: =G19*12 -> 188228880 | G19: 15685740 | H19: =G19/($I$5*1000) -> 0.65231435 | I19: =(G19/$I$6)/$I$5 -> 0.040769647
B20: =B19+1 -> 12 | C20: Beban Pemeliharaan Alat Inventaris Kecil | D20: 253700695 | E20: =IFERROR(D20/12,0) -> 21141725 | F20: =G20*12 -> 2.6638573e+08 | G20: 22198811 | H20: =G20/($I$5*1000) -> 0.92316989 | I20: =(G20/$I$6)/$I$5 -> 0.057698118
B21: =B20+1 -> 13 | C21: Beban Pemakaian Inventaris Kecil | D21: 1859843066 | E21: =IFERROR(D21/12,0) -> 1.5498692e+08 | F21: =G21*12 -> 335473201 | G21: 27956100 | H21: =G21/($I$5*1000) -> 1.1625951 | I21: =(G21/$I$6)/$I$5 -> 0.072662197
B22: =B21+1 -> 14 | C22: Beban Iuran, Sumbangan, & Bina Lingkungan | D22: 694460474 | E22: =IFERROR(D22/12,0) -> 57871706 | F22: =G22*12 -> 2.6839105e+08 | G22: 22365921 | H22: =G22/($I$5*1000) -> 0.93011941 | I22: =(G22/$I$6)/$I$5 -> 0.058132463
B23: =B22+1 -> 15 | C23: Beban Instansi Kelembagaan | E23: =IFERROR(D23/12,0) -> 0 | F23: =G23*12 -> 60000000 | G23: 5000000 | H23: =G23/($I$5*1000) -> 0.20793228 | I23: =(G23/$I$6)/$I$5 -> 0.012995768
B24: =B23+1 -> 16 | C24: Beban Pajak & Retribusi | D24: 659276883 | E24: =IFERROR(D24/12,0) -> 54939740 | F24: =G24*12 -> 1518332400 | G24: 126527700 | H24: =G24/($I$5*1000) -> 5.2618387 | I24: =(G24/$I$6)/$I$5 -> 0.32886492
B25: =B24+1 -> 17 | C25: Beban Premi Assuransi | E25: =IFERROR(D25/12,0) -> 0 | F25: =G25*12 -> 197000000 | G25: 16416667 | H25: =G25/($I$5*1000) -> 0.682711 | I25: =(G25/$I$6)/$I$5 -> 0.042669437
B26: =B25+1 -> 18 | C26: Beban Penerangan | D26: 62716328 | E26: =IFERROR(D26/12,0) -> 5226360.7 | F26: =G26*12 -> 80400000 | G26: 6700000 | H26: =G26/($I$5*1000) -> 0.27862926 | I26: =(G26/$I$6)/$I$5 -> 0.017414329
B27: =B26+1 -> 19 | C27: Beban Persediaan Air | D27: 1756590 | E27: =IFERROR(D27/12,0) -> 146382.5 | F27: =G27*12 -> 6840000 | G27: 570000 | H27: =G27/($I$5*1000) -> 0.02370428 | I27: =(G27/$I$6)/$I$5 -> 0.0014815175
B28: =B27+1 -> 20 | C28: Beban Pemakaian Perlengkapan Kantor | D28: 1.1936208e+09 | E28: =IFERROR(D28/12,0) -> 99468402 | F28: =G28*12 -> 1.1936208e+09 | G28: 99468402 | H28: =G28/($I$5*1000) -> 4.1365384 | I28: =(G28/$I$6)/$I$5 -> 0.25853365
B29: =B28+1 -> 21 | C29: Beban Pengendalian Lingkungan (ISO 14000) | D29: 488020500 | E29: =IFERROR(D29/12,0) -> 40668375 | F29: =G29*12 -> 264000000 | G29: 22000000 | H29: =G29/($I$5*1000) -> 0.91490205 | I29: =(G29/$I$6)/$I$5 -> 0.057181378
B30: =B29+1 -> 22 | C30: Beban Sistem Manajemen Keselamatan & Kesehatan Kerja (SMK3) | D30: 68171900 | E30: =IFERROR(D30/12,0) -> 5680991.7 | F30: =G30*12 -> 258000000 | G30: 21500000 | H30: =G30/($I$5*1000) -> 0.89410882 | I30: =(G30/$I$6)/$I$5 -> 0.055881801
B31: =B30+1 -> 23 | C31: Beban Pendidikan & Pengembangan SDM | D31: 1186354647 | E31: =IFERROR(D31/12,0) -> 98862887 | F31: =G31*12 -> 10000000 | G31: 833333.33 | H31: =G31/($I$5*1000) -> 0.034655381 | I31: =(G31/$I$6)/$I$5 -> 0.0021659613
B32: =B31+1 -> 24 | C32: Beban Audit (Independent Auditor) | D32: 8.477783e+08 | E32: =IFERROR(D32/12,0) -> 70648192 | F32: =G32*12 -> 9.0712278e+08 | G32: 75593565 | H32: =G32/($I$5*1000) -> 3.1436685 | I32: =(G32/$I$6)/$I$5 -> 0.19647928
B33: =B32+1 -> 25 | C33: Beban Konsultan - Eksternal | D33: 245454645 | E33: =IFERROR(D33/12,0) -> 20454554 | F33: =G33*12 -> 2.7000011e+08 | G33: 22500009 | H33: =G33/($I$5*1000) -> 0.93569566 | I33: =(G33/$I$6)/$I$5 -> 0.058480979
B34: =B33+1 -> 26 | C34: Beban Insentif Karyawan | E34: =IFERROR(D34/12,0) -> 0 | F34: =G34*12 -> 0 | G34: 0 | H34: =G34/($I$5*1000) -> 0 | I34: =(G34/$I$6)/$I$5 -> 0
B35: =B34+1 -> 27 | C35: Beban Jasa Produksi Karyawan | E35: =IFERROR(D35/12,0) -> 0 | F35: =G35*12 -> 0 | G35: 0 | H35: =G35/($I$5*1000) -> 0 | I35: =(G35/$I$6)/$I$5 -> 0
B36: =B35+1 -> 28 | C36: Beban Uang Jasa (Jubilium, SHT, Dll) | D36: 188207400 | E36: =IFERROR(D36/12,0) -> 15683950 | F36: =G36*12 -> 207028140 | G36: 17252345 | H36: =G36/($I$5*1000) -> 0.7174639 | I36: =(G36/$I$6)/$I$5 -> 0.044841494
B37: =B36+1 -> 29 | C37: Beban Imbalan Pasca Kerja | D37: 4384212523 | E37: =IFERROR(D37/12,0) -> 3.6535104e+08 | F37: =G37*12 -> 666345107 | G37: 55528759 | H37: =G37/($I$5*1000) -> 2.3092443 | I37: =(G37/$I$6)/$I$5 -> 0.14432777
B38: =B37+1 -> 30 | C38: Beban Pengurusan Sertifikasi / Hak Merk / Izin / Dll | D38: 108648500 | E38: =IFERROR(D38/12,0) -> 9054041.7 | F38: =G38*12 -> 114080925 | G38: 9506743.8 | H38: =G38/($I$5*1000) -> 0.39535179 | I38: =(G38/$I$6)/$I$5 -> 0.024709487
B39: =B38+1 -> 31 | C39: Beban Entertainment | D39: 80056015 | E39: =IFERROR(D39/12,0) -> 6671334.6 | F39: =G39*12 -> 0 | G39: 0 | H39: =G39/($I$5*1000) -> 0 | I39: =(G39/$I$6)/$I$5 -> 0
B40: =B39+1 -> 32 | C40: Beban Akomodasi Rapat | D40: 84564877 | E40: =IFERROR(D40/12,0) -> 7047073.1 | F40: =G40*12 -> 88793121 | G40: 7399426.7 | H40: =G40/($I$5*1000) -> 0.30771594 | I40: =(G40/$I$6)/$I$5 -> 0.019232246
B41: =B40+1 -> 33 | C41: Beban Bonus Karyawan | E41: =IFERROR(D41/12,0) -> 0 | F41: =G41*12 -> 0 | G41: 0 | H41: =G41/($I$5*1000) -> 0 | I41: =(G41/$I$6)/$I$5 -> 0
...

Sheet Convert Gas
B3: CONVERT PEMAKAIAN GAS HP BOILER & MP BOILER
D4: 2024
C5: HP BOILER | F5: TOTAL CORRECTED VOLUME (Sm3) | K5: ENERGY MP BOILER (MMBTU) | L5: TOTAL GAS CONSUMPTION (MMBTU) | M5: PERCENTAGE
C6: UNCORRECTED VOLUME (UV) (m3) | D6: PRESS. Bar | E6: CORRECTED VOLUME (CV) (Sm3) | G6: Convert Sm3 to SCF | H6: VOLUME (MSCF) | I6: HEATING VALUE (BTU / SCF) | J6: ENERGY HP BOILER (MMBTU) | M6: HP Boiler | N6: MP Boiler
C7: 1 | D7: 2 | E7: 3 = 1 x 2 | F7: 4 = 3 | G7: 5 | H7: 6 = (4 x 5) / 1000 | I7: 7 | J7: 8 = (6 x 7) / 1000 | K7: 9 = 10 - 8 | L7: 10 | M7: 11 = 8 / 10 | N7: 12 = 9 / 10
B8: 1 | C8: 750.8 | D8: 5 | E8: =C8*D8 -> 3754 | F8: =E8 -> 3754 | G8: 35.314667 | H8: =(F8*G8)/1000 -> 132.57126 | I8: 1063.6404 | J8: =(H8*I8)/1000 -> 141.00815 | K8: =L8-J8 -> -141.00815 | M8: =(J8/L8) -> #DIV/0! | N8: =K8/L8 -> #DIV/0!
B9: =B8+1 -> 2 | C9: 928.9 | D9: 5 | E9: =C9*D9 -> 4644.5 | F9: =E9 -> 4644.5 | G9: 35.314667 | H9: =(F9*G9)/1000 -> 164.01897 | I9: 1063.7814 | J9: =(H9*I9)/1000 -> 174.48033 | K9: =L9-J9 -> -174.48033 | M9: =(J9/L9) -> #DIV/0! | N9: =K9/L9 -> #DIV/0!
B10: =B9+1 -> 3 | C10: 1286 | D10: 5 | E10: =C10*D10 -> 6430 | F10: =E10 -> 6430 | G10: 35.314667 | H10: =(F10*G10)/1000 -> 227.07331 | I10: 1064.493 | J10: =(H10*I10)/1000 -> 241.71796 | K10: =L10-J10 -> -241.71796 | M10: =(J10/L10) -> #DIV/0! | N10: =K10/L10 -> #DIV/0!
B11: =B10+1 -> 4 | C11: 1351.5 | D11: 5 | E11: =C11*D11 -> 6757.5 | F11: =E11 -> 6757.5 | G11: 35.314667 | H11: =(F11*G11)/1000 -> 238.63886 | I11: 1065.46 | J11: =(H11*I11)/1000 -> 254.26015 | K11: =L11-J11 -> -254.26015 | M11: =(J11/L11) -> #DIV/0! | N11: =K11/L11 -> #DIV/0!
B12: =B11+1 -> 5 | C12: 673.7 | D12: 5 | E12: =C12*D12 -> 3368.5 | F12: =E12 -> 3368.5 | G12: 35.314667 | H12: =(F12*G12)/1000 -> 118.95746 | I12: 1064.3053 | J12: =(H12*I12)/1000 -> 126.60705 | K12: =L12-J12 -> -126.60705 | M12: =(J12/L12) -> #DIV/0! | N12: =K12/L12 -> #DIV/0!
B13: =B12+1 -> 6 | C13: 736.9 | D13: 5 | E13: =C13*D13 -> 3684.5 | F13: =E13 -> 3684.5 | G13: 35.314667 | H13: =(F13*G13)/1000 -> 130.11689 | I13: 1059.8926 | J13: =(H13*I13)/1000 -> 137.90993 | K13: =L13-J13 -> -137.90993 | M13: =(J13/L13) -> #DIV/0! | N13: =K13/L13 -> #DIV/0!
B14: =B13+1 -> 7 | C14: 681.7 | D14: 5 | E14: =C14*D14 -> 3408.5 | F14: =E14 -> 3408.5 | G14: 35.314667 | H14: =(F14*G14)/1000 -> 120.37004 | I14: 1063.2268 | J14: =(H14*I14)/1000 -> 127.98066 | K14: =L14-J14 -> -127.98066 | M14: =(J14/L14) -> #DIV/0! | N14: =K14/L14 -> #DIV/0!
B15: =B14+1 -> 8 | C15: 402.4 | D15: 5 | E15: =C15*D15 -> 2012 | F15: =E15 -> 2012 | G15: 35.314667 | H15: =(F15*G15)/1000 -> 71.05311 | I15: 1067.715 | J15: =(H15*I15)/1000 -> 75.864469 | K15: =L15-J15 -> -75.864469 | M15: =(J15/L15) -> #DIV/0! | N15: =K15/L15 -> #DIV/0!
B16: =B15+1 -> 9 | C16: 1008 | D16: 5 | E16: =C16*D16 -> 5040 | F16: =E16 -> 5040 | G16: 35.314667 | H16: =(F16*G16)/1000 -> 177.98592 | I16: 1067.715 | J16: =(H16*I16)/1000 -> 190.03823 | K16: =L16-J16 -> -190.03823 | M16: =(J16/L16) -> #DIV/0! | N16: =K16/L16 -> #DIV/0!
B17: =B16+1 -> 10 | C17: 1307.1 | D17: 5 | E17: =C17*D17 -> 6535.5 | F17: =E17 -> 6535.5 | G17: 35.314667 | H17: =(F17*G17)/1000 -> 230.79901 | I17: 1065.3777 | J17: =(H17*I17)/1000 -> 245.88812 | K17: =L17-J17 -> -245.88812 | M17: =(J17/L17) -> #DIV/0! | N17: =K17/L17 -> #DIV/0!
B18: =B17+1 -> 11 | C18: 1361.4 | D18: 5 | E18: =C18*D18 -> 6807 | F18: =E18 -> 6807 | G18: 35.314667 | H18: =(F18*G18)/1000 -> 240.38694 | I18: 1069.3462 | J18: =(H18*I18)/1000 -> 257.05687 | K18: =L18-J18 -> -257.05687 | M18: =(J18/L18) -> #DIV/0! | N18: =K18/L18 -> #DIV/0!
B19: =B18+1 -> 12 | C19: 645.6 | D19: 5 | E19: =C19*D19 -> 3228 | F19: =E19 -> 3228 | G19: 35.314667 | H19: =(F19*G19)/1000 -> 113.99575 | I19: 1051.8029 | J19: =(H19*I19)/1000 -> 119.90105 | K19: =L19-J19 -> -119.90105 | M19: =(J19/L19) -> #DIV/0! | N19: =K19/L19 -> #DIV/0!
B20: =B19+1 -> 13 | C20: 848.8 | D20: 5 | E20: =C20*D20 -> 4244 | F20: =E20 -> 4244 | G20: 35.314667 | H20: =(F20*G20)/1000 -> 149.87545 | I20: 1056.0701 | J20: =(H20*I20)/1000 -> 158.27897 | K20: =L20-J20 -> -158.27897 | M20: =(J20/L20) -> #DIV/0! | N20: =K20/L20 -> #DIV/0!
... B37: =B36+1 -> 30 | C37: 809.9 | D37: 5 | E37: =C37*D37 -> 4049.5 | F37: =E37 -> 4049.5 | G37: 51.314667 | H37: =(F37*G37)/1000 -> 207.79874 | I37: 1041.5933 | J37: =(H37*I37)/1000 -> 216.44177 | K37: =L37-J37 -> -216.44177 | M37: =(J37/L37) -> #DIV/0! | N37: =K37/L37 -> #DIV/0!
B38: =B37+1 -> 31 | D38: 5 | E38: =C38*D38 -> 0 | F38: =E38 -> 0 | G38: 52.314667 | H38: =(F38*G38)/1000 -> 0 | J38: =(H38*I38)/1000 -> 0 | K38: =L38-J38 -> 0 | M38: =(J38/L38) -> #DIV/0! | N38: =K38/L38 -> #DIV/0!
B39: Average | F39: =AVERAGE(F8:F38) -> 4473.129 | H39: =AVERAGE(H8:H38) -> 179.39688 | I39: =AVERAGE(I8:I38) -> 1055.7775 | J39: =AVERAGE(J8:J38) -> 189.31077 | K39: =AVERAGE(K8:K38) -> -189.31077 | L39: =AVERAGE(L8:L38) -> #DIV/0! | M39: =AVERAGE(M8:M38) -> #DIV/0! | N39: =AVERAGE(N8:N38) -> #DIV/0!
B40: TOTAL | C40: =SUM(C8:C38) -> 27733.4 | E40: =SUM(E8:E38) -> 138667 | F40: =SUM(F8:F38) -> 138667 | H40: =SUM(H8:H38) -> 5561.3034 | J40: =SUM(J8:J38) -> 5868.634
B41: Koreksi
B42: Total Setelah Koreksi | H42: =H40+H41 -> 5561.3034 | J42: =J40+J41 -> 5868.634
C44: CONVERT HP Boiler from Utility
C45: =C40 -> 27733.4 | D45: m3 | F45: =C40*5 -> 138667 | G45: 9983.7
C46: 5 | D46: bar | F46: 21286.9 | G46: =G45-C40 -> -17749.7
C47: =C45*C46 -> 138667 | D47: Sm3 | F47: =F45/F46 -> 6.5141942
C48: =G38 -> 52.314667 | D48: Scf
C49: =(C47*C48)/1000 -> 7254.3179 | D49: Volume (MSCF)
C50: =I39 -> 1055.7775 | D50: Heating Value
C51: =(C49*C50)/1000 -> 7658.9453 | D51: Energy (mmbtu)

Sheet OIP Refinery
B2: Oil In Plant Refinery
B4: No | C4: Tanggal | D4: Opening Stock | E4: Closing Stock | F4: Closing Stock | G4: Selisih OIP Consume
B5: 1 | C5: 45536 | D5: 283428 | E5: 258370 | F5: 278115 | G5: =E5-D5 -> -25058
B6: 2 | C6: 45537 | D6: =E5 -> 258370 | E6: 263554 | F6: 218067 | G6: =E6-D6 -> 5184
B7: 3 | C7: 45538 | D7: =E6 -> 263554 | E7: 276348 | F7: 257614 | G7: =E7-D7 -> 12794
B8: 4 | C8: 45539 | D8: =E7 -> 276348 | E8: 261140 | F8: 246851 | G8: =E8-D8 -> -15208
B9: 5 | C9: 45540 | D9: =E8 -> 261140 | E9: 258430 | F9: 255653 | G9: =E9-D9 -> -2710
B10: 6 | C10: 45541 | D10: =E9 -> 258430 | E10: 262670 | F10: 258450 | G10: =E10-D10 -> 4240
B11: 7 | C11: 45542 | D11: =E10 -> 262670 | E11: 266620 | F11: 238552 | G11: =E11-D11 -> 3950
B12: 8 | C12: 45543 | D12: =E11 -> 266620 | E12: 274697 | F12: 283505 | G12: =E12-D12 -> 8077
