Workbook

Sheet November 2024
C1: PRODUCTION REPORT
C2: No | D2: ITEM | E2: Budget / Norma | F2: UoM | G2: November | AL2: TOTAL MONTHLY (Kg)
G3: 1 | H3: 2 | I3: 3 | J3: 4 | K3: 5 | L3: 6 | M3: 7 | N3: 8 | O3: 9 | P3: 10 | Q3: 11 | R3: 12 | S3: 13 | T3: 14 | U3: 15 | V3: 16 | W3: 17 | X3: 18 | Y3: 19 | Z3: 20 | AA3: 21 | AB3: 22 | AC3: 23 | AD3: 24 | AE3: 25 | AF3: 26 | AG3: 27 | AH3: 28 | AI3: 29 | AJ3: 30
C4: 1 | D4: PRODUCTION | AL4: Production
D5: Refinery | AL5: Refinery
D6: Running Days | F6: Day | G6: 1 | H6: 1 | I6: 1 | J6: 1 | K6: 1 | L6: 1 | M6: 1 | N6: 1 | O6: 1 | P6: 1 | Q6: 1 | R6: 1 | S6: 1 | T6: 1 | U6: 1 | V6: 1 | W6: 1 | X6: 1 | Y6: 1 | Z6: 1 | AA6: 1 | AB6: 1 | AC6: 0 | AD6: 0 | AE6: 0 | AF6: 0 | AG6: 0 | AH6: 0 | AI6: 0 | AJ6: 0 | AL6: =SUM(G6:AJ6) -> 22
D7: Incoming CPO | F7: Kg | G7: ='[1]01'!$P$15 -> 839697 | H7: ='[2]02'!$P$15 -> 1188983 | I7: ='[2]03'!$P$15 -> 686390 | J7: 631759 | K7: 768297 | L7: ='[3]06'!$P$15 -> 265829 | M7: ='[4]07'!$P$15 -> 1355300 | N7: ='[5]08'!$P$15 -> 1709933 | O7: ='[5]09'!$P$15 -> 1254148 | P7: ='[5]10'!$P$15 -> 427434 | Q7: ='[6]11'!$P$15 -> 1046286 | R7: ='[7]12'!$P$15 -> 1337112 | S7: ='[8]13'!$P$15 -> 1544985 | T7: ='[9]14'!$P$15 -> 1532271 | U7: ='[10]15'!$P$15 -> 1051996 | V7: ='[11]16'!$P$15 -> 1149146 | W7: ='[11]17'!$P$15 -> 0 | X7: ='[12]18'!$P$15 -> 1135049 | Y7: ='[13]19'!$P$15 -> 890223 | Z7: ='[14]20'!$P$15 -> 949617 | AA7: ='[15]21'!$P$15 -> 1535903 | AB7: ='[16]22'!$P$15 -> 1313539 | AC7: ='[17]23'!$P$15 -> 1943723 | AD7: ='[17]24'!$P$15 -> 413342 | AE7: ='[18]25'!$P$15 -> 2214932 | AF7: ='[19]26'!$P$15 -> 2308752 | AG7: ='[19]27'!$P$15 -> 434771 | AH7: ='[20]28'!$P$15 -> 1330147 | AI7: ='[1]28'!$P$15 -> 990392 | AJ7: ='[21]30 (Stock Opname)'!$P$15 -> 1416573 | AL7: =SUM(G7:AJ7) -> 33666529
D8: Ratio Run CPO | F8: % | G8: =G9/2200000*100 -> 39.072136 | H8: =H9/2200000*100 -> 24.422727 | I8: =I9/2200000*100 -> 33.490955 | J8: =J9/2200000*100 -> 40.663136 | K8: 40.936545 | L8: =L9/2200000*100 -> 38.4625 | M8: =M9/2200000*100 -> 34.265182 | N8: =N9/2200000*100 -> 31.670136 | O8: =O9/2200000*100 -> 37.663364 | P8: =P9/2200000*100 -> 45.620455 | Q8: =Q9/2200000*100 -> 45.491318 | R8: =R9/2200000*100 -> 42.072636 | S8: =S9/2200000*100 -> 36.530273 | ... AJ8: =AJ9/2200000*100 -> 0 | AL8: =SUM(G8:AJ8)/AL6 -> 42.102025
D9: CPO Consume Total | E9: 36359000 | F9: Kg | G9: ='[1]01'!$Q$15 -> 859587 | H9: ='[2]02'!$Q$15 -> 537300 | I9: ='[2]03'!$Q$15 -> 736801 | J9: 894589 | K9: 900604 | L9: ='[3]06'!$Q$15 -> 846175 | M9: ='[4]07'!$Q$15 -> 753834 | N9: ='[5]08'!$Q$15 -> 696743 | O9: ='[5]09'!$Q$15 -> 828594 | P9: ='[5]10'!$Q$15 -> 1003650 | Q9: ='[6]11'!$Q$15 -> 1000809 | R9: ='[7]12'!$Q$15 -> 925598 | S9: ='[8]13'!$Q$15 -> 803666 | T9: ='[9]14'!$Q$15 -> 1009988 | U9: ='[10]15'!$Q$15 -> 1042124 | V9: ='[11]16'!$Q$15 -> 991679 | W9: ='[11]17'!$Q$15 -> 633826 | X9: ='[12]18'!$Q$15 -> 1114065 | Y9: ='[13]19'!$Q$15 -> 1358019 | Z9: ='[14]20'!$Q$15 -> 1573360 | AA9: ='[15]21'!$Q$15 -> 1433933 | AB9: ='[16]22'!$Q$15 -> 432436 | AC9: ='[17]23'!$Q$15 -> 0 | AD9: ='[17]24'!$Q$15 -> 0 | AE9: ='[18]25'!$Q$15 -> 0 | AF9: ='[19]26'!$Q$15 -> 0 | AG9: ='[19]27'!$Q$15 -> 0 | AH9: ='[20]28'!$Q$15 -> 0 | AI9: ='[1]28'!$Q$15 -> 0 | AJ9: ='[21]30 (Stock Opname)'!$Q$15 -> 0 | AL9: =SUM(G9:AJ9) -> 20377380
D10: Avg Daily Consump CPO ( MTD ) | AL10: =AL9/AL6 -> 926244.55 | AM10: =AL9/E9 -> 0.56044941
D11: CPO Consume Poram | E11: 29045000 | F11: Kg | G11: =G9-G12 -> 859587 | H11: =H9-H12 -> 537300 | I11: =I9-I12 -> 736801 | J11: =J9-J12 -> 894589 | K11: 900604 | L11: =L9-L12 -> 846175 | M11: =M9-M12 -> 753834 | N11: =N9-N12 -> 696743 | O11: =O9-O12 -> 828594 | P11: =P9-P12 -> 1003650 | Q11: =Q9-Q12 -> 1000809 | R11: =R9-R12 -> 925598 | S11: =S9-S12 -> 803666 | ... AJ11: =AJ9-AJ12 -> 0 | AL11: =SUM(G11:AJ11) -> 20377380
D12: CPO Consume Brand | E12: 7314000 | F12: Kg | G12: =G36+G45+G50 -> 0 | H12: =H36+H45+H50 -> 0 | I12: =I36+I45+I50 -> 0 | J12: =J36+J45+J50 -> 0 | K12: 0 | L12: =L36+L45+L50 -> 0 | M12: =M36+M45+M50 -> 0 | N12: =N36+N45+N50 -> 0 | O12: =O36+O45+O50 -> 0 | P12: =P36+P45+P50 -> 0 | Q12: =Q36+Q45+Q50 -> 0 | R12: =R36+R45+R50 -> 0 | S12: =S36+S45+S50 -> 0 | ... AJ12: =AJ36+AJ45+AJ50 -> 0 | AL12: =SUM(G12:AJ12) -> 0
D13: - FFA | E13: 5 | F13: % | G13: 3.95 | H13: =(4.11+3.38)/2 -> 3.745 | I13: =(4.12+3.52)/2 -> 3.82 | J13: 3.84 | K13: 3.87 | L13: 3.93 | M13: 3.65 | N13: =(4.3+3.73)/2 -> 4.015 | O13: 4.04 | P13: =(4.06+3.79)/2 -> 3.925 | Q13: 3.86 | R13: =(3.9+3.87+3.35)/3 -> 3.7066667 | S13: =(3.73+3.33)/2 -> 3.53 | T13: =(3.86+3.36)/2 -> 3.61 | U13: =(3.96+3.45)/2 -> 3.705 | V13: =(3.75+3.52)/2 -> 3.635 | W13: 4.17 | X13: =(4.3+3.83)/2 -> 4.065 | Y13: =(4.33+3.69)/2 -> 4.01 | Z13: =(4.03+3.71)/2 -> 3.87 | AA13: 4.16 | AB13: 4.06 | AC13: 0 | AD13: 0 | AE13: 0 | AF13: 0 | AG13: 0 | AH13: 0 | AI13: 0 | AJ13: 0 | AL13: =SUM(G13:AJ13)/AL6 -> 3.8712121
D14: - Moist & Impurities | E14: 0.5 | F14: % | G14: 0.41 | H14: =(0.48+0.44)/2 -> 0.46 | I14: =(0.48+0.48)/2 -> 0.48 | J14: 0.42 | K14: 0.45 | L14: 0.47 | M14: 0.41 | N14: =(0.41+0.45)/2 -> 0.43 | O14: 0.43 | P14: =(0.4+0.45)/2 -> 0.425 | Q14: 0.48 | R14: =(0.4+0.4+0.45)/3 -> 0.41666667 | S14: =(0.42+0.4)/2 -> 0.41 | T14: =(0.38+0.43)/2 -> 0.405 | U14: =(0.42+0.43)/2 -> 0.425 | V14: =(0.42+0.44)/2 -> 0.43 | W14: 0.45 | X14: =(0.46+0.42)/2 -> 0.44 | Y14: =(0.4+0.39)/2 -> 0.395 | Z14: =(0.42+0.41)/2 -> 0.415 | AA14: 0.45 | AB14: 0.45 | AC14: 0 | AD14: 0 | AE14: 0 | AF14: 0 | AG14: 0 | AH14: 0 | AI14: 0 | AJ14: 0 | AL14: =SUM(G14:AJ14)/AL6 -> 0.43416667
D15: - DOBI | E15: 2,20 Min | F15: % | G15: 2.02 | H15: 2.01 | I15: 2.02 | J15: 2.01 | K15: 2.02 | L15: 2.01 | M15: 2.02 | N15: 2.01 | O15: 2.02 | P15: 2.01 | Q15: 2.02 | R15: 2.01 | S15: 2.02 | T15: 2.01 | U15: 2.02 | V15: 2.01 | W15: 2.02 | X15: 2.01 | Y15: 2.02 | Z15: 2.01 | AA15: 2.02 | AB15: 2.01 | AC15: 0 | AD15: 0 | AE15: 0 | AF15: 0 | AG15: 0 | AH15: 0 | AI15: 0 | AJ15: 0 | AL15: =SUM(G15:AJ15)/AL6 -> 2.015
D16: Product | AL16: Product
D17: OIP RBDPO | G17: ='[22]OIP Refinery'!G5 -> -406 | H17: ='OIP Refinery'!G6 -> -6347 | I17: ='OIP Refinery'!G7 -> 3041 | J17: ='OIP Refinery'!G8 -> -3727 | K17: 3867 | L17: ='OIP Refinery'!G10 -> 4672 | M17: ='OIP Refinery'!G11 -> -3984 | N17: ='OIP Refinery'!G12 -> -49689 | O17: ='OIP Refinery'!G13 -> 42583 | P17: ='OIP Refinery'!G14 -> 9236 | Q17: ='OIP Refinery'!G15 -> 12226 | R17: ='OIP Refinery'!G16 -> 2888 | S17: ='OIP Refinery'!G17 -> -11029 | T17: ='OIP Refinery'!G18 -> 14415 | U17: ='OIP Refinery'!G19 -> -23435 | V17: ='OIP Refinery'!G20 -> 15090 | W17: ='OIP Refinery'!G21 -> -22972 | X17: ='OIP Refinery'!G22 -> 32794 | Y17: ='OIP Refinery'!G23 -> -20863 | Z17: ='OIP Refinery'!G24 -> -38825 | AA17: ='OIP Refinery'!G25 -> 40150 | AB17: ='OIP Refinery'!G26 -> -95665 | AC17: ='OIP Refinery'!G27 -> -179950 | AD17: ='OIP Refinery'!G28 -> 0 | AE17: ='OIP Refinery'!G29 -> 0 | AF17: ='OIP Refinery'!G30 -> 0 | AG17: ='OIP Refinery'!G31 -> 0 | AH17: ='OIP Refinery'!G32 -> 0 | AI17: ='OIP Refinery'!G33 -> 0 | AJ17: ='OIP Refinery'!G34 -> 0
D18: RBDPO | E18: 34458000 | F18: Kg | G18: ='[1]01'!$P$18+G17 -> 832484 | H18: ='[2]02'!$P$18+H17 -> 503888 | I18: ='[2]03'!$P$18+I17 -> 717643 | J18: =854343+J17 -> 850616 | K18: =862559+K17 -> 866426 | L18: ='[3]06'!$P$18+L17 -> 804611 | M18: ='[4]07'!$P$18+M17 -> 717374 | N18: ='[5]08'!$P$18+N17 -> 631067 | O18: ='[5]09'!$P$18+O17 -> 754534 | P18: ='[5]10'!$P$18+P17 -> 966838 | Q18: ='[6]11'!$P$18+Q17 -> 948306 | R18: ='[7]12'!$P$18+R17 -> 870851 | S18: ='[8]13'!$P$18+S17 -> 758174 | T18: ='[9]14'!$P$18+T17 -> 937848 | U18: ='[10]15'!$P$18+U17 -> 978639 | V18: ='[11]16'!$P$18+V17 -> 945977 | W18: ='[11]17'!$P$18+22972 -> 655261 | X18: ='[12]18'!$P$18+X17 -> 1058377 | Y18: ='[13]19'!$P$18+20863 -> 1311371 | Z18: ='[14]20'!$P$18+38825 -> 1504302 | AA18: ='[15]21'!$P$18+40150 -> 1396518 | AB18: ='[16]22'!$P$18+95665 -> 599189 | AC18: ='[17]23'!$P$18+179950 -> 347862 | AD18: ='[17]24'!$P$18 -> 0 | AE18: ='[18]25'!$P$18 -> 0 | AF18: ='[19]26'!$P$18 -> 0 | AG18: ='[19]27'!$P$18 -> 0 | AH18: ='[20]28'!$P$18 -> 0 | AI18: ='[1]28'!$P$18 -> 0 | AJ18: ='[21]30 (Stock Opname)'!$P$18 -> 0 | AL18: =SUM(G18:AJ18) -> 19958156
D19: PFAD | E19: 1636000 | F19: Kg | G19: ='[1]01'!$P$26 -> 34408 | H19: ='[2]02'!$P$26 -> 24264 | I19: ='[2]03'!$P$26 -> 31198 | J19: 43177 | K19: 29951 | L19: ='[3]06'!$P$26 -> 35234 | M19: ='[4]07'!$P$26 -> 30033 | N19: ='[5]08'!$P$26 -> 30410 | O19: ='[5]09'!$P$26 -> 37854 | P19: ='[5]10'!$P$26 -> 43557 | Q19: ='[6]11'!$P$26 -> 43387 | R19: ='[7]12'!$P$26 -> 39212 | S19: ='[8]13'!$P$26 -> 41814 | T19: ='[9]14'!$P$26 -> 33066 | U19: ='[10]15'!$P$26 -> 55468 | V19: ='[11]16'!$P$26 -> 39691 | W19: ='[11]17'!$P$26 -> 31383 | X19: ='[12]18'!$P$26 -> 47540 | Y19: ='[13]19'!$P$26 -> 40680 | Z19: ='[14]20'!$P$26 -> 57733 | AA19: ='[15]21'!$P$26 -> 64108 | AB19: ='[16]22'!$P$26 -> 29969 | AC19: ='[17]23'!$P$26 -> 6321 | AD19: ='[17]24'!$P$26 -> 0 | AE19: ='[18]25'!$P$26 -> 0 | AF19: ='[19]26'!$P$26 -> 0 | AG19: ='[19]27'!$P$26 -> 0 | AH19: ='[20]28'!$P$26 -> 0 | AI19: ='[1]28'!$P$26 -> 0 | AJ19: ='[21]30 (Stock Opname)'!$P$26 -> 0 | AL19: =SUM(G19:AJ19) -> 870458
D20: Fractionation
D21: Running Days | F21: Day | G21: 1 | H21: 1 | I21: 1 | J21: 1 | K21: 1 | L21: 1 | M21: 1 | N21: 1 | O21: 1 | P21: 1 | Q21: 1 | R21: 1 | S21: 1 | T21: 1 | U21: 1 | V21: 1 | W21: 1 | X21: 1 | Y21: 1 | Z21: 1 | AA21: 1 | AB21: 1 | AC21: 1 | AD21: 1 | AE21: 0 | AF21: 0 | AG21: 0 | AH21: 0 | AI21: 0 | AJ21: 0 | AL21: =SUM(G21:AJ21) -> 24
D22: Filling Langsung CR Fr Refinery | F22: Kg | G22: 0 | H22: 0 | I22: 0 | J22: 0 | K22: 0 | L22: 0 | M22: 0 | N22: 0 | O22: 0 | P22: 0 | Q22: 0 | R22: 0 | S22: 0 | T22: 0 | U22: 0 | V22: 0 | W22: 0 | X22: 0 | Y22: 0 | Z22: 0 | AA22: 0 | AB22: 0 | AC22: 0 | AD22: 0 | AE22: 0 | AF22: 0 | AG22: 0 | AH22: 0 | AI22: 0 | AJ22: 0 | AL22: =SUM(G22:AJ22) -> 0
D23: Total Filling Crystalizer ( Feed ) | F23: Kg | G23: ='[1]01'!$Q$18 -> 995005 | H23: ='[2]02'!$Q$18 -> 1111304 | I23: ='[2]03'!$Q$18 -> 1103741 | J23: 952027 | K23: 967829 | L23: ='[3]06'!$Q$18 -> 982946 | M23: ='[4]07'!$Q$18 -> 991841 | N23: ='[5]08'!$Q$18 -> 769268 | O23: ='[5]09'!$Q$18 -> 743523 | P23: ='[5]10'!$Q$18 -> 1142644 | Q23: ='[6]11'!$Q$18 -> 991404 | R23: ='[7]12'!$Q$18 -> 958171 | S23: ='[8]13'!$Q$18 -> 760178 | T23: ='[9]14'!$Q$18 -> 805516 | U23: ='[10]15'!$Q$18 -> 827755 | V23: ='[11]16'!$Q$18 -> 811972 | W23: ='[11]17'!$Q$18 -> 928407 | X23: ='[12]18'!$Q$18 -> 862219 | Y23: ='[13]19'!$Q$18 -> 882883 | Z23: ='[14]20'!$Q$18 -> 920378 | AA23: ='[15]21'!$Q$18 -> 907770 | AB23: ='[16]22'!$Q$18 -> 931307 | AC23: ='[17]23'!$Q$18 -> 871518 | AD23: ='[17]24'!$Q$18 -> 518230 | AE23: ='[18]25'!$Q$18 -> 0 | AF23: ='[19]26'!$Q$18 -> 0 | AG23: ='[19]27'!$Q$18 -> 0 | AH23: ='[20]28'!$Q$18 -> 0 | AI23: ='[1]28'!$Q$18 -> 0 | AJ23: ='[21]30 (Stock Opname)'!$Q$18 -> 0 | AL23: =SUM(G23:AJ23) -> 21737836
D24: Avg Daily Consump RPO ( MTD ) | AL24: =AL23/AL21 -> 905743.17
D25: Total Proses RBDPO | F25: Kg | G25: =SUM(G28,G32,G37,G41,G51) -> 994298 | H25: =SUM(H28,H32,H37,H41,H51) -> 1115291 | I25: =SUM(I28,I32,I37,I41,I51) -> 1038010 | J25: =SUM(J28,J32,J37,J41,J51) -> 1058141 | K25: 899356 | L25: =SUM(L28,L32,L37,L41,L51) -> 939422 | M25: =SUM(M28,M32,M37,M41,M51) -> 1003337 | N25: =SUM(N28,N32,N37,N41,N51) -> 899475 | O25: =SUM(O28,O32,O37,O41,O51) -> 923368 | P25: =SUM(P28,P32,P37,P41,P51) -> 1178496 | Q25: =SUM(Q28,Q32,Q37,Q41,Q51) -> 1073268 | R25: =SUM(R28,R32,R37,R41,R51) -> 927936 | S25: =SUM(S28,S32,S37,S41,S51) -> 732528 | ... AJ25: =SUM(AJ28,AJ32,AJ37,AJ41,AJ51) -> 0 | AL25: =SUM(G25:AJ25) -> 22537659 | AM25: =AL25/E18 -> 0.65406173
D26: Sisa Filling Crystalizer | F26: Kg | G26: =G23-G25 -> 707 | I26: =I23-I25 -> 65731 | J26: =J23-J25 -> -106114 | K26: 68473 | L26: =L23-L25 -> 43524 | M26: =M23-M25 -> -11496 | N26: =N23-N25 -> -130207 | O26: =O23-O25 -> -179845 | P26: =P23-P25 -> -35852 | Q26: =Q23-Q25 -> -81864 | R26: =R23-R25 -> 30235 | S26: =S23-S25 -> 27650 | ... AJ26: =AJ23-AJ25 -> 0 | AL26: =SUM(G26:AJ26) -> -795836
D27: Fractionation OLEIN IV 56 | AL27: Olein IV 56
D28: RBDPO Consume | F28: Kg | G28: =G29+G30 -> 0 | H28: =H29+H30 -> 0 | I28: =I29+I30 -> 0 | J28: =J29+J30 -> 0 | K28: 0 | L28: =L29+L30 -> 0 | M28: =M29+M30 -> 0 | N28: =N29+N30 -> 0 | O28: =O29+O30 -> 0 | P28: =P29+P30 -> 958540 | Q28: =Q29+Q30 -> 1073268 | R28: =R29+R30 -> 927936 | S28: =S29+S30 -> 732528 | ... AJ28: =AJ29+AJ30 -> 0 | AL28: =SUM(G28:AJ28) -> 5970222
D29: OLEIN IV 56 | F29: Kg | G29: 0 | H29: 0 | I29: 0 | J29: 0 | K29: 0 | L29: 0 | M29: 0 | N29: 0 | O29: 0 | P29: ='[5]10'!$P$21 -> 792648 | Q29: ='[6]11'!$P$21 -> 886386 | R29: ='[7]12'!$P$21 -> 785685 | S29: ='[8]13'!$P$21 -> 615419 | T29: ='[9]14'!$P$21 -> 827507 | U29: ='[10]15'!$P$21 -> 420382 | V29: 0 | W29: 0 | X29: 0 | Y29: 0 | Z29: 0 | AA29: 0 | AB29: 0 | AC29: 0 | AD29: ='[17]24'!$P$21 -> 662727 | AE29: 0 | AF29: 0 | AG29: 0 | AH29: 0 | AI29: 0 | AJ29: 0 | AL29: =SUM(G29:AJ29) -> 4990754
D30: STEARIN | F30: Kg | G30: 0 | H30: 0 | I30: 0 | J30: 0 | K30: 0 | L30: 0 | M30: 0 | N30: 0 | O30: 0 | P30: 165892 | Q30: ='[6]11'!$P$30 -> 186882 | R30: ='[7]12'!$P$30 -> 142251 | S30: ='[8]13'!$P$30 -> 117109 | T30: ='[9]14'!$P$30 -> 153671 | U30: 83550 | V30: 0 | W30: 0 | X30: 0 | Y30: 0 | Z30: 0 | AA30: 0 | AB30: 0 | AC30: 0 | AD30: 130113 | AE30: 0 | AF30: 0 | AG30: 0 | AH30: 0 | AI30: 0 | AJ30: 0 | AL30: =SUM(G30:AJ30) -> 979468
D31: Fractionation OLEIN IV 57 ( Bulk ) | AL31: Olein IV 57 ( Bulk )
D32: RBDPO Consume | F32: Kg | G32: =G33+G34 -> 0 | H32: =H33+H34 -> 0 | I32: =I33+I34 -> 0 | J32: =J33+J34 -> 0 | K32: 0 | L32: =L33+L34 -> 0 | M32: =M33+M34 -> 0 | N32: =N33+N34 -> 0 | O32: =O33+O34 -> 0 | P32: =P33+P34 -> 0 | Q32: =Q33+Q34 -> 0 | R32: =R33+R34 -> 0 | S32: =S33+S34 -> 0 | ... AJ32: =AJ33+AJ34 -> 0 | AL32: =SUM(G32:AJ32) -> 0
D33: OLEIN IV 57 | F33: Kg | G33: 0 | H33: 0 | I33: 0 | J33: 0 | K33: 0 | L33: 0 | M33: 0 | N33: 0 | O33: 0 | P33: 0 | Q33: 0 | R33: 0 | S33: 0 | T33: 0 | U33: 0 | V33: 0 | W33: 0 | X33: 0 | Y33: 0 | Z33: 0 | AA33: 0 | AB33: 0 | AC33: 0 | AD33: 0 | AE33: 0 | AF33: 0 | AG33: 0 | AH33: 0 | AI33: 0 | AJ33: 0 | AL33: =SUM(G33:AJ33) -> 0
D34: STEARIN | F34: Kg | G34: 0 | H34: 0 | I34: 0 | J34: 0 | K34: 0 | L34: 0 | M34: 0 | N34: 0 | O34: 0 | P34: 0 | Q34: 0 | R34: 0 | S34: 0 | T34: 0 | U34: 0 | V34: 0 | W34: 0 | X34: 0 | Y34: 0 | Z34: 0 | AA34: 0 | AB34: 0 | AC34: 0 | AD34: 0 | AE34: 0 | AF34: 0 | AG34: 0 | AH34: 0 | AI34: 0 | AJ34: 0 | AL34: =SUM(G34:AJ34) -> 0
D35: Fractionation OLEIN IV 57 ( Retail ) | AL35: Olein IV 57 ( Retail )
D36: CPO Consume | F36: Kg | AL36: =SUM(G36:AJ36) -> 0
D37: RBDPO Brand Consume | F37: Kg | G37: =G38+G39 -> 0 | H37: =H38+H39 -> 0 | I37: =I38+I39 -> 0 | J37: =J38+J39 -> 0 | K37: 0 | L37: =L38+L39 -> 0 | M37: =M38+M39 -> 0 | N37: =N38+N39 -> 0 | O37: =O38+O39 -> 0 | P37: =P38+P39 -> 0 | Q37: =Q38+Q39 -> 0 | R37: =R38+R39 -> 0 | S37: =S38+S39 -> 0 | ... AJ37: =AJ38+AJ39 -> 0 | AL37: =SUM(G37:AJ37) -> 0
D38: OLEIN IV 57 Low Color | F38: Kg | G38: 0 | H38: 0 | I38: 0 | J38: 0 | K38: 0 | L38: 0 | M38: 0 | N38: 0 | O38: 0 | P38: 0 | Q38: 0 | R38: 0 | S38: 0 | T38: 0 | U38: 0 | V38: 0 | W38: 0 | X38: 0 | Y38: 0 | Z38: 0 | AA38: 0 | AB38: 0 | AC38: 0 | AD38: 0 | AE38: 0 | AF38: 0 | AG38: 0 | AH38: 0 | AI38: 0 | AJ38: 0 | AL38: =SUM(G38:AJ38) -> 0
D39: STEARIN | F39: Kg | G39: 0 | H39: 0 | I39: 0 | J39: 0 | K39: 0 | L39: 0 | M39: 0 | N39: 0 | O39: 0 | P39: 0 | Q39: 0 | R39: 0 | S39: 0 | T39: 0 | U39: 0 | V39: 0 | W39: 0 | X39: 0 | Y39: 0 | Z39: 0 | AA39: 0 | AB39: 0 | AC39: 0 | AD39: 0 | AE39: 0 | AF39: 0 | AG39: 0 | AH39: 0 | AI39: 0 | AJ39: 0 | AL39: =SUM(G39:AJ39) -> 0
D40: Fractionation OLEIN IV 58 ( Bulk ) | AL40: Olein IV 58 ( Bulk )
...

Sheet SUMMARY HPP 
B2: Production Cost September
B3: Through Put CPO Proses (Ton/Day) | H3: TPD | I3: ='HPP REF '!$N$3 -> 926.24455
B4: Working Day | F4: 1 | H4: Days | I4: ='HPP REF '!$N$4 -> 22
B5: Refined CPO ( Ton/month ) | H5: MTD | I5: =$I$4*$I$3 -> 20377.38
B6: Through Put RPO Proses (Ton/Day) | H6: TPD | I6: ='HPP FRACT'!$O$3 -> 905.74317
B7: Working Day | H7: Days | I7: ='HPP FRACT'!$O$4 -> 24
B8: Fract RPO ( ton/month ) | H8: MTD | I8: =$I$7*$I$6 -> 21737.836
B9: KURS | H9: Rp/USD | I9: 15546
B10: No | C10: Items | D10: Description | G10: Rupiah | H10: Rp/Kg | I10: USD/MT
B11: I | C11: Production Cost | D11: ● | E11: Refining Cost | G11: ='HPP REF '!$M$48 -> 5.3772519e+09 | H11: =$G$11/($I$5*1000) -> 263.88338 | I11: =(G11/$I$9)/$I$5 -> 16.974359
D12: ● | E12: Fractionation Cost | G12: ='HPP FRACT'!$M$22 -> 1.4786844e+09 | H12: =$G$12/($I$8*1000) -> 68.023534 | I12: =(G12/$I$9)/$I$8 -> 4.3756293
D13: ● | E13: Preventive Maintenance Cost | F13: =F4 -> 1 | G13: =MTC!$F$18*F13 -> 5.7883129e+08 | H13: =$G$13/($I$5*1000) -> 28.405579 | I13: =(G13/$I$9)/$I$5 -> 1.8271954
G14: =SUM(G11:$G$13) -> 7.4347676e+09 | H14: =SUM($H$11:$H$13) -> 360.31249 | I14: =SUM(I11:I13) -> 23.177183 | K14: =I14+I26 -> 51.114957
B16: II | C16: Port Cost | D16: ● | E16: Trucking Komoditi ke Kuala Tanjung | G16: =LOG!I8+LOG!I9+LOG!$I$10 -> 2.1156611e+09 | H16: =$G$16/($I$5*1000) -> 103.824 | I16: =($G$16/$I$9)/$I$5 -> 6.6785025
D17: ● | E17: Sewa Tank PTI Total Volume : 24.000 MT ( 5 Unit ) | F17: =F4 -> 1 | G17: =LOG!I11+LOG!I12+LOG!I13+LOG!$I$14*F17 -> 1886000000 | H17: =$G$17/($I$5*1000) -> 92.553606 | I17: =($G$17/$I$9)/$I$5 -> 5.9535318
D18: ● | E18: Instalasi & Pemanasan, Pompa, Surveyor dan Documen | G18: =LOG!I18+LOG!I19+LOG!I20+LOG!$I$21 -> 1.0915755e+09 | H18: =$G$18/($I$5*1000) -> 53.568 | I18: =($G$18/$I$9)/$I$5 -> 3.4457738
D19: ● | E19: Finalty Over Capacity Tank | G19: =LOG!I15+LOG!I16+LOG!$I$17 -> 8.6921752e+08 | H19: =$G$19/($I$5*1000) -> 42.656 | I19: =($G$19/$I$9)/$I$5 -> 2.7438569
G20: =SUM($G$16:$G$19) -> 5.9624541e+09 | H20: =SUM($H$16:$H$19) -> 292.60161 | I20: =SUM($I$16:$I$19) -> 18.821665
B22: II | C22: Fix Cost | D22: ● | E22: Manpower Cost | F22: =F4 -> 1 | G22: =[23]MPC!$H$29*$F$22 -> 2.1846655e+09 | H22: =$G$22/($I$5*1000) -> 107.21032 | I22: =($G$22/$I$9)/$I$5 -> 6.8963286
D23: ● | E23: Admin OH Cost | F23: =F4 -> 1 | G23: =OH!G51*$F$23 -> 1.4360564e+09 | H23: =$G$23/($I$5*1000) -> 70.473063 | I23: =($G$23/$I$9)/$I$5 -> 4.5331959
D24: ● | E24: Depresiasi Cost | F24: =F4 -> 1 | G24: =DEP!I9*$F$24 -> 4.1811848e+09 | H24: =$G$24/($I$5*1000) -> 205.18756 | I24: =($G$24/$I$9)/$I$5 -> 13.198736
D25: ● | E25: Amortisation of leasehold land Cost | F25: =F4 -> 1 | G25: =AMOR!$G$20*$F$25 -> 1.0484098e+09 | H25: =$G$25/($I$5*1000) -> 51.449686 | I25: =($G$25/$I$9)/$I$5 -> 3.3095128
G26: =SUM($G$22:$G$25) -> 8.8503165e+09 | H26: =SUM($H$22:$H$25) -> 434.32063 | I26: =SUM($I$22:$I$25) -> 27.937774 | K26: =I26+I14 -> 51.114957
B28: Total Production Cost | G28: =$G$26+$G$20+$G$14 -> 2.2247538e+10 | H28: =$H$26+$H$20+$H$14 -> 1087.2347 | I28: =$I$26+$I$20+$I$14 -> 69.936622

Sheet Convert Gas
B3: CONVERT PEMAKAIAN GAS HP BOILER & MP BOILER
D4: 2024
C5: HP BOILER | F5: TOTAL CORRECTED VOLUME (Sm3) | K5: ENERGY MP BOILER (MMBTU) | L5: TOTAL GAS CONSUMPTION (MMBTU) | M5: PERCENTAGE
C6: UNCORRECTED VOLUME (UV) (m3) | D6: PRESS. Bar | E6: CORRECTED VOLUME (CV) (Sm3) | G6: Convert Sm3 to SCF | H6: VOLUME (MSCF) | I6: HEATING VALUE (BTU / SCF) | J6: ENERGY HP BOILER (MMBTU) | M6: HP Boiler | N6: MP Boiler
C7: 1 | D7: 2 | E7: 3 = 1 x 2 | F7: 4 = 3 | G7: 5 | H7: 6 = (4 x 5) / 1000 | I7: 7 | J7: 8 = (6 x 7) / 1000 | K7: 9 = 10 - 8 | L7: 10 | M7: 11 = 8 / 10 | N7: 12 = 9 / 10
B8: 1 | C8: 988.4 | D8: 5 | E8: =C8*D8 -> 4942 | F8: =E8 -> 4942 | G8: 35.314667 | H8: =(F8*G8)/1000 -> 174.52508 | I8: 1038.4131 | J8: =(H8*I8)/1000 -> 181.22913 | K8: =L8-J8 -> -181.22913 | M8: =(J8/L8) -> #DIV/0! | N8: =K8/L8 -> #DIV/0!
B9: =B8+1 -> 2 | C9: 872.9 | D9: 5 | E9: =C9*D9 -> 4364.5 | F9: =E9 -> 4364.5 | G9: 35.314667 | H9: =(F9*G9)/1000 -> 154.13086 | I9: 1044.2698 | J9: =(H9*I9)/1000 -> 160.9542 | K9: =L9-J9 -> -160.9542 | M9: =(J9/L9) -> #DIV/0! | N9: =K9/L9 -> #DIV/0!
B10: =B9+1 -> 3 | C10: 816.9 | D10: 5 | E10: =C10*D10 -> 4084.5 | F10: =E10 -> 4084.5 | G10: 35.314667 | H10: =(F10*G10)/1000 -> 144.24276 | I10: 1044.7709 | J10: =(H10*I10)/1000 -> 150.70063 | K10: =L10-J10 -> -150.70063 | M10: =(J10/L10) -> #DIV/0! | N10: =K10/L10 -> #DIV/0!
B11: =B10+1 -> 4 | C11: 896.2 | D11: 5 | E11: =C11*D11 -> 4481 | F11: =E11 -> 4481 | G11: 35.314667 | H11: =(F11*G11)/1000 -> 158.24502 | I11: 1043.9567 | J11: =(H11*I11)/1000 -> 165.20095 | K11: =L11-J11 -> -165.20095 | M11: =(J11/L11) -> #DIV/0! | N11: =K11/L11 -> #DIV/0!
B12: =B11+1 -> 5 | C12: 891.4 | D12: 5 | E12: =C12*D12 -> 4457 | F12: =E12 -> 4457 | G12: 35.314667 | H12: =(F12*G12)/1000 -> 157.39747 | I12: 1044.7373 | J12: =(H12*I12)/1000 -> 164.43901 | K12: =L12-J12 -> -164.43901 | M12: =(J12/L12) -> #DIV/0! | N12: =K12/L12 -> #DIV/0!
B13: =B12+1 -> 6 | C13: 796.1 | D13: 5 | E13: =C13*D13 -> 3980.5 | F13: =E13 -> 3980.5 | G13: 35.314667 | H13: =(F13*G13)/1000 -> 140.57003 | I13: 1044.793 | J13: =(H13*I13)/1000 -> 146.86659 | K13: =L13-J13 -> -146.86659 | M13: =(J13/L13) -> #DIV/0! | N13: =K13/L13 -> #DIV/0!
B14: =B13+1 -> 7 | C14: 738.6 | D14: 5 | E14: =C14*D14 -> 3693 | F14: =E14 -> 3693 | G14: 35.314667 | H14: =(F14*G14)/1000 -> 130.41707 | I14: 1045.6588 | J14: =(H14*I14)/1000 -> 136.37175 | K14: =L14-J14 -> -136.37175 | M14: =(J14/L14) -> #DIV/0! | N14: =K14/L14 -> #DIV/0!
B15: =B14+1 -> 8 | C15: 777 | D15: 5 | E15: =C15*D15 -> 3885 | F15: =E15 -> 3885 | G15: 35.314667 | H15: =(F15*G15)/1000 -> 137.19748 | I15: 1045.501 | J15: =(H15*I15)/1000 -> 143.4401 | K15: =L15-J15 -> -143.4401 | M15: =(J15/L15) -> #DIV/0! | N15: =K15/L15 -> #DIV/0!
B16: =B15+1 -> 9 | C16: 825.1 | D16: 5 | E16: =C16*D16 -> 4125.5 | F16: =E16 -> 4125.5 | G16: 35.314667 | H16: =(F16*G16)/1000 -> 145.69066 | I16: 1046.5619 | J16: =(H16*I16)/1000 -> 152.47429 | K16: =L16-J16 -> -152.47429 | M16: =(J16/L16) -> #DIV/0! | N16: =K16/L16 -> #DIV/0!
B17: =B16+1 -> 10 | C17: 965.8 | D17: 5 | E17: =C17*D17 -> 4829 | F17: =E17 -> 4829 | G17: 35.314667 | H17: =(F17*G17)/1000 -> 170.53453 | I17: 1045.8094 | J17: =(H17*I17)/1000 -> 178.34662 | K17: =L17-J17 -> -178.34662 | M17: =(J17/L17) -> #DIV/0! | N17: =K17/L17 -> #DIV/0!
B18: =B17+1 -> 11 | C18: 909.1 | D18: 5 | E18: =C18*D18 -> 4545.5 | F18: =E18 -> 4545.5 | G18: 35.314667 | H18: =(F18*G18)/1000 -> 160.52282 | I18: 1047.8197 | J18: =(H18*I18)/1000 -> 168.19897 | K18: =L18-J18 -> -168.19897 | M18: =(J18/L18) -> #DIV/0! | N18: =K18/L18 -> #DIV/0!
B19: =B18+1 -> 12 | C19: 861.1 | D19: 5 | E19: =C19*D19 -> 4305.5 | F19: =E19 -> 4305.5 | G19: 35.314667 | H19: =(F19*G19)/1000 -> 152.0473 | I19: 1047.0739 | J19: =(H19*I19)/1000 -> 159.20476 | K19: =L19-J19 -> -159.20476 | M19: =(J19/L19) -> #DIV/0! | N19: =K19/L19 -> #DIV/0!
B20: =B19+1 -> 13 | C20: 908 | D20: 5 | E20: =C20*D20 -> 4540 | F20: =E20 -> 4540 | G20: 35.314667 | H20: =(F20*G20)/1000 -> 160.32859 | I20: 1047.4429 | J20: =(H20*I20)/1000 -> 167.93504 | K20: =L20-J20 -> -167.93504 | M20: =(J20/L20) -> #DIV/0! | N20: =K20/L20 -> #DIV/0!
... B37: =B36+1 -> 30 | C37: 0 | D37: 5 | E37: =C37*D37 -> 0 | F37: =E37 -> 0 | G37: 51.314667 | H37: =(F37*G37)/1000 -> 0 | I37: 1044.8302 | J37: =(H37*I37)/1000 -> 0 | K37: =L37-J37 -> 0 | M37: =(J37/L37) -> #DIV/0! | N37: =K37/L37 -> #DIV/0!
B38: Average | F38: =AVERAGE(F8:F37) -> 3429.7333 | H38: =AVERAGE(H8:H37) -> 127.60446 | I38: =AVERAGE(I8:I37) -> 1045.774 | J38: =AVERAGE(J8:J37) -> 133.48926 | K38: =AVERAGE(K8:K37) -> -133.48926 | L38: =AVERAGE(L8:L37) -> #DIV/0! | M38: =AVERAGE(M8:M37) -> #DIV/0! | N38: =AVERAGE(N8:N37) -> #DIV/0!
B39: TOTAL | C39: =SUM(C8:C37) -> 20578.4 | E39: =SUM(E8:E37) -> 102892 | F39: =SUM(F8:F37) -> 102892 | H39: =SUM(H8:H37) -> 3828.1337 | J39: =SUM(J8:J37) -> 4004.6778
B40: Koreksi
B41: Total Setelah Koreksi | H41: =H39+H40 -> 3828.1337 | J41: =J39+J40 -> 4004.6778
C43: CONVERT HP Boiler from Utility
C44: =C39 -> 20578.4 | D44: m3 | F44: =C39*5 -> 102892 | G44: 9983.7
C45: 5 | D45: bar | F45: 21286.9 | G45: =G44-C39 -> -10594.7
C46: =C44*C45 -> 102892 | D46: Sm3 | F46: =F44/F45 -> 4.8335831
C47: =G37 -> 51.314667 | D47: Scf
C48: =(C46*C47)/1000 -> 5279.8687 | D48: Volume (MSCF)
C49: =I38 -> 1045.774 | D49: Heating Value
C50: =(C48*C49)/1000 -> 5521.5494 | D50: Energy (mmbtu)

Sheet OIP Refinery
B2: Oil In Plant Refinery
B4: No | C4: Tanggal | D4: Opening Stock | E4: Closing Stock | F4: Closing Stock | G4: Selisih OIP Consume
B5: 1 | C5: 45597 | D5: =265930+10000 -> 275930 | E5: 275524 | F5: 278115 | G5: =E5-D5 -> -406
B6: =B5+1 -> 2 | C6: 45598 | D6: =E5 -> 275524 | E6: 269177 | F6: 218067 | G6: =E6-D6 -> -6347
B7: =B6+1 -> 3 | C7: 45599 | D7: =E6 -> 269177 | E7: 272218 | F7: 257614 | G7: =E7-D7 -> 3041
B8: =B7+1 -> 4 | C8: 45600 | D8: =E7 -> 272218 | E8: 268491 | F8: 246851 | G8: =E8-D8 -> -3727
B9: =B8+1 -> 5 | C9: 45601 | D9: =E8 -> 268491 | E9: 272358 | F9: 255653 | G9: =E9-D9 -> 3867
B10: =B9+1 -> 6 | C10: 45602 | D10: =E9 -> 272358 | E10: 277030 | F10: 258450 | G10: =E10-D10 -> 4672
B11: =B10+1 -> 7 | C11: 45603 | D11: =E10 -> 277030 | E11: 273046 | F11: 238552 | G11: =E11-D11 -> -3984
B12: =B11+1 -> 8 | C12: 45604 | D12: =E11 -> 273046 | E12: 223357 | F12: 283505 | G12: =E12-D12 -> -49689
B13: =B12+1 -> 9 | C13: 45605 | D13: =E12 -> 223357 | E13: 265940 | F13: 269320 | G13: =E13-D13 -> 42583
B14: =B13+1 -> 10 | C14: 45606 | D14: =E13 -> 265940 | E14: 275176 | F14: 281809 | G14: =E14-D14 -> 9236
B15: =B14+1 -> 11 | C15: 45607 | D15: =E14 -> 275176 | E15: 287402 | F15: 267958 | G15: =E15-D15 -> 12226
B16: =B15+1 -> 12 | C16: 45608 | D16: =E15 -> 287402 | E16: =260290+30000 -> 290290 | F16: 267268 | G16: =E16-D16 -> 2888
B17: =B16+1 -> 13 | C17: 45609 | D17: =E16 -> 290290 | E17: 279261 | F17: 285895 | G17: =E17-D17 -> -11029
B18: =B17+1 -> 14 | C18: 45610 | D18: =E17 -> 279261 | E18: 293676 | F18: =286934-27000 -> 259934 | G18: =E18-D18 -> 14415
B19: =B18+1 -> 15 | C19: 45611 | D19: =E18 -> 293676 | E19: =262861+7380 -> 270241 | F19: =259375-30000 -> 229375 | G19: =E19-D19 -> -23435
B20: =B19+1 -> 16 | C20: 45612 | D20: =E19 -> 270241 | E20: 285331 | F20: 206080 | G20: =E20-D20 -> 15090
B21: =B20+1 -> 17 | C21: 45613 | D21: =E20 -> 285331 | E21: 262359 | F21: 205580 | G21: =E21-D21 -> -22972
B22: =B21+1 -> 18 | C22: 45614 | D22: =E21 -> 262359 | E22: 295153 | F22: 204650 | G22: =E22-D22 -> 32794
B23: =B22+1 -> 19 | C23: 45615 | D23: =E22 -> 295153 | E23: 274290 | F23: 204650 | G23: =E23-D23 -> -20863
B24: =B23+1 -> 20 | C24: 45616 | D24: =E23 -> 274290 | E24: 235465 | F24: =259103-20000 -> 239103 | G24: =E24-D24 -> -38825
B25: =B24+1 -> 21 | C25: 45617 | D25: =E24 -> 235465 | E25: 275615 | F25: =222878+20000 -> 242878 | G25: =E25-D25 -> 40150
B26: =B25+1 -> 22 | C26: 45618 | D26: =E25 -> 275615 | E26: 179950 | F26: =222984+20500 -> 243484 | G26: =E26-D26 -> -95665
B27: =B26+1 -> 23 | C27: 45619 | D27: =E26 -> 179950 | E27: 0 | F27: 219216 | G27: =E27-D27 -> -179950
B28: =B27+1 -> 24 | C28: 45620 | D28: =E27 -> 0 | E28: 0 | F28: 244970 | G28: =E28-D28 -> 0
B29: =B28+1 -> 25 | C29: 45621 | D29: =E28 -> 0 | E29: 0 | F29: =209886+25000 -> 234886 | G29: =E29-D29 -> 0
B30: =B29+1 -> 26 | C30: 45622 | D30: =E29 -> 0 | E30: 0 | F30: 0 | G30: =E30-D30 -> 0
B31: =B30+1 -> 27 | C31: 45623 | D31: =E30 -> 0 | E31: 0 | F31: 0 | G31: =E31-D31 -> 0
B32: =B31+1 -> 28 | C32: 45624 | D32: =E31 -> 0 | E32: 0 | F32: 0 | G32: =E32-D32 -> 0
B33: =B32+1 -> 29 | C33: 45625 | D33: =E32 -> 0 | E33: 0 | F33: 0 | G33: =E33-D33 -> 0
B34: =B33+1 -> 30 | C34: 45626 | D34: =E33 -> 0 | E34: 0 | F34: 0 | G34: =E34-D34 -> 0

Sheet OIP Fract
B2: Oil In Plant Fract
B4: No | C4: Tanggal | D4: Opening Stock | E4: Closing Stock | F4: Selisih OIP
B5: 1 | C5: 45597 | D5: 635650 | E5: 652190 | F5: =E5-D5 -> 16540
B6: =B5+1 -> 2 | C6: 45598 | D6: =E5 -> 652190 | E6: 630990 | F6: =E6-D6 -> -21200
B7: =B6+1 -> 3 | C7: 45599 | D7: =E6 -> 630990 | E7: 686700 | F7: =E7-D7 -> 55710
B8: =B7+1 -> 4 | C8: 45600 | D8: =E7 -> 686700 | E8: 612200 | F8: =E8-D8 -> -74500
B9: =B8+1 -> 5 | C9: 45601 | D9: =E8 -> 612200 | E9: 641660 | F9: =E9-D9 -> 29460
B10: =B9+1 -> 6 | C10: 45602 | D10: =E9 -> 641660 | E10: 640430 | F10: =E10-D10 -> -1230
B11: =B10+1 -> 7 | C11: 45603 | D11: =E10 -> 640430 | E11: 640290 | F11: =E11-D11 -> -140
B12: =B11+1 -> 8 | C12: 45604 | D12: =E11 -> 640290 | E12: 513970 | F12: =E12-D12 -> -126320
B13: =B12+1 -> 9 | C13: 45605 | D13: =E12 -> 513970 | E13: 590370 | F13: =E13-D13 -> 76400
B14: =B13+1 -> 10 | C14: 45606 | D14: =E13 -> 590370 | E14: 422220 | F14: =E14-D14 -> -168150
B15: =B14+1 -> 11 | C15: 45607 | D15: =E14 -> 422220 | E15: 332600 | F15: =E15-D15 -> -89620
B16: =B15+1 -> 12 | C16: 45608 | D16: =E15 -> 332600 | E16: 419490 | F16: =E16-D16 -> 86890
B17: =B16+1 -> 13 | C17: 45609 | D17: =E16 -> 419490 | E17: 432330 | F17: =E17-D17 -> 12840
... B34: =B33+1 -> 30 | C34: 45626 | D34: =E33 -> 0 | E34: 0 | F34: =E34-D34 -> 0

Sheet 2024
C2: PRODUCTION REPORT 2024
F3: ok | G3: ok | H3: ok | I3: ok | J3: OK | K3: OK | L3: ok | M3: ok | N3: ok
B4: No | C4: ITEM | D4: Budget / Norma | E4: UoM | F4: MONTHLY REPORT | S4: Yearly Report | T4: Yearly Report RKAP (Budget) | U4: Yearly Report RKAP
F5: JANUARI | G5: FEBRUARI | H5: MARET | I5: APRIL | J5: MEI | K5: JUNI | L5: JULI | M5: AGUSTUS | N5: SEPTEMBER | O5: OKTOBER | P5: NOVEMBER | Q5: DESEMBER | S5: TOTAL (Kg) | T5: TOTAL (Kg) | U5: TOTAL (%)
B6: 1 | C6: PRODUCTION | S6: Production | T6: Production | U6: Production | DF6: 29 | DG6: 30 | DH6: 31
C7: Refinery | S7: Refinery | T7: Refinery | U7: Refinery | DD7: CPO Olah | DE7: Kg | DF7: 1971320 | DG7: 2015120 | DH7: 2015230 | AIT7: Sounding | AIU7: Production | AIV7: Diff
C8: Running Days | E8: Day | F8: 18 | G8: 11 | H8: 27 | I8: 22 | J8: 27 | K8: 18 | L8: 22 | M8: 28 | N8: 27 | O8: 28 | P8: ='November 2024'!AL6 -> 22 | Q8: ='[24]Desember 24'!AL9 -> 0 | S8: =SUM(F8:Q8) -> 250 | T8: 231 | U8: =S8/T8*100 -> 108.22511 | OQ8: Poram | AED8: 14 Juni | AEE8: 15 Juni | AIS8: CPO | AIT8: 11008948 | AIU8: =S11 -> 180889691 | AIV8: =AIT8-AIU8 -> -169880743
C9: Ratio Run CPO | F9: 17.46 | G9: ='[24]Februari 24'!AL10 -> 17.224767 | H9: ='[24]Maret 24'!AL10 -> 4.5497713 | I9: ='[25]April - 24'!$AK$11 -> 0 | J9: ='[26]Mei - 24'!$AL$11 -> 0 | K9: ='[27]Juni - 24'!$AL$11 -> 13.078035 | L9: ='[28]Juli - 2024 ( Revisi )'!$AL$8 -> 23.454544 | M9: ='[29]Agustus - 2024'!$AN$8 -> 33.834848 | N9: ='[30]September - 2024'!$AM$8 -> 40.48197 | O9: ='[31]Oktober- 2024'!$AM$8 -> 37.300669 | P9: ='November 2024'!AL8 -> 42.102025 | Q9: ='[24]Desember 24'!AL10 -> 0
C10: Utilitas CPO | F10: =F11/F14*100 -> 18.288923 | G10: =G11/G14*100 -> 18.044994 | H10: =H11/H14*100 -> 43.450394 | I10: =I11/I14*100 -> 24.340125 | J10: =J11/J14*100 -> 42.665478 | K10: =K11/K14*100 -> 24.530983 | L10: =L11/L14*100 -> 43.994607 | M10: =M11/M14*100 -> 63.465348 | ... Q10: =Q11/Q14*100 -> #DIV/0! | S10: =AVERAGE(F10:P10) -> 42.320696
C11: CPO Consume Total | D11: 701400000 | E11: Kg | F11: 11906089 | G11: 11747291 | H11: 16983890 | I11: 8849826 | J11: 15512741 | K11: 8919220 | L11: 15995999 | M11: 23075366 | N11: 24046290 | O11: 23475599 | P11: ='November 2024'!AL9 -> 20377380 | Q11: ='[24]Desember 24'!AL11 -> 0 | S11: =SUM(F11:P11) -> 180889691 | T11: 421374000 | U11: =S11/T11 -> 0.42928536 | AW11: =S11/D11 -> 0.25789805 | DD11: HP Boiler | DE11: mmbtu | DF11: 251.19642 | DG11: 257.91391 | DH11: 251.51265 | ON11: 26946.108 | OO11: 17383.234 | OQ11: RBDPO Olah | AED11: =35.8500000000058*1000 -> 35850 | AIS11: PFAD | AIT11: 566885 | AIU11: =S20 -> 7877801 | AIV11: =AIT11-AIU11 -> -7310916
C12: CPO Consume Poram | E12: Kg | F12: 10284033 | G12: 10885811 | H12: 16067553 | I12: 8849826 | J12: 15512741 | K12: 8919220 | L12: 15995999 | M12: 22890671 | N12: =N11-N13 -> 24046290 | O12: 23419757 | P12: ='November 2024'!AL9 -> 20377380 | Q12: ='[24]Desember 24'!AL12 -> #DIV/0! | S12: =SUM(F12:P12) -> 1.7724928e+08
C13: CPO Consume Brand | E13: Kg | F13: 1622056.5 | G13: 861480.39 | H13: 916336.51 | I13: 0 | J13: 0 | K13: 0 | L13: 0 | M13: 184695 | N13: 0 | O13: 55842.105 | P13: 0 | Q13: ='[24]Desember 24'!AL13 -> #DIV/0! | S13: =SUM(F13:P13) -> 3640410.5 | AW13: =AV13/P13 -> #DIV/0!
C14: Budget CPO Olah | E14: Kg | F14: 65100000 | G14: 65100000 | H14: 39088000 | I14: 36359000 | J14: 36359000 | K14: 36359000 | L14: 36359000 | M14: 36359000 | N14: 36359000 | O14: ='[31]Oktober- 2024'!$E$9 -> 36359000 | P14: ='November 2024'!E9 -> 36359000 | S14: =SUM(F14:P14) -> 460160000
C15: - FFA | D15: 5 | E15: % | F15: 4.38 | G15: 4.5590909 | H15: 4.135 | I15: 4.11 | J15: 3.859375 | K15: 4.248125 | L15: 3.8848485 | M15: 3.9614881 | N15: 3.6441975 | O15: ='[31]Oktober- 2024'!$AM$13 -> 3.7106548 | P15: ='November 2024'!AL13 -> 3.8712121 | Q15: ='[24]Desember 24'!AL14 -> #DIV/0! | S15: =AVERAGE(F15:P15) -> 4.0330902 | T15: =AVERAGE(G15:R15) -> #DIV/0! | U15: =AVERAGE(H15:S15) -> #DIV/0! | DD15: Steam Ref | DE15: Kg | DF15: 182230 | DG15: 190070 | DH15: 197800 | ON15: =S11/1000 -> 180889.69 | OO15: =(S25+S48+S34)/1000 -> 53829.832 | OQ15: =SUM(OQ16:OQ17) -> #REF! | AGU15: 2000
C16: - Moist & Impurities | D16: 0.5 | E16: % | F16: 0.42 | G16: 0.43545455 | H16: 0.42375 | I16: 0.42 | J16: 0.431875 | K16: 0.45375 | L16: 0.41795455 | M16: 0.43083333 | N16: 0.41401235 | O16: ='[31]Oktober- 2024'!$AM$14 -> 0.37321429 | P16: ='November 2024'!AL14 -> 0.43416667 | Q16: ='[24]Desember 24'!AL15 -> #DIV/0! | S16: =AVERAGE(F16:P16) -> 0.42318279 | T16: =AVERAGE(G16:R16) -> #DIV/0! | U16: =AVERAGE(H16:S16) -> #DIV/0! | DE16: Kg/MT | DF16: =DF15/(DF7/1000) -> 92.440598 | DG16: =DG15/(DG7/1000) -> 94.321926 | DH16: =DH15/(DH7/1000) -> 98.152568 | OQ16: =#REF!/1000 -> #REF! | OR16: =OQ16/OQ15*100 -> #REF! | AGT16: 0.942 | AGU16: =AGT16*AGU15 -> 1884 | AGV16: Refinery | AIS16: Olein IV 56 | AIT16: 9594130 | AIU16: =S26 -> 41876768 | AIV16: =AIT16-AIU16 -> -32282638
C17: - DOBI | D17: 2,20 Min | E17: % | F17: 2.21 | G17: 2.2127273 | H17: 2.2104167 | I17: 2.21 | J17: 2.21 | K17: 2.21 | L17: 2.1131818 | M17: 2.2129286 | N17: 2.27 | O17: ='[31]Oktober- 2024'!$AM$15 -> 19.65575 | P17: ='November 2024'!AL15 -> 2.015 | Q17: ='[24]Desember 24'!AL16 -> #DIV/0! | S17: =AVERAGE(F17:P17) -> 3.7754549 | T17: =AVERAGE(G17:R17) -> #DIV/0! | U17: =AVERAGE(H17:S17) -> #DIV/0! | ON17: =SUM(ON15:ON16) -> 180889.69 | OO17: =SUM(OO15:OO16) -> 53829.832 | OQ17: =#REF!/1000 -> #REF! | OR17: =OQ17/OQ15*100 -> #REF! | AGT17: 0.05 | AGU17: =AGT17*AGU15 -> 100 | AIS17: Stearin | AIT17: 2161151 | AIU17: =S27 -> 8544076 | AIV17: =AIT17-AIU17 -> -6382925
C18: Product | S18: Product | T18: Product | U18: Product | ON18: =ON17/ON11*100 -> 671.30174 | OO18: =OO17/OO11*100 -> 309.66524 | AEF18: Product OIP | AEP18: Juni | AEQ18: Sisa Product OIP
C19: RbdPO | D19: =D56%*D11 -> 660718800 | E19: Kg | F19: 11255730 | G19: 11075536 | H19: 16117978 | I19: 8393524 | J19: 14773343 | K19: 8432668 | L19: 14396709 | M19: 22151806 | N19: 22783491 | O19: 22361608 | P19: ='November 2024'!AL18 -> 19958156 | Q19: ='[24]Desember 24'!AL18 -> 0 | S19: =SUM(F19:P19) -> 1.7170055e+08 | T19: 399336000 | U19: =S19/T19*100 -> 42.996512 | Y19: =S19/11 -> 15609141 | Z19: RBDPO | AW19: =AW20/D19 -> 0.26115599 | DD19: Tahun 2021 | AED19: 136360 | AEE19: 109340 | AEF19: =SUM(AED19:AEE19) -> 245700 | AEP19: 34157.88 | AEQ19: =AEF19-AEP19 -> 211542.12 | AGU19: =AGU16 -> 1884
C20: PFAD | D20: =D57%*D11 -> 35070000 | E20: Kg | F20: 568791 | G20: 594383 | H20: 753150 | I20: 419494 | J20: 630157 | K20: 432588 | L20: 713632 | M20: 947460 | N20: 998518 | O20: 949170 | P20: ='November 2024'!AL19 -> 870458 | Q20: ='[24]Desember 24'!AL19 -> 0 | S20: =SUM(F20:P20) -> 7877801 | T20: 19024000 | U20: =S20/T20*100 -> 41.409803 | Y20: =S20/11 -> 716163.73 | Z20: PFAD | AW20: =S25+S29+S34+S48+S38 -> 172550675 | DD20: Items | DF20: Agustus | DG20: Oktober | ON20: =ON11-ON17 -> -153943.58 | OO20: =OO11-OO17 -> -36446.598 | OQ20: Olein IV 58 | OR20: 0 | PD20: 564.70507 | PE20: =OR20/PD20*100 -> 0 | AED20: 13800 | AEE20: 2800 | AEF20: =SUM(AED20:AEE20) -> 16600 | AEP20: 1469.85 | AEQ20: =AEF20-AEP20 -> 15130.15 | AGT20: 0.75 | AGU20: =AGT20*AGU19 -> 1413
C21: Fractionation
C22: Total Filling Crystalizer ( Feed ) | D22: =399289.3*1000 -> 399289300 | E22: Kg | F22: =F23 -> 13630524 | G22: =G23 -> 8090413 | H22: =H23 -> 16273198 | I22: =I23 -> 9676196 | J22: =J23 -> 14816948 | K22: =K23 -> 7764784 | L22: =L23 -> 11846463 | M22: =M23 -> 24206356 | N22: 22592969 | O22: 20122000 | P22: ='November 2024'!AL23 -> 21737836 | S22: =SUM(F22:P22) -> 170757687
C23: Total Proses RBDPO | E23: Kg | F23: =SUM(F25,F29,F34,F38,F48) -> 13630524 | G23: =SUM(G25,G29,G34,G38,G48) -> 8090413 | H23: =SUM(H25,H29,H34,H38,H48) -> 16273198 | I23: =SUM(I25,I29,I34,I38,I48) -> 9676196 | J23: =SUM(J25,J29,J34,J38,J48) -> 14816948 | K23: =SUM(K25,K29,K34,K38,K48) -> 7764784 | L23: =SUM(L25,L29,L34,L38,L48) -> 11846463 | M23: =SUM(M25,M29,M34,M38,M48) -> 24206356 | N23: =SUM(N25,N29,N34,N38,N48) -> 23189025 | O23: ='[31]Oktober- 2024'!$AM$25 -> 18946789 | P23: ='November 2024'!AL25 -> 22537659 | S23: =SUM(F23:P23) -> 170978355
C24: Fractionation OLEIN IV 56 | S24: Olein IV 56 | T24: Olein IV 56 | U24: Olein IV 56 | DF24: 24 | DG24: 2 | DH24: 3 | OQ24: Olein IV 60 | OR24: =80.53776+PE34 -> 120.78492 | PD24: 4695.7554 | PE24: =OR24/PD24*100 -> 2.5722149 | AGT24: 0.25 | AGU24: =AGT24*AGU19 -> 471
C25: RBDPO Consume | D25: =SUM(D26:D27) -> 0 | E25: Kg | F25: 2379082 | G25: 50570 | H25: 1699905 | I25: ='[24]April 24'!AL21 -> 0 | J25: 0 | K25: 0 | L25: 160400 | M25: 14223412 | N25: 16566545 | O25: 9370708 | P25: ='November 2024'!AL28 -> 5970222 | Q25: =Q26+Q27 -> 0 | S25: =S26+S27 -> 50420844 | T25: =T26+T27 -> 87311000 | U25: =S25/T25*100 -> 57.748559 | DD25: CPO Olah | DE25: Kg | DF25: 2000530 | DG25: 2005167 | DH25: 2025879 | AED25: =95.28%*AED11 -> 34157.88 | AEF25: =AED19-AEP19 -> 102202.12 | AIP25: CPO Feed - Sounding
C26: OLEIN IV 56 | E26: Kg | F26: 1982807 | G26: 42320 | H26: 1394887 | I26: ='[24]April 24'!AL22 -> 0 | J26: 0 | K26: 0 | L26: 135300 | M26: 11670227 | N26: 13789795 | O26: 7870678 | P26: ='November 2024'!AL29 -> 4990754 | Q26: ='[24]Desember 24'!AL22 -> 0 | S26: =SUM(F26:P26) -> 41876768 | T26: 71627000 | U26: =S26/T26*100 -> 58.465059 | DD26: HP Boiler | DE26: mmbtu | DF26: 255.53619 | DG26: 255.09239 | DH26: 260.82455 | ON26: =#REF!/1000 -> #REF! | OQ26: INL 900 ml | OR26: 0 | PD26: 9.75348 | PE26: =(OR26*PD26)/1000 -> 0 | AED26: =4.1%*AED11 -> 1469.85 | AEF26: =AED20-AEP20 -> 12330.15
C27: STEARIN | E27: Kg | F27: 396275 | G27: 8250 | H27: 305018 | I27: ='[24]April 24'!AL23 -> 0 | J27: 0 | K27: 0 | L27: 25100 | M27: 2553185 | N27: 2776750 | O27: 1500030 | P27: ='November 2024'!AL30 -> 979468 | Q27: ='[24]Desember 24'!AL23 -> 0 | S27: =SUM(F27:P27) -> 8544076 | T27: 15684000 | U27: =S27/T27*100 -> 54.476384 | DD27: Steam Ref | DE27: Kg | DF27: 146000 | DG27: 151100 | DH27: 152900 | ON27: 1796 | OQ27: Salvaco 1L | OR27: 1262 | PD27: 10.86 | PE27: =(OR27*PD27)/1000 -> 13.70532 | AIP27: Report Prod
C28: Fractionation OLEIN IV 57 ( Bulk ) | S28: Olein IV 57 ( Bulk ) | T28: Olein IV 57 ( Bulk ) | U28: Olein IV 57 ( Bulk )
C29: RBDPO Consume | E29: Kg | F29: 2827867 | G29: 0 | H29: 0 | I29: 60502 | J29: 0 | K29: 0 | L29: 0 | M29: 0 | N29: 0 | O29: ='[31]Oktober- 2024'!$AM$32 -> 0 | P29: ='November 2024'!AL32 -> 0 | Q29: =Q30+Q31 -> 0 | S29: =S30+S31 -> 2888369 | T29: =T30+T31 -> 5121000 | U29: =S29/T29*100 -> 56.402441 | W29: =S26+S30+S35+S39+S50 -> 129064029 | Y29: =W29/11 -> 11733094 | Z29: Olein | AW29: =S29+S34 -> 4098296
C30: OLEIN IV 57 | E30: Kg | F30: 2230587 | G30: 0 | H30: 0 | I30: 45478 | J30: 0 | K30: 0 | L30: 0 | M30: 0 | N30: 0 | O30: ='[31]Oktober- 2024'!$AM$33 -> 0 | P30: ='November 2024'!AL33 -> 0 | Q30: ='[24]Desember 24'!AL26 -> 0 | S30: =SUM(F30:P30) -> 2276065 | T30: 3934000 | U30: =S30/T30*100 -> 57.856253 | AW30: =S30+S35 -> 3177959
C31: STEARIN | E31: Kg | F31: 597280 | G31: 0 | H31: 0 | I31: 15024 | J31: 0 | K31: 0 | L31: 0 | M31: 0 | N31: 0 | O31: ='[31]Oktober- 2024'!$AM$34 -> 0 | P31: ='November 2024'!AL34 -> 0 | Q31: ='[24]Desember 24'!AL27 -> 0 | S31: =SUM(F31:P31) -> 612304 | T31: 1187000 | U31: =S31/T31*100 -> 51.584162 | W31: =S27+S31+S36+S40+S51 -> 43486646 | Y31: =W31/11 -> 3953331.5 | Z31: stearin | AW31: =S31+S36 -> 920337
C32: Fractionation OLEIN IV 57 ( Retail ) | S32: Olein IV 57 ( Retail ) | T32: Olein IV 57 ( Retail ) | U32: Olein IV 57 ( Retail ) | DE32: Kg/MT | DF32: =DF27/(DF25/1000) -> 72.98066 | DG32: =DG27/(DG25/1000) -> 75.35532 | DH32: =DH27/(DH25/1000) -> 75.473412 | ON32: =ON26/ON27*100 -> #REF! | OQ32: Salvaco 2L | OR32: 2444 | PD32: 10.86 | PE32: =(OR32*PD32)/1000 -> 26.54184 | AIP32: Diff
C33: CPO Consume | E33: Kg | F33: 0 | G33: 440053.75 | H33: 793075.77 | I33: ='[24]April 24'!AL29 -> 0 | J33: 0 | K33: 0 | L33: 0 | M33: 0 | N33: 0 | O33: ='[31]Oktober- 2024'!$AM$36 -> 0 | P33: ='November 2024'!AL36 -> 0 | Q33: ='[24]Desember 24'!AL29 -> 0 | S33: =SUM(F33:P33) -> 1233129.5 | T33: =T34/T56% -> 32338304 | U33: =(S33/T33)*100 -> 3.8132164 | DE33: Kg/MT | DF33: =DF27/(DF20/1000) -> #VALUE! | DG33: =DH27/(DG20/1000) -> #VALUE! | DH33: =#REF!/(DH20/1000) -> #REF!
C34: RBDPO Brand Consume | D34: =SUM(D35:D36) -> 0 | E34: Kg | F34: 0 | G34: 417044 | H34: 751933 | I34: =I35+I36 -> 0 | J34: 0 | K34: 0 | L34: 0 | M34: 0 | N34: 40950 | O34: ='[31]Oktober- 2024'!$AM$37 -> 0 | P34: ='November 2024'!AL37 -> 0 | Q34: =Q35+Q36 -> 0 | S34: =S35+S36 -> 1209927 | T34: =T35+T36 -> 30647000 | U34: =(S34/T34)*100 -> 3.947946 | PE34: =SUM(PE27:PE32) -> 40.24716
C35: OLEIN IV 57 ( Retail ) | E35: Kg | F35: 0 | G35: 327115 | H35: 543979 | I35: ='[24]April 24'!AL31 -> 0 | J35: 0 | K35: 0 | L35: 0 | M35: 0 | N35: 30800 | O35: ='[31]Oktober- 2024'!$AM$38 -> 0 | P35: ='November 2024'!AL38 -> 0 | Q35: ='[24]Desember 24'!AL31 -> 0 | S35: =SUM(F35:P35) -> 901894 | T35: 23002000 | U35: =S35/T35*100 -> 3.9209373
C36: STEARIN | E36: Kg | F36: 0 | G36: 89929 | H36: 207954 | I36: ='[24]April 24'!AL32 -> 0 | J36: 0 | K36: 0 | L36: 0 | M36: 0 | N36: 10150 | O36: ='[31]Oktober- 2024'!$AM$39 -> 0 | P36: ='November 2024'!AL39 -> 0 | Q36: ='[24]Desember 24'!AL32 -> 0 | S36: =SUM(F36:P36) -> 308033 | T36: 7645000 | U36: =S36/T36*100 -> 4.0292086
C37: Fractionation OLEIN IV 58 ( BULK ) | S37: Olein IV 58 | T37: Olein IV 58 | U37: Olein IV 58
C38: RBDPO Consume | E38: Kg | F38: 6885934 | G38: 7224129 | H38: 13704210 | I38: 9615694 | J38: 14816948 | K38: 7764784 | L38: 11686063 | M38: 9837344 | N38: 6581530 | O38: 10628161 | P38: ='November 2024'!AL41 -> 16567437 | Q38: =Q39+Q40 -> 0 | S38: =S39+S40 -> 115832474 | T38: =T39+T40 -> 249961000 | U38: =S38/T38*100 -> 46.340219
C39: OLEIN IV 58 ( Bulk ) | E39: Kg | F39: 4847146 | G39: 5178274 | H39: 8651956 | I39: 6783108 | J39: 10840932 | K39: 5498655 | L39: 8627479 | M39: 6991936 | N39: 4788598 | O39: 7897790 | P39: ='November 2024'!AL42 -> 12573252 | Q39: ='[24]Desember 24'!AL35 -> 0 | S39: =SUM(F39:P39) -> 82679126 | T39: 175000000 | U39: =S39/T39*100 -> 47.245215
C40: STEARIN | E40: Kg | F40: 2038788 | G40: 2045855 | H40: 5052254 | I40: 2832586 | J40: 3976016 | K40: 2266129 | L40: 3578824 | M40: 2845408 | N40: 1792932 | O40: 2730371 | P40: ='November 2024'!AL43 -> 3994185 | Q40: ='[24]Desember 24'!AL36 -> 0 | S40: =SUM(F40:P40) -> 33153348 | T40: 74961000 | U40: =S40/T40*100 -> 44.227462
C41: Fractionation OLEIN IV 58 ( Retail )
...

Sheet Downtime Ref Nov
F2: DOWN TIME SLOW FLOWRATE PRODUCTION REFINERY
F4: Periode 01 s/d 30 November 2024
F5: TANGGAL | G5: CAPACITY (Kg) | H5: REMARKS | I5: Down time | M5: Tph
I6: Stop | J6: Slow | K6: % | AE6: 17 | AF6: 18 | AG6: 19 | AH6: 20 | AI6: 21 | AJ6: 22 | AK6: 23 | AL6: 24 | AM6: 25 | AN6: 26 | AO6: 27 | AP6: 28 | AQ6: 29 | AR6: 30 | AS6: 31
F7: 1 | G7: 859587 | H7: Penyesuaian incoming CPO | J7: =(2200-(G7/1000))/91.7 -> 14.617372 | K7: =G7/2200/1000 -> 0.39072136 | M7: =(G7/1000)/24 -> 35.816125 | O7: =249.262+270.9 -> 520.162 | P7: =1356.367+39.742 -> 1396.109 | Q7: =1086.521+50.6 -> 1137.121 | R7: =1353.558+373.309 -> 1726.867 | S7: 1942.746 | T7: 1868.212 | U7: 2057.011 | V7: 1781.844 | W7: 1250.764 | X7: 1613.486 | Y7: 1325.077 | Z7: =66.442+571.568 -> 638.01 | AA7: =815.429 -> 815.429 | AB7: =352.234+731.627 -> 1083.861 | AC7: =1626.002+13.213 -> 1639.215 | AD7: 2094.791 | AE7: 2075.375 | AF7: 2008.804 | AG7: 1946.712 | AH7: 1998.939 | AI7: =1623.839+281.468 -> 1905.307 | AJ7: 1610.024 | AK7: =1135.181+98.368 -> 1233.549 | AL7: =958.893+543.852 -> 1502.745 | AM7: 2043.15 | AN7: 1762.642 | AO7: 2170.336 | AP7: =1181.38+463.711 -> 1645.091 | AQ7: 219.474 | AR7: =48.153+1225.968+107.3 -> 1381.421
F8: 2 | G8: 537300 | H8: Penyesuaian incoming CPO | J8: =(2200-(G8/1000))/91.7 -> 18.131952 | K8: =G8/2200/1000 -> 0.24422727 | M8: =(G8/1000)/24 -> 22.3875
F9: 3 | G9: 736801 | H9: Penyesuaian incoming CPO | J9: =(2200-(G9/1000))/91.7 -> 15.956369 | K9: =G9/2200/1000 -> 0.33490955 | M9: =(G9/1000)/24 -> 30.700042
F10: 4 | G10: 894589 | H10: Penyesuaian incoming CPO | J10: =(2200-(G10/1000))/91.7 -> 14.235671 | K10: =G10/2200/1000 -> 0.40663136 | M10: =(G10/1000)/24 -> 37.274542
F11: 5 | G11: 900604 | H11: Penyesuaian incoming CPO | J11: =(2200-(G11/1000))/91.7 -> 14.170076 | K11: =G11/2000/1000 -> 0.450302 | M11: =(G11/1000)/24 -> 37.525167
F12: 6 | G12: 846175 | H12: Penyesuaian incoming CPO | J12: =(2200-(G12/1000))/91.7 -> 14.763631 | K12: =G12/2200/1000 -> 0.384625 | M12: =(G12/1000)/24 -> 35.257292
F13: 7 | G13: 753834 | H13: Penyesuaian incoming CPO | J13: =(2200-(G13/1000))/91.7 -> 15.770622 | K13: =G13/2200/1000 -> 0.34265182 | M13: =(G13/1000)/24 -> 31.40975
F14: 8 | G14: 696743 | H14: Penyesuaian incoming CPO | J14: =(2200-(G14/1000))/91.7 -> 16.393206 | K14: =G14/2200/1000 -> 0.31670136 | M14: =(G14/1000)/24 -> 29.030958
F15: 9 | G15: 828594 | H15: Penyesuaian incoming CPO | J15: =(2200-(G15/1000))/91.7 -> 14.955354 | K15: =G15/2200/1000 -> 0.37663364 | M15: =(G15/1000)/24 -> 34.52475
F16: 10 | G16: 1003650 | H16: Penyesuaian incoming CPO | J16: =(2200-(G16/1000))/91.7 -> 13.046347 | K16: =G16/2200/1000 -> 0.45620455 | M16: =(G16/1000)/24 -> 41.81875
F17: 11 | G17: 1000809 | H17: Penyesuaian incoming CPO | J17: =(2200-(G17/1000))/91.7 -> 13.077328 | K17: =G17/2200/1000 -> 0.45491318 | M17: =(G17/1000)/24 -> 41.700375
F18: 12 | G18: 925598 | H18: Penyesuaian incoming CPO | J18: =(2200-(G18/1000))/91.7 -> 13.897514 | K18: =G18/2200/1000 -> 0.42072636 | M18: =(G18/1000)/24 -> 38.566583
F19: 13 | G19: 803666 | H19: Penyesuaian incoming CPO | J19: =(2200-(G19/1000))/91.7 -> 15.227197 | K19: =G19/2200/1000 -> 0.36530273 | M19: =(G19/1000)/24 -> 33.486083
F20: 14 | G20: 1009988 | H20: Penyesuaian incoming CPO | J20: =(2200-(G20/1000))/91.7 -> 12.97723 | K20: =G20/2200/1000 -> 0.45908545 | M20: =(G20/1000)/24 -> 42.082833
F21: 15 | G21: 1042124 | H21: Penyesuaian incoming CPO | J21: =(2200-(G21/1000))/91.7 -> 12.626783 | K21: =G21/2200/1000 -> 0.47369273 | M21: =(G21/1000)/24 -> 43.421833
F22: 16 | G22: 991679 | H22: Penyesuaian incoming CPO | J22: =(2200-(G22/1000))/91.7 -> 13.176892 | K22: =G22/2200/1000 -> 0.45076318 | M22: =(G22/1000)/24 -> 41.319958
F23: 17 | G23: 633826 | H23: Penyesuaian incoming CPO | J23: =(2200-(G23/1000))/91.7 -> 17.079324 | K23: =G23/2200/1000 -> 0.28810273 | M23: =(G23/1000)/24 -> 26.409417
... F36: 30 | G36: 0 | H36: SHUT DOWN | J36: =(2200-(G36/1000))/91.7 -> 23.991276 | K36: =G36/2200/1000 -> 0 | M36: =(G36/1000)/24 -> 0
F37: TOTAL | G37: =SUM(G7:G36) -> 20377380 | I37: =SUM(I7:I36) -> 0 | J37: =SUM(J7:J36) -> 497.52039 | M37: =AVERAGE(M7:M36) -> 28.301917
G39: Summary
G40: 1. Slow flow rate due to Space Tank High | I40: 0 | J40: hours
G41: 2. Slow flow rate due to Olein IV 60 process | I41: 0 | J41: hours
G42: 3. Hold plant due to trip MP boiler & maintenance | I42: 0 | J42: hours
G43: 4. Penyesuaian incoming CPO | I43: =SUM(J7,J8,J9,J10,J11,J12,J13,J14,J15,J16,J17,J18,J19,J20,J21,J22,J23,J24,J25,J26,J27,J28) -> 305.59019 | J43: hours
G44: 5. Downtime due to Start Up Plant | J44: hours
G45: 6. Running Normal Plant | I45: 0 | J45: hours
G46: 7. Stop Plant due to Preventive Maintenance Plant | I46: 0 | J46: hours
G47: 8. Energizing PMG II | I47: 0 | J47: hours
G48: 9. Zero Suplay Gas (Problem Pertagas) | I48: 0 | J48: hours
G49: 10, Stop Plant | I49: =SUM(J29,J30,J31,J32,J33,J34,J35,J36) -> 191.93021 | J49: hours
G50: 11.HOLD CPO Shortage | J50: hours
G51: Total | I51: =SUM(I40:I50) -> 497.52039 | J51: hours
G52: Note : Kapasitas 2200 TPD
E62: Prepared by, | H62: Checked by, | J62: Approved by,
E66: Bany Subana | H66: Reza P. Panjaitan | J66: Sudarianto
E67: Admin. Process | H67: Supervisor Produksi | J67: Jr. Manager Produksi

Sheet Downtime Fract Oktober
F2: DOWN TIME SLOW FLOWRATE PRODUCTION FRACTIONATION
F4: Periode 01 s/d 30 November 2024
F5: TANGGAL | G5: CAPACITY (Kg) | H5: REMARKS | I5: Down time | M5: Tph
I6: Stop | J6: Slow | K6: % | AE6: 17 | AF6: 18 | AG6: 19 | AH6: 20 | AI6: 21 | AJ6: 22 | AK6: 23 | AL6: 24 | AM6: 25 | AN6: 26 | AO6: 27 | AP6: 28 | AQ6: 29 | AR6: 30 | AS6: 31
F7: 1 | G7: 994298 | H7: Slow flow rate due to Olein IV 58 process | J7: =(2000-(G7/1000))/83.33 -> 12.068907 | K7: =G7/2000/1000 -> 0.497149 | M7: =(G7/1000)/24 -> 41.429083 | O7: =249.262+270.9 -> 520.162 | P7: =1356.367+39.742 -> 1396.109 | Q7: =1086.521+50.6 -> 1137.121 | R7: =1353.558+373.309 -> 1726.867 | S7: 1942.746 | T7: 1868.212 | U7: 2057.011 | V7: 1781.844 | W7: 1250.764 | X7: 1613.486 | Y7: 1325.077 | Z7: =66.442+571.568 -> 638.01 | AA7: =815.429 -> 815.429 | AB7: =352.234+731.627 -> 1083.861 | AC7: =1626.002+13.213 -> 1639.215 | AD7: 2094.791 | AE7: 2075.375 | AF7: 2008.804 | AG7: 1946.712 | AH7: 1998.939 | AI7: =1623.839+281.468 -> 1905.307 | AJ7: 1610.024 | AK7: =1135.181+98.368 -> 1233.549 | AL7: =958.893+543.852 -> 1502.745 | AM7: 2043.15 | AN7: 1762.642 | AO7: 2170.336 | AP7: =1181.38+463.711 -> 1645.091 | AQ7: 219.474 | AR7: =48.153+1225.968+107.3 -> 1381.421
F8: 2 | G8: 1115291 | H8: Slow flow rate due to Olein IV 58 process | J8: =(2000-(G8/1000))/83.33 -> 10.616933 | K8: =G8/2000/1000 -> 0.5576455 | M8: =(G8/1000)/24 -> 46.470458
F9: 3 | G9: 1038010 | H9: Slow flow rate due to Olein IV 58 process | J9: =(2000-(G9/1000))/83.33 -> 11.544342 | K9: =G9/2000/1000 -> 0.519005 | M9: =(G9/1000)/24 -> 43.250417
F10: 4 | G10: 1058141 | H10: Slow flow rate due to Olein IV 58 process | J10: =(2000-(G10/1000))/83.33 -> 11.30276 | K10: =G10/2000/1000 -> 0.5290705 | M10: =(G10/1000)/24 -> 44.089208
F11: 5 | G11: 899356 | H11: Slow flow rate due to Olein IV 58 process | J11: =(2000-(G11/1000))/83.33 -> 13.208256 | K11: =G11/2000/1000 -> 0.449678 | M11: =(G11/1000)/24 -> 37.473167
F12: 6 | G12: 939422 | H12: Slow flow rate due to Olein IV 58 process | J12: =(2000-(G12/1000))/83.33 -> 12.727445 | K12: =G12/2000/1000 -> 0.469711 | M12: =(G12/1000)/24 -> 39.142583
F13: 7 | G13: 1003337 | H13: Slow flow rate due to Olein IV 58 process | J13: =(2000-(G13/1000))/83.33 -> 11.960434 | K13: =G13/2000/1000 -> 0.5016685 | M13: =(G13/1000)/24 -> 41.805708
F14: 8 | G14: 899475 | H14: Slow flow rate due to Olein IV 58 process | J14: =(2000-(G14/1000))/83.33 -> 13.206828 | K14: =G14/2000/1000 -> 0.4497375 | M14: =(G14/1000)/24 -> 37.478125
F15: 9 | G15: 923368 | H15: Slow flow rate due to Olein IV 58 process | J15: =(2000-(G15/1000))/83.33 -> 12.920101 | K15: =G15/2000/1000 -> 0.461684 | M15: =(G15/1000)/24 -> 38.473667
F16: 10 | G16: 1178496 | H16: Slow flow rate due to Olein IV 56 process & IV 58 process | J16: =(2000-(G16/1000))/83.33 -> 9.8584423 | K16: =G16/2000/1000 -> 0.589248 | M16: =(G16/1000)/24 -> 49.104
F17: 11 | G17: 1073268 | H17: Slow flow rate due to Olein IV 56 process | J17: =(2000-(G17/1000))/83.33 -> 11.121229 | K17: =G17/2000/1000 -> 0.536634 | M17: =(G17/1000)/24 -> 44.7195
F18: 12 | G18: 927936 | H18: Slow flow rate due to Olein IV 56 process | J18: =(2000-(G18/1000))/83.33 -> 12.865283 | K18: =G18/2000/1000 -> 0.463968 | M18: =(G18/1000)/24 -> 38.664
F19: 13 | G19: 732528 | H19: Slow flow rate due to Olein IV 56 process | J19: =(2000-(G19/1000))/83.33 -> 15.210272 | K19: =G19/2000/1000 -> 0.366264 | M19: =(G19/1000)/24 -> 30.522
... F37: 31 | G37: 0 | H37: STOP PLANT | J37: =(2000-(G37/1000))/83.33 -> 24.00096 | K37: =G37/2000/1000 -> 0 | M37: =(G37/1000)/24 -> 0
F38: TOTAL | G38: =SUM(G7:G37) -> 22537679 | I38: =SUM(I7:I36) -> 0 | J38: =SUM(J7:J37) -> 473.56679 | M38: =AVERAGE(M7:M37) -> 30.292579
G40: Summary
G41: 1. Slow flow rate due to Space Tank High | I41: 0 | J41: hours
G42: 2. Slow flow rate due to Olein IV 60 process | I42: 0 | J42: hours
G43: 3. Slow flow rate due to Olein IV 57 process | I43: 0 | J43: hours
G44: 4. Slow Flow rate terkait material sortage & menyesuaikan | I44: 0 | J44: hours
G45: 5. Downtime due to Start/Stop Up Plant | I45: 0 | J45: hours
G46: 6. Running Normal Plant | I46: 0 | J46: hours
G47: 7. Stop Plant due to Preventive Maintenance Plant | I47: 0 | J47: hours
G48: 8. Energizing PMG II | I48: 0 | J48: hours
G49: 9. Zero Suplay Gas (Problem Pertagas) | I49: 0 | J49: hours
G50: 10. Slow flow rate due to Olein IV 58 process | I50: =SUM(J7,J8,J9,J10,J11,J12,J13,J14,J15,J22,J23,J24,J25,J26,J27,J28,J29) -> 217.20805 | J50: hours
G51: 11. STOP PLANT | I51: =SUM(J31,J32,J33,J34,J35,J36,J37) -> 168.00672 | J51: hours
G52: 12.Slow flow rate due to Olein IV 56 process | I52: =SUM(J17,J18,J19,J20) -> 51.423137 | J52: hours
G53: 13. Slow flow rate due to Olein IV 56 process & IV 57 process | I53: 0 | J53: hours
G54: 14. Slow flow rate due to Olein IV 56 process & IV 58 process | I54: =SUM(J16,J21,J30) -> 36.928885 | J54: hours
G55: Total | I55: =SUM(I41:I54) -> 473.56679 | J55: hours
G56: Note : Kapasitas 2000 TPD
E65: Prepared by, | H65: Checked by, | J65: Approved by,
E69: Bany Subana | H69: Reza P. Panjaitan | J69: Sudarianto
E70: Admin. Process | H70: Supervisor Produksi | J70: Jr. Manager Produksi

Sheet Prod
B2: MONTHLY PRODUCTION REPORT
B3: PT. INDUSTRI NABATI LESTARI
B4: Periode 01 s/d 30 November 2024
B5: NO | C5: Item | D5: Unit | E5: November | H5: Remaks
E6: Budget | F6: Actual | G6: Percentage Act.
B7: 1. | C7: PRODUCTION
C8: Refinery Plant
C9: Running Days | D9: Days | E9: 18 | F9: ='November 2024'!$AL$6 -> 22 | G9: =(F9/E9) -> 1.2222222 | H9: Tercapai
C10: CPO Incoming | D10: Kg
C11: Total CPO Consume | D11: Kg | E11: ='November 2024'!E9 -> 36359000 | F11: =F12+F13 -> 20377380 | G11: =(F11/E11) -> 0.56044941 | H11: Tidak Tercapai
C12: CPO Consume Poram | F12: ='November 2024'!AL11 -> 20377380
C13: CPO Consume Brand | F13: ='November 2024'!AL12 -> 0
C14: - Avg. FFA | D14: % | E14: 5 | F14: ='November 2024'!AL13 -> 3.8712121 | G14: =(F14/E14) -> 0.77424242
C15: - Avg. Moist & Impurities | D15: % | E15: 0.5 | F15: ='November 2024'!AL14 -> 0.43416667 | G15: =(F15/E15) -> 0.86833333
C16: - Avg. DOBI | D16: % | E16: 22.2 | F16: ='November 2024'!AL15 -> 2.015 | G16: =(F16/E16) -> 0.090765766
C17: Product
C18: RBDPO | D18: Kg | E18: 33124010 | F18: ='November 2024'!AL18 -> 19958156 | G18: =(F18/E18) -> 0.60252837
C19: PFAD | D19: Kg | E19: 1572840 | F19: ='November 2024'!$AL$19 -> 870458 | G19: =(F19/E19) -> 0.55343074
C21: Fraksinasi Plant
C22: Total Proses RBDPO | D22: Kg | E22: =E25+E38+E43 -> 31417000 | F22: ='November 2024'!$AL$25 -> 22537659 | G22: =(F22/E22) -> 0.71737145 | H22: Tidak Tercapai
C23: Total Olah RBDPO ( Feed ) | D23: Kg | E23: =E25+E38+E43 -> 31417000 | F23: ='November 2024'!$AL$23 -> 21737836 | G23: =(F23/E23) -> 0.69191317 | H23: Tidak Tercapai
C24: Fractionation Olein IV 56
C25: RBDPO Consume | D25: Kg | E25: 7883000 | F25: =F26+F27 -> 5970222 | G25: =(F25/E25) -> 0.75735405 | H25: Tercapai
C26: Olein IV 56 | D26: Kg | E26: 6464000 | F26: ='November 2024'!$AL$29 -> 4990754 | G26: =(F26/E26) -> 0.77208447 | H26: Tercapai
C27: Stearin | D27: Kg | E27: 1419000 | F27: ='November 2024'!$AL$30 -> 979468 | G27: =(F27/E27) -> 0.69025229 | H27: Tercapai
C28: Fractionation Olein IV 57 ( Bulk )
C29: RBDPO Consume | D29: Kg | E29: 0
C30: Olein IV 57 | D30: Kg | E30: 0 | F30: 0 | G30: 0
C31: Stearin | D31: Kg | E31: 0
C32: Fractionation Olein IV 57 ( Retail )
C33: CPO | D33: Kg | E33: 1812101.9 | G33: =(F33/E33)*100 -> 0
C34: RBDPO Consume | D34: Kg | E34: 1707000 | F34: =F35+F36 -> 0 | G34: =(F34/E34)*100 -> 0 | H34: Tidak Tercapai
C35: Olein IV 57 | D35: Kg | E35: 1280000 | G35: =(F35/E35)*100 -> 0 | H35: Tidak Tercapai
C36: Stearin | D36: Kg | E36: 427000 | G36: =(F36/E36)*100 -> 0 | H36: Tidak Tercapai
C37: Fractionation Olein IV 58
C38: RBDPO Consume | D38: Kg | E38: 21429000 | F38: =F39+F40 -> 16567437 | G38: =(F38/E38)*100 -> 77.31316 | H38: Tidak Tercapai
C39: Olein IV 58 | D39: Kg | E39: 15000000 | F39: ='November 2024'!$AL$42 -> 12573252 | G39: =(F39/E39)*100 -> 83.82168 | H39: Tidak Tercapai
C40: Stearin | D40: Kg | E40: 6429000 | F40: ='November 2024'!$AL$43 -> 3994185 | G40: =(F40/E40)*100 -> 62.127625 | H40: Tidak Tercapai
C41: Fractionation Olein IV 60
C42: CPO | E42: 2234607.2 | F42: 0 | G42: =(F42/E42)*100 -> 0
...

Sheet Utility
D2: UTILITY (GAS, STEAM, WATER & POWER) REPORT
D3: PT. INDUSTRI NABATI LESTARI
D5: Periode 01 s/d 30 November 2024
D6: No | E6: Item | F6: Norma | G6: UoM | H6: November | K6: Consume CPO ( MT ) | L6: Remaks
H7: Budget | I7: Actual | J7: Percentage Act.
E9: Total Feed Raw Material CPO | K9: 24046
D10: 1. | E10: GAS CONSUMPTION
E11: Incoming *base on INL | G11: mmbtu | I11: ='November 2024'!$AL$234 -> 30948.411
E12: Incoming *base on Pertagas | F12: 1460.001 | G12: mmbtu | H12: 26051.47 | I12: ='November 2024'!$AL$232 -> 28780.462 | J12: =I12/H12 -> 1.1047539 | K12: =I12/K9 -> 1.1968919
E13: Distribution to
E14: HP Boiler Refinery | G14: mmbtu | H14: 3907.73 | I14: ='November 2024'!$AL$236 -> 4004.6778 | J14: =I14/H14 -> 1.0248092 | K14: =I14/K9 -> 0.16654237
E15: MP Boiler | G15: mmbtu | H15: 22143.74 | I15: =I12-$I$14 -> 24775.784 | J15: =I15/H15 -> 1.1188618 | K15: =I15/K9 -> 1.0303495
E16: Total | G16: mmbtu | H16: 26051.47 | I16: =$I$12 -> 28780.462 | J16: =I16/H16 -> 1.1047539 | K16: =SUM(K14+K15) -> 1.1968919
D17: 2. | E17: STEAM CONSUMPTION
E18: Incoming | G18: Kg | H18: 11424000 | I18: ='November 2024'!$AL$241 -> 5582656 | J18: =I18/H18 -> 0.48867787 | K18: =I18/$K$9 -> 232.16568
E19: Distribution to | K19: =I19/$K$9 -> 0
E20: Refinery | F20: < 90 | G20: Kg | H20: 3420000 | I20: ='November 2024'!$AL$243 -> 3611900 | J20: =I20/H20 -> 1.0561111 | K20: =I20/$K$9 -> 150.20793
E21: Fractionation | F21: < 61 | G21: Kg | H21: 2318000 | I21: ='November 2024'!$AL$245 -> 1796900 | J21: =I21/H21 -> 0.77519413 | K21: =I21/$K$9 -> 74.727605
E22: Others | F22: 106000 | G22: Kg | H22: 5686000 | I22: ='November 2024'!$AL$247 -> 173856 | J22: =I22/H22 -> 0.030576152 | K22: =I22/$K$9 -> 7.2301422
E23: Total | G23: Kg | H23: 11424000 | I23: =SUM(I20:I22) -> 5582656 | J23: =I23/H23 -> 0.48867787 | K23: =I23/$K$9 -> 232.16568
D24: 3. | E24: WATER CONSUMPTION
E25: Incoming Raw Water | G25: m3 | H25: 19123.69 | I25: =SUM(I26:$I$27) -> 17740 | J25: =I25/H25 -> 0.92764524 | K25: =I25/$K$9 -> 0.73775264
E26: - Suplay To RO Product | I26: ='November 2024'!$AL$257 -> 8222 | K26: =I26/$K$9 -> 0.34192797
E27: - Suplay To Proses dan Sanitary | I27: =SUM(I29:$I$31) -> 9518 | K27: =I27/$K$9 -> 0.39582467
E28: Rincian Outgoing Proses | K28: =I28/$K$9 -> 0
E29: Softener Product (to Refinery) | F29: < 0,5 | G29: m3 | H29: 1521.33 | I29: ='November 2024'!$AL$253 -> 2042 | J29: =I29/H29 -> 1.3422466 | K29: =I29/$K$9 -> 0.084920569
E30: Softener Product (to Fractionation) | F30: < 0,4 | G30: m3 | H30: 2622 | I30: ='November 2024'!$AL$255 -> 2158 | J30: =I30/H30 -> 0.82303585 | K30: =I30/$K$9 -> 0.089744656
E31: Others | G31: m3 | H31: 2730.3 | I31: ='November 2024'!$AL$258 -> 5318 | J31: =I31/H31 -> 1.9477713 | K31: =I31/$K$9 -> 0.22115944
E32: Total | G32: m3 | H32: 6873.63 | I32: =SUM(I26:I27) -> 17740 | J32: =I32/H32 -> 2.5808779 | K32: =I32/$K$9 -> 0.73775264
D33: 4 | E33: POWER CONSUMPTION
E34: Incoming
E35: PLN *base on BA Kinra | G35: Kwh | H35: 568099 | I35: ='November 2024'!$AL$263 -> 556600 | J35: =I35/H35 -> 0.97975881 | K35: =I35/$K$9 -> 23.147301
E36: Outgoing | K36: =I36/$K$9 -> 0
