Workbook

Sheet Desember 2024
C1: PRODUCTION REPORT PMG II
C2: No | D2: ITEM | E2: Budget / Norma | F2: UoM | G2: DESEMBER | AM2: TOTAL MONTHLY (Kg)
G3: 1 | H3: 2 | I3: 3 | J3: 4 | K3: 5 | L3: 6 | M3: 7 | N3: 8 | O3: 9 | P3: 10 | Q3: 11 | R3: 12 | S3: 13 | T3: 14 | U3: 15 | V3: 16 | W3: 17 | X3: 18 | Y3: 19 | Z3: 20 | AA3: 21 | AB3: 22 | AC3: 23 | AD3: 24 | AE3: 25 | AF3: 26 | AG3: 27 | AH3: 28 | AI3: 29 | AJ3: 30 | AK3: 31
C4: 1 | D4: PRODUCTION | AM4: Production
D5: Refinery | AM5: Refinery
D6: Running Days | F6: Day | I6: 1 | J6: 1 | K6: 1 | L6: 1 | M6: 1 | N6: 1 | O6: 1 | P6: 1 | Q6: 1 | R6: 1 | S6: 1 | T6: 1 | U6: 1 | V6: 1 | W6: 1 | X6: 1 | Y6: 1 | Z6: 1 | AA6: 1 | AB6: 1 | AC6: 1 | AD6: 1 | AE6: 1 | AM6: =SUM(G6:AJ6) -> 23
D7: Incoming CPO | F7: Kg | G7: ='[1]01'!$P$15 -> 864484 | H7: ='[1]02'!$P$15 -> 920182 | I7: ='[1]03'!$P$15 -> 464321 | J7: ='[2]30 (Stock Opname)'!$P$15 -> 1416573 | K7: ='[3]02'!$P$15 -> 920182 | L7: ='[4]06'!$P$15 -> 1133688 | M7: ='[4]07'!$P$15 -> 1225114 | O7: ='[5]09'!$P$15 -> 600192 | P7: ='[6]10'!$P$15 -> 397080 | Q7: ='[7]11'!$P$15 -> 902048 | R7: ='[8]12'!$P$15 -> 558257 | S7: ='[9]13'!$P$15 -> 248740 | T7: ='[10]14'!$P$15 -> 598141 | U7: 0 | V7: ='[11]16'!$P$15 -> 313454 | W7: 0 | X7: ='[8]18'!$P$15 -> 111765 | Y7: ='[10]19'!$P$15 -> 0 | Z7: ='[12]20'!$P$15 -> 28079 | AA7: 0 | AB7: 0 | AC7: 0 | AD7: 0 | AE7: 0 | AF7: 0 | AG7: ='[9]27'!$P$15 -> 326528 | AH7: 172434 | AM7: =SUM(G7:AJ7) -> 11201262
D8: Ratio Run CPO | F8: % | G8: =G9/2500000*100 -> 0 | H8: =H9/2500000*100 -> 0 | I8: =I9/2500000 -> 0 | J8: =J9/2500000 -> 0 | K8: =K9/2500000 -> 0 | L8: =L9/2500000 -> 0 | M8: =M9/2500000 -> 0.1978084 | N8: =N9/2500000 -> 0.7459128 | O8: =O9/2500000 -> 0.63258 | P8: =P9/2500000 -> 0.24841 | Q8: =Q9/2500000 -> 0.0991936 | R8: =R9/2500000*100 -> 42.528 | S8: =S9/2500000 -> 0.8785152 | T8: =T9/2500000*100 -> 65.56452 | U8: =U9/2500000*100 -> 64.66848 | V8: =V9/2500000 -> 0.3628544 | W8: =W9/2500000 -> 0.7848968 | X8: =X9/2500000 -> 0.9665644 | Y8: =Y9/2500000 -> 0.8621888 | Z8: =Z9/2500000 -> 0.5995688 | AA8: =AA9/2500000 -> 0.279426 | AB8: =AB9/2500000 -> 0.67005 | AC8: =AC9/2500000 -> 0.7161404 | ... AE8: =AE9/2500000 -> 0.0420068 | AF8: =AF9/2500000*100 -> 0 | AG8: =AG9/2500000*100 -> 0 | AH8: =AH9/2500000*100 -> 0 | AI8: =AI9/2500000*100 -> 0 | AJ8: =AJ9/2500000*100 -> 0 | AK8: =AK9/2500000*100 -> 0 | AM8: =AM9/2500000/AM6 -> 0.43952621
D9: CPO Consume Total | E9: 36359000 | F9: Kg | I9: ='[2]30 (Stock Opname)'!$Q$15 -> 0 | J9: ='[2]30 (Stock Opname)'!$Q$15 -> 0 | M9: 494521 | N9: ='[4]08'!$Q$15 -> 1864782 | O9: 1581450 | P9: ='[6]10'!$Q$15 -> 621025 | Q9: ='[7]11'!$Q$15 -> 247984 | R9: ='[8]12'!$Q$15 -> 1063200 | S9: ='[9]13'!$Q$15 -> 2196288 | T9: ='[10]14'!$Q$15 -> 1639113 | U9: ='[10]15'!$Q$15 -> 1616712 | V9: ='[11]16'!$Q$15 -> 907136 | W9: ='[13]17'!$Q$15 -> 1962242 | X9: ='[8]18'!$Q$15 -> 2416411 | Y9: ='[10]19'!$Q$15 -> 2155472 | Z9: ='[12]20'!$Q$15 -> 1498922 | AA9: ='[12]21'!$Q$15 -> 698565 | AB9: ='[12]22'!$Q$15 -> 1675125 | AC9: ='[14]23'!$Q$15 -> 1790351 | AD9: ='[15]24'!$Q$15 -> 738441 | AE9: ='[15]25'!$Q$15 -> 105017 | AG9: ='[9]27'!$Q$15 -> 0 | AM9: =SUM(G9:AJ9) -> 25272757
D10: Avg Daily Consump CPO ( MTD ) | AM10: =AM9/AM6 -> 1098815.5 | AN10: =AM9/E9 -> 0.69508944
D11: CPO Consume Poram | E11: 29045000 | F11: Kg | G11: =G9-G12 -> 0 | H11: =H9-H12 -> 0 | I11: =I9-I12 -> 0 | J11: =J9-J12 -> 0 | L11: =L9-L12 -> 0 | M11: =M9-M12 -> 494521 | N11: =N9-N12 -> 1864782 | O11: =O9-O12 -> 1581450 | P11: =P9-P12 -> 621025 | Q11: =Q9-Q12 -> 247984 | R11: =R9-R12 -> 1063200 | S11: =S9-S12 -> 2196288 | ... AK11: =AK9-AK12 -> 0 | AM11: =SUM(G11:AJ11) -> 25272757
D12: CPO Consume Brand | E12: 7314000 | F12: Kg | G12: =G39+G48+G53 -> 0 | H12: =H39+H48+H53 -> 0 | I12: =I39+I48+I53 -> 0 | J12: =J39+J48+J53 -> 0 | K12: 0 | L12: =L39+L48+L53 -> 0 | M12: =M39+M48+M53 -> 0 | N12: =N39+N48+N53 -> 0 | O12: =O39+O48+O53 -> 0 | P12: =P39+P48+P53 -> 0 | Q12: =Q39+Q48+Q53 -> 0 | R12: =R39+R48+R53 -> 0 | S12: =S39+S48+S53 -> 0 | ... AK12: =AK39+AK48+AK53 -> 0 | AM12: =SUM(G12:AJ12) -> 0
D13: - FFA | E13: 5 | F13: % | I13: 3.92 | J13: 3.9 | M13: 3.94 | N13: 3.95 | O13: 3.98 | P13: 4.03 | Q13: 4.06 | R13: 3.95 | S13: 4.01 | T13: 4.01 | U13: 3.99 | V13: 4.03 | W13: 3.85 | X13: 4 | Y13: =(4.09+4.06)/2 -> 4.075 | Z13: 4.1 | AA13: 4.08 | AB13: 4.11 | AC13: 4.12 | AD13: 4.6 | AG13: 0 | AM13: =SUM(G13:AJ13)/AM6 -> 3.3336957
D14: - Moist & Impurities | E14: 0.5 | F14: % | I14: 0.4 | J14: 0.42 | M14: 0.39 | N14: 0.39 | O14: 0.39 | P14: 0.4 | Q14: 0.42 | R14: 0.44 | S14: 0.39 | T14: 0.4 | U14: 0.4 | V14: 0.41 | W14: 0.42 | X14: 0.43 | Y14: =(0.44+0.42)/2 -> 0.43 | Z14: 0.4 | AA14: 0.4 | AB14: 0.4 | AC14: 0.44 | AD14: 0.6 | AG14: 0 | AM14: =SUM(G14:AJ14)/AM6 -> 0.36391304
D15: - DOBI | E15: 2,20 Min | F15: % | I15: 2.22 | J15: 2.22 | M15: 2.21 | N15: 2.2 | O15: 2.21 | P15: 2.2 | Q15: 2.21 | R15: 2.4 | S15: 2.4 | T15: 2.2 | U15: 2.2 | V15: 2.38 | W15: 2.2 | X15: 2.2 | Y15: 2.2 | Z15: 2.2 | AA15: 2.2 | AB15: 2.2 | AC15: 2.21 | AD15: 2.2 | AG15: 0 | AM15: =SUM(G15:AJ15)/AM6 -> 1.8452174
D16: TANK | I16: 104 | J16: 104 | M16: 103 | N16: 104 | O16: 104 | P16: 104 | Q16: 104 | R16: 105 | S16: 105 | T16: 106 | U16: 106 | V16: 106 | W16: 107 | X16: 107 | Y16: 107.103 | Z16: 103 | AA16: 103 | AB16: 104 | AC16: 105 | AD16: "105/107 | AG16: 0
D17: Product | AM17: Product
D18: OIP RBDPO | J18: ='OIP Refinery '!K9 -> 308515.38 | K18: ='OIP Refinery '!L10 -> 0 | L18: ='OIP Refinery '!L11 -> 24423 | M18: ='OIP Refinery '!L12 -> -23693 | N18: ='OIP Refinery '!L13 -> 8781 | O18: ='OIP Refinery '!L14 -> -6501 | P18: ='OIP Refinery '!L15 -> -1620 | Q18: ='OIP Refinery '!L16 -> 727 | S18: ='[16]OIP Refinery '!L18 -> 16100 | V18: ='OIP Refinery '!L21 -> 9196 | W18: ='OIP Refinery '!L22 -> -35039 | X18: ='OIP Refinery '!L23 -> -426 | Y18: ='OIP Refinery '!L24 -> 4784 | Z18: ='OIP Refinery '!L25 -> 22542 | AA18: ='OIP Refinery '!L26 -> 9106 | AB18: ='OIP Refinery '!L27 -> -1526 | AC18: ='OIP Refinery '!L28 -> -17952 | AD18: ='OIP Refinery '!L29 -> 108237 | AE18: ='OIP Refinery '!L30 -> 9535 | AG18: ='OIP Refinery '!L32 -> 0
D19: RBDPO | E19: 34458000 | F19: Kg | M19: =457152+23693 -> 480845 | N19: ='[4]08'!$P$18+8781 -> 1684248 | O19: =1441290+45083 -> 1486373 | P19: ='[6]10'!$P$18+1620 -> 664578 | Q19: ='[7]11'!$P$18+727 -> 246488 | R19: ='[8]12'!$P$18+2355 -> 923422 | S19: ='[9]13'!$P$18+16100 -> 2130396 | T19: ='[10]14'!$P$18+17373 -> 1575805 | U19: ='[10]15'!$P$18+23544 -> 1589390 | V19: ='[11]16'!$P$23+9196 -> 863761 | W19: ='[13]17'!$P$18+35039 -> 1815060 | X19: ='[8]18'!$P$18+426 -> 2519497 | Y19: ='[10]19'!$P$18+4784 -> 2031197 | Z19: ='[12]20'!$P$18+22542 -> 1454272 | AA19: ='[12]21'!$P$18+9106 -> 694376 | AB19: ='[12]22'!$P$18+1526 -> 1576860 | AC19: ='[14]23'!$P$18+17952 -> 1730769 | AD19: ='[15]24'!$P$18+108237 -> 682583 | AE19: ='[15]25'!$P$18+9535 -> 185490 | AF19: 54158 | AG19: ='[9]27'!$P$18 -> 0 | AM19: =SUM(G19:AJ19) -> 24389568
D20: PFAD | E20: 1636000 | F20: Kg | M20: 21360 | N20: ='[4]08'!$P$27 -> 74300 | O20: 63960 | P20: 25820 | Q20: ='[7]11'!$P$27 -> 10475 | R20: ='[8]12'!$P$27 -> 42351 | S20: ='[9]13'!$P$27 -> 100021 | T20: ='[10]14'!$P$27 -> 71404 | U20: ='[10]15'!$P$27 -> 70951 | V20: ='[11]16'!$P$27 -> 40085 | W20: ='[13]17'!$P$27 -> 75721 | X20: ='[8]18'!$P$27 -> 105866 | Y20: ='[10]19'!$P$27 -> 87291 | Z20: ='[12]20'!$P$27 -> 64662 | AA20: ='[12]21'!$P$27 -> 28286 | AB20: ='[12]22'!$P$27 -> 69976 | AC20: ='[14]23'!$P$27 -> 73470 | AD20: ='[15]24'!$P$27 -> 36964 | AE20: ='[15]25'!$P$27 -> 18342 | AF20: 7825 | AG20: ='[9]27'!$P$27 -> 0 | AM20: =SUM(G20:AJ20) -> 1089130
D21: Fractionation
D22: Running Days | F22: Day | N22: 1 | O22: 1 | P22: 1 | Q22: 1 | R22: 1 | S22: 1 | T22: 1 | U22: 1 | V22: 1 | W22: 1 | X22: 1 | Y22: 1 | Z22: 1 | AA22: 1 | AB22: 1 | AC22: 1 | AD22: 1 | AE22: 1 | AF22: 1 | AG22: 1 | AH22: 1 | AM22: =SUM(G22:AK22) -> 21
D23: Avg Daily Consump RBDPO ( MTD ) | F23: Kg | G23: 0 | H23: 0 | I23: 0 | J23: 0 | K23: 0 | L23: 0 | M23: 0 | N23: 0 | O23: 0 | P23: 0 | Q23: 0 | R23: 0 | S23: 0 | T23: 0 | U23: 0 | V23: 0 | W23: 0 | X23: 0 | Y23: 0 | Z23: 0 | AA23: 0 | AB23: 0 | AC23: 0 | AD23: 0 | AE23: 0 | AF23: 0 | AG23: 0 | AH23: 0 | AI23: 0 | AJ23: 0 | AK23: 0 | AM23: =AM28/AM22 -> 1147468.4
D24: Total RBDPO transfer to plant | F24: Kg | N24: ='Oip Fract .'!L14 -> 281577 | O24: 392100 | P24: ='[6]10'!$Q$18 -> 366697 | Q24: ='[7]11'!$Q$18 -> 1206767 | R24: ='[8]12'!$Q$18 -> 1107426 | S24: ='[9]13'!$Q$18 -> 985016 | T24: ='[10]14'!$Q$18 -> 2026430 | U24: ='[10]15'!$Q$18 -> 2148697 | V24: ='[11]16'!$Q$18 -> 657964 | W24: ='[13]17'!$Q$18 -> 2347734 | X24: ='[8]18'!$Q$18 -> 3737260 | Y24: ='[10]19'!$Q$18 -> 1378873 | Z24: ='[12]20'!$Q$18 -> 30924 | AA24: ='[12]21'!$Q$18 -> 476133 | AB24: ='[12]22'!$Q$18 -> 1230701 | AC24: ='[14]23'!$Q$18 -> 1954027 | AD24: ='[15]24'!$Q$18 -> 1112757 | AE24: ='[15]25'!$Q$18 -> 1485846 | AF24: 1185518 | AG24: ='[9]27'!$Q$18 -> 0 | AM24: =SUM(G24:AJ24) -> 24112447
D25: Stok TK 131 | E25: 559 | F25: ton | P25: 361081 | Q25: 312272 | R25: ='[17]Oip Fract .'!U18 -> 447800 | S25: ='[16]Oip Fract .'!U19 -> 160000 | T25: ='Oip Fract .'!U20 -> 156000 | U25: ='Oip Fract .'!U21 -> 265000 | V25: ='Oip Fract .'!U22 -> 88200 | W25: ='Oip Fract .'!U23 -> 35220 | X25: ='Oip Fract .'!U24 -> 95225 | Y25: ='Oip Fract .'!U25 -> 234123 | Z25: ='Oip Fract .'!U26 -> 223284 | AA25: ='Oip Fract .'!U27 -> 158003 | AB25: ='Oip Fract .'!U28 -> 167918 | AC25: ='Oip Fract .'!U29 -> 340216 | AD25: ='Oip Fract .'!U30 -> 156238 | AE25: ='Oip Fract .'!U31 -> 78021 | AF25: ='Oip Fract .'!U32 -> 37638 | AG25: ='Oip Fract .'!U33 -> 37954 | AH25: ='Oip Fract .'!U33 -> 37954
D26: Stok TK 132 | E26: 559 | F26: ton | P26: ='Oip Fract .'!W16 -> 38852 | Q26: 312272 | R26: ='[17]Oip Fract .'!W18 -> 347595 | S26: ='[16]Oip Fract .'!W19 -> 112000 | T26: ='Oip Fract .'!W20 -> 85000 | U26: ='Oip Fract .'!W21 -> 265000 | V26: ='Oip Fract .'!W22 -> 80200 | W26: ='Oip Fract .'!W23 -> 35220 | X26: ='Oip Fract .'!W24 -> 105225 | Y26: ='Oip Fract .'!W25 -> 234125 | Z26: ='Oip Fract .'!W26 -> 216280 | AA26: ='Oip Fract .'!W27 -> 155107 | AB26: ='Oip Fract .'!W28 -> 164248 | AC26: ='Oip Fract .'!W29 -> 330359 | AD26: ='Oip Fract .'!W30 -> 156022 | AE26: ='Oip Fract .'!W31 -> 156240 | AF26: ='Oip Fract .'!W32 -> 197872 | AG26: ='Oip Fract .'!W33 -> 108106 | AH26: ='Oip Fract .'!W33 -> 108106
D27: Ratio Run RBDPO | P27: =P28/2500000 -> 0.0715696 | Q27: =Q28/2500000 -> 0.2793592 | R27: =R28/2500000 -> 0.4093536 | S27: =S28/2500000 -> 0.546472 | T27: =T28/2500000 -> 0.7772728 | U27: =U28/2500000 -> 0.8476676 | V27: =V28/2500000 -> 0.4410548 | W27: =W28/2500000 -> 0.907438 | ... AH27: =AH28/2500000 -> 0.058144 | AM27: =AM28/2500000/10 -> 0.96387348
D28: Total Proses RBDPO | F28: Kg | G28: =SUM(G31,G35,G40,G44,G54) -> 0 | H28: =SUM(H31,H35,H40,H44,H54) -> 0 | I28: =SUM(I31,I35,I40,I44,I54) -> 0 | J28: =SUM(J31,J35,J40,J44,J54) -> 0 | L28: =SUM(L31,L35,L40,L44,L54) -> 0 | M28: =SUM(M31,M35,M40,M44,M54) -> 0 | N28: =SUM(N31,N35,N40,N44,N54) -> 0 | O28: =SUM(O31,O35,O40,O44,O54) -> 0 | P28: =SUM(P31,P35,P40,P44,P54) -> 178924 | Q28: =SUM(Q31,Q35,Q40,Q44,Q54) -> 698398 | R28: =SUM(R31,R35,R40,R44,R54) -> 1023384 | S28: =SUM(S31,S35,S40,S44,S54) -> 1366180 | ... AA28: =SUM(AA31,AA35,AA40,AA44,AA54) -> 546176 | AB28: ='[12]22'!$Q$18 -> 1230701 | AC28: =SUM(AC31,AC35,AC40,AC44,AC54) -> 1595581 | AD28: =SUM(AD31,AD35,AD40,AD44,AD54) -> 1493796 | AE28: =SUM(AE31,AE35,AE40,AE44,AE54) -> 1574199 | AF28: =SUM(AF31,AF35,AF40,AF44,AF54) -> 2042339 | AG28: =SUM(AG31,AG35,AG40,AG44,AG54) -> 223353 | AH28: =SUM(AH31,AH35,AH40,AH44,AH54) -> 145360 | AI28: =SUM(AI31,AI35,AI40,AI44,AI54) -> 0 | AJ28: =SUM(AJ31,AJ35,AJ40,AJ44,AJ54) -> 0 | AK28: =SUM(AK31,AK35,AK40,AK44,AK54) -> 0 | AM28: =SUM(G28:AJ28) -> 24096837 | AN28: =AM28/E19 -> 0.69931038
D29: Sisa Filling Crystalizer | F29: Kg | G29: =G24-G28 -> 0 | I29: =I24-I28 -> 0 | J29: =SUM(J32,J36,J41,J45,#REF!) -> #REF! | K29: 68473 | L29: =L24-L28 -> 0 | M29: =M24-M28 -> 0 | N29: =N24-N28 -> 281577 | O29: =O24-O28 -> 392100 | P29: =P24-P28 -> 187773 | Q29: =Q24-Q28 -> 508369 | R29: =R24-R28 -> 84042 | S29: =S24-S28 -> -381164 | ... AK29: =AK24-AK28 -> 0 | AM29: =SUM(G29:AJ29) -> #REF!
D30: Fractionation OLEIN IV 56 | AM30: Olein IV 56
D31: RBDPO Consume | F31: Kg | G31: =G32+G33 -> 0 | H31: =H32+H33 -> 0 | I31: =I32+I33 -> 0 | J31: =J32+J33 -> 0 | K31: 0 | L31: =L32+L33 -> 0 | M31: =M32+M33 -> 0 | N31: =N32+N33 -> 0 | O31: =O32+O33 -> 0 | P31: =P32+P33 -> 178924 | Q31: =Q32+Q33 -> 111217 | R31: =R32+R33 -> 114465 | S31: =S32+S33 -> 0 | ... AK31: =AK32+AK33 -> 0 | AM31: =SUM(G31:AJ31) -> 7003508
D32: OLEIN IV 56 | F32: Kg | G32: 0 | H32: 0 | I32: 0 | J32: 0 | K32: 0 | L32: 0 | M32: 0 | N32: 0 | O32: 0 | P32: ='[6]10'!$P$23 -> 144963 | Q32: ='[7]11'!$P$21 -> 91214 | R32: ='[8]12'!$P$21 -> 92131 | V32: ='[11]16'!$P$21 -> 275346 | W32: ='[13]17'!$P$19 -> 1618321 | X32: ='[8]18'!$P$23 -> 2369769 | Y32: 123327 | AA32: 0 | AB32: 0 | AC32: 0 | AE32: 0 | AF32: 734495 | AG32: ='[9]27'!$P$21 -> 134128 | AH32: 0 | AI32: 0 | AJ32: 0 | AK32: 0 | AM32: =SUM(G32:AJ32) -> 5583694
D33: STEARIN | F33: Kg | G33: 0 | H33: 0 | I33: 0 | J33: 0 | K33: 0 | L33: 0 | M33: 0 | N33: 0 | O33: 0 | P33: ='[6]10'!$P$31 -> 33961 | Q33: 20003 | R33: 22334 | V33: 59345 | W33: 384307 | X33: ='[8]18'!$P$31 -> 547180 | Y33: 28223 | AA33: 0 | AB33: 0 | AC33: 0 | AE33: 0 | AF33: 235236 | AG33: 89225 | AJ33: 0 | AK33: 0 | AM33: =SUM(G33:AJ33) -> 1419814
D34: Fractionation OLEIN IV 57 ( Bulk ) | AM34: Olein IV 57 ( Bulk )
D35: RBDPO Consume | F35: Kg | G35: =G36+G37 -> 0 | H35: =H36+H37 -> 0 | I35: =I36+I37 -> 0 | J35: =J36+J37 -> 0 | K35: 0 | L35: =L36+L37 -> 0 | M35: =M36+M37 -> 0 | N35: =N36+N37 -> 0 | O35: =O36+O37 -> 0 | P35: =P36+P37 -> 0 | Q35: =Q36+Q37 -> 0 | R35: =R36+R37 -> 0 | S35: =S36+S37 -> 0 | ... X35: =X36+X37 -> 0 | AA35: =AA36+AA37 -> 0 | AB35: =AB36+AB37 -> 0 | AC35: =AC36+AC37 -> 0 | AD35: =AD36+AD37 -> 0 | AE35: =AE36+AE37 -> 0 | AF35: =AF36+AF37 -> 0 | AG35: =AG36+AG37 -> 0 | AH35: =AH36+AH37 -> 0 | ... AK35: =AK36+AK37 -> 0 | AM35: =SUM(G35:AJ35) -> 0
D36: OLEIN IV 57 | F36: Kg | G36: 0 | H36: 0 | I36: 0 | J36: 0 | K36: 0 | L36: 0 | M36: 0 | N36: 0 | O36: 0 | P36: 0 | Q36: 0 | R36: 0 | S36: 0 | T36: 0 | U36: 0 | V36: 0 | W36: 0 | X36: 0 | AA36: 0 | AB36: 0 | AC36: 0 | AD36: 0 | AE36: 0 | AF36: 0 | AG36: 0 | AM36: =SUM(G36:AJ36) -> 0
D37: STEARIN | F37: Kg | G37: 0 | H37: 0 | I37: 0 | J37: 0 | K37: 0 | L37: 0 | M37: 0 | N37: 0 | O37: 0 | P37: 0 | Q37: 0 | R37: 0 | S37: 0 | T37: 0 | U37: 0 | V37: 0 | W37: 0 | X37: 0 | AA37: 0 | AB37: 0 | AC37: 0 | AD37: 0 | AE37: 0 | AF37: 0 | AG37: 0 | AM37: =SUM(G37:AJ37) -> 0
D38: Fractionation OLEIN IV 57 ( Retail ) | AM38: Olein IV 57 ( Retail )
D39: CPO Consume | F39: Kg | AM39: =SUM(G39:AJ39) -> 0
D40: RBDPO Brand Consume | F40: Kg | G40: =G41+G42 -> 0 | H40: =H41+H42 -> 0 | I40: =I41+I42 -> 0 | J40: =J41+J42 -> 0 | K40: 0 | L40: =L41+L42 -> 0 | M40: =M41+M42 -> 0 | N40: =N41+N42 -> 0 | O40: =O41+O42 -> 0 | P40: =P41+P42 -> 0 | Q40: =Q41+Q42 -> 0 | R40: =R41+R42 -> 0 | S40: =S41+S42 -> 0 | ... X40: =X41+X42 -> 0 | AA40: =AA41+AA42 -> 0 | AB40: =AB41+AB42 -> 0 | AC40: =AC41+AC42 -> 0 | AD40: =AD41+AD42 -> 0 | AE40: =AE41+AE42 -> 0 | AF40: =AF41+AF42 -> 0 | AG40: =AG41+AG42 -> 0 | AH40: =AH41+AH42 -> 0 | ... AK40: =AK41+AK42 -> 0 | AM40: =SUM(G40:AJ40) -> 0
...

Sheet Peformance test Fract 1
C1: PT.INDUSTRI NABATI LESTARI
C2: Pabrik Minyak Goreng ( PMG 2 )
C3: Kantor Pusat: Komp. KEK Sei Mangkei, Kav.2-3, Kec. Bosar Maligas, Kab. Simalungun, Sumatera Utara, 21184
C4: ACTUAL PEFORMANCE / CONSUMPT REPORT FRAKSINASI PLANT | H4: Trial | I4: 1
H5: Start / Date / Time | I5: 17/12/24 ( 07.00 Wib )
H6: Finish / Date / Time | I6: 17/12/24 ( 07.00 Wib )
A8: No | B8: ITEM | C8: Kontrak LIPICO | D8: UOM | E8: TOTALIZER
A10: 1 | B10: PRODUCTION | C10: IV 56 | D10: 24 jam | E10: BEFORE | F10: AFTER | G10: TOTAL | H10: YIELD % | I10: STATUS/REMAKS
B11: Fraksinasi
B12: Running Days
B13: Incoming CPO
B14: Ratio Run CPO
B15: RBDPO Consume Total | C15: 2500 | D15: TPD | E15: 8982.8 | F15: 11717.8 | G15: =F15-E15 -> 2735 | H15: =G15/25000*10 -> 1.094 | I15: OK
B16: Avg Daily Consump CPO ( MTD )
B17: CPO Consume Poram | C17: 29045000
B18: CPO Consume Brand | C18: 7314000 | E18: =E49+E58+E63 -> 0
B19: QUALITY
B20: - FFA | C20: 0.1 | D20: % Max | H20: 0.063
B21: - Moist & Impurities | C21: 0.1 | D21: % Max | H21: 0.05
B22: - IV | C22: 52 - 52,5 | H22: 51.8
B23: - LC | H23: 2,6/20
B24: - Temp | C24: 68 | D24: ˚C Min | H24: 65
B25: TANK | H25: 108/109
B26: Product
B27: OLEIN IV 56 | C27: =C15*84% -> 2100 | D27: TPD | E27: 6537.1 | F27: 8213 | G27: =F27-E27 -> 1675.9 | H27: =G27/(G27+G32) -> 0.82838219 | I27: OK
B28: QUALITY
B29: - IV | C29: 56 | D29: Min
B30: - LC
B31: - Cloud Point ( metter ) | C31: 10 | D31: ˚C Max
B32: STEARIN | C32: =C15*16% -> 400 | E32: 2268.1 | F32: 2615.3 | G32: =F32-E32 -> 347.2 | H32: =G32/(G32+G27) -> 0.17161781 | I32: OK
B33: Fractionation
B34: Running Days
B35: Filling Langsung CR Fr Refinery | E35: 0
B36: Total Filling Crystalizer ( Feed ) | E36: 392100
B37: Avg Daily Consump RPO ( MTD )
B38: Total Proses RBDPO | E38: =SUM(E41,E45,E50,E54,E64) -> 0
B39: Sisa Filling Crystalizer | E39: =E36-E38 -> 392100
B40: Fractionation OLEIN IV 56
B41: RBDPO Consume | E41: =E42+E43 -> 0
B42: OLEIN IV 56 | E42: 0
...

Sheet Peformance Test REFINERY 1
C1: PT.INDUSTRI NABATI LESTARI
C2: Pabrik Minyak Goreng ( PMG 2 )
C3: Kantor Pusat: Komp. KEK Sei Mangkei, Kav.2-3, Kec. Bosar Maligas, Kab. Simalungun, Sumatera Utara, 21184
C4: ACTUAL PEFORMANCE / CONSUMPT REPORT REFINERY PLANT | H4: Peformance | I4: 1
H5: Start / Date / Time | I5: 17/12/24 ( 21.00 Wib )
H6: Finish / Date / Time | I6: 18/12/24 ( 21.00 Wib )
A7: No | B7: ITEM | C7: Kontrak LIPICO | D7: UOM | E7: TOTALIZER
A9: 1 | B9: PRODUCTION | E9: BEFORE | F9: AFTER | G9: TOTAL | H9: Yield ( % ) | I9: STATUS/REMAKS
B10: Refinery
B11: Running Days
B12: Incoming CPO
B13: Ratio Run CPO
B14: CPO Consume Total | C14: 2500 | D14: TPD | E14: 13533.82 | F14: 16053.42 | G14: =F14-E14 -> 2519.6 | I14: OK
B15: Avg Daily Consump CPO ( MTD )
B16: CPO Consume Poram | C16: 29045000
B17: CPO Consume Brand | C17: 7314000 | E17: =E53+E62+E67 -> 0
B18: - FFA | C18: 5 | D18: % | G18: 4
B19: - Moist & Impurities | C19: 0.5 | D19: % | G19: 0.41
B20: - DOBI | C20: 2.2 | D20: Min | G20: 2.42
B21: - TOTOX 2PV + AV | C21: 12 | D21: Max | G21: N/A
B22: - FE Content | C22: < 5 | D22: ppm | G22: N/A
B23: - PV | C23: < 4 | D23: Meg/kg | G23: N/A
B24: - Phosporus Max | C24: 25 | D24: ppm | G24: N/A
B25: TANK / TEMP | C25: 50 | D25: ˚C | G25: 50
B26: Product
B27: RBDPO | C27: =C14*94.2% -> 2355 | D27: TPD | E27: 12357.54 | F27: 14705.95 | G27: =F27-E27 -> 2348.41 | H27: =G27/G14 -> 0.93205668
B28: - FFA | C28: 0.05 | D28: % | G28: 0.06
B29: - Moist & Impurities | C29: 0.03 | D29: % | G29: 0.05
B30: - Peroxide value | D30: Nil | G30: -
B31: - Phosporous max | C31: 2 | D31: ppm | G31: N/A
B32: - LC | C32: 2.5 | D32: % | G32: 2.5
B33: - Aom stability min ( hr ) | C33: 60 | D33: min ( hr ) | G33: N/A
B34: - teste & Odor | C34: bland/Odorless | G34: N/A
B35: - temp max ( C ) | C35: 50 | D35: max˚C | G35: 50
B36: PFAD | C36: =C14*5% -> 125 | D36: TPD | E36: 572.71 | F36: 675.39 | G36: =F36-E36 -> 102.68 | H36: =G36/G14 -> 0.0407525
B37: Fractionation
B38: Running Days
B39: Filling Langsung CR Fr Refinery | E39: 0
B40: Total Filling Crystalizer ( Feed ) | E40: 392100
B41: Avg Daily Consump RPO ( MTD )
...

Sheet peformance  test REFINERY 2
A1: REFINERY PMG 2
A2: No | B2: ITEM | C2: Norma LIPICO | D2: UOM | E2: Day 2 tanggal 12/12/2024
A4: 1 | B4: PRODUCTION | E4: BEFORE | F4: AFTER | G4: TOTAL | H4: Yield ( % )
B5: Refinery
B6: Running Days
B7: Incoming CPO
B8: Ratio Run CPO
B9: CPO Consume Total | C9: 2500 | D9: TPD | E9: 5880.74 | F9: 8383.74 | G9: =F9-E9 -> 2503 | H9: =G9/2500000*100000 -> 100.12
B10: Avg Daily Consump CPO ( MTD )
B11: CPO Consume Poram | C11: 29045000
B12: CPO Consume Brand | C12: 7314000 | E12: =E43+E52+E57 -> 0
B13: - FFA | C13: 5 | D13: % | G13: 3.97
B14: - Moist & Impurities | C14: 0.5 | D14: % | G14: 0.4
B15: - DOBI | C15: 2.2 | D15: Min | G15: 2.42
B16: TANK | G16: 105
B17: Product
B18: OIP RBDPO
B19: RBDPO | C19: =C9*94.2% -> 2355 | D19: TPD | E19: 5143.38 | F19: 7493.18 | G19: =F19-E19 -> 2349.8 | H19: =G19/G9*100 -> 93.879345
B20: - FFA | C20: 0.05 | D20: % | G20: 0.043
B21: - Moist & Impurities | C21: 0.03 | D21: % | G21: 0.04
B22: - LC | C22: 2.5 | D22: % | G22: 2.5
B23: - Aom stability min ( hr ) | C23: 60 | D23: min ( hr )
B24: - teste & Odor | C24: bland/Odorless
B25: - temp max ( C ) | C25: 50 | D25: max˚C
B26: PFAD | C26: =C9*5% -> 125 | D26: TPD | E26: 243.04 | F26: 347.1 | G26: =F26-E26 -> 104.06 | H26: =G26/G9*100 -> 4.1574111
B27: Fractionation
B28: Running Days
B29: Filling Langsung CR Fr Refinery | E29: 0
B30: Total Filling Crystalizer ( Feed ) | E30: 392100
B31: Avg Daily Consump RPO ( MTD )
B32: Total Proses RBDPO | E32: =SUM(E35,E39,E44,E48,E58) -> 0
B33: Sisa Filling Crystalizer | E33: =E30-E32 -> 392100
B34: Fractionation OLEIN IV 56
B35: RBDPO Consume | E35: =E36+E37 -> 0
B36: OLEIN IV 56 | E36: 0
B37: STEARIN | E37: 0
B38: Fractionation OLEIN IV 57 ( Bulk )
B39: RBDPO Consume | E39: =E40+E41 -> 0
B40: OLEIN IV 57 | E40: 0
B41: STEARIN | E41: 0
...

Sheet HPP REF 
B2: Refinery Cost
B3: Through Put CPO Proses | N3: =('Desember 2024'!AM10)/1000 -> 1098.8155 | O3: TPD
B4: Working Day | N4: ='Desember 2024'!AM6 -> 23 | O4: Days
B5: Total CPO Process | N5: =N4*N3 -> 25272.757 | O5: MTD
B6: KURS | N6: ='SUMMARY HPP '!I9 -> 15546 | O6: Rp/USD
B7: No | C7: Item Cost | D7: Norma | F7: Pemakaian / Hari | H7: HK | J7: Total Pemakaian | K7: Harga / stn | M7: Total Biaya | N7: Rp / kg | O7: USD/MT
B8: 1 | C8: Bleaching Earth | D8: ='Desember 2024'!$AM$75 -> 0.90731656 | F8: =($D$8*$N$3*10) -> 9969.7352 | G8: Kg/day | H8: =$N$4 -> 23 | J8: =$H$8*$F$8 -> 229303.91 | K8: 2400 | M8: =$J$8*$K$8 -> 550329384 | N8: =$M$8/($N$5*1000) -> 21.775597 | O8: =($M$8/$N$6)/$N$5 -> 1.4007203
B9: 2 | C9: Phosporic acid | D9: ='Desember 2024'!$AM$83 -> 0.050540366 | F9: =($D$9*$N$3*10) -> 555.34539 | G9: Kg/day | H9: =$H$8 -> 23 | J9: =$H$9*$F$9 -> 12772.944 | K9: 17420 | M9: =$J$9*$K$9 -> 2.2250468e+08 | N9: =$M$9/($N$5*1000) -> 8.8041318 | O9: =($M$9/$N$6)/$N$5 -> 0.56632779
B10: 3 | C10: Caustic Soda | D10: 29.166667 | E10: kg/day | F10: =D10 -> 29.166667 | G10: kg/day | H10: =$H$8 -> 23 | J10: =$H$10*$F$10 -> 670.83333 | K10: 15700 | M10: =$J$10*$K$10 -> 10532083 | N10: =$M$10/($N$5*1000) -> 0.41673662 | O10: =($M$10/$N$6)/$N$5 -> 0.026806678
B11: 4 | C11: Pemakaian Natural Gas HPB Geka
C12: Normal Consumption | D12: ='Desember 2024'!$AM$243 -> 0.30264218 | E12: MMBTU/MT CPO | F12: =$D$12*$N$3 -> 332.54793 | G12: MMBTU/day | H12: =$H$8 -> 23 | J12: =$H$12*$F$12 -> 7648.6024 | K12: =11.5*$N$6 -> 178779 | M12: =$J$12*$K$12 -> 1.3674095e+09 | N12: =$M$12/($N$5*1000) -> 54.106067 | O12: =($M$12/$N$6)/$N$5 -> 3.4803851
C13: Penalty Below Consumption | D13: 0 | E13: MMBTU/MT CPO | F13: =$D$13*$N$3 -> 0 | G13: MMBTU/day | H13: =$H$8 -> 23 | J13: =$H$13*$F$13 -> 0 | K13: =11.5*$N$6 -> 178779 | M13: =$J$13*$K$13 -> 0 | N13: =$M$13/($N$5*1000) -> 0 | O13: =($M$13/$N$6)/$N$5 -> 0
C14: Penalty Above Consumption | D14: 0 | E14: MMBTU/MT CPO | F14: =$D$14*$N$3 -> 0 | G14: MMBTU/day | H14: =$H$8 -> 23 | J14: =$H$14*$F$14 -> 0 | K14: =11.5*$N$6 -> 178779 | M14: =$J$14*$K$14 -> 0 | N14: =$M$14/($N$5*1000) -> 0 | O14: =($M$14/$N$6)/$N$5 -> 0
B15: 5 | C15: Pemakaian Steam
C16: For Process | D16: ='Desember 2024'!$AM$250 -> 34.678451 | E16: Kg/MT CPO | F16: =$D$16*$N$3/1000 -> 38.10522 | G16: Ton/day | H16: =$H$8 -> 23 | J16: =$H$16*$F$16 -> 876.42007 | K16: =Steam!H15 -> 183326.68 | M16: =$J$16*$K$16 -> 1.6067118e+08 | N16: =$M$16/($N$5*1000) -> 6.3574853 | O16: =($M$16/$N$6)/$N$5 -> 0.40894669
C17: Storage Tank for Heating | D17: ='Desember 2024'!$AM$254 -> 18.21772 | E17: Kg/MT CPO | F17: =$D$17*$N$3/1000 -> 20.017913 | G17: Ton/day | H17: =$H$8 -> 23 | J17: =$H$17*$F$17 -> 460.41201 | K17: =Steam!H15 -> 183326.68 | M17: =$J$17*$K$17 -> 84405804 | N17: =$M$17/($N$5*1000) -> 3.3397941 | O17: =($M$17/$N$6)/$N$5 -> 0.21483302
B18: 6 | C18: Pemakaian Electrical
C19: For Process | D19: ='Desember 2024'!$AM$273 -> 29.759471 | E19: kW/MT CPO | F19: =$D$19*$N$3 -> 32700.169 | G19: kW/day | H19: =$H$8 -> 23 | I19: 0 | J19: =$H$19*$F$19 -> 752103.89 | K19: 1550 | L19: =[18]Electric!H21 -> 3666.6667 | M19: =($F$19*$H$19*$K$19)+($F$19*$I$19*$L$19) -> 1.165761e+09 | N19: =$M$19/($N$5*1000) -> 46.127181 | O19: =($M$19/$N$6)/$N$5 -> 2.9671414
C20: Cooling Tower | D20: ='Desember 2024'!$AM$275 -> 7.1115462 | E20: kW/MT CPO | F20: =$D$20*$N$3 -> 7814.2774 | G20: kW/day | H20: =$H$8 -> 23 | I20: 0 | J20: =$H$20*$F$20 -> 179728.38 | K20: 1550 | L20: =L19 -> 3666.6667 | M20: =(F20*H20*K20)+(F20*I20*L20) -> 2.7857899e+08 | N20: =$M$20/($N$5*1000) -> 11.022897 | O20: =($M$20/$N$6)/$N$5 -> 0.70905035
C21: Storage Tank | D21: 0.3377877 | E21: kW/MT CPO | F21: =$D$21*$N$3 -> 371.16637 | G21: kW/day | H21: =$H$8 -> 23 | I21: 0 | J21: =$H$21*$F$21 -> 8536.8264 | K21: 1550 | L21: =L20 -> 3666.6667 | M21: =($F$21*$H$21*$K$21)+($F$21*$I$21*$L$21) -> 13232081 | N21: =$M$21/($N$5*1000) -> 0.52357093 | O21: =($M$21/$N$6)/$N$5 -> 0.03367882
B22: 7 | C22: Pemakaian Water
C23: Make Up CT | D23: ='Desember 2024'!$AM$260 -> 39.884845 | E23: M3/day | F23: =$D$23 -> 39.884845 | G23: M3/day | H23: =$H$8 -> 23 | J23: =$H$23*$F$23 -> 917.35144 | K23: =WTP!H13 -> 16370.605 | M23: =$J$23*$K$23 -> 15017598 | N23: =$M$23/($N$5*1000) -> 0.59422082 | O23: =($M$23/$N$6)/$N$5 -> 0.03822339
B24: 8 | C24: Chemical Water | N24: =$M$24/($N$5*1000) -> 0 | O24: =($M$24/$N$6)/$N$5 -> 0
C25: EONBAC BC 3108 | D25: 0.4 | E25: Kg/day | F25: =D25 -> 0.4 | G25: Kg/day | H25: =$H$8 -> 23 | J25: =$H$25*$F$25 -> 9.2 | K25: 27240 | M25: =$J$25*$K$25 -> 250608 | N25: =$M$25/($N$5*1000) -> 0.0099161322 | O25: =($M$25/$N$6)/$N$5 -> 0.00063785747
C26: EONLINE T722 | D26: 0.66 | E26: Kg/day | F26: =D26 -> 0.66 | G26: Kg/day | H26: =$H$8 -> 23 | J26: =$H$26*$F$26 -> 15.18 | K26: 29120 | M26: =$J$26*$K$26 -> 442041.6 | N26: =$M$26/($N$5*1000) -> 0.017490834 | O26: =($M$26/$N$6)/$N$5 -> 0.0011251019
C27: EONLINE AG5770 | D27: 0.41 | E27: Kg/day | F27: =D27 -> 0.41 | G27: Kg/day | H27: =$H$8 -> 23 | J27: =$H$27*$F$27 -> 9.43 | K27: 117212 | M27: =$J$27*$K$27 -> 1105309.2 | N27: =$M$27/($N$5*1000) -> 0.043735203 | O27: =($M$27/$N$6)/$N$5 -> 0.0028132769
C28: EONScale T2511 | D28: 0.1 | E28: Kg/day | F28: =D28 -> 0.1 | G28: Kg/day | H28: =$H$8 -> 23 | J28: =$H$28*$F$28 -> 2.3 | K28: 45940 | M28: =$J$28*$K$28 -> 105662 | N28: =$M$28/($N$5*1000) -> 0.0041808656 | O28: =($M$28/$N$6)/$N$5 -> 0.00026893513
B29: 9 | C29: Others
C30: Filter Bag 10 Microne | D30: 0.90361446 | E30: Pcs/day | F30: =D30 -> 0.90361446 | G30: Pcs/day | H30: =$H$8 -> 23 | J30: =$H$30*$F$30 -> 20.783133 | K30: 40000 | M30: =$J$30*$K$30 -> 831325.3 | N30: =$M$30/($N$5*1000) -> 0.032894128 | O30: =($M$30/$N$6)/$N$5 -> 0.0021159223
C31: Filter Bag 100 Microne | D31: 0.63253012 | E31: Pcs/day | F31: =D31 -> 0.63253012 | G31: Pcs/day | H31: =$H$8 -> 23 | J31: =$H$31*$F$31 -> 14.548193 | K31: 125000 | M31: =$J$31*$K$31 -> 1818524.1 | N31: =$M$31/($N$5*1000) -> 0.071955905 | O31: =($M$31/$N$6)/$N$5 -> 0.00462858
C32: Filter Cartridge 10 Microne | D32: 1.5666667 | E32: Pcs/day | F32: =D32 -> 1.5666667 | G32: Pcs/day | H32: =$H$8 -> 23 | J32: =$H$32*$F$32 -> 36.033333 | K32: 145000 | M32: =$J$32*$K$32 -> 5224833.3 | N32: =$M$32/($N$5*1000) -> 0.20673777 | O32: =($M$32/$N$6)/$N$5 -> 0.013298454
C33: Filter Dustbag | D33: 0.12048193 | E33: Pcs/day | F33: =D33 -> 0.12048193 | G33: Pcs/day | H33: =$H$8 -> 23 | J33: =$H$33*$F$33 -> 2.7710843 | K33: 682500 | M33: =$J$33*$K$33 -> 1891265.1 | N33: =$M$33/($N$5*1000) -> 0.074834141 | O33: =($M$33/$N$6)/$N$5 -> 0.0048137232
C34: O Ring Filter Leaves | D34: 3.6144578 | E34: Pcs/day | F34: =D34 -> 3.6144578 | G34: Pcs/day | H34: =$H$8 -> 23 | J34: =$H$34*$F$34 -> 83.13253 | K34: 14500 | M34: =$J$34*$K$34 -> 1205421.7 | N34: =$M$34/($N$5*1000) -> 0.047696485 | O34: =($M$34/$N$6)/$N$5 -> 0.0030680873
B35: 10 | C35: Waste Water Treatment Plant ( WWTP ) | D35: ='Desember 2024'!$AM$266 -> 165.91304 | E35: M3/day | F35: =D35 -> 165.91304 | G35: M3/day | H35: =$H$8 -> 23 | J35: =$H$35*$F$35 -> 3816 | K35: =WWTP!H17 -> 25456.97 | M35: =$J$35*$K$35 -> 97143798 | N35: =$M$35/($N$5*1000) -> 3.8438148 | O35: =($M$35/$N$6)/$N$5 -> 0.24725427
B36: 11 | C36: SHE
C37: SBE | D37: ='Desember 2024'!$AM$87 -> 231452.55 | E37: Kg/day | F37: =D37 -> 231452.55 | G37: Kg/day | H37: =$H$8 -> 23 | J37: =$F$37 -> 231452.55 | K37: 275 | M37: =$J$37*$K$37 -> 63649452 | N37: =$M$37/($N$5*1000) -> 2.5185005 | O37: =($M$37/$N$6)/$N$5 -> 0.16200312
C38: Domestic | D38: 0.1 | E38: Trip/day | F38: =D38 -> 0.1 | G38: Trip/day | H38: =$H$8 -> 23 | J38: =$H$38*$F$38 -> 2.3 | K38: 303030.3 | M38: =$J$38*$K$38 -> 696969.7 | N38: =$M$38/($N$5*1000) -> 0.027577905 | O38: =($M$38/$N$6)/$N$5 -> 0.0017739551
B39: 12 | C39: Chemical Consumption | N39: =$M$39/($N$5*1000) -> 0 | O39: =($M$39/$N$6)/$N$5 -> 0
C40: LAB Chemical | D40: =lab!H33 -> 745255.21 | E40: Rp/day | F40: =D40 -> 745255.21 | G40: Rp/day | H40: =$H$8 -> 23 | M40: =$H$40*$F$40 -> 17140870 | N40: =$M$40/($N$5*1000) -> 0.67823506 | O40: =($M$40/$N$6)/$N$5 -> 0.043627625
C41: Chemical Boiler dan WTP | D41: =lab!H54 -> 259161.44 | E41: Rp/day | F41: =D41 -> 259161.44 | G41: Rp/day | H41: =$H$8 -> 23 | M41: =$H$41*$F$41 -> 5960713.2 | N41: =$M$41/($N$5*1000) -> 0.23585528 | O41: =($M$41/$N$6)/$N$5 -> 0.015171445
...

Sheet HPP FRACT
B2: Fractionation Cost
B3: RPO Proses / Day | N3: TPD | O3: ='Desember 2024'!AM23/1000 -> 1147.4684
B4: Working Day | N4: Days | O4: ='Desember 2024'!AM22 -> 21
B5: Total CPO Process | N5: MTD | O5: =O3*O4 -> 24096.837
B6: KURS | N6: Rp/USD | O6: ='SUMMARY HPP '!I9 -> 15546
B7: No | C7: Item Cost | D7: Norma | F7: Pemakaian / Hari | H7: HK | J7: Total Pemakaian | K7: Harga / stn | M7: Total Biaya | N7: Rp / kg | O7: USD/MT
B8: 1 | C8: Steam | D8: ='Desember 2024'!AM252 -> 59.116634 | E8: Kg/MT CPO | F8: =$D$8*$O$3/1000 -> 67.834471 | G8: Ton/day | H8: =$O$4 -> 21 | J8: =$H$8*$F$8 -> 1424.5239 | K8: =Steam!H15 -> 183326.68 | M8: =$K$8*$J$8 -> 2.6115323e+08 | N8: =$M$8/($O$5*1000) -> 10.837656 | O8: =($M$8/$O$6)/$O$5 -> 0.69713471
B9: 2 | C9: Electrical
C10: For Process | D10: ='Desember 2024'!$AM$280 -> 6.8307775 | E10: kW/MT CPO | F10: =$D$10*$O$3 -> 7838.1015 | G10: kW/day | H10: =$O$4 -> 21 | I10: 0 | J10: =$H$10*$F$10 -> 164600.13 | K10: =[18]Electric!$L$5 -> 1550 | L10: 3666.6667 | M10: =($F$10*$H$10*$K$10)+($F$10*$I$10*$L$10) -> 2.551302e+08 | N10: =$M$10/($O$5*1000) -> 10.587705 | O10: =($M$10/$O$6)/$O$5 -> 0.68105655
C11: Cooling Tower | D11: ='Desember 2024'!$AM$278 -> 6.8299995 | E11: kW/MT CPO | F11: =$D$11*$O$3 -> 7837.2087 | G11: kW/day | H11: =$H$10 -> 21 | I11: 0 | J11: =$H$11*$F$11 -> 164581.38 | K11: =$K$10 -> 1550 | L11: 3666.6667 | M11: =($F$11*$H$11*$K$11)+($F$11*$I$11*$L$11) -> 2.5510114e+08 | N11: =$M$11/($O$5*1000) -> 10.586499 | O11: =($M$11/$O$6)/$O$5 -> 0.68097898
B12: 3 | C12: Water
C13: Make Up CT | D13: ='Desember 2024'!$AM$262 -> 46.313132 | E13: M3/day | F13: =$D$13 -> 46.313132 | G13: M3/day | H13: =$H$11 -> 21 | J13: =$H$13*$F$13 -> 972.57578 | K13: =WTP!H13 -> 16370.605 | M13: =$K$13*$J$13 -> 15921654 | N13: =$M$13/($O$5*1000) -> 0.66073627 | O13: =($M$13/$O$6)/$O$5 -> 0.042502011
B14: 4 | C14: Chemical Water
C15: EONBAC BC 3108 | D15: 0.4 | E15: Kg/day | F15: =$D$15 -> 0.4 | G15: Kg/day | H15: =$H$13 -> 21 | J15: =$H$15*$F$15 -> 8.4 | K15: 27240 | M15: =$K$15*$J$15 -> 228816 | N15: =$M$15/($O$5*1000) -> 0.0094956861 | O15: =($M$15/$O$6)/$O$5 -> 0.00061081218
C16: EONLINE T722 | D16: 0.66 | E16: Kg/day | F16: =$D$16 -> 0.66 | G16: Kg/day | H16: =$H$15 -> 21 | J16: =$H$16*$F$16 -> 13.86 | K16: 29120 | M16: =$K$16*$J$16 -> 403603.2 | N16: =$M$16/($O$5*1000) -> 0.016749219 | O16: =($M$16/$O$6)/$O$5 -> 0.0010773973
C17: EONLINE AG5770 | D17: 0.41 | E17: Kg/day | F17: =$D$17 -> 0.41 | G17: Kg/day | H17: =$H$15 -> 21 | J17: =$H$17*$F$17 -> 8.61 | K17: 117212 | M17: =$K$17*$J$17 -> 1009195.3 | N17: =$M$17/($O$5*1000) -> 0.041880821 | O17: =($M$17/$O$6)/$O$5 -> 0.0026939934
C18: EONScale T2511 | D18: 0.1 | E18: Kg/day | F18: =$D$18 -> 0.1 | G18: Kg/day | H18: =$H$16 -> 21 | J18: =$H$18*$F$18 -> 2.1 | K18: 45940 | M18: =$K$18*$J$18 -> 96474 | N18: =$M$18/($O$5*1000) -> 0.004003596 | O18: =($M$18/$O$6)/$O$5 -> 0.00025753223
B19: 5 | C19: Others
C20: Filter Cloth | D20: 0.33333333 | E20: Pcs/day | F20: =$D$20 -> 0.33333333 | G20: Pcs/day | H20: =$H$18 -> 21 | J20: =$H$20*$F$20 -> 7 | K20: 895000 | M20: =$K$20*$J$20 -> 6265000 | N20: =$M$20/($O$5*1000) -> 0.25999263 | O20: =($M$20/$O$6)/$O$5 -> 0.016724085
C21: Filter Bag 100 Microne | D21: 0.63253012 | E21: Pcs/day | F21: =$D$21 -> 0.63253012 | G21: Pcs/day | H21: =$H$20 -> 21 | J21: =$H$21*$F$21 -> 13.283133 | K21: 125000 | M21: =$K$21*$J$21 -> 1660391.6 | N21: =$M$21/($O$5*1000) -> 0.068904959 | O21: =($M$21/$O$6)/$O$5 -> 0.0044323272
M22: =SUM(M8:M21) -> 7.9696972e+08 | N22: =SUM(N8:N21) -> 33.073624 | O22: =SUM($O$8:$O$21) -> 2.1274684

Sheet SUMMARY HPP 
B2: Production Cost September
B3: Through Put CPO Proses (Ton/Day) | H3: TPD | I3: ='HPP REF '!$N$3 -> 1098.8155
B4: Working Day | F4: 1 | H4: Days | I4: ='HPP REF '!$N$4 -> 23
B5: Refined CPO ( Ton/month ) | H5: MTD | I5: =$I$4*$I$3 -> 25272.757
B6: Through Put RPO Proses (Ton/Day) | H6: TPD | I6: ='HPP FRACT'!$O$3 -> 1147.4684
B7: Working Day | H7: Days | I7: ='HPP FRACT'!$O$4 -> 21
B8: Fract RPO ( ton/month ) | H8: MTD | I8: =$I$7*$I$6 -> 24096.837
B9: KURS | H9: Rp/USD | I9: 15546
B10: No | C10: Items | D10: Description | G10: Rupiah | H10: Rp/Kg | I10: USD/MT
B11: I | C11: Production Cost | D11: ● | E11: Refining Cost | G11: ='HPP REF '!$M$48 -> 4.075111e+09 | H11: =$G$11/($I$5*1000) -> 161.24521 | I11: =(G11/$I$9)/$I$5 -> 10.372135
D12: ● | E12: Fractionation Cost | G12: ='HPP FRACT'!$M$22 -> 7.9696972e+08 | H12: =$G$12/($I$8*1000) -> 33.073624 | I12: =(G12/$I$9)/$I$8 -> 2.1274684
D13: ● | E13: Preventive Maintenance Cost | F13: 0 | G13: =MTC!$F$18*F13 -> 0 | H13: =$G$13/($I$5*1000) -> 0 | I13: =(G13/$I$9)/$I$5 -> 0
G14: =SUM(G11:$G$13) -> 4.8720807e+09 | H14: =SUM($H$11:$H$13) -> 194.31883 | I14: =SUM(I11:I13) -> 12.499603 | K14: =I14+I26 -> 35.025782
B16: II | C16: Port Cost | D16: ● | E16: Trucking Komoditi ke Kuala Tanjung | G16: =LOG!I8+LOG!I9+LOG!$I$10 -> 2.6239187e+09 | H16: =$G$16/($I$5*1000) -> 103.824 | I16: =($G$16/$I$9)/$I$5 -> 6.6785025
D17: ● | E17: Sewa Tank PTI Total Volume : 24.000 MT ( 5 Unit ) | F17: =F4 -> 1 | G17: =LOG!I11+LOG!I12+LOG!I13+LOG!$I$14*F17 -> 1886000000 | H17: =$G$17/($I$5*1000) -> 74.625812 | I17: =($G$17/$I$9)/$I$5 -> 4.8003224
D18: ● | E18: Instalasi & Pemanasan, Pompa, Surveyor dan Documen | G18: =LOG!I18+LOG!I19+LOG!I20+LOG!$I$21 -> 1.353811e+09 | H18: =$G$18/($I$5*1000) -> 53.568 | I18: =($G$18/$I$9)/$I$5 -> 3.4457738
D19: ● | E19: Finalty Over Capacity Tank | G19: =LOG!I15+LOG!I16+LOG!$I$17 -> 1.0780347e+09 | H19: =$G$19/($I$5*1000) -> 42.656 | I19: =($G$19/$I$9)/$I$5 -> 2.7438569
G20: =SUM($G$16:$G$19) -> 6.9417645e+09 | H20: =SUM($H$16:$H$19) -> 274.67381 | I20: =SUM($I$16:$I$19) -> 17.668456
B22: II | C22: Fix Cost | D22: ● | E22: Manpower Cost | F22: =F4 -> 1 | G22: =[18]MPC!$H$29*$F$22 -> 2.1846655e+09 | H22: =$G$22/($I$5*1000) -> 86.443499 | I22: =($G$22/$I$9)/$I$5 -> 5.5604978
D23: ● | E23: Admin OH Cost | F23: =F4 -> 1 | G23: =OH!G51*$F$23 -> 1.4360564e+09 | H23: =$G$23/($I$5*1000) -> 56.822308 | I23: =($G$23/$I$9)/$I$5 -> 3.655108
D24: ● | E24: Depresiasi Cost | F24: =F4 -> 1 | G24: =DEP!I9*$F$24 -> 4.1811848e+09 | H24: =$G$24/($I$5*1000) -> 165.44237 | I24: =($G$24/$I$9)/$I$5 -> 10.642118
D25: ● | E25: Amortisation of leasehold land Cost | F25: =F4 -> 1 | G25: =AMOR!$G$20*$F$25 -> 1.0484098e+09 | H25: =$G$25/($I$5*1000) -> 41.483792 | I25: =($G$25/$I$9)/$I$5 -> 2.6684544
G26: =SUM($G$22:$G$25) -> 8.8503165e+09 | H26: =SUM($H$22:$H$25) -> 350.19197 | I26: =SUM($I$22:$I$25) -> 22.526178 | K26: =I26+I14 -> 35.025782
B28: Total Production Cost | G28: =$G$26+$G$20+$G$14 -> 2.0664162e+10 | H28: =$H$26+$H$20+$H$14 -> 819.18461 | I28: =$I$26+$I$20+$I$14 -> 52.694237

Sheet Convert Gas
B3: CONVERT PEMAKAIAN GAS HP BOILER & MP BOILER
D4: 2024
C5: HP BOILER | F5: TOTAL CORRECTED VOLUME (Sm3) | K5: ENERGY MP BOILER (MMBTU) | L5: TOTAL GAS CONSUMPTION (MMBTU) | M5: PERCENTAGE
C6: UNCORRECTED VOLUME (UV) (Nm3) | D6: PRESS. Bar | E6: CORRECTED VOLUME (CV) (Sm3) | G6: Convert Sm3 to SCF | H6: VOLUME (MSCF) | I6: HEATING VALUE (BTU / SCF) | J6: ENERGY HP BOILER (MMBTU) | M6: HP Boiler | N6: MP Boiler
C7: 1 | D7: 2 | E7: 3 = 1 x 2 | F7: 4 = 3 | G7: 5 | H7: 6 = (4 x 5) / 1000 | I7: 7 | J7: 8 = (6 x 7) / 1000 | K7: 9 = 10 - 8 | L7: 10 | M7: 11 = 8 / 10 | N7: 12 = 9 / 10
B8: 1 | D8: 5 | E8: =C8*D8 -> 0 | F8: =E8 -> 0 | G8: 35.314667 | H8: =(F8*G8)/1000 -> 0 | I8: 1047.7934 | J8: =(H8*I8)/1000 -> 0 | K8: =L8-J8 -> 0 | L8: 0 | M8: =(J8/L8) -> #DIV/0! | N8: =K8/L8 -> #DIV/0!
B9: =B8+1 -> 2 | D9: 5 | E9: =C9*D9 -> 0 | F9: =E9 -> 0 | G9: 35.314667 | H9: =(F9*G9)/1000 -> 0 | I9: 1042.7042 | J9: =(H9*I9)/1000 -> 0 | K9: =L9-J9 -> 0.7969 | L9: 0.7969 | M9: =(J9/L9) -> 0 | N9: =K9/L9 -> 1
B10: =B9+1 -> 3 | C10: 159.69 | D10: 5 | E10: =C10*D10 -> 798.45 | F10: =E10 -> 798.45 | G10: 35.314667 | H10: =(F10*G10)/1000 -> 28.196996 | I10: 1044.8302 | J10: =(H10*I10)/1000 -> 29.461073 | K10: =L10-J10 -> 656.37333 | L10: 685.8344 | M10: =(J10/L10) -> 0.04295654 | N10: =K10/L10 -> 0.95704346
B11: =B10+1 -> 4 | C11: 788.24 | D11: 5 | E11: =C11*D11 -> 3941.2 | F11: =E11 -> 3941.2 | G11: 35.314667 | H11: =(F11*G11)/1000 -> 139.18217 | I11: 1050.3635 | J11: =(H11*I11)/1000 -> 146.19187 | K11: =L11-J11 -> 696.04741 | L11: 842.23928 | M11: =(J11/L11) -> 0.17357522 | N11: =K11/L11 -> 0.82642478
B12: =B11+1 -> 5 | C12: 3.33 | D12: 5 | E12: =C12*D12 -> 16.65 | F12: =E12 -> 16.65 | G12: 35.314667 | H12: =(F12*G12)/1000 -> 0.58798921 | I12: 1050.6498 | J12: =(H12*I12)/1000 -> 0.61777073 | K12: =L12-J12 -> 767.54333 | L12: 768.1611 | M12: =(J12/L12) -> 0.00080422027 | N12: =K12/L12 -> 0.99919578
B13: =B12+1 -> 6 | C13: 1356.95 | D13: 5 | E13: =C13*D13 -> 6784.75 | F13: =E13 -> 6784.75 | G13: 35.314667 | H13: =(F13*G13)/1000 -> 239.60119 | I13: 1051.3912 | J13: =(H13*I13)/1000 -> 251.91459 | K13: =L13-J13 -> 389.14956 | L13: 641.06415 | M13: =(J13/L13) -> 0.39296315 | N13: =K13/L13 -> 0.60703685
B14: =B13+1 -> 7 | C14: 4051.52 | D14: 5 | E14: =C14*D14 -> 20257.6 | F14: =E14 -> 20257.6 | G14: 35.314667 | H14: =(F14*G14)/1000 -> 715.3904 | I14: 1053.7683 | J14: =(H14*I14)/1000 -> 753.85573 | K14: =L14-J14 -> 105.66983 | L14: 859.52556 | M14: =(J14/L14) -> 0.87706028 | N14: =K14/L14 -> 0.12293972
B15: =B14+1 -> 8 | C15: 5815.62 | D15: 5 | E15: =C15*D15 -> 29078.1 | F15: =E15 -> 29078.1 | G15: 35.314667 | H15: =(F15*G15)/1000 -> 1026.8834 | I15: 1055.9121 | J15: =(H15*I15)/1000 -> 1084.2986 | K15: =L15-J15 -> -55.066247 | L15: 1029.2324 | M15: =(J15/L15) -> 1.0535022 | N15: =K15/L15 -> -0.053502249
B16: =B15+1 -> 9 | C16: 5220.53 | D16: 5 | E16: =C16*D16 -> 26102.65 | F16: =E16 -> 26102.65 | G16: 35.314667 | H16: =(F16*G16)/1000 -> 921.80639 | I16: 1058.5967 | J16: =(H16*I16)/1000 -> 975.82117 | K16: =L16-J16 -> 139.90533 | L16: 1115.7265 | M16: =(J16/L16) -> 0.87460607 | N16: =K16/L16 -> 0.12539393
B17: =B16+1 -> 10 | C17: 2188 | D17: 5 | E17: =C17*D17 -> 10940 | F17: =E17 -> 10940 | G17: 35.314667 | H17: =(F17*G17)/1000 -> 386.34246 | I17: 1055.6055 | J17: =(H17*I17)/1000 -> 407.82521 | K17: =L17-J17 -> 551.84729 | L17: 959.6725 | M17: =(J17/L17) -> 0.4249629 | N17: =K17/L17 -> 0.5750371
B18: =B17+1 -> 11 | C18: 1796.49 | D18: 5 | E18: =C18*D18 -> 8982.45 | F18: =E18 -> 8982.45 | G18: 35.314667 | H18: =(F18*G18)/1000 -> 317.21223 | I18: 1056.3096 | J18: =(H18*I18)/1000 -> 335.07431 | K18: =L18-J18 -> 538.27709 | L18: 873.3514 | M18: =(J18/L18) -> 0.38366494 | N18: =K18/L18 -> 0.61633506
B19: =B18+1 -> 12 | C19: 4866.75 | D19: 5 | E19: =C19*D19 -> 24333.75 | F19: =E19 -> 24333.75 | G19: 35.314667 | H19: =(F19*G19)/1000 -> 859.33828 | I19: 1051.5483 | J19: =(H19*I19)/1000 -> 903.63574 | K19: =L19-J19 -> 6.6809602 | L19: 910.3167 | M19: =(J19/L19) -> 0.99266084 | N19: =K19/L19 -> 0.0073391603
B20: =B19+1 -> 13 | C20: 6932.28 | D20: 5 | E20: =C20*D20 -> 34661.4 | F20: =E20 -> 34661.4 | G20: 35.314667 | H20: =(F20*G20)/1000 -> 1224.0558 | I20: 1053.7374 | J20: =(H20*I20)/1000 -> 1289.8334 | K20: =L20-J20 -> -53.700699 | L20: 1236.1327 | M20: =(J20/L20) -> 1.0434425 | N20: =K20/L20 -> -0.043442504
B21: =B20+1 -> 14 | C21: 6338.15 | D21: 5 | E21: =C21*D21 -> 31690.75 | F21: =E21 -> 31690.75 | G21: 35.314667 | H21: =(F21*G21)/1000 -> 1119.1483 | I21: 1054.6459 | J21: =(H21*I21)/1000 -> 1180.3051 | K21: =L21-J21 -> -24.066515 | L21: 1156.2386 | M21: =(J21/L21) -> 1.0208145 | N21: =K21/L21 -> -0.020814488
... B24: =B23+1 -> 17 | C24: 6388.24 | D24: 5 | E24: =C24*D24 -> 31941.2 | F24: =E24 -> 31941.2 | G24: 38.314667 | H24: =(F24*G24)/1000 -> 1223.8164 | I24: 1041.3329 | J24: =(H24*I24)/1000 -> 1274.4003 | K24: =L24-J24 -> -125.496 | L24: 1148.9043 | M24: =(J24/L24) -> 1.109231 | N24: =K24/L24 -> -0.10923103
B25: =B24+1 -> 18 | C25: 7607.66 | D25: 5 | E25: =C25*D25 -> 38038.3 | F25: =E25 -> 38038.3 | G25: 39.314667 | H25: =(F25*G25)/1000 -> 1495.4631 | I25: 1042.2141 | J25: =(H25*I25)/1000 -> 1558.5927 | K25: =L25-J25 -> -1558.5927 | M25: =(J25/L25) -> #DIV/0! | N25: =K25/L25 -> #DIV/0!
B26: =B25+1 -> 19 | C26: 6514.97 | D26: 5 | E26: =C26*D26 -> 32574.85 | F26: =E26 -> 32574.85 | G26: 40.314667 | H26: =(F26*G26)/1000 -> 1313.2442 | I26: 1042.5071 | J26: =(H26*I26)/1000 -> 1369.0664 | K26: =L26-J26 -> -1369.0664 | M26: =(J26/L26) -> #DIV/0! | N26: =K26/L26 -> #DIV/0!
B27: =B26+1 -> 20 | C27: 4942.41 | D27: 5 | E27: =C27*D27 -> 24712.05 | F27: =E27 -> 24712.05 | G27: 41.314667 | H27: =(F27*G27)/1000 -> 1020.9701 | I27: 1042.9853 | J27: =(H27*I27)/1000 -> 1064.8569 | K27: =L27-J27 -> -1064.8569 | M27: =(J27/L27) -> #DIV/0! | N27: =K27/L27 -> #DIV/0!
B28: =B27+1 -> 21 | C28: 3073.52 | D28: 5 | E28: =C28*D28 -> 15367.6 | F28: =E28 -> 15367.6 | G28: 42.314667 | H28: =(F28*G28)/1000 -> 650.27488 | I28: 1043.1149 | J28: =(H28*I28)/1000 -> 678.31139 | K28: =L28-J28 -> -678.31139 | M28: =(J28/L28) -> #DIV/0! | N28: =K28/L28 -> #DIV/0!
B29: =B28+1 -> 22 | D29: 5 | E29: =C29*D29 -> 0 | F29: =E29 -> 0 | G29: 42.314667 | H29: =(F29*G29)/1000 -> 0 | I29: 1042.5884 | J29: =(H29*I29)/1000 -> 0 | K29: =L29-J29 -> 0 | M29: =(J29/L29) -> #DIV/0! | N29: =K29/L29 -> #DIV/0!
B30: =B29+1 -> 23 | D30: 5 | E30: =C30*D30 -> 0 | F30: =E30 -> 0 | G30: 44.314667 | H30: =(F30*G30)/1000 -> 0 | I30: 1042.7497 | J30: =(H30*I30)/1000 -> 0 | K30: =L30-J30 -> 0 | M30: =(J30/L30) -> #DIV/0! | N30: =K30/L30 -> #DIV/0!
B31: =B30+1 -> 24 | D31: 5 | E31: =C31*D31 -> 0 | F31: =E31 -> 0 | G31: 45.314667 | H31: =(F31*G31)/1000 -> 0 | I31: 1042.2931 | J31: =(H31*I31)/1000 -> 0 | K31: =L31-J31 -> 0 | M31: =(J31/L31) -> #DIV/0! | N31: =K31/L31 -> #DIV/0!
B32: =B31+1 -> 25 | D32: 5 | E32: =C32*D32 -> 0 | F32: =E32 -> 0 | G32: 46.314667 | H32: =(F32*G32)/1000 -> 0 | I32: 1039.4114 | J32: =(H32*I32)/1000 -> 0 | K32: =L32-J32 -> 0 | M32: =(J32/L32) -> #DIV/0! | N32: =K32/L32 -> #DIV/0!
B33: =B32+1 -> 26 | D33: 5 | E33: =C33*D33 -> 0 | F33: =E33 -> 0 | G33: 47.314667 | H33: =(F33*G33)/1000 -> 0 | I33: 1039.4407 | J33: =(H33*I33)/1000 -> 0 | K33: =L33-J33 -> 0 | M33: =(J33/L33) -> #DIV/0! | N33: =K33/L33 -> #DIV/0!
B34: =B33+1 -> 27 | D34: 5 | E34: =C34*D34 -> 0 | F34: =E34 -> 0 | G34: 48.314667 | H34: =(F34*G34)/1000 -> 0 | I34: 1040.2491 | J34: =(H34*I34)/1000 -> 0 | K34: =L34-J34 -> 0 | M34: =(J34/L34) -> #DIV/0! | N34: =K34/L34 -> #DIV/0!
B35: =B34+1 -> 28 | D35: 5 | E35: =C35*D35 -> 0 | F35: =E35 -> 0 | G35: 49.314667 | H35: =(F35*G35)/1000 -> 0 | J35: =(H35*I35)/1000 -> 0 | K35: =L35-J35 -> 0 | M35: =(J35/L35) -> #DIV/0! | N35: =K35/L35 -> #DIV/0!
B36: =B35+1 -> 29 | D36: 5 | E36: =C36*D36 -> 0 | F36: =E36 -> 0 | G36: 50.314667 | H36: =(F36*G36)/1000 -> 0 | J36: =(H36*I36)/1000 -> 0 | K36: =L36-J36 -> 0 | M36: =(J36/L36) -> #DIV/0! | N36: =K36/L36 -> #DIV/0!
B37: =B36+1 -> 30 | D37: 5 | E37: =C37*D37 -> 0 | F37: =E37 -> 0 | G37: 51.314667 | H37: =(F37*G37)/1000 -> 0 | J37: =(H37*I37)/1000 -> 0 | K37: =L37-J37 -> 0 | M37: =(J37/L37) -> #DIV/0! | N37: =K37/L37 -> #DIV/0!
B38: Average | F38: =AVERAGE(F8:F37) -> 12674.528 | H38: =AVERAGE(H8:H37) -> 471.76255 | I38: =AVERAGE(I8:I37) -> 1047.1339 | J38: =AVERAGE(J8:J37) -> 494.65048 | K38: =AVERAGE(K8:K37) -> -12.578486 | L38: =AVERAGE(L8:L37) -> 850.71528 | M38: =AVERAGE(M8:M37) -> #DIV/0! | N38: =AVERAGE(N8:N37) -> #DIV/0!
B39: TOTAL | C39: =SUM(C8:C37) -> 76047.17 | E39: =SUM(E8:E37) -> 380235.85 | F39: =SUM(F8:F37) -> 380235.85 | H39: =SUM(H8:H37) -> 14152.877 | J39: =SUM(J8:J37) -> 14839.514
B40: Koreksi
B41: Total Setelah Koreksi | H41: =H39+H40 -> 14152.877 | J41: =J39+J40 -> 14839.514
C43: CONVERT HP Boiler from Utility
C44: =C39 -> 76047.17 | D44: m3 | F44: =C39*5 -> 380235.85 | G44: 9983.7
C45: 5 | D45: bar | F45: 21286.9 | G45: =G44-C39 -> -66063.47
...

Sheet Qty cons analysis
D2: Quantity Utility Consumption Analysis (based on Guarantee Utility Consumption)
D3: Refinery & Fractionation Plant
D4: Periode 01 s/d 31 Desember 2024
D5: Consumption | E5: UoM | F5: Budget | G5: Actual | H5: Under (Over) Budget | I5: Explanation Under / Over budget
D6: CPO Consume | E6: Kg | F6: 36359000 | G6: ='Desember 2024'!$AM$9 -> 25272757 | H6: =G6/F6 -> 0.69508944
D7: RbdPO Consume | E7: Kg | F7: 34458000 | G7: ='Desember 2024'!$AM$24 -> 24112447 | H7: =G7/F7 -> 0.69976339
D8: TOTAL ACTUAL CONSUMPTION
D9: Refinery
D10: Bleaching Earth to Poram Spec | E10: Kg | F10: 232362 | G10: ='Desember 2024'!$AM$74 -> 229303.91 | H10: =F10-G10 -> 3058.09
D11: Bleaching Earth to Branded Spec | E11: Kg | F11: 131651 | G11: ='Desember 2024'!$AM$80 -> 0 | H11: =F11-G11 -> 131651
D12: Phosporic Acid | E12: Kg | F12: 21815 | G12: ='Desember 2024'!$AM$82 -> 12772.944 | H12: =F12-G12 -> 9042.056
D13: Gas Consumption (MP Boiler) | E13: mmbtu | F13: 20978.28 | G13: ='Desember 2024'!$AM$244+'Desember 2024'!$AM$243 -> -50695.652 | H13: =F13-G13 -> 71673.932
D14: Gas Consumption (HP Boiler) | E14: mmbtu | F14: 3702.06 | G14: ='Desember 2024'!$AM$242 -> 76486.024 | H14: =F14-G14 -> -72783.964
D15: Cooling Water top up to Cooling Tower | E15: m3 | F15: 1441.26 | G15: ='Desember 2024'!$AM$259 -> 1008 | H15: =F15-G15 -> 433.26
D16: Steam | E16: Kg | F16: 8640000 | G16: ='Desember 2024'!$AM$249 -> 876420.07 | H16: =F16-G16 -> 7763579.9
D17: Power (Process Plant) | E17: Kwh | F17: 97275 | G17: ='Desember 2024'!$AM$274 -> 179728.38 | H17: =F17-G17 -> -82453.38
D18: Power (Cooling Tower) | E18: Kwh | F18: 69307 | G18: ='Desember 2024'!$AM$272 -> 752103.89 | H18: =F18-G18 -> -682796.89
D19: Fractionation
D20: Cooling Water top up to Cooling Tower | E20: m3 | F20: 2489 | G20: ='Desember 2024'!$AM$261 -> 1116 | H20: =F20-G20 -> 1373
D21: Steam | E21: Kg | F21: 2196000 | G21: ='Desember 2024'!$AM$251 -> 1425446.7 | H21: =F21-G21 -> 770553.3
D22: Power (Process Plant) | E22: Kwh | F22: 103680 | G22: ='Desember 2024'!$AM$279 -> 164706.76 | H22: =F22-G22 -> -61026.76
D23: Power (Cooling Tower) | E23: Kwh | F23: 27234 | G23: ='Desember 2024'!$AM$277 -> 164688 | H23: =F23-G23 -> -137454
D24: ACTUAL CONSUMPTION PER MT RAW MATERIAL
D25: Refinery
D26: Bleaching Earth to Poram Spec | E26: Kg/MT | F26: 9 | G26: =(G10/$G$6)*1000 -> 9.0731656 | H26: =F26-G26 -> -0.073165623
D27: Bleaching Earth to Branded Spec | E27: Kg/MT | F27: 18 | G27: =(G11/$G$6)*1000 -> 0 | H27: =F27-G27 -> 18
D28: Phosporic Acid | E28: Kg/MT | F28: 0.6 | G28: =(G12/$G$6)*1000 -> 0.50540366 | H28: =F28-G28 -> 0.094596335
D29: Gas Consumption (HP Boiler) | E29: Nm3/MT | F29: 4.2 | G29: =(G13/$G$6)*1000 -> -2.0059407 | H29: =F29-G29 -> 6.2059407 | I29: Gas Over dikarenakan kapasitas tidak tercapai
D30: Gas Consumption (HP Boiler) **) | E30: mmbtu/MT | F30: 0.147294 | G30: =(G14/$G$6)*1000 -> 3.0264218 | H30: =F30-G30 -> -2.8791278
D31: Cooling Water top up to Cooling Tower | E31: m3/MT | F31: 0.6 | G31: =(G15/$G$6)*1000 -> 0.039884845 | H31: =F31-G31 -> 0.56011515
D32: Steam | E32: Kg/MT | F32: 46 | G32: =(G16/$G$6)*1000 -> 34.678451 | H32: =F32-G32 -> 11.321549 | I32: Steam Refinery Over dikarenakan kapasitas tidak tercapai
D33: Power (Process Plant) | E33: Kwh/MT | F33: 4.3033333 | G33: =(G17/$G$6)*1000 -> 7.1115462 | H33: =F33-G33 -> -2.8082129 | I33: Power Over dikarenakan kapasitas tidak tercapai
D34: Power (Utility System/Chiller) | E34: Kwh/MT | F34: 7.3 | G34: =(G18/$G$6)*1000 -> 29.759471 | H34: =F34-G34 -> -22.459471
D35: Fractionation
D36: Cooling Water top up to Cooling Tower | E36: m3/MT | F36: 0.4 | G36: =(G20/$G$6)*1000 -> 0.044158221 | H36: =F36-G36 -> 0.35584178
D37: Steam | E37: Kg/MT | F37: 45 | G37: =(G21/$G$6)*1000 -> 56.402501 | H37: =F37-G37 -> -11.402501 | I37: Steam Over dikarenakan menggunakan 2 unit chiller
D38: Power (Process Plant) | E38: Kwh/MT | F38: 4.5 | G38: =(G22/$G$6)*1000 -> 6.5171663 | H38: =F38-G38 -> -2.0171663 | I38: Power Over dikarenakan kapasitas tidak tercapai
D39: Power (utility System/chiller ) | E39: Kwh/MT | F39: 4.1 | G39: =(G23/$G$6)*1000 -> 6.516424 | H39: =F39-G39 -> -2.416424
D42: - PMG II Commissioning
D43: - BE Achieve dengan pemakaian consume Bleaching Earth 7,80 Kg/MT
...

Sheet Utility
D2: UTILITY (GAS, STEAM, WATER & POWER) REPORT
D3: PT. INDUSTRI NABATI LESTARI
D5: Periode 01 s/d 31 Desember 2024
D6: No | E6: Item | F6: Norma | G6: UoM | H6: Desember | K6: Consume CPO ( MT ) | L6: Remaks
H7: Budget | I7: Actual | J7: Percentage Act.
E9: Total Feed Raw Material CPO | K9: 29045
D10: 1. | E10: GAS CONSUMPTION
E11: Incoming *base on INL | G11: mmbtu | I11: ='Desember 2024'!$AM$240 -> 25913.808
E12: Incoming *base on Pertagas | F12: 1460.001 | G12: mmbtu | H12: 24680.34 | I12: ='Desember 2024'!$AM$238 -> 25790.069 | J12: =I12/H12 -> 1.0449641 | K12: =I12/K9 -> 0.88793489
E13: Distribution to
E14: HP Boiler Refinery | G14: mmbtu | H14: 3702.06 | I14: ='Desember 2024'!$AM$242 -> 76486.024 | J14: =I14/H14 -> 20.660396 | K14: =I14/K9 -> 2.6333628
E15: MP Boiler | G15: mmbtu | H15: 22143.74 | I15: =I12-$I$14 -> -50695.955 | J15: =I15/H15 -> -2.2894035 | K15: =I15/K9 -> -1.745428
E16: Total | G16: mmbtu | H16: =H12 -> 24680.34 | I16: =I14+I12 -> 102276.09 | J16: =I16/H16 -> 4.144031 | K16: =SUM(K14+K15) -> 0.88793489
D17: 2. | E17: STEAM CONSUMPTION
E18: Incoming | G18: Kg | H18: =480*'Desember 2024'!AM6 -> 11040 | I18: ='Desember 2024'!$AM$247 -> 2568027.3 | J18: =I18/H18 -> 232.61117 | K18: =I18/$K$9 -> 88.41547
E19: Distribution to | K19: =I19/$K$9 -> 0
E20: Refinery | F20: < 28 | G20: Kg | H20: 3240000 | I20: ='Desember 2024'!$AM$249 -> 876420.07 | J20: =I20/H20 -> 0.27050002 | K20: =I20/$K$9 -> 30.174559
E21: Fractionation | F21: < 35 | G21: Kg | H21: 2196000 | I21: ='Desember 2024'!$AM$251 -> 1425446.7 | J21: =I21/H21 -> 0.64911052 | K21: =I21/$K$9 -> 49.07718
E22: Others | F22: 106000 | G22: Kg | H22: 3204000 | I22: ='Desember 2024'!$AM$253 -> 460412.01 | J22: =I22/H22 -> 0.14369913 | K22: =I22/$K$9 -> 15.851679
E23: Total | G23: Kg | H23: =H20+H21+H22 -> 8640000 | I23: =SUM(I20:I22) -> 2762278.8 | J23: =I23/H23 -> 0.31970819 | K23: =I23/$K$9 -> 95.103418
D24: 3. | E24: WATER CONSUMPTION
E25: Incoming Raw Water | G25: m3 | H25: 18117.18 | I25: =SUM(I26:$I$27) -> 18195 | J25: =I25/H25 -> 1.0042954 | K25: =I25/$K$9 -> 0.62644173
E26: - Suplay To RO Product | I26: ='Desember 2024'!$AM$263 -> 7710 | K26: =I26/$K$9 -> 0.26545016
E27: - Suplay To Proses dan Sanitary | I27: =SUM(I29:$I$31) -> 10485 | K27: =I27/$K$9 -> 0.36099156
E28: Rincian Outgoing Proses | K28: =I28/$K$9 -> 0
E29: Softener Product (to Refinery) | F29: < 0,04 | G29: m3 | H29: 1441.26 | I29: ='Desember 2024'!$AM$259 -> 1008 | J29: =I29/H29 -> 0.69938804 | K29: =I29/$K$9 -> 0.034704768
E30: Softener Product (to Fractionation) | F30: < 0,13 | G30: m3 | H30: 2489.58 | I30: ='Desember 2024'!$AM$261 -> 1116 | J30: =I30/H30 -> 0.44826838 | K30: =I30/$K$9 -> 0.038423137
E31: Others | G31: m3 | H31: 14186.34 | I31: ='Desember 2024'!$AM$264 -> 8361 | J31: =I31/H31 -> 0.58936977 | K31: =I31/$K$9 -> 0.28786366
E32: Total | G32: m3 | H32: =H29+H30+H31 -> 18117.18 | I32: =SUM(I26:I27) -> 18195 | J32: =I32/H32 -> 1.0042954 | K32: =I32/$K$9 -> 0.62644173
D33: 4 | E33: POWER CONSUMPTION
E34: Incoming
E35: PLN *base on BA Kinra | G35: Kwh | H35: 538199 | I35: ='Desember 2024'!$AM$269 -> 504.24 | J35: =I35/H35 -> 0.00093690252 | K35: =I35/$K$9 -> 0.017360647
E36: Outgoing | K36: =I36/$K$9 -> 0
E37: - Physical Refinery Plant | F37: 10946.3 | G37: Kwh | H37: 97275 | I37: ='Desember 2024'!$AM$274 -> 179728.38 | J37: =I37/H37 -> 1.8476318 | K37: =I37/$K$9*1000 -> 6187.9284
E38: - Refinery - Utility / Chiller | F38: 18374.4 | G38: Kwh | H38: 69307 | I38: ='Desember 2024'!$AM$272 -> 752103.89 | J38: =I38/H38 -> 10.851774 | K38: =I38/$K$9*1000 -> 25894.436
E39: - Refinery - Utilities | F39: 11.81 | G39: Kwh | H39: 212 | I39: ='Desember 2024'!$AM$282 -> 0 | J39: =I39/H39 -> 0 | K39: =I39/$K$9*1000 -> 0
E40: - Dry Fractionation Plant | F40: 11201.3 | G40: Kwh | H40: 103680 | I40: ='Desember 2024'!$AM$279 -> 164706.76 | J40: =I40/H40 -> 1.5886069 | K40: =I40/$K$9*1000 -> 5670.744
E41: - Utility Chiller | F41: 10272 | G41: Kwh | H41: 27234 | I41: ='Desember 2024'!$AM$277 -> 164688 | J41: =I41/H41 -> 6.0471469 | K41: =I41/$K$9*1000 -> 5670.0981
E42: - Lighting - Refinery & Dry Fractionation | F42: 241.12 | G42: Kwh | H42: 4581 | I42: ='Desember 2024'!$AM$283 -> 0 | J42: =I42/H42 -> 0 | K42: =I42/$K$9*1000 -> 0
D44: Note untuk Power Consumption
...

Sheet Prod
B2: MONTHLY PRODUCTION REPORT PMG II
B3: PT. INDUSTRI NABATI LESTARI
B4: Periode 01 s/d 31 Desember 2024
B5: NO | C5: Item | D5: Unit | E5: Desember | H5: Remaks
E6: Budget | F6: Actual | G6: Percentage Act.
B7: 1. | C7: PRODUCTION
C8: Refinery Plant
C9: Running Days | D9: Days | E9: 18 | F9: ='Desember 2024'!$AM$6 -> 23 | G9: =(F9/E9) -> 1.2777778 | H9: Tercapai
C10: CPO Incoming | D10: Kg
C11: Total CPO Consume | D11: Kg | E11: 36359000 | F11: =F12+F13 -> 25272757 | G11: =(F11/E11) -> 0.69508944 | H11: Tidak Tercapai
C12: CPO Consume Poram | F12: ='Desember 2024'!$AM$11 -> 25272757
C13: CPO Consume Brand | F13: ='Desember 2024'!$AM$12 -> 0
C14: - Avg. FFA | D14: % | E14: 5 | F14: ='Desember 2024'!$AM$13 -> 3.3336957 | G14: =(F14/E14) -> 0.66673913
C15: - Avg. Moist & Impurities | D15: % | E15: 0.5 | F15: ='Desember 2024'!$AM$14 -> 0.36391304 | G15: =(F15/E15) -> 0.72782609
C16: - Avg. DOBI | D16: % | E16: 22.2 | F16: ='Desember 2024'!AM15 -> 1.8452174 | G16: =(F16/E16) -> 0.083117901
C17: Product
C18: RBDPO | D18: Kg | E18: 34458000 | F18: ='Desember 2024'!$AM$19 -> 24389568 | G18: =(F18/E18) -> 0.70780568
C19: PFAD | D19: Kg | E19: 1636000 | F19: ='Desember 2024'!$AM$20 -> 1089130 | G19: =(F19/E19) -> 0.66572738
C21: Fraksinasi Plant
C22: Total Proses RBDPO | D22: Kg | E22: =E25+E38+E43 -> 31417000 | F22: ='Desember 2024'!$AM$28 -> 24096837 | G22: =(F22/E22) -> 0.76699994 | H22: Tidak Tercapai
C23: Total Olah RBDPO ( Feed ) | D23: Kg | E23: =E25+E38+E43 -> 31417000 | F23: ='Desember 2024'!$AM$24 -> 24112447 | G23: =(F23/E23) -> 0.7674968 | H23: Tidak Tercapai
C24: Fractionation Olein IV 56
C25: RBDPO Consume | D25: Kg | E25: =E26+E27 -> 7883000 | F25: =F26+F27 -> 7003508 | G25: =(F25/E25) -> 0.88843182 | H25: Tercapai
C26: Olein IV 56 | D26: Kg | E26: 6464000 | F26: ='Desember 2024'!$AM$32 -> 5583694 | G26: =(F26/E26) -> 0.86381405 | H26: Tercapai
C27: Stearin | D27: Kg | E27: 1419000 | F27: ='Desember 2024'!$AM$33 -> 1419814 | G27: =(F27/E27) -> 1.0005736 | H27: Tercapai
C28: Fractionation Olein IV 57 ( Bulk )
C29: RBDPO Consume | D29: Kg | E29: 0
C30: Olein IV 57 | D30: Kg | E30: 0 | F30: 0 | G30: 0
C31: Stearin | D31: Kg | E31: 0
C32: Fractionation Olein IV 57 ( Retail )
C33: CPO | D33: Kg | E33: 1812101.9 | G33: =(F33/E33)*100 -> 0
C34: RBDPO Consume | D34: Kg | E34: =E35+E36 -> 3040000 | F34: =F35+F36 -> 0 | G34: =(F34/E34)*100 -> 0 | H34: Tidak Produksi
C35: Olein IV 57 | D35: Kg | E35: 2280000 | G35: =(F35/E35)*100 -> 0 | H35: Tidak Produksi
C36: Stearin | D36: Kg | E36: 760000 | G36: =(F36/E36)*100 -> 0 | H36: Tidak Produksi
C37: Fractionation Olein IV 58
C38: RBDPO Consume | D38: Kg | E38: =E39+E40 -> 21429000 | F38: =F39+F40 -> 16973017 | G38: =(F38/E38)*100 -> 79.205829 | H38: Tidak Tercapai
C39: Olein IV 58 | D39: Kg | E39: 15000000 | F39: ='Desember 2024'!$AM$45 -> 11987575 | G39: =(F39/E39)*100 -> 79.917167 | H39: Tidak Tercapai
C40: Stearin | D40: Kg | E40: 6429000 | F40: ='Desember 2024'!$AM$46 -> 4985442 | G40: =(F40/E40)*100 -> 77.54615 | H40: Tidak Tercapai
C41: Fractionation Olein IV 60
C42: CPO | E42: 2234607.2 | F42: 0 | G42: =(F42/E42)*100 -> 0
...

Sheet OIP Refinery 
B4: Oil In Plant (OIP) Refinery | I4: DESEMBER | J4: OIP | M4: TK131 RPO | P4: TK132 RPO | S4: TOTAL STOK RPO DI PLANT
B5: Vessel | C5: Operating Volume (m3) | D5: Oil Density (kg/m3) | E5: MT | F5: Level yg diisi | G5: Actual OIP (Kg) | I5: Tanggal | J5: Opening Stock | K5: Closing Stock | L5: balance stok | M5: Opening Stock | N5: Closing Stock | O5: CONSUMP stok | P5: Opening Stock | Q5: Closing Stock | R5: CONSUMP stok
B6: 2MX312 | C6: 5.67 | D6: 850 | E6: =C6*D6/1000 -> 4.8195 | F6: 0 | G6: =(F6*E6/100)*1000 -> 0 | I6: 45627
B7: 2VE611A | C7: 47.22 | D7: 850 | E7: =C7*D7/1000 -> 40.137 | F7: 0 | G7: =(F7*E7/100)*1000 -> 0 | I7: 45628
B8: 2VE611B | C8: 47.22 | D8: 850 | E8: =C8*D8/1000 -> 40.137 | F8: 0 | G8: =(F8*E8/100)*1000 -> 0 | I8: 45629
B9: 2VE612 | C9: 35.68 | D9: 850 | E9: =C9*D9/1000 -> 30.328 | F9: 0 | G9: =(F9*E9/100)*1000 -> 0 | I9: 45630 | K9: 308515.38
B10: 2VE661 | C10: 10.8 | D10: 850 | E10: =C10*D10/1000 -> 9.18 | F10: 0 | G10: =(F10*E10/100)*1000 -> 0 | I10: 45631 | J10: 308515
B11: FL621 | C11: 10.1 | D11: 850 | E11: =C11*D11/1000 -> 8.585 | F11: 0 | G11: =(F11*E11/100)*1000 -> 0 | I11: 45632 | J11: 308515 | K11: 284092 | L11: =J11-K11 -> 24423
B12: FL622 | C12: 10.1 | D12: 850 | E12: =C12*D12/1000 -> 8.585 | F12: 0 | G12: =(F12*E12/100)*1000 -> 0 | I12: 45633 | J12: 284092 | K12: 307785 | L12: =J12-K12 -> -23693
B13: FL623 | C13: 10.1 | D13: 850 | E13: =C13*D13/1000 -> 8.585 | F13: 0 | G13: =(F13*E13/100)*1000 -> 0 | I13: 45634 | J13: 307798 | K13: 299017 | L13: =J13-K13 -> 8781 | N13: 0 | Q13: 174609
B14: FL624 | C14: 10.1 | D14: 850 | E14: =C14*D14/1000 -> 8.585 | F14: 0 | G14: =(F14*E14/100)*1000 -> 0 | I14: 45635 | J14: 299017 | K14: 305518 | L14: =J14-K14 -> -6501 | N14: 44191 | P14: 174609 | Q14: 38852 | R14: =P14-Q14 -> 135757 | S14: =R14+O14+L14 -> 129256
B15: FL625 | C15: 10.1 | D15: 850 | E15: =C15*D15/1000 -> 8.585 | F15: 0 | G15: =(F15*E15/100)*1000 -> 0 | I15: 45636 | J15: 305518 | K15: 307138 | L15: =J15-K15 -> -1620 | M15: 44191 | N15: 405272 | O15: =M15-N15 -> -361081 | P15: 38852 | Q15: 38852 | R15: =P15-Q15 -> 0 | S15: =R15+O15+L15 -> -362701
B16: 2VE701 | C16: 72.13 | D16: 850 | E16: =C16*D16/1000 -> 61.3105 | F16: 40.8 | G16: =(F16*E16/100)*1000 -> 25014.684 | I16: 45637 | J16: 307138 | K16: 306411 | L16: =J16-K16 -> 727
B17: 2VE751 | C17: 4.28 | D17: 860 | E17: =C17*D17/1000 -> 3.6808 | F17: 50 | G17: =(F17*E17/100)*1000 -> 1840.4 | I17: 45638 | J17: 306411 | K17: 304056 | L17: =J17-K17 -> 2355
B18: 2HE721A (tube) | C18: 10 | D18: 810 | E18: =C18*D18/1000 -> 8.1 | F18: 100 | G18: =(F18*E18/100)*1000 -> 8100 | I18: 45639 | J18: 304056 | K18: 287956 | L18: =J18-K18 -> 16100
B19: 2HE721A (shell) | C19: 21.8 | D19: 800 | E19: =C19*D19/1000 -> 17.44 | F19: 60 | G19: =(F19*E19/100)*1000 -> 10464 | I19: 45640 | J19: 287956 | K19: 270583 | L19: =J19-K19 -> 17373
