Workbook

Sheet 2020
B2: YEARLY PRODUCTION SUMMARY -TAHUN 2020
B5: in MT | F5: 2020 | S5: Grand Total
B6: ACTUAL PRODUCTION | F6: 20 | G6: 29 | H6: 31 | I6: 29 | J6: 22 | K6: 30 | L6: 23 | M6: 17 | N6: 22 | O6: 13 | P6: 17 | Q6: 31 | S6: =SUM(F6:Q6) -> 284
B7: Product | D7: Budget | E7: Actual | F7: Januari | G7: Februari | H7: Maret | I7: April | J7: Mei | K7: Juni | L7: Juli | M7: Agustus | N7: September | O7: Oktober | P7: November | Q7: Desember | T7: in Kg
B8: Total CPO & COL Consume | D8: 1 | E8: 1 | F8: =SUM(F9:F10) -> 31386.719 | G8: =SUM(G9:G10) -> 47885.813 | H8: =SUM(H9:H10) -> 45905.106 | I8: =SUM(I9:I10) -> 54213.038 | J8: =SUM(J9:J10) -> 36539.132 | K8: =SUM(K9:K10) -> 51486.064 | L8: =SUM(L9:L10) -> 32365.656 | M8: =SUM(M9:M10) -> 18178.235 | ... Q8: =SUM(Q9:Q10) -> 44557.177 | S8: =SUM(F8:Q8) -> 423245.81 | T8: =S8*1000 -> 4.2324581e+08 | U8: =S8/S6 -> 1490.3022
B9: - CPO Consume | F9: ='Monthly-Prod'!E25/1000 -> 31386.719 | G9: ='Monthly-Prod'!F25/1000 -> 47885.813 | H9: ='Monthly-Prod'!G25/1000 -> 45905.106 | I9: ='Monthly-Prod'!H25/1000 -> 54213.038 | J9: ='Monthly-Prod'!I25/1000 -> 36539.132 | K9: ='Monthly-Prod'!J25/1000 -> 51486.064 | L9: ='Monthly-Prod'!K25/1000 -> 31253.915 | M9: ='Monthly-Prod'!L25/1000 -> 17543.224 | ... Q9: ='Monthly-Prod'!P25/1000 -> 42842.172 | S9: =SUM(F9:Q9) -> 418577.3
B10: - COL Consume | F10: 0 | G10: 0 | H10: 0 | I10: 0 | J10: 0 | K10: 0 | L10: ='Monthly-Prod'!K26/1000 -> 1111.741 | M10: ='Monthly-Prod'!L26/1000 -> 635.011 | N10: ='Monthly-Prod'!M26/1000 -> 349.232 | O10: ='Monthly-Prod'!N26/1000 -> 618.256 | P10: ='Monthly-Prod'!O26/1000 -> 239.26252 | Q10: ='Monthly-Prod'!P26/1000 -> 1715.005 | S10: =SUM(F10:Q10) -> 4668.5075
B11: Total RBDPO Refinery
B12: - Poram & Branded Spec | D12: 0.942 | E12: =S12/S8 -> 0.94576361 | F12: ='Monthly-Prod'!E31/1000 -> 29721.7 | G12: ='Monthly-Prod'!F31/1000 -> 45410 | H12: ='Monthly-Prod'!G31/1000 -> 43605.3 | I12: ='Monthly-Prod'!H31/1000 -> 51512.461 | J12: ='Monthly-Prod'!I31/1000 -> 34773.259 | K12: ='Monthly-Prod'!J31/1000 -> 48874.8 | L12: ='Monthly-Prod'!K31/1000 -> 30439.289 | M12: ='Monthly-Prod'!L31/1000 -> 17113.976 | ... Q12: ='Monthly-Prod'!P31/1000 -> 41854.3 | S12: =SUM(F12:Q12) -> 400290.49 | T12: =S12*1000 -> 400290489
B13: Total RBDPO Consume to Fractionation | T13: =T12/T8*100 -> 94.576361
B14: - Poram Spec (IV 56) | F14: =SUM(F17,F20) -> 28475.438 | G14: =SUM(G17,G20) -> 34911.29 | H14: =SUM(H17,H20) -> 42598.542 | I14: =SUM(I17,I20) -> 30611.75 | J14: =SUM(J17,J20) -> 21950.703 | K14: =SUM(K17,K20) -> 41356.225 | L14: =SUM(L17,L20) -> 24638.015 | M14: =SUM(M17,M20) -> 15187.927 | ... Q14: =SUM(Q17,Q20) -> 37173.36 | S14: =SUM(F14:Q14) -> 322080.16
B15: - Branded Spec (IV 60) | F15: =SUM(F18,F21) -> 0 | G15: =SUM(G18,G21) -> 102.527 | H15: =SUM(H18,H21) -> 654.915 | I15: =SUM(I18,I21) -> 1120 | J15: =SUM(J18,J21) -> 1196.278 | K15: =SUM(K18,K21) -> 1512.3 | L15: =SUM(L18,L21) -> 279.588 | M15: =SUM(M18,M21) -> 1282.62 | ... Q15: =SUM(Q18,Q21) -> 2213.72 | S15: =SUM(F15:Q15) -> 13483.823 | T15: =S14+S15 -> 335563.98
B16: Total Olein
B17: - Poram Spec (IV 56) | D17: 0.82 | E17: =S17/S14 -> 0.82677121 | F17: ='Monthly-Prod'!E35/1000 -> 23485.058 | G17: ='Monthly-Prod'!F35/1000 -> 28896.63 | H17: ='Monthly-Prod'!G35/1000 -> 35239.042 | I17: ='Monthly-Prod'!H35/1000 -> 25269.358 | J17: ='Monthly-Prod'!I35/1000 -> 18191.369 | K17: ='Monthly-Prod'!J35/1000 -> 34175.133 | L17: ='Monthly-Prod'!K35/1000 -> 20368.572 | M17: ='Monthly-Prod'!L35/1000 -> 12564.411 | ... Q17: ='Monthly-Prod'!P35/1000 -> 30739.375 | S17: =SUM(F17:Q17) -> 266286.6 | T17: =S17*1000 -> 266286599
B18: - Branded Spec (IV 60) | D18: 0.58 | E18: =S18/S15 -> 0.52473724 | F18: 0 | G18: ='Monthly-Prod'!F39/1000 -> 49.027 | H18: ='Monthly-Prod'!G39/1000 -> 358.865 | I18: ='Monthly-Prod'!H39/1000 -> 575.812 | J18: ='Monthly-Prod'!I39/1000 -> 602.223 | K18: ='Monthly-Prod'!J39/1000 -> 731.845 | L18: ='Monthly-Prod'!K39/1000 -> 140.988 | M18: ='Monthly-Prod'!L39/1000 -> 640.32 | N18: ='Monthly-Prod'!M39/1000 -> 1001.687 | ... Q18: ='Monthly-Prod'!P39/1000 -> 1285.73 | S18: =SUM(F18:Q18) -> 7075.464 | T18: =S18*1000 -> 7075464 | U18: =T17+T18 -> 273362063
B19: Total Stearin
B20: - Stearin | D20: 0.18 | E20: =S20/S14 -> 0.17322879 | F20: ='Monthly-Prod'!E36/1000 -> 4990.38 | G20: ='Monthly-Prod'!F36/1000 -> 6014.66 | H20: ='Monthly-Prod'!G36/1000 -> 7359.5 | I20: ='Monthly-Prod'!H36/1000 -> 5342.392 | J20: ='Monthly-Prod'!I36/1000 -> 3759.334 | K20: ='Monthly-Prod'!J36/1000 -> 7181.092 | L20: ='Monthly-Prod'!K36/1000 -> 4269.443 | M20: ='Monthly-Prod'!L36/1000 -> 2623.516 | ... Q20: ='Monthly-Prod'!P36/1000 -> 6433.985 | S20: =SUM(F20:Q20) -> 55793.557 | T20: =S20+S21 -> 62201.916
B21: - Soft Stearin (IV 38) | D21: 0.42 | E21: =S21/S15 -> 0.47526276 | F21: 0 | G21: ='Monthly-Prod'!F40/1000 -> 53.5 | H21: ='Monthly-Prod'!G40/1000 -> 296.05 | I21: ='Monthly-Prod'!H40/1000 -> 544.188 | J21: ='Monthly-Prod'!I40/1000 -> 594.055 | K21: ='Monthly-Prod'!J40/1000 -> 780.455 | L21: ='Monthly-Prod'!K40/1000 -> 138.6 | M21: ='Monthly-Prod'!L40/1000 -> 642.3 | N21: ='Monthly-Prod'!M40/1000 -> 1041.698 | ... Q21: ='Monthly-Prod'!P40/1000 -> 927.99 | S21: =SUM(F21:Q21) -> 6408.359
B22: PFAD - by Product | D22: 0.05 | E22: =S22/S8 -> 0.046788788 | F22: ='Monthly-Prod'!E32/1000 -> 1457.818 | G22: ='Monthly-Prod'!F32/1000 -> 2122.264 | H22: ='Monthly-Prod'!G32/1000 -> 1980.427 | I22: ='Monthly-Prod'!H32/1000 -> 2269.639 | J22: ='Monthly-Prod'!I32/1000 -> 1540.632 | K22: ='Monthly-Prod'!J32/1000 -> 2224.235 | L22: ='Monthly-Prod'!K32/1000 -> 1620.897 | M22: ='Monthly-Prod'!L32/1000 -> 910.72957 | ... Q22: ='Monthly-Prod'!P32/1000 -> 2372.695 | S22: =SUM(F22:Q22) -> 19803.159 | T22: =S22*1000 -> 19803159
B23: Loss / Waste | D23: 0.008 | E23: =S23/S8 -> 0.0074475974 | F23: =F8-SUM(F12,F22) -> 207.201 | G23: =G8-SUM(G12,G22) -> 353.549 | H23: =H8-SUM(H12,H22) -> 319.379 | I23: =I8-SUM(I12,I22) -> 430.938 | J23: =J8-SUM(J12,J22) -> 225.241 | K23: =K8-SUM(K12,K22) -> 387.029 | L23: =L8-SUM(L12,L22) -> 305.47 | M23: =M8-SUM(M12,M22) -> 153.52943 | ... Q23: =Q8-SUM(Q12,Q22) -> 330.182 | S23: =SUM(F23:Q23) -> 3152.1644 | T23: =T22/T8*100 -> 4.6788788
F26: 2020 | S26: Grand Total
B27: CHEMICAL CONSUMPTION | F27: 20 | G27: 29 | H27: 31 | I27: 29 | J27: 22 | K27: 30 | L27: 23 | M27: 17 | N27: 22 | O27: 13 | P27: 17 | Q27: 31 | S27: =SUM(F27:Q27) -> 284
F28: Januari | G28: Februari | H28: Maret | I28: April | J28: Mei | K28: Juni | L28: Juli | M28: Agustus | N28: September | O28: Oktober | P28: November | Q28: Desember
B29: Bleaching Earth | C29: Budget | D29: Actual
B30: - BE to Poram & Branded | C30: =(8+18)/2 -> 13 | D30: =S30/S8 -> 9.4817666 | E30: Kg/MT | F30: 248367 | G30: 387087 | H30: 339582 | I30: 402582 | J30: 292206 | K30: 443004 | L30: 286948 | M30: 173609 | N30: 232892 | O30: 180464 | P30: 410877 | Q30: 615500 | S30: =SUM(F30:Q30) -> 4013118
B31: *budget diambil dari rata-rata consume BE Poram dan Branded
B32: Phosporic Acid | C32: 0.55 | D32: =S32/S8 -> 0.53585074 | E32: Kg/MT | F32: 15430.7 | G32: 24848.97 | H32: 22106.41 | I32: 25638.8 | J32: 18388 | K32: 26661.8 | L32: 16921.8 | M32: 9616 | N32: 11826.7 | O32: 8847.8 | P32: 17110.8 | Q32: 29398.8 | S32: =SUM(F32:Q32) -> 226796.58
F36: 2020 | S36: Grand Total
B37: WASTE | F37: 20 | G37: 29 | H37: 31 | I37: 29 | J37: 22 | K37: 30 | L37: 23 | M37: 17 | N37: 22 | O37: 13 | P37: 17 | Q37: 31 | S37: =SUM(F37:Q37) -> 284
F38: Januari | G38: Februari | H38: Maret | I38: April | J38: Mei | K38: Juni | L38: Juli | M38: Agustus | N38: September | O38: Oktober | P38: November | Q38: Desember
C39: Budget | D39: Actual
B40: Spent Bleaching Earth | C40: 0.22 | D40: =S40 -> 0.2171425 | E40: OC | F40: ='Monthly-Prod'!E55% -> 0.2172 | G40: ='Monthly-Prod'!F55% -> 0.2191 | H40: ='Monthly-Prod'!G55% -> 0.2205 | I40: ='Monthly-Prod'!H55% -> 0.2199 | J40: ='Monthly-Prod'!I55% -> 0.2207 | K40: ='Monthly-Prod'!J55% -> 0.2202 | L40: ='Monthly-Prod'!K55% -> 0.221 | M40: ='Monthly-Prod'!L55% -> 0.2215 | ... Q40: ='Monthly-Prod'!P55% -> 0.2113 | S40: =AVERAGE(F40:Q40) -> 0.2171425
F41: =F30+(F40*F30) -> 302312.31 | G41: =G30+(G40*G30) -> 471897.76 | H41: =H30+(H40*H30) -> 414459.83 | I41: =I30+(I40*I30) -> 491109.78 | J41: =J30+(J40*J30) -> 356695.86 | K41: =K30+(K40*K30) -> 540553.48 | L41: =L30+(L40*L30) -> 350363.51 | M41: =M30+(M40*M30) -> 212063.39 | ... Q41: =Q30+(Q40*Q30) -> 745555.15 | S41: =SUM(F41:Q41) -> 4883317.1
B43: Effluent | D43: =S43/S93 -> 0.10579604 | E43: Raw Water | F43: 1237 | G43: 1220 | H43: 1461 | I43: 1138 | J43: 1143 | K43: 1104 | L43: 1279 | M43: 663 | N43: 0 | O43: 1574 | P43: 3337 | Q43: 5311 | S43: =SUM(F43:Q43) -> 19467
B48: YEARLY UTILITY CONSUMPTION DETAILS - Tahun 2020
F50: 2020 | S50: Grand Total
B51: UTILITY CONSUMPTION PER DAY | F51: 20 | G51: 29 | H51: 31 | I51: 29 | J51: 22 | K51: 30 | L51: 23 | M51: 17 | N51: 22 | O51: 13 | P51: 17 | Q51: 31 | S51: =SUM(F51:Q51) -> 284
F52: Januari | G52: Februari | H52: Maret | I52: April | J52: Mei | K52: Juni | L52: Juli | M52: Agustus | N52: September | O52: Oktober | P52: November | Q52: Desember
B53: Gas Consumption | D53: Actual
B54: Total | D54: =S54/S51 -> 1265.9037 | E54: mmbtu/day | F54: 25619.432 | G54: 35150.354 | H54: 38747.294 | I54: 35200.464 | J54: 30010.421 | K54: 42046.553 | L54: 28190.715 | M54: 20723.92 | N54: 25451.31 | O54: 16839.501 | P54: 22736.12 | Q54: 38800.562 | S54: =SUM(F54:Q54) -> 359516.64
...

Sheet Monthly-Prod
B2: YEARLY PRODUCTION REPORT
B3: PT. INDUSTRI NABATI LESTARI
B5: No. | C5: ITEM | D5: UoM | E5: JAN | F5: FEB | G5: MAR | H5: APR | I5: MEI | J5: JUN | K5: JUL | L5: AUGUST | M5: SEPT | N5: OKT | O5: NOV | P5: DES | Q5: TOTAL
B7: 1 | C7: CPO INCOMING | Q7: CPO Incoming
C8: Group
C9: D/O Weight | D9: Kg | E9: 34712190 | F9: 46794650 | G9: 48958310 | H9: 49512120 | I9: 49624840 | J9: 38554430 | K9: 24913990 | L9: 18636910 | M9: 13072230 | N9: 18425380 | O9: =[1]November!$AJ$9 -> 30775240 | P9: =[2]Desember!$AL$9 -> 40452040 | Q9: =SUM(E9:P9) -> 414432330
C10: Receiving Weight | D10: Kg | E10: 34664660 | F10: 46706440 | G10: 48874490 | H10: 49430470 | I10: 49555300 | J10: 38499030 | K10: 24874530 | L10: 18603310 | M10: 13050780 | N10: 18396300 | O10: =[1]November!$AJ$10 -> 30713520 | P10: =[2]Desember!$AL$10 -> 40375140 | Q10: =SUM(E10:P10) -> 413743970
C11: Transportation (Loss)/Gain | D11: % | E11: =((E10-E9)/E9)*100 -> -0.13692596 | F11: =((F10-F9)/F9)*100 -> -0.18850446 | G11: =((G10-G9)/G9)*100 -> -0.17120689 | H11: =((H10-H9)/H9)*100 -> -0.16490912 | I11: =((I10-I9)/I9)*100 -> -0.14013143 | J11: =((J10-J9)/J9)*100 -> -0.14369296 | K11: =((K10-K9)/K9)*100 -> -0.15838491 | L11: =((L10-L9)/L9)*100 -> -0.1802874 | ... Q11: =((Q10-Q9)/Q9)*100 -> -0.16609708
C12: Swasta
C13: D/O Weight | D13: Kg | E13: 57050 | F13: 1120030 | G13: 2641060 | H13: 1043600 | I13: 1385440 | J13: 1279790 | K13: 1443350 | L13: 536250 | M13: 100100 | N13: 0 | O13: 0 | P13: =[2]Desember!$AL$13 -> 932560 | Q13: =SUM(E13:P13) -> 10539230
C14: Receiving Weight | D14: Kg | E14: 56930 | F14: 1119070 | G14: 2635410 | H14: 1039720 | I14: 1382580 | J14: 1279610 | K14: 1445080 | L14: 537300 | M14: 99820 | N14: 0 | O14: 0 | P14: =[2]Desember!$AL$14 -> 931750 | Q14: =SUM(E14:P14) -> 10527270
C15: Transportation (Loss)/Gain | D15: % | E15: =((E14-E13)/E13)*100 -> -0.21034181 | F15: =((F14-F13)/F13)*100 -> -0.08571199 | G15: =((G14-G13)/G13)*100 -> -0.21392926 | H15: =((H14-H13)/H13)*100 -> -0.37178996 | I15: =((I14-I13)/I13)*100 -> -0.20643261 | J15: =((J14-J13)/J13)*100 -> -0.014064808 | K15: =((K14-K13)/K13)*100 -> 0.11986005 | L15: =((L14-L13)/L13)*100 -> 0.1958042 | M15: =((M14-M13)/M13)*100 -> -0.27972028 | N15: 0 | O15: 0 | P15: =((P14-P13)/P13)*100 -> -0.086857682 | Q15: =((Q14-Q13)/Q13)*100 -> -0.11348078
C16: Total Received | D16: Kg | E16: =E10+E14 -> 34721590 | F16: =F10+F14 -> 47825510 | G16: =G10+G14 -> 51509900 | H16: =H10+H14 -> 50470190 | I16: =I10+I14 -> 50937880 | J16: =J10+J14 -> 39778640 | K16: =K10+K14 -> 26319610 | L16: =L10+L14 -> 19140610 | ... Q16: =Q10+Q14 -> 424271240
C17: COL INCOMING | Q17: COL Incoming
C18: D/O Weight | D18: Kg | E18: 0 | F18: 0 | G18: 0 | H18: 0 | I18: 0 | J18: 0 | K18: 5984070 | L18: 0 | M18: 0 | N18: 0 | O18: 0 | P18: 0 | Q18: =SUM(E18:P18) -> 5984070
C19: Receiving Weight | D19: Kg | E19: 0 | F19: 0 | G19: 0 | H19: 0 | I19: 0 | J19: 0 | K19: 5982270 | L19: 0 | M19: 0 | N19: 0 | O19: 0 | P19: 0 | Q19: =SUM(E19:P19) -> 5982270
C20: Transportation (Loss)/Gain | D20: % | E20: 0 | F20: 0 | G20: 0 | H20: 0 | I20: 0 | J20: 0 | K20: =((K19-K18)/K18)*100 -> -0.030079862 | L20: 0 | M20: 0 | N20: 0 | O20: 0 | P20: 0 | Q20: =((Q19-Q18)/Q18)*100 -> -0.030079862
C21: Total Received | D21: Kg | E21: =E19 -> 0 | F21: =F19 -> 0 | G21: =G19 -> 0 | H21: =H19 -> 0 | I21: =I19 -> 0 | J21: =J19 -> 0 | K21: =K19 -> 5982270 | L21: =L19 -> 0 | ... Q21: =Q19 -> 5982270
B22: 2 | C22: PRODUCTION | Q22: Production
C23: Refinery Plant
C24: Running Days | D24: Days | E24: 20 | F24: 29 | G24: 31 | H24: 29 | I24: 22 | J24: 30 | K24: 23 | L24: 17 | M24: 22 | N24: 13 | O24: =[1]November!$AJ$26 -> 17 | P24: =[2]Desember!$AL$19 -> 31 | Q24: =SUM(E24:P24) -> 284
C25: CPO Consume | D25: Kg | E25: 31386719 | F25: 47885813 | G25: 45905106 | H25: =43495130+[3]Prod!$E$35 -> 54213038 | I25: 36539132 | J25: 51486064 | K25: 31253915 | L25: =18178235-L26 -> 17543224 | M25: 18225883 | N25: 15438945 | O25: =[1]November!$AJ$27 -> 25857293 | P25: =[2]Desember!$AL$20 -> 42842172 | Q25: =SUM(E25:P25) -> 4.185773e+08
C26: COL Consume | D26: Kg | E26: 0 | F26: 0 | G26: 0 | H26: 0 | I26: 0 | J26: 0 | K26: 1111741 | L26: 635011 | M26: 349232 | N26: 618256 | O26: =[1]November!$AJ$28 -> 239262.52 | P26: =[2]Desember!$AL$21 -> 1715005 | Q26: =SUM(E26:P26) -> 4668507.5
C27: - FFA | D27: % | E27: 4.3813845 | F27: 4.2789655 | G27: 4.2132963 | H27: 4.0269052 | I27: 4.0740472 | J27: 4.2 | K27: 5.42 | L27: 6.58 | M27: 5.6268182 | N27: 8.3557692 | O27: =[1]November!$AJ$29 -> 4.9994118 | P27: =[2]Desember!$AL$22 -> 7.7377419 | Q27: =AVERAGE(E27:P27) -> 5.3245283
C28: - M & I | D28: % | E28: 0.41567357 | F28: 0.40482759 | G28: 0.40222222 | H28: 0.37993144 | I28: 0.37252659 | J28: 0.35 | K28: 0.35 | L28: 0.36 | M28: 0.34409091 | N28: 0.33769231 | O28: =[1]November!$AJ$30 -> 0.38011765 | P28: =[2]Desember!$AL$23 -> 0.37322581 | Q28: =AVERAGE(E28:P28) -> 0.37252567
C29: - DOBI | D29: % | E29: 2.2051667 | F29: 2.2017241 | G29: 2.2944444 | H29: 2.2369052 | I29: 2.2607583 | J29: 2.25 | K29: 2.2 | L29: 2.17 | M29: 2.1925 | N29: 2.1938462 | O29: =[1]November!$AJ$31 -> 2.1496471 | P29: =[2]Desember!$AL$24 -> 2.1551613 | Q29: =AVERAGE(E29:P29) -> 2.2091794
C30: Product
C31: - RBDPO | D31: Kg | E31: 29721700 | F31: 45410000 | G31: 43605300 | H31: =40378300+[3]Prod!$E$36+H38 -> 51512461 | I31: 34773259 | J31: 48874800 | K31: 30439289 | L31: 17113976 | M31: 17465388 | N31: 15021516 | O31: =[1]November!$AJ$33 -> 24498500 | P31: =[2]Desember!$AL$26 -> 41854300 | Q31: =SUM(E31:P31) -> 400290489
C32: - PFAD | D32: Kg | E32: 1457818 | F32: 2122264 | G32: 1980427 | H32: =1743033+[3]Prod!$E$37 -> 2269639 | I32: 1540632 | J32: 2224235 | K32: 1620897 | L32: 910729.57 | M32: 981008 | N32: 928178 | O32: =[1]November!$AJ$34 -> 1394636 | P32: =[2]Desember!$AL$27 -> 2372695 | Q32: =SUM(E32:P32) -> 19803159
C33: Fractionation Olein IV 56
C34: - RBDPO Consume | D34: Kg | E34: 28475438 | F34: 34911290 | G34: 42598542 | H34: 30611750 | I34: 21950703 | J34: 41356225 | K34: 24638015 | L34: 15187927 | M34: 14186771 | N34: 7292410 | O34: =[1]November!$AJ$37 -> 23697725 | P34: =[2]Desember!$AL$29 -> 37173360 | Q34: =SUM(E34:P34) -> 322080156
C35: - Olein IV 56 | D35: Kg | E35: 23485058 | F35: 28896630 | G35: 35239042 | H35: 25269358 | I35: 18191369 | J35: 34175133 | K35: 20368572 | L35: 12564411 | M35: 11634596 | N35: 5921578 | O35: =[1]November!$AJ$38 -> 19801477 | P35: =[2]Desember!$AL$30 -> 30739375 | Q35: =SUM(E35:P35) -> 266286599
C36: - Stearin | D36: Kg | E36: 4990380 | F36: 6014660 | G36: 7359500 | H36: 5342392 | I36: 3759334 | J36: 7181092 | K36: 4269443 | L36: 2623516 | M36: 2552175 | N36: 1370832 | O36: =[1]November!$AJ$39 -> 3896248 | P36: =[2]Desember!$AL$31 -> 6433985 | Q36: =SUM(E36:P36) -> 55793557
C37: Fractionation Olein IV 60
C38: - RBDPO Consume | D38: Kg | E38: 0 | F38: =SUM(F39:F40) -> 102527 | G38: 654915 | H38: 1120000 | I38: 1196278 | J38: 1512300 | K38: 279588 | L38: 1282620 | M38: 2043385 | N38: 1577780 | O38: =[1]November!$AJ$41 -> 1500710 | P38: =[2]Desember!$AL$34 -> 2213720 | Q38: =SUM(E38:P38) -> 13483823
C39: - Olein IV 60 | D39: Kg | E39: 0 | F39: 49027 | G39: 358865 | H39: 575812 | I39: 602223 | J39: 731845 | K39: 140988 | L39: 640320 | M39: 1001687 | N39: 834667 | O39: =[1]November!$AJ$42 -> 854300 | P39: =[2]Desember!$AL$35 -> 1285730 | Q39: =SUM(E39:P39) -> 7075464
C40: - Soft Stearin | D40: Kg | E40: 0 | F40: 53500 | G40: 296050 | H40: 544188 | I40: 594055 | J40: 780455 | K40: 138600 | L40: 642300 | M40: 1041698 | N40: 743113 | O40: =[1]November!$AJ$43 -> 646410 | P40: =[2]Desember!$AL$36 -> 927990 | Q40: =SUM(E40:P40) -> 6408359
B41: 3 | C41: % YIELD
C42: RBDPO | D42: % | E42: =E31/E25*100 -> 94.695148 | F42: =F31/F25*100 -> 94.829757 | G42: =G31/G25*100 -> 94.990087 | H42: =H31/H25*100 -> 95.018584 | I42: =I31/I25*100 -> 95.167173 | J42: =J31/J25*100 -> 94.928212 | K42: =K31/(K25+K26)*100 -> 94.048114 | L42: =L31/(L25+L26)*100 -> 94.145422 | M42: =M31/(M25+M26)*100 -> 94.025733 | N42: =N31/(N25+N26)*100 -> 93.550028 | O42: =O31/O25*100 -> 94.745028 | P42: =P31/P25*100 -> 97.69416 | Q42: =Q31/(SUM(Q25:Q26))*100 -> 94.576361
C43: PFAD | D43: % | E43: =E32/E25*100 -> 4.644697 | F43: =F32/F25*100 -> 4.4319264 | G43: =G32/G25*100 -> 4.3141759 | H43: =H32/H25*100 -> 4.1865187 | I43: =I32/I25*100 -> 4.2163892 | J43: =J32/J25*100 -> 4.3200719 | K43: =K32/(K25+K26)*100 -> 5.0080771 | L43: =L32/(L25+L26)*100 -> 5.01 | M43: =M32/(M25+M26)*100 -> 5.2813024 | N43: =N32/(N25+N26)*100 -> 5.780447 | O43: =O32/O25*100 -> 5.3935885 | P43: =P32/P25*100 -> 5.5382229 | Q43: =Q32/(SUM(Q25:Q26))*100 -> 4.6788788
...

Sheet Monthly-UTL
B2: UTILITY (GAS, STEAM, WATER & POWER) REPORT -2020
B3: PT. INDUSTRI NABATI LESTARI
B5: NO. | C5: ITEM | D5: UoM | E5: JAN | F5: FEB | G5: MARCH | H5: APRIL | I5: MEI | J5: JUN | K5: JUL | L5: AUGUST | M5: SEPT | N5: OKT | O5: NOV | P5: DES | Q5: TOTAL
B7: 1 | C7: GAS CONSUMPTION
C8: Incoming *based on INL
C9: Incoming from Pertagas | D9: mmbtu | E9: 25619.432 | F9: 35150.354 | G9: 38747.294 | H9: 35200.464 | I9: 30010.421 | J9: 42046.553 | K9: 28190.715 | L9: 20723.92 | M9: 25451.31 | N9: 16839.501 | O9: 22736.12 | P9: 38800.562 | Q9: =SUM(E9:P9) -> 359516.64 | S9: 4
C10: Outgoing
C11: HP Boiler Refinery | D11: mmbtu | E11: 4114.5515 | F11: 5705.9416 | G11: 5609.3238 | H11: 6946.385 | I11: 5046.7805 | J11: 7304.2366 | K11: 4555.5714 | L11: 2720.641 | M11: 3105.0776 | N11: 2213.3026 | O11: 3483.614 | P11: 5715.1624 | Q11: =SUM(E11:P11) -> 56520.588
C12: MP Boiler 1,2 | D12: mmbtu | E12: =E9-E11 -> 21504.881 | F12: =F9-F11 -> 29444.412 | G12: =G9-G11 -> 33137.97 | H12: =H9-H11 -> 28254.079 | I12: =I9-I11 -> 24963.64 | J12: =J9-J11 -> 34742.316 | K12: =K9-K11 -> 23635.143 | L12: =L9-L11 -> 18003.279 | ... P12: =P9-P11 -> 33085.399 | Q12: =SUM(E12:P12) -> 302996.06
C13: Total | D13: mmbtu | E13: =SUM(E11:E12) -> 25619.432 | F13: =SUM(F11:F12) -> 35150.354 | G13: =SUM(G11:G12) -> 38747.294 | H13: =SUM(H11:H12) -> 35200.464 | I13: =SUM(I11:I12) -> 30010.421 | J13: =SUM(J11:J12) -> 42046.553 | K13: =SUM(K11:K12) -> 28190.715 | L13: =SUM(L11:L12) -> 20723.92 | ... Q13: =SUM(Q11:Q12) -> 359516.64
B14: 2 | C14: STEAM CONSUMPTION
C15: Incoming | D15: Kg | E15: 5551210 | F15: 7618960 | G15: 8896320 | H15: 7678500 | I15: 5833676 | J15: 9269220.5 | K15: 6898980 | L15: 4977373 | M15: 6905420 | N15: 4557880 | O15: 6200067 | P15: 9818573 | Q15: =SUM(E15:P15) -> 84206180
C16: Distribution to
C17: Refinery | D17: Kg | E17: 3076400 | F17: 4361800 | G17: 4496900 | H17: 4347600 | I17: 3338900 | J17: 4388100 | K17: 3412300 | L17: 2580000 | M17: 3456200 | N17: 1990700 | O17: 2630300 | P17: 5019100 | Q17: =SUM(E17:P17) -> 43098300
C18: Fractionation | D18: Kg | E18: 1394500 | F18: 2130000 | G18: 3345500 | H18: 2123200 | I18: 1371900 | J18: 2447300 | K18: 1354700 | L18: 1123400 | M18: 1322100 | N18: 646800 | O18: 1371800 | P18: 2121300 | Q18: =SUM(E18:P18) -> 20752500
C19: Others | D19: Kg | E19: 1080310 | F19: 1127160 | G19: 1053920 | H19: 1207700 | I19: 1122876 | J19: 2433820.5 | K19: 2131980 | L19: 1273973 | M19: =M15-(SUM(M17:M18)) -> 2127120 | N19: =N15-(SUM(N17:N18)) -> 1920380 | O19: 2197967 | P19: =P15-SUM(P17:P18) -> 2678173 | Q19: =SUM(E19:P19) -> 20355380
C20: Total | D20: Kg | E20: =SUM(E17:E19) -> 5551210 | F20: =SUM(F17:F19) -> 7618960 | G20: =SUM(G17:G19) -> 8896320 | H20: =SUM(H17:H19) -> 7678500 | I20: =SUM(I17:I19) -> 5833676 | J20: =SUM(J17:J19) -> 9269220.5 | K20: =SUM(K17:K19) -> 6898980 | L20: =SUM(L17:L19) -> 4977373 | ... Q20: =SUM(Q17:Q19) -> 84206180
B21: 3 | C21: WATER CONSUMPTION
C22: Incoming | D22: M3 | E22: 13184 | F22: 17060 | G22: 20064 | H22: 17673 | I22: 13991 | J22: 18090 | K22: 15029 | L22: 11960 | M22: 14577 | N22: 10106 | O22: 12492 | P22: 19779 | Q22: =SUM(E22:P22) -> 184005
C23: Outgoing
C24: Refinery | D24: M3 | E24: 1280 | F24: 2256 | G24: 2548 | H24: 2417 | I24: 1992 | J24: 2188 | K24: 1868 | L24: 1380 | M24: 1164 | N24: 1359 | O24: 1013 | P24: 1621 | Q24: =SUM(E24:P24) -> 21086
C25: Fractionation | D25: M3 | E25: 1904 | F25: 2892 | G25: 4010 | H25: 2769 | I25: 2319 | J25: 3035 | K25: 1663 | L25: 1515 | M25: 1461 | N25: 719 | O25: 1542 | P25: 2665 | Q25: =SUM(E25:P25) -> 26494
C26: Others | D26: M3 | E26: =E22-(SUM(E24:E25)) -> 10000 | F26: =F22-(SUM(F24:F25)) -> 11912 | G26: =G22-(SUM(G24:G25)) -> 13506 | H26: =H22-(SUM(H24:H25)) -> 12487 | I26: =I22-(SUM(I24:I25)) -> 9680 | J26: =J22-(SUM(J24:J25)) -> 12867 | K26: 11498 | L26: 9065 | M26: =M22-(SUM(M24:M25)) -> 11952 | N26: =N22-(SUM(N24:N25)) -> 8028 | O26: =O22-(SUM(O24:O25)) -> 9937 | P26: =P22-SUM(P24:P25) -> 15493 | Q26: =SUM(E26:P26) -> 136425
C27: Total | D27: M3 | E27: =E22 -> 13184 | F27: =F22 -> 17060 | G27: =G22 -> 20064 | H27: =H22 -> 17673 | I27: =I22 -> 13991 | J27: =J22 -> 18090 | K27: =K22 -> 15029 | L27: =L22 -> 11960 | ... P27: =P22 -> 19779 | Q27: =SUM(Q24:Q26) -> 184005
C28: Waste Water (Effluent) | D28: M3 | E28: 1237 | F28: 1220 | G28: 1461 | H28: 1138 | I28: 1143 | J28: 1104 | K28: 1279 | L28: 663 | M28: 0 | N28: 1574 | O28: 3337 | P28: 5311 | Q28: =SUM(E28:P28) -> 19467
C29: WTP & WWTP Details
C30: Raw Water | D30: M3 | E30: =E22 -> 13184 | F30: =F22 -> 17060 | G30: =G22 -> 20064 | H30: =H22 -> 17673 | I30: =I22 -> 13991 | J30: =J22 -> 18090 | K30: =K22 -> 15029 | L30: =L22 -> 11960 | M30: 14577 | N30: 10106 | O30: =O22 -> 12492 | P30: =P22 -> 19779 | Q30: =SUM(E30:P30) -> 184005
C31: - Softener Product (to Refinery) | D31: M3 | E31: 1280 | F31: 2256 | G31: 2548 | H31: 2417 | I31: 1992 | J31: 2188 | K31: 1868 | L31: 1380 | M31: 1164 | N31: 1359 | O31: =O24 -> 1013 | P31: =P24 -> 1621 | Q31: =SUM(E31:P31) -> 21086
C32: - Softener Product (to Fractionation) | D32: M3 | E32: 1904 | F32: 2892 | G32: 4010 | H32: 2769 | I32: 2319 | J32: 3035 | K32: 1663 | L32: 1515 | M32: 1461 | N32: 719 | O32: =O25 -> 1542 | P32: =P25 -> 2665 | Q32: =SUM(E32:P32) -> 26494
C33: - RO Product | D33: M3 | E33: 5595.4 | F33: 7255.8 | G33: 8063.3 | H33: 7288.2 | I33: 5761.7 | J33: 7894.4 | K33: 6863.1 | L33: 5347.1 | M33: 7068.9 | N33: 4499.4 | O33: =[4]November!$AK$102 -> 5716.4 | P33: 9337 | Q33: =SUM(E33:P33) -> 80690.7
C34: - Reject Water RO Product | D34: M3 | E34: =((20/14)*E33)-E33 -> 2398.0286 | F34: =((20/14)*F33)-F33 -> 3109.6286 | G34: =((20/14)*G33)-G33 -> 3455.7 | H34: =((20/14)*H33)-H33 -> 3123.5143 | I34: =((20/14)*I33)-I33 -> 2469.3 | J34: =((20/14)*J33)-J33 -> 3383.3143 | K34: =((20/14)*K33)-K33 -> 2941.3286 | L34: =((20/14)*L33)-L33 -> 2291.6143 | ... P34: =((20/14)*P33)-P33 -> 4001.5714 | Q34: =SUM(E34:P34) -> 34581.729
C35: - Sanitary & Service Equipment | D35: M3 | E35: =E30-(SUM(E31:E34)) -> 2006.5714 | F35: =F30-(SUM(F31:F34)) -> 1546.5714 | G35: =G30-(SUM(G31:G34)) -> 1987 | H35: =H30-(SUM(H31:H34)) -> 2075.2857 | I35: =I30-(SUM(I31:I34)) -> 1449 | J35: =J30-(SUM(J31:J34)) -> 1589.2857 | K35: =K30-(SUM(K31:K34)) -> 1693.5714 | L35: =L30-(SUM(L31:L34)) -> 1426.2857 | M35: 1853.9 | N35: 1600.3 | O35: =O30-SUM(O31:O34) -> 1770.7143 | P35: =P30-SUM(P31:P34) -> 2154.4286 | Q35: =SUM(E35:P35) -> 21152.914
C36: Waste Water (Effluent) | D36: M3 | E36: 1237 | F36: 1220 | G36: 1461 | H36: 1138 | I36: 1143 | J36: 1104 | K36: 1279 | L36: 663 | M36: 0 | N36: 1574 | O36: =O28 -> 3337 | P36: =P28 -> 5311 | Q36: =SUM(E36:P36) -> 19467
B37: 4 | C37: POWER CONSUMPTION
C38: Incoming
C39: PLN *Base onKinra | D39: Kwh | E39: 576934 | F39: 711126 | G39: 782041 | H39: 739379 | I39: 585067 | J39: 760275 | K39: 592254 | L39: 455799 | M39: 566027 | N39: 374624 | O39: 486302 | P39: 723265 | Q39: =SUM(E39:P39) -> 7353093
C40: PLN *Base on INL | D40: Kwh | E40: 578100 | F40: 712800 | G40: 781300 | H40: 738700 | I40: 591800 | J40: 762400 | K40: 594200 | L40: 460800 | M40: 565700 | N40: 390200 | O40: 465600 | P40: 720500 | Q40: =SUM(E40:P40) -> 7362100
C41: Outgoing
C42: Utility-MP Boiler *) | D42: Kwh | E42: 0 | F42: 0 | G42: 0 | H42: 0 | I42: 0 | J42: 28662.8 | K42: 22238 | L42: 16668 | M42: 20520 | N42: 14365 | O42: 17780 | P42: 30040 | Q42: =SUM(E42:P42) -> 150273.8
C43: Utility-WTP&WWTP | D43: Kwh | E43: 12785 | F43: 13864 | G43: 14977 | H43: 14211 | I43: 12985 | J43: 13729 | K43: 13424 | L43: 7951 | M43: 7039 | N43: 7508 | O43: 8135 | P43: 11220 | Q43: =SUM(E43:P43) -> 137828
...

Sheet Monthly-Pack
B2: PACKAGING PERFORMANCE
B3: PT. INDUSTRI NABATI LESTARI
B5: No. | C5: ITEM | D5: UoM | E5: JAN | F5: FEB | G5: MAR | H5: APR | I5: MEI | J5: JUN | K5: JUL | L5: AUGUST | M5: SEPT | N5: OKT | O5: NOV | P5: DES | Q5: TOTAL
B7: 1 | C7: Production
C8: Fractionation Olein IV 60
C9: RBDPO Consume | D9: Kg | E9: 0 | F9: 102527 | G9: 654915 | H9: 1120000 | I9: 1196278 | J9: 1512300 | K9: 279588 | L9: 1282620 | M9: 2043385 | N9: 1577780 | O9: 1500710 | P9: =SUM(P10:P11) -> 2213720 | Q9: =SUM(E9:P9) -> 13483823
C10: Olein IV 60 (FM) | D10: Kg | E10: 0 | F10: 49027 | G10: 358865 | H10: 575812 | I10: 602223 | J10: 731845 | K10: 140988 | L10: 640320 | M10: 1001687 | N10: 834667 | O10: 854300 | P10: 1285730 | Q10: =SUM(E10:P10) -> 7075464
C11: Soft Stearin | D11: Kg | E11: 0 | F11: 53500 | G11: 296050 | H11: 544188 | I11: 594055 | J11: 780455 | K11: 138600 | L11: 642300 | M11: 1041698 | N11: 743113 | O11: 646410 | P11: 927990 | Q11: =SUM(E11:P11) -> 6408359
B12: 2 | C12: Yield Percentage
C13: Olein IV 60 | D13: % | E13: 0 | F13: 52.232143 | G13: 54.795661 | H13: 51.411786 | I13: =I10/I9*100 -> 50.341392 | J13: =J10/J9*100 -> 48.392845 | K13: =K10/K9*100 -> 50.427057 | L13: =L10/L9*100 -> 49.922814 | M13: =M10/M9*100 -> 49.020963 | N13: =N10/N9*100 -> 52.901355 | O13: =O10/O9*100 -> 56.926388 | P13: =P10/P9*100 -> 58.080064 | Q13: =Q10/Q9*100 -> 52.473724
C14: Soft Stearin | D14: % | E14: 0 | F14: 47.767857 | G14: 45.204339 | H14: 48.588214 | I14: =I11/I9*100 -> 49.658608 | J14: =J11/J9*100 -> 51.607155 | K14: =K11/K9*100 -> 49.572943 | L14: =L11/L9*100 -> 50.077186 | M14: =M11/M9*100 -> 50.979037 | N14: =N11/N9*100 -> 47.098645 | O14: =O11/O9*100 -> 43.073612 | P14: =P11/P9*100 -> 41.919936 | Q14: =Q11/Q9*100 -> 47.526276
B15: 3 | C15: Filling Machine
C16: Olein IV 60 Received | D16: Kg | F16: 49027 | G16: 358865 | H16: 575812 | I16: 602223 | J16: 731845 | K16: 140988 | L16: 640320 | M16: =M10 -> 1001687 | N16: 834667 | O16: 854300 | P16: =P10 -> 1285730 | Q16: =SUM(E16:P16) -> 7075464
C17: Olein IV 60 Consume | D17: Kg | E17: 0 | F17: 39410.94 | G17: 320896 | H17: 541413.69 | I17: 547172.96 | J17: 853778.76 | K17: 5483.43 | L17: 665502.25 | M17: 1036853.1 | N17: 873527.76 | O17: =[1]November!$AJ$61 -> 743609.57 | P17: 1323285.7 | Q17: =SUM(E17:P17) -> 6950934.2
C18: - to finished product | D18: Kg | E18: =(SUM(E21:E22))*10.86 -> 0 | F18: =(SUM(F21:F22))*10.86 -> 39378.36 | G18: =(SUM(G21:G22))*10.86 -> 319946.46 | H18: =(SUM(H21:H22))*10.86 -> 541034.34 | I18: =(SUM(I21:I22))*10.86 -> 546920.46 | J18: =(SUM(J21:J22))*10.86 -> 853020.42 | K18: =(SUM(K21:K22))*10.86 -> 5473.44 | L18: =(SUM(L21:L22))*10.86 -> 665305.32 | ... P18: =(SUM(P21:P22))*10.86 -> 1323084.7 | Q18: =SUM(E18:P18) -> 6947641.6
C19: - to sample and remelt | D19: Kg | E19: =E17-E18 -> 0 | F19: =F17-F18 -> 32.58 | G19: =G17-G18 -> 949.54 | H19: =H17-H18 -> 379.349 | I19: =I17-I18 -> 252.5 | J19: =J17-J18 -> 758.34 | K19: =K17-K18 -> 9.99 | L19: =L17-L18 -> 196.93 | ... P19: =P17-P18 -> 201.015 | Q19: =SUM(E19:P19) -> 3292.599
C20: Carton
C21: - Salvaco 1 Liter | D21: carton | E21: 0 | F21: 0 | G21: 12814 | H21: 24468 | I21: 18280 | J21: 44364 | K21: 0 | L21: 24168 | M21: 45997 | N21: 33929 | O21: =[1]November!$AJ$65 -> 35562 | P21: 44768 | Q21: =SUM(E21:P21) -> 284350
C22: - Salvaco 2 Liter | D22: carton | E22: 0 | F22: 3626 | G22: 16647 | H22: 25351 | I22: 32081 | J22: 34183 | K22: 504 | L22: 37094 | M22: 49463 | N22: 46488 | O22: =[1]November!$AJ$66 -> 32896 | P22: 77063 | Q22: =SUM(E22:P22) -> 355396
C23: Pouch
C24: - Salvaco 1 Liter | D24: pouch | E24: 0 | F24: 0 | G24: 153768 | H24: 293616 | I24: =I21*12 -> 219360 | J24: =J21*12 -> 532368 | K24: =K21*12 -> 0 | L24: =L21*12 -> 290016 | M24: =M21*12 -> 551964 | N24: =N21*12 -> 407148 | O24: =O21*12 -> 426744 | P24: =P21*12 -> 537216 | Q24: =SUM(E24:P24) -> 3412200
C25: - Salvaco 2 Liter | D25: pouch | E25: 0 | F25: =F22*6 -> 21756 | G25: 99882 | H25: 152106 | I25: =I22*6 -> 192486 | J25: =J22*6 -> 205098 | K25: =K22*6 -> 3024 | L25: =L22*6 -> 222564 | M25: =M22*6 -> 296778 | N25: =N22*6 -> 278928 | O25: =O22*6 -> 197376 | P25: =P22*6 -> 462378 | Q25: =SUM(E25:P25) -> 2132376
C26: Consumable Vit. A | D26: Kg | E26: 0 | F26: 0 | G26: ='[6]DATA PEMAKAIAN VITAMIN A'!$D$5/1000 -> 7.417 | H26: ='[6]DATA PEMAKAIAN VITAMIN A'!$D$6/1000 -> 11.144 | I26: ='[6]DATA PEMAKAIAN VITAMIN A'!$D$7/1000 -> 11.262 | J26: ='[6]DATA PEMAKAIAN VITAMIN A'!$D$8/1000 -> 17.562 | K26: ='[6]DATA PEMAKAIAN VITAMIN A'!$D$9/1000 -> 0.112 | L26: ='[6]DATA PEMAKAIAN VITAMIN A'!$D$10/1000 -> 13.691 | M26: ='[6]DATA PEMAKAIAN VITAMIN A'!$D$11/1000 -> 21.339 | N26: ='[6]DATA PEMAKAIAN VITAMIN A'!$D$12/1000 -> 17.979 | O26: =[1]November!$AJ$70/1000 -> 12.911 | P26: =19593/1000 -> 19.593 | Q26: =SUM(E26:P26) -> 133.01
C27: Consumable packing tape | D27: roll | E27: 0 | F27: ='[6]PACKING TAPE'!$E$7 -> 8 | G27: ='[6]PACKING TAPE'!$E$8 -> 59 | H27: ='[6]PACKING TAPE'!$E$9 -> 100 | I27: ='[6]PACKING TAPE'!$E$10 -> 101 | J27: ='[6]PACKING TAPE'!$E$11 -> 157 | K27: ='[6]PACKING TAPE'!$E$12 -> 1 | L27: ='[6]PACKING TAPE'!$E$13 -> 122 | M27: ='[6]PACKING TAPE'!$E$14 -> 190 | N27: ='[6]PACKING TAPE'!$E$15 -> 160 | O27: =[1]November!$AJ$71 -> 122 | P27: 224 | Q27: =SUM(E27:P27) -> 1244
B28: 4 | C28: Qty Reject Material
C29: Carton
C30: - Salvaco 1 Liter | D30: % | E30: 0 | F30: 0 | G30: 22 | H30: 19 | I30: 6 | J30: 138 | K30: 0 | L30: 8 | M30: 19 | N30: 31 | O30: 29 | P30: 49 | Q30: =SUM(E30:P30) -> 321
C31: - Salvaco 2 Liter | D31: % | E31: 0 | F31: 8 | G31: 18 | H31: 23 | I31: 17 | J31: 61 | K31: 0 | L31: 105 | M31: 44 | N31: 35 | O31: 17 | P31: 63 | Q31: =SUM(E31:P31) -> 391
C32: Pouch
C33: - Salvaco 1 Liter | D33: % | E33: 0 | F33: 0 | G33: 325 | H33: 606 | I33: 135 | J33: 337 | K33: 0 | L33: 263 | M33: 427 | N33: 556 | O33: 445 | P33: 672 | Q33: =SUM(E33:P33) -> 3766
C34: - Salvaco 2 Liter | D34: % | E34: 0 | F34: 72 | G34: 212 | H34: 138 | I34: 39 | J34: 52 | K34: 2 | L34: 87 | M34: 167 | N34: 164 | O34: 165 | P34: 402 | Q34: =SUM(E34:P34) -> 1500
B35: 5 | C35: % Reject Material
C36: Carton
C37: - Salvaco 1 Liter | D37: % | E37: =0 -> 0 | F37: =F30/F21*100 -> #DIV/0! | G37: =G30/G21*100 -> 0.17168722 | H37: =H30/H21*100 -> 0.077652444 | I37: =I30/I21*100 -> 0.032822757 | J37: =J30/J21*100 -> 0.31106302 | K37: =K30/K21*100 -> #DIV/0! | L37: =L30/L21*100 -> 0.033101622 | M37: =M30/M21*100 -> 0.041307042 | ... Q37: =Q30/Q21*100 -> 0.11288905
C38: - Salvaco 2 Liter | D38: % | E38: 0 | F38: =F31/F22*100 -> 0.22062879 | G38: =G31/G22*100 -> 0.10812759 | H38: =H31/H22*100 -> 0.090726204 | I38: =I31/I22*100 -> 0.052990867 | J38: =J31/J22*100 -> 0.17845128 | K38: =K31/K22*100 -> 0 | L38: =L31/L22*100 -> 0.28306465 | M38: =M31/M22*100 -> 0.088955381 | ... Q38: =Q31/Q22*100 -> 0.11001812
C39: Pouch
C40: - Salvaco 1 Liter | D40: % | E40: 0 | F40: 0 | G40: =G33/G24*100 -> 0.21135737 | H40: =H33/H24*100 -> 0.20639202 | I40: =I33/I24*100 -> 0.06154267 | J40: =J33/J24*100 -> 0.063302077 | K40: =K33/K24*100 -> #DIV/0! | L40: =L33/L24*100 -> 0.090684652 | M40: =M33/M24*100 -> 0.077360118 | N40: =N33/N24*100 -> 0.13655968 | ... Q40: =Q33/Q24*100 -> 0.11036868
C41: - Salvaco 2 Liter | D41: % | E41: 0 | F41: =F34/F25*100 -> 0.33094319 | G41: =G34/G25*100 -> 0.21225046 | H41: =H34/H25*100 -> 0.090726204 | I41: =I34/I25*100 -> 0.020261214 | J41: =J34/J25*100 -> 0.025353733 | K41: =K34/K25*100 -> 0.066137566 | L41: =L34/L25*100 -> 0.03908988 | M41: =M34/M25*100 -> 0.056271017 | ... Q41: =Q34/Q25*100 -> 0.070344067
B43: Note
B44: Qty Olein IV 60 base on sounding
