Workbook

Sheet Prod-in MT
B2: YEARLY PRODUCTION SUMMARY -TAHUN 2021
B5: in MT | F5: 2021 | S5: Grand Total
B6: ACTUAL PRODUCTION | F6: 31 | G6: 18 | H6: 31 | I6: 30 | J6: 31 | K6: 30 | L6: 31 | M6: 31 | N6: 30 | O6: 31 | P6: 30 | Q6: 20 | S6: =SUM(F6:Q6) -> 344
B7: Product | D7: Budget | E7: Actual | F7: Januari | G7: Februari | H7: Maret | I7: April | J7: Mei | K7: Juni | L7: Juli | M7: Agustus | N7: September | O7: Oktober | P7: November | Q7: Desember
B8: Total CPO & COL Consume | D8: 1 | E8: 1 | F8: =SUM(F9:F10) -> 43483.127 | G8: =SUM(G9:G10) -> 29035.67 | H8: =SUM(H9:H10) -> 51822.527 | I8: =SUM(I9:I10) -> 45758.36 | J8: =SUM(J9:J10) -> 48290.547 | K8: =SUM(K9:K10) -> 49740.939 | L8: =SUM(L9:L10) -> 48669.136 | M8: =SUM(M9:M10) -> 54214.019 | ... Q8: =SUM(Q9:Q10) -> 29768.361 | S8: =SUM(F8:Q8) -> 555758.88
B9: - CPO Consume | F9: ='Prod -in Kg'!F9/1000 -> 41605.447 | G9: ='Prod -in Kg'!G9/1000 -> 28905.898 | H9: ='Prod -in Kg'!H9/1000 -> 51487.425 | I9: ='Prod -in Kg'!I9/1000 -> 45758.36 | J9: ='Prod -in Kg'!J9/1000 -> 48290.547 | K9: ='Prod -in Kg'!K9/1000 -> 49740.939 | L9: ='Prod -in Kg'!L9/1000 -> 48669.136 | M9: ='Prod -in Kg'!M9/1000 -> 54214.019 | ... Q9: ='Prod -in Kg'!Q9/1000 -> 29768.361 | S9: =SUM(F9:Q9) -> 553416.32
B10: - COL Consume | F10: ='Prod -in Kg'!F10/1000 -> 1877.68 | G10: ='Prod -in Kg'!G10/1000 -> 129.77167 | H10: ='Prod -in Kg'!H10/1000 -> 335.102 | I10: ='Prod -in Kg'!I10/1000 -> 0 | J10: ='Prod -in Kg'!J10/1000 -> 0 | K10: ='Prod -in Kg'!K10/1000 -> 0 | L10: ='Prod -in Kg'!L10/1000 -> 0 | M10: ='Prod -in Kg'!M10/1000 -> 0 | ... Q10: ='Prod -in Kg'!Q10/1000 -> 0 | S10: =SUM(F10:Q10) -> 2342.5537
B12: Total RBDPO Refinery
B13: - Poram & Branded Spec | D13: 0.942 | E13: =S13/S8 -> 0.94832594 | F13: ='Prod -in Kg'!F12/1000 -> 40859 | G13: ='Prod -in Kg'!G12/1000 -> 27410.3 | H13: ='Prod -in Kg'!H12/1000 -> 49037.21 | I13: ='Prod -in Kg'!I12/1000 -> 43431.9 | J13: ='Prod -in Kg'!J12/1000 -> 45808.5 | K13: ='Prod -in Kg'!K12/1000 -> 47176.2 | L13: ='Prod -in Kg'!L12/1000 -> 46057.6 | M13: ='Prod -in Kg'!M12/1000 -> 51529.3 | ... Q13: ='Prod -in Kg'!Q12/1000 -> 28253.65 | S13: =SUM(F13:Q13) -> 527040.56
B15: Total RBDPO Consume to Fractionation
B16: - Poram Spec (IV 56) | F16: =SUM(F21,F26) -> 33037.204 | G16: =SUM(G21,G26) -> 23726.091 | H16: =SUM(H21,H26) -> 42518.062 | I16: =SUM(I21,I26) -> 38051.968 | J16: =SUM(J21,J26) -> 31497.784 | K16: =SUM(K21,K26) -> 40664.074 | L16: =SUM(L21,L26) -> 40068.635 | M16: =SUM(M21,M26) -> 45890.756 | ... Q16: =SUM(Q21,Q26) -> 12603.528 | S16: =SUM(F16:Q16) -> 423755.71
B17: - Branded Spec (IV 58) | F17: =SUM(F22,F27) -> 0 | G17: =SUM(G22,G27) -> 0 | H17: =SUM(H22,H27) -> 0 | I17: =SUM(I22,I27) -> 1147.027 | J17: =SUM(J22,J27) -> 447.318 | K17: =SUM(K22,K27) -> 304.053 | L17: =SUM(L22,L27) -> 0 | M17: =SUM(M22,M27) -> 0 | ... Q17: =SUM(Q22,Q27) -> 0 | S17: =SUM(F17:Q17) -> 2300.106
B18: - Branded Spec (IV 60) | F18: =SUM(F23,F28) -> 2141.997 | G18: =SUM(G23,G28) -> 2919.3902 | H18: =SUM(H23,H28) -> 893.82671 | I18: =SUM(I23,I28) -> 2402.731 | J18: =SUM(J23,J28) -> 2392.3 | K18: =SUM(K23,K28) -> 2533.95 | L18: =SUM(L23,L28) -> 2676.5 | M18: =SUM(M23,M28) -> 3856.608 | ... Q18: =SUM(Q23,Q28) -> 5097.302 | S18: =SUM(F18:Q18) -> 42228.112
B20: Total Olein
B21: - Poram Spec (IV 56) | D21: 0.82 | E21: =S21/S16 -> 0.82663634 | F21: ='Prod -in Kg'!F18/1000 -> 27617.726 | G21: ='Prod -in Kg'!G18/1000 -> 19562.21 | H21: ='Prod -in Kg'!H18/1000 -> 35211.166 | I21: ='Prod -in Kg'!I18/1000 -> 31293.783 | J21: ='Prod -in Kg'!J18/1000 -> 25924.821 | K21: ='Prod -in Kg'!K18/1000 -> 33552.679 | L21: ='Prod -in Kg'!L18/1000 -> 33026.742 | M21: ='Prod -in Kg'!M18/1000 -> 37906.528 | ... Q21: ='Prod -in Kg'!Q18/1000 -> 10477.852 | S21: =SUM(F21:Q21) -> 350291.87
B22: - Branded Spec (IV 58) | D22: 0.7 | E22: =S22/S17 -> 0.68230029 | F22: 0 | G22: 0 | H22: 0 | I22: ='Prod -in Kg'!I19/1000 -> 757.337 | J22: ='Prod -in Kg'!J19/1000 -> 313.318 | K22: ='Prod -in Kg'!K19/1000 -> 214.1 | L22: ='Prod -in Kg'!L19/1000 -> 0 | M22: ='Prod -in Kg'!M19/1000 -> 0 | N22: ='Prod -in Kg'!N19/1000 -> 0 | O22: ='Prod -in Kg'!O19/1000 -> 0 | P22: ='Prod -in Kg'!P19/1000 -> 284.608 | Q22: ='Prod -in Kg'!Q19/1000 -> 0 | S22: =SUM(F22:Q22) -> 1569.363
B23: - Branded Spec (IV 60) | D23: 0.58 | E23: =S23/S18 -> 0.60025393 | F23: ='Prod -in Kg'!F20/1000 -> 1315.197 | G23: ='Prod -in Kg'!G20/1000 -> 1713.716 | H23: ='Prod -in Kg'!H20/1000 -> 541.907 | I23: ='Prod -in Kg'!I20/1000 -> 1415.75 | J23: ='Prod -in Kg'!J20/1000 -> 1406.5 | K23: ='Prod -in Kg'!K20/1000 -> 1497.65 | L23: ='Prod -in Kg'!L20/1000 -> 1596.7 | M23: ='Prod -in Kg'!M20/1000 -> 2323.178 | ... Q23: ='Prod -in Kg'!Q20/1000 -> 3076.418 | S23: =SUM(F23:Q23) -> 25347.59
B25: Total Stearin
B26: - Stearin | D26: 0.18 | E26: =S26/S16 -> 0.17336366 | F26: ='Prod -in Kg'!F22/1000 -> 5419.478 | G26: ='Prod -in Kg'!G22/1000 -> 4163.8808 | H26: ='Prod -in Kg'!H22/1000 -> 7306.8963 | I26: ='Prod -in Kg'!I22/1000 -> 6758.1849 | J26: ='Prod -in Kg'!J22/1000 -> 5572.963 | K26: ='Prod -in Kg'!K22/1000 -> 7111.395 | L26: ='Prod -in Kg'!L22/1000 -> 7041.893 | M26: ='Prod -in Kg'!M22/1000 -> 7984.228 | ... Q26: ='Prod -in Kg'!Q22/1000 -> 2125.676 | S26: =SUM(F26:Q26) -> 73463.841
B27: - Stearin | D27: 0.3 | E27: =S27/S17 -> 0.31769971 | F27: 0 | G27: 0 | H27: 0 | I27: ='Prod -in Kg'!I23/1000 -> 389.69 | J27: ='Prod -in Kg'!J23/1000 -> 134 | K27: ='Prod -in Kg'!K23/1000 -> 89.953 | L27: ='Prod -in Kg'!L23/1000 -> 0 | M27: ='Prod -in Kg'!M23/1000 -> 0 | N27: ='Prod -in Kg'!N23/1000 -> 0 | O27: ='Prod -in Kg'!O23/1000 -> 0 | P27: ='Prod -in Kg'!P23/1000 -> 117.1 | Q27: ='Prod -in Kg'!Q23/1000 -> 0 | S27: =SUM(F27:Q27) -> 730.743
B28: - Soft Stearin (IV 38) | D28: 0.42 | E28: =S28/S18 -> 0.39974607 | F28: ='Prod -in Kg'!F24/1000 -> 826.8 | G28: ='Prod -in Kg'!G24/1000 -> 1205.6742 | H28: ='Prod -in Kg'!H24/1000 -> 351.91971 | I28: ='Prod -in Kg'!I24/1000 -> 986.981 | J28: ='Prod -in Kg'!J24/1000 -> 985.8 | K28: ='Prod -in Kg'!K24/1000 -> 1036.3 | L28: ='Prod -in Kg'!L24/1000 -> 1079.8 | M28: ='Prod -in Kg'!M24/1000 -> 1533.43 | ... Q28: ='Prod -in Kg'!Q24/1000 -> 2020.884 | S28: =SUM(F28:Q28) -> 16880.522
B29: PFAD - by Product | D29: 0.05 | E29: =S29/S8 -> 0.045527737 | F29: ='Prod -in Kg'!F25/1000 -> 2348.498 | G29: ='Prod -in Kg'!G25/1000 -> 1441.531 | H29: ='Prod -in Kg'!H25/1000 -> 2474.69 | I29: ='Prod -in Kg'!I25/1000 -> 2052.1316 | J29: ='Prod -in Kg'!J25/1000 -> 2192.3129 | K29: ='Prod -in Kg'!K25/1000 -> 2266.547 | L29: ='Prod -in Kg'!L25/1000 -> 2315.505 | M29: ='Prod -in Kg'!M25/1000 -> 2355.8763 | ... Q29: ='Prod -in Kg'!Q25/1000 -> 1301.139 | S29: =SUM(F29:Q29) -> 25302.444
B30: Loss / Waste | D30: 0.008 | E30: =S30/S8 -> 0.006146319 | F30: =F8-SUM(F13,F29) -> 275.62901 | G30: =G8-SUM(G13,G29) -> 183.839 | H30: =H8-SUM(H13,H29) -> 310.627 | I30: =I8-SUM(I13,I29) -> 274.32837 | J30: =J8-SUM(J13,J29) -> 289.73425 | K30: =K8-SUM(K13,K29) -> 298.192 | L30: =L8-SUM(L13,L29) -> 296.031 | M30: =M8-SUM(M13,M29) -> 328.84269 | ... Q30: =Q8-SUM(Q13,Q29) -> 213.572 | S30: =SUM(F30:Q30) -> 3415.8713
F36: 2021 | S36: Grand Total
B37: CHEMICAL CONSUMPTION | F37: =F6 -> 31 | G37: =G6 -> 18 | H37: =H6 -> 31 | I37: =I6 -> 30 | J37: =J6 -> 31 | K37: =K6 -> 30 | L37: =L6 -> 31 | M37: =M6 -> 31 | ... Q37: =Q6 -> 20 | S37: =SUM(F37:Q37) -> 344
F38: Januari | G38: Februari | H38: Maret | I38: April | J38: Mei | K38: Juni | L38: Juli | M38: Agustus | N38: September | O38: Oktober | P38: November | Q38: Desember
B39: Bleaching Earth | C39: Budget | D39: Actual
B40: - BE to Poram Spec | C40: 8 | D40: =S41 -> 9.3106683 | E40: Kg/MT | F40: 462920 | G40: 273537 | H40: 580177 | I40: 428406 | J40: 490057 | K40: 536488 | L40: 497144 | M40: 387640 | N40: 326941 | O40: 294249 | P40: 299055 | Q40: 173727 | S40: =SUM(F40:Q40) -> 4750341
F41: 11.210515 | G41: 10.544904 | H41: 11.403077 | I41: 9.9112393 | J41: 10.818887 | K41: 11.475621 | L41: 10.844833 | M41: 7.7291691 | N41: 7.1579792 | O41: 6.1434458 | P41: 6.9004705 | Q41: 7.2639413 | S41: 9.3106683
B43: - BE to Branded Spec | C43: 18 | D43: =S44 -> 17.512888 | E43: Kg/MT | F43: 38633 | G43: 58638 | H43: 18075 | I43: 46762 | J43: 52543 | K43: 53751 | L43: 49870 | M43: 68202 | N43: 88692 | O43: 111307 | P43: 110351 | Q43: 100972 | S43: =SUM(F43:Q43) -> 797796
F44: 17.642633 | G44: 18.943218 | H44: 19.156555 | I44: 18.453111 | J44: 17.548773 | K44: 17.972709 | L44: 17.636985 | M44: 16.793762 | N44: 16.815204 | O44: 17.401458 | P44: 17.254589 | Q44: 17.254255 | S44: 17.512888
B46: Phosporic Acid | C46: 0.55 | D46: =S46/S8 -> 0.52988942 | E46: Kg/MT | F46: 23110.1 | G46: 16837.4 | H46: 29578 | I46: 25392.3 | J46: 26283.9 | K46: 26343.3 | L46: 26424.82 | M46: 27578.8 | N46: 26254.9 | O46: 27600.8 | P46: 24730.53 | Q46: 14355.9 | S46: =SUM(F46:Q46) -> 294490.75
F47: =F46/F8 -> 0.53147282 | G47: =G46/G8 -> 0.57988674 | H47: =H46/H8 -> 0.57075565 | I47: =I46/I8 -> 0.55492155 | J47: =J46/J8 -> 0.54428665 | K47: =K46/K8 -> 0.52961003 | L47: =L46/L8 -> 0.5429482 | M47: =M46/M8 -> 0.50870237 | ... Q47: =Q46/Q8 -> 0.48225362 | S47: =S46/S8 -> 0.52988942
F51: 2021 | S51: Grand Total
B52: WASTE | F52: =F6 -> 31 | G52: =G6 -> 18 | H52: =H6 -> 31 | I52: =I6 -> 30 | J52: =J6 -> 31 | K52: =K6 -> 30 | L52: =L6 -> 31 | M52: =M6 -> 31 | ... Q52: =Q6 -> 20 | S52: =SUM(F52:Q52) -> 344
F53: Januari | G53: Februari | H53: Maret | I53: April | J53: Mei | K53: Juni | L53: Juli | M53: Agustus | N53: September | O53: Oktober | P53: November | Q53: Desember
C54: Budget | D54: Actual
B55: Spent Bleaching Earth | C55: 0.22 | D55: =S55% -> 0.21340648 | E55: OC | F55: 21.122903 | G55: 21.09 | H55: 21.43129 | I55: 21.42 | J55: 21.4 | K55: 21.44 | L55: 21.424839 | M55: 21.389032 | N55: 21.353 | O55: 21.34871 | P55: 21.349 | Q55: 21.319 | S55: =AVERAGE(F55:Q55) -> 21.340648
F56: =(SUM(F40,F43))+(F55%*(SUM(F40,F43))) -> 607495.55 | G56: =(SUM(G40,G43))+(G55%*(SUM(G40,G43))) -> 402230.71 | H56: =(SUM(H40,H43))+(H55%*(SUM(H40,H43))) -> 726465.12 | I56: =(SUM(I40,I43))+(I55%*(SUM(I40,I43))) -> 576948.99 | J56: =(SUM(J40,J43))+(J55%*(SUM(J40,J43))) -> 658716.4 | K56: =(SUM(K40,K43))+(K55%*(SUM(K40,K43))) -> 716786.24 | L56: =(SUM(L40,L43))+(L55%*(SUM(L40,L43))) -> 664210.87 | M56: =(SUM(M40,M43))+(M55%*(SUM(M40,M43))) -> 553342.19 | ... Q56: =(SUM(Q40,Q43))+(Q55%*(SUM(Q40,Q43))) -> 333262.08 | S56: =SUM(F56:Q56) -> 6732788.3
B58: Effluent | C58: 0.3 | D58: =S58/S80 -> 0.26968646 | E58: raw water | F58: 5616 | G58: 4577 | H58: 5645 | I58: 5591 | J58: 6207 | K58: 4589 | L58: 4716 | M58: 4631 | N58: 4537 | O58: 4859 | P58: 4239 | Q58: 5045 | S58: =SUM(F58:Q58) -> 60252
...

Sheet Prod -in Kg
B2: YEARLY PRODUCTION SUMMARY -TAHUN 2021
B5: in Kg | F5: 2021 | S5: Grand Total
B6: ACTUAL PRODUCTION | F6: 31 | G6: 18 | H6: 31 | I6: 30 | J6: 31 | K6: 30 | L6: 31 | M6: 31 | N6: 30 | O6: 31 | P6: 30 | Q6: 20 | S6: =SUM(F6:Q6) -> 344
B7: Product | D7: Budget | E7: Actual | F7: Januari | G7: Februari | H7: Maret | I7: April | J7: Mei | K7: Juni | L7: Juli | M7: Agustus | N7: September | O7: Oktober | P7: November | Q7: Desember
B8: Total CPO & COL Consume | D8: 1 | E8: 1 | F8: =SUM(F9:F10) -> 43483127 | G8: =SUM(G9:G10) -> 29035670 | H8: =SUM(H9:H10) -> 51822527 | I8: =SUM(I9:I10) -> 45758360 | J8: =SUM(J9:J10) -> 48290547 | K8: =SUM(K9:K10) -> 49740939 | L8: =SUM(L9:L10) -> 48669136 | M8: =SUM(M9:M10) -> 54214019 | ... Q8: =SUM(Q9:Q10) -> 29768361 | S8: =SUM(F8:Q8) -> 555758875
B9: - CPO Consume | F9: 41605447 | G9: 28905898 | H9: 51487425 | I9: 45758360 | J9: 48290547 | K9: 49740939 | L9: 48669136 | M9: 54214019 | N9: 50949554 | O9: 54292828 | P9: 49733807 | Q9: 29768361 | S9: =SUM(F9:Q9) -> 5.5341632e+08
B10: - COL Consume | F10: 1877680 | G10: 129771.67 | H10: 335102 | I10: 0 | J10: 0 | K10: 0 | L10: 0 | M10: 0 | N10: 0 | O10: 0 | P10: 0 | Q10: 0 | S10: =SUM(F10:Q10) -> 2342553.7
B11: Total RBDPO Refinery
B12: - Poram & Branded Spec | D12: 0.942 | E12: =S12/S8 -> 0.94832594 | F12: 40859000 | G12: 27410300 | H12: 49037210 | I12: 43431900 | J12: 45808500 | K12: 47176200 | L12: 46057600 | M12: 51529300 | N12: 48364700 | O12: 51703800 | P12: 47408400 | Q12: 28253650 | S12: =SUM(F12:Q12) -> 5.2704056e+08
B13: Total RBDPO Consume to Fractionation
B14: - Poram Spec (IV 56) | F14: 33037204 | G14: 23726091 | H14: 42518062 | I14: 38051968 | J14: 31497784 | K14: 40664074 | L14: 40068635 | M14: 45890756 | N14: 41535010 | O14: 33791704 | P14: 40370895 | Q14: 12603528 | S14: =SUM(F14:Q14) -> 4.2375571e+08
B15: - Branded Spec (IV 58) | F15: 0 | G15: 0 | H15: 0 | I15: 1147027 | J15: 447318 | K15: 304053 | L15: 0 | M15: 0 | N15: 0 | O15: 0 | P15: 401708 | Q15: 0 | S15: =SUM(F15:Q15) -> 2300106
B16: - Branded Spec (IV 60) | F16: 2141997 | G16: 2919390.3 | H16: 893827 | I16: 2402731 | J16: 2392300 | K16: 2533950 | L16: 2676500 | M16: 3856608 | N16: 4999578 | O16: 6622748 | P16: 5691181 | Q16: 5097302 | S16: =SUM(F16:Q16) -> 42228112
B17: Total Olein
B18: - Poram Spec (IV 56) | D18: 0.82 | E18: =S18/S14 -> 0.82663634 | F18: 27617726 | G18: 19562210 | H18: 35211166 | I18: 31293783 | J18: 25924821 | K18: 33552679 | L18: 33026742 | M18: 37906528 | N18: 34164148 | O18: 28141510 | P18: 33412705 | Q18: 10477852 | S18: =SUM(F18:Q18) -> 3.5029187e+08
B19: - Branded Spec (IV 58) | D19: 0.7 | E19: =S19/S15 -> 0.68230029 | F19: 0 | G19: 0 | H19: 0 | I19: 757337 | J19: 313318 | K19: 214100 | L19: 0 | M19: 0 | N19: 0 | O19: 0 | P19: 284608 | Q19: 0 | S19: =SUM(F19:Q19) -> 1569363
B20: - Branded Spec (IV 60) | D20: 0.58 | E20: =S20/S16 -> 0.60025392 | F20: 1315197 | G20: 1713716 | H20: 541907 | I20: 1415750 | J20: 1406500 | K20: 1497650 | L20: 1596700 | M20: 2323178 | N20: 3028055 | O20: 4013817 | P20: 3418702 | Q20: 3076418 | S20: =SUM(F20:Q20) -> 25347590
B21: Total Stearin
B22: - Stearin | D22: 0.18 | E22: =S22/S14 -> 0.17336366 | F22: 5419478 | G22: 4163880.8 | H22: 7306896.3 | I22: 6758184.9 | J22: 5572963 | K22: 7111395 | L22: 7041893 | M22: 7984228 | N22: 7370862 | O22: 5650194 | P22: 6958190 | Q22: 2125676 | S22: =SUM(F22:Q22) -> 73463841
B23: - Stearin | D23: 0.3 | E23: =S23/S15 -> 0.31769971 | F23: 0 | G23: 0 | H23: 0 | I23: 389690 | J23: 134000 | K23: 89953 | L23: 0 | M23: 0 | N23: 0 | O23: 0 | P23: 117100 | Q23: 0 | S23: =SUM(F23:Q23) -> 730743
B24: - Soft Stearin (IV 38) | D24: 0.42 | E24: =S24/S16 -> 0.39974607 | F24: 826800 | G24: 1205674.2 | H24: 351919.71 | I24: 986981 | J24: 985800 | K24: 1036300 | L24: 1079800 | M24: 1533430 | N24: 1971523 | O24: 2608931 | P24: 2272479 | Q24: 2020884 | S24: =SUM(F24:Q24) -> 16880522
B25: PFAD - by Product | D25: 0.05 | E25: =S25/S8 -> 0.045527737 | F25: 2348498 | G25: 1441531 | H25: 2474690 | I25: 2052131.6 | J25: 2192312.9 | K25: 2266547 | L25: 2315505 | M25: 2355876.3 | N25: 2275098 | O25: 2257011 | P25: 2022104 | Q25: 1301139 | S25: =SUM(F25:Q25) -> 25302444
B26: Loss / Waste | D26: 0.008 | E26: =S26/S8 -> 0.006146319 | F26: =F8-SUM(F12,F25) -> 275629.01 | G26: =G8-SUM(G12,G25) -> 183839 | H26: =H8-SUM(H12,H25) -> 310627 | I26: =I8-SUM(I12,I25) -> 274328.37 | J26: =J8-SUM(J12,J25) -> 289734.25 | K26: =K8-SUM(K12,K25) -> 298192 | L26: =L8-SUM(L12,L25) -> 296031 | M26: =M8-SUM(M12,M25) -> 328842.69 | ... Q26: =Q8-SUM(Q12,Q25) -> 213572 | S26: =SUM(F26:Q26) -> 3415871.3
F29: =F5 -> 2021 | S29: Grand Total
B30: CHEMICAL CONSUMPTION | F30: 20 | G30: 29 | H30: 31 | I30: 29 | J30: 22 | K30: 30 | L30: 23 | M30: 17 | N30: 22 | O30: 13 | P30: 17 | Q30: 31 | S30: =SUM(F30:Q30) -> 284
F31: Januari | G31: Februari | H31: Maret | I31: April | J31: Mei | K31: Juni | L31: Juli | M31: Agustus | N31: September | O31: Oktober | P31: November | Q31: Desember
B32: Bleaching Earth | C32: Budget | D32: Actual
B33: - BE to Poram Spec | C33: 8 | E33: Kg/MT | F33: 462920 | G33: 273537 | H33: 580177 | I33: 428406 | J33: 490057 | K33: 536488 | L33: 497144 | M33: 387640 | N33: 326941 | O33: 294249 | P33: 299055 | Q33: 173727 | S33: =SUM(F33:Q33) -> 4750341
B36: - BE to Branded Spec | C36: 18 | D36: =S36/S8 -> 0.0014355074 | E36: Kg/MT | F36: 38633 | G36: 58638 | H36: 18075 | I36: 46762 | J36: 52543 | K36: 53751 | L36: 49870 | M36: 68202 | N36: 88692 | O36: 111307 | P36: 110351 | Q36: 100972 | S36: =SUM(F36:Q36) -> 797796
B39: Phosporic Acid | C39: 0.55 | D39: =S39/S8 -> 0.00052988942 | E39: Kg/MT | F39: 23110.1 | G39: 16837.4 | H39: 29578 | I39: 25392.3 | J39: 26283.9 | K39: 26343.3 | L39: 26424.82 | M39: 27578.8 | N39: 26254.9 | O39: 27600.8 | P39: 24730.53 | Q39: 14355.9 | S39: =SUM(F39:Q39) -> 294490.75
F44: =F5 -> 2021 | S44: Grand Total
B45: WASTE | F45: 20 | G45: 29 | H45: 31 | I45: 29 | J45: 22 | K45: 30 | L45: 23 | M45: 17 | N45: 22 | O45: 13 | P45: 17 | Q45: 31 | S45: =SUM(F45:Q45) -> 284
F46: Januari | G46: Februari | H46: Maret | I46: April | J46: Mei | K46: Juni | L46: Juli | M46: Agustus | N46: September | O46: Oktober | P46: November | Q46: Desember
C47: Budget | D47: Actual
B48: Spent Bleaching Earth | C48: 0.22 | D48: =S48 -> #DIV/0! | E48: OC | S48: =AVERAGE(F48:Q48) -> #DIV/0!
F49: =F36+(F48*F36) -> 38633 | G49: =G36+(G48*G36) -> 58638 | H49: =H36+(H48*H36) -> 18075 | I49: =I36+(I48*I36) -> 46762 | J49: =J36+(J48*J36) -> 52543 | K49: =K36+(K48*K36) -> 53751 | L49: =L36+(L48*L36) -> 49870 | M49: =M36+(M48*M36) -> 68202 | ... Q49: =Q36+(Q48*Q36) -> 100972 | S49: =SUM(F49:Q49) -> 797796
B51: Effluent | D51: =S51/S101 -> 0 | E51: Raw Water | S51: =SUM(F51:Q51) -> 0
B56: YEARLY UTILITY CONSUMPTION DETAILS - Tahun 2020
F58: 2020 | S58: Grand Total
B59: UTILITY CONSUMPTION PER DAY | F59: 20 | G59: 29 | H59: 31 | I59: 29 | J59: 22 | K59: 30 | L59: 23 | M59: 17 | N59: 22 | O59: 13 | P59: 17 | Q59: 31 | S59: =SUM(F59:Q59) -> 284
...
